I0714 05:31:02.819533       1 cache.go:1363] There are <0> Jobs, <1> Queues and <5> Nodes in total for scheduling.
I0714 05:31:02.819696       1 session.go:190] Open Session 660de3a3-3d12-4720-97bf-da50c780ebc0 with <0> Job and <1> Queues
I0714 05:31:02.822166       1 enqueue.go:79] Try to enqueue PodGroup to 0 Queues
I0714 05:31:02.822292       1 allocate.go:64] Try to allocate resource to 0 Queues
I0714 05:31:02.822649       1 session.go:244] Close Session 660de3a3-3d12-4720-97bf-da50c780ebc0
I0714 05:31:03.825755       1 cache.go:1363] There are <0> Jobs, <1> Queues and <5> Nodes in total for scheduling.
I0714 05:31:03.825924       1 session.go:190] Open Session a32ab3cf-50d4-4a13-9766-e5331138eec1 with <0> Job and <1> Queues
I0714 05:31:03.827672       1 enqueue.go:79] Try to enqueue PodGroup to 0 Queues
I0714 05:31:03.827753       1 allocate.go:64] Try to allocate resource to 0 Queues
I0714 05:31:03.827953       1 session.go:244] Close Session a32ab3cf-50d4-4a13-9766-e5331138eec1
I0714 05:31:04.830910       1 cache.go:1363] There are <0> Jobs, <1> Queues and <5> Nodes in total for scheduling.
I0714 05:31:04.831087       1 session.go:190] Open Session 2e64d13e-cbeb-4dc8-88c0-19176ab1b44d with <0> Job and <1> Queues
I0714 05:31:04.833030       1 enqueue.go:79] Try to enqueue PodGroup to 0 Queues
I0714 05:31:04.833104       1 allocate.go:64] Try to allocate resource to 0 Queues
I0714 05:31:04.833322       1 session.go:244] Close Session 2e64d13e-cbeb-4dc8-88c0-19176ab1b44d
I0714 05:31:05.835567       1 cache.go:1363] There are <0> Jobs, <1> Queues and <5> Nodes in total for scheduling.
I0714 05:31:05.835781       1 session.go:190] Open Session 1dd59e77-df7c-4dcf-a7db-db4860855622 with <0> Job and <1> Queues
I0714 05:31:05.837702       1 enqueue.go:79] Try to enqueue PodGroup to 0 Queues
I0714 05:31:05.837773       1 allocate.go:64] Try to allocate resource to 0 Queues
I0714 05:31:05.837992       1 session.go:244] Close Session 1dd59e77-df7c-4dcf-a7db-db4860855622
I0714 05:31:06.268403       1 cache.go:1489] The metrics type is not set in the volcano scheduler configmap file. As a result, the CPU and memory load information of the node is not collected.
I0714 05:31:06.840510       1 cache.go:1363] There are <0> Jobs, <1> Queues and <5> Nodes in total for scheduling.
I0714 05:31:06.840694       1 session.go:190] Open Session 2fe76506-db88-4bbf-bb7d-c03a96a4027f with <0> Job and <1> Queues
I0714 05:31:06.842498       1 enqueue.go:79] Try to enqueue PodGroup to 0 Queues
I0714 05:31:06.842565       1 allocate.go:64] Try to allocate resource to 0 Queues
I0714 05:31:06.842797       1 session.go:244] Close Session 2fe76506-db88-4bbf-bb7d-c03a96a4027f
I0714 05:31:07.845450       1 cache.go:1363] There are <0> Jobs, <1> Queues and <5> Nodes in total for scheduling.
I0714 05:31:07.845617       1 session.go:190] Open Session e2229e19-5d10-4e43-b821-78bc69380664 with <0> Job and <1> Queues
I0714 05:31:07.847361       1 enqueue.go:79] Try to enqueue PodGroup to 0 Queues
I0714 05:31:07.847453       1 allocate.go:64] Try to allocate resource to 0 Queues
I0714 05:31:07.847684       1 session.go:244] Close Session e2229e19-5d10-4e43-b821-78bc69380664
I0714 05:31:08.850599       1 cache.go:1363] There are <0> Jobs, <1> Queues and <5> Nodes in total for scheduling.
I0714 05:31:08.850755       1 session.go:190] Open Session 1b83f529-93e7-45b8-b9d2-68fc5f3ebdc1 with <0> Job and <1> Queues
I0714 05:31:08.852557       1 enqueue.go:79] Try to enqueue PodGroup to 0 Queues
I0714 05:31:08.852627       1 allocate.go:64] Try to allocate resource to 0 Queues
I0714 05:31:08.852844       1 session.go:244] Close Session 1b83f529-93e7-45b8-b9d2-68fc5f3ebdc1
I0714 05:31:09.855575       1 cache.go:1363] There are <0> Jobs, <1> Queues and <5> Nodes in total for scheduling.
I0714 05:31:09.855747       1 session.go:190] Open Session 181aeacc-8662-4140-80af-58c12c3bdf98 with <0> Job and <1> Queues
I0714 05:31:09.857713       1 enqueue.go:79] Try to enqueue PodGroup to 0 Queues
I0714 05:31:09.857779       1 allocate.go:64] Try to allocate resource to 0 Queues
I0714 05:31:09.857993       1 session.go:244] Close Session 181aeacc-8662-4140-80af-58c12c3bdf98
I0714 05:31:10.860801       1 cache.go:1363] There are <0> Jobs, <1> Queues and <5> Nodes in total for scheduling.
I0714 05:31:10.860989       1 session.go:190] Open Session 88b310f5-7297-4057-86d2-bfd703abfc01 with <0> Job and <1> Queues
I0714 05:31:10.862840       1 enqueue.go:79] Try to enqueue PodGroup to 0 Queues
I0714 05:31:10.862909       1 allocate.go:64] Try to allocate resource to 0 Queues
I0714 05:31:10.863129       1 session.go:244] Close Session 88b310f5-7297-4057-86d2-bfd703abfc01
I0714 05:31:11.865539       1 cache.go:1363] There are <0> Jobs, <1> Queues and <5> Nodes in total for scheduling.
I0714 05:31:11.865719       1 session.go:190] Open Session e9db3588-5cf6-497d-8fb2-4b7c7c22c728 with <0> Job and <1> Queues
I0714 05:31:11.867463       1 enqueue.go:79] Try to enqueue PodGroup to 0 Queues
I0714 05:31:11.867536       1 allocate.go:64] Try to allocate resource to 0 Queues
I0714 05:31:11.867762       1 session.go:244] Close Session e9db3588-5cf6-497d-8fb2-4b7c7c22c728
I0714 05:31:12.870411       1 cache.go:1363] There are <0> Jobs, <1> Queues and <5> Nodes in total for scheduling.
I0714 05:31:12.870586       1 session.go:190] Open Session b3a7c566-75c2-4ab0-8929-544ec3ddc420 with <0> Job and <1> Queues
I0714 05:31:12.872471       1 enqueue.go:79] Try to enqueue PodGroup to 0 Queues
I0714 05:31:12.872540       1 allocate.go:64] Try to allocate resource to 0 Queues
I0714 05:31:12.872762       1 session.go:244] Close Session b3a7c566-75c2-4ab0-8929-544ec3ddc420
I0714 05:31:13.874969       1 cache.go:1363] There are <0> Jobs, <1> Queues and <5> Nodes in total for scheduling.
I0714 05:31:13.875112       1 session.go:190] Open Session 04668e2b-34a8-4b78-bf21-1550b6156552 with <0> Job and <1> Queues
I0714 05:31:13.876728       1 enqueue.go:79] Try to enqueue PodGroup to 0 Queues
I0714 05:31:13.876791       1 allocate.go:64] Try to allocate resource to 0 Queues
I0714 05:31:13.876987       1 session.go:244] Close Session 04668e2b-34a8-4b78-bf21-1550b6156552
I0714 05:31:14.879049       1 cache.go:1363] There are <0> Jobs, <1> Queues and <5> Nodes in total for scheduling.
I0714 05:31:14.879207       1 session.go:190] Open Session 44d17f43-c4d6-4682-be17-5a33e1ebdc37 with <0> Job and <1> Queues
I0714 05:31:14.880903       1 enqueue.go:79] Try to enqueue PodGroup to 0 Queues
I0714 05:31:14.880969       1 allocate.go:64] Try to allocate resource to 0 Queues
I0714 05:31:14.881182       1 session.go:244] Close Session 44d17f43-c4d6-4682-be17-5a33e1ebdc37
I0714 05:31:15.883851       1 cache.go:1363] There are <0> Jobs, <1> Queues and <5> Nodes in total for scheduling.
I0714 05:31:15.884028       1 session.go:190] Open Session 15cb4c8f-9ff7-4bba-8fa4-35fded5707cd with <0> Job and <1> Queues
I0714 05:31:15.885933       1 enqueue.go:79] Try to enqueue PodGroup to 0 Queues
I0714 05:31:15.886006       1 allocate.go:64] Try to allocate resource to 0 Queues
I0714 05:31:15.886226       1 session.go:244] Close Session 15cb4c8f-9ff7-4bba-8fa4-35fded5707cd
I0714 05:31:16.888247       1 cache.go:1363] There are <0> Jobs, <1> Queues and <5> Nodes in total for scheduling.
I0714 05:31:16.888430       1 session.go:190] Open Session 5ad698b7-1b1f-4883-934d-39fcaa4c40d3 with <0> Job and <1> Queues
I0714 05:31:16.890132       1 enqueue.go:79] Try to enqueue PodGroup to 0 Queues
I0714 05:31:16.890211       1 allocate.go:64] Try to allocate resource to 0 Queues
I0714 05:31:16.890433       1 session.go:244] Close Session 5ad698b7-1b1f-4883-934d-39fcaa4c40d3
I0714 05:31:17.892631       1 cache.go:1363] There are <0> Jobs, <1> Queues and <5> Nodes in total for scheduling.
I0714 05:31:17.892791       1 session.go:190] Open Session dbf47f65-1c7f-480d-9016-a098b5c74c3f with <0> Job and <1> Queues
I0714 05:31:17.894448       1 enqueue.go:79] Try to enqueue PodGroup to 0 Queues
I0714 05:31:17.894512       1 allocate.go:64] Try to allocate resource to 0 Queues
I0714 05:31:17.894727       1 session.go:244] Close Session dbf47f65-1c7f-480d-9016-a098b5c74c3f
I0714 05:31:18.897631       1 cache.go:1363] There are <0> Jobs, <1> Queues and <5> Nodes in total for scheduling.
I0714 05:31:18.897770       1 session.go:190] Open Session 0a1281b0-0481-4962-b377-4299cb93508b with <0> Job and <1> Queues
I0714 05:31:18.899461       1 enqueue.go:79] Try to enqueue PodGroup to 0 Queues
I0714 05:31:18.899531       1 allocate.go:64] Try to allocate resource to 0 Queues
I0714 05:31:18.899735       1 session.go:244] Close Session 0a1281b0-0481-4962-b377-4299cb93508b
I0714 05:31:19.902186       1 cache.go:1363] There are <0> Jobs, <1> Queues and <5> Nodes in total for scheduling.
I0714 05:31:19.902343       1 session.go:190] Open Session a79f6f8d-4b19-4f84-9799-379b86685612 with <0> Job and <1> Queues
I0714 05:31:19.904052       1 enqueue.go:79] Try to enqueue PodGroup to 0 Queues
I0714 05:31:19.904123       1 allocate.go:64] Try to allocate resource to 0 Queues
I0714 05:31:19.904377       1 session.go:244] Close Session a79f6f8d-4b19-4f84-9799-379b86685612
I0714 05:31:20.907210       1 cache.go:1363] There are <0> Jobs, <1> Queues and <5> Nodes in total for scheduling.
I0714 05:31:20.907399       1 session.go:190] Open Session 059fb978-2f78-4696-92e3-e8c553bebd27 with <0> Job and <1> Queues
I0714 05:31:20.909166       1 enqueue.go:79] Try to enqueue PodGroup to 0 Queues
I0714 05:31:20.909237       1 allocate.go:64] Try to allocate resource to 0 Queues
I0714 05:31:20.909445       1 session.go:244] Close Session 059fb978-2f78-4696-92e3-e8c553bebd27
I0714 05:31:21.911836       1 cache.go:1363] There are <0> Jobs, <1> Queues and <5> Nodes in total for scheduling.
I0714 05:31:21.912017       1 session.go:190] Open Session 822796e0-4cb7-442d-9937-41cfdc859636 with <0> Job and <1> Queues
I0714 05:31:21.913780       1 enqueue.go:79] Try to enqueue PodGroup to 0 Queues
I0714 05:31:21.913852       1 allocate.go:64] Try to allocate resource to 0 Queues
I0714 05:31:21.914054       1 session.go:244] Close Session 822796e0-4cb7-442d-9937-41cfdc859636
I0714 05:31:22.917149       1 cache.go:1363] There are <0> Jobs, <1> Queues and <5> Nodes in total for scheduling.
I0714 05:31:22.917301       1 session.go:190] Open Session 016322e3-d5b2-4b47-a2fa-30e9c55d6f2f with <0> Job and <1> Queues
I0714 05:31:22.918941       1 enqueue.go:79] Try to enqueue PodGroup to 0 Queues
I0714 05:31:22.919023       1 allocate.go:64] Try to allocate resource to 0 Queues
I0714 05:31:22.919248       1 session.go:244] Close Session 016322e3-d5b2-4b47-a2fa-30e9c55d6f2f
I0714 05:31:23.921656       1 cache.go:1363] There are <0> Jobs, <1> Queues and <5> Nodes in total for scheduling.
I0714 05:31:23.921786       1 session.go:190] Open Session 9ab02b93-c4c5-4b94-bf07-dcb749e6b23b with <0> Job and <1> Queues
I0714 05:31:23.923310       1 enqueue.go:79] Try to enqueue PodGroup to 0 Queues
I0714 05:31:23.923372       1 allocate.go:64] Try to allocate resource to 0 Queues
I0714 05:31:23.923539       1 session.go:244] Close Session 9ab02b93-c4c5-4b94-bf07-dcb749e6b23b
I0714 05:31:24.925947       1 cache.go:1363] There are <0> Jobs, <1> Queues and <5> Nodes in total for scheduling.
I0714 05:31:24.926145       1 session.go:190] Open Session c96a515f-fe73-4ffc-8ef6-ba963debce59 with <0> Job and <1> Queues
I0714 05:31:24.927935       1 enqueue.go:79] Try to enqueue PodGroup to 0 Queues
I0714 05:31:24.928000       1 allocate.go:64] Try to allocate resource to 0 Queues
I0714 05:31:24.928226       1 session.go:244] Close Session c96a515f-fe73-4ffc-8ef6-ba963debce59
I0714 05:31:25.931039       1 cache.go:1363] There are <0> Jobs, <1> Queues and <5> Nodes in total for scheduling.
I0714 05:31:25.931214       1 session.go:190] Open Session 774a770a-7956-410c-90a2-daeff0d526dd with <0> Job and <1> Queues
I0714 05:31:25.932997       1 enqueue.go:79] Try to enqueue PodGroup to 0 Queues
I0714 05:31:25.933065       1 allocate.go:64] Try to allocate resource to 0 Queues
I0714 05:31:25.933275       1 session.go:244] Close Session 774a770a-7956-410c-90a2-daeff0d526dd
I0714 05:31:26.935631       1 cache.go:1363] There are <0> Jobs, <1> Queues and <5> Nodes in total for scheduling.
I0714 05:31:26.935782       1 session.go:190] Open Session 657219ce-9f0b-48a3-b8e4-bad58af5747d with <0> Job and <1> Queues
I0714 05:31:26.937530       1 enqueue.go:79] Try to enqueue PodGroup to 0 Queues
I0714 05:31:26.937596       1 allocate.go:64] Try to allocate resource to 0 Queues
I0714 05:31:26.937828       1 session.go:244] Close Session 657219ce-9f0b-48a3-b8e4-bad58af5747d
I0714 05:31:27.939800       1 cache.go:1363] There are <0> Jobs, <1> Queues and <5> Nodes in total for scheduling.
I0714 05:31:27.939943       1 session.go:190] Open Session f7cac917-dbdf-4aa3-bca3-af492f4fdb92 with <0> Job and <1> Queues
I0714 05:31:27.941602       1 enqueue.go:79] Try to enqueue PodGroup to 0 Queues
I0714 05:31:27.941668       1 allocate.go:64] Try to allocate resource to 0 Queues
I0714 05:31:27.941869       1 session.go:244] Close Session f7cac917-dbdf-4aa3-bca3-af492f4fdb92
I0714 05:31:28.944129       1 cache.go:1363] There are <0> Jobs, <1> Queues and <5> Nodes in total for scheduling.
I0714 05:31:28.944343       1 session.go:190] Open Session cec5e50e-e49a-4628-a1bb-6a7b7c1ba80c with <0> Job and <1> Queues
I0714 05:31:28.946014       1 enqueue.go:79] Try to enqueue PodGroup to 0 Queues
I0714 05:31:28.946079       1 allocate.go:64] Try to allocate resource to 0 Queues
I0714 05:31:28.946292       1 session.go:244] Close Session cec5e50e-e49a-4628-a1bb-6a7b7c1ba80c
I0714 05:31:29.948825       1 cache.go:1363] There are <0> Jobs, <1> Queues and <5> Nodes in total for scheduling.
I0714 05:31:29.948993       1 session.go:190] Open Session 401450a8-5353-4f5c-bdae-5a3630210218 with <0> Job and <1> Queues
I0714 05:31:29.950787       1 enqueue.go:79] Try to enqueue PodGroup to 0 Queues
I0714 05:31:29.950851       1 allocate.go:64] Try to allocate resource to 0 Queues
I0714 05:31:29.951076       1 session.go:244] Close Session 401450a8-5353-4f5c-bdae-5a3630210218
I0714 05:31:30.953891       1 cache.go:1363] There are <0> Jobs, <1> Queues and <5> Nodes in total for scheduling.
I0714 05:31:30.954066       1 session.go:190] Open Session f6eae503-187f-43dd-9fe7-8ab0d3a5295b with <0> Job and <1> Queues
I0714 05:31:30.955765       1 enqueue.go:79] Try to enqueue PodGroup to 0 Queues
I0714 05:31:30.955834       1 allocate.go:64] Try to allocate resource to 0 Queues
I0714 05:31:30.956048       1 session.go:244] Close Session f6eae503-187f-43dd-9fe7-8ab0d3a5295b
I0714 05:31:31.958758       1 cache.go:1363] There are <0> Jobs, <1> Queues and <5> Nodes in total for scheduling.
I0714 05:31:31.958905       1 session.go:190] Open Session f35c5749-dab0-40da-99be-82aff075b5ba with <0> Job and <1> Queues
I0714 05:31:31.960524       1 enqueue.go:79] Try to enqueue PodGroup to 0 Queues
I0714 05:31:31.960588       1 allocate.go:64] Try to allocate resource to 0 Queues
I0714 05:31:31.960792       1 session.go:244] Close Session f35c5749-dab0-40da-99be-82aff075b5ba
I0714 05:31:32.963170       1 cache.go:1363] There are <0> Jobs, <1> Queues and <5> Nodes in total for scheduling.
I0714 05:31:32.963312       1 session.go:190] Open Session 47864c23-2273-4e11-9ff3-f3bf219e645d with <0> Job and <1> Queues
I0714 05:31:32.964973       1 enqueue.go:79] Try to enqueue PodGroup to 0 Queues
I0714 05:31:32.965041       1 allocate.go:64] Try to allocate resource to 0 Queues
I0714 05:31:32.965223       1 session.go:244] Close Session 47864c23-2273-4e11-9ff3-f3bf219e645d
I0714 05:31:33.967559       1 cache.go:1363] There are <0> Jobs, <1> Queues and <5> Nodes in total for scheduling.
I0714 05:31:33.967729       1 session.go:190] Open Session 968807ad-12b6-48a6-b0bb-7fc4575cb3d8 with <0> Job and <1> Queues
I0714 05:31:33.969450       1 enqueue.go:79] Try to enqueue PodGroup to 0 Queues
I0714 05:31:33.969518       1 allocate.go:64] Try to allocate resource to 0 Queues
I0714 05:31:33.969740       1 session.go:244] Close Session 968807ad-12b6-48a6-b0bb-7fc4575cb3d8
I0714 05:31:34.972192       1 cache.go:1363] There are <0> Jobs, <1> Queues and <5> Nodes in total for scheduling.
I0714 05:31:34.972386       1 session.go:190] Open Session c589be1c-3674-4a28-8288-6a9bd563d296 with <0> Job and <1> Queues
I0714 05:31:34.974041       1 enqueue.go:79] Try to enqueue PodGroup to 0 Queues
I0714 05:31:34.974112       1 allocate.go:64] Try to allocate resource to 0 Queues
I0714 05:31:34.974348       1 session.go:244] Close Session c589be1c-3674-4a28-8288-6a9bd563d296
I0714 05:31:35.976729       1 cache.go:1363] There are <0> Jobs, <1> Queues and <5> Nodes in total for scheduling.
I0714 05:31:35.976899       1 session.go:190] Open Session c979954f-0ad5-4504-8a82-32d138872397 with <0> Job and <1> Queues
I0714 05:31:35.978641       1 enqueue.go:79] Try to enqueue PodGroup to 0 Queues
I0714 05:31:35.978713       1 allocate.go:64] Try to allocate resource to 0 Queues
I0714 05:31:35.978946       1 session.go:244] Close Session c979954f-0ad5-4504-8a82-32d138872397
I0714 05:31:36.269611       1 cache.go:1489] The metrics type is not set in the volcano scheduler configmap file. As a result, the CPU and memory load information of the node is not collected.
I0714 05:31:36.981485       1 cache.go:1363] There are <0> Jobs, <1> Queues and <5> Nodes in total for scheduling.
I0714 05:31:36.981682       1 session.go:190] Open Session 72e69e6a-1a0e-4c3f-917b-cd0b4e2d1650 with <0> Job and <1> Queues
I0714 05:31:36.983451       1 enqueue.go:79] Try to enqueue PodGroup to 0 Queues
I0714 05:31:36.983522       1 allocate.go:64] Try to allocate resource to 0 Queues
I0714 05:31:36.983742       1 session.go:244] Close Session 72e69e6a-1a0e-4c3f-917b-cd0b4e2d1650
I0714 05:31:37.986570       1 cache.go:1363] There are <0> Jobs, <1> Queues and <5> Nodes in total for scheduling.
I0714 05:31:37.986764       1 session.go:190] Open Session 396f0f8d-5d31-426f-a663-901d93bf047c with <0> Job and <1> Queues
I0714 05:31:37.988688       1 enqueue.go:79] Try to enqueue PodGroup to 0 Queues
I0714 05:31:37.988761       1 allocate.go:64] Try to allocate resource to 0 Queues
I0714 05:31:37.988994       1 session.go:244] Close Session 396f0f8d-5d31-426f-a663-901d93bf047c
I0714 05:31:38.992019       1 cache.go:1363] There are <0> Jobs, <1> Queues and <5> Nodes in total for scheduling.
I0714 05:31:38.992201       1 session.go:190] Open Session e0be75ba-fdd8-47fc-b88c-3a58ae609a76 with <0> Job and <1> Queues
I0714 05:31:38.993986       1 enqueue.go:79] Try to enqueue PodGroup to 0 Queues
I0714 05:31:38.994058       1 allocate.go:64] Try to allocate resource to 0 Queues
I0714 05:31:38.994287       1 session.go:244] Close Session e0be75ba-fdd8-47fc-b88c-3a58ae609a76
I0714 05:31:39.997900       1 cache.go:1363] There are <0> Jobs, <1> Queues and <5> Nodes in total for scheduling.
I0714 05:31:39.998087       1 session.go:190] Open Session 483b706c-ef5f-4d81-b318-db8b7a54850f with <0> Job and <1> Queues
I0714 05:31:39.999808       1 enqueue.go:79] Try to enqueue PodGroup to 0 Queues
I0714 05:31:39.999879       1 allocate.go:64] Try to allocate resource to 0 Queues
I0714 05:31:40.000105       1 session.go:244] Close Session 483b706c-ef5f-4d81-b318-db8b7a54850f
I0714 05:31:41.002666       1 cache.go:1363] There are <0> Jobs, <1> Queues and <5> Nodes in total for scheduling.
I0714 05:31:41.002849       1 session.go:190] Open Session ed9972fc-a6a4-4586-859e-5eae69e951c1 with <0> Job and <1> Queues
I0714 05:31:41.004677       1 enqueue.go:79] Try to enqueue PodGroup to 0 Queues
I0714 05:31:41.004751       1 allocate.go:64] Try to allocate resource to 0 Queues
I0714 05:31:41.004980       1 session.go:244] Close Session ed9972fc-a6a4-4586-859e-5eae69e951c1
I0714 05:31:42.007620       1 cache.go:1363] There are <0> Jobs, <1> Queues and <5> Nodes in total for scheduling.
I0714 05:31:42.007783       1 session.go:190] Open Session 608c380a-03ed-45d3-a78f-03d754849f2d with <0> Job and <1> Queues
I0714 05:31:42.009497       1 enqueue.go:79] Try to enqueue PodGroup to 0 Queues
I0714 05:31:42.009565       1 allocate.go:64] Try to allocate resource to 0 Queues
I0714 05:31:42.009768       1 session.go:244] Close Session 608c380a-03ed-45d3-a78f-03d754849f2d
I0714 05:31:43.012095       1 cache.go:1363] There are <0> Jobs, <1> Queues and <5> Nodes in total for scheduling.
I0714 05:31:43.012244       1 session.go:190] Open Session 72537d2e-8e21-4b1d-bfd7-944e15418739 with <0> Job and <1> Queues
I0714 05:31:43.013931       1 enqueue.go:79] Try to enqueue PodGroup to 0 Queues
I0714 05:31:43.013999       1 allocate.go:64] Try to allocate resource to 0 Queues
I0714 05:31:43.014218       1 session.go:244] Close Session 72537d2e-8e21-4b1d-bfd7-944e15418739
I0714 05:31:44.016851       1 cache.go:1363] There are <0> Jobs, <1> Queues and <5> Nodes in total for scheduling.
I0714 05:31:44.016999       1 session.go:190] Open Session a72f8563-60ec-4d89-b1c7-329c790d8c0b with <0> Job and <1> Queues
I0714 05:31:44.018681       1 enqueue.go:79] Try to enqueue PodGroup to 0 Queues
I0714 05:31:44.018754       1 allocate.go:64] Try to allocate resource to 0 Queues
I0714 05:31:44.018958       1 session.go:244] Close Session a72f8563-60ec-4d89-b1c7-329c790d8c0b
I0714 05:31:45.021174       1 cache.go:1363] There are <0> Jobs, <1> Queues and <5> Nodes in total for scheduling.
I0714 05:31:45.021313       1 session.go:190] Open Session 3b629d91-e6a3-41ed-aa59-5e7bcd119260 with <0> Job and <1> Queues
I0714 05:31:45.022927       1 enqueue.go:79] Try to enqueue PodGroup to 0 Queues
I0714 05:31:45.022993       1 allocate.go:64] Try to allocate resource to 0 Queues
I0714 05:31:45.023200       1 session.go:244] Close Session 3b629d91-e6a3-41ed-aa59-5e7bcd119260
I0714 05:31:46.025492       1 cache.go:1363] There are <0> Jobs, <1> Queues and <5> Nodes in total for scheduling.
I0714 05:31:46.025677       1 session.go:190] Open Session 610775cb-f499-4c54-8579-9b04636242cf with <0> Job and <1> Queues
I0714 05:31:46.027454       1 enqueue.go:79] Try to enqueue PodGroup to 0 Queues
I0714 05:31:46.027528       1 allocate.go:64] Try to allocate resource to 0 Queues
I0714 05:31:46.027744       1 session.go:244] Close Session 610775cb-f499-4c54-8579-9b04636242cf
I0714 05:31:47.032024       1 cache.go:1363] There are <0> Jobs, <1> Queues and <5> Nodes in total for scheduling.
I0714 05:31:47.032238       1 session.go:190] Open Session 7565eaa9-1065-4556-ba5d-e791db7ca576 with <0> Job and <1> Queues
I0714 05:31:47.034321       1 enqueue.go:79] Try to enqueue PodGroup to 0 Queues
I0714 05:31:47.034410       1 allocate.go:64] Try to allocate resource to 0 Queues
I0714 05:31:47.034749       1 session.go:244] Close Session 7565eaa9-1065-4556-ba5d-e791db7ca576
I0714 05:31:48.037723       1 cache.go:1363] There are <0> Jobs, <1> Queues and <5> Nodes in total for scheduling.
I0714 05:31:48.037893       1 session.go:190] Open Session cd1ed757-595d-457e-8f67-26604e39895b with <0> Job and <1> Queues
I0714 05:31:48.039599       1 enqueue.go:79] Try to enqueue PodGroup to 0 Queues
I0714 05:31:48.039667       1 allocate.go:64] Try to allocate resource to 0 Queues
I0714 05:31:48.039879       1 session.go:244] Close Session cd1ed757-595d-457e-8f67-26604e39895b
I0714 05:31:49.042442       1 cache.go:1363] There are <0> Jobs, <1> Queues and <5> Nodes in total for scheduling.
I0714 05:31:49.042592       1 session.go:190] Open Session f48db9a5-b66e-4ec3-8928-3bf79acacb59 with <0> Job and <1> Queues
I0714 05:31:49.044235       1 enqueue.go:79] Try to enqueue PodGroup to 0 Queues
I0714 05:31:49.044344       1 allocate.go:64] Try to allocate resource to 0 Queues
I0714 05:31:49.044553       1 session.go:244] Close Session f48db9a5-b66e-4ec3-8928-3bf79acacb59
I0714 05:31:50.047106       1 cache.go:1363] There are <0> Jobs, <1> Queues and <5> Nodes in total for scheduling.
I0714 05:31:50.047301       1 session.go:190] Open Session a8e5175d-67f9-47bb-89a5-52eb93584285 with <0> Job and <1> Queues
I0714 05:31:50.049200       1 enqueue.go:79] Try to enqueue PodGroup to 0 Queues
I0714 05:31:50.049269       1 allocate.go:64] Try to allocate resource to 0 Queues
I0714 05:31:50.049496       1 session.go:244] Close Session a8e5175d-67f9-47bb-89a5-52eb93584285
I0714 05:31:51.052099       1 cache.go:1363] There are <0> Jobs, <1> Queues and <5> Nodes in total for scheduling.
I0714 05:31:51.052371       1 session.go:190] Open Session 488d05fb-94aa-40b8-a33f-79a40945ade4 with <0> Job and <1> Queues
I0714 05:31:51.054205       1 enqueue.go:79] Try to enqueue PodGroup to 0 Queues
I0714 05:31:51.054283       1 allocate.go:64] Try to allocate resource to 0 Queues
I0714 05:31:51.054504       1 session.go:244] Close Session 488d05fb-94aa-40b8-a33f-79a40945ade4
I0714 05:31:52.057041       1 cache.go:1363] There are <0> Jobs, <1> Queues and <5> Nodes in total for scheduling.
I0714 05:31:52.057239       1 session.go:190] Open Session 21bafdc0-e198-4cb2-aeeb-5d229ec331d2 with <0> Job and <1> Queues
I0714 05:31:52.059044       1 enqueue.go:79] Try to enqueue PodGroup to 0 Queues
I0714 05:31:52.059110       1 allocate.go:64] Try to allocate resource to 0 Queues
I0714 05:31:52.059310       1 session.go:244] Close Session 21bafdc0-e198-4cb2-aeeb-5d229ec331d2
I0714 05:31:53.062115       1 cache.go:1363] There are <0> Jobs, <1> Queues and <5> Nodes in total for scheduling.
I0714 05:31:53.062291       1 session.go:190] Open Session f6012126-f611-420d-b6db-c0af40e3a3cd with <0> Job and <1> Queues
I0714 05:31:53.064069       1 enqueue.go:79] Try to enqueue PodGroup to 0 Queues
I0714 05:31:53.064142       1 allocate.go:64] Try to allocate resource to 0 Queues
I0714 05:31:53.064399       1 session.go:244] Close Session f6012126-f611-420d-b6db-c0af40e3a3cd
I0714 05:31:54.066422       1 cache.go:1363] There are <0> Jobs, <1> Queues and <5> Nodes in total for scheduling.
I0714 05:31:54.066596       1 session.go:190] Open Session f593dc62-8ca5-4051-ab86-3a87a5744304 with <0> Job and <1> Queues
I0714 05:31:54.068380       1 enqueue.go:79] Try to enqueue PodGroup to 0 Queues
I0714 05:31:54.068447       1 allocate.go:64] Try to allocate resource to 0 Queues
I0714 05:31:54.068644       1 session.go:244] Close Session f593dc62-8ca5-4051-ab86-3a87a5744304
I0714 05:31:55.070453       1 cache.go:1363] There are <0> Jobs, <1> Queues and <5> Nodes in total for scheduling.
I0714 05:31:55.070627       1 session.go:190] Open Session 7c083ed1-7660-48c7-a80f-81063d016725 with <0> Job and <1> Queues
I0714 05:31:55.072432       1 enqueue.go:79] Try to enqueue PodGroup to 0 Queues
I0714 05:31:55.072503       1 allocate.go:64] Try to allocate resource to 0 Queues
I0714 05:31:55.072715       1 session.go:244] Close Session 7c083ed1-7660-48c7-a80f-81063d016725
I0714 05:31:56.074789       1 cache.go:1363] There are <0> Jobs, <1> Queues and <5> Nodes in total for scheduling.
I0714 05:31:56.074994       1 session.go:190] Open Session 461d689d-2d34-4fd9-a426-906c5991643f with <0> Job and <1> Queues
I0714 05:31:56.076869       1 enqueue.go:79] Try to enqueue PodGroup to 0 Queues
I0714 05:31:56.076940       1 allocate.go:64] Try to allocate resource to 0 Queues
I0714 05:31:56.077178       1 session.go:244] Close Session 461d689d-2d34-4fd9-a426-906c5991643f
I0714 05:31:57.079580       1 cache.go:1363] There are <0> Jobs, <1> Queues and <5> Nodes in total for scheduling.
I0714 05:31:57.079739       1 session.go:190] Open Session 2e775e4f-2a48-450d-a986-d13ab729cb60 with <0> Job and <1> Queues
I0714 05:31:57.081397       1 enqueue.go:79] Try to enqueue PodGroup to 0 Queues
I0714 05:31:57.081461       1 allocate.go:64] Try to allocate resource to 0 Queues
I0714 05:31:57.081665       1 session.go:244] Close Session 2e775e4f-2a48-450d-a986-d13ab729cb60
I0714 05:31:58.083803       1 cache.go:1363] There are <0> Jobs, <1> Queues and <5> Nodes in total for scheduling.
I0714 05:31:58.083950       1 session.go:190] Open Session 93df620e-22ab-4636-b1b4-830204960353 with <0> Job and <1> Queues
I0714 05:31:58.085724       1 enqueue.go:79] Try to enqueue PodGroup to 0 Queues
I0714 05:31:58.085790       1 allocate.go:64] Try to allocate resource to 0 Queues
I0714 05:31:58.085989       1 session.go:244] Close Session 93df620e-22ab-4636-b1b4-830204960353
I0714 05:31:59.087882       1 cache.go:1363] There are <0> Jobs, <1> Queues and <5> Nodes in total for scheduling.
I0714 05:31:59.088012       1 session.go:190] Open Session 1cdf53ab-fb3e-47b0-98e0-a389bb491fb2 with <0> Job and <1> Queues
I0714 05:31:59.089659       1 enqueue.go:79] Try to enqueue PodGroup to 0 Queues
I0714 05:31:59.089725       1 allocate.go:64] Try to allocate resource to 0 Queues
I0714 05:31:59.089912       1 session.go:244] Close Session 1cdf53ab-fb3e-47b0-98e0-a389bb491fb2
I0714 05:32:00.091956       1 cache.go:1363] There are <0> Jobs, <1> Queues and <5> Nodes in total for scheduling.
I0714 05:32:00.092149       1 session.go:190] Open Session 4dc4bbd1-4758-426f-b3f5-98d0f0c38194 with <0> Job and <1> Queues
I0714 05:32:00.094070       1 enqueue.go:79] Try to enqueue PodGroup to 0 Queues
I0714 05:32:00.094147       1 allocate.go:64] Try to allocate resource to 0 Queues
I0714 05:32:00.094357       1 session.go:244] Close Session 4dc4bbd1-4758-426f-b3f5-98d0f0c38194
I0714 05:32:01.097211       1 cache.go:1363] There are <0> Jobs, <1> Queues and <5> Nodes in total for scheduling.
I0714 05:32:01.097390       1 session.go:190] Open Session 63596cad-12e6-454e-aba9-3f3615137ed3 with <0> Job and <1> Queues
I0714 05:32:01.099139       1 enqueue.go:79] Try to enqueue PodGroup to 0 Queues
I0714 05:32:01.099207       1 allocate.go:64] Try to allocate resource to 0 Queues
I0714 05:32:01.099425       1 session.go:244] Close Session 63596cad-12e6-454e-aba9-3f3615137ed3
I0714 05:32:02.102114       1 cache.go:1363] There are <0> Jobs, <1> Queues and <5> Nodes in total for scheduling.
I0714 05:32:02.102299       1 session.go:190] Open Session e6c1d2c5-98bc-4318-8f32-6eb4cf722d52 with <0> Job and <1> Queues
I0714 05:32:02.104040       1 enqueue.go:79] Try to enqueue PodGroup to 0 Queues
I0714 05:32:02.104110       1 allocate.go:64] Try to allocate resource to 0 Queues
I0714 05:32:02.104376       1 session.go:244] Close Session e6c1d2c5-98bc-4318-8f32-6eb4cf722d52
I0714 05:32:03.107687       1 cache.go:1363] There are <0> Jobs, <1> Queues and <5> Nodes in total for scheduling.
I0714 05:32:03.107864       1 session.go:190] Open Session 5a38207a-e13e-4142-bfa4-42378515ed9c with <0> Job and <1> Queues
I0714 05:32:03.109693       1 enqueue.go:79] Try to enqueue PodGroup to 0 Queues
I0714 05:32:03.109764       1 allocate.go:64] Try to allocate resource to 0 Queues
I0714 05:32:03.109991       1 session.go:244] Close Session 5a38207a-e13e-4142-bfa4-42378515ed9c
I0714 05:32:04.112191       1 cache.go:1363] There are <0> Jobs, <1> Queues and <5> Nodes in total for scheduling.
I0714 05:32:04.112326       1 session.go:190] Open Session d66b3e63-db3e-4ef6-b652-ec985e4965c2 with <0> Job and <1> Queues
I0714 05:32:04.113601       1 enqueue.go:79] Try to enqueue PodGroup to 0 Queues
I0714 05:32:04.113666       1 allocate.go:64] Try to allocate resource to 0 Queues
I0714 05:32:04.113832       1 session.go:244] Close Session d66b3e63-db3e-4ef6-b652-ec985e4965c2
I0714 05:32:05.115817       1 cache.go:1363] There are <0> Jobs, <1> Queues and <5> Nodes in total for scheduling.
I0714 05:32:05.115912       1 session.go:190] Open Session 2556e41e-e0c4-44f5-be3e-9e1ddffd8ac7 with <0> Job and <1> Queues
I0714 05:32:05.117033       1 enqueue.go:79] Try to enqueue PodGroup to 0 Queues
I0714 05:32:05.117083       1 allocate.go:64] Try to allocate resource to 0 Queues
I0714 05:32:05.117215       1 session.go:244] Close Session 2556e41e-e0c4-44f5-be3e-9e1ddffd8ac7
I0714 05:32:06.119416       1 cache.go:1363] There are <0> Jobs, <1> Queues and <5> Nodes in total for scheduling.
I0714 05:32:06.119586       1 session.go:190] Open Session a5c3b37a-215f-4089-8afd-660cc2e6ea03 with <0> Job and <1> Queues
I0714 05:32:06.121500       1 enqueue.go:79] Try to enqueue PodGroup to 0 Queues
I0714 05:32:06.121571       1 allocate.go:64] Try to allocate resource to 0 Queues
I0714 05:32:06.121787       1 session.go:244] Close Session a5c3b37a-215f-4089-8afd-660cc2e6ea03
I0714 05:32:06.270632       1 cache.go:1489] The metrics type is not set in the volcano scheduler configmap file. As a result, the CPU and memory load information of the node is not collected.
I0714 05:32:07.124085       1 cache.go:1363] There are <0> Jobs, <1> Queues and <5> Nodes in total for scheduling.
I0714 05:32:07.124240       1 session.go:190] Open Session 8c4f626f-3b9c-4c3a-84d9-5d52c0476c14 with <0> Job and <1> Queues
I0714 05:32:07.125953       1 enqueue.go:79] Try to enqueue PodGroup to 0 Queues
I0714 05:32:07.126030       1 allocate.go:64] Try to allocate resource to 0 Queues
I0714 05:32:07.126255       1 session.go:244] Close Session 8c4f626f-3b9c-4c3a-84d9-5d52c0476c14
I0714 05:32:08.128081       1 cache.go:1363] There are <0> Jobs, <1> Queues and <5> Nodes in total for scheduling.
I0714 05:32:08.128202       1 session.go:190] Open Session 90744941-480d-4e58-9596-bb652f6f4f0a with <0> Job and <1> Queues
I0714 05:32:08.129792       1 enqueue.go:79] Try to enqueue PodGroup to 0 Queues
I0714 05:32:08.129861       1 allocate.go:64] Try to allocate resource to 0 Queues
I0714 05:32:08.130062       1 session.go:244] Close Session 90744941-480d-4e58-9596-bb652f6f4f0a
I0714 05:32:09.132913       1 cache.go:1363] There are <0> Jobs, <1> Queues and <5> Nodes in total for scheduling.
I0714 05:32:09.133083       1 session.go:190] Open Session 84d7bf04-1661-4f17-86dd-d0c3b4dcf5a0 with <0> Job and <1> Queues
I0714 05:32:09.134912       1 enqueue.go:79] Try to enqueue PodGroup to 0 Queues
I0714 05:32:09.134997       1 allocate.go:64] Try to allocate resource to 0 Queues
I0714 05:32:09.135228       1 session.go:244] Close Session 84d7bf04-1661-4f17-86dd-d0c3b4dcf5a0
I0714 05:32:10.138354       1 cache.go:1363] There are <0> Jobs, <1> Queues and <5> Nodes in total for scheduling.
I0714 05:32:10.138523       1 session.go:190] Open Session 5bef6ce4-2ba3-4ff1-b41f-645d82d66b52 with <0> Job and <1> Queues
I0714 05:32:10.140246       1 enqueue.go:79] Try to enqueue PodGroup to 0 Queues
I0714 05:32:10.140364       1 allocate.go:64] Try to allocate resource to 0 Queues
I0714 05:32:10.140593       1 session.go:244] Close Session 5bef6ce4-2ba3-4ff1-b41f-645d82d66b52
I0714 05:32:11.142955       1 cache.go:1363] There are <0> Jobs, <1> Queues and <5> Nodes in total for scheduling.
I0714 05:32:11.143153       1 session.go:190] Open Session 1aada6c0-e732-4a5e-a0ce-ef421dca9153 with <0> Job and <1> Queues
I0714 05:32:11.145149       1 enqueue.go:79] Try to enqueue PodGroup to 0 Queues
I0714 05:32:11.145220       1 allocate.go:64] Try to allocate resource to 0 Queues
I0714 05:32:11.145443       1 session.go:244] Close Session 1aada6c0-e732-4a5e-a0ce-ef421dca9153
I0714 05:32:12.147574       1 cache.go:1363] There are <0> Jobs, <1> Queues and <5> Nodes in total for scheduling.
I0714 05:32:12.147730       1 session.go:190] Open Session 64a3e92a-5cbd-4aca-b1c9-bb5aa28cec69 with <0> Job and <1> Queues
I0714 05:32:12.149512       1 enqueue.go:79] Try to enqueue PodGroup to 0 Queues
I0714 05:32:12.149587       1 allocate.go:64] Try to allocate resource to 0 Queues
I0714 05:32:12.149805       1 session.go:244] Close Session 64a3e92a-5cbd-4aca-b1c9-bb5aa28cec69
I0714 05:32:13.152057       1 cache.go:1363] There are <0> Jobs, <1> Queues and <5> Nodes in total for scheduling.
I0714 05:32:13.152226       1 session.go:190] Open Session 5b7d8000-6b37-4b41-9931-ef401901b687 with <0> Job and <1> Queues
I0714 05:32:13.153957       1 enqueue.go:79] Try to enqueue PodGroup to 0 Queues
I0714 05:32:13.154029       1 allocate.go:64] Try to allocate resource to 0 Queues
I0714 05:32:13.154238       1 session.go:244] Close Session 5b7d8000-6b37-4b41-9931-ef401901b687
I0714 05:32:14.157134       1 cache.go:1363] There are <0> Jobs, <1> Queues and <5> Nodes in total for scheduling.
I0714 05:32:14.157293       1 session.go:190] Open Session a90ea24e-3405-442a-bd23-9d14d7d75d6a with <0> Job and <1> Queues
I0714 05:32:14.159066       1 enqueue.go:79] Try to enqueue PodGroup to 0 Queues
I0714 05:32:14.159137       1 allocate.go:64] Try to allocate resource to 0 Queues
I0714 05:32:14.159371       1 session.go:244] Close Session a90ea24e-3405-442a-bd23-9d14d7d75d6a
I0714 05:32:15.161986       1 cache.go:1363] There are <0> Jobs, <1> Queues and <5> Nodes in total for scheduling.
I0714 05:32:15.162129       1 session.go:190] Open Session 71c80573-45d7-4742-8a24-4081fb35269f with <0> Job and <1> Queues
I0714 05:32:15.163749       1 enqueue.go:79] Try to enqueue PodGroup to 0 Queues
I0714 05:32:15.163812       1 allocate.go:64] Try to allocate resource to 0 Queues
I0714 05:32:15.163994       1 session.go:244] Close Session 71c80573-45d7-4742-8a24-4081fb35269f
I0714 05:32:16.166986       1 cache.go:1363] There are <0> Jobs, <1> Queues and <5> Nodes in total for scheduling.
I0714 05:32:16.167203       1 session.go:190] Open Session ffadfe31-ec3f-42e8-809c-ba1781e60786 with <0> Job and <1> Queues
I0714 05:32:16.169057       1 enqueue.go:79] Try to enqueue PodGroup to 0 Queues
I0714 05:32:16.169142       1 allocate.go:64] Try to allocate resource to 0 Queues
I0714 05:32:16.169352       1 session.go:244] Close Session ffadfe31-ec3f-42e8-809c-ba1781e60786
I0714 05:32:17.171964       1 cache.go:1363] There are <0> Jobs, <1> Queues and <5> Nodes in total for scheduling.
I0714 05:32:17.172155       1 session.go:190] Open Session 569bd6c6-c488-4430-9169-c0ca5acf14c9 with <0> Job and <1> Queues
I0714 05:32:17.174168       1 enqueue.go:79] Try to enqueue PodGroup to 0 Queues
I0714 05:32:17.174271       1 allocate.go:64] Try to allocate resource to 0 Queues
I0714 05:32:17.174500       1 session.go:244] Close Session 569bd6c6-c488-4430-9169-c0ca5acf14c9
I0714 05:32:18.176788       1 cache.go:1363] There are <0> Jobs, <1> Queues and <5> Nodes in total for scheduling.
I0714 05:32:18.176961       1 session.go:190] Open Session d209cdd0-7ccc-47a9-aad8-abf65ff4b78e with <0> Job and <1> Queues
I0714 05:32:18.178783       1 enqueue.go:79] Try to enqueue PodGroup to 0 Queues
I0714 05:32:18.178855       1 allocate.go:64] Try to allocate resource to 0 Queues
I0714 05:32:18.179095       1 session.go:244] Close Session d209cdd0-7ccc-47a9-aad8-abf65ff4b78e
I0714 05:32:19.181830       1 cache.go:1363] There are <0> Jobs, <1> Queues and <5> Nodes in total for scheduling.
I0714 05:32:19.182017       1 session.go:190] Open Session 8efe9dc9-4555-4457-bdd8-fa57f80b7400 with <0> Job and <1> Queues
I0714 05:32:19.183849       1 enqueue.go:79] Try to enqueue PodGroup to 0 Queues
I0714 05:32:19.183920       1 allocate.go:64] Try to allocate resource to 0 Queues
I0714 05:32:19.184154       1 session.go:244] Close Session 8efe9dc9-4555-4457-bdd8-fa57f80b7400
I0714 05:32:20.187055       1 cache.go:1363] There are <0> Jobs, <1> Queues and <5> Nodes in total for scheduling.
I0714 05:32:20.187222       1 session.go:190] Open Session af16452a-eb6e-4c09-b96b-80354dafec52 with <0> Job and <1> Queues
I0714 05:32:20.189087       1 enqueue.go:79] Try to enqueue PodGroup to 0 Queues
I0714 05:32:20.189158       1 allocate.go:64] Try to allocate resource to 0 Queues
I0714 05:32:20.189376       1 session.go:244] Close Session af16452a-eb6e-4c09-b96b-80354dafec52
I0714 05:32:21.192028       1 cache.go:1363] There are <0> Jobs, <1> Queues and <5> Nodes in total for scheduling.
I0714 05:32:21.192206       1 session.go:190] Open Session 905564d8-fa01-4634-828f-7665ba57c02f with <0> Job and <1> Queues
I0714 05:32:21.194109       1 enqueue.go:79] Try to enqueue PodGroup to 0 Queues
I0714 05:32:21.194203       1 allocate.go:64] Try to allocate resource to 0 Queues
I0714 05:32:21.194428       1 session.go:244] Close Session 905564d8-fa01-4634-828f-7665ba57c02f
I0714 05:32:22.196895       1 cache.go:1363] There are <0> Jobs, <1> Queues and <5> Nodes in total for scheduling.
I0714 05:32:22.197125       1 session.go:190] Open Session 6320adc6-1d46-42fb-9ae9-af6e57e2f24d with <0> Job and <1> Queues
I0714 05:32:22.199106       1 enqueue.go:79] Try to enqueue PodGroup to 0 Queues
I0714 05:32:22.199183       1 allocate.go:64] Try to allocate resource to 0 Queues
I0714 05:32:22.199396       1 session.go:244] Close Session 6320adc6-1d46-42fb-9ae9-af6e57e2f24d
I0714 05:32:23.201656       1 cache.go:1363] There are <0> Jobs, <1> Queues and <5> Nodes in total for scheduling.
I0714 05:32:23.201832       1 session.go:190] Open Session fe67271d-2301-4af7-9ec9-fffbea4255c8 with <0> Job and <1> Queues
I0714 05:32:23.203644       1 enqueue.go:79] Try to enqueue PodGroup to 0 Queues
I0714 05:32:23.203717       1 allocate.go:64] Try to allocate resource to 0 Queues
I0714 05:32:23.203937       1 session.go:244] Close Session fe67271d-2301-4af7-9ec9-fffbea4255c8
I0714 05:32:24.206829       1 cache.go:1363] There are <0> Jobs, <1> Queues and <5> Nodes in total for scheduling.
I0714 05:32:24.206994       1 session.go:190] Open Session 6c5346ee-53b1-461e-8fce-55a2458a35f2 with <0> Job and <1> Queues
I0714 05:32:24.208792       1 enqueue.go:79] Try to enqueue PodGroup to 0 Queues
I0714 05:32:24.208865       1 allocate.go:64] Try to allocate resource to 0 Queues
I0714 05:32:24.209077       1 session.go:244] Close Session 6c5346ee-53b1-461e-8fce-55a2458a35f2
I0714 05:32:25.211638       1 cache.go:1363] There are <0> Jobs, <1> Queues and <5> Nodes in total for scheduling.
I0714 05:32:25.211818       1 session.go:190] Open Session b78cf3d5-e7e4-444d-bc84-efb5829f382b with <0> Job and <1> Queues
I0714 05:32:25.213648       1 enqueue.go:79] Try to enqueue PodGroup to 0 Queues
I0714 05:32:25.213722       1 allocate.go:64] Try to allocate resource to 0 Queues
I0714 05:32:25.213930       1 session.go:244] Close Session b78cf3d5-e7e4-444d-bc84-efb5829f382b
I0714 05:32:26.216094       1 cache.go:1363] There are <0> Jobs, <1> Queues and <5> Nodes in total for scheduling.
I0714 05:32:26.216355       1 session.go:190] Open Session 396a9185-78ce-437d-9d4d-4c0747e42aee with <0> Job and <1> Queues
I0714 05:32:26.218329       1 enqueue.go:79] Try to enqueue PodGroup to 0 Queues
I0714 05:32:26.218398       1 allocate.go:64] Try to allocate resource to 0 Queues
I0714 05:32:26.218666       1 session.go:244] Close Session 396a9185-78ce-437d-9d4d-4c0747e42aee
I0714 05:32:27.220832       1 cache.go:1363] There are <0> Jobs, <1> Queues and <5> Nodes in total for scheduling.
I0714 05:32:27.221002       1 session.go:190] Open Session a9eca8e0-93d4-4f4c-81dd-2279f424947b with <0> Job and <1> Queues
I0714 05:32:27.222880       1 enqueue.go:79] Try to enqueue PodGroup to 0 Queues
I0714 05:32:27.222955       1 allocate.go:64] Try to allocate resource to 0 Queues
I0714 05:32:27.223155       1 session.go:244] Close Session a9eca8e0-93d4-4f4c-81dd-2279f424947b
I0714 05:32:28.225936       1 cache.go:1363] There are <0> Jobs, <1> Queues and <5> Nodes in total for scheduling.
I0714 05:32:28.226093       1 session.go:190] Open Session 4c026463-632b-45dd-8e04-e6f3ea222680 with <0> Job and <1> Queues
I0714 05:32:28.227761       1 enqueue.go:79] Try to enqueue PodGroup to 0 Queues
I0714 05:32:28.227839       1 allocate.go:64] Try to allocate resource to 0 Queues
I0714 05:32:28.228035       1 session.go:244] Close Session 4c026463-632b-45dd-8e04-e6f3ea222680
I0714 05:32:29.230412       1 cache.go:1363] There are <0> Jobs, <1> Queues and <5> Nodes in total for scheduling.
I0714 05:32:29.230572       1 session.go:190] Open Session 3be634e7-d89c-47f9-bc9e-0e2b74fb38a9 with <0> Job and <1> Queues
I0714 05:32:29.232394       1 enqueue.go:79] Try to enqueue PodGroup to 0 Queues
I0714 05:32:29.232465       1 allocate.go:64] Try to allocate resource to 0 Queues
I0714 05:32:29.232676       1 session.go:244] Close Session 3be634e7-d89c-47f9-bc9e-0e2b74fb38a9
I0714 05:32:30.235626       1 cache.go:1363] There are <0> Jobs, <1> Queues and <5> Nodes in total for scheduling.
I0714 05:32:30.235800       1 session.go:190] Open Session 15c3f3ef-9e2c-4cd6-83d7-36e944adcd45 with <0> Job and <1> Queues
I0714 05:32:30.237595       1 enqueue.go:79] Try to enqueue PodGroup to 0 Queues
I0714 05:32:30.237668       1 allocate.go:64] Try to allocate resource to 0 Queues
I0714 05:32:30.237896       1 session.go:244] Close Session 15c3f3ef-9e2c-4cd6-83d7-36e944adcd45
I0714 05:32:31.240664       1 cache.go:1363] There are <0> Jobs, <1> Queues and <5> Nodes in total for scheduling.
I0714 05:32:31.240850       1 session.go:190] Open Session a34f1ee9-35cb-4789-bfe2-7df2993a7dba with <0> Job and <1> Queues
I0714 05:32:31.242683       1 enqueue.go:79] Try to enqueue PodGroup to 0 Queues
I0714 05:32:31.242755       1 allocate.go:64] Try to allocate resource to 0 Queues
I0714 05:32:31.242968       1 session.go:244] Close Session a34f1ee9-35cb-4789-bfe2-7df2993a7dba
I0714 05:32:32.245441       1 cache.go:1363] There are <0> Jobs, <1> Queues and <5> Nodes in total for scheduling.
I0714 05:32:32.245627       1 session.go:190] Open Session 2738a9ee-ec0d-4162-a83b-40babb81cd67 with <0> Job and <1> Queues
I0714 05:32:32.247440       1 enqueue.go:79] Try to enqueue PodGroup to 0 Queues
I0714 05:32:32.247514       1 allocate.go:64] Try to allocate resource to 0 Queues
I0714 05:32:32.247743       1 session.go:244] Close Session 2738a9ee-ec0d-4162-a83b-40babb81cd67
I0714 05:32:33.250662       1 cache.go:1363] There are <0> Jobs, <1> Queues and <5> Nodes in total for scheduling.
I0714 05:32:33.250835       1 session.go:190] Open Session 2d337104-13a0-4b55-9689-00082f61c053 with <0> Job and <1> Queues
I0714 05:32:33.252731       1 enqueue.go:79] Try to enqueue PodGroup to 0 Queues
I0714 05:32:33.252801       1 allocate.go:64] Try to allocate resource to 0 Queues
I0714 05:32:33.253013       1 session.go:244] Close Session 2d337104-13a0-4b55-9689-00082f61c053
I0714 05:32:34.255236       1 cache.go:1363] There are <0> Jobs, <1> Queues and <5> Nodes in total for scheduling.
I0714 05:32:34.255412       1 session.go:190] Open Session 3dbcb4d1-5528-4e49-bb87-9984227de592 with <0> Job and <1> Queues
I0714 05:32:34.257181       1 enqueue.go:79] Try to enqueue PodGroup to 0 Queues
I0714 05:32:34.257258       1 allocate.go:64] Try to allocate resource to 0 Queues
I0714 05:32:34.257487       1 session.go:244] Close Session 3dbcb4d1-5528-4e49-bb87-9984227de592
I0714 05:32:35.259324       1 cache.go:1363] There are <0> Jobs, <1> Queues and <5> Nodes in total for scheduling.
I0714 05:32:35.259478       1 session.go:190] Open Session af757d06-f9c6-4025-99ad-7df841bee0a9 with <0> Job and <1> Queues
I0714 05:32:35.261278       1 enqueue.go:79] Try to enqueue PodGroup to 0 Queues
I0714 05:32:35.261349       1 allocate.go:64] Try to allocate resource to 0 Queues
I0714 05:32:35.261546       1 session.go:244] Close Session af757d06-f9c6-4025-99ad-7df841bee0a9
I0714 05:32:36.275177       1 cache.go:1489] The metrics type is not set in the volcano scheduler configmap file. As a result, the CPU and memory load information of the node is not collected.
I0714 05:32:36.275329       1 cache.go:1363] There are <0> Jobs, <1> Queues and <5> Nodes in total for scheduling.
I0714 05:32:36.275545       1 session.go:190] Open Session 5abdfa37-ed0f-4879-b386-118644675882 with <0> Job and <1> Queues
I0714 05:32:36.278668       1 enqueue.go:79] Try to enqueue PodGroup to 0 Queues
I0714 05:32:36.278766       1 allocate.go:64] Try to allocate resource to 0 Queues
I0714 05:32:36.278990       1 session.go:244] Close Session 5abdfa37-ed0f-4879-b386-118644675882
I0714 05:32:37.281478       1 cache.go:1363] There are <0> Jobs, <1> Queues and <5> Nodes in total for scheduling.
I0714 05:32:37.281677       1 session.go:190] Open Session 19f6e981-f68c-4005-89fe-9c3926b2b361 with <0> Job and <1> Queues
I0714 05:32:37.283559       1 enqueue.go:79] Try to enqueue PodGroup to 0 Queues
I0714 05:32:37.283629       1 allocate.go:64] Try to allocate resource to 0 Queues
I0714 05:32:37.283852       1 session.go:244] Close Session 19f6e981-f68c-4005-89fe-9c3926b2b361
I0714 05:32:38.286628       1 cache.go:1363] There are <0> Jobs, <1> Queues and <5> Nodes in total for scheduling.
I0714 05:32:38.286779       1 session.go:190] Open Session 73d5e0c1-bbe4-4eba-b570-8f2c27205825 with <0> Job and <1> Queues
I0714 05:32:38.288572       1 enqueue.go:79] Try to enqueue PodGroup to 0 Queues
I0714 05:32:38.288642       1 allocate.go:64] Try to allocate resource to 0 Queues
I0714 05:32:38.288855       1 session.go:244] Close Session 73d5e0c1-bbe4-4eba-b570-8f2c27205825
I0714 05:32:39.291623       1 cache.go:1363] There are <0> Jobs, <1> Queues and <5> Nodes in total for scheduling.
I0714 05:32:39.291803       1 session.go:190] Open Session ad0403e4-585a-4c51-8eff-d7167d47471b with <0> Job and <1> Queues
I0714 05:32:39.293611       1 enqueue.go:79] Try to enqueue PodGroup to 0 Queues
I0714 05:32:39.293680       1 allocate.go:64] Try to allocate resource to 0 Queues
I0714 05:32:39.293896       1 session.go:244] Close Session ad0403e4-585a-4c51-8eff-d7167d47471b
I0714 05:32:40.297191       1 cache.go:1363] There are <0> Jobs, <1> Queues and <5> Nodes in total for scheduling.
I0714 05:32:40.297388       1 session.go:190] Open Session f349d7f8-dd79-4a61-9e39-a3874d2fa9b3 with <0> Job and <1> Queues
I0714 05:32:40.299258       1 enqueue.go:79] Try to enqueue PodGroup to 0 Queues
I0714 05:32:40.299326       1 allocate.go:64] Try to allocate resource to 0 Queues
I0714 05:32:40.299547       1 session.go:244] Close Session f349d7f8-dd79-4a61-9e39-a3874d2fa9b3
I0714 05:32:41.302165       1 cache.go:1363] There are <0> Jobs, <1> Queues and <5> Nodes in total for scheduling.
I0714 05:32:41.302343       1 session.go:190] Open Session 4b688315-e444-4dbe-a4b7-4ee7fd62c838 with <0> Job and <1> Queues
I0714 05:32:41.304115       1 enqueue.go:79] Try to enqueue PodGroup to 0 Queues
I0714 05:32:41.304180       1 allocate.go:64] Try to allocate resource to 0 Queues
I0714 05:32:41.304415       1 session.go:244] Close Session 4b688315-e444-4dbe-a4b7-4ee7fd62c838
I0714 05:32:42.307267       1 cache.go:1363] There are <0> Jobs, <1> Queues and <5> Nodes in total for scheduling.
I0714 05:32:42.307457       1 session.go:190] Open Session 0bfac0c2-fde6-4ad1-b5d3-6218b40044c1 with <0> Job and <1> Queues
I0714 05:32:42.309268       1 enqueue.go:79] Try to enqueue PodGroup to 0 Queues
I0714 05:32:42.309337       1 allocate.go:64] Try to allocate resource to 0 Queues
I0714 05:32:42.309561       1 session.go:244] Close Session 0bfac0c2-fde6-4ad1-b5d3-6218b40044c1
I0714 05:32:43.312249       1 cache.go:1363] There are <0> Jobs, <1> Queues and <5> Nodes in total for scheduling.
I0714 05:32:43.312454       1 session.go:190] Open Session 4b89493f-4dbc-4cd6-a618-db4ab569640e with <0> Job and <1> Queues
I0714 05:32:43.314259       1 enqueue.go:79] Try to enqueue PodGroup to 0 Queues
I0714 05:32:43.314327       1 allocate.go:64] Try to allocate resource to 0 Queues
I0714 05:32:43.314540       1 session.go:244] Close Session 4b89493f-4dbc-4cd6-a618-db4ab569640e
I0714 05:32:44.317054       1 cache.go:1363] There are <0> Jobs, <1> Queues and <5> Nodes in total for scheduling.
I0714 05:32:44.317232       1 session.go:190] Open Session 6b190385-61ac-4334-8587-59cfaa293783 with <0> Job and <1> Queues
I0714 05:32:44.318939       1 enqueue.go:79] Try to enqueue PodGroup to 0 Queues
I0714 05:32:44.319003       1 allocate.go:64] Try to allocate resource to 0 Queues
I0714 05:32:44.319221       1 session.go:244] Close Session 6b190385-61ac-4334-8587-59cfaa293783
I0714 05:32:45.322099       1 cache.go:1363] There are <0> Jobs, <1> Queues and <5> Nodes in total for scheduling.
I0714 05:32:45.322263       1 session.go:190] Open Session a68d1b7a-ae47-4f48-9c8d-f731e818c842 with <0> Job and <1> Queues
I0714 05:32:45.323964       1 enqueue.go:79] Try to enqueue PodGroup to 0 Queues
I0714 05:32:45.324028       1 allocate.go:64] Try to allocate resource to 0 Queues
I0714 05:32:45.324249       1 session.go:244] Close Session a68d1b7a-ae47-4f48-9c8d-f731e818c842
I0714 05:32:46.326746       1 cache.go:1363] There are <0> Jobs, <1> Queues and <5> Nodes in total for scheduling.
I0714 05:32:46.326927       1 session.go:190] Open Session d757b2e0-6dfc-44fe-8cc2-4733553beb82 with <0> Job and <1> Queues
I0714 05:32:46.328769       1 enqueue.go:79] Try to enqueue PodGroup to 0 Queues
I0714 05:32:46.328848       1 allocate.go:64] Try to allocate resource to 0 Queues
I0714 05:32:46.329055       1 session.go:244] Close Session d757b2e0-6dfc-44fe-8cc2-4733553beb82
I0714 05:32:47.332056       1 cache.go:1363] There are <0> Jobs, <1> Queues and <5> Nodes in total for scheduling.
I0714 05:32:47.332234       1 session.go:190] Open Session b38411de-c833-4171-8d23-6aa8f07882d1 with <0> Job and <1> Queues
I0714 05:32:47.334070       1 enqueue.go:79] Try to enqueue PodGroup to 0 Queues
I0714 05:32:47.334145       1 allocate.go:64] Try to allocate resource to 0 Queues
I0714 05:32:47.334366       1 session.go:244] Close Session b38411de-c833-4171-8d23-6aa8f07882d1
I0714 05:32:48.337302       1 cache.go:1363] There are <0> Jobs, <1> Queues and <5> Nodes in total for scheduling.
I0714 05:32:48.337480       1 session.go:190] Open Session d0a8d4cd-b335-494c-aabc-c323d1905030 with <0> Job and <1> Queues
I0714 05:32:48.339189       1 enqueue.go:79] Try to enqueue PodGroup to 0 Queues
I0714 05:32:48.339259       1 allocate.go:64] Try to allocate resource to 0 Queues
I0714 05:32:48.339480       1 session.go:244] Close Session d0a8d4cd-b335-494c-aabc-c323d1905030
I0714 05:32:49.342598       1 cache.go:1363] There are <0> Jobs, <1> Queues and <5> Nodes in total for scheduling.
I0714 05:32:49.342777       1 session.go:190] Open Session 92194278-8075-4204-9a09-821ecc1e2e1d with <0> Job and <1> Queues
I0714 05:32:49.344548       1 enqueue.go:79] Try to enqueue PodGroup to 0 Queues
I0714 05:32:49.344612       1 allocate.go:64] Try to allocate resource to 0 Queues
I0714 05:32:49.344815       1 session.go:244] Close Session 92194278-8075-4204-9a09-821ecc1e2e1d
I0714 05:32:50.347660       1 cache.go:1363] There are <0> Jobs, <1> Queues and <5> Nodes in total for scheduling.
I0714 05:32:50.347832       1 session.go:190] Open Session 0f6a8fb6-0a04-43f5-8bcf-d12015e1b793 with <0> Job and <1> Queues
I0714 05:32:50.349562       1 enqueue.go:79] Try to enqueue PodGroup to 0 Queues
I0714 05:32:50.349636       1 allocate.go:64] Try to allocate resource to 0 Queues
I0714 05:32:50.349857       1 session.go:244] Close Session 0f6a8fb6-0a04-43f5-8bcf-d12015e1b793
I0714 05:32:51.351914       1 cache.go:1363] There are <0> Jobs, <1> Queues and <5> Nodes in total for scheduling.
I0714 05:32:51.352092       1 session.go:190] Open Session 72323df0-0a18-412e-bbfc-a46bd189b475 with <0> Job and <1> Queues
I0714 05:32:51.353958       1 enqueue.go:79] Try to enqueue PodGroup to 0 Queues
I0714 05:32:51.354032       1 allocate.go:64] Try to allocate resource to 0 Queues
I0714 05:32:51.354255       1 session.go:244] Close Session 72323df0-0a18-412e-bbfc-a46bd189b475
I0714 05:32:52.356857       1 cache.go:1363] There are <0> Jobs, <1> Queues and <5> Nodes in total for scheduling.
I0714 05:32:52.357002       1 session.go:190] Open Session ee36790b-2c69-497e-8e5d-7e6232597998 with <0> Job and <1> Queues
I0714 05:32:52.358581       1 enqueue.go:79] Try to enqueue PodGroup to 0 Queues
I0714 05:32:52.358649       1 allocate.go:64] Try to allocate resource to 0 Queues
I0714 05:32:52.358854       1 session.go:244] Close Session ee36790b-2c69-497e-8e5d-7e6232597998
I0714 05:32:53.361636       1 cache.go:1363] There are <0> Jobs, <1> Queues and <5> Nodes in total for scheduling.
I0714 05:32:53.361816       1 session.go:190] Open Session 88eb66cd-cc5d-4b36-9c8b-c5a6f3bcd84f with <0> Job and <1> Queues
I0714 05:32:53.363673       1 enqueue.go:79] Try to enqueue PodGroup to 0 Queues
I0714 05:32:53.363745       1 allocate.go:64] Try to allocate resource to 0 Queues
I0714 05:32:53.363970       1 session.go:244] Close Session 88eb66cd-cc5d-4b36-9c8b-c5a6f3bcd84f
I0714 05:32:54.366301       1 cache.go:1363] There are <0> Jobs, <1> Queues and <5> Nodes in total for scheduling.
I0714 05:32:54.366480       1 session.go:190] Open Session f66868a3-b30c-422e-933a-21eccd53e2db with <0> Job and <1> Queues
I0714 05:32:54.368211       1 enqueue.go:79] Try to enqueue PodGroup to 0 Queues
I0714 05:32:54.368322       1 allocate.go:64] Try to allocate resource to 0 Queues
I0714 05:32:54.368570       1 session.go:244] Close Session f66868a3-b30c-422e-933a-21eccd53e2db
I0714 05:32:55.370924       1 cache.go:1363] There are <0> Jobs, <1> Queues and <5> Nodes in total for scheduling.
I0714 05:32:55.371091       1 session.go:190] Open Session 795266e7-7cb5-45a2-a78c-b86fdd550283 with <0> Job and <1> Queues
I0714 05:32:55.372949       1 enqueue.go:79] Try to enqueue PodGroup to 0 Queues
I0714 05:32:55.373023       1 allocate.go:64] Try to allocate resource to 0 Queues
I0714 05:32:55.373240       1 session.go:244] Close Session 795266e7-7cb5-45a2-a78c-b86fdd550283
I0714 05:32:56.375528       1 cache.go:1363] There are <0> Jobs, <1> Queues and <5> Nodes in total for scheduling.
I0714 05:32:56.375696       1 session.go:190] Open Session f5c96a1d-3e41-481a-a3ef-0236b11486d8 with <0> Job and <1> Queues
I0714 05:32:56.377533       1 enqueue.go:79] Try to enqueue PodGroup to 0 Queues
I0714 05:32:56.377606       1 allocate.go:64] Try to allocate resource to 0 Queues
I0714 05:32:56.377830       1 session.go:244] Close Session f5c96a1d-3e41-481a-a3ef-0236b11486d8
I0714 05:32:57.380232       1 cache.go:1363] There are <0> Jobs, <1> Queues and <5> Nodes in total for scheduling.
I0714 05:32:57.380370       1 session.go:190] Open Session 3ced298e-a614-4ecc-bbc4-4480c97888fc with <0> Job and <1> Queues
I0714 05:32:57.381855       1 enqueue.go:79] Try to enqueue PodGroup to 0 Queues
I0714 05:32:57.381913       1 allocate.go:64] Try to allocate resource to 0 Queues
I0714 05:32:57.382108       1 session.go:244] Close Session 3ced298e-a614-4ecc-bbc4-4480c97888fc
I0714 05:32:58.384334       1 cache.go:1363] There are <0> Jobs, <1> Queues and <5> Nodes in total for scheduling.
I0714 05:32:58.384442       1 session.go:190] Open Session 5ddc0092-3597-4bd9-83e8-640c38ee1de6 with <0> Job and <1> Queues
I0714 05:32:58.385786       1 enqueue.go:79] Try to enqueue PodGroup to 0 Queues
I0714 05:32:58.385842       1 allocate.go:64] Try to allocate resource to 0 Queues
I0714 05:32:58.386018       1 session.go:244] Close Session 5ddc0092-3597-4bd9-83e8-640c38ee1de6
I0714 05:32:59.388485       1 cache.go:1363] There are <0> Jobs, <1> Queues and <5> Nodes in total for scheduling.
I0714 05:32:59.388653       1 session.go:190] Open Session ca7511ba-76d4-4139-89cb-766fbdec335c with <0> Job and <1> Queues
I0714 05:32:59.390344       1 enqueue.go:79] Try to enqueue PodGroup to 0 Queues
I0714 05:32:59.390419       1 allocate.go:64] Try to allocate resource to 0 Queues
I0714 05:32:59.390649       1 session.go:244] Close Session ca7511ba-76d4-4139-89cb-766fbdec335c
I0714 05:33:00.392795       1 cache.go:1363] There are <0> Jobs, <1> Queues and <5> Nodes in total for scheduling.
I0714 05:33:00.392938       1 session.go:190] Open Session a5a885ef-c1ef-4ff9-bd2a-4acbd2b20eb1 with <0> Job and <1> Queues
I0714 05:33:00.394559       1 enqueue.go:79] Try to enqueue PodGroup to 0 Queues
I0714 05:33:00.394624       1 allocate.go:64] Try to allocate resource to 0 Queues
I0714 05:33:00.394828       1 session.go:244] Close Session a5a885ef-c1ef-4ff9-bd2a-4acbd2b20eb1
I0714 05:33:01.397422       1 cache.go:1363] There are <0> Jobs, <1> Queues and <5> Nodes in total for scheduling.
I0714 05:33:01.397598       1 session.go:190] Open Session 8cc7fc45-704c-4264-aa03-58e972fb0a60 with <0> Job and <1> Queues
I0714 05:33:01.399298       1 enqueue.go:79] Try to enqueue PodGroup to 0 Queues
I0714 05:33:01.399372       1 allocate.go:64] Try to allocate resource to 0 Queues
I0714 05:33:01.399580       1 session.go:244] Close Session 8cc7fc45-704c-4264-aa03-58e972fb0a60
I0714 05:33:02.401979       1 cache.go:1363] There are <0> Jobs, <1> Queues and <5> Nodes in total for scheduling.
I0714 05:33:02.402138       1 session.go:190] Open Session 08791082-c091-4b56-8b6a-2bb7d2ab97ac with <0> Job and <1> Queues
I0714 05:33:02.403978       1 enqueue.go:79] Try to enqueue PodGroup to 0 Queues
I0714 05:33:02.404048       1 allocate.go:64] Try to allocate resource to 0 Queues
I0714 05:33:02.404250       1 session.go:244] Close Session 08791082-c091-4b56-8b6a-2bb7d2ab97ac
I0714 05:33:03.406463       1 cache.go:1363] There are <0> Jobs, <1> Queues and <5> Nodes in total for scheduling.
I0714 05:33:03.406643       1 session.go:190] Open Session 079475ee-1e06-4d02-8847-3437aa12b6a1 with <0> Job and <1> Queues
I0714 05:33:03.408459       1 enqueue.go:79] Try to enqueue PodGroup to 0 Queues
I0714 05:33:03.408539       1 allocate.go:64] Try to allocate resource to 0 Queues
I0714 05:33:03.408761       1 session.go:244] Close Session 079475ee-1e06-4d02-8847-3437aa12b6a1
I0714 05:33:04.411303       1 cache.go:1363] There are <0> Jobs, <1> Queues and <5> Nodes in total for scheduling.
I0714 05:33:04.411447       1 session.go:190] Open Session 1143c5cc-c797-4e6e-b48c-c7ba458399c5 with <0> Job and <1> Queues
I0714 05:33:04.413122       1 enqueue.go:79] Try to enqueue PodGroup to 0 Queues
I0714 05:33:04.413188       1 allocate.go:64] Try to allocate resource to 0 Queues
I0714 05:33:04.413402       1 session.go:244] Close Session 1143c5cc-c797-4e6e-b48c-c7ba458399c5
I0714 05:33:05.416220       1 cache.go:1363] There are <0> Jobs, <1> Queues and <5> Nodes in total for scheduling.
I0714 05:33:05.416412       1 session.go:190] Open Session 416ae8b4-e12c-46aa-aed4-87558a3210de with <0> Job and <1> Queues
I0714 05:33:05.418136       1 enqueue.go:79] Try to enqueue PodGroup to 0 Queues
I0714 05:33:05.418198       1 allocate.go:64] Try to allocate resource to 0 Queues
I0714 05:33:05.418400       1 session.go:244] Close Session 416ae8b4-e12c-46aa-aed4-87558a3210de
I0714 05:33:06.275763       1 cache.go:1489] The metrics type is not set in the volcano scheduler configmap file. As a result, the CPU and memory load information of the node is not collected.
I0714 05:33:06.420696       1 cache.go:1363] There are <0> Jobs, <1> Queues and <5> Nodes in total for scheduling.
I0714 05:33:06.420813       1 session.go:190] Open Session 0bc3273f-5071-4d0f-bbb1-cc858c5bedc7 with <0> Job and <1> Queues
I0714 05:33:06.422539       1 enqueue.go:79] Try to enqueue PodGroup to 0 Queues
I0714 05:33:06.422606       1 allocate.go:64] Try to allocate resource to 0 Queues
I0714 05:33:06.422831       1 session.go:244] Close Session 0bc3273f-5071-4d0f-bbb1-cc858c5bedc7
I0714 05:33:07.425068       1 cache.go:1363] There are <0> Jobs, <1> Queues and <5> Nodes in total for scheduling.
I0714 05:33:07.425253       1 session.go:190] Open Session 95d90ba6-77ff-411d-852a-10dadd25fbc6 with <0> Job and <1> Queues
I0714 05:33:07.427013       1 enqueue.go:79] Try to enqueue PodGroup to 0 Queues
I0714 05:33:07.427087       1 allocate.go:64] Try to allocate resource to 0 Queues
I0714 05:33:07.427417       1 session.go:244] Close Session 95d90ba6-77ff-411d-852a-10dadd25fbc6
I0714 05:33:08.430164       1 cache.go:1363] There are <0> Jobs, <1> Queues and <5> Nodes in total for scheduling.
I0714 05:33:08.430312       1 session.go:190] Open Session 0f7a82e6-f65b-4241-9792-6aa4bf92824a with <0> Job and <1> Queues
I0714 05:33:08.432054       1 enqueue.go:79] Try to enqueue PodGroup to 0 Queues
I0714 05:33:08.432126       1 allocate.go:64] Try to allocate resource to 0 Queues
I0714 05:33:08.432363       1 session.go:244] Close Session 0f7a82e6-f65b-4241-9792-6aa4bf92824a
I0714 05:33:09.434695       1 cache.go:1363] There are <0> Jobs, <1> Queues and <5> Nodes in total for scheduling.
I0714 05:33:09.434856       1 session.go:190] Open Session ed32158e-0c69-4520-831a-06f2c6876e29 with <0> Job and <1> Queues
I0714 05:33:09.436597       1 enqueue.go:79] Try to enqueue PodGroup to 0 Queues
I0714 05:33:09.436666       1 allocate.go:64] Try to allocate resource to 0 Queues
I0714 05:33:09.436870       1 session.go:244] Close Session ed32158e-0c69-4520-831a-06f2c6876e29
I0714 05:33:10.439517       1 cache.go:1363] There are <0> Jobs, <1> Queues and <5> Nodes in total for scheduling.
I0714 05:33:10.439687       1 session.go:190] Open Session 855a8637-4eb6-4d88-a440-bc51db603b0c with <0> Job and <1> Queues
I0714 05:33:10.441460       1 enqueue.go:79] Try to enqueue PodGroup to 0 Queues
I0714 05:33:10.441533       1 allocate.go:64] Try to allocate resource to 0 Queues
I0714 05:33:10.441757       1 session.go:244] Close Session 855a8637-4eb6-4d88-a440-bc51db603b0c
I0714 05:33:11.444031       1 cache.go:1363] There are <0> Jobs, <1> Queues and <5> Nodes in total for scheduling.
I0714 05:33:11.444210       1 session.go:190] Open Session 14b75223-d42e-4497-b540-9cad0ef0ac61 with <0> Job and <1> Queues
I0714 05:33:11.445987       1 enqueue.go:79] Try to enqueue PodGroup to 0 Queues
I0714 05:33:11.446059       1 allocate.go:64] Try to allocate resource to 0 Queues
I0714 05:33:11.446301       1 session.go:244] Close Session 14b75223-d42e-4497-b540-9cad0ef0ac61
I0714 05:33:12.448947       1 cache.go:1363] There are <0> Jobs, <1> Queues and <5> Nodes in total for scheduling.
I0714 05:33:12.449118       1 session.go:190] Open Session 525a5384-aed3-4d0e-a9b1-cea154b9ff95 with <0> Job and <1> Queues
I0714 05:33:12.450703       1 enqueue.go:79] Try to enqueue PodGroup to 0 Queues
I0714 05:33:12.450775       1 allocate.go:64] Try to allocate resource to 0 Queues
I0714 05:33:12.450994       1 session.go:244] Close Session 525a5384-aed3-4d0e-a9b1-cea154b9ff95
I0714 05:33:13.453773       1 cache.go:1363] There are <0> Jobs, <1> Queues and <5> Nodes in total for scheduling.
I0714 05:33:13.453941       1 session.go:190] Open Session ad0c2ff1-6a16-4299-9e57-27e00e145c57 with <0> Job and <1> Queues
I0714 05:33:13.455691       1 enqueue.go:79] Try to enqueue PodGroup to 0 Queues
I0714 05:33:13.455762       1 allocate.go:64] Try to allocate resource to 0 Queues
I0714 05:33:13.455986       1 session.go:244] Close Session ad0c2ff1-6a16-4299-9e57-27e00e145c57
I0714 05:33:14.458721       1 cache.go:1363] There are <0> Jobs, <1> Queues and <5> Nodes in total for scheduling.
I0714 05:33:14.458888       1 session.go:190] Open Session 682a8a0d-ec67-4567-adaf-579769c534c5 with <0> Job and <1> Queues
I0714 05:33:14.460626       1 enqueue.go:79] Try to enqueue PodGroup to 0 Queues
I0714 05:33:14.460696       1 allocate.go:64] Try to allocate resource to 0 Queues
I0714 05:33:14.460905       1 session.go:244] Close Session 682a8a0d-ec67-4567-adaf-579769c534c5
I0714 05:33:15.463331       1 cache.go:1363] There are <0> Jobs, <1> Queues and <5> Nodes in total for scheduling.
I0714 05:33:15.463488       1 session.go:190] Open Session e08f4a27-25cf-4bec-bfa4-d61f97be7984 with <0> Job and <1> Queues
I0714 05:33:15.465178       1 enqueue.go:79] Try to enqueue PodGroup to 0 Queues
I0714 05:33:15.465246       1 allocate.go:64] Try to allocate resource to 0 Queues
I0714 05:33:15.465446       1 session.go:244] Close Session e08f4a27-25cf-4bec-bfa4-d61f97be7984
I0714 05:33:16.467430       1 cache.go:1363] There are <0> Jobs, <1> Queues and <5> Nodes in total for scheduling.
I0714 05:33:16.467594       1 session.go:190] Open Session 175fd0c0-e4f0-4f6c-b900-de9df476ccf5 with <0> Job and <1> Queues
I0714 05:33:16.469346       1 enqueue.go:79] Try to enqueue PodGroup to 0 Queues
I0714 05:33:16.469430       1 allocate.go:64] Try to allocate resource to 0 Queues
I0714 05:33:16.469650       1 session.go:244] Close Session 175fd0c0-e4f0-4f6c-b900-de9df476ccf5
I0714 05:33:17.472441       1 cache.go:1363] There are <0> Jobs, <1> Queues and <5> Nodes in total for scheduling.
I0714 05:33:17.472609       1 session.go:190] Open Session 8cfc2723-c9de-48a1-bf05-b5f6960da52d with <0> Job and <1> Queues
I0714 05:33:17.474345       1 enqueue.go:79] Try to enqueue PodGroup to 0 Queues
I0714 05:33:17.474417       1 allocate.go:64] Try to allocate resource to 0 Queues
I0714 05:33:17.474647       1 session.go:244] Close Session 8cfc2723-c9de-48a1-bf05-b5f6960da52d
I0714 05:33:18.477342       1 cache.go:1363] There are <0> Jobs, <1> Queues and <5> Nodes in total for scheduling.
I0714 05:33:18.477507       1 session.go:190] Open Session a9634901-8b79-41db-a676-e118d20671c2 with <0> Job and <1> Queues
I0714 05:33:18.479217       1 enqueue.go:79] Try to enqueue PodGroup to 0 Queues
I0714 05:33:18.479282       1 allocate.go:64] Try to allocate resource to 0 Queues
I0714 05:33:18.479499       1 session.go:244] Close Session a9634901-8b79-41db-a676-e118d20671c2
I0714 05:33:19.481780       1 cache.go:1363] There are <0> Jobs, <1> Queues and <5> Nodes in total for scheduling.
I0714 05:33:19.481957       1 session.go:190] Open Session baf9ca3b-f188-46f7-b439-dde20730065c with <0> Job and <1> Queues
I0714 05:33:19.483722       1 enqueue.go:79] Try to enqueue PodGroup to 0 Queues
I0714 05:33:19.483780       1 allocate.go:64] Try to allocate resource to 0 Queues
I0714 05:33:19.483956       1 session.go:244] Close Session baf9ca3b-f188-46f7-b439-dde20730065c
I0714 05:33:20.486207       1 cache.go:1363] There are <0> Jobs, <1> Queues and <5> Nodes in total for scheduling.
I0714 05:33:20.486379       1 session.go:190] Open Session ac74a729-7ce4-496e-98b6-e6076cdc6388 with <0> Job and <1> Queues
I0714 05:33:20.488074       1 enqueue.go:79] Try to enqueue PodGroup to 0 Queues
I0714 05:33:20.488150       1 allocate.go:64] Try to allocate resource to 0 Queues
I0714 05:33:20.488406       1 session.go:244] Close Session ac74a729-7ce4-496e-98b6-e6076cdc6388
I0714 05:33:21.490720       1 cache.go:1363] There are <0> Jobs, <1> Queues and <5> Nodes in total for scheduling.
I0714 05:33:21.490897       1 session.go:190] Open Session c912d2b2-562c-4cff-bfee-0a7d9e631f9f with <0> Job and <1> Queues
I0714 05:33:21.492699       1 enqueue.go:79] Try to enqueue PodGroup to 0 Queues
I0714 05:33:21.492775       1 allocate.go:64] Try to allocate resource to 0 Queues
I0714 05:33:21.493027       1 session.go:244] Close Session c912d2b2-562c-4cff-bfee-0a7d9e631f9f
I0714 05:33:22.495729       1 cache.go:1363] There are <0> Jobs, <1> Queues and <5> Nodes in total for scheduling.
I0714 05:33:22.495907       1 session.go:190] Open Session 9838f937-baf5-4a52-94a4-29d9c6c3cd89 with <0> Job and <1> Queues
I0714 05:33:22.497651       1 enqueue.go:79] Try to enqueue PodGroup to 0 Queues
I0714 05:33:22.497727       1 allocate.go:64] Try to allocate resource to 0 Queues
I0714 05:33:22.497950       1 session.go:244] Close Session 9838f937-baf5-4a52-94a4-29d9c6c3cd89
I0714 05:33:23.500675       1 cache.go:1363] There are <0> Jobs, <1> Queues and <5> Nodes in total for scheduling.
I0714 05:33:23.500848       1 session.go:190] Open Session d1b2860a-390f-48dd-a8de-c093284c2c04 with <0> Job and <1> Queues
I0714 05:33:23.502668       1 enqueue.go:79] Try to enqueue PodGroup to 0 Queues
I0714 05:33:23.502735       1 allocate.go:64] Try to allocate resource to 0 Queues
I0714 05:33:23.502939       1 session.go:244] Close Session d1b2860a-390f-48dd-a8de-c093284c2c04
I0714 05:33:24.505808       1 cache.go:1363] There are <0> Jobs, <1> Queues and <5> Nodes in total for scheduling.
I0714 05:33:24.505981       1 session.go:190] Open Session a079fe13-9e74-4801-9b45-99057bf0620f with <0> Job and <1> Queues
I0714 05:33:24.507701       1 enqueue.go:79] Try to enqueue PodGroup to 0 Queues
I0714 05:33:24.507767       1 allocate.go:64] Try to allocate resource to 0 Queues
I0714 05:33:24.508003       1 session.go:244] Close Session a079fe13-9e74-4801-9b45-99057bf0620f
I0714 05:33:25.510477       1 cache.go:1363] There are <0> Jobs, <1> Queues and <5> Nodes in total for scheduling.
I0714 05:33:25.510644       1 session.go:190] Open Session 3fea9f97-4181-4abf-af75-ad9bd215b4e3 with <0> Job and <1> Queues
I0714 05:33:25.512360       1 enqueue.go:79] Try to enqueue PodGroup to 0 Queues
I0714 05:33:25.512433       1 allocate.go:64] Try to allocate resource to 0 Queues
I0714 05:33:25.512632       1 session.go:244] Close Session 3fea9f97-4181-4abf-af75-ad9bd215b4e3
I0714 05:33:26.515554       1 cache.go:1363] There are <0> Jobs, <1> Queues and <5> Nodes in total for scheduling.
I0714 05:33:26.515722       1 session.go:190] Open Session 963c2c76-5385-4625-82eb-64c5e98a8025 with <0> Job and <1> Queues
I0714 05:33:26.517546       1 enqueue.go:79] Try to enqueue PodGroup to 0 Queues
I0714 05:33:26.517621       1 allocate.go:64] Try to allocate resource to 0 Queues
I0714 05:33:26.517839       1 session.go:244] Close Session 963c2c76-5385-4625-82eb-64c5e98a8025
I0714 05:33:27.519829       1 cache.go:1363] There are <0> Jobs, <1> Queues and <5> Nodes in total for scheduling.
I0714 05:33:27.520000       1 session.go:190] Open Session d2947a9b-3169-4371-bc6c-bbc3477ce199 with <0> Job and <1> Queues
I0714 05:33:27.521866       1 enqueue.go:79] Try to enqueue PodGroup to 0 Queues
I0714 05:33:27.521941       1 allocate.go:64] Try to allocate resource to 0 Queues
I0714 05:33:27.522173       1 session.go:244] Close Session d2947a9b-3169-4371-bc6c-bbc3477ce199
I0714 05:33:28.527103       1 cache.go:1363] There are <0> Jobs, <1> Queues and <5> Nodes in total for scheduling.
I0714 05:33:28.527371       1 session.go:190] Open Session 59769414-540c-4b11-a94d-c701243026b7 with <0> Job and <1> Queues
I0714 05:33:28.529257       1 enqueue.go:79] Try to enqueue PodGroup to 0 Queues
I0714 05:33:28.529338       1 allocate.go:64] Try to allocate resource to 0 Queues
I0714 05:33:28.529589       1 session.go:244] Close Session 59769414-540c-4b11-a94d-c701243026b7
I0714 05:33:29.532059       1 cache.go:1363] There are <0> Jobs, <1> Queues and <5> Nodes in total for scheduling.
I0714 05:33:29.532246       1 session.go:190] Open Session 3af82c0a-f3ec-499d-9e3c-935727a4ed85 with <0> Job and <1> Queues
I0714 05:33:29.534099       1 enqueue.go:79] Try to enqueue PodGroup to 0 Queues
I0714 05:33:29.534171       1 allocate.go:64] Try to allocate resource to 0 Queues
I0714 05:33:29.534395       1 session.go:244] Close Session 3af82c0a-f3ec-499d-9e3c-935727a4ed85
I0714 05:33:30.536672       1 cache.go:1363] There are <0> Jobs, <1> Queues and <5> Nodes in total for scheduling.
I0714 05:33:30.536844       1 session.go:190] Open Session 284ff9e7-c71a-484b-8fa8-d48c5f039e7f with <0> Job and <1> Queues
I0714 05:33:30.538736       1 enqueue.go:79] Try to enqueue PodGroup to 0 Queues
I0714 05:33:30.538810       1 allocate.go:64] Try to allocate resource to 0 Queues
I0714 05:33:30.539012       1 session.go:244] Close Session 284ff9e7-c71a-484b-8fa8-d48c5f039e7f
I0714 05:33:31.541284       1 cache.go:1363] There are <0> Jobs, <1> Queues and <5> Nodes in total for scheduling.
I0714 05:33:31.541450       1 session.go:190] Open Session 55cbb0e6-b21e-459e-84c0-5e141502bb54 with <0> Job and <1> Queues
I0714 05:33:31.543234       1 enqueue.go:79] Try to enqueue PodGroup to 0 Queues
I0714 05:33:31.543308       1 allocate.go:64] Try to allocate resource to 0 Queues
I0714 05:33:31.543535       1 session.go:244] Close Session 55cbb0e6-b21e-459e-84c0-5e141502bb54
I0714 05:33:32.545827       1 cache.go:1363] There are <0> Jobs, <1> Queues and <5> Nodes in total for scheduling.
I0714 05:33:32.545988       1 session.go:190] Open Session 97fcad2d-12c2-4961-9887-91f06bac471c with <0> Job and <1> Queues
I0714 05:33:32.547683       1 enqueue.go:79] Try to enqueue PodGroup to 0 Queues
I0714 05:33:32.547755       1 allocate.go:64] Try to allocate resource to 0 Queues
I0714 05:33:32.547975       1 session.go:244] Close Session 97fcad2d-12c2-4961-9887-91f06bac471c
I0714 05:33:33.550240       1 cache.go:1363] There are <0> Jobs, <1> Queues and <5> Nodes in total for scheduling.
I0714 05:33:33.550402       1 session.go:190] Open Session 3665a160-a0f8-4d07-8318-ad6627fbddfc with <0> Job and <1> Queues
I0714 05:33:33.552208       1 enqueue.go:79] Try to enqueue PodGroup to 0 Queues
I0714 05:33:33.552279       1 allocate.go:64] Try to allocate resource to 0 Queues
I0714 05:33:33.552564       1 session.go:244] Close Session 3665a160-a0f8-4d07-8318-ad6627fbddfc
I0714 05:33:34.555185       1 cache.go:1363] There are <0> Jobs, <1> Queues and <5> Nodes in total for scheduling.
I0714 05:33:34.555344       1 session.go:190] Open Session 63a79e41-ae35-437e-9e16-5001a1d0f354 with <0> Job and <1> Queues
I0714 05:33:34.557079       1 enqueue.go:79] Try to enqueue PodGroup to 0 Queues
I0714 05:33:34.557150       1 allocate.go:64] Try to allocate resource to 0 Queues
I0714 05:33:34.557366       1 session.go:244] Close Session 63a79e41-ae35-437e-9e16-5001a1d0f354
I0714 05:33:35.560144       1 cache.go:1363] There are <0> Jobs, <1> Queues and <5> Nodes in total for scheduling.
I0714 05:33:35.560352       1 session.go:190] Open Session 79bb12a6-a69e-4efe-a509-9892eed0bf9c with <0> Job and <1> Queues
I0714 05:33:35.562222       1 enqueue.go:79] Try to enqueue PodGroup to 0 Queues
I0714 05:33:35.562294       1 allocate.go:64] Try to allocate resource to 0 Queues
I0714 05:33:35.562494       1 session.go:244] Close Session 79bb12a6-a69e-4efe-a509-9892eed0bf9c
I0714 05:33:36.276912       1 cache.go:1489] The metrics type is not set in the volcano scheduler configmap file. As a result, the CPU and memory load information of the node is not collected.
I0714 05:33:36.565577       1 cache.go:1363] There are <0> Jobs, <1> Queues and <5> Nodes in total for scheduling.
I0714 05:33:36.565740       1 session.go:190] Open Session e9e0e6cc-53cb-4104-a748-e2d1b03d283c with <0> Job and <1> Queues
I0714 05:33:36.567527       1 enqueue.go:79] Try to enqueue PodGroup to 0 Queues
I0714 05:33:36.567596       1 allocate.go:64] Try to allocate resource to 0 Queues
I0714 05:33:36.567836       1 session.go:244] Close Session e9e0e6cc-53cb-4104-a748-e2d1b03d283c
I0714 05:33:37.570271       1 cache.go:1363] There are <0> Jobs, <1> Queues and <5> Nodes in total for scheduling.
I0714 05:33:37.570438       1 session.go:190] Open Session e9f7493e-dc47-4b0d-95d3-136f2cc9003b with <0> Job and <1> Queues
I0714 05:33:37.572203       1 enqueue.go:79] Try to enqueue PodGroup to 0 Queues
I0714 05:33:37.572279       1 allocate.go:64] Try to allocate resource to 0 Queues
I0714 05:33:37.572564       1 session.go:244] Close Session e9f7493e-dc47-4b0d-95d3-136f2cc9003b
I0714 05:33:38.575509       1 cache.go:1363] There are <0> Jobs, <1> Queues and <5> Nodes in total for scheduling.
I0714 05:33:38.575681       1 session.go:190] Open Session c93eb6d5-f5e3-48f1-93f8-f869218c5567 with <0> Job and <1> Queues
I0714 05:33:38.577543       1 enqueue.go:79] Try to enqueue PodGroup to 0 Queues
I0714 05:33:38.577616       1 allocate.go:64] Try to allocate resource to 0 Queues
I0714 05:33:38.577863       1 session.go:244] Close Session c93eb6d5-f5e3-48f1-93f8-f869218c5567
I0714 05:33:39.579846       1 cache.go:1363] There are <0> Jobs, <1> Queues and <5> Nodes in total for scheduling.
I0714 05:33:39.580003       1 session.go:190] Open Session e30f68ba-23c7-42f0-b939-a5aa8773b612 with <0> Job and <1> Queues
I0714 05:33:39.581926       1 enqueue.go:79] Try to enqueue PodGroup to 0 Queues
I0714 05:33:39.581998       1 allocate.go:64] Try to allocate resource to 0 Queues
I0714 05:33:39.582221       1 session.go:244] Close Session e30f68ba-23c7-42f0-b939-a5aa8773b612
I0714 05:33:40.584611       1 cache.go:1363] There are <0> Jobs, <1> Queues and <5> Nodes in total for scheduling.
I0714 05:33:40.584801       1 session.go:190] Open Session 78036d8e-398a-49ed-b9f3-f3cb0b0b54e8 with <0> Job and <1> Queues
I0714 05:33:40.586449       1 enqueue.go:79] Try to enqueue PodGroup to 0 Queues
I0714 05:33:40.586512       1 allocate.go:64] Try to allocate resource to 0 Queues
I0714 05:33:40.586713       1 session.go:244] Close Session 78036d8e-398a-49ed-b9f3-f3cb0b0b54e8
I0714 05:33:41.589663       1 cache.go:1363] There are <0> Jobs, <1> Queues and <5> Nodes in total for scheduling.
I0714 05:33:41.589849       1 session.go:190] Open Session b7102c1b-805d-47a8-a6a7-2489da45fca9 with <0> Job and <1> Queues
I0714 05:33:41.591623       1 enqueue.go:79] Try to enqueue PodGroup to 0 Queues
I0714 05:33:41.591700       1 allocate.go:64] Try to allocate resource to 0 Queues
I0714 05:33:41.591934       1 session.go:244] Close Session b7102c1b-805d-47a8-a6a7-2489da45fca9
I0714 05:33:42.594278       1 cache.go:1363] There are <0> Jobs, <1> Queues and <5> Nodes in total for scheduling.
I0714 05:33:42.594449       1 session.go:190] Open Session 83bf0e53-673c-453e-b711-ea32e711bafa with <0> Job and <1> Queues
I0714 05:33:42.596260       1 enqueue.go:79] Try to enqueue PodGroup to 0 Queues
I0714 05:33:42.596392       1 allocate.go:64] Try to allocate resource to 0 Queues
I0714 05:33:42.596616       1 session.go:244] Close Session 83bf0e53-673c-453e-b711-ea32e711bafa
I0714 05:33:43.599559       1 cache.go:1363] There are <0> Jobs, <1> Queues and <5> Nodes in total for scheduling.
I0714 05:33:43.599745       1 session.go:190] Open Session faf09333-3858-49d6-9997-b38da442f70f with <0> Job and <1> Queues
I0714 05:33:43.601645       1 enqueue.go:79] Try to enqueue PodGroup to 0 Queues
I0714 05:33:43.601723       1 allocate.go:64] Try to allocate resource to 0 Queues
I0714 05:33:43.601928       1 session.go:244] Close Session faf09333-3858-49d6-9997-b38da442f70f
I0714 05:33:44.604801       1 cache.go:1363] There are <0> Jobs, <1> Queues and <5> Nodes in total for scheduling.
I0714 05:33:44.604983       1 session.go:190] Open Session 89b24c0b-5daa-4f96-99d7-e59094d22fe7 with <0> Job and <1> Queues
I0714 05:33:44.606713       1 enqueue.go:79] Try to enqueue PodGroup to 0 Queues
I0714 05:33:44.606781       1 allocate.go:64] Try to allocate resource to 0 Queues
I0714 05:33:44.607007       1 session.go:244] Close Session 89b24c0b-5daa-4f96-99d7-e59094d22fe7
I0714 05:33:45.609267       1 cache.go:1363] There are <0> Jobs, <1> Queues and <5> Nodes in total for scheduling.
I0714 05:33:45.609390       1 session.go:190] Open Session faa08007-233f-4136-a440-9c20e0018e52 with <0> Job and <1> Queues
I0714 05:33:45.610823       1 enqueue.go:79] Try to enqueue PodGroup to 0 Queues
I0714 05:33:45.610886       1 allocate.go:64] Try to allocate resource to 0 Queues
I0714 05:33:45.611059       1 session.go:244] Close Session faa08007-233f-4136-a440-9c20e0018e52
I0714 05:33:46.614074       1 cache.go:1363] There are <0> Jobs, <1> Queues and <5> Nodes in total for scheduling.
I0714 05:33:46.614245       1 session.go:190] Open Session 02cb28e8-6691-476c-8796-1199f5efd66e with <0> Job and <1> Queues
I0714 05:33:46.616009       1 enqueue.go:79] Try to enqueue PodGroup to 0 Queues
I0714 05:33:46.616075       1 allocate.go:64] Try to allocate resource to 0 Queues
I0714 05:33:46.616273       1 session.go:244] Close Session 02cb28e8-6691-476c-8796-1199f5efd66e
I0714 05:33:47.619222       1 cache.go:1363] There are <0> Jobs, <1> Queues and <5> Nodes in total for scheduling.
I0714 05:33:47.619376       1 session.go:190] Open Session 065115fc-95d1-4160-8620-a9a9c39c0908 with <0> Job and <1> Queues
I0714 05:33:47.621307       1 enqueue.go:79] Try to enqueue PodGroup to 0 Queues
I0714 05:33:47.621373       1 allocate.go:64] Try to allocate resource to 0 Queues
I0714 05:33:47.621577       1 session.go:244] Close Session 065115fc-95d1-4160-8620-a9a9c39c0908
I0714 05:33:48.624634       1 cache.go:1363] There are <0> Jobs, <1> Queues and <5> Nodes in total for scheduling.
I0714 05:33:48.624807       1 session.go:190] Open Session 3ba701b2-1cdd-46e1-a271-85ba98287f63 with <0> Job and <1> Queues
I0714 05:33:48.626619       1 enqueue.go:79] Try to enqueue PodGroup to 0 Queues
I0714 05:33:48.626688       1 allocate.go:64] Try to allocate resource to 0 Queues
I0714 05:33:48.626904       1 session.go:244] Close Session 3ba701b2-1cdd-46e1-a271-85ba98287f63
I0714 05:33:49.629072       1 cache.go:1363] There are <0> Jobs, <1> Queues and <5> Nodes in total for scheduling.
I0714 05:33:49.629237       1 session.go:190] Open Session 04e4851c-5291-4cd0-82e7-dec895b20521 with <0> Job and <1> Queues
I0714 05:33:49.630975       1 enqueue.go:79] Try to enqueue PodGroup to 0 Queues
I0714 05:33:49.631046       1 allocate.go:64] Try to allocate resource to 0 Queues
I0714 05:33:49.631260       1 session.go:244] Close Session 04e4851c-5291-4cd0-82e7-dec895b20521
I0714 05:33:50.633857       1 cache.go:1363] There are <0> Jobs, <1> Queues and <5> Nodes in total for scheduling.
I0714 05:33:50.634011       1 session.go:190] Open Session 9fc57f1b-fb88-4ef5-954a-1ee76f6f1570 with <0> Job and <1> Queues
I0714 05:33:50.635581       1 enqueue.go:79] Try to enqueue PodGroup to 0 Queues
I0714 05:33:50.635646       1 allocate.go:64] Try to allocate resource to 0 Queues
I0714 05:33:50.635841       1 session.go:244] Close Session 9fc57f1b-fb88-4ef5-954a-1ee76f6f1570
I0714 05:33:51.637996       1 cache.go:1363] There are <0> Jobs, <1> Queues and <5> Nodes in total for scheduling.
I0714 05:33:51.638181       1 session.go:190] Open Session 34b301b5-0312-40ed-bc16-ccf234ed3f03 with <0> Job and <1> Queues
I0714 05:33:51.639948       1 enqueue.go:79] Try to enqueue PodGroup to 0 Queues
I0714 05:33:51.640017       1 allocate.go:64] Try to allocate resource to 0 Queues
I0714 05:33:51.640253       1 session.go:244] Close Session 34b301b5-0312-40ed-bc16-ccf234ed3f03
I0714 05:33:52.642844       1 cache.go:1363] There are <0> Jobs, <1> Queues and <5> Nodes in total for scheduling.
I0714 05:33:52.643024       1 session.go:190] Open Session cc950940-b5a5-4290-81a2-2d88ad453609 with <0> Job and <1> Queues
I0714 05:33:52.644863       1 enqueue.go:79] Try to enqueue PodGroup to 0 Queues
I0714 05:33:52.644945       1 allocate.go:64] Try to allocate resource to 0 Queues
I0714 05:33:52.645164       1 session.go:244] Close Session cc950940-b5a5-4290-81a2-2d88ad453609
I0714 05:33:53.647359       1 cache.go:1363] There are <0> Jobs, <1> Queues and <5> Nodes in total for scheduling.
I0714 05:33:53.647518       1 session.go:190] Open Session 664f709a-082d-423a-9f34-a9994f44bdf1 with <0> Job and <1> Queues
I0714 05:33:53.649231       1 enqueue.go:79] Try to enqueue PodGroup to 0 Queues
I0714 05:33:53.649306       1 allocate.go:64] Try to allocate resource to 0 Queues
I0714 05:33:53.649511       1 session.go:244] Close Session 664f709a-082d-423a-9f34-a9994f44bdf1
I0714 05:33:54.652094       1 cache.go:1363] There are <0> Jobs, <1> Queues and <5> Nodes in total for scheduling.
I0714 05:33:54.652274       1 session.go:190] Open Session 629bdb67-cc56-4109-8de2-8e88146c6988 with <0> Job and <1> Queues
I0714 05:33:54.654051       1 enqueue.go:79] Try to enqueue PodGroup to 0 Queues
I0714 05:33:54.654118       1 allocate.go:64] Try to allocate resource to 0 Queues
I0714 05:33:54.654337       1 session.go:244] Close Session 629bdb67-cc56-4109-8de2-8e88146c6988
I0714 05:33:55.656676       1 cache.go:1363] There are <0> Jobs, <1> Queues and <5> Nodes in total for scheduling.
I0714 05:33:55.656836       1 session.go:190] Open Session a6692ccb-4923-4bcd-a7fc-47462c8028be with <0> Job and <1> Queues
I0714 05:33:55.658520       1 enqueue.go:79] Try to enqueue PodGroup to 0 Queues
I0714 05:33:55.658585       1 allocate.go:64] Try to allocate resource to 0 Queues
I0714 05:33:55.658771       1 session.go:244] Close Session a6692ccb-4923-4bcd-a7fc-47462c8028be
I0714 05:33:56.661287       1 cache.go:1363] There are <0> Jobs, <1> Queues and <5> Nodes in total for scheduling.
I0714 05:33:56.661455       1 session.go:190] Open Session 4c7a412e-b235-439f-8d56-8f4a113470f8 with <0> Job and <1> Queues
I0714 05:33:56.663240       1 enqueue.go:79] Try to enqueue PodGroup to 0 Queues
I0714 05:33:56.663308       1 allocate.go:64] Try to allocate resource to 0 Queues
I0714 05:33:56.663516       1 session.go:244] Close Session 4c7a412e-b235-439f-8d56-8f4a113470f8
I0714 05:33:57.666488       1 cache.go:1363] There are <0> Jobs, <1> Queues and <5> Nodes in total for scheduling.
I0714 05:33:57.666653       1 session.go:190] Open Session ad2f709f-4d22-4982-b518-a255eb9189f1 with <0> Job and <1> Queues
I0714 05:33:57.668547       1 enqueue.go:79] Try to enqueue PodGroup to 0 Queues
I0714 05:33:57.668618       1 allocate.go:64] Try to allocate resource to 0 Queues
I0714 05:33:57.668848       1 session.go:244] Close Session ad2f709f-4d22-4982-b518-a255eb9189f1
I0714 05:33:58.671373       1 cache.go:1363] There are <0> Jobs, <1> Queues and <5> Nodes in total for scheduling.
I0714 05:33:58.671522       1 session.go:190] Open Session 9d9f272c-8f86-4240-98ac-016c5876d5fc with <0> Job and <1> Queues
I0714 05:33:58.673137       1 enqueue.go:79] Try to enqueue PodGroup to 0 Queues
I0714 05:33:58.673214       1 allocate.go:64] Try to allocate resource to 0 Queues
I0714 05:33:58.673427       1 session.go:244] Close Session 9d9f272c-8f86-4240-98ac-016c5876d5fc
I0714 05:33:59.675636       1 cache.go:1363] There are <0> Jobs, <1> Queues and <5> Nodes in total for scheduling.
I0714 05:33:59.675788       1 session.go:190] Open Session 9362339f-e2f6-4b7f-830a-6fbb1e73722d with <0> Job and <1> Queues
I0714 05:33:59.677446       1 enqueue.go:79] Try to enqueue PodGroup to 0 Queues
I0714 05:33:59.677514       1 allocate.go:64] Try to allocate resource to 0 Queues
I0714 05:33:59.677724       1 session.go:244] Close Session 9362339f-e2f6-4b7f-830a-6fbb1e73722d
I0714 05:34:00.679706       1 cache.go:1363] There are <0> Jobs, <1> Queues and <5> Nodes in total for scheduling.
I0714 05:34:00.679868       1 session.go:190] Open Session 6cf726ee-aaa4-4ef6-ad1c-8e8777c6e26e with <0> Job and <1> Queues
I0714 05:34:00.681495       1 enqueue.go:79] Try to enqueue PodGroup to 0 Queues
I0714 05:34:00.681563       1 allocate.go:64] Try to allocate resource to 0 Queues
I0714 05:34:00.681776       1 session.go:244] Close Session 6cf726ee-aaa4-4ef6-ad1c-8e8777c6e26e
I0714 05:34:01.684244       1 cache.go:1363] There are <0> Jobs, <1> Queues and <5> Nodes in total for scheduling.
I0714 05:34:01.684478       1 session.go:190] Open Session 14e5388a-6c30-47e8-b65b-bd0ae90d2b0b with <0> Job and <1> Queues
I0714 05:34:01.686287       1 enqueue.go:79] Try to enqueue PodGroup to 0 Queues
I0714 05:34:01.686361       1 allocate.go:64] Try to allocate resource to 0 Queues
I0714 05:34:01.686582       1 session.go:244] Close Session 14e5388a-6c30-47e8-b65b-bd0ae90d2b0b
I0714 05:34:02.688908       1 cache.go:1363] There are <0> Jobs, <1> Queues and <5> Nodes in total for scheduling.
I0714 05:34:02.689062       1 session.go:190] Open Session 6f3cf824-fa7d-4ad0-83e8-4a1f67bd5ccf with <0> Job and <1> Queues
I0714 05:34:02.690654       1 enqueue.go:79] Try to enqueue PodGroup to 0 Queues
I0714 05:34:02.690720       1 allocate.go:64] Try to allocate resource to 0 Queues
I0714 05:34:02.690942       1 session.go:244] Close Session 6f3cf824-fa7d-4ad0-83e8-4a1f67bd5ccf
I0714 05:34:03.693284       1 cache.go:1363] There are <0> Jobs, <1> Queues and <5> Nodes in total for scheduling.
I0714 05:34:03.693446       1 session.go:190] Open Session 432ce78f-7894-44aa-891b-9914ada7641d with <0> Job and <1> Queues
I0714 05:34:03.695341       1 enqueue.go:79] Try to enqueue PodGroup to 0 Queues
I0714 05:34:03.695412       1 allocate.go:64] Try to allocate resource to 0 Queues
I0714 05:34:03.695637       1 session.go:244] Close Session 432ce78f-7894-44aa-891b-9914ada7641d
I0714 05:34:04.697738       1 cache.go:1363] There are <0> Jobs, <1> Queues and <5> Nodes in total for scheduling.
I0714 05:34:04.697900       1 session.go:190] Open Session 9203f6d0-2fc7-4e0f-950b-feaef8faa4c9 with <0> Job and <1> Queues
I0714 05:34:04.699590       1 enqueue.go:79] Try to enqueue PodGroup to 0 Queues
I0714 05:34:04.699653       1 allocate.go:64] Try to allocate resource to 0 Queues
I0714 05:34:04.699871       1 session.go:244] Close Session 9203f6d0-2fc7-4e0f-950b-feaef8faa4c9
I0714 05:34:05.702690       1 cache.go:1363] There are <0> Jobs, <1> Queues and <5> Nodes in total for scheduling.
I0714 05:34:05.702841       1 session.go:190] Open Session 5658fff2-8f4e-4d04-9c92-e847e423e14f with <0> Job and <1> Queues
I0714 05:34:05.704736       1 enqueue.go:79] Try to enqueue PodGroup to 0 Queues
I0714 05:34:05.704808       1 allocate.go:64] Try to allocate resource to 0 Queues
I0714 05:34:05.705030       1 session.go:244] Close Session 5658fff2-8f4e-4d04-9c92-e847e423e14f
I0714 05:34:06.277465       1 cache.go:1489] The metrics type is not set in the volcano scheduler configmap file. As a result, the CPU and memory load information of the node is not collected.
I0714 05:34:06.707917       1 cache.go:1363] There are <0> Jobs, <1> Queues and <5> Nodes in total for scheduling.
I0714 05:34:06.708117       1 session.go:190] Open Session a0af887d-c302-4dc1-aec1-7fb1cd6fff53 with <0> Job and <1> Queues
I0714 05:34:06.709943       1 enqueue.go:79] Try to enqueue PodGroup to 0 Queues
I0714 05:34:06.710017       1 allocate.go:64] Try to allocate resource to 0 Queues
I0714 05:34:06.710229       1 session.go:244] Close Session a0af887d-c302-4dc1-aec1-7fb1cd6fff53
I0714 05:34:07.712823       1 cache.go:1363] There are <0> Jobs, <1> Queues and <5> Nodes in total for scheduling.
I0714 05:34:07.712995       1 session.go:190] Open Session 9f990239-a1a2-45da-86fb-88798a76b80a with <0> Job and <1> Queues
I0714 05:34:07.714941       1 enqueue.go:79] Try to enqueue PodGroup to 0 Queues
I0714 05:34:07.715032       1 allocate.go:64] Try to allocate resource to 0 Queues
I0714 05:34:07.715249       1 session.go:244] Close Session 9f990239-a1a2-45da-86fb-88798a76b80a
I0714 05:34:08.717305       1 cache.go:1363] There are <0> Jobs, <1> Queues and <5> Nodes in total for scheduling.
I0714 05:34:08.717500       1 session.go:190] Open Session 426e35ea-784f-4b96-829d-176b150af564 with <0> Job and <1> Queues
I0714 05:34:08.719214       1 enqueue.go:79] Try to enqueue PodGroup to 0 Queues
I0714 05:34:08.719282       1 allocate.go:64] Try to allocate resource to 0 Queues
I0714 05:34:08.719506       1 session.go:244] Close Session 426e35ea-784f-4b96-829d-176b150af564
I0714 05:34:09.721596       1 cache.go:1363] There are <0> Jobs, <1> Queues and <5> Nodes in total for scheduling.
I0714 05:34:09.721765       1 session.go:190] Open Session 2c78e1d5-90a7-4d62-ab51-8f0b4b139f19 with <0> Job and <1> Queues
I0714 05:34:09.723441       1 enqueue.go:79] Try to enqueue PodGroup to 0 Queues
I0714 05:34:09.723511       1 allocate.go:64] Try to allocate resource to 0 Queues
I0714 05:34:09.723738       1 session.go:244] Close Session 2c78e1d5-90a7-4d62-ab51-8f0b4b139f19
I0714 05:34:10.726249       1 cache.go:1363] There are <0> Jobs, <1> Queues and <5> Nodes in total for scheduling.
I0714 05:34:10.726440       1 session.go:190] Open Session b878cfa4-7f25-4886-a0c2-776836293f1a with <0> Job and <1> Queues
I0714 05:34:10.728237       1 enqueue.go:79] Try to enqueue PodGroup to 0 Queues
I0714 05:34:10.728420       1 allocate.go:64] Try to allocate resource to 0 Queues
I0714 05:34:10.728651       1 session.go:244] Close Session b878cfa4-7f25-4886-a0c2-776836293f1a
I0714 05:34:11.731147       1 cache.go:1363] There are <0> Jobs, <1> Queues and <5> Nodes in total for scheduling.
I0714 05:34:11.731315       1 session.go:190] Open Session c869b0bb-ed3c-4480-b9d0-8e92411c6afc with <0> Job and <1> Queues
I0714 05:34:11.733066       1 enqueue.go:79] Try to enqueue PodGroup to 0 Queues
I0714 05:34:11.733140       1 allocate.go:64] Try to allocate resource to 0 Queues
I0714 05:34:11.733351       1 session.go:244] Close Session c869b0bb-ed3c-4480-b9d0-8e92411c6afc
I0714 05:34:12.735995       1 cache.go:1363] There are <0> Jobs, <1> Queues and <5> Nodes in total for scheduling.
I0714 05:34:12.736154       1 session.go:190] Open Session 4a55c4cc-bea3-42f1-af4c-1388f3a19b07 with <0> Job and <1> Queues
I0714 05:34:12.737884       1 enqueue.go:79] Try to enqueue PodGroup to 0 Queues
I0714 05:34:12.737960       1 allocate.go:64] Try to allocate resource to 0 Queues
I0714 05:34:12.738162       1 session.go:244] Close Session 4a55c4cc-bea3-42f1-af4c-1388f3a19b07
I0714 05:34:13.739944       1 cache.go:1363] There are <0> Jobs, <1> Queues and <5> Nodes in total for scheduling.
I0714 05:34:13.740105       1 session.go:190] Open Session b9dd4dc3-c635-4eac-b098-40df9f2d7dcc with <0> Job and <1> Queues
I0714 05:34:13.741861       1 enqueue.go:79] Try to enqueue PodGroup to 0 Queues
I0714 05:34:13.741933       1 allocate.go:64] Try to allocate resource to 0 Queues
I0714 05:34:13.742143       1 session.go:244] Close Session b9dd4dc3-c635-4eac-b098-40df9f2d7dcc
I0714 05:34:14.745099       1 cache.go:1363] There are <0> Jobs, <1> Queues and <5> Nodes in total for scheduling.
I0714 05:34:14.745271       1 session.go:190] Open Session 28b7b1aa-2d5d-419d-8423-003c0ceccbd6 with <0> Job and <1> Queues
I0714 05:34:14.747005       1 enqueue.go:79] Try to enqueue PodGroup to 0 Queues
I0714 05:34:14.747077       1 allocate.go:64] Try to allocate resource to 0 Queues
I0714 05:34:14.747297       1 session.go:244] Close Session 28b7b1aa-2d5d-419d-8423-003c0ceccbd6
I0714 05:34:15.749267       1 cache.go:1363] There are <0> Jobs, <1> Queues and <5> Nodes in total for scheduling.
I0714 05:34:15.749413       1 session.go:190] Open Session 21dee6d7-485f-4ed3-9044-0c5ececa3340 with <0> Job and <1> Queues
I0714 05:34:15.751146       1 enqueue.go:79] Try to enqueue PodGroup to 0 Queues
I0714 05:34:15.751213       1 allocate.go:64] Try to allocate resource to 0 Queues
I0714 05:34:15.751419       1 session.go:244] Close Session 21dee6d7-485f-4ed3-9044-0c5ececa3340
I0714 05:34:16.753618       1 cache.go:1363] There are <0> Jobs, <1> Queues and <5> Nodes in total for scheduling.
I0714 05:34:16.753797       1 session.go:190] Open Session 3659b421-0418-4b38-a052-f1da889940c6 with <0> Job and <1> Queues
I0714 05:34:16.755698       1 enqueue.go:79] Try to enqueue PodGroup to 0 Queues
I0714 05:34:16.755777       1 allocate.go:64] Try to allocate resource to 0 Queues
I0714 05:34:16.756021       1 session.go:244] Close Session 3659b421-0418-4b38-a052-f1da889940c6
I0714 05:34:17.758868       1 cache.go:1363] There are <0> Jobs, <1> Queues and <5> Nodes in total for scheduling.
I0714 05:34:17.759036       1 session.go:190] Open Session a1ec52ae-ebc6-4c02-a6be-a1e944a3fe62 with <0> Job and <1> Queues
I0714 05:34:17.760871       1 enqueue.go:79] Try to enqueue PodGroup to 0 Queues
I0714 05:34:17.760944       1 allocate.go:64] Try to allocate resource to 0 Queues
I0714 05:34:17.761164       1 session.go:244] Close Session a1ec52ae-ebc6-4c02-a6be-a1e944a3fe62
I0714 05:34:18.764029       1 cache.go:1363] There are <0> Jobs, <1> Queues and <5> Nodes in total for scheduling.
I0714 05:34:18.764184       1 session.go:190] Open Session 4695284d-b174-4421-8207-41cd3a5864c9 with <0> Job and <1> Queues
I0714 05:34:18.765886       1 enqueue.go:79] Try to enqueue PodGroup to 0 Queues
I0714 05:34:18.765954       1 allocate.go:64] Try to allocate resource to 0 Queues
I0714 05:34:18.766159       1 session.go:244] Close Session 4695284d-b174-4421-8207-41cd3a5864c9
I0714 05:34:19.768224       1 cache.go:1363] There are <0> Jobs, <1> Queues and <5> Nodes in total for scheduling.
I0714 05:34:19.768434       1 session.go:190] Open Session f836ca5a-75f4-4da1-81c2-7276041d5033 with <0> Job and <1> Queues
I0714 05:34:19.770348       1 enqueue.go:79] Try to enqueue PodGroup to 0 Queues
I0714 05:34:19.770417       1 allocate.go:64] Try to allocate resource to 0 Queues
I0714 05:34:19.770640       1 session.go:244] Close Session f836ca5a-75f4-4da1-81c2-7276041d5033
I0714 05:34:20.773094       1 cache.go:1363] There are <0> Jobs, <1> Queues and <5> Nodes in total for scheduling.
I0714 05:34:20.773264       1 session.go:190] Open Session ba6065d2-bbfa-46d1-a88d-a98885e1ab0b with <0> Job and <1> Queues
I0714 05:34:20.775036       1 enqueue.go:79] Try to enqueue PodGroup to 0 Queues
I0714 05:34:20.775111       1 allocate.go:64] Try to allocate resource to 0 Queues
I0714 05:34:20.775307       1 session.go:244] Close Session ba6065d2-bbfa-46d1-a88d-a98885e1ab0b
I0714 05:34:21.777720       1 cache.go:1363] There are <0> Jobs, <1> Queues and <5> Nodes in total for scheduling.
I0714 05:34:21.777915       1 session.go:190] Open Session bde6a2f4-7628-40e2-8d84-e9b947c81d31 with <0> Job and <1> Queues
I0714 05:34:21.782537       1 enqueue.go:79] Try to enqueue PodGroup to 0 Queues
I0714 05:34:21.783199       1 allocate.go:64] Try to allocate resource to 0 Queues
I0714 05:34:21.783589       1 session.go:244] Close Session bde6a2f4-7628-40e2-8d84-e9b947c81d31
I0714 05:34:22.786199       1 cache.go:1363] There are <0> Jobs, <1> Queues and <5> Nodes in total for scheduling.
I0714 05:34:22.786401       1 session.go:190] Open Session 5fb5aa9a-64f0-4536-b57f-d71421aa1977 with <0> Job and <1> Queues
I0714 05:34:22.788200       1 enqueue.go:79] Try to enqueue PodGroup to 0 Queues
I0714 05:34:22.788267       1 allocate.go:64] Try to allocate resource to 0 Queues
I0714 05:34:22.788561       1 session.go:244] Close Session 5fb5aa9a-64f0-4536-b57f-d71421aa1977
I0714 05:34:23.791063       1 cache.go:1363] There are <0> Jobs, <1> Queues and <5> Nodes in total for scheduling.
I0714 05:34:23.791249       1 session.go:190] Open Session 1d029199-7211-4002-999d-af132a366be4 with <0> Job and <1> Queues
I0714 05:34:23.793058       1 enqueue.go:79] Try to enqueue PodGroup to 0 Queues
I0714 05:34:23.793129       1 allocate.go:64] Try to allocate resource to 0 Queues
I0714 05:34:23.793367       1 session.go:244] Close Session 1d029199-7211-4002-999d-af132a366be4
I0714 05:34:24.795827       1 cache.go:1363] There are <0> Jobs, <1> Queues and <5> Nodes in total for scheduling.
I0714 05:34:24.796037       1 session.go:190] Open Session c4758bb1-ac41-435a-a990-72890852fab8 with <0> Job and <1> Queues
I0714 05:34:24.797846       1 enqueue.go:79] Try to enqueue PodGroup to 0 Queues
I0714 05:34:24.797915       1 allocate.go:64] Try to allocate resource to 0 Queues
I0714 05:34:24.798130       1 session.go:244] Close Session c4758bb1-ac41-435a-a990-72890852fab8
I0714 05:34:25.800246       1 cache.go:1363] There are <0> Jobs, <1> Queues and <5> Nodes in total for scheduling.
I0714 05:34:25.800457       1 session.go:190] Open Session 4f67cf6b-1f9e-44fa-aa7b-d0911a94bb1b with <0> Job and <1> Queues
I0714 05:34:25.802162       1 enqueue.go:79] Try to enqueue PodGroup to 0 Queues
I0714 05:34:25.802221       1 allocate.go:64] Try to allocate resource to 0 Queues
I0714 05:34:25.802426       1 session.go:244] Close Session 4f67cf6b-1f9e-44fa-aa7b-d0911a94bb1b
I0714 05:34:26.805408       1 cache.go:1363] There are <0> Jobs, <1> Queues and <5> Nodes in total for scheduling.
I0714 05:34:26.805572       1 session.go:190] Open Session 82a44af5-8b9f-44ed-ab08-0181abfe10cf with <0> Job and <1> Queues
I0714 05:34:26.807319       1 enqueue.go:79] Try to enqueue PodGroup to 0 Queues
I0714 05:34:26.807400       1 allocate.go:64] Try to allocate resource to 0 Queues
I0714 05:34:26.807627       1 session.go:244] Close Session 82a44af5-8b9f-44ed-ab08-0181abfe10cf
I0714 05:34:27.809949       1 cache.go:1363] There are <0> Jobs, <1> Queues and <5> Nodes in total for scheduling.
I0714 05:34:27.810129       1 session.go:190] Open Session 29a6c644-ece2-4e27-b748-dc66f4ece2dc with <0> Job and <1> Queues
I0714 05:34:27.811845       1 enqueue.go:79] Try to enqueue PodGroup to 0 Queues
I0714 05:34:27.811909       1 allocate.go:64] Try to allocate resource to 0 Queues
I0714 05:34:27.812115       1 session.go:244] Close Session 29a6c644-ece2-4e27-b748-dc66f4ece2dc
I0714 05:34:28.814914       1 cache.go:1363] There are <0> Jobs, <1> Queues and <5> Nodes in total for scheduling.
I0714 05:34:28.815108       1 session.go:190] Open Session d7ededd4-2242-4ac5-b8f4-3466e3ed1b34 with <0> Job and <1> Queues
I0714 05:34:28.816957       1 enqueue.go:79] Try to enqueue PodGroup to 0 Queues
I0714 05:34:28.817028       1 allocate.go:64] Try to allocate resource to 0 Queues
I0714 05:34:28.817252       1 session.go:244] Close Session d7ededd4-2242-4ac5-b8f4-3466e3ed1b34
I0714 05:34:29.819695       1 cache.go:1363] There are <0> Jobs, <1> Queues and <5> Nodes in total for scheduling.
I0714 05:34:29.819864       1 session.go:190] Open Session dfe24229-2e20-462d-951d-4004acb5a3ff with <0> Job and <1> Queues
I0714 05:34:29.821596       1 enqueue.go:79] Try to enqueue PodGroup to 0 Queues
I0714 05:34:29.821665       1 allocate.go:64] Try to allocate resource to 0 Queues
I0714 05:34:29.821859       1 session.go:244] Close Session dfe24229-2e20-462d-951d-4004acb5a3ff
I0714 05:34:30.824589       1 cache.go:1363] There are <0> Jobs, <1> Queues and <5> Nodes in total for scheduling.
I0714 05:34:30.824745       1 session.go:190] Open Session a05bc38c-aa76-43de-9107-6e88aae7d787 with <0> Job and <1> Queues
I0714 05:34:30.826078       1 enqueue.go:79] Try to enqueue PodGroup to 0 Queues
I0714 05:34:30.826116       1 allocate.go:64] Try to allocate resource to 0 Queues
I0714 05:34:30.826212       1 session.go:244] Close Session a05bc38c-aa76-43de-9107-6e88aae7d787
I0714 05:34:31.828537       1 cache.go:1363] There are <0> Jobs, <1> Queues and <5> Nodes in total for scheduling.
I0714 05:34:31.828699       1 session.go:190] Open Session 2026ada4-264b-414f-b95f-7c62dddec37e with <0> Job and <1> Queues
I0714 05:34:31.830469       1 enqueue.go:79] Try to enqueue PodGroup to 0 Queues
I0714 05:34:31.830538       1 allocate.go:64] Try to allocate resource to 0 Queues
I0714 05:34:31.830780       1 session.go:244] Close Session 2026ada4-264b-414f-b95f-7c62dddec37e
I0714 05:34:32.832902       1 cache.go:1363] There are <0> Jobs, <1> Queues and <5> Nodes in total for scheduling.
I0714 05:34:32.833098       1 session.go:190] Open Session 4ab1d1e1-54c1-49ea-9b48-1e24e428edba with <0> Job and <1> Queues
I0714 05:34:32.834958       1 enqueue.go:79] Try to enqueue PodGroup to 0 Queues
I0714 05:34:32.835029       1 allocate.go:64] Try to allocate resource to 0 Queues
I0714 05:34:32.835256       1 session.go:244] Close Session 4ab1d1e1-54c1-49ea-9b48-1e24e428edba
I0714 05:34:33.837969       1 cache.go:1363] There are <0> Jobs, <1> Queues and <5> Nodes in total for scheduling.
I0714 05:34:33.838178       1 session.go:190] Open Session 5fc61e4f-2951-49a3-9de9-062f82a19479 with <0> Job and <1> Queues
I0714 05:34:33.839921       1 enqueue.go:79] Try to enqueue PodGroup to 0 Queues
I0714 05:34:33.839991       1 allocate.go:64] Try to allocate resource to 0 Queues
I0714 05:34:33.840223       1 session.go:244] Close Session 5fc61e4f-2951-49a3-9de9-062f82a19479
I0714 05:34:34.842871       1 cache.go:1363] There are <0> Jobs, <1> Queues and <5> Nodes in total for scheduling.
I0714 05:34:34.843041       1 session.go:190] Open Session e9d6c80e-58db-45fb-8afc-30002a429ed9 with <0> Job and <1> Queues
I0714 05:34:34.844780       1 enqueue.go:79] Try to enqueue PodGroup to 0 Queues
I0714 05:34:34.844851       1 allocate.go:64] Try to allocate resource to 0 Queues
I0714 05:34:34.845069       1 session.go:244] Close Session e9d6c80e-58db-45fb-8afc-30002a429ed9
I0714 05:34:35.847091       1 cache.go:1363] There are <0> Jobs, <1> Queues and <5> Nodes in total for scheduling.
I0714 05:34:35.847182       1 session.go:190] Open Session ff0baa8b-480e-4485-a59e-67ff5ebdb41a with <0> Job and <1> Queues
I0714 05:34:35.848102       1 enqueue.go:79] Try to enqueue PodGroup to 0 Queues
I0714 05:34:35.848153       1 allocate.go:64] Try to allocate resource to 0 Queues
I0714 05:34:35.848267       1 session.go:244] Close Session ff0baa8b-480e-4485-a59e-67ff5ebdb41a
I0714 05:34:36.278561       1 cache.go:1489] The metrics type is not set in the volcano scheduler configmap file. As a result, the CPU and memory load information of the node is not collected.
I0714 05:34:36.851426       1 cache.go:1363] There are <0> Jobs, <1> Queues and <5> Nodes in total for scheduling.
I0714 05:34:36.851610       1 session.go:190] Open Session a654670b-ea55-422f-ab75-f8a4dd120404 with <0> Job and <1> Queues
I0714 05:34:36.853509       1 enqueue.go:79] Try to enqueue PodGroup to 0 Queues
I0714 05:34:36.853584       1 allocate.go:64] Try to allocate resource to 0 Queues
I0714 05:34:36.853793       1 session.go:244] Close Session a654670b-ea55-422f-ab75-f8a4dd120404
I0714 05:34:37.856044       1 cache.go:1363] There are <0> Jobs, <1> Queues and <5> Nodes in total for scheduling.
I0714 05:34:37.856222       1 session.go:190] Open Session 6f5952cc-4189-4882-80dd-32e3563626a8 with <0> Job and <1> Queues
I0714 05:34:37.858113       1 enqueue.go:79] Try to enqueue PodGroup to 0 Queues
I0714 05:34:37.858192       1 allocate.go:64] Try to allocate resource to 0 Queues
I0714 05:34:37.858412       1 session.go:244] Close Session 6f5952cc-4189-4882-80dd-32e3563626a8
I0714 05:34:38.861430       1 cache.go:1363] There are <0> Jobs, <1> Queues and <5> Nodes in total for scheduling.
I0714 05:34:38.861597       1 session.go:190] Open Session b22b9b65-6f64-4a50-b921-0b26238e3299 with <0> Job and <1> Queues
I0714 05:34:38.863367       1 enqueue.go:79] Try to enqueue PodGroup to 0 Queues
I0714 05:34:38.863448       1 allocate.go:64] Try to allocate resource to 0 Queues
I0714 05:34:38.863680       1 session.go:244] Close Session b22b9b65-6f64-4a50-b921-0b26238e3299
I0714 05:34:39.866237       1 cache.go:1363] There are <0> Jobs, <1> Queues and <5> Nodes in total for scheduling.
I0714 05:34:39.866404       1 session.go:190] Open Session b47cae1e-3c1a-4eaf-a2ce-9be687316ed3 with <0> Job and <1> Queues
I0714 05:34:39.868224       1 enqueue.go:79] Try to enqueue PodGroup to 0 Queues
I0714 05:34:39.868337       1 allocate.go:64] Try to allocate resource to 0 Queues
I0714 05:34:39.868572       1 session.go:244] Close Session b47cae1e-3c1a-4eaf-a2ce-9be687316ed3
I0714 05:34:40.870851       1 cache.go:1363] There are <0> Jobs, <1> Queues and <5> Nodes in total for scheduling.
I0714 05:34:40.870933       1 session.go:190] Open Session 72c1e3a2-f611-4d2f-9bda-0d09c20cbc7f with <0> Job and <1> Queues
I0714 05:34:40.871777       1 enqueue.go:79] Try to enqueue PodGroup to 0 Queues
I0714 05:34:40.871816       1 allocate.go:64] Try to allocate resource to 0 Queues
I0714 05:34:40.871908       1 session.go:244] Close Session 72c1e3a2-f611-4d2f-9bda-0d09c20cbc7f
I0714 05:34:41.874605       1 cache.go:1363] There are <0> Jobs, <1> Queues and <5> Nodes in total for scheduling.
I0714 05:34:41.874785       1 session.go:190] Open Session daed90e7-fa50-4e6f-a3b4-8467d3f9f562 with <0> Job and <1> Queues
I0714 05:34:41.876587       1 enqueue.go:79] Try to enqueue PodGroup to 0 Queues
I0714 05:34:41.876657       1 allocate.go:64] Try to allocate resource to 0 Queues
I0714 05:34:41.876867       1 session.go:244] Close Session daed90e7-fa50-4e6f-a3b4-8467d3f9f562
I0714 05:34:42.879497       1 cache.go:1363] There are <0> Jobs, <1> Queues and <5> Nodes in total for scheduling.
I0714 05:34:42.879654       1 session.go:190] Open Session a6dbe35e-9584-421e-8984-4fd3b2d01630 with <0> Job and <1> Queues
I0714 05:34:42.881481       1 enqueue.go:79] Try to enqueue PodGroup to 0 Queues
I0714 05:34:42.881567       1 allocate.go:64] Try to allocate resource to 0 Queues
I0714 05:34:42.881782       1 session.go:244] Close Session a6dbe35e-9584-421e-8984-4fd3b2d01630
I0714 05:34:43.883910       1 cache.go:1363] There are <0> Jobs, <1> Queues and <5> Nodes in total for scheduling.
I0714 05:34:43.884066       1 session.go:190] Open Session 55b0b358-d84e-4b9c-a0fc-dc5896adb407 with <0> Job and <1> Queues
I0714 05:34:43.886064       1 enqueue.go:79] Try to enqueue PodGroup to 0 Queues
I0714 05:34:43.886136       1 allocate.go:64] Try to allocate resource to 0 Queues
I0714 05:34:43.886341       1 session.go:244] Close Session 55b0b358-d84e-4b9c-a0fc-dc5896adb407
I0714 05:34:44.889096       1 cache.go:1363] There are <0> Jobs, <1> Queues and <5> Nodes in total for scheduling.
I0714 05:34:44.889260       1 session.go:190] Open Session fa37168f-72c0-490a-b0fc-3625a6c9ccdc with <0> Job and <1> Queues
I0714 05:34:44.891012       1 enqueue.go:79] Try to enqueue PodGroup to 0 Queues
I0714 05:34:44.891080       1 allocate.go:64] Try to allocate resource to 0 Queues
I0714 05:34:44.891310       1 session.go:244] Close Session fa37168f-72c0-490a-b0fc-3625a6c9ccdc
I0714 05:34:45.892879       1 cache.go:1363] There are <0> Jobs, <1> Queues and <5> Nodes in total for scheduling.
I0714 05:34:45.892977       1 session.go:190] Open Session f1f4fdef-4652-4dd6-80f8-0c4ae6219770 with <0> Job and <1> Queues
I0714 05:34:45.893842       1 enqueue.go:79] Try to enqueue PodGroup to 0 Queues
I0714 05:34:45.893886       1 allocate.go:64] Try to allocate resource to 0 Queues
I0714 05:34:45.894001       1 session.go:244] Close Session f1f4fdef-4652-4dd6-80f8-0c4ae6219770
I0714 05:34:46.896621       1 cache.go:1363] There are <0> Jobs, <1> Queues and <5> Nodes in total for scheduling.
I0714 05:34:46.896793       1 session.go:190] Open Session 8502f49c-4321-488e-9468-dd7d2669db22 with <0> Job and <1> Queues
I0714 05:34:46.898568       1 enqueue.go:79] Try to enqueue PodGroup to 0 Queues
I0714 05:34:46.898649       1 allocate.go:64] Try to allocate resource to 0 Queues
I0714 05:34:46.898887       1 session.go:244] Close Session 8502f49c-4321-488e-9468-dd7d2669db22
I0714 05:34:47.901517       1 cache.go:1363] There are <0> Jobs, <1> Queues and <5> Nodes in total for scheduling.
I0714 05:34:47.901669       1 session.go:190] Open Session 5af53fe7-de15-4af3-a976-b33f764e9003 with <0> Job and <1> Queues
I0714 05:34:47.903364       1 enqueue.go:79] Try to enqueue PodGroup to 0 Queues
I0714 05:34:47.903428       1 allocate.go:64] Try to allocate resource to 0 Queues
I0714 05:34:47.903631       1 session.go:244] Close Session 5af53fe7-de15-4af3-a976-b33f764e9003
I0714 05:34:48.905800       1 cache.go:1363] There are <0> Jobs, <1> Queues and <5> Nodes in total for scheduling.
I0714 05:34:48.905953       1 session.go:190] Open Session db24629e-f2c2-4100-933e-c01ef70a5ed5 with <0> Job and <1> Queues
I0714 05:34:48.907718       1 enqueue.go:79] Try to enqueue PodGroup to 0 Queues
I0714 05:34:48.907788       1 allocate.go:64] Try to allocate resource to 0 Queues
I0714 05:34:48.907980       1 session.go:244] Close Session db24629e-f2c2-4100-933e-c01ef70a5ed5
I0714 05:34:49.910657       1 cache.go:1363] There are <0> Jobs, <1> Queues and <5> Nodes in total for scheduling.
I0714 05:34:49.910825       1 session.go:190] Open Session 3630f35e-10fc-4e41-9ee8-e29e376e7ee9 with <0> Job and <1> Queues
I0714 05:34:49.912626       1 enqueue.go:79] Try to enqueue PodGroup to 0 Queues
I0714 05:34:49.912709       1 allocate.go:64] Try to allocate resource to 0 Queues
I0714 05:34:49.912930       1 session.go:244] Close Session 3630f35e-10fc-4e41-9ee8-e29e376e7ee9
I0714 05:34:50.913992       1 cache.go:1363] There are <0> Jobs, <1> Queues and <5> Nodes in total for scheduling.
I0714 05:34:50.914071       1 session.go:190] Open Session 09ff9fec-1622-43d9-a78a-137e58d38b51 with <0> Job and <1> Queues
I0714 05:34:50.914862       1 enqueue.go:79] Try to enqueue PodGroup to 0 Queues
I0714 05:34:50.914898       1 allocate.go:64] Try to allocate resource to 0 Queues
I0714 05:34:50.914994       1 session.go:244] Close Session 09ff9fec-1622-43d9-a78a-137e58d38b51
I0714 05:34:51.917946       1 cache.go:1363] There are <0> Jobs, <1> Queues and <5> Nodes in total for scheduling.
I0714 05:34:51.918122       1 session.go:190] Open Session da0a3030-2b4f-4e25-8b3c-4c063dc3817c with <0> Job and <1> Queues
I0714 05:34:51.919867       1 enqueue.go:79] Try to enqueue PodGroup to 0 Queues
I0714 05:34:51.919936       1 allocate.go:64] Try to allocate resource to 0 Queues
I0714 05:34:51.920171       1 session.go:244] Close Session da0a3030-2b4f-4e25-8b3c-4c063dc3817c
I0714 05:34:52.923202       1 cache.go:1363] There are <0> Jobs, <1> Queues and <5> Nodes in total for scheduling.
I0714 05:34:52.923365       1 session.go:190] Open Session e326139a-d155-4507-988e-c51517587396 with <0> Job and <1> Queues
I0714 05:34:52.925175       1 enqueue.go:79] Try to enqueue PodGroup to 0 Queues
I0714 05:34:52.925245       1 allocate.go:64] Try to allocate resource to 0 Queues
I0714 05:34:52.925472       1 session.go:244] Close Session e326139a-d155-4507-988e-c51517587396
I0714 05:34:53.927943       1 cache.go:1363] There are <0> Jobs, <1> Queues and <5> Nodes in total for scheduling.
I0714 05:34:53.928104       1 session.go:190] Open Session fd170c17-a8ed-47af-9337-4b56e0dca68b with <0> Job and <1> Queues
I0714 05:34:53.929973       1 enqueue.go:79] Try to enqueue PodGroup to 0 Queues
I0714 05:34:53.930039       1 allocate.go:64] Try to allocate resource to 0 Queues
I0714 05:34:53.930249       1 session.go:244] Close Session fd170c17-a8ed-47af-9337-4b56e0dca68b
I0714 05:34:54.932949       1 cache.go:1363] There are <0> Jobs, <1> Queues and <5> Nodes in total for scheduling.
I0714 05:34:54.933126       1 session.go:190] Open Session c98f94a6-d9eb-44d1-9c35-3d3ac3670c1f with <0> Job and <1> Queues
I0714 05:34:54.934903       1 enqueue.go:79] Try to enqueue PodGroup to 0 Queues
I0714 05:34:54.934965       1 allocate.go:64] Try to allocate resource to 0 Queues
I0714 05:34:54.935159       1 session.go:244] Close Session c98f94a6-d9eb-44d1-9c35-3d3ac3670c1f
I0714 05:34:55.936559       1 cache.go:1363] There are <0> Jobs, <1> Queues and <5> Nodes in total for scheduling.
I0714 05:34:55.936655       1 session.go:190] Open Session 00a1fb40-1970-49cb-b94a-42653e11404b with <0> Job and <1> Queues
I0714 05:34:55.937566       1 enqueue.go:79] Try to enqueue PodGroup to 0 Queues
I0714 05:34:55.937611       1 allocate.go:64] Try to allocate resource to 0 Queues
I0714 05:34:55.937732       1 session.go:244] Close Session 00a1fb40-1970-49cb-b94a-42653e11404b
I0714 05:34:56.940178       1 cache.go:1363] There are <0> Jobs, <1> Queues and <5> Nodes in total for scheduling.
I0714 05:34:56.940394       1 session.go:190] Open Session 594f06ca-ea28-437d-b525-1945d8753b9b with <0> Job and <1> Queues
I0714 05:34:56.942108       1 enqueue.go:79] Try to enqueue PodGroup to 0 Queues
I0714 05:34:56.942173       1 allocate.go:64] Try to allocate resource to 0 Queues
I0714 05:34:56.942379       1 session.go:244] Close Session 594f06ca-ea28-437d-b525-1945d8753b9b
I0714 05:34:57.945289       1 cache.go:1363] There are <0> Jobs, <1> Queues and <5> Nodes in total for scheduling.
I0714 05:34:57.945441       1 session.go:190] Open Session 0ab6d14b-6118-4644-ac9e-18e18c7619e1 with <0> Job and <1> Queues
I0714 05:34:57.947199       1 enqueue.go:79] Try to enqueue PodGroup to 0 Queues
I0714 05:34:57.947264       1 allocate.go:64] Try to allocate resource to 0 Queues
I0714 05:34:57.947482       1 session.go:244] Close Session 0ab6d14b-6118-4644-ac9e-18e18c7619e1
I0714 05:34:58.949591       1 cache.go:1363] There are <0> Jobs, <1> Queues and <5> Nodes in total for scheduling.
I0714 05:34:58.949745       1 session.go:190] Open Session 3103b5d2-42ce-4356-a118-4894efa91f49 with <0> Job and <1> Queues
I0714 05:34:58.951493       1 enqueue.go:79] Try to enqueue PodGroup to 0 Queues
I0714 05:34:58.951561       1 allocate.go:64] Try to allocate resource to 0 Queues
I0714 05:34:58.951779       1 session.go:244] Close Session 3103b5d2-42ce-4356-a118-4894efa91f49
I0714 05:34:59.954187       1 cache.go:1363] There are <0> Jobs, <1> Queues and <5> Nodes in total for scheduling.
I0714 05:34:59.954366       1 session.go:190] Open Session b1614b0e-c36a-429e-bfb5-6909a9d4208e with <0> Job and <1> Queues
I0714 05:34:59.956095       1 enqueue.go:79] Try to enqueue PodGroup to 0 Queues
I0714 05:34:59.956166       1 allocate.go:64] Try to allocate resource to 0 Queues
I0714 05:34:59.956430       1 session.go:244] Close Session b1614b0e-c36a-429e-bfb5-6909a9d4208e
I0714 05:35:00.959032       1 cache.go:1363] There are <0> Jobs, <1> Queues and <5> Nodes in total for scheduling.
I0714 05:35:00.959206       1 session.go:190] Open Session d2273c31-9004-48e4-870f-4a20150ca2b1 with <0> Job and <1> Queues
I0714 05:35:00.961095       1 enqueue.go:79] Try to enqueue PodGroup to 0 Queues
I0714 05:35:00.961160       1 allocate.go:64] Try to allocate resource to 0 Queues
I0714 05:35:00.961380       1 session.go:244] Close Session d2273c31-9004-48e4-870f-4a20150ca2b1
I0714 05:35:01.964337       1 cache.go:1363] There are <0> Jobs, <1> Queues and <5> Nodes in total for scheduling.
I0714 05:35:01.964520       1 session.go:190] Open Session 12e0c860-61c0-4869-991a-0b1adf10cdb7 with <0> Job and <1> Queues
I0714 05:35:01.966300       1 enqueue.go:79] Try to enqueue PodGroup to 0 Queues
I0714 05:35:01.966372       1 allocate.go:64] Try to allocate resource to 0 Queues
I0714 05:35:01.966582       1 session.go:244] Close Session 12e0c860-61c0-4869-991a-0b1adf10cdb7
I0714 05:35:02.969045       1 cache.go:1363] There are <0> Jobs, <1> Queues and <5> Nodes in total for scheduling.
I0714 05:35:02.969214       1 session.go:190] Open Session ab20ff1e-0eab-4478-b111-e5cfe86aca5f with <0> Job and <1> Queues
I0714 05:35:02.970918       1 enqueue.go:79] Try to enqueue PodGroup to 0 Queues
I0714 05:35:02.970988       1 allocate.go:64] Try to allocate resource to 0 Queues
I0714 05:35:02.971203       1 session.go:244] Close Session ab20ff1e-0eab-4478-b111-e5cfe86aca5f
I0714 05:35:03.973327       1 cache.go:1363] There are <0> Jobs, <1> Queues and <5> Nodes in total for scheduling.
I0714 05:35:03.973505       1 session.go:190] Open Session 25813f93-18bb-4484-96c2-6111e28d235c with <0> Job and <1> Queues
I0714 05:35:03.975251       1 enqueue.go:79] Try to enqueue PodGroup to 0 Queues
I0714 05:35:03.975319       1 allocate.go:64] Try to allocate resource to 0 Queues
I0714 05:35:03.975550       1 session.go:244] Close Session 25813f93-18bb-4484-96c2-6111e28d235c
I0714 05:35:04.978429       1 cache.go:1363] There are <0> Jobs, <1> Queues and <5> Nodes in total for scheduling.
I0714 05:35:04.978599       1 session.go:190] Open Session cdbef8f8-d3ea-4676-843e-c52d732d703d with <0> Job and <1> Queues
I0714 05:35:04.980267       1 enqueue.go:79] Try to enqueue PodGroup to 0 Queues
I0714 05:35:04.980377       1 allocate.go:64] Try to allocate resource to 0 Queues
I0714 05:35:04.980601       1 session.go:244] Close Session cdbef8f8-d3ea-4676-843e-c52d732d703d
I0714 05:35:05.983769       1 cache.go:1363] There are <0> Jobs, <1> Queues and <5> Nodes in total for scheduling.
I0714 05:35:05.983951       1 session.go:190] Open Session d55c8a22-f15e-411f-94e8-c723d7dc31f5 with <0> Job and <1> Queues
I0714 05:35:05.985894       1 enqueue.go:79] Try to enqueue PodGroup to 0 Queues
I0714 05:35:05.985967       1 allocate.go:64] Try to allocate resource to 0 Queues
I0714 05:35:05.986180       1 session.go:244] Close Session d55c8a22-f15e-411f-94e8-c723d7dc31f5
I0714 05:35:06.279440       1 cache.go:1489] The metrics type is not set in the volcano scheduler configmap file. As a result, the CPU and memory load information of the node is not collected.
I0714 05:35:06.988951       1 cache.go:1363] There are <0> Jobs, <1> Queues and <5> Nodes in total for scheduling.
I0714 05:35:06.989149       1 session.go:190] Open Session 010918ab-56ba-428e-8a88-78571fb666b4 with <0> Job and <1> Queues
I0714 05:35:06.990824       1 enqueue.go:79] Try to enqueue PodGroup to 0 Queues
I0714 05:35:06.990899       1 allocate.go:64] Try to allocate resource to 0 Queues
I0714 05:35:06.991135       1 session.go:244] Close Session 010918ab-56ba-428e-8a88-78571fb666b4
I0714 05:35:07.993863       1 cache.go:1363] There are <0> Jobs, <1> Queues and <5> Nodes in total for scheduling.
I0714 05:35:07.994031       1 session.go:190] Open Session 77d696de-122b-4287-b7ba-67aca0730f50 with <0> Job and <1> Queues
I0714 05:35:07.995678       1 enqueue.go:79] Try to enqueue PodGroup to 0 Queues
I0714 05:35:07.995759       1 allocate.go:64] Try to allocate resource to 0 Queues
I0714 05:35:07.995983       1 session.go:244] Close Session 77d696de-122b-4287-b7ba-67aca0730f50
I0714 05:35:08.997926       1 cache.go:1363] There are <0> Jobs, <1> Queues and <5> Nodes in total for scheduling.
I0714 05:35:08.998091       1 session.go:190] Open Session e991ffdd-8e02-4c27-9d1e-5ad53d17f064 with <0> Job and <1> Queues
I0714 05:35:08.999769       1 enqueue.go:79] Try to enqueue PodGroup to 0 Queues
I0714 05:35:08.999844       1 allocate.go:64] Try to allocate resource to 0 Queues
I0714 05:35:09.000063       1 session.go:244] Close Session e991ffdd-8e02-4c27-9d1e-5ad53d17f064
I0714 05:35:10.002104       1 cache.go:1363] There are <0> Jobs, <1> Queues and <5> Nodes in total for scheduling.
I0714 05:35:10.002251       1 session.go:190] Open Session 7fef6fbc-226f-4650-9937-a09c2d702967 with <0> Job and <1> Queues
I0714 05:35:10.003822       1 enqueue.go:79] Try to enqueue PodGroup to 0 Queues
I0714 05:35:10.003889       1 allocate.go:64] Try to allocate resource to 0 Queues
I0714 05:35:10.004131       1 session.go:244] Close Session 7fef6fbc-226f-4650-9937-a09c2d702967
I0714 05:35:11.006766       1 cache.go:1363] There are <0> Jobs, <1> Queues and <5> Nodes in total for scheduling.
I0714 05:35:11.006923       1 session.go:190] Open Session 9e5d40da-1237-4b15-a4bf-e3070d21eb1f with <0> Job and <1> Queues
I0714 05:35:11.008677       1 enqueue.go:79] Try to enqueue PodGroup to 0 Queues
I0714 05:35:11.008748       1 allocate.go:64] Try to allocate resource to 0 Queues
I0714 05:35:11.008949       1 session.go:244] Close Session 9e5d40da-1237-4b15-a4bf-e3070d21eb1f
I0714 05:35:12.011591       1 cache.go:1363] There are <0> Jobs, <1> Queues and <5> Nodes in total for scheduling.
I0714 05:35:12.011752       1 session.go:190] Open Session 86e5256f-31ca-444a-afb2-579784b5bdef with <0> Job and <1> Queues
I0714 05:35:12.013419       1 enqueue.go:79] Try to enqueue PodGroup to 0 Queues
I0714 05:35:12.013495       1 allocate.go:64] Try to allocate resource to 0 Queues
I0714 05:35:12.013702       1 session.go:244] Close Session 86e5256f-31ca-444a-afb2-579784b5bdef
I0714 05:35:13.016596       1 cache.go:1363] There are <0> Jobs, <1> Queues and <5> Nodes in total for scheduling.
I0714 05:35:13.016755       1 session.go:190] Open Session ff2a44dd-2a7b-443b-bcc7-e4589d3e0126 with <0> Job and <1> Queues
I0714 05:35:13.018304       1 enqueue.go:79] Try to enqueue PodGroup to 0 Queues
I0714 05:35:13.018369       1 allocate.go:64] Try to allocate resource to 0 Queues
I0714 05:35:13.018704       1 session.go:244] Close Session ff2a44dd-2a7b-443b-bcc7-e4589d3e0126
I0714 05:35:14.022246       1 cache.go:1363] There are <0> Jobs, <1> Queues and <5> Nodes in total for scheduling.
I0714 05:35:14.022443       1 session.go:190] Open Session ad398603-91e4-4405-b4da-50dde3077091 with <0> Job and <1> Queues
I0714 05:35:14.025571       1 enqueue.go:79] Try to enqueue PodGroup to 0 Queues
I0714 05:35:14.025725       1 allocate.go:64] Try to allocate resource to 0 Queues
I0714 05:35:14.025948       1 session.go:244] Close Session ad398603-91e4-4405-b4da-50dde3077091
I0714 05:35:15.028214       1 cache.go:1363] There are <0> Jobs, <1> Queues and <5> Nodes in total for scheduling.
I0714 05:35:15.028418       1 session.go:190] Open Session 960693ff-8bcc-4270-8126-b833f76b4f2f with <0> Job and <1> Queues
I0714 05:35:15.030151       1 enqueue.go:79] Try to enqueue PodGroup to 0 Queues
I0714 05:35:15.030223       1 allocate.go:64] Try to allocate resource to 0 Queues
I0714 05:35:15.030440       1 session.go:244] Close Session 960693ff-8bcc-4270-8126-b833f76b4f2f
I0714 05:35:16.033073       1 cache.go:1363] There are <0> Jobs, <1> Queues and <5> Nodes in total for scheduling.
I0714 05:35:16.033220       1 session.go:190] Open Session c10b20a5-9da7-4c6b-836b-aefdd7afd380 with <0> Job and <1> Queues
I0714 05:35:16.034851       1 enqueue.go:79] Try to enqueue PodGroup to 0 Queues
I0714 05:35:16.034916       1 allocate.go:64] Try to allocate resource to 0 Queues
I0714 05:35:16.035135       1 session.go:244] Close Session c10b20a5-9da7-4c6b-836b-aefdd7afd380
I0714 05:35:17.037650       1 cache.go:1363] There are <0> Jobs, <1> Queues and <5> Nodes in total for scheduling.
I0714 05:35:17.037817       1 session.go:190] Open Session d85d4018-cc30-4aeb-98cf-b95d9652b720 with <0> Job and <1> Queues
I0714 05:35:17.039559       1 enqueue.go:79] Try to enqueue PodGroup to 0 Queues
I0714 05:35:17.039623       1 allocate.go:64] Try to allocate resource to 0 Queues
I0714 05:35:17.039844       1 session.go:244] Close Session d85d4018-cc30-4aeb-98cf-b95d9652b720
I0714 05:35:18.042674       1 cache.go:1363] There are <0> Jobs, <1> Queues and <5> Nodes in total for scheduling.
I0714 05:35:18.042864       1 session.go:190] Open Session 42665c8e-c8c7-4cd0-8c1b-69ddc24ff5c4 with <0> Job and <1> Queues
I0714 05:35:18.044778       1 enqueue.go:79] Try to enqueue PodGroup to 0 Queues
I0714 05:35:18.044849       1 allocate.go:64] Try to allocate resource to 0 Queues
I0714 05:35:18.045080       1 session.go:244] Close Session 42665c8e-c8c7-4cd0-8c1b-69ddc24ff5c4
I0714 05:35:19.047411       1 cache.go:1363] There are <0> Jobs, <1> Queues and <5> Nodes in total for scheduling.
I0714 05:35:19.047566       1 session.go:190] Open Session 803642f2-3bce-401e-968a-b4f40092ce19 with <0> Job and <1> Queues
I0714 05:35:19.049469       1 enqueue.go:79] Try to enqueue PodGroup to 0 Queues
I0714 05:35:19.049540       1 allocate.go:64] Try to allocate resource to 0 Queues
I0714 05:35:19.049775       1 session.go:244] Close Session 803642f2-3bce-401e-968a-b4f40092ce19
I0714 05:35:20.052003       1 cache.go:1363] There are <0> Jobs, <1> Queues and <5> Nodes in total for scheduling.
I0714 05:35:20.052192       1 session.go:190] Open Session 58f658d1-58fa-493b-9831-b2864df48cb5 with <0> Job and <1> Queues
I0714 05:35:20.054061       1 enqueue.go:79] Try to enqueue PodGroup to 0 Queues
I0714 05:35:20.054126       1 allocate.go:64] Try to allocate resource to 0 Queues
I0714 05:35:20.054343       1 session.go:244] Close Session 58f658d1-58fa-493b-9831-b2864df48cb5
I0714 05:35:21.056503       1 cache.go:1363] There are <0> Jobs, <1> Queues and <5> Nodes in total for scheduling.
I0714 05:35:21.056682       1 session.go:190] Open Session b1201184-7b42-4e7d-9f7a-ea8f44097863 with <0> Job and <1> Queues
I0714 05:35:21.058418       1 enqueue.go:79] Try to enqueue PodGroup to 0 Queues
I0714 05:35:21.058483       1 allocate.go:64] Try to allocate resource to 0 Queues
I0714 05:35:21.058680       1 session.go:244] Close Session b1201184-7b42-4e7d-9f7a-ea8f44097863
I0714 05:35:22.061414       1 cache.go:1363] There are <0> Jobs, <1> Queues and <5> Nodes in total for scheduling.
I0714 05:35:22.061579       1 session.go:190] Open Session 0aefb3a8-e974-4533-b463-437f5548b894 with <0> Job and <1> Queues
I0714 05:35:22.063399       1 enqueue.go:79] Try to enqueue PodGroup to 0 Queues
I0714 05:35:22.063468       1 allocate.go:64] Try to allocate resource to 0 Queues
I0714 05:35:22.063684       1 session.go:244] Close Session 0aefb3a8-e974-4533-b463-437f5548b894
I0714 05:35:23.066487       1 cache.go:1363] There are <0> Jobs, <1> Queues and <5> Nodes in total for scheduling.
I0714 05:35:23.066664       1 session.go:190] Open Session 6ef7e73b-7c68-42f9-a46a-ed9e8a7cd283 with <0> Job and <1> Queues
I0714 05:35:23.068327       1 enqueue.go:79] Try to enqueue PodGroup to 0 Queues
I0714 05:35:23.068399       1 allocate.go:64] Try to allocate resource to 0 Queues
I0714 05:35:23.068622       1 session.go:244] Close Session 6ef7e73b-7c68-42f9-a46a-ed9e8a7cd283
I0714 05:35:24.071016       1 cache.go:1363] There are <0> Jobs, <1> Queues and <5> Nodes in total for scheduling.
I0714 05:35:24.071185       1 session.go:190] Open Session 77c62489-12f1-4d8c-8f11-3248fb3a615f with <0> Job and <1> Queues
I0714 05:35:24.072977       1 enqueue.go:79] Try to enqueue PodGroup to 0 Queues
I0714 05:35:24.073050       1 allocate.go:64] Try to allocate resource to 0 Queues
I0714 05:35:24.073283       1 session.go:244] Close Session 77c62489-12f1-4d8c-8f11-3248fb3a615f
I0714 05:35:25.075688       1 cache.go:1363] There are <0> Jobs, <1> Queues and <5> Nodes in total for scheduling.
I0714 05:35:25.075852       1 session.go:190] Open Session 408b1500-34c7-473c-b221-a0a30b06f248 with <0> Job and <1> Queues
I0714 05:35:25.077593       1 enqueue.go:79] Try to enqueue PodGroup to 0 Queues
I0714 05:35:25.077662       1 allocate.go:64] Try to allocate resource to 0 Queues
I0714 05:35:25.077892       1 session.go:244] Close Session 408b1500-34c7-473c-b221-a0a30b06f248
I0714 05:35:26.080903       1 cache.go:1363] There are <0> Jobs, <1> Queues and <5> Nodes in total for scheduling.
I0714 05:35:26.081069       1 session.go:190] Open Session 1aa9c02e-327a-407e-ab83-4d2399cab415 with <0> Job and <1> Queues
I0714 05:35:26.082784       1 enqueue.go:79] Try to enqueue PodGroup to 0 Queues
I0714 05:35:26.082852       1 allocate.go:64] Try to allocate resource to 0 Queues
I0714 05:35:26.083071       1 session.go:244] Close Session 1aa9c02e-327a-407e-ab83-4d2399cab415
I0714 05:35:27.085639       1 cache.go:1363] There are <0> Jobs, <1> Queues and <5> Nodes in total for scheduling.
I0714 05:35:27.085809       1 session.go:190] Open Session 519643cc-8eb2-4cd9-a9a1-5a769a1e7836 with <0> Job and <1> Queues
I0714 05:35:27.087436       1 enqueue.go:79] Try to enqueue PodGroup to 0 Queues
I0714 05:35:27.087500       1 allocate.go:64] Try to allocate resource to 0 Queues
I0714 05:35:27.087721       1 session.go:244] Close Session 519643cc-8eb2-4cd9-a9a1-5a769a1e7836
I0714 05:35:28.090530       1 cache.go:1363] There are <0> Jobs, <1> Queues and <5> Nodes in total for scheduling.
I0714 05:35:28.090712       1 session.go:190] Open Session eea92454-c4d3-4787-a1e6-0ae73bcb00d9 with <0> Job and <1> Queues
I0714 05:35:28.092508       1 enqueue.go:79] Try to enqueue PodGroup to 0 Queues
I0714 05:35:28.092585       1 allocate.go:64] Try to allocate resource to 0 Queues
I0714 05:35:28.092807       1 session.go:244] Close Session eea92454-c4d3-4787-a1e6-0ae73bcb00d9
I0714 05:35:29.095130       1 cache.go:1363] There are <0> Jobs, <1> Queues and <5> Nodes in total for scheduling.
I0714 05:35:29.095328       1 session.go:190] Open Session 84a9b99e-2fb5-4a4b-ad12-6343fb431078 with <0> Job and <1> Queues
I0714 05:35:29.097193       1 enqueue.go:79] Try to enqueue PodGroup to 0 Queues
I0714 05:35:29.097274       1 allocate.go:64] Try to allocate resource to 0 Queues
I0714 05:35:29.097494       1 session.go:244] Close Session 84a9b99e-2fb5-4a4b-ad12-6343fb431078
I0714 05:35:30.100225       1 cache.go:1363] There are <0> Jobs, <1> Queues and <5> Nodes in total for scheduling.
I0714 05:35:30.100438       1 session.go:190] Open Session e11d1e11-8c00-408f-bc4c-7b7470b83d93 with <0> Job and <1> Queues
I0714 05:35:30.102196       1 enqueue.go:79] Try to enqueue PodGroup to 0 Queues
I0714 05:35:30.102278       1 allocate.go:64] Try to allocate resource to 0 Queues
I0714 05:35:30.102491       1 session.go:244] Close Session e11d1e11-8c00-408f-bc4c-7b7470b83d93
I0714 05:35:31.105090       1 cache.go:1363] There are <0> Jobs, <1> Queues and <5> Nodes in total for scheduling.
I0714 05:35:31.105253       1 session.go:190] Open Session 14625163-b8c2-4d5b-81ce-d3c669452ed7 with <0> Job and <1> Queues
I0714 05:35:31.106938       1 enqueue.go:79] Try to enqueue PodGroup to 0 Queues
I0714 05:35:31.107002       1 allocate.go:64] Try to allocate resource to 0 Queues
I0714 05:35:31.107216       1 session.go:244] Close Session 14625163-b8c2-4d5b-81ce-d3c669452ed7
I0714 05:35:32.109699       1 cache.go:1363] There are <0> Jobs, <1> Queues and <5> Nodes in total for scheduling.
I0714 05:35:32.109874       1 session.go:190] Open Session 77de05ca-8066-45d9-990b-5655079e54e8 with <0> Job and <1> Queues
I0714 05:35:32.111588       1 enqueue.go:79] Try to enqueue PodGroup to 0 Queues
I0714 05:35:32.111651       1 allocate.go:64] Try to allocate resource to 0 Queues
I0714 05:35:32.111856       1 session.go:244] Close Session 77de05ca-8066-45d9-990b-5655079e54e8
I0714 05:35:33.114411       1 cache.go:1363] There are <0> Jobs, <1> Queues and <5> Nodes in total for scheduling.
I0714 05:35:33.114601       1 session.go:190] Open Session b4f21823-1365-40e6-a100-e08a691b435d with <0> Job and <1> Queues
I0714 05:35:33.116373       1 enqueue.go:79] Try to enqueue PodGroup to 0 Queues
I0714 05:35:33.116443       1 allocate.go:64] Try to allocate resource to 0 Queues
I0714 05:35:33.116692       1 session.go:244] Close Session b4f21823-1365-40e6-a100-e08a691b435d
I0714 05:35:34.118699       1 cache.go:1363] There are <0> Jobs, <1> Queues and <5> Nodes in total for scheduling.
I0714 05:35:34.118866       1 session.go:190] Open Session 0f8cc979-3d21-4344-9584-8cb7ddb1a1b1 with <0> Job and <1> Queues
I0714 05:35:34.120716       1 enqueue.go:79] Try to enqueue PodGroup to 0 Queues
I0714 05:35:34.120789       1 allocate.go:64] Try to allocate resource to 0 Queues
I0714 05:35:34.121004       1 session.go:244] Close Session 0f8cc979-3d21-4344-9584-8cb7ddb1a1b1
I0714 05:35:35.123480       1 cache.go:1363] There are <0> Jobs, <1> Queues and <5> Nodes in total for scheduling.
I0714 05:35:35.123655       1 session.go:190] Open Session 78b0996e-ae8e-432a-b64a-69e9f0667911 with <0> Job and <1> Queues
I0714 05:35:35.125432       1 enqueue.go:79] Try to enqueue PodGroup to 0 Queues
I0714 05:35:35.125501       1 allocate.go:64] Try to allocate resource to 0 Queues
I0714 05:35:35.125722       1 session.go:244] Close Session 78b0996e-ae8e-432a-b64a-69e9f0667911
I0714 05:35:36.127771       1 cache.go:1363] There are <0> Jobs, <1> Queues and <5> Nodes in total for scheduling.
I0714 05:35:36.127948       1 session.go:190] Open Session 858b3d1f-9c39-4f9d-88e3-a5901b9de036 with <0> Job and <1> Queues
I0714 05:35:36.129740       1 enqueue.go:79] Try to enqueue PodGroup to 0 Queues
I0714 05:35:36.129813       1 allocate.go:64] Try to allocate resource to 0 Queues
I0714 05:35:36.130023       1 session.go:244] Close Session 858b3d1f-9c39-4f9d-88e3-a5901b9de036
I0714 05:35:36.279921       1 cache.go:1489] The metrics type is not set in the volcano scheduler configmap file. As a result, the CPU and memory load information of the node is not collected.
I0714 05:35:37.133082       1 cache.go:1363] There are <0> Jobs, <1> Queues and <5> Nodes in total for scheduling.
I0714 05:35:37.133258       1 session.go:190] Open Session 57de7f2e-615c-4002-baad-6f8536003c64 with <0> Job and <1> Queues
I0714 05:35:37.134981       1 enqueue.go:79] Try to enqueue PodGroup to 0 Queues
I0714 05:35:37.135054       1 allocate.go:64] Try to allocate resource to 0 Queues
I0714 05:35:37.135279       1 session.go:244] Close Session 57de7f2e-615c-4002-baad-6f8536003c64
I0714 05:35:38.137596       1 cache.go:1363] There are <0> Jobs, <1> Queues and <5> Nodes in total for scheduling.
I0714 05:35:38.137760       1 session.go:190] Open Session 85099f7d-a54b-4618-b1a7-320210dfc02d with <0> Job and <1> Queues
I0714 05:35:38.139611       1 enqueue.go:79] Try to enqueue PodGroup to 0 Queues
I0714 05:35:38.139680       1 allocate.go:64] Try to allocate resource to 0 Queues
I0714 05:35:38.139902       1 session.go:244] Close Session 85099f7d-a54b-4618-b1a7-320210dfc02d
I0714 05:35:39.141984       1 cache.go:1363] There are <0> Jobs, <1> Queues and <5> Nodes in total for scheduling.
I0714 05:35:39.142170       1 session.go:190] Open Session e1bdfa99-59c7-4134-b9b7-b583e862f674 with <0> Job and <1> Queues
I0714 05:35:39.143905       1 enqueue.go:79] Try to enqueue PodGroup to 0 Queues
I0714 05:35:39.143972       1 allocate.go:64] Try to allocate resource to 0 Queues
I0714 05:35:39.144179       1 session.go:244] Close Session e1bdfa99-59c7-4134-b9b7-b583e862f674
I0714 05:35:40.146679       1 cache.go:1363] There are <0> Jobs, <1> Queues and <5> Nodes in total for scheduling.
I0714 05:35:40.146862       1 session.go:190] Open Session 346423e5-3617-4ace-819e-0d7be71f070e with <0> Job and <1> Queues
I0714 05:35:40.148693       1 enqueue.go:79] Try to enqueue PodGroup to 0 Queues
I0714 05:35:40.148769       1 allocate.go:64] Try to allocate resource to 0 Queues
I0714 05:35:40.149014       1 session.go:244] Close Session 346423e5-3617-4ace-819e-0d7be71f070e
I0714 05:35:41.151471       1 cache.go:1363] There are <0> Jobs, <1> Queues and <5> Nodes in total for scheduling.
I0714 05:35:41.151636       1 session.go:190] Open Session d4387a12-532f-43b1-b288-513ac727c192 with <0> Job and <1> Queues
I0714 05:35:41.153432       1 enqueue.go:79] Try to enqueue PodGroup to 0 Queues
I0714 05:35:41.153501       1 allocate.go:64] Try to allocate resource to 0 Queues
I0714 05:35:41.153729       1 session.go:244] Close Session d4387a12-532f-43b1-b288-513ac727c192
I0714 05:35:42.154877       1 cache.go:1363] There are <0> Jobs, <1> Queues and <5> Nodes in total for scheduling.
I0714 05:35:42.154960       1 session.go:190] Open Session f743a492-e9e9-4d7b-853e-58b55d4a793a with <0> Job and <1> Queues
I0714 05:35:42.155733       1 enqueue.go:79] Try to enqueue PodGroup to 0 Queues
I0714 05:35:42.155769       1 allocate.go:64] Try to allocate resource to 0 Queues
I0714 05:35:42.155863       1 session.go:244] Close Session f743a492-e9e9-4d7b-853e-58b55d4a793a
I0714 05:35:43.158859       1 cache.go:1363] There are <0> Jobs, <1> Queues and <5> Nodes in total for scheduling.
I0714 05:35:43.159030       1 session.go:190] Open Session c4619829-ab52-4186-be10-6deb2d0a0f2e with <0> Job and <1> Queues
I0714 05:35:43.160764       1 enqueue.go:79] Try to enqueue PodGroup to 0 Queues
I0714 05:35:43.160834       1 allocate.go:64] Try to allocate resource to 0 Queues
I0714 05:35:43.161061       1 session.go:244] Close Session c4619829-ab52-4186-be10-6deb2d0a0f2e
I0714 05:35:44.163757       1 cache.go:1363] There are <0> Jobs, <1> Queues and <5> Nodes in total for scheduling.
I0714 05:35:44.163943       1 session.go:190] Open Session 6e496e58-b844-4fee-aa8b-1db13b1cb86e with <0> Job and <1> Queues
I0714 05:35:44.165807       1 enqueue.go:79] Try to enqueue PodGroup to 0 Queues
I0714 05:35:44.165877       1 allocate.go:64] Try to allocate resource to 0 Queues
I0714 05:35:44.166113       1 session.go:244] Close Session 6e496e58-b844-4fee-aa8b-1db13b1cb86e
I0714 05:35:45.169076       1 cache.go:1363] There are <0> Jobs, <1> Queues and <5> Nodes in total for scheduling.
I0714 05:35:45.169253       1 session.go:190] Open Session 42468e39-e9bf-4909-a7ad-6926f8fd456b with <0> Job and <1> Queues
I0714 05:35:45.171001       1 enqueue.go:79] Try to enqueue PodGroup to 0 Queues
I0714 05:35:45.171080       1 allocate.go:64] Try to allocate resource to 0 Queues
I0714 05:35:45.171303       1 session.go:244] Close Session 42468e39-e9bf-4909-a7ad-6926f8fd456b
I0714 05:35:46.174100       1 cache.go:1363] There are <0> Jobs, <1> Queues and <5> Nodes in total for scheduling.
I0714 05:35:46.174267       1 session.go:190] Open Session 04c20bc1-1b3b-4da8-978b-64b30bc7d5fe with <0> Job and <1> Queues
I0714 05:35:46.176116       1 enqueue.go:79] Try to enqueue PodGroup to 0 Queues
I0714 05:35:46.176185       1 allocate.go:64] Try to allocate resource to 0 Queues
I0714 05:35:46.176483       1 session.go:244] Close Session 04c20bc1-1b3b-4da8-978b-64b30bc7d5fe
I0714 05:35:47.177860       1 cache.go:1363] There are <0> Jobs, <1> Queues and <5> Nodes in total for scheduling.
I0714 05:35:47.177944       1 session.go:190] Open Session c7f88de1-3555-4ac3-b775-a52acf495a41 with <0> Job and <1> Queues
I0714 05:35:47.178722       1 enqueue.go:79] Try to enqueue PodGroup to 0 Queues
I0714 05:35:47.178759       1 allocate.go:64] Try to allocate resource to 0 Queues
I0714 05:35:47.178853       1 session.go:244] Close Session c7f88de1-3555-4ac3-b775-a52acf495a41
I0714 05:35:48.181543       1 cache.go:1363] There are <0> Jobs, <1> Queues and <5> Nodes in total for scheduling.
I0714 05:35:48.181714       1 session.go:190] Open Session 846c3b90-c5ac-4f6a-b956-683d1cc66b7c with <0> Job and <1> Queues
I0714 05:35:48.183446       1 enqueue.go:79] Try to enqueue PodGroup to 0 Queues
I0714 05:35:48.183514       1 allocate.go:64] Try to allocate resource to 0 Queues
I0714 05:35:48.183751       1 session.go:244] Close Session 846c3b90-c5ac-4f6a-b956-683d1cc66b7c
I0714 05:35:49.186377       1 cache.go:1363] There are <0> Jobs, <1> Queues and <5> Nodes in total for scheduling.
I0714 05:35:49.186551       1 session.go:190] Open Session 96a61e7d-5ef0-4240-89c8-76165a3f17c1 with <0> Job and <1> Queues
I0714 05:35:49.188275       1 enqueue.go:79] Try to enqueue PodGroup to 0 Queues
I0714 05:35:49.188391       1 allocate.go:64] Try to allocate resource to 0 Queues
I0714 05:35:49.188610       1 session.go:244] Close Session 96a61e7d-5ef0-4240-89c8-76165a3f17c1
I0714 05:35:50.191595       1 cache.go:1363] There are <0> Jobs, <1> Queues and <5> Nodes in total for scheduling.
I0714 05:35:50.191768       1 session.go:190] Open Session a3b8757a-a70f-427f-b371-a52df0f0df6f with <0> Job and <1> Queues
I0714 05:35:50.193669       1 enqueue.go:79] Try to enqueue PodGroup to 0 Queues
I0714 05:35:50.193742       1 allocate.go:64] Try to allocate resource to 0 Queues
I0714 05:35:50.193961       1 session.go:244] Close Session a3b8757a-a70f-427f-b371-a52df0f0df6f
I0714 05:35:51.196848       1 cache.go:1363] There are <0> Jobs, <1> Queues and <5> Nodes in total for scheduling.
I0714 05:35:51.197033       1 session.go:190] Open Session 8a4cb531-c5d0-47b6-be83-355a2a90c8c1 with <0> Job and <1> Queues
I0714 05:35:51.198920       1 enqueue.go:79] Try to enqueue PodGroup to 0 Queues
I0714 05:35:51.198988       1 allocate.go:64] Try to allocate resource to 0 Queues
I0714 05:35:51.199208       1 session.go:244] Close Session 8a4cb531-c5d0-47b6-be83-355a2a90c8c1
I0714 05:35:52.200735       1 cache.go:1363] There are <0> Jobs, <1> Queues and <5> Nodes in total for scheduling.
I0714 05:35:52.200813       1 session.go:190] Open Session 7dcea66f-c540-4238-91d8-86f7078d58ba with <0> Job and <1> Queues
I0714 05:35:52.201641       1 enqueue.go:79] Try to enqueue PodGroup to 0 Queues
I0714 05:35:52.201683       1 allocate.go:64] Try to allocate resource to 0 Queues
I0714 05:35:52.201788       1 session.go:244] Close Session 7dcea66f-c540-4238-91d8-86f7078d58ba
I0714 05:35:53.204793       1 cache.go:1363] There are <0> Jobs, <1> Queues and <5> Nodes in total for scheduling.
I0714 05:35:53.204975       1 session.go:190] Open Session bfaaebe9-a17c-47d9-aec9-29a409d85876 with <0> Job and <1> Queues
I0714 05:35:53.206882       1 enqueue.go:79] Try to enqueue PodGroup to 0 Queues
I0714 05:35:53.206965       1 allocate.go:64] Try to allocate resource to 0 Queues
I0714 05:35:53.207194       1 session.go:244] Close Session bfaaebe9-a17c-47d9-aec9-29a409d85876
I0714 05:35:54.209736       1 cache.go:1363] There are <0> Jobs, <1> Queues and <5> Nodes in total for scheduling.
I0714 05:35:54.209905       1 session.go:190] Open Session f32a6fdb-07a1-42c4-8b77-839c57fd7740 with <0> Job and <1> Queues
I0714 05:35:54.211701       1 enqueue.go:79] Try to enqueue PodGroup to 0 Queues
I0714 05:35:54.211768       1 allocate.go:64] Try to allocate resource to 0 Queues
I0714 05:35:54.212001       1 session.go:244] Close Session f32a6fdb-07a1-42c4-8b77-839c57fd7740
I0714 05:35:55.214688       1 cache.go:1363] There are <0> Jobs, <1> Queues and <5> Nodes in total for scheduling.
I0714 05:35:55.214865       1 session.go:190] Open Session dbd4ba1c-b8ae-4b44-94ad-634c6e2abf01 with <0> Job and <1> Queues
I0714 05:35:55.216677       1 enqueue.go:79] Try to enqueue PodGroup to 0 Queues
I0714 05:35:55.216745       1 allocate.go:64] Try to allocate resource to 0 Queues
I0714 05:35:55.216974       1 session.go:244] Close Session dbd4ba1c-b8ae-4b44-94ad-634c6e2abf01
I0714 05:35:56.220035       1 cache.go:1363] There are <0> Jobs, <1> Queues and <5> Nodes in total for scheduling.
I0714 05:35:56.220212       1 session.go:190] Open Session 77e66d86-f33e-4460-a53c-ad9691172549 with <0> Job and <1> Queues
I0714 05:35:56.221986       1 enqueue.go:79] Try to enqueue PodGroup to 0 Queues
I0714 05:35:56.222057       1 allocate.go:64] Try to allocate resource to 0 Queues
I0714 05:35:56.222273       1 session.go:244] Close Session 77e66d86-f33e-4460-a53c-ad9691172549
I0714 05:35:57.225003       1 cache.go:1363] There are <0> Jobs, <1> Queues and <5> Nodes in total for scheduling.
I0714 05:35:57.225176       1 session.go:190] Open Session cd6ed71e-3b10-4a2e-80f8-bc6e821b460f with <0> Job and <1> Queues
I0714 05:35:57.226887       1 enqueue.go:79] Try to enqueue PodGroup to 0 Queues
I0714 05:35:57.226969       1 allocate.go:64] Try to allocate resource to 0 Queues
I0714 05:35:57.227190       1 session.go:244] Close Session cd6ed71e-3b10-4a2e-80f8-bc6e821b460f
I0714 05:35:58.229785       1 cache.go:1363] There are <0> Jobs, <1> Queues and <5> Nodes in total for scheduling.
I0714 05:35:58.229958       1 session.go:190] Open Session 232cf89f-92b7-4649-acc6-c80943a88f76 with <0> Job and <1> Queues
I0714 05:35:58.231710       1 enqueue.go:79] Try to enqueue PodGroup to 0 Queues
I0714 05:35:58.231781       1 allocate.go:64] Try to allocate resource to 0 Queues
I0714 05:35:58.231986       1 session.go:244] Close Session 232cf89f-92b7-4649-acc6-c80943a88f76
I0714 05:35:59.234881       1 cache.go:1363] There are <0> Jobs, <1> Queues and <5> Nodes in total for scheduling.
I0714 05:35:59.235069       1 session.go:190] Open Session 7b5a0707-7e4c-49b9-80b5-4bd0b95985eb with <0> Job and <1> Queues
I0714 05:35:59.236920       1 enqueue.go:79] Try to enqueue PodGroup to 0 Queues
I0714 05:35:59.236991       1 allocate.go:64] Try to allocate resource to 0 Queues
I0714 05:35:59.237209       1 session.go:244] Close Session 7b5a0707-7e4c-49b9-80b5-4bd0b95985eb
I0714 05:36:00.239819       1 cache.go:1363] There are <0> Jobs, <1> Queues and <5> Nodes in total for scheduling.
I0714 05:36:00.240007       1 session.go:190] Open Session e54104c8-f92d-4110-b033-897cc4a73c43 with <0> Job and <1> Queues
I0714 05:36:00.241943       1 enqueue.go:79] Try to enqueue PodGroup to 0 Queues
I0714 05:36:00.242014       1 allocate.go:64] Try to allocate resource to 0 Queues
I0714 05:36:00.242224       1 session.go:244] Close Session e54104c8-f92d-4110-b033-897cc4a73c43
I0714 05:36:01.244946       1 cache.go:1363] There are <0> Jobs, <1> Queues and <5> Nodes in total for scheduling.
I0714 05:36:01.245124       1 session.go:190] Open Session c50613ea-7087-4b32-ba84-7a7a020ae95b with <0> Job and <1> Queues
I0714 05:36:01.246953       1 enqueue.go:79] Try to enqueue PodGroup to 0 Queues
I0714 05:36:01.247025       1 allocate.go:64] Try to allocate resource to 0 Queues
I0714 05:36:01.247259       1 session.go:244] Close Session c50613ea-7087-4b32-ba84-7a7a020ae95b
I0714 05:36:02.250273       1 cache.go:1363] There are <0> Jobs, <1> Queues and <5> Nodes in total for scheduling.
I0714 05:36:02.250460       1 session.go:190] Open Session 087383ee-2246-4a3a-a1ee-c5d667a2d434 with <0> Job and <1> Queues
I0714 05:36:02.252249       1 enqueue.go:79] Try to enqueue PodGroup to 0 Queues
I0714 05:36:02.252359       1 allocate.go:64] Try to allocate resource to 0 Queues
I0714 05:36:02.252606       1 session.go:244] Close Session 087383ee-2246-4a3a-a1ee-c5d667a2d434
I0714 05:36:03.254696       1 cache.go:1363] There are <0> Jobs, <1> Queues and <5> Nodes in total for scheduling.
I0714 05:36:03.254905       1 session.go:190] Open Session f16ff949-9da1-4525-ae10-1e8852c7f391 with <0> Job and <1> Queues
I0714 05:36:03.256812       1 enqueue.go:79] Try to enqueue PodGroup to 0 Queues
I0714 05:36:03.256897       1 allocate.go:64] Try to allocate resource to 0 Queues
I0714 05:36:03.257123       1 session.go:244] Close Session f16ff949-9da1-4525-ae10-1e8852c7f391
I0714 05:36:04.259671       1 cache.go:1363] There are <0> Jobs, <1> Queues and <5> Nodes in total for scheduling.
I0714 05:36:04.259838       1 session.go:190] Open Session 7adba1cf-ec23-431b-a615-8a662b9fa565 with <0> Job and <1> Queues
I0714 05:36:04.261801       1 enqueue.go:79] Try to enqueue PodGroup to 0 Queues
I0714 05:36:04.261873       1 allocate.go:64] Try to allocate resource to 0 Queues
I0714 05:36:04.262090       1 session.go:244] Close Session 7adba1cf-ec23-431b-a615-8a662b9fa565
I0714 05:36:05.264943       1 cache.go:1363] There are <0> Jobs, <1> Queues and <5> Nodes in total for scheduling.
I0714 05:36:05.265096       1 session.go:190] Open Session d8802fd9-9373-4209-a62a-bbc410aedde4 with <0> Job and <1> Queues
I0714 05:36:05.266806       1 enqueue.go:79] Try to enqueue PodGroup to 0 Queues
I0714 05:36:05.266882       1 allocate.go:64] Try to allocate resource to 0 Queues
I0714 05:36:05.267097       1 session.go:244] Close Session d8802fd9-9373-4209-a62a-bbc410aedde4
I0714 05:36:06.273612       1 cache.go:1363] There are <0> Jobs, <1> Queues and <5> Nodes in total for scheduling.
I0714 05:36:06.273856       1 session.go:190] Open Session fa4bc32a-3f33-4f61-9920-de33ac5c28a3 with <0> Job and <1> Queues
I0714 05:36:06.275856       1 enqueue.go:79] Try to enqueue PodGroup to 0 Queues
I0714 05:36:06.275930       1 allocate.go:64] Try to allocate resource to 0 Queues
I0714 05:36:06.276161       1 session.go:244] Close Session fa4bc32a-3f33-4f61-9920-de33ac5c28a3
I0714 05:36:06.282098       1 cache.go:1489] The metrics type is not set in the volcano scheduler configmap file. As a result, the CPU and memory load information of the node is not collected.
I0714 05:36:07.278468       1 cache.go:1363] There are <0> Jobs, <1> Queues and <5> Nodes in total for scheduling.
I0714 05:36:07.278631       1 session.go:190] Open Session df744ee2-71af-4529-a9f4-bcdecf13fde4 with <0> Job and <1> Queues
I0714 05:36:07.280451       1 enqueue.go:79] Try to enqueue PodGroup to 0 Queues
I0714 05:36:07.280524       1 allocate.go:64] Try to allocate resource to 0 Queues
I0714 05:36:07.280719       1 session.go:244] Close Session df744ee2-71af-4529-a9f4-bcdecf13fde4
I0714 05:36:08.283232       1 cache.go:1363] There are <0> Jobs, <1> Queues and <5> Nodes in total for scheduling.
I0714 05:36:08.283399       1 session.go:190] Open Session 9a63fdb7-10a0-4c80-b4b1-37da21c860a7 with <0> Job and <1> Queues
I0714 05:36:08.285191       1 enqueue.go:79] Try to enqueue PodGroup to 0 Queues
I0714 05:36:08.285262       1 allocate.go:64] Try to allocate resource to 0 Queues
I0714 05:36:08.285481       1 session.go:244] Close Session 9a63fdb7-10a0-4c80-b4b1-37da21c860a7
I0714 05:36:09.287902       1 cache.go:1363] There are <0> Jobs, <1> Queues and <5> Nodes in total for scheduling.
I0714 05:36:09.288141       1 session.go:190] Open Session 99a66929-f2b4-4e52-8659-74f321775d15 with <0> Job and <1> Queues
I0714 05:36:09.289962       1 enqueue.go:79] Try to enqueue PodGroup to 0 Queues
I0714 05:36:09.290035       1 allocate.go:64] Try to allocate resource to 0 Queues
I0714 05:36:09.290258       1 session.go:244] Close Session 99a66929-f2b4-4e52-8659-74f321775d15
I0714 05:36:10.293083       1 cache.go:1363] There are <0> Jobs, <1> Queues and <5> Nodes in total for scheduling.
I0714 05:36:10.293309       1 session.go:190] Open Session 5b0c1ec1-a2e5-46d7-84d7-ae5d56403680 with <0> Job and <1> Queues
I0714 05:36:10.295116       1 enqueue.go:79] Try to enqueue PodGroup to 0 Queues
I0714 05:36:10.295183       1 allocate.go:64] Try to allocate resource to 0 Queues
I0714 05:36:10.295412       1 session.go:244] Close Session 5b0c1ec1-a2e5-46d7-84d7-ae5d56403680
I0714 05:36:11.298099       1 cache.go:1363] There are <0> Jobs, <1> Queues and <5> Nodes in total for scheduling.
I0714 05:36:11.298299       1 session.go:190] Open Session 20967343-abef-4266-b087-e943fa4bb571 with <0> Job and <1> Queues
I0714 05:36:11.300181       1 enqueue.go:79] Try to enqueue PodGroup to 0 Queues
I0714 05:36:11.300253       1 allocate.go:64] Try to allocate resource to 0 Queues
I0714 05:36:11.300531       1 session.go:244] Close Session 20967343-abef-4266-b087-e943fa4bb571
I0714 05:36:12.302631       1 cache.go:1363] There are <0> Jobs, <1> Queues and <5> Nodes in total for scheduling.
I0714 05:36:12.302813       1 session.go:190] Open Session 0bbd15c8-9789-4e57-9ae0-5a5777789cdb with <0> Job and <1> Queues
I0714 05:36:12.304423       1 enqueue.go:79] Try to enqueue PodGroup to 0 Queues
I0714 05:36:12.304491       1 allocate.go:64] Try to allocate resource to 0 Queues
I0714 05:36:12.304698       1 session.go:244] Close Session 0bbd15c8-9789-4e57-9ae0-5a5777789cdb
I0714 05:36:13.307241       1 cache.go:1363] There are <0> Jobs, <1> Queues and <5> Nodes in total for scheduling.
I0714 05:36:13.307410       1 session.go:190] Open Session 186c6a2e-6306-4a91-8372-33ccf9061348 with <0> Job and <1> Queues
I0714 05:36:13.309201       1 enqueue.go:79] Try to enqueue PodGroup to 0 Queues
I0714 05:36:13.309279       1 allocate.go:64] Try to allocate resource to 0 Queues
I0714 05:36:13.309505       1 session.go:244] Close Session 186c6a2e-6306-4a91-8372-33ccf9061348
I0714 05:36:14.311881       1 cache.go:1363] There are <0> Jobs, <1> Queues and <5> Nodes in total for scheduling.
I0714 05:36:14.312069       1 session.go:190] Open Session 36e3d958-dc7a-495d-8457-abad5f20cd11 with <0> Job and <1> Queues
I0714 05:36:14.313883       1 enqueue.go:79] Try to enqueue PodGroup to 0 Queues
I0714 05:36:14.313973       1 allocate.go:64] Try to allocate resource to 0 Queues
I0714 05:36:14.314192       1 session.go:244] Close Session 36e3d958-dc7a-495d-8457-abad5f20cd11
I0714 05:36:15.316634       1 cache.go:1363] There are <0> Jobs, <1> Queues and <5> Nodes in total for scheduling.
I0714 05:36:15.316786       1 session.go:190] Open Session 46d9a823-04f6-4a4b-a690-a407582fb78d with <0> Job and <1> Queues
I0714 05:36:15.318501       1 enqueue.go:79] Try to enqueue PodGroup to 0 Queues
I0714 05:36:15.318580       1 allocate.go:64] Try to allocate resource to 0 Queues
I0714 05:36:15.318797       1 session.go:244] Close Session 46d9a823-04f6-4a4b-a690-a407582fb78d
I0714 05:36:16.321467       1 cache.go:1363] There are <0> Jobs, <1> Queues and <5> Nodes in total for scheduling.
I0714 05:36:16.321618       1 session.go:190] Open Session 3702bcfe-8cf0-4149-a807-50324eb721ed with <0> Job and <1> Queues
I0714 05:36:16.323258       1 enqueue.go:79] Try to enqueue PodGroup to 0 Queues
I0714 05:36:16.323328       1 allocate.go:64] Try to allocate resource to 0 Queues
I0714 05:36:16.323558       1 session.go:244] Close Session 3702bcfe-8cf0-4149-a807-50324eb721ed
I0714 05:36:17.326408       1 cache.go:1363] There are <0> Jobs, <1> Queues and <5> Nodes in total for scheduling.
I0714 05:36:17.326606       1 session.go:190] Open Session 2455e2b1-ee53-498b-8dbb-a72b2ba0cb1f with <0> Job and <1> Queues
I0714 05:36:17.328538       1 enqueue.go:79] Try to enqueue PodGroup to 0 Queues
I0714 05:36:17.328632       1 allocate.go:64] Try to allocate resource to 0 Queues
I0714 05:36:17.328842       1 session.go:244] Close Session 2455e2b1-ee53-498b-8dbb-a72b2ba0cb1f
I0714 05:36:18.331244       1 cache.go:1363] There are <0> Jobs, <1> Queues and <5> Nodes in total for scheduling.
I0714 05:36:18.331413       1 session.go:190] Open Session 443e549a-ebc0-459a-abd8-b4f9791bf676 with <0> Job and <1> Queues
I0714 05:36:18.333263       1 enqueue.go:79] Try to enqueue PodGroup to 0 Queues
I0714 05:36:18.333333       1 allocate.go:64] Try to allocate resource to 0 Queues
I0714 05:36:18.333552       1 session.go:244] Close Session 443e549a-ebc0-459a-abd8-b4f9791bf676
I0714 05:36:19.336279       1 cache.go:1363] There are <0> Jobs, <1> Queues and <5> Nodes in total for scheduling.
I0714 05:36:19.336487       1 session.go:190] Open Session 0f91b569-ccd1-4834-96b0-e7a211718a52 with <0> Job and <1> Queues
I0714 05:36:19.338314       1 enqueue.go:79] Try to enqueue PodGroup to 0 Queues
I0714 05:36:19.338380       1 allocate.go:64] Try to allocate resource to 0 Queues
I0714 05:36:19.338615       1 session.go:244] Close Session 0f91b569-ccd1-4834-96b0-e7a211718a52
I0714 05:36:20.341030       1 cache.go:1363] There are <0> Jobs, <1> Queues and <5> Nodes in total for scheduling.
I0714 05:36:20.341195       1 session.go:190] Open Session 7299670c-0811-4cd8-8e6a-4f67e3fec342 with <0> Job and <1> Queues
I0714 05:36:20.342953       1 enqueue.go:79] Try to enqueue PodGroup to 0 Queues
I0714 05:36:20.343020       1 allocate.go:64] Try to allocate resource to 0 Queues
I0714 05:36:20.343248       1 session.go:244] Close Session 7299670c-0811-4cd8-8e6a-4f67e3fec342
I0714 05:36:21.345979       1 cache.go:1363] There are <0> Jobs, <1> Queues and <5> Nodes in total for scheduling.
I0714 05:36:21.346145       1 session.go:190] Open Session c429f890-c512-4ceb-8f7f-c60a6e52b328 with <0> Job and <1> Queues
I0714 05:36:21.347866       1 enqueue.go:79] Try to enqueue PodGroup to 0 Queues
I0714 05:36:21.347937       1 allocate.go:64] Try to allocate resource to 0 Queues
I0714 05:36:21.348157       1 session.go:244] Close Session c429f890-c512-4ceb-8f7f-c60a6e52b328
I0714 05:36:22.351029       1 cache.go:1363] There are <0> Jobs, <1> Queues and <5> Nodes in total for scheduling.
I0714 05:36:22.351188       1 session.go:190] Open Session b28eac4f-4911-4efd-b6be-f982e2cc2d79 with <0> Job and <1> Queues
I0714 05:36:22.353127       1 enqueue.go:79] Try to enqueue PodGroup to 0 Queues
I0714 05:36:22.353197       1 allocate.go:64] Try to allocate resource to 0 Queues
I0714 05:36:22.353407       1 session.go:244] Close Session b28eac4f-4911-4efd-b6be-f982e2cc2d79
I0714 05:36:23.355953       1 cache.go:1363] There are <0> Jobs, <1> Queues and <5> Nodes in total for scheduling.
I0714 05:36:23.356125       1 session.go:190] Open Session 407f56b6-fe50-45f3-95f7-a26cb2311759 with <0> Job and <1> Queues
I0714 05:36:23.357999       1 enqueue.go:79] Try to enqueue PodGroup to 0 Queues
I0714 05:36:23.358067       1 allocate.go:64] Try to allocate resource to 0 Queues
I0714 05:36:23.358280       1 session.go:244] Close Session 407f56b6-fe50-45f3-95f7-a26cb2311759
I0714 05:36:24.360358       1 cache.go:1363] There are <0> Jobs, <1> Queues and <5> Nodes in total for scheduling.
I0714 05:36:24.360517       1 session.go:190] Open Session e435f85f-8f4f-4507-bbd6-ad48b64ae901 with <0> Job and <1> Queues
I0714 05:36:24.362260       1 enqueue.go:79] Try to enqueue PodGroup to 0 Queues
I0714 05:36:24.362329       1 allocate.go:64] Try to allocate resource to 0 Queues
I0714 05:36:24.362554       1 session.go:244] Close Session e435f85f-8f4f-4507-bbd6-ad48b64ae901
I0714 05:36:25.365378       1 cache.go:1363] There are <0> Jobs, <1> Queues and <5> Nodes in total for scheduling.
I0714 05:36:25.365555       1 session.go:190] Open Session 1454cf8d-da70-4e9f-a060-787b6eaaaca0 with <0> Job and <1> Queues
I0714 05:36:25.367251       1 enqueue.go:79] Try to enqueue PodGroup to 0 Queues
I0714 05:36:25.367318       1 allocate.go:64] Try to allocate resource to 0 Queues
I0714 05:36:25.367538       1 session.go:244] Close Session 1454cf8d-da70-4e9f-a060-787b6eaaaca0
I0714 05:36:26.369581       1 cache.go:1363] There are <0> Jobs, <1> Queues and <5> Nodes in total for scheduling.
I0714 05:36:26.369760       1 session.go:190] Open Session 307ac487-24a6-4cbf-a69b-0ab4a6a39c29 with <0> Job and <1> Queues
I0714 05:36:26.371514       1 enqueue.go:79] Try to enqueue PodGroup to 0 Queues
I0714 05:36:26.371581       1 allocate.go:64] Try to allocate resource to 0 Queues
I0714 05:36:26.371800       1 session.go:244] Close Session 307ac487-24a6-4cbf-a69b-0ab4a6a39c29
I0714 05:36:27.374415       1 cache.go:1363] There are <0> Jobs, <1> Queues and <5> Nodes in total for scheduling.
I0714 05:36:27.374571       1 session.go:190] Open Session 40542437-0e14-4828-be40-fdbbbd70eb8d with <0> Job and <1> Queues
I0714 05:36:27.376388       1 enqueue.go:79] Try to enqueue PodGroup to 0 Queues
I0714 05:36:27.376453       1 allocate.go:64] Try to allocate resource to 0 Queues
I0714 05:36:27.376673       1 session.go:244] Close Session 40542437-0e14-4828-be40-fdbbbd70eb8d
I0714 05:36:28.379172       1 cache.go:1363] There are <0> Jobs, <1> Queues and <5> Nodes in total for scheduling.
I0714 05:36:28.379354       1 session.go:190] Open Session 911c9aca-f520-40ad-ba9a-c6fcce4c5683 with <0> Job and <1> Queues
I0714 05:36:28.381194       1 enqueue.go:79] Try to enqueue PodGroup to 0 Queues
I0714 05:36:28.381261       1 allocate.go:64] Try to allocate resource to 0 Queues
I0714 05:36:28.381474       1 session.go:244] Close Session 911c9aca-f520-40ad-ba9a-c6fcce4c5683
I0714 05:36:29.384559       1 cache.go:1363] There are <0> Jobs, <1> Queues and <5> Nodes in total for scheduling.
I0714 05:36:29.384725       1 session.go:190] Open Session 2224fc9c-504f-4ef8-8c00-cfcd1904ec2e with <0> Job and <1> Queues
I0714 05:36:29.386763       1 enqueue.go:79] Try to enqueue PodGroup to 0 Queues
I0714 05:36:29.386821       1 allocate.go:64] Try to allocate resource to 0 Queues
I0714 05:36:29.387016       1 session.go:244] Close Session 2224fc9c-504f-4ef8-8c00-cfcd1904ec2e
I0714 05:36:30.389798       1 cache.go:1363] There are <0> Jobs, <1> Queues and <5> Nodes in total for scheduling.
I0714 05:36:30.389966       1 session.go:190] Open Session a81e3be1-cdcd-4f36-aa75-c1b49e9d9aa0 with <0> Job and <1> Queues
I0714 05:36:30.391862       1 enqueue.go:79] Try to enqueue PodGroup to 0 Queues
I0714 05:36:30.391945       1 allocate.go:64] Try to allocate resource to 0 Queues
I0714 05:36:30.392172       1 session.go:244] Close Session a81e3be1-cdcd-4f36-aa75-c1b49e9d9aa0
I0714 05:36:31.394419       1 cache.go:1363] There are <0> Jobs, <1> Queues and <5> Nodes in total for scheduling.
I0714 05:36:31.394592       1 session.go:190] Open Session 55e506d3-27dc-4efb-9f59-519730754b2f with <0> Job and <1> Queues
I0714 05:36:31.396566       1 enqueue.go:79] Try to enqueue PodGroup to 0 Queues
I0714 05:36:31.396637       1 allocate.go:64] Try to allocate resource to 0 Queues
I0714 05:36:31.396848       1 session.go:244] Close Session 55e506d3-27dc-4efb-9f59-519730754b2f
I0714 05:36:32.399303       1 cache.go:1363] There are <0> Jobs, <1> Queues and <5> Nodes in total for scheduling.
I0714 05:36:32.399460       1 session.go:190] Open Session d64dd7a0-a22c-4e00-86d2-78522a0711af with <0> Job and <1> Queues
I0714 05:36:32.401156       1 enqueue.go:79] Try to enqueue PodGroup to 0 Queues
I0714 05:36:32.401223       1 allocate.go:64] Try to allocate resource to 0 Queues
I0714 05:36:32.401431       1 session.go:244] Close Session d64dd7a0-a22c-4e00-86d2-78522a0711af
I0714 05:36:33.404189       1 cache.go:1363] There are <0> Jobs, <1> Queues and <5> Nodes in total for scheduling.
I0714 05:36:33.404401       1 session.go:190] Open Session da90f17d-d21b-4440-8ade-a96aa60c7cee with <0> Job and <1> Queues
I0714 05:36:33.406161       1 enqueue.go:79] Try to enqueue PodGroup to 0 Queues
I0714 05:36:33.406228       1 allocate.go:64] Try to allocate resource to 0 Queues
I0714 05:36:33.406464       1 session.go:244] Close Session da90f17d-d21b-4440-8ade-a96aa60c7cee
I0714 05:36:34.409475       1 cache.go:1363] There are <0> Jobs, <1> Queues and <5> Nodes in total for scheduling.
I0714 05:36:34.409650       1 session.go:190] Open Session b91660b1-5345-4ec3-9838-31680bd9fb8d with <0> Job and <1> Queues
I0714 05:36:34.411431       1 enqueue.go:79] Try to enqueue PodGroup to 0 Queues
I0714 05:36:34.411494       1 allocate.go:64] Try to allocate resource to 0 Queues
I0714 05:36:34.411734       1 session.go:244] Close Session b91660b1-5345-4ec3-9838-31680bd9fb8d
I0714 05:36:35.413921       1 cache.go:1363] There are <0> Jobs, <1> Queues and <5> Nodes in total for scheduling.
I0714 05:36:35.414098       1 session.go:190] Open Session a219d7a8-bbf4-4b6d-8969-82d064f464c8 with <0> Job and <1> Queues
I0714 05:36:35.415859       1 enqueue.go:79] Try to enqueue PodGroup to 0 Queues
I0714 05:36:35.415922       1 allocate.go:64] Try to allocate resource to 0 Queues
I0714 05:36:35.416130       1 session.go:244] Close Session a219d7a8-bbf4-4b6d-8969-82d064f464c8
I0714 05:36:36.283138       1 cache.go:1489] The metrics type is not set in the volcano scheduler configmap file. As a result, the CPU and memory load information of the node is not collected.
I0714 05:36:36.418129       1 cache.go:1363] There are <0> Jobs, <1> Queues and <5> Nodes in total for scheduling.
I0714 05:36:36.418248       1 session.go:190] Open Session 5139f1be-53d5-488f-986c-2d86902a5f40 with <0> Job and <1> Queues
I0714 05:36:36.420035       1 enqueue.go:79] Try to enqueue PodGroup to 0 Queues
I0714 05:36:36.420102       1 allocate.go:64] Try to allocate resource to 0 Queues
I0714 05:36:36.420380       1 session.go:244] Close Session 5139f1be-53d5-488f-986c-2d86902a5f40
I0714 05:36:37.422699       1 cache.go:1363] There are <0> Jobs, <1> Queues and <5> Nodes in total for scheduling.
I0714 05:36:37.422858       1 session.go:190] Open Session 6b44ab84-2501-4697-9372-77ecb5d291eb with <0> Job and <1> Queues
I0714 05:36:37.424788       1 enqueue.go:79] Try to enqueue PodGroup to 0 Queues
I0714 05:36:37.424872       1 allocate.go:64] Try to allocate resource to 0 Queues
I0714 05:36:37.425096       1 session.go:244] Close Session 6b44ab84-2501-4697-9372-77ecb5d291eb
I0714 05:36:38.427327       1 cache.go:1363] There are <0> Jobs, <1> Queues and <5> Nodes in total for scheduling.
I0714 05:36:38.427506       1 session.go:190] Open Session 15ed4c51-3137-4224-82ae-a601a3a6ba05 with <0> Job and <1> Queues
I0714 05:36:38.429311       1 enqueue.go:79] Try to enqueue PodGroup to 0 Queues
I0714 05:36:38.429393       1 allocate.go:64] Try to allocate resource to 0 Queues
I0714 05:36:38.429624       1 session.go:244] Close Session 15ed4c51-3137-4224-82ae-a601a3a6ba05
I0714 05:36:39.431834       1 cache.go:1363] There are <0> Jobs, <1> Queues and <5> Nodes in total for scheduling.
I0714 05:36:39.431994       1 session.go:190] Open Session 01167b51-2a7b-4898-b8f3-99ae22023c98 with <0> Job and <1> Queues
I0714 05:36:39.433748       1 enqueue.go:79] Try to enqueue PodGroup to 0 Queues
I0714 05:36:39.433842       1 allocate.go:64] Try to allocate resource to 0 Queues
I0714 05:36:39.434058       1 session.go:244] Close Session 01167b51-2a7b-4898-b8f3-99ae22023c98
I0714 05:36:40.435910       1 cache.go:1363] There are <0> Jobs, <1> Queues and <5> Nodes in total for scheduling.
I0714 05:36:40.436024       1 session.go:190] Open Session b60398e4-26d4-4aea-bd8c-3b5f60e00f89 with <0> Job and <1> Queues
I0714 05:36:40.437499       1 enqueue.go:79] Try to enqueue PodGroup to 0 Queues
I0714 05:36:40.437561       1 allocate.go:64] Try to allocate resource to 0 Queues
I0714 05:36:40.437748       1 session.go:244] Close Session b60398e4-26d4-4aea-bd8c-3b5f60e00f89
I0714 05:36:41.440362       1 cache.go:1363] There are <0> Jobs, <1> Queues and <5> Nodes in total for scheduling.
I0714 05:36:41.440495       1 session.go:190] Open Session 3338bcdd-5559-4f2f-b09c-da571cb95adb with <0> Job and <1> Queues
I0714 05:36:41.442028       1 enqueue.go:79] Try to enqueue PodGroup to 0 Queues
I0714 05:36:41.442096       1 allocate.go:64] Try to allocate resource to 0 Queues
I0714 05:36:41.442298       1 session.go:244] Close Session 3338bcdd-5559-4f2f-b09c-da571cb95adb
I0714 05:36:42.443945       1 cache.go:1363] There are <0> Jobs, <1> Queues and <5> Nodes in total for scheduling.
I0714 05:36:42.444071       1 session.go:190] Open Session 7b749378-1fab-4067-ba6f-ac2693662d8f with <0> Job and <1> Queues
I0714 05:36:42.445574       1 enqueue.go:79] Try to enqueue PodGroup to 0 Queues
I0714 05:36:42.445635       1 allocate.go:64] Try to allocate resource to 0 Queues
I0714 05:36:42.445830       1 session.go:244] Close Session 7b749378-1fab-4067-ba6f-ac2693662d8f
I0714 05:36:43.448210       1 cache.go:1363] There are <0> Jobs, <1> Queues and <5> Nodes in total for scheduling.
I0714 05:36:43.448445       1 session.go:190] Open Session b55870c3-4dde-42db-8522-775c1227f7a0 with <0> Job and <1> Queues
I0714 05:36:43.450287       1 enqueue.go:79] Try to enqueue PodGroup to 0 Queues
I0714 05:36:43.450377       1 allocate.go:64] Try to allocate resource to 0 Queues
I0714 05:36:43.450601       1 session.go:244] Close Session b55870c3-4dde-42db-8522-775c1227f7a0
I0714 05:36:44.453093       1 cache.go:1363] There are <0> Jobs, <1> Queues and <5> Nodes in total for scheduling.
I0714 05:36:44.453270       1 session.go:190] Open Session 76a89106-bf9d-4498-a962-d7501e931183 with <0> Job and <1> Queues
I0714 05:36:44.455049       1 enqueue.go:79] Try to enqueue PodGroup to 0 Queues
I0714 05:36:44.455141       1 allocate.go:64] Try to allocate resource to 0 Queues
I0714 05:36:44.455380       1 session.go:244] Close Session 76a89106-bf9d-4498-a962-d7501e931183
I0714 05:36:45.457537       1 cache.go:1363] There are <0> Jobs, <1> Queues and <5> Nodes in total for scheduling.
I0714 05:36:45.457720       1 session.go:190] Open Session 5df0ecea-fe8d-4b9d-b109-1891fa8e05dd with <0> Job and <1> Queues
I0714 05:36:45.459541       1 enqueue.go:79] Try to enqueue PodGroup to 0 Queues
I0714 05:36:45.459623       1 allocate.go:64] Try to allocate resource to 0 Queues
I0714 05:36:45.459836       1 session.go:244] Close Session 5df0ecea-fe8d-4b9d-b109-1891fa8e05dd
I0714 05:36:46.462446       1 cache.go:1363] There are <0> Jobs, <1> Queues and <5> Nodes in total for scheduling.
I0714 05:36:46.462616       1 session.go:190] Open Session f55f72f5-494a-4eaf-8edc-d60b12fb302e with <0> Job and <1> Queues
I0714 05:36:46.464366       1 enqueue.go:79] Try to enqueue PodGroup to 0 Queues
I0714 05:36:46.464446       1 allocate.go:64] Try to allocate resource to 0 Queues
I0714 05:36:46.464705       1 session.go:244] Close Session f55f72f5-494a-4eaf-8edc-d60b12fb302e
I0714 05:36:47.467449       1 cache.go:1363] There are <0> Jobs, <1> Queues and <5> Nodes in total for scheduling.
I0714 05:36:47.467601       1 session.go:190] Open Session 1ec54388-6c78-4ceb-80c4-f1e780955922 with <0> Job and <1> Queues
I0714 05:36:47.469326       1 enqueue.go:79] Try to enqueue PodGroup to 0 Queues
I0714 05:36:47.469404       1 allocate.go:64] Try to allocate resource to 0 Queues
I0714 05:36:47.469614       1 session.go:244] Close Session 1ec54388-6c78-4ceb-80c4-f1e780955922
I0714 05:36:48.471810       1 cache.go:1363] There are <0> Jobs, <1> Queues and <5> Nodes in total for scheduling.
I0714 05:36:48.471991       1 session.go:190] Open Session 5b258f34-d8d2-49f4-b978-7dc7e7a71311 with <0> Job and <1> Queues
I0714 05:36:48.473815       1 enqueue.go:79] Try to enqueue PodGroup to 0 Queues
I0714 05:36:48.473896       1 allocate.go:64] Try to allocate resource to 0 Queues
I0714 05:36:48.474124       1 session.go:244] Close Session 5b258f34-d8d2-49f4-b978-7dc7e7a71311
I0714 05:36:49.477074       1 cache.go:1363] There are <0> Jobs, <1> Queues and <5> Nodes in total for scheduling.
I0714 05:36:49.477236       1 session.go:190] Open Session 9f0781c4-c105-4d47-bc56-a515dab3d0d6 with <0> Job and <1> Queues
I0714 05:36:49.478978       1 enqueue.go:79] Try to enqueue PodGroup to 0 Queues
I0714 05:36:49.479047       1 allocate.go:64] Try to allocate resource to 0 Queues
I0714 05:36:49.479285       1 session.go:244] Close Session 9f0781c4-c105-4d47-bc56-a515dab3d0d6
I0714 05:36:50.481748       1 cache.go:1363] There are <0> Jobs, <1> Queues and <5> Nodes in total for scheduling.
I0714 05:36:50.481913       1 session.go:190] Open Session 65347f28-57ea-4a19-89d0-a3661f3ce6a0 with <0> Job and <1> Queues
I0714 05:36:50.483651       1 enqueue.go:79] Try to enqueue PodGroup to 0 Queues
I0714 05:36:50.483717       1 allocate.go:64] Try to allocate resource to 0 Queues
I0714 05:36:50.483945       1 session.go:244] Close Session 65347f28-57ea-4a19-89d0-a3661f3ce6a0
I0714 05:36:51.486777       1 cache.go:1363] There are <0> Jobs, <1> Queues and <5> Nodes in total for scheduling.
I0714 05:36:51.486989       1 session.go:190] Open Session efabbcec-e9e1-4418-a9ce-a87e19923794 with <0> Job and <1> Queues
I0714 05:36:51.488764       1 enqueue.go:79] Try to enqueue PodGroup to 0 Queues
I0714 05:36:51.488831       1 allocate.go:64] Try to allocate resource to 0 Queues
I0714 05:36:51.489049       1 session.go:244] Close Session efabbcec-e9e1-4418-a9ce-a87e19923794
I0714 05:36:52.491013       1 cache.go:1363] There are <0> Jobs, <1> Queues and <5> Nodes in total for scheduling.
I0714 05:36:52.491177       1 session.go:190] Open Session 38407303-248f-40f8-b346-1ef96fe079e4 with <0> Job and <1> Queues
I0714 05:36:52.492903       1 enqueue.go:79] Try to enqueue PodGroup to 0 Queues
I0714 05:36:52.492970       1 allocate.go:64] Try to allocate resource to 0 Queues
I0714 05:36:52.493192       1 session.go:244] Close Session 38407303-248f-40f8-b346-1ef96fe079e4
I0714 05:36:53.495566       1 cache.go:1363] There are <0> Jobs, <1> Queues and <5> Nodes in total for scheduling.
I0714 05:36:53.495736       1 session.go:190] Open Session ca4cfc82-2122-4d29-8430-8a247446165b with <0> Job and <1> Queues
I0714 05:36:53.497527       1 enqueue.go:79] Try to enqueue PodGroup to 0 Queues
I0714 05:36:53.497597       1 allocate.go:64] Try to allocate resource to 0 Queues
I0714 05:36:53.497822       1 session.go:244] Close Session ca4cfc82-2122-4d29-8430-8a247446165b
I0714 05:36:54.500269       1 cache.go:1363] There are <0> Jobs, <1> Queues and <5> Nodes in total for scheduling.
I0714 05:36:54.500468       1 session.go:190] Open Session 157248ee-e9d8-4a58-a334-633b993c1276 with <0> Job and <1> Queues
I0714 05:36:54.503717       1 enqueue.go:79] Try to enqueue PodGroup to 0 Queues
I0714 05:36:54.503822       1 allocate.go:64] Try to allocate resource to 0 Queues
I0714 05:36:54.504113       1 session.go:244] Close Session 157248ee-e9d8-4a58-a334-633b993c1276
I0714 05:36:55.506796       1 cache.go:1363] There are <0> Jobs, <1> Queues and <5> Nodes in total for scheduling.
I0714 05:36:55.506975       1 session.go:190] Open Session 809cc86e-1df5-4486-9e07-b61dc5b19a63 with <0> Job and <1> Queues
I0714 05:36:55.508795       1 enqueue.go:79] Try to enqueue PodGroup to 0 Queues
I0714 05:36:55.508873       1 allocate.go:64] Try to allocate resource to 0 Queues
I0714 05:36:55.509107       1 session.go:244] Close Session 809cc86e-1df5-4486-9e07-b61dc5b19a63
I0714 05:36:56.511425       1 cache.go:1363] There are <0> Jobs, <1> Queues and <5> Nodes in total for scheduling.
I0714 05:36:56.511605       1 session.go:190] Open Session f3a99117-1f2f-4bae-b966-a474ce470212 with <0> Job and <1> Queues
I0714 05:36:56.513385       1 enqueue.go:79] Try to enqueue PodGroup to 0 Queues
I0714 05:36:56.513460       1 allocate.go:64] Try to allocate resource to 0 Queues
I0714 05:36:56.513664       1 session.go:244] Close Session f3a99117-1f2f-4bae-b966-a474ce470212
I0714 05:36:57.515676       1 cache.go:1363] There are <0> Jobs, <1> Queues and <5> Nodes in total for scheduling.
I0714 05:36:57.515843       1 session.go:190] Open Session 7bba8ecb-46f6-47fc-86c5-4f0e7aab5718 with <0> Job and <1> Queues
I0714 05:36:57.517632       1 enqueue.go:79] Try to enqueue PodGroup to 0 Queues
I0714 05:36:57.517703       1 allocate.go:64] Try to allocate resource to 0 Queues
I0714 05:36:57.517903       1 session.go:244] Close Session 7bba8ecb-46f6-47fc-86c5-4f0e7aab5718
I0714 05:36:58.520684       1 cache.go:1363] There are <0> Jobs, <1> Queues and <5> Nodes in total for scheduling.
I0714 05:36:58.520863       1 session.go:190] Open Session 2a3c5d0b-7306-4bc0-aee0-6e034fdb5421 with <0> Job and <1> Queues
I0714 05:36:58.522638       1 enqueue.go:79] Try to enqueue PodGroup to 0 Queues
I0714 05:36:58.522719       1 allocate.go:64] Try to allocate resource to 0 Queues
I0714 05:36:58.522930       1 session.go:244] Close Session 2a3c5d0b-7306-4bc0-aee0-6e034fdb5421
I0714 05:36:59.525345       1 cache.go:1363] There are <0> Jobs, <1> Queues and <5> Nodes in total for scheduling.
I0714 05:36:59.525526       1 session.go:190] Open Session 35884cba-6977-49da-94c8-cc8225dbf69e with <0> Job and <1> Queues
I0714 05:36:59.527377       1 enqueue.go:79] Try to enqueue PodGroup to 0 Queues
I0714 05:36:59.527448       1 allocate.go:64] Try to allocate resource to 0 Queues
I0714 05:36:59.527675       1 session.go:244] Close Session 35884cba-6977-49da-94c8-cc8225dbf69e
I0714 05:37:00.529847       1 cache.go:1363] There are <0> Jobs, <1> Queues and <5> Nodes in total for scheduling.
I0714 05:37:00.530020       1 session.go:190] Open Session ff964c5f-e5b7-43d9-8633-e04ef40936b4 with <0> Job and <1> Queues
I0714 05:37:00.531827       1 enqueue.go:79] Try to enqueue PodGroup to 0 Queues
I0714 05:37:00.531896       1 allocate.go:64] Try to allocate resource to 0 Queues
I0714 05:37:00.532109       1 session.go:244] Close Session ff964c5f-e5b7-43d9-8633-e04ef40936b4
I0714 05:37:01.534709       1 cache.go:1363] There are <0> Jobs, <1> Queues and <5> Nodes in total for scheduling.
I0714 05:37:01.534874       1 session.go:190] Open Session 9ac4a4bd-32ff-4ff3-b413-451ae8a3dd5e with <0> Job and <1> Queues
I0714 05:37:01.536854       1 enqueue.go:79] Try to enqueue PodGroup to 0 Queues
I0714 05:37:01.536927       1 allocate.go:64] Try to allocate resource to 0 Queues
I0714 05:37:01.537143       1 session.go:244] Close Session 9ac4a4bd-32ff-4ff3-b413-451ae8a3dd5e
I0714 05:37:02.539363       1 cache.go:1363] There are <0> Jobs, <1> Queues and <5> Nodes in total for scheduling.
I0714 05:37:02.539525       1 session.go:190] Open Session b8dc76f4-a14a-4dab-8000-4c542aa44a25 with <0> Job and <1> Queues
I0714 05:37:02.541411       1 enqueue.go:79] Try to enqueue PodGroup to 0 Queues
I0714 05:37:02.541484       1 allocate.go:64] Try to allocate resource to 0 Queues
I0714 05:37:02.541694       1 session.go:244] Close Session b8dc76f4-a14a-4dab-8000-4c542aa44a25
I0714 05:37:03.544065       1 cache.go:1363] There are <0> Jobs, <1> Queues and <5> Nodes in total for scheduling.
I0714 05:37:03.544254       1 session.go:190] Open Session 055617c7-1394-4dbe-b5ca-1bcc7ec0d816 with <0> Job and <1> Queues
I0714 05:37:03.546054       1 enqueue.go:79] Try to enqueue PodGroup to 0 Queues
I0714 05:37:03.546133       1 allocate.go:64] Try to allocate resource to 0 Queues
I0714 05:37:03.546344       1 session.go:244] Close Session 055617c7-1394-4dbe-b5ca-1bcc7ec0d816
I0714 05:37:04.549035       1 cache.go:1363] There are <0> Jobs, <1> Queues and <5> Nodes in total for scheduling.
I0714 05:37:04.549200       1 session.go:190] Open Session 86beb04d-246b-451b-9523-3472b6ef42cc with <0> Job and <1> Queues
I0714 05:37:04.550957       1 enqueue.go:79] Try to enqueue PodGroup to 0 Queues
I0714 05:37:04.551026       1 allocate.go:64] Try to allocate resource to 0 Queues
I0714 05:37:04.551243       1 session.go:244] Close Session 86beb04d-246b-451b-9523-3472b6ef42cc
I0714 05:37:05.553606       1 cache.go:1363] There are <0> Jobs, <1> Queues and <5> Nodes in total for scheduling.
I0714 05:37:05.553767       1 session.go:190] Open Session a7c5dbe9-2714-43ed-b944-209948b4cf0a with <0> Job and <1> Queues
I0714 05:37:05.555492       1 enqueue.go:79] Try to enqueue PodGroup to 0 Queues
I0714 05:37:05.555555       1 allocate.go:64] Try to allocate resource to 0 Queues
I0714 05:37:05.555765       1 session.go:244] Close Session a7c5dbe9-2714-43ed-b944-209948b4cf0a
I0714 05:37:06.283486       1 cache.go:1489] The metrics type is not set in the volcano scheduler configmap file. As a result, the CPU and memory load information of the node is not collected.
I0714 05:37:06.558786       1 cache.go:1363] There are <0> Jobs, <1> Queues and <5> Nodes in total for scheduling.
I0714 05:37:06.558958       1 session.go:190] Open Session 5d0720e3-08b8-4da0-82d2-1469d76c81ab with <0> Job and <1> Queues
I0714 05:37:06.560773       1 enqueue.go:79] Try to enqueue PodGroup to 0 Queues
I0714 05:37:06.560844       1 allocate.go:64] Try to allocate resource to 0 Queues
I0714 05:37:06.561070       1 session.go:244] Close Session 5d0720e3-08b8-4da0-82d2-1469d76c81ab
I0714 05:37:07.563933       1 cache.go:1363] There are <0> Jobs, <1> Queues and <5> Nodes in total for scheduling.
I0714 05:37:07.564094       1 session.go:190] Open Session 121e0047-d728-4a83-a13a-4fd900c3837b with <0> Job and <1> Queues
I0714 05:37:07.565857       1 enqueue.go:79] Try to enqueue PodGroup to 0 Queues
I0714 05:37:07.565924       1 allocate.go:64] Try to allocate resource to 0 Queues
I0714 05:37:07.566112       1 session.go:244] Close Session 121e0047-d728-4a83-a13a-4fd900c3837b
I0714 05:37:08.569091       1 cache.go:1363] There are <0> Jobs, <1> Queues and <5> Nodes in total for scheduling.
I0714 05:37:08.569271       1 session.go:190] Open Session 9d5296af-020d-4b6a-a1b8-1ae71e5a0d33 with <0> Job and <1> Queues
I0714 05:37:08.570984       1 enqueue.go:79] Try to enqueue PodGroup to 0 Queues
I0714 05:37:08.571057       1 allocate.go:64] Try to allocate resource to 0 Queues
I0714 05:37:08.571282       1 session.go:244] Close Session 9d5296af-020d-4b6a-a1b8-1ae71e5a0d33
I0714 05:37:09.574283       1 cache.go:1363] There are <0> Jobs, <1> Queues and <5> Nodes in total for scheduling.
I0714 05:37:09.574457       1 session.go:190] Open Session 5b825fb0-d452-4259-820d-43733f5c204a with <0> Job and <1> Queues
I0714 05:37:09.576388       1 enqueue.go:79] Try to enqueue PodGroup to 0 Queues
I0714 05:37:09.576476       1 allocate.go:64] Try to allocate resource to 0 Queues
I0714 05:37:09.576702       1 session.go:244] Close Session 5b825fb0-d452-4259-820d-43733f5c204a
I0714 05:37:10.579611       1 cache.go:1363] There are <0> Jobs, <1> Queues and <5> Nodes in total for scheduling.
I0714 05:37:10.579774       1 session.go:190] Open Session 0a3acbf9-fbe5-4252-9816-91841563b35c with <0> Job and <1> Queues
I0714 05:37:10.581608       1 enqueue.go:79] Try to enqueue PodGroup to 0 Queues
I0714 05:37:10.581683       1 allocate.go:64] Try to allocate resource to 0 Queues
I0714 05:37:10.581879       1 session.go:244] Close Session 0a3acbf9-fbe5-4252-9816-91841563b35c
I0714 05:37:11.584954       1 cache.go:1363] There are <0> Jobs, <1> Queues and <5> Nodes in total for scheduling.
I0714 05:37:11.585135       1 session.go:190] Open Session 725566d4-11dc-4ea7-8c19-b41ebae773db with <0> Job and <1> Queues
I0714 05:37:11.586984       1 enqueue.go:79] Try to enqueue PodGroup to 0 Queues
I0714 05:37:11.587059       1 allocate.go:64] Try to allocate resource to 0 Queues
I0714 05:37:11.587279       1 session.go:244] Close Session 725566d4-11dc-4ea7-8c19-b41ebae773db
I0714 05:37:12.589645       1 cache.go:1363] There are <0> Jobs, <1> Queues and <5> Nodes in total for scheduling.
I0714 05:37:12.589832       1 session.go:190] Open Session cd5a5111-1072-484b-885d-f696e843fda4 with <0> Job and <1> Queues
I0714 05:37:12.591638       1 enqueue.go:79] Try to enqueue PodGroup to 0 Queues
I0714 05:37:12.591709       1 allocate.go:64] Try to allocate resource to 0 Queues
I0714 05:37:12.591928       1 session.go:244] Close Session cd5a5111-1072-484b-885d-f696e843fda4
I0714 05:37:13.593736       1 cache.go:1363] There are <0> Jobs, <1> Queues and <5> Nodes in total for scheduling.
I0714 05:37:13.593899       1 session.go:190] Open Session f4eb3916-22ec-400d-8878-bef0739de3f6 with <0> Job and <1> Queues
I0714 05:37:13.595520       1 enqueue.go:79] Try to enqueue PodGroup to 0 Queues
I0714 05:37:13.595590       1 allocate.go:64] Try to allocate resource to 0 Queues
I0714 05:37:13.595791       1 session.go:244] Close Session f4eb3916-22ec-400d-8878-bef0739de3f6
I0714 05:37:14.598622       1 cache.go:1363] There are <0> Jobs, <1> Queues and <5> Nodes in total for scheduling.
I0714 05:37:14.598798       1 session.go:190] Open Session 25bdb280-9475-4a8b-bdb6-d0cba40d21ba with <0> Job and <1> Queues
I0714 05:37:14.600578       1 enqueue.go:79] Try to enqueue PodGroup to 0 Queues
I0714 05:37:14.600652       1 allocate.go:64] Try to allocate resource to 0 Queues
I0714 05:37:14.600860       1 session.go:244] Close Session 25bdb280-9475-4a8b-bdb6-d0cba40d21ba
I0714 05:37:15.603789       1 cache.go:1363] There are <0> Jobs, <1> Queues and <5> Nodes in total for scheduling.
I0714 05:37:15.603953       1 session.go:190] Open Session 52950000-f810-4f80-84e0-e14db113d385 with <0> Job and <1> Queues
I0714 05:37:15.605765       1 enqueue.go:79] Try to enqueue PodGroup to 0 Queues
I0714 05:37:15.605844       1 allocate.go:64] Try to allocate resource to 0 Queues
I0714 05:37:15.606067       1 session.go:244] Close Session 52950000-f810-4f80-84e0-e14db113d385
I0714 05:37:16.608729       1 cache.go:1363] There are <0> Jobs, <1> Queues and <5> Nodes in total for scheduling.
I0714 05:37:16.609026       1 session.go:190] Open Session d6f801f9-c554-499d-bab0-6f2b045c5f50 with <0> Job and <1> Queues
I0714 05:37:16.610729       1 enqueue.go:79] Try to enqueue PodGroup to 0 Queues
I0714 05:37:16.610797       1 allocate.go:64] Try to allocate resource to 0 Queues
I0714 05:37:16.611017       1 session.go:244] Close Session d6f801f9-c554-499d-bab0-6f2b045c5f50
I0714 05:37:17.614104       1 cache.go:1363] There are <0> Jobs, <1> Queues and <5> Nodes in total for scheduling.
I0714 05:37:17.614296       1 session.go:190] Open Session 81b4d1f2-a591-43f1-b6d9-254c71c9c8fc with <0> Job and <1> Queues
I0714 05:37:17.616166       1 enqueue.go:79] Try to enqueue PodGroup to 0 Queues
I0714 05:37:17.616240       1 allocate.go:64] Try to allocate resource to 0 Queues
I0714 05:37:17.616592       1 session.go:244] Close Session 81b4d1f2-a591-43f1-b6d9-254c71c9c8fc
I0714 05:37:18.618964       1 cache.go:1363] There are <0> Jobs, <1> Queues and <5> Nodes in total for scheduling.
I0714 05:37:18.619145       1 session.go:190] Open Session 11d3042a-8424-42c9-bf1c-66f8f630cf42 with <0> Job and <1> Queues
I0714 05:37:18.621098       1 enqueue.go:79] Try to enqueue PodGroup to 0 Queues
I0714 05:37:18.621166       1 allocate.go:64] Try to allocate resource to 0 Queues
I0714 05:37:18.621398       1 session.go:244] Close Session 11d3042a-8424-42c9-bf1c-66f8f630cf42
I0714 05:37:19.623458       1 cache.go:1363] There are <0> Jobs, <1> Queues and <5> Nodes in total for scheduling.
I0714 05:37:19.623642       1 session.go:190] Open Session 1fde42e2-87bf-4951-9803-3bc64b6e5415 with <0> Job and <1> Queues
I0714 05:37:19.625483       1 enqueue.go:79] Try to enqueue PodGroup to 0 Queues
I0714 05:37:19.625554       1 allocate.go:64] Try to allocate resource to 0 Queues
I0714 05:37:19.625775       1 session.go:244] Close Session 1fde42e2-87bf-4951-9803-3bc64b6e5415
I0714 05:37:20.628167       1 cache.go:1363] There are <0> Jobs, <1> Queues and <5> Nodes in total for scheduling.
I0714 05:37:20.628377       1 session.go:190] Open Session ead0b9e6-3f62-4b51-b1ac-68087e37c120 with <0> Job and <1> Queues
I0714 05:37:20.630204       1 enqueue.go:79] Try to enqueue PodGroup to 0 Queues
I0714 05:37:20.630270       1 allocate.go:64] Try to allocate resource to 0 Queues
I0714 05:37:20.630489       1 session.go:244] Close Session ead0b9e6-3f62-4b51-b1ac-68087e37c120
I0714 05:37:21.632883       1 cache.go:1363] There are <0> Jobs, <1> Queues and <5> Nodes in total for scheduling.
I0714 05:37:21.633056       1 session.go:190] Open Session ef483d72-9cef-4af2-ba8e-837fd70c76af with <0> Job and <1> Queues
I0714 05:37:21.634998       1 enqueue.go:79] Try to enqueue PodGroup to 0 Queues
I0714 05:37:21.635073       1 allocate.go:64] Try to allocate resource to 0 Queues
I0714 05:37:21.635286       1 session.go:244] Close Session ef483d72-9cef-4af2-ba8e-837fd70c76af
I0714 05:37:22.638157       1 cache.go:1363] There are <0> Jobs, <1> Queues and <5> Nodes in total for scheduling.
I0714 05:37:22.638332       1 session.go:190] Open Session 4650a84b-3f97-452f-97df-c50cd490edc6 with <0> Job and <1> Queues
I0714 05:37:22.640077       1 enqueue.go:79] Try to enqueue PodGroup to 0 Queues
I0714 05:37:22.640144       1 allocate.go:64] Try to allocate resource to 0 Queues
I0714 05:37:22.640395       1 session.go:244] Close Session 4650a84b-3f97-452f-97df-c50cd490edc6
I0714 05:37:23.643025       1 cache.go:1363] There are <0> Jobs, <1> Queues and <5> Nodes in total for scheduling.
I0714 05:37:23.643212       1 session.go:190] Open Session aadbeb53-847b-45e7-8916-2329ddf9dc99 with <0> Job and <1> Queues
I0714 05:37:23.645138       1 enqueue.go:79] Try to enqueue PodGroup to 0 Queues
I0714 05:37:23.645210       1 allocate.go:64] Try to allocate resource to 0 Queues
I0714 05:37:23.645419       1 session.go:244] Close Session aadbeb53-847b-45e7-8916-2329ddf9dc99
I0714 05:37:24.647692       1 cache.go:1363] There are <0> Jobs, <1> Queues and <5> Nodes in total for scheduling.
I0714 05:37:24.647870       1 session.go:190] Open Session 6982f118-0d74-436d-a05c-f614b3610b53 with <0> Job and <1> Queues
I0714 05:37:24.649657       1 enqueue.go:79] Try to enqueue PodGroup to 0 Queues
I0714 05:37:24.649729       1 allocate.go:64] Try to allocate resource to 0 Queues
I0714 05:37:24.649958       1 session.go:244] Close Session 6982f118-0d74-436d-a05c-f614b3610b53
I0714 05:37:25.652357       1 cache.go:1363] There are <0> Jobs, <1> Queues and <5> Nodes in total for scheduling.
I0714 05:37:25.652515       1 session.go:190] Open Session b1059a94-67e8-4612-8333-b5d380304c60 with <0> Job and <1> Queues
I0714 05:37:25.654237       1 enqueue.go:79] Try to enqueue PodGroup to 0 Queues
I0714 05:37:25.654304       1 allocate.go:64] Try to allocate resource to 0 Queues
I0714 05:37:25.654532       1 session.go:244] Close Session b1059a94-67e8-4612-8333-b5d380304c60
I0714 05:37:26.657232       1 cache.go:1363] There are <0> Jobs, <1> Queues and <5> Nodes in total for scheduling.
I0714 05:37:26.657394       1 session.go:190] Open Session c0374834-4b77-4fae-8644-b6c32759c328 with <0> Job and <1> Queues
I0714 05:37:26.659105       1 enqueue.go:79] Try to enqueue PodGroup to 0 Queues
I0714 05:37:26.659179       1 allocate.go:64] Try to allocate resource to 0 Queues
I0714 05:37:26.659382       1 session.go:244] Close Session c0374834-4b77-4fae-8644-b6c32759c328
I0714 05:37:27.661920       1 cache.go:1363] There are <0> Jobs, <1> Queues and <5> Nodes in total for scheduling.
I0714 05:37:27.662065       1 session.go:190] Open Session 041068bd-cd5f-415b-9f8e-e690028bc6fd with <0> Job and <1> Queues
I0714 05:37:27.663817       1 enqueue.go:79] Try to enqueue PodGroup to 0 Queues
I0714 05:37:27.663910       1 allocate.go:64] Try to allocate resource to 0 Queues
I0714 05:37:27.664182       1 session.go:244] Close Session 041068bd-cd5f-415b-9f8e-e690028bc6fd
I0714 05:37:28.667135       1 cache.go:1363] There are <0> Jobs, <1> Queues and <5> Nodes in total for scheduling.
I0714 05:37:28.667301       1 session.go:190] Open Session 13739eb0-2470-4abe-92b2-cadd81ee0af3 with <0> Job and <1> Queues
I0714 05:37:28.669209       1 enqueue.go:79] Try to enqueue PodGroup to 0 Queues
I0714 05:37:28.669281       1 allocate.go:64] Try to allocate resource to 0 Queues
I0714 05:37:28.669516       1 session.go:244] Close Session 13739eb0-2470-4abe-92b2-cadd81ee0af3
I0714 05:37:29.671965       1 cache.go:1363] There are <0> Jobs, <1> Queues and <5> Nodes in total for scheduling.
I0714 05:37:29.672134       1 session.go:190] Open Session f13ff71e-9684-4cfa-aca9-ef730f52e7ae with <0> Job and <1> Queues
I0714 05:37:29.673940       1 enqueue.go:79] Try to enqueue PodGroup to 0 Queues
I0714 05:37:29.674015       1 allocate.go:64] Try to allocate resource to 0 Queues
I0714 05:37:29.674231       1 session.go:244] Close Session f13ff71e-9684-4cfa-aca9-ef730f52e7ae
I0714 05:37:30.676745       1 cache.go:1363] There are <0> Jobs, <1> Queues and <5> Nodes in total for scheduling.
I0714 05:37:30.676902       1 session.go:190] Open Session b70fa975-d801-4ece-85e9-b257a1519b53 with <0> Job and <1> Queues
I0714 05:37:30.678663       1 enqueue.go:79] Try to enqueue PodGroup to 0 Queues
I0714 05:37:30.678728       1 allocate.go:64] Try to allocate resource to 0 Queues
I0714 05:37:30.678951       1 session.go:244] Close Session b70fa975-d801-4ece-85e9-b257a1519b53
I0714 05:37:31.681298       1 cache.go:1363] There are <0> Jobs, <1> Queues and <5> Nodes in total for scheduling.
I0714 05:37:31.681488       1 session.go:190] Open Session 353d8aec-8655-4415-a47c-7de3ea0d7e0b with <0> Job and <1> Queues
I0714 05:37:31.683265       1 enqueue.go:79] Try to enqueue PodGroup to 0 Queues
I0714 05:37:31.683339       1 allocate.go:64] Try to allocate resource to 0 Queues
I0714 05:37:31.683559       1 session.go:244] Close Session 353d8aec-8655-4415-a47c-7de3ea0d7e0b
I0714 05:37:32.685611       1 cache.go:1363] There are <0> Jobs, <1> Queues and <5> Nodes in total for scheduling.
I0714 05:37:32.685773       1 session.go:190] Open Session 6a62b4e3-03d2-4fd6-8fa7-a6a23dbf9357 with <0> Job and <1> Queues
I0714 05:37:32.687517       1 enqueue.go:79] Try to enqueue PodGroup to 0 Queues
I0714 05:37:32.687587       1 allocate.go:64] Try to allocate resource to 0 Queues
I0714 05:37:32.687802       1 session.go:244] Close Session 6a62b4e3-03d2-4fd6-8fa7-a6a23dbf9357
I0714 05:37:33.690283       1 cache.go:1363] There are <0> Jobs, <1> Queues and <5> Nodes in total for scheduling.
I0714 05:37:33.690454       1 session.go:190] Open Session 6a913f0b-0166-4f6e-8b30-a15609f0ca86 with <0> Job and <1> Queues
I0714 05:37:33.692234       1 enqueue.go:79] Try to enqueue PodGroup to 0 Queues
I0714 05:37:33.692335       1 allocate.go:64] Try to allocate resource to 0 Queues
I0714 05:37:33.692578       1 session.go:244] Close Session 6a913f0b-0166-4f6e-8b30-a15609f0ca86
I0714 05:37:34.695285       1 cache.go:1363] There are <0> Jobs, <1> Queues and <5> Nodes in total for scheduling.
I0714 05:37:34.695449       1 session.go:190] Open Session ba33252c-1271-4e1f-89f0-3f36328a6158 with <0> Job and <1> Queues
I0714 05:37:34.697256       1 enqueue.go:79] Try to enqueue PodGroup to 0 Queues
I0714 05:37:34.697330       1 allocate.go:64] Try to allocate resource to 0 Queues
I0714 05:37:34.697550       1 session.go:244] Close Session ba33252c-1271-4e1f-89f0-3f36328a6158
I0714 05:37:35.699919       1 cache.go:1363] There are <0> Jobs, <1> Queues and <5> Nodes in total for scheduling.
I0714 05:37:35.700079       1 session.go:190] Open Session b87af268-e7e3-4b24-88bd-8a71dff84958 with <0> Job and <1> Queues
I0714 05:37:35.701873       1 enqueue.go:79] Try to enqueue PodGroup to 0 Queues
I0714 05:37:35.701950       1 allocate.go:64] Try to allocate resource to 0 Queues
I0714 05:37:35.702171       1 session.go:244] Close Session b87af268-e7e3-4b24-88bd-8a71dff84958
I0714 05:37:36.283999       1 cache.go:1489] The metrics type is not set in the volcano scheduler configmap file. As a result, the CPU and memory load information of the node is not collected.
I0714 05:37:36.704281       1 cache.go:1363] There are <0> Jobs, <1> Queues and <5> Nodes in total for scheduling.
I0714 05:37:36.704503       1 session.go:190] Open Session 37c19f3f-9b61-4328-a746-4381ec1187fb with <0> Job and <1> Queues
I0714 05:37:36.706279       1 enqueue.go:79] Try to enqueue PodGroup to 0 Queues
I0714 05:37:36.706346       1 allocate.go:64] Try to allocate resource to 0 Queues
I0714 05:37:36.706572       1 session.go:244] Close Session 37c19f3f-9b61-4328-a746-4381ec1187fb
I0714 05:37:37.708551       1 cache.go:1363] There are <0> Jobs, <1> Queues and <5> Nodes in total for scheduling.
I0714 05:37:37.708723       1 session.go:190] Open Session 37fa34f5-c5de-4470-9aac-17a654f5e4c9 with <0> Job and <1> Queues
I0714 05:37:37.710647       1 enqueue.go:79] Try to enqueue PodGroup to 0 Queues
I0714 05:37:37.710714       1 allocate.go:64] Try to allocate resource to 0 Queues
I0714 05:37:37.710931       1 session.go:244] Close Session 37fa34f5-c5de-4470-9aac-17a654f5e4c9
I0714 05:37:38.713561       1 cache.go:1363] There are <0> Jobs, <1> Queues and <5> Nodes in total for scheduling.
I0714 05:37:38.713732       1 session.go:190] Open Session 4c5636a4-3835-4477-9c46-e0da87ca8d38 with <0> Job and <1> Queues
I0714 05:37:38.715474       1 enqueue.go:79] Try to enqueue PodGroup to 0 Queues
I0714 05:37:38.715543       1 allocate.go:64] Try to allocate resource to 0 Queues
I0714 05:37:38.715771       1 session.go:244] Close Session 4c5636a4-3835-4477-9c46-e0da87ca8d38
I0714 05:37:39.717891       1 cache.go:1363] There are <0> Jobs, <1> Queues and <5> Nodes in total for scheduling.
I0714 05:37:39.718056       1 session.go:190] Open Session 8fcfe2ab-73da-46fa-92fe-a75380b7a5e3 with <0> Job and <1> Queues
I0714 05:37:39.719927       1 enqueue.go:79] Try to enqueue PodGroup to 0 Queues
I0714 05:37:39.719992       1 allocate.go:64] Try to allocate resource to 0 Queues
I0714 05:37:39.720213       1 session.go:244] Close Session 8fcfe2ab-73da-46fa-92fe-a75380b7a5e3
I0714 05:37:40.722576       1 cache.go:1363] There are <0> Jobs, <1> Queues and <5> Nodes in total for scheduling.
I0714 05:37:40.722736       1 session.go:190] Open Session ff77faac-4692-431d-bf0a-134c501de813 with <0> Job and <1> Queues
I0714 05:37:40.724389       1 enqueue.go:79] Try to enqueue PodGroup to 0 Queues
I0714 05:37:40.724457       1 allocate.go:64] Try to allocate resource to 0 Queues
I0714 05:37:40.724669       1 session.go:244] Close Session ff77faac-4692-431d-bf0a-134c501de813
I0714 05:37:41.727476       1 cache.go:1363] There are <0> Jobs, <1> Queues and <5> Nodes in total for scheduling.
I0714 05:37:41.727661       1 session.go:190] Open Session 04089fc6-1d00-479f-a605-4fcdea7f5c72 with <0> Job and <1> Queues
I0714 05:37:41.729428       1 enqueue.go:79] Try to enqueue PodGroup to 0 Queues
I0714 05:37:41.729499       1 allocate.go:64] Try to allocate resource to 0 Queues
I0714 05:37:41.729733       1 session.go:244] Close Session 04089fc6-1d00-479f-a605-4fcdea7f5c72
I0714 05:37:42.732169       1 cache.go:1363] There are <0> Jobs, <1> Queues and <5> Nodes in total for scheduling.
I0714 05:37:42.732343       1 session.go:190] Open Session 306cdb8b-f6ab-4ad7-b6fe-d5cd4a553f2d with <0> Job and <1> Queues
I0714 05:37:42.736175       1 enqueue.go:79] Try to enqueue PodGroup to 0 Queues
I0714 05:37:42.736327       1 allocate.go:64] Try to allocate resource to 0 Queues
I0714 05:37:42.736646       1 session.go:244] Close Session 306cdb8b-f6ab-4ad7-b6fe-d5cd4a553f2d
I0714 05:37:43.739509       1 cache.go:1363] There are <0> Jobs, <1> Queues and <5> Nodes in total for scheduling.
I0714 05:37:43.739685       1 session.go:190] Open Session f76aedc1-fc55-4f98-b812-f86e7fdbf6c4 with <0> Job and <1> Queues
I0714 05:37:43.741500       1 enqueue.go:79] Try to enqueue PodGroup to 0 Queues
I0714 05:37:43.741567       1 allocate.go:64] Try to allocate resource to 0 Queues
I0714 05:37:43.741786       1 session.go:244] Close Session f76aedc1-fc55-4f98-b812-f86e7fdbf6c4
I0714 05:37:44.743959       1 cache.go:1363] There are <0> Jobs, <1> Queues and <5> Nodes in total for scheduling.
I0714 05:37:44.744140       1 session.go:190] Open Session 15e5c76e-cf73-4d6c-a369-2493fa71de79 with <0> Job and <1> Queues
I0714 05:37:44.745904       1 enqueue.go:79] Try to enqueue PodGroup to 0 Queues
I0714 05:37:44.745973       1 allocate.go:64] Try to allocate resource to 0 Queues
I0714 05:37:44.746190       1 session.go:244] Close Session 15e5c76e-cf73-4d6c-a369-2493fa71de79
I0714 05:37:45.748784       1 cache.go:1363] There are <0> Jobs, <1> Queues and <5> Nodes in total for scheduling.
I0714 05:37:45.748930       1 session.go:190] Open Session 4dd308f9-6a21-4487-bd53-64f35142c253 with <0> Job and <1> Queues
I0714 05:37:45.750625       1 enqueue.go:79] Try to enqueue PodGroup to 0 Queues
I0714 05:37:45.750695       1 allocate.go:64] Try to allocate resource to 0 Queues
I0714 05:37:45.750910       1 session.go:244] Close Session 4dd308f9-6a21-4487-bd53-64f35142c253
I0714 05:37:46.753398       1 cache.go:1363] There are <0> Jobs, <1> Queues and <5> Nodes in total for scheduling.
I0714 05:37:46.753613       1 session.go:190] Open Session 7365fe6e-d542-41d9-8137-001c74c0a6cf with <0> Job and <1> Queues
I0714 05:37:46.755373       1 enqueue.go:79] Try to enqueue PodGroup to 0 Queues
I0714 05:37:46.755442       1 allocate.go:64] Try to allocate resource to 0 Queues
I0714 05:37:46.755659       1 session.go:244] Close Session 7365fe6e-d542-41d9-8137-001c74c0a6cf
I0714 05:37:47.757960       1 cache.go:1363] There are <0> Jobs, <1> Queues and <5> Nodes in total for scheduling.
I0714 05:37:47.758140       1 session.go:190] Open Session 9799a440-25d1-4ca3-9cff-9814c50bea0e with <0> Job and <1> Queues
I0714 05:37:47.759800       1 enqueue.go:79] Try to enqueue PodGroup to 0 Queues
I0714 05:37:47.759871       1 allocate.go:64] Try to allocate resource to 0 Queues
I0714 05:37:47.760090       1 session.go:244] Close Session 9799a440-25d1-4ca3-9cff-9814c50bea0e
I0714 05:37:48.762213       1 cache.go:1363] There are <0> Jobs, <1> Queues and <5> Nodes in total for scheduling.
I0714 05:37:48.762379       1 session.go:190] Open Session e189b729-ef27-427d-8ace-f1677eb8af75 with <0> Job and <1> Queues
I0714 05:37:48.764235       1 enqueue.go:79] Try to enqueue PodGroup to 0 Queues
I0714 05:37:48.764354       1 allocate.go:64] Try to allocate resource to 0 Queues
I0714 05:37:48.764580       1 session.go:244] Close Session e189b729-ef27-427d-8ace-f1677eb8af75
I0714 05:37:49.767185       1 cache.go:1363] There are <0> Jobs, <1> Queues and <5> Nodes in total for scheduling.
I0714 05:37:49.767386       1 session.go:190] Open Session 74846c6e-b16e-42bf-aae0-c2edae44f034 with <0> Job and <1> Queues
I0714 05:37:49.769242       1 enqueue.go:79] Try to enqueue PodGroup to 0 Queues
I0714 05:37:49.769313       1 allocate.go:64] Try to allocate resource to 0 Queues
I0714 05:37:49.769532       1 session.go:244] Close Session 74846c6e-b16e-42bf-aae0-c2edae44f034
I0714 05:37:50.772146       1 cache.go:1363] There are <0> Jobs, <1> Queues and <5> Nodes in total for scheduling.
I0714 05:37:50.772346       1 session.go:190] Open Session aae88577-c7f2-4713-a827-3f810854e002 with <0> Job and <1> Queues
I0714 05:37:50.774165       1 enqueue.go:79] Try to enqueue PodGroup to 0 Queues
I0714 05:37:50.774232       1 allocate.go:64] Try to allocate resource to 0 Queues
I0714 05:37:50.774450       1 session.go:244] Close Session aae88577-c7f2-4713-a827-3f810854e002
I0714 05:37:51.776812       1 cache.go:1363] There are <0> Jobs, <1> Queues and <5> Nodes in total for scheduling.
I0714 05:37:51.776999       1 session.go:190] Open Session ddd88ebd-2c8c-4478-b7a0-3ca5a5749d84 with <0> Job and <1> Queues
I0714 05:37:51.778887       1 enqueue.go:79] Try to enqueue PodGroup to 0 Queues
I0714 05:37:51.778955       1 allocate.go:64] Try to allocate resource to 0 Queues
I0714 05:37:51.779176       1 session.go:244] Close Session ddd88ebd-2c8c-4478-b7a0-3ca5a5749d84
I0714 05:37:52.782068       1 cache.go:1363] There are <0> Jobs, <1> Queues and <5> Nodes in total for scheduling.
I0714 05:37:52.782251       1 session.go:190] Open Session a2075656-8623-487e-9ffa-ef8d532acf41 with <0> Job and <1> Queues
I0714 05:37:52.783920       1 enqueue.go:79] Try to enqueue PodGroup to 0 Queues
I0714 05:37:52.783991       1 allocate.go:64] Try to allocate resource to 0 Queues
I0714 05:37:52.784197       1 session.go:244] Close Session a2075656-8623-487e-9ffa-ef8d532acf41
I0714 05:37:53.786134       1 cache.go:1363] There are <0> Jobs, <1> Queues and <5> Nodes in total for scheduling.
I0714 05:37:53.786345       1 session.go:190] Open Session fa742ee6-0bef-4273-a3f7-14568d5a3d5e with <0> Job and <1> Queues
I0714 05:37:53.788162       1 enqueue.go:79] Try to enqueue PodGroup to 0 Queues
I0714 05:37:53.788237       1 allocate.go:64] Try to allocate resource to 0 Queues
I0714 05:37:53.788495       1 session.go:244] Close Session fa742ee6-0bef-4273-a3f7-14568d5a3d5e
I0714 05:37:54.791084       1 cache.go:1363] There are <0> Jobs, <1> Queues and <5> Nodes in total for scheduling.
I0714 05:37:54.791273       1 session.go:190] Open Session 6a9c0b3f-bcd2-444b-95bc-cca3ce37e55b with <0> Job and <1> Queues
I0714 05:37:54.793104       1 enqueue.go:79] Try to enqueue PodGroup to 0 Queues
I0714 05:37:54.793181       1 allocate.go:64] Try to allocate resource to 0 Queues
I0714 05:37:54.793408       1 session.go:244] Close Session 6a9c0b3f-bcd2-444b-95bc-cca3ce37e55b
I0714 05:37:55.795177       1 cache.go:1363] There are <0> Jobs, <1> Queues and <5> Nodes in total for scheduling.
I0714 05:37:55.795334       1 session.go:190] Open Session f3287125-fcc6-4afa-9af3-d15da77abc6a with <0> Job and <1> Queues
I0714 05:37:55.796959       1 enqueue.go:79] Try to enqueue PodGroup to 0 Queues
I0714 05:37:55.797038       1 allocate.go:64] Try to allocate resource to 0 Queues
I0714 05:37:55.797247       1 session.go:244] Close Session f3287125-fcc6-4afa-9af3-d15da77abc6a
I0714 05:37:56.799439       1 cache.go:1363] There are <0> Jobs, <1> Queues and <5> Nodes in total for scheduling.
I0714 05:37:56.799601       1 session.go:190] Open Session 6fde224e-cdb1-4a9a-98c2-cbe31b116cde with <0> Job and <1> Queues
I0714 05:37:56.801397       1 enqueue.go:79] Try to enqueue PodGroup to 0 Queues
I0714 05:37:56.801461       1 allocate.go:64] Try to allocate resource to 0 Queues
I0714 05:37:56.801677       1 session.go:244] Close Session 6fde224e-cdb1-4a9a-98c2-cbe31b116cde
I0714 05:37:57.803592       1 cache.go:1363] There are <0> Jobs, <1> Queues and <5> Nodes in total for scheduling.
I0714 05:37:57.803716       1 session.go:190] Open Session 5d10a1b3-8a1f-4ab0-8b74-3c2700496088 with <0> Job and <1> Queues
I0714 05:37:57.805286       1 enqueue.go:79] Try to enqueue PodGroup to 0 Queues
I0714 05:37:57.805352       1 allocate.go:64] Try to allocate resource to 0 Queues
I0714 05:37:57.805532       1 session.go:244] Close Session 5d10a1b3-8a1f-4ab0-8b74-3c2700496088
I0714 05:37:58.808059       1 cache.go:1363] There are <0> Jobs, <1> Queues and <5> Nodes in total for scheduling.
I0714 05:37:58.808259       1 session.go:190] Open Session 0fc21320-30ac-4a31-a5b6-a38023e865e9 with <0> Job and <1> Queues
I0714 05:37:58.810072       1 enqueue.go:79] Try to enqueue PodGroup to 0 Queues
I0714 05:37:58.810143       1 allocate.go:64] Try to allocate resource to 0 Queues
I0714 05:37:58.810351       1 session.go:244] Close Session 0fc21320-30ac-4a31-a5b6-a38023e865e9
I0714 05:37:59.812428       1 cache.go:1363] There are <0> Jobs, <1> Queues and <5> Nodes in total for scheduling.
I0714 05:37:59.812619       1 session.go:190] Open Session d22a7a22-2683-4cac-b65c-068ebf70634a with <0> Job and <1> Queues
I0714 05:37:59.814387       1 enqueue.go:79] Try to enqueue PodGroup to 0 Queues
I0714 05:37:59.814455       1 allocate.go:64] Try to allocate resource to 0 Queues
I0714 05:37:59.814659       1 session.go:244] Close Session d22a7a22-2683-4cac-b65c-068ebf70634a
I0714 05:38:00.817336       1 cache.go:1363] There are <0> Jobs, <1> Queues and <5> Nodes in total for scheduling.
I0714 05:38:00.817516       1 session.go:190] Open Session e8024285-ea40-4d63-b34c-3418e28f8b9f with <0> Job and <1> Queues
I0714 05:38:00.819234       1 enqueue.go:79] Try to enqueue PodGroup to 0 Queues
I0714 05:38:00.819303       1 allocate.go:64] Try to allocate resource to 0 Queues
I0714 05:38:00.819513       1 session.go:244] Close Session e8024285-ea40-4d63-b34c-3418e28f8b9f
I0714 05:38:01.821672       1 cache.go:1363] There are <0> Jobs, <1> Queues and <5> Nodes in total for scheduling.
I0714 05:38:01.821843       1 session.go:190] Open Session 4ab163d2-d492-448c-9efe-a45671bc22bc with <0> Job and <1> Queues
I0714 05:38:01.823631       1 enqueue.go:79] Try to enqueue PodGroup to 0 Queues
I0714 05:38:01.823697       1 allocate.go:64] Try to allocate resource to 0 Queues
I0714 05:38:01.823911       1 session.go:244] Close Session 4ab163d2-d492-448c-9efe-a45671bc22bc
I0714 05:38:02.826414       1 cache.go:1363] There are <0> Jobs, <1> Queues and <5> Nodes in total for scheduling.
I0714 05:38:02.826564       1 session.go:190] Open Session 377ff90e-a5ae-46aa-9210-b3f193c21536 with <0> Job and <1> Queues
I0714 05:38:02.828259       1 enqueue.go:79] Try to enqueue PodGroup to 0 Queues
I0714 05:38:02.828370       1 allocate.go:64] Try to allocate resource to 0 Queues
I0714 05:38:02.828581       1 session.go:244] Close Session 377ff90e-a5ae-46aa-9210-b3f193c21536
I0714 05:38:03.830694       1 cache.go:1363] There are <0> Jobs, <1> Queues and <5> Nodes in total for scheduling.
I0714 05:38:03.830871       1 session.go:190] Open Session 4513caad-fcc8-4837-86f6-a4091dc71a3f with <0> Job and <1> Queues
I0714 05:38:03.832745       1 enqueue.go:79] Try to enqueue PodGroup to 0 Queues
I0714 05:38:03.832818       1 allocate.go:64] Try to allocate resource to 0 Queues
I0714 05:38:03.833064       1 session.go:244] Close Session 4513caad-fcc8-4837-86f6-a4091dc71a3f
I0714 05:38:04.835195       1 cache.go:1363] There are <0> Jobs, <1> Queues and <5> Nodes in total for scheduling.
I0714 05:38:04.835363       1 session.go:190] Open Session 8c2bfd3e-32ae-4af7-aa79-f5eea5ad6788 with <0> Job and <1> Queues
I0714 05:38:04.837344       1 enqueue.go:79] Try to enqueue PodGroup to 0 Queues
I0714 05:38:04.837416       1 allocate.go:64] Try to allocate resource to 0 Queues
I0714 05:38:04.837638       1 session.go:244] Close Session 8c2bfd3e-32ae-4af7-aa79-f5eea5ad6788
I0714 05:38:05.839684       1 cache.go:1363] There are <0> Jobs, <1> Queues and <5> Nodes in total for scheduling.
I0714 05:38:05.839841       1 session.go:190] Open Session 487a76d5-1b74-4d4f-ad2f-9bc48bfa225d with <0> Job and <1> Queues
I0714 05:38:05.841681       1 enqueue.go:79] Try to enqueue PodGroup to 0 Queues
I0714 05:38:05.841760       1 allocate.go:64] Try to allocate resource to 0 Queues
I0714 05:38:05.841974       1 session.go:244] Close Session 487a76d5-1b74-4d4f-ad2f-9bc48bfa225d
I0714 05:38:06.284953       1 cache.go:1489] The metrics type is not set in the volcano scheduler configmap file. As a result, the CPU and memory load information of the node is not collected.
I0714 05:38:06.844426       1 cache.go:1363] There are <0> Jobs, <1> Queues and <5> Nodes in total for scheduling.
I0714 05:38:06.844593       1 session.go:190] Open Session 20ab6e7d-747b-4496-be9e-84b406224d45 with <0> Job and <1> Queues
I0714 05:38:06.846347       1 enqueue.go:79] Try to enqueue PodGroup to 0 Queues
I0714 05:38:06.846423       1 allocate.go:64] Try to allocate resource to 0 Queues
I0714 05:38:06.846652       1 session.go:244] Close Session 20ab6e7d-747b-4496-be9e-84b406224d45
I0714 05:38:07.849197       1 cache.go:1363] There are <0> Jobs, <1> Queues and <5> Nodes in total for scheduling.
I0714 05:38:07.849349       1 session.go:190] Open Session 2963d14e-4044-409f-bce1-babab179d24d with <0> Job and <1> Queues
I0714 05:38:07.851033       1 enqueue.go:79] Try to enqueue PodGroup to 0 Queues
I0714 05:38:07.851097       1 allocate.go:64] Try to allocate resource to 0 Queues
I0714 05:38:07.851333       1 session.go:244] Close Session 2963d14e-4044-409f-bce1-babab179d24d
I0714 05:38:08.853702       1 cache.go:1363] There are <0> Jobs, <1> Queues and <5> Nodes in total for scheduling.
I0714 05:38:08.853895       1 session.go:190] Open Session 485096d2-fe2a-4887-9ea5-46e516a22fd4 with <0> Job and <1> Queues
I0714 05:38:08.855760       1 enqueue.go:79] Try to enqueue PodGroup to 0 Queues
I0714 05:38:08.855829       1 allocate.go:64] Try to allocate resource to 0 Queues
I0714 05:38:08.856064       1 session.go:244] Close Session 485096d2-fe2a-4887-9ea5-46e516a22fd4
I0714 05:38:09.858688       1 cache.go:1363] There are <0> Jobs, <1> Queues and <5> Nodes in total for scheduling.
I0714 05:38:09.858867       1 session.go:190] Open Session 3e5da3d7-c2cb-425a-915f-c8d8e8075522 with <0> Job and <1> Queues
I0714 05:38:09.860817       1 enqueue.go:79] Try to enqueue PodGroup to 0 Queues
I0714 05:38:09.860896       1 allocate.go:64] Try to allocate resource to 0 Queues
I0714 05:38:09.861119       1 session.go:244] Close Session 3e5da3d7-c2cb-425a-915f-c8d8e8075522
I0714 05:38:10.863907       1 cache.go:1363] There are <0> Jobs, <1> Queues and <5> Nodes in total for scheduling.
I0714 05:38:10.864112       1 session.go:190] Open Session 9dc625e2-7995-46e6-b2a6-57259bfb23e8 with <0> Job and <1> Queues
I0714 05:38:10.865986       1 enqueue.go:79] Try to enqueue PodGroup to 0 Queues
I0714 05:38:10.866055       1 allocate.go:64] Try to allocate resource to 0 Queues
I0714 05:38:10.866263       1 session.go:244] Close Session 9dc625e2-7995-46e6-b2a6-57259bfb23e8
I0714 05:38:11.869033       1 cache.go:1363] There are <0> Jobs, <1> Queues and <5> Nodes in total for scheduling.
I0714 05:38:11.869207       1 session.go:190] Open Session 86c17be7-df77-464d-a9a4-5b0fecc21f85 with <0> Job and <1> Queues
I0714 05:38:11.870933       1 enqueue.go:79] Try to enqueue PodGroup to 0 Queues
I0714 05:38:11.871004       1 allocate.go:64] Try to allocate resource to 0 Queues
I0714 05:38:11.871226       1 session.go:244] Close Session 86c17be7-df77-464d-a9a4-5b0fecc21f85
I0714 05:38:12.873986       1 cache.go:1363] There are <0> Jobs, <1> Queues and <5> Nodes in total for scheduling.
I0714 05:38:12.874157       1 session.go:190] Open Session 64fdf233-d196-4202-992d-04214437eb1f with <0> Job and <1> Queues
I0714 05:38:12.875888       1 enqueue.go:79] Try to enqueue PodGroup to 0 Queues
I0714 05:38:12.875947       1 allocate.go:64] Try to allocate resource to 0 Queues
I0714 05:38:12.876130       1 session.go:244] Close Session 64fdf233-d196-4202-992d-04214437eb1f
I0714 05:38:13.878664       1 cache.go:1363] There are <0> Jobs, <1> Queues and <5> Nodes in total for scheduling.
I0714 05:38:13.878979       1 session.go:190] Open Session c1a52bf1-475a-432e-9634-d38296de8981 with <0> Job and <1> Queues
I0714 05:38:13.880877       1 enqueue.go:79] Try to enqueue PodGroup to 0 Queues
I0714 05:38:13.880942       1 allocate.go:64] Try to allocate resource to 0 Queues
I0714 05:38:13.881146       1 session.go:244] Close Session c1a52bf1-475a-432e-9634-d38296de8981
I0714 05:38:14.883552       1 cache.go:1363] There are <0> Jobs, <1> Queues and <5> Nodes in total for scheduling.
I0714 05:38:14.883735       1 session.go:190] Open Session d385b70b-df2a-43d7-a9c6-47a01e7f7f2f with <0> Job and <1> Queues
I0714 05:38:14.885526       1 enqueue.go:79] Try to enqueue PodGroup to 0 Queues
I0714 05:38:14.885592       1 allocate.go:64] Try to allocate resource to 0 Queues
I0714 05:38:14.885818       1 session.go:244] Close Session d385b70b-df2a-43d7-a9c6-47a01e7f7f2f
I0714 05:38:15.888228       1 cache.go:1363] There are <0> Jobs, <1> Queues and <5> Nodes in total for scheduling.
I0714 05:38:15.888415       1 session.go:190] Open Session f8571b41-7223-47dc-bdbb-f3a5ec3ba304 with <0> Job and <1> Queues
I0714 05:38:15.890012       1 enqueue.go:79] Try to enqueue PodGroup to 0 Queues
I0714 05:38:15.890071       1 allocate.go:64] Try to allocate resource to 0 Queues
I0714 05:38:15.890261       1 session.go:244] Close Session f8571b41-7223-47dc-bdbb-f3a5ec3ba304
I0714 05:38:16.893065       1 cache.go:1363] There are <0> Jobs, <1> Queues and <5> Nodes in total for scheduling.
I0714 05:38:16.893238       1 session.go:190] Open Session bbc8bbfe-10e4-46b1-8c5d-c8fbf6e3951a with <0> Job and <1> Queues
I0714 05:38:16.894847       1 enqueue.go:79] Try to enqueue PodGroup to 0 Queues
I0714 05:38:16.894918       1 allocate.go:64] Try to allocate resource to 0 Queues
I0714 05:38:16.895143       1 session.go:244] Close Session bbc8bbfe-10e4-46b1-8c5d-c8fbf6e3951a
I0714 05:38:17.897666       1 cache.go:1363] There are <0> Jobs, <1> Queues and <5> Nodes in total for scheduling.
I0714 05:38:17.897784       1 session.go:190] Open Session 9cb7b139-4a7d-43ee-b901-ffcc2eb3aae9 with <0> Job and <1> Queues
I0714 05:38:17.899102       1 enqueue.go:79] Try to enqueue PodGroup to 0 Queues
I0714 05:38:17.899162       1 allocate.go:64] Try to allocate resource to 0 Queues
I0714 05:38:17.899339       1 session.go:244] Close Session 9cb7b139-4a7d-43ee-b901-ffcc2eb3aae9
I0714 05:38:18.902315       1 cache.go:1363] There are <0> Jobs, <1> Queues and <5> Nodes in total for scheduling.
I0714 05:38:18.902510       1 session.go:190] Open Session b2e255a5-84a9-4286-8da5-f78c492f45d9 with <0> Job and <1> Queues
I0714 05:38:18.904388       1 enqueue.go:79] Try to enqueue PodGroup to 0 Queues
I0714 05:38:18.904484       1 allocate.go:64] Try to allocate resource to 0 Queues
I0714 05:38:18.904710       1 session.go:244] Close Session b2e255a5-84a9-4286-8da5-f78c492f45d9
I0714 05:38:19.907638       1 cache.go:1363] There are <0> Jobs, <1> Queues and <5> Nodes in total for scheduling.
I0714 05:38:19.907821       1 session.go:190] Open Session d8e70066-f0c4-4035-9845-e9b95738304c with <0> Job and <1> Queues
I0714 05:38:19.909584       1 enqueue.go:79] Try to enqueue PodGroup to 0 Queues
I0714 05:38:19.909665       1 allocate.go:64] Try to allocate resource to 0 Queues
I0714 05:38:19.909883       1 session.go:244] Close Session d8e70066-f0c4-4035-9845-e9b95738304c
I0714 05:38:20.912042       1 cache.go:1363] There are <0> Jobs, <1> Queues and <5> Nodes in total for scheduling.
I0714 05:38:20.912187       1 session.go:190] Open Session c20f38ca-e8d5-4f3c-acb4-84cfa9bb3283 with <0> Job and <1> Queues
I0714 05:38:20.913825       1 enqueue.go:79] Try to enqueue PodGroup to 0 Queues
I0714 05:38:20.913894       1 allocate.go:64] Try to allocate resource to 0 Queues
I0714 05:38:20.914110       1 session.go:244] Close Session c20f38ca-e8d5-4f3c-acb4-84cfa9bb3283
I0714 05:38:21.916584       1 cache.go:1363] There are <0> Jobs, <1> Queues and <5> Nodes in total for scheduling.
I0714 05:38:21.916755       1 session.go:190] Open Session bae107c8-0c14-4f89-ac34-c886531f374a with <0> Job and <1> Queues
I0714 05:38:21.918433       1 enqueue.go:79] Try to enqueue PodGroup to 0 Queues
I0714 05:38:21.918496       1 allocate.go:64] Try to allocate resource to 0 Queues
I0714 05:38:21.918723       1 session.go:244] Close Session bae107c8-0c14-4f89-ac34-c886531f374a
I0714 05:38:22.921111       1 cache.go:1363] There are <0> Jobs, <1> Queues and <5> Nodes in total for scheduling.
I0714 05:38:22.921292       1 session.go:190] Open Session 8a5827f6-41a2-49da-8a12-20fa65a749dc with <0> Job and <1> Queues
I0714 05:38:22.922981       1 enqueue.go:79] Try to enqueue PodGroup to 0 Queues
I0714 05:38:22.923047       1 allocate.go:64] Try to allocate resource to 0 Queues
I0714 05:38:22.923255       1 session.go:244] Close Session 8a5827f6-41a2-49da-8a12-20fa65a749dc
I0714 05:38:23.925785       1 cache.go:1363] There are <0> Jobs, <1> Queues and <5> Nodes in total for scheduling.
I0714 05:38:23.925931       1 session.go:190] Open Session e74a278c-9e63-4a06-81ab-4e40f362416c with <0> Job and <1> Queues
I0714 05:38:23.927462       1 enqueue.go:79] Try to enqueue PodGroup to 0 Queues
I0714 05:38:23.927528       1 allocate.go:64] Try to allocate resource to 0 Queues
I0714 05:38:23.927707       1 session.go:244] Close Session e74a278c-9e63-4a06-81ab-4e40f362416c
I0714 05:38:24.929914       1 cache.go:1363] There are <0> Jobs, <1> Queues and <5> Nodes in total for scheduling.
I0714 05:38:24.930080       1 session.go:190] Open Session c9e03a0d-727c-473e-bbfb-6194045e6d87 with <0> Job and <1> Queues
I0714 05:38:24.931850       1 enqueue.go:79] Try to enqueue PodGroup to 0 Queues
I0714 05:38:24.931913       1 allocate.go:64] Try to allocate resource to 0 Queues
I0714 05:38:24.932120       1 session.go:244] Close Session c9e03a0d-727c-473e-bbfb-6194045e6d87
I0714 05:38:25.933905       1 cache.go:1363] There are <0> Jobs, <1> Queues and <5> Nodes in total for scheduling.
I0714 05:38:25.934057       1 session.go:190] Open Session 39a226ab-ebf3-4d23-9be5-af1dd524c861 with <0> Job and <1> Queues
I0714 05:38:25.935685       1 enqueue.go:79] Try to enqueue PodGroup to 0 Queues
I0714 05:38:25.935745       1 allocate.go:64] Try to allocate resource to 0 Queues
I0714 05:38:25.935936       1 session.go:244] Close Session 39a226ab-ebf3-4d23-9be5-af1dd524c861
I0714 05:38:26.938543       1 cache.go:1363] There are <0> Jobs, <1> Queues and <5> Nodes in total for scheduling.
I0714 05:38:26.938715       1 session.go:190] Open Session 148f2dc3-aedc-4b07-8e57-aa7c41331854 with <0> Job and <1> Queues
I0714 05:38:26.940467       1 enqueue.go:79] Try to enqueue PodGroup to 0 Queues
I0714 05:38:26.940531       1 allocate.go:64] Try to allocate resource to 0 Queues
I0714 05:38:26.940719       1 session.go:244] Close Session 148f2dc3-aedc-4b07-8e57-aa7c41331854
I0714 05:38:27.943136       1 cache.go:1363] There are <0> Jobs, <1> Queues and <5> Nodes in total for scheduling.
I0714 05:38:27.943297       1 session.go:190] Open Session 2a1c6655-7761-45f7-8b2b-51094daf7752 with <0> Job and <1> Queues
I0714 05:38:27.945022       1 enqueue.go:79] Try to enqueue PodGroup to 0 Queues
I0714 05:38:27.945085       1 allocate.go:64] Try to allocate resource to 0 Queues
I0714 05:38:27.945307       1 session.go:244] Close Session 2a1c6655-7761-45f7-8b2b-51094daf7752
I0714 05:38:28.947590       1 cache.go:1363] There are <0> Jobs, <1> Queues and <5> Nodes in total for scheduling.
I0714 05:38:28.947761       1 session.go:190] Open Session ae78f37a-75dd-4830-b887-bae6f56745cf with <0> Job and <1> Queues
I0714 05:38:28.949667       1 enqueue.go:79] Try to enqueue PodGroup to 0 Queues
I0714 05:38:28.949743       1 allocate.go:64] Try to allocate resource to 0 Queues
I0714 05:38:28.949959       1 session.go:244] Close Session ae78f37a-75dd-4830-b887-bae6f56745cf
I0714 05:38:29.952268       1 cache.go:1363] There are <0> Jobs, <1> Queues and <5> Nodes in total for scheduling.
I0714 05:38:29.952475       1 session.go:190] Open Session 8b0d00cd-d586-4608-b092-67fdc60b0cb5 with <0> Job and <1> Queues
I0714 05:38:29.954206       1 enqueue.go:79] Try to enqueue PodGroup to 0 Queues
I0714 05:38:29.954273       1 allocate.go:64] Try to allocate resource to 0 Queues
I0714 05:38:29.954495       1 session.go:244] Close Session 8b0d00cd-d586-4608-b092-67fdc60b0cb5
I0714 05:38:30.956725       1 cache.go:1363] There are <0> Jobs, <1> Queues and <5> Nodes in total for scheduling.
I0714 05:38:30.956896       1 session.go:190] Open Session 0489f5da-e758-4063-b6cf-aa0bf152158b with <0> Job and <1> Queues
I0714 05:38:30.958599       1 enqueue.go:79] Try to enqueue PodGroup to 0 Queues
I0714 05:38:30.958675       1 allocate.go:64] Try to allocate resource to 0 Queues
I0714 05:38:30.958889       1 session.go:244] Close Session 0489f5da-e758-4063-b6cf-aa0bf152158b
I0714 05:38:31.961739       1 cache.go:1363] There are <0> Jobs, <1> Queues and <5> Nodes in total for scheduling.
I0714 05:38:31.961911       1 session.go:190] Open Session dd01e818-2c7c-4129-a507-b63cdfa9fb28 with <0> Job and <1> Queues
I0714 05:38:31.963663       1 enqueue.go:79] Try to enqueue PodGroup to 0 Queues
I0714 05:38:31.963728       1 allocate.go:64] Try to allocate resource to 0 Queues
I0714 05:38:31.963940       1 session.go:244] Close Session dd01e818-2c7c-4129-a507-b63cdfa9fb28
I0714 05:38:32.966047       1 cache.go:1363] There are <0> Jobs, <1> Queues and <5> Nodes in total for scheduling.
I0714 05:38:32.966191       1 session.go:190] Open Session d866cdfc-fbc2-48d5-bda7-3b0801994088 with <0> Job and <1> Queues
I0714 05:38:32.967899       1 enqueue.go:79] Try to enqueue PodGroup to 0 Queues
I0714 05:38:32.967961       1 allocate.go:64] Try to allocate resource to 0 Queues
I0714 05:38:32.968172       1 session.go:244] Close Session d866cdfc-fbc2-48d5-bda7-3b0801994088
I0714 05:38:33.971070       1 cache.go:1363] There are <0> Jobs, <1> Queues and <5> Nodes in total for scheduling.
I0714 05:38:33.971252       1 session.go:190] Open Session 73ad59d7-6eb0-4139-9538-44fac9bb0051 with <0> Job and <1> Queues
I0714 05:38:33.973109       1 enqueue.go:79] Try to enqueue PodGroup to 0 Queues
I0714 05:38:33.973180       1 allocate.go:64] Try to allocate resource to 0 Queues
I0714 05:38:33.973403       1 session.go:244] Close Session 73ad59d7-6eb0-4139-9538-44fac9bb0051
I0714 05:38:34.977681       1 cache.go:1363] There are <0> Jobs, <1> Queues and <5> Nodes in total for scheduling.
I0714 05:38:34.978315       1 session.go:190] Open Session 23885f82-b733-46ec-868d-fd7ece814b92 with <0> Job and <1> Queues
I0714 05:38:34.980679       1 enqueue.go:79] Try to enqueue PodGroup to 0 Queues
I0714 05:38:34.980754       1 allocate.go:64] Try to allocate resource to 0 Queues
I0714 05:38:34.980982       1 session.go:244] Close Session 23885f82-b733-46ec-868d-fd7ece814b92
I0714 05:38:35.983772       1 cache.go:1363] There are <0> Jobs, <1> Queues and <5> Nodes in total for scheduling.
I0714 05:38:35.983964       1 session.go:190] Open Session e03e4d35-3a11-41e3-8313-82a7b55e591b with <0> Job and <1> Queues
I0714 05:38:35.985783       1 enqueue.go:79] Try to enqueue PodGroup to 0 Queues
I0714 05:38:35.985852       1 allocate.go:64] Try to allocate resource to 0 Queues
I0714 05:38:35.986073       1 session.go:244] Close Session e03e4d35-3a11-41e3-8313-82a7b55e591b
I0714 05:38:36.286038       1 cache.go:1489] The metrics type is not set in the volcano scheduler configmap file. As a result, the CPU and memory load information of the node is not collected.
I0714 05:38:36.988879       1 cache.go:1363] There are <0> Jobs, <1> Queues and <5> Nodes in total for scheduling.
I0714 05:38:36.989066       1 session.go:190] Open Session 07e66e54-e033-4549-b4c9-834bfb7a1815 with <0> Job and <1> Queues
I0714 05:38:36.990788       1 enqueue.go:79] Try to enqueue PodGroup to 0 Queues
I0714 05:38:36.990854       1 allocate.go:64] Try to allocate resource to 0 Queues
I0714 05:38:36.991062       1 session.go:244] Close Session 07e66e54-e033-4549-b4c9-834bfb7a1815
I0714 05:38:37.993871       1 cache.go:1363] There are <0> Jobs, <1> Queues and <5> Nodes in total for scheduling.
I0714 05:38:37.994048       1 session.go:190] Open Session 6074bd2b-8dc0-4525-8bd5-6c4db7853634 with <0> Job and <1> Queues
I0714 05:38:37.995746       1 enqueue.go:79] Try to enqueue PodGroup to 0 Queues
I0714 05:38:37.995806       1 allocate.go:64] Try to allocate resource to 0 Queues
I0714 05:38:37.996017       1 session.go:244] Close Session 6074bd2b-8dc0-4525-8bd5-6c4db7853634
I0714 05:38:38.998565       1 cache.go:1363] There are <0> Jobs, <1> Queues and <5> Nodes in total for scheduling.
I0714 05:38:38.998734       1 session.go:190] Open Session ab993d3b-4545-4e81-ad86-291cafd76411 with <0> Job and <1> Queues
I0714 05:38:39.000639       1 enqueue.go:79] Try to enqueue PodGroup to 0 Queues
I0714 05:38:39.000707       1 allocate.go:64] Try to allocate resource to 0 Queues
I0714 05:38:39.000919       1 session.go:244] Close Session ab993d3b-4545-4e81-ad86-291cafd76411
I0714 05:38:40.003092       1 cache.go:1363] There are <0> Jobs, <1> Queues and <5> Nodes in total for scheduling.
I0714 05:38:40.003258       1 session.go:190] Open Session 55880eea-eb7e-4cf4-8f13-f6b0b0d75c6e with <0> Job and <1> Queues
I0714 05:38:40.005058       1 enqueue.go:79] Try to enqueue PodGroup to 0 Queues
I0714 05:38:40.005125       1 allocate.go:64] Try to allocate resource to 0 Queues
I0714 05:38:40.005341       1 session.go:244] Close Session 55880eea-eb7e-4cf4-8f13-f6b0b0d75c6e
I0714 05:38:41.007883       1 cache.go:1363] There are <0> Jobs, <1> Queues and <5> Nodes in total for scheduling.
I0714 05:38:41.008040       1 session.go:190] Open Session a720dfae-2d0d-4bd0-a3ed-85b3660c0720 with <0> Job and <1> Queues
I0714 05:38:41.009833       1 enqueue.go:79] Try to enqueue PodGroup to 0 Queues
I0714 05:38:41.009898       1 allocate.go:64] Try to allocate resource to 0 Queues
I0714 05:38:41.010100       1 session.go:244] Close Session a720dfae-2d0d-4bd0-a3ed-85b3660c0720
I0714 05:38:42.013002       1 cache.go:1363] There are <0> Jobs, <1> Queues and <5> Nodes in total for scheduling.
I0714 05:38:42.013162       1 session.go:190] Open Session ad6da34d-ee8d-4805-ad23-b6973dfe966d with <0> Job and <1> Queues
I0714 05:38:42.014905       1 enqueue.go:79] Try to enqueue PodGroup to 0 Queues
I0714 05:38:42.014969       1 allocate.go:64] Try to allocate resource to 0 Queues
I0714 05:38:42.015187       1 session.go:244] Close Session ad6da34d-ee8d-4805-ad23-b6973dfe966d
I0714 05:38:43.018103       1 cache.go:1363] There are <0> Jobs, <1> Queues and <5> Nodes in total for scheduling.
I0714 05:38:43.018273       1 session.go:190] Open Session 6dafac0c-f523-435c-a72d-4fed9e055422 with <0> Job and <1> Queues
I0714 05:38:43.020135       1 enqueue.go:79] Try to enqueue PodGroup to 0 Queues
I0714 05:38:43.020200       1 allocate.go:64] Try to allocate resource to 0 Queues
I0714 05:38:43.020458       1 session.go:244] Close Session 6dafac0c-f523-435c-a72d-4fed9e055422
I0714 05:38:44.023318       1 cache.go:1363] There are <0> Jobs, <1> Queues and <5> Nodes in total for scheduling.
I0714 05:38:44.023534       1 session.go:190] Open Session c16d2b46-d049-48fd-ab56-ba7d4d83b0b7 with <0> Job and <1> Queues
I0714 05:38:44.025466       1 enqueue.go:79] Try to enqueue PodGroup to 0 Queues
I0714 05:38:44.025532       1 allocate.go:64] Try to allocate resource to 0 Queues
I0714 05:38:44.025759       1 session.go:244] Close Session c16d2b46-d049-48fd-ab56-ba7d4d83b0b7
I0714 05:38:45.028708       1 cache.go:1363] There are <0> Jobs, <1> Queues and <5> Nodes in total for scheduling.
I0714 05:38:45.028868       1 session.go:190] Open Session f021a657-b951-4b34-8c66-3d4abce14125 with <0> Job and <1> Queues
I0714 05:38:45.030651       1 enqueue.go:79] Try to enqueue PodGroup to 0 Queues
I0714 05:38:45.030728       1 allocate.go:64] Try to allocate resource to 0 Queues
I0714 05:38:45.030962       1 session.go:244] Close Session f021a657-b951-4b34-8c66-3d4abce14125
I0714 05:38:46.033027       1 cache.go:1363] There are <0> Jobs, <1> Queues and <5> Nodes in total for scheduling.
I0714 05:38:46.033180       1 session.go:190] Open Session 45d108c3-9fa7-4a77-a2c9-6c9304837af3 with <0> Job and <1> Queues
I0714 05:38:46.034815       1 enqueue.go:79] Try to enqueue PodGroup to 0 Queues
I0714 05:38:46.034876       1 allocate.go:64] Try to allocate resource to 0 Queues
I0714 05:38:46.035102       1 session.go:244] Close Session 45d108c3-9fa7-4a77-a2c9-6c9304837af3
I0714 05:38:47.037247       1 cache.go:1363] There are <0> Jobs, <1> Queues and <5> Nodes in total for scheduling.
I0714 05:38:47.037417       1 session.go:190] Open Session 177f01e1-6e19-45ae-aad8-c7eefd3def47 with <0> Job and <1> Queues
I0714 05:38:47.039141       1 enqueue.go:79] Try to enqueue PodGroup to 0 Queues
I0714 05:38:47.039210       1 allocate.go:64] Try to allocate resource to 0 Queues
I0714 05:38:47.039430       1 session.go:244] Close Session 177f01e1-6e19-45ae-aad8-c7eefd3def47
I0714 05:38:48.041786       1 cache.go:1363] There are <0> Jobs, <1> Queues and <5> Nodes in total for scheduling.
I0714 05:38:48.041943       1 session.go:190] Open Session d173361b-2b9a-4a5b-ad34-fb7f91219d01 with <0> Job and <1> Queues
I0714 05:38:48.043546       1 enqueue.go:79] Try to enqueue PodGroup to 0 Queues
I0714 05:38:48.043612       1 allocate.go:64] Try to allocate resource to 0 Queues
I0714 05:38:48.043827       1 session.go:244] Close Session d173361b-2b9a-4a5b-ad34-fb7f91219d01
I0714 05:38:49.045896       1 cache.go:1363] There are <0> Jobs, <1> Queues and <5> Nodes in total for scheduling.
I0714 05:38:49.046081       1 session.go:190] Open Session b1de3c7a-9afa-472d-ab38-07d1aa598fa3 with <0> Job and <1> Queues
I0714 05:38:49.047912       1 enqueue.go:79] Try to enqueue PodGroup to 0 Queues
I0714 05:38:49.047983       1 allocate.go:64] Try to allocate resource to 0 Queues
I0714 05:38:49.048208       1 session.go:244] Close Session b1de3c7a-9afa-472d-ab38-07d1aa598fa3
I0714 05:38:50.050483       1 cache.go:1363] There are <0> Jobs, <1> Queues and <5> Nodes in total for scheduling.
I0714 05:38:50.050660       1 session.go:190] Open Session 382a323c-6bac-4daa-864f-b5d6ed90dd63 with <0> Job and <1> Queues
I0714 05:38:50.052594       1 enqueue.go:79] Try to enqueue PodGroup to 0 Queues
I0714 05:38:50.052666       1 allocate.go:64] Try to allocate resource to 0 Queues
I0714 05:38:50.052907       1 session.go:244] Close Session 382a323c-6bac-4daa-864f-b5d6ed90dd63
I0714 05:38:51.055443       1 cache.go:1363] There are <0> Jobs, <1> Queues and <5> Nodes in total for scheduling.
I0714 05:38:51.055606       1 session.go:190] Open Session 571afb18-3af9-430c-8140-c782b60c72c8 with <0> Job and <1> Queues
I0714 05:38:51.057439       1 enqueue.go:79] Try to enqueue PodGroup to 0 Queues
I0714 05:38:51.057525       1 allocate.go:64] Try to allocate resource to 0 Queues
I0714 05:38:51.057742       1 session.go:244] Close Session 571afb18-3af9-430c-8140-c782b60c72c8
I0714 05:38:52.060618       1 cache.go:1363] There are <0> Jobs, <1> Queues and <5> Nodes in total for scheduling.
I0714 05:38:52.060778       1 session.go:190] Open Session eebe4314-7531-42b6-ad1f-60ca13cb4a73 with <0> Job and <1> Queues
I0714 05:38:52.062467       1 enqueue.go:79] Try to enqueue PodGroup to 0 Queues
I0714 05:38:52.062533       1 allocate.go:64] Try to allocate resource to 0 Queues
I0714 05:38:52.062759       1 session.go:244] Close Session eebe4314-7531-42b6-ad1f-60ca13cb4a73
I0714 05:38:53.064723       1 cache.go:1363] There are <0> Jobs, <1> Queues and <5> Nodes in total for scheduling.
I0714 05:38:53.064896       1 session.go:190] Open Session 350e5aa7-3350-4593-b182-952842ce535d with <0> Job and <1> Queues
I0714 05:38:53.066788       1 enqueue.go:79] Try to enqueue PodGroup to 0 Queues
I0714 05:38:53.066857       1 allocate.go:64] Try to allocate resource to 0 Queues
I0714 05:38:53.067079       1 session.go:244] Close Session 350e5aa7-3350-4593-b182-952842ce535d
I0714 05:38:54.069958       1 cache.go:1363] There are <0> Jobs, <1> Queues and <5> Nodes in total for scheduling.
I0714 05:38:54.070139       1 session.go:190] Open Session 47562bf8-d289-4928-bc25-6777522d03e5 with <0> Job and <1> Queues
I0714 05:38:54.071897       1 enqueue.go:79] Try to enqueue PodGroup to 0 Queues
I0714 05:38:54.071970       1 allocate.go:64] Try to allocate resource to 0 Queues
I0714 05:38:54.072178       1 session.go:244] Close Session 47562bf8-d289-4928-bc25-6777522d03e5
I0714 05:38:55.074134       1 cache.go:1363] There are <0> Jobs, <1> Queues and <5> Nodes in total for scheduling.
I0714 05:38:55.074309       1 session.go:190] Open Session 60616d12-df97-4375-b7da-d6f239803f69 with <0> Job and <1> Queues
I0714 05:38:55.076077       1 enqueue.go:79] Try to enqueue PodGroup to 0 Queues
I0714 05:38:55.076148       1 allocate.go:64] Try to allocate resource to 0 Queues
I0714 05:38:55.076413       1 session.go:244] Close Session 60616d12-df97-4375-b7da-d6f239803f69
I0714 05:38:56.078822       1 cache.go:1363] There are <0> Jobs, <1> Queues and <5> Nodes in total for scheduling.
I0714 05:38:56.078976       1 session.go:190] Open Session c2e8bca2-0f90-4712-a1dc-b026122f07e6 with <0> Job and <1> Queues
I0714 05:38:56.080757       1 enqueue.go:79] Try to enqueue PodGroup to 0 Queues
I0714 05:38:56.080825       1 allocate.go:64] Try to allocate resource to 0 Queues
I0714 05:38:56.081034       1 session.go:244] Close Session c2e8bca2-0f90-4712-a1dc-b026122f07e6
I0714 05:38:57.082957       1 cache.go:1363] There are <0> Jobs, <1> Queues and <5> Nodes in total for scheduling.
I0714 05:38:57.083113       1 session.go:190] Open Session 0735cccf-c085-4fb0-bb6e-6d03d32d5885 with <0> Job and <1> Queues
I0714 05:38:57.084895       1 enqueue.go:79] Try to enqueue PodGroup to 0 Queues
I0714 05:38:57.084961       1 allocate.go:64] Try to allocate resource to 0 Queues
I0714 05:38:57.085183       1 session.go:244] Close Session 0735cccf-c085-4fb0-bb6e-6d03d32d5885
I0714 05:38:58.087734       1 cache.go:1363] There are <0> Jobs, <1> Queues and <5> Nodes in total for scheduling.
I0714 05:38:58.087889       1 session.go:190] Open Session 66e4a0f6-2ad7-470a-a15e-6d4c21d2f300 with <0> Job and <1> Queues
I0714 05:38:58.089637       1 enqueue.go:79] Try to enqueue PodGroup to 0 Queues
I0714 05:38:58.089705       1 allocate.go:64] Try to allocate resource to 0 Queues
I0714 05:38:58.089914       1 session.go:244] Close Session 66e4a0f6-2ad7-470a-a15e-6d4c21d2f300
I0714 05:38:59.092758       1 cache.go:1363] There are <0> Jobs, <1> Queues and <5> Nodes in total for scheduling.
I0714 05:38:59.092925       1 session.go:190] Open Session e022c2e7-d7cc-4c5c-b702-2410fa89d05a with <0> Job and <1> Queues
I0714 05:38:59.094728       1 enqueue.go:79] Try to enqueue PodGroup to 0 Queues
I0714 05:38:59.094799       1 allocate.go:64] Try to allocate resource to 0 Queues
I0714 05:38:59.095009       1 session.go:244] Close Session e022c2e7-d7cc-4c5c-b702-2410fa89d05a
I0714 05:39:00.097627       1 cache.go:1363] There are <0> Jobs, <1> Queues and <5> Nodes in total for scheduling.
I0714 05:39:00.097788       1 session.go:190] Open Session e572cb15-b9a8-41f6-b7f7-b4d88e4a0e62 with <0> Job and <1> Queues
I0714 05:39:00.099501       1 enqueue.go:79] Try to enqueue PodGroup to 0 Queues
I0714 05:39:00.099569       1 allocate.go:64] Try to allocate resource to 0 Queues
I0714 05:39:00.099791       1 session.go:244] Close Session e572cb15-b9a8-41f6-b7f7-b4d88e4a0e62
I0714 05:39:01.101899       1 cache.go:1363] There are <0> Jobs, <1> Queues and <5> Nodes in total for scheduling.
I0714 05:39:01.102054       1 session.go:190] Open Session 4600c4aa-f8ab-4814-85b2-2da20081f4dc with <0> Job and <1> Queues
I0714 05:39:01.103872       1 enqueue.go:79] Try to enqueue PodGroup to 0 Queues
I0714 05:39:01.103957       1 allocate.go:64] Try to allocate resource to 0 Queues
I0714 05:39:01.104169       1 session.go:244] Close Session 4600c4aa-f8ab-4814-85b2-2da20081f4dc
I0714 05:39:02.106427       1 cache.go:1363] There are <0> Jobs, <1> Queues and <5> Nodes in total for scheduling.
I0714 05:39:02.106599       1 session.go:190] Open Session 7a79b73a-8138-42ef-9582-49e85ba3025f with <0> Job and <1> Queues
I0714 05:39:02.108371       1 enqueue.go:79] Try to enqueue PodGroup to 0 Queues
I0714 05:39:02.108442       1 allocate.go:64] Try to allocate resource to 0 Queues
I0714 05:39:02.108659       1 session.go:244] Close Session 7a79b73a-8138-42ef-9582-49e85ba3025f
I0714 05:39:03.111436       1 cache.go:1363] There are <0> Jobs, <1> Queues and <5> Nodes in total for scheduling.
I0714 05:39:03.111574       1 session.go:190] Open Session 0ecc4b8a-aa5d-4df8-a5bb-07b2061c19b7 with <0> Job and <1> Queues
I0714 05:39:03.113206       1 enqueue.go:79] Try to enqueue PodGroup to 0 Queues
I0714 05:39:03.113279       1 allocate.go:64] Try to allocate resource to 0 Queues
I0714 05:39:03.113507       1 session.go:244] Close Session 0ecc4b8a-aa5d-4df8-a5bb-07b2061c19b7
I0714 05:39:04.116378       1 cache.go:1363] There are <0> Jobs, <1> Queues and <5> Nodes in total for scheduling.
I0714 05:39:04.116552       1 session.go:190] Open Session 0efc374d-330d-4783-9810-ce8e6bb92054 with <0> Job and <1> Queues
I0714 05:39:04.118257       1 enqueue.go:79] Try to enqueue PodGroup to 0 Queues
I0714 05:39:04.118335       1 allocate.go:64] Try to allocate resource to 0 Queues
I0714 05:39:04.118565       1 session.go:244] Close Session 0efc374d-330d-4783-9810-ce8e6bb92054
I0714 05:39:05.120203       1 cache.go:1363] There are <0> Jobs, <1> Queues and <5> Nodes in total for scheduling.
I0714 05:39:05.120350       1 session.go:190] Open Session 1bdccc7f-f5fa-4b9e-bb2d-7acd54d21b4c with <0> Job and <1> Queues
I0714 05:39:05.121718       1 enqueue.go:79] Try to enqueue PodGroup to 0 Queues
I0714 05:39:05.121782       1 allocate.go:64] Try to allocate resource to 0 Queues
I0714 05:39:05.121961       1 session.go:244] Close Session 1bdccc7f-f5fa-4b9e-bb2d-7acd54d21b4c
I0714 05:39:06.124228       1 cache.go:1363] There are <0> Jobs, <1> Queues and <5> Nodes in total for scheduling.
I0714 05:39:06.124421       1 session.go:190] Open Session ba325ee4-856c-4eaa-98e7-1014fdb3fe98 with <0> Job and <1> Queues
I0714 05:39:06.126026       1 enqueue.go:79] Try to enqueue PodGroup to 0 Queues
I0714 05:39:06.126097       1 allocate.go:64] Try to allocate resource to 0 Queues
I0714 05:39:06.126308       1 session.go:244] Close Session ba325ee4-856c-4eaa-98e7-1014fdb3fe98
I0714 05:39:06.287114       1 cache.go:1489] The metrics type is not set in the volcano scheduler configmap file. As a result, the CPU and memory load information of the node is not collected.
I0714 05:39:07.128218       1 cache.go:1363] There are <0> Jobs, <1> Queues and <5> Nodes in total for scheduling.
I0714 05:39:07.128430       1 session.go:190] Open Session c72016d2-da3b-4521-bd49-c4c528ace97c with <0> Job and <1> Queues
I0714 05:39:07.130264       1 enqueue.go:79] Try to enqueue PodGroup to 0 Queues
I0714 05:39:07.130328       1 allocate.go:64] Try to allocate resource to 0 Queues
I0714 05:39:07.130534       1 session.go:244] Close Session c72016d2-da3b-4521-bd49-c4c528ace97c
I0714 05:39:08.133052       1 cache.go:1363] There are <0> Jobs, <1> Queues and <5> Nodes in total for scheduling.
I0714 05:39:08.133199       1 session.go:190] Open Session ec300340-70b2-40fe-bbcd-49d991f041c9 with <0> Job and <1> Queues
I0714 05:39:08.134772       1 enqueue.go:79] Try to enqueue PodGroup to 0 Queues
I0714 05:39:08.134835       1 allocate.go:64] Try to allocate resource to 0 Queues
I0714 05:39:08.135045       1 session.go:244] Close Session ec300340-70b2-40fe-bbcd-49d991f041c9
I0714 05:39:09.138232       1 cache.go:1363] There are <0> Jobs, <1> Queues and <5> Nodes in total for scheduling.
I0714 05:39:09.138403       1 session.go:190] Open Session f7441887-7e57-40f2-8fcb-6a893b924ca5 with <0> Job and <1> Queues
I0714 05:39:09.140087       1 enqueue.go:79] Try to enqueue PodGroup to 0 Queues
I0714 05:39:09.140163       1 allocate.go:64] Try to allocate resource to 0 Queues
I0714 05:39:09.140408       1 session.go:244] Close Session f7441887-7e57-40f2-8fcb-6a893b924ca5
I0714 05:39:10.142701       1 cache.go:1363] There are <0> Jobs, <1> Queues and <5> Nodes in total for scheduling.
I0714 05:39:10.142871       1 session.go:190] Open Session fdb1b668-6eaa-4ffc-9d70-c90d084c2f81 with <0> Job and <1> Queues
I0714 05:39:10.144633       1 enqueue.go:79] Try to enqueue PodGroup to 0 Queues
I0714 05:39:10.144706       1 allocate.go:64] Try to allocate resource to 0 Queues
I0714 05:39:10.144925       1 session.go:244] Close Session fdb1b668-6eaa-4ffc-9d70-c90d084c2f81
I0714 05:39:11.147550       1 cache.go:1363] There are <0> Jobs, <1> Queues and <5> Nodes in total for scheduling.
I0714 05:39:11.147750       1 session.go:190] Open Session 959fc5aa-d2cd-4f44-bee2-1d2ef04024f2 with <0> Job and <1> Queues
I0714 05:39:11.149507       1 enqueue.go:79] Try to enqueue PodGroup to 0 Queues
I0714 05:39:11.149581       1 allocate.go:64] Try to allocate resource to 0 Queues
I0714 05:39:11.149792       1 session.go:244] Close Session 959fc5aa-d2cd-4f44-bee2-1d2ef04024f2
I0714 05:39:12.152467       1 cache.go:1363] There are <0> Jobs, <1> Queues and <5> Nodes in total for scheduling.
I0714 05:39:12.152639       1 session.go:190] Open Session 05ffcedc-4915-4ce0-acbf-1431a533ec86 with <0> Job and <1> Queues
I0714 05:39:12.154363       1 enqueue.go:79] Try to enqueue PodGroup to 0 Queues
I0714 05:39:12.154433       1 allocate.go:64] Try to allocate resource to 0 Queues
I0714 05:39:12.154642       1 session.go:244] Close Session 05ffcedc-4915-4ce0-acbf-1431a533ec86
I0714 05:39:13.157529       1 cache.go:1363] There are <0> Jobs, <1> Queues and <5> Nodes in total for scheduling.
I0714 05:39:13.157697       1 session.go:190] Open Session b4dd1263-d73c-4f86-8cbe-5bef1a1c8e40 with <0> Job and <1> Queues
I0714 05:39:13.159303       1 enqueue.go:79] Try to enqueue PodGroup to 0 Queues
I0714 05:39:13.159373       1 allocate.go:64] Try to allocate resource to 0 Queues
I0714 05:39:13.159585       1 session.go:244] Close Session b4dd1263-d73c-4f86-8cbe-5bef1a1c8e40
I0714 05:39:14.161957       1 cache.go:1363] There are <0> Jobs, <1> Queues and <5> Nodes in total for scheduling.
I0714 05:39:14.162148       1 session.go:190] Open Session 6ebcd32a-b0a7-4441-a437-4b3808d6c3ac with <0> Job and <1> Queues
I0714 05:39:14.164016       1 enqueue.go:79] Try to enqueue PodGroup to 0 Queues
I0714 05:39:14.164087       1 allocate.go:64] Try to allocate resource to 0 Queues
I0714 05:39:14.164331       1 session.go:244] Close Session 6ebcd32a-b0a7-4441-a437-4b3808d6c3ac
I0714 05:39:15.166406       1 cache.go:1363] There are <0> Jobs, <1> Queues and <5> Nodes in total for scheduling.
I0714 05:39:15.166578       1 session.go:190] Open Session f0742a92-cc35-4959-9634-a23b245de587 with <0> Job and <1> Queues
I0714 05:39:15.168500       1 enqueue.go:79] Try to enqueue PodGroup to 0 Queues
I0714 05:39:15.168571       1 allocate.go:64] Try to allocate resource to 0 Queues
I0714 05:39:15.168799       1 session.go:244] Close Session f0742a92-cc35-4959-9634-a23b245de587
I0714 05:39:16.170727       1 cache.go:1363] There are <0> Jobs, <1> Queues and <5> Nodes in total for scheduling.
I0714 05:39:16.170846       1 session.go:190] Open Session 912108e4-fe3a-48f8-9bf3-eaded7315202 with <0> Job and <1> Queues
I0714 05:39:16.172276       1 enqueue.go:79] Try to enqueue PodGroup to 0 Queues
I0714 05:39:16.172368       1 allocate.go:64] Try to allocate resource to 0 Queues
I0714 05:39:16.172536       1 session.go:244] Close Session 912108e4-fe3a-48f8-9bf3-eaded7315202
I0714 05:39:17.174712       1 cache.go:1363] There are <0> Jobs, <1> Queues and <5> Nodes in total for scheduling.
I0714 05:39:17.174868       1 session.go:190] Open Session 76753506-b8fe-4325-9758-98e694e30d88 with <0> Job and <1> Queues
I0714 05:39:17.176479       1 enqueue.go:79] Try to enqueue PodGroup to 0 Queues
I0714 05:39:17.176539       1 allocate.go:64] Try to allocate resource to 0 Queues
I0714 05:39:17.176746       1 session.go:244] Close Session 76753506-b8fe-4325-9758-98e694e30d88
I0714 05:39:18.179298       1 cache.go:1363] There are <0> Jobs, <1> Queues and <5> Nodes in total for scheduling.
I0714 05:39:18.179440       1 session.go:190] Open Session c7aea204-addf-4f1a-aedc-f0f4713ed228 with <0> Job and <1> Queues
I0714 05:39:18.181101       1 enqueue.go:79] Try to enqueue PodGroup to 0 Queues
I0714 05:39:18.181166       1 allocate.go:64] Try to allocate resource to 0 Queues
I0714 05:39:18.181358       1 session.go:244] Close Session c7aea204-addf-4f1a-aedc-f0f4713ed228
I0714 05:39:19.184053       1 cache.go:1363] There are <0> Jobs, <1> Queues and <5> Nodes in total for scheduling.
I0714 05:39:19.184229       1 session.go:190] Open Session 568d0988-cfb0-4190-b8dc-33c2f9332253 with <0> Job and <1> Queues
I0714 05:39:19.185959       1 enqueue.go:79] Try to enqueue PodGroup to 0 Queues
I0714 05:39:19.186028       1 allocate.go:64] Try to allocate resource to 0 Queues
I0714 05:39:19.186244       1 session.go:244] Close Session 568d0988-cfb0-4190-b8dc-33c2f9332253
I0714 05:39:20.188218       1 cache.go:1363] There are <0> Jobs, <1> Queues and <5> Nodes in total for scheduling.
I0714 05:39:20.188397       1 session.go:190] Open Session 98cd665c-ac89-4da1-aeec-66cd341c8575 with <0> Job and <1> Queues
I0714 05:39:20.189984       1 enqueue.go:79] Try to enqueue PodGroup to 0 Queues
I0714 05:39:20.190048       1 allocate.go:64] Try to allocate resource to 0 Queues
I0714 05:39:20.190358       1 session.go:244] Close Session 98cd665c-ac89-4da1-aeec-66cd341c8575
I0714 05:39:21.193035       1 cache.go:1363] There are <0> Jobs, <1> Queues and <5> Nodes in total for scheduling.
I0714 05:39:21.193213       1 session.go:190] Open Session 3cd74e04-2b55-493c-8790-f3c426b78806 with <0> Job and <1> Queues
I0714 05:39:21.194880       1 enqueue.go:79] Try to enqueue PodGroup to 0 Queues
I0714 05:39:21.194960       1 allocate.go:64] Try to allocate resource to 0 Queues
I0714 05:39:21.195172       1 session.go:244] Close Session 3cd74e04-2b55-493c-8790-f3c426b78806
I0714 05:39:22.197623       1 cache.go:1363] There are <0> Jobs, <1> Queues and <5> Nodes in total for scheduling.
I0714 05:39:22.197811       1 session.go:190] Open Session 6a2b5699-36de-4651-beaf-24213cace2bc with <0> Job and <1> Queues
I0714 05:39:22.199527       1 enqueue.go:79] Try to enqueue PodGroup to 0 Queues
I0714 05:39:22.199593       1 allocate.go:64] Try to allocate resource to 0 Queues
I0714 05:39:22.199812       1 session.go:244] Close Session 6a2b5699-36de-4651-beaf-24213cace2bc
I0714 05:39:23.202480       1 cache.go:1363] There are <0> Jobs, <1> Queues and <5> Nodes in total for scheduling.
I0714 05:39:23.202642       1 session.go:190] Open Session f17bbc4c-368c-4c9f-a2dc-82b450f4a2a6 with <0> Job and <1> Queues
I0714 05:39:23.204468       1 enqueue.go:79] Try to enqueue PodGroup to 0 Queues
I0714 05:39:23.204543       1 allocate.go:64] Try to allocate resource to 0 Queues
I0714 05:39:23.204758       1 session.go:244] Close Session f17bbc4c-368c-4c9f-a2dc-82b450f4a2a6
I0714 05:39:24.206927       1 cache.go:1363] There are <0> Jobs, <1> Queues and <5> Nodes in total for scheduling.
I0714 05:39:24.207157       1 session.go:190] Open Session c49aaf74-4eed-4769-b870-7077e0abe702 with <0> Job and <1> Queues
I0714 05:39:24.208943       1 enqueue.go:79] Try to enqueue PodGroup to 0 Queues
I0714 05:39:24.209051       1 allocate.go:64] Try to allocate resource to 0 Queues
I0714 05:39:24.209295       1 session.go:244] Close Session c49aaf74-4eed-4769-b870-7077e0abe702
I0714 05:39:25.211895       1 cache.go:1363] There are <0> Jobs, <1> Queues and <5> Nodes in total for scheduling.
I0714 05:39:25.212051       1 session.go:190] Open Session 8069c9d0-d172-498a-b288-2a85765ea328 with <0> Job and <1> Queues
I0714 05:39:25.215138       1 enqueue.go:79] Try to enqueue PodGroup to 0 Queues
I0714 05:39:25.215231       1 allocate.go:64] Try to allocate resource to 0 Queues
I0714 05:39:25.215496       1 session.go:244] Close Session 8069c9d0-d172-498a-b288-2a85765ea328
I0714 05:39:26.218090       1 cache.go:1363] There are <0> Jobs, <1> Queues and <5> Nodes in total for scheduling.
I0714 05:39:26.218260       1 session.go:190] Open Session 63136030-0fef-403c-a888-015508ffb430 with <0> Job and <1> Queues
I0714 05:39:26.219887       1 enqueue.go:79] Try to enqueue PodGroup to 0 Queues
I0714 05:39:26.219952       1 allocate.go:64] Try to allocate resource to 0 Queues
I0714 05:39:26.220161       1 session.go:244] Close Session 63136030-0fef-403c-a888-015508ffb430
I0714 05:39:27.223240       1 cache.go:1363] There are <0> Jobs, <1> Queues and <5> Nodes in total for scheduling.
I0714 05:39:27.223419       1 session.go:190] Open Session 5d776592-3645-4de7-ae76-0ba9c6444e56 with <0> Job and <1> Queues
I0714 05:39:27.225032       1 enqueue.go:79] Try to enqueue PodGroup to 0 Queues
I0714 05:39:27.225098       1 allocate.go:64] Try to allocate resource to 0 Queues
I0714 05:39:27.225305       1 session.go:244] Close Session 5d776592-3645-4de7-ae76-0ba9c6444e56
I0714 05:39:28.227602       1 cache.go:1363] There are <0> Jobs, <1> Queues and <5> Nodes in total for scheduling.
I0714 05:39:28.227755       1 session.go:190] Open Session 0d28aec2-f477-45ac-94c4-ff33d0c04d93 with <0> Job and <1> Queues
I0714 05:39:28.229437       1 enqueue.go:79] Try to enqueue PodGroup to 0 Queues
I0714 05:39:28.229520       1 allocate.go:64] Try to allocate resource to 0 Queues
I0714 05:39:28.229724       1 session.go:244] Close Session 0d28aec2-f477-45ac-94c4-ff33d0c04d93
I0714 05:39:29.232321       1 cache.go:1363] There are <0> Jobs, <1> Queues and <5> Nodes in total for scheduling.
I0714 05:39:29.232510       1 session.go:190] Open Session 75bf3be9-b62c-4f70-b4df-63b87e564d0f with <0> Job and <1> Queues
I0714 05:39:29.234304       1 enqueue.go:79] Try to enqueue PodGroup to 0 Queues
I0714 05:39:29.234373       1 allocate.go:64] Try to allocate resource to 0 Queues
I0714 05:39:29.234576       1 session.go:244] Close Session 75bf3be9-b62c-4f70-b4df-63b87e564d0f
I0714 05:39:30.237459       1 cache.go:1363] There are <0> Jobs, <1> Queues and <5> Nodes in total for scheduling.
I0714 05:39:30.237640       1 session.go:190] Open Session f081d960-e598-411f-84e1-8cade413e969 with <0> Job and <1> Queues
I0714 05:39:30.239363       1 enqueue.go:79] Try to enqueue PodGroup to 0 Queues
I0714 05:39:30.239438       1 allocate.go:64] Try to allocate resource to 0 Queues
I0714 05:39:30.239676       1 session.go:244] Close Session f081d960-e598-411f-84e1-8cade413e969
I0714 05:39:31.242242       1 cache.go:1363] There are <0> Jobs, <1> Queues and <5> Nodes in total for scheduling.
I0714 05:39:31.242401       1 session.go:190] Open Session 99681fd2-c14e-489d-9cb0-80e7c6f95308 with <0> Job and <1> Queues
I0714 05:39:31.244159       1 enqueue.go:79] Try to enqueue PodGroup to 0 Queues
I0714 05:39:31.244230       1 allocate.go:64] Try to allocate resource to 0 Queues
I0714 05:39:31.244466       1 session.go:244] Close Session 99681fd2-c14e-489d-9cb0-80e7c6f95308
I0714 05:39:32.246472       1 cache.go:1363] There are <0> Jobs, <1> Queues and <5> Nodes in total for scheduling.
I0714 05:39:32.246675       1 session.go:190] Open Session 8ab2f7ea-9a4b-42a8-a915-10cbe9200b96 with <0> Job and <1> Queues
I0714 05:39:32.248433       1 enqueue.go:79] Try to enqueue PodGroup to 0 Queues
I0714 05:39:32.248504       1 allocate.go:64] Try to allocate resource to 0 Queues
I0714 05:39:32.248710       1 session.go:244] Close Session 8ab2f7ea-9a4b-42a8-a915-10cbe9200b96
I0714 05:39:33.251331       1 cache.go:1363] There are <0> Jobs, <1> Queues and <5> Nodes in total for scheduling.
I0714 05:39:33.251521       1 session.go:190] Open Session 0cce38c8-de7d-4dc7-8d84-e4c671263900 with <0> Job and <1> Queues
I0714 05:39:33.253284       1 enqueue.go:79] Try to enqueue PodGroup to 0 Queues
I0714 05:39:33.253417       1 allocate.go:64] Try to allocate resource to 0 Queues
I0714 05:39:33.253736       1 session.go:244] Close Session 0cce38c8-de7d-4dc7-8d84-e4c671263900
I0714 05:39:34.255963       1 cache.go:1363] There are <0> Jobs, <1> Queues and <5> Nodes in total for scheduling.
I0714 05:39:34.256162       1 session.go:190] Open Session a72323e1-9629-4519-a9de-ad369e1de554 with <0> Job and <1> Queues
I0714 05:39:34.258052       1 enqueue.go:79] Try to enqueue PodGroup to 0 Queues
I0714 05:39:34.258139       1 allocate.go:64] Try to allocate resource to 0 Queues
I0714 05:39:34.258359       1 session.go:244] Close Session a72323e1-9629-4519-a9de-ad369e1de554
I0714 05:39:35.261058       1 cache.go:1363] There are <0> Jobs, <1> Queues and <5> Nodes in total for scheduling.
I0714 05:39:35.261227       1 session.go:190] Open Session 90bad024-b19c-45c1-8e50-3f42b0000b66 with <0> Job and <1> Queues
I0714 05:39:35.263099       1 enqueue.go:79] Try to enqueue PodGroup to 0 Queues
I0714 05:39:35.263172       1 allocate.go:64] Try to allocate resource to 0 Queues
I0714 05:39:35.263402       1 session.go:244] Close Session 90bad024-b19c-45c1-8e50-3f42b0000b66
I0714 05:39:36.266260       1 cache.go:1363] There are <0> Jobs, <1> Queues and <5> Nodes in total for scheduling.
I0714 05:39:36.266424       1 session.go:190] Open Session 76979740-ec33-4b7d-ba5e-0e2830da17ba with <0> Job and <1> Queues
I0714 05:39:36.268151       1 enqueue.go:79] Try to enqueue PodGroup to 0 Queues
I0714 05:39:36.268219       1 allocate.go:64] Try to allocate resource to 0 Queues
I0714 05:39:36.268472       1 session.go:244] Close Session 76979740-ec33-4b7d-ba5e-0e2830da17ba
I0714 05:39:36.288141       1 cache.go:1489] The metrics type is not set in the volcano scheduler configmap file. As a result, the CPU and memory load information of the node is not collected.
I0714 05:39:37.270453       1 cache.go:1363] There are <0> Jobs, <1> Queues and <5> Nodes in total for scheduling.
I0714 05:39:37.270604       1 session.go:190] Open Session b9a8f72d-57a1-4139-8214-34e8e80cbc81 with <0> Job and <1> Queues
I0714 05:39:37.272323       1 enqueue.go:79] Try to enqueue PodGroup to 0 Queues
I0714 05:39:37.272398       1 allocate.go:64] Try to allocate resource to 0 Queues
I0714 05:39:37.272631       1 session.go:244] Close Session b9a8f72d-57a1-4139-8214-34e8e80cbc81
I0714 05:39:38.274971       1 cache.go:1363] There are <0> Jobs, <1> Queues and <5> Nodes in total for scheduling.
I0714 05:39:38.275088       1 session.go:190] Open Session ec78a97b-a295-4942-9421-6388ca05db6d with <0> Job and <1> Queues
I0714 05:39:38.276693       1 enqueue.go:79] Try to enqueue PodGroup to 0 Queues
I0714 05:39:38.276757       1 allocate.go:64] Try to allocate resource to 0 Queues
I0714 05:39:38.276955       1 session.go:244] Close Session ec78a97b-a295-4942-9421-6388ca05db6d
I0714 05:39:39.279864       1 cache.go:1363] There are <0> Jobs, <1> Queues and <5> Nodes in total for scheduling.
I0714 05:39:39.280035       1 session.go:190] Open Session 7d1e19c1-65db-4b64-80dd-2c124d059b9f with <0> Job and <1> Queues
I0714 05:39:39.281975       1 enqueue.go:79] Try to enqueue PodGroup to 0 Queues
I0714 05:39:39.282062       1 allocate.go:64] Try to allocate resource to 0 Queues
I0714 05:39:39.282285       1 session.go:244] Close Session 7d1e19c1-65db-4b64-80dd-2c124d059b9f
I0714 05:39:40.284655       1 cache.go:1363] There are <0> Jobs, <1> Queues and <5> Nodes in total for scheduling.
I0714 05:39:40.284778       1 session.go:190] Open Session 37e280e6-5764-407d-8465-30119355cc48 with <0> Job and <1> Queues
I0714 05:39:40.286268       1 enqueue.go:79] Try to enqueue PodGroup to 0 Queues
I0714 05:39:40.286335       1 allocate.go:64] Try to allocate resource to 0 Queues
I0714 05:39:40.286518       1 session.go:244] Close Session 37e280e6-5764-407d-8465-30119355cc48
I0714 05:39:41.288095       1 cache.go:1363] There are <0> Jobs, <1> Queues and <5> Nodes in total for scheduling.
I0714 05:39:41.288251       1 session.go:190] Open Session 0ca9d070-d9ea-4c57-abab-5eec5e41dc08 with <0> Job and <1> Queues
I0714 05:39:41.289840       1 enqueue.go:79] Try to enqueue PodGroup to 0 Queues
I0714 05:39:41.289921       1 allocate.go:64] Try to allocate resource to 0 Queues
I0714 05:39:41.290122       1 session.go:244] Close Session 0ca9d070-d9ea-4c57-abab-5eec5e41dc08
I0714 05:39:42.291574       1 cache.go:1363] There are <0> Jobs, <1> Queues and <5> Nodes in total for scheduling.
I0714 05:39:42.291707       1 session.go:190] Open Session 982d7106-6c3a-472c-b15f-c82efd8c3fae with <0> Job and <1> Queues
I0714 05:39:42.293241       1 enqueue.go:79] Try to enqueue PodGroup to 0 Queues
I0714 05:39:42.293321       1 allocate.go:64] Try to allocate resource to 0 Queues
I0714 05:39:42.293501       1 session.go:244] Close Session 982d7106-6c3a-472c-b15f-c82efd8c3fae
I0714 05:39:43.295206       1 cache.go:1363] There are <0> Jobs, <1> Queues and <5> Nodes in total for scheduling.
I0714 05:39:43.295320       1 session.go:190] Open Session 0658f199-ce91-4489-96e5-0e0212554c67 with <0> Job and <1> Queues
I0714 05:39:43.296649       1 enqueue.go:79] Try to enqueue PodGroup to 0 Queues
I0714 05:39:43.296702       1 allocate.go:64] Try to allocate resource to 0 Queues
I0714 05:39:43.296854       1 session.go:244] Close Session 0658f199-ce91-4489-96e5-0e0212554c67
I0714 05:39:44.299332       1 cache.go:1363] There are <0> Jobs, <1> Queues and <5> Nodes in total for scheduling.
I0714 05:39:44.299529       1 session.go:190] Open Session 304705d0-9ad1-4775-bddf-a0df142e6d67 with <0> Job and <1> Queues
I0714 05:39:44.301394       1 enqueue.go:79] Try to enqueue PodGroup to 0 Queues
I0714 05:39:44.301465       1 allocate.go:64] Try to allocate resource to 0 Queues
I0714 05:39:44.301661       1 session.go:244] Close Session 304705d0-9ad1-4775-bddf-a0df142e6d67
I0714 05:39:45.303813       1 cache.go:1363] There are <0> Jobs, <1> Queues and <5> Nodes in total for scheduling.
I0714 05:39:45.303992       1 session.go:190] Open Session 9ad4f95a-2977-4d6e-acbf-c9518ab20a31 with <0> Job and <1> Queues
I0714 05:39:45.305895       1 enqueue.go:79] Try to enqueue PodGroup to 0 Queues
I0714 05:39:45.305964       1 allocate.go:64] Try to allocate resource to 0 Queues
I0714 05:39:45.306165       1 session.go:244] Close Session 9ad4f95a-2977-4d6e-acbf-c9518ab20a31
I0714 05:39:46.308727       1 cache.go:1363] There are <0> Jobs, <1> Queues and <5> Nodes in total for scheduling.
I0714 05:39:46.308887       1 session.go:190] Open Session 036b2188-ad6a-4c4c-b25f-01dc6cf0ec49 with <0> Job and <1> Queues
I0714 05:39:46.310568       1 enqueue.go:79] Try to enqueue PodGroup to 0 Queues
I0714 05:39:46.310631       1 allocate.go:64] Try to allocate resource to 0 Queues
I0714 05:39:46.310837       1 session.go:244] Close Session 036b2188-ad6a-4c4c-b25f-01dc6cf0ec49
I0714 05:39:47.313501       1 cache.go:1363] There are <0> Jobs, <1> Queues and <5> Nodes in total for scheduling.
I0714 05:39:47.313657       1 session.go:190] Open Session 211a29b9-6ae9-4501-b4c5-6a750cc13ffb with <0> Job and <1> Queues
I0714 05:39:47.315297       1 enqueue.go:79] Try to enqueue PodGroup to 0 Queues
I0714 05:39:47.315366       1 allocate.go:64] Try to allocate resource to 0 Queues
I0714 05:39:47.315662       1 session.go:244] Close Session 211a29b9-6ae9-4501-b4c5-6a750cc13ffb
I0714 05:39:48.318130       1 cache.go:1363] There are <0> Jobs, <1> Queues and <5> Nodes in total for scheduling.
I0714 05:39:48.318281       1 session.go:190] Open Session fe1d5749-cbef-44f8-9505-8be5c9dc8572 with <0> Job and <1> Queues
I0714 05:39:48.319990       1 enqueue.go:79] Try to enqueue PodGroup to 0 Queues
I0714 05:39:48.320058       1 allocate.go:64] Try to allocate resource to 0 Queues
I0714 05:39:48.320269       1 session.go:244] Close Session fe1d5749-cbef-44f8-9505-8be5c9dc8572
I0714 05:39:49.322274       1 cache.go:1363] There are <0> Jobs, <1> Queues and <5> Nodes in total for scheduling.
I0714 05:39:49.322377       1 session.go:190] Open Session 16a1cfbb-d55e-47bb-80b5-d678c963b6ae with <0> Job and <1> Queues
I0714 05:39:49.323301       1 enqueue.go:79] Try to enqueue PodGroup to 0 Queues
I0714 05:39:49.323346       1 allocate.go:64] Try to allocate resource to 0 Queues
I0714 05:39:49.323459       1 session.go:244] Close Session 16a1cfbb-d55e-47bb-80b5-d678c963b6ae
I0714 05:39:50.326058       1 cache.go:1363] There are <0> Jobs, <1> Queues and <5> Nodes in total for scheduling.
I0714 05:39:50.326232       1 session.go:190] Open Session a10a1f0e-425a-4cf9-884f-3d8b1e197d0a with <0> Job and <1> Queues
I0714 05:39:50.327966       1 enqueue.go:79] Try to enqueue PodGroup to 0 Queues
I0714 05:39:50.328035       1 allocate.go:64] Try to allocate resource to 0 Queues
I0714 05:39:50.328251       1 session.go:244] Close Session a10a1f0e-425a-4cf9-884f-3d8b1e197d0a
I0714 05:39:51.330780       1 cache.go:1363] There are <0> Jobs, <1> Queues and <5> Nodes in total for scheduling.
I0714 05:39:51.330963       1 session.go:190] Open Session a6ae5065-7c97-43f7-b8cb-dca667d63e72 with <0> Job and <1> Queues
I0714 05:39:51.332768       1 enqueue.go:79] Try to enqueue PodGroup to 0 Queues
I0714 05:39:51.332835       1 allocate.go:64] Try to allocate resource to 0 Queues
I0714 05:39:51.333053       1 session.go:244] Close Session a6ae5065-7c97-43f7-b8cb-dca667d63e72
I0714 05:39:52.335457       1 cache.go:1363] There are <0> Jobs, <1> Queues and <5> Nodes in total for scheduling.
I0714 05:39:52.335623       1 session.go:190] Open Session eaa34779-aae9-426a-befe-6141cc15bc1f with <0> Job and <1> Queues
I0714 05:39:52.337418       1 enqueue.go:79] Try to enqueue PodGroup to 0 Queues
I0714 05:39:52.337490       1 allocate.go:64] Try to allocate resource to 0 Queues
I0714 05:39:52.337693       1 session.go:244] Close Session eaa34779-aae9-426a-befe-6141cc15bc1f
I0714 05:39:53.340392       1 cache.go:1363] There are <0> Jobs, <1> Queues and <5> Nodes in total for scheduling.
I0714 05:39:53.340557       1 session.go:190] Open Session 661469ca-d30b-4c6c-8779-110d4c85b4cf with <0> Job and <1> Queues
I0714 05:39:53.342236       1 enqueue.go:79] Try to enqueue PodGroup to 0 Queues
I0714 05:39:53.342313       1 allocate.go:64] Try to allocate resource to 0 Queues
I0714 05:39:53.342524       1 session.go:244] Close Session 661469ca-d30b-4c6c-8779-110d4c85b4cf
I0714 05:39:54.345551       1 cache.go:1363] There are <0> Jobs, <1> Queues and <5> Nodes in total for scheduling.
I0714 05:39:54.345725       1 session.go:190] Open Session f8608c5c-6db3-4f72-ba97-0ce68976afd3 with <0> Job and <1> Queues
I0714 05:39:54.347500       1 enqueue.go:79] Try to enqueue PodGroup to 0 Queues
I0714 05:39:54.347569       1 allocate.go:64] Try to allocate resource to 0 Queues
I0714 05:39:54.347780       1 session.go:244] Close Session f8608c5c-6db3-4f72-ba97-0ce68976afd3
I0714 05:39:55.349849       1 cache.go:1363] There are <0> Jobs, <1> Queues and <5> Nodes in total for scheduling.
I0714 05:39:55.350023       1 session.go:190] Open Session 10a62f76-f854-4bbd-9e32-c0d10bebc914 with <0> Job and <1> Queues
I0714 05:39:55.351814       1 enqueue.go:79] Try to enqueue PodGroup to 0 Queues
I0714 05:39:55.351883       1 allocate.go:64] Try to allocate resource to 0 Queues
I0714 05:39:55.352083       1 session.go:244] Close Session 10a62f76-f854-4bbd-9e32-c0d10bebc914
I0714 05:39:56.353993       1 cache.go:1363] There are <0> Jobs, <1> Queues and <5> Nodes in total for scheduling.
I0714 05:39:56.354159       1 session.go:190] Open Session 99be8f90-a65e-4cd0-83b4-6eddb38ba79b with <0> Job and <1> Queues
I0714 05:39:56.355740       1 enqueue.go:79] Try to enqueue PodGroup to 0 Queues
I0714 05:39:56.355808       1 allocate.go:64] Try to allocate resource to 0 Queues
I0714 05:39:56.356017       1 session.go:244] Close Session 99be8f90-a65e-4cd0-83b4-6eddb38ba79b
I0714 05:39:57.358954       1 cache.go:1363] There are <0> Jobs, <1> Queues and <5> Nodes in total for scheduling.
I0714 05:39:57.359132       1 session.go:190] Open Session 971de602-bcfd-4475-90a3-e5e8628687f0 with <0> Job and <1> Queues
I0714 05:39:57.360961       1 enqueue.go:79] Try to enqueue PodGroup to 0 Queues
I0714 05:39:57.361033       1 allocate.go:64] Try to allocate resource to 0 Queues
I0714 05:39:57.361242       1 session.go:244] Close Session 971de602-bcfd-4475-90a3-e5e8628687f0
I0714 05:39:58.363569       1 cache.go:1363] There are <0> Jobs, <1> Queues and <5> Nodes in total for scheduling.
I0714 05:39:58.363726       1 session.go:190] Open Session 9b3b6c8b-a396-4264-a906-8d404eb75c67 with <0> Job and <1> Queues
I0714 05:39:58.365457       1 enqueue.go:79] Try to enqueue PodGroup to 0 Queues
I0714 05:39:58.365522       1 allocate.go:64] Try to allocate resource to 0 Queues
I0714 05:39:58.365748       1 session.go:244] Close Session 9b3b6c8b-a396-4264-a906-8d404eb75c67
I0714 05:39:59.367980       1 cache.go:1363] There are <0> Jobs, <1> Queues and <5> Nodes in total for scheduling.
I0714 05:39:59.368201       1 session.go:190] Open Session bfeec1f9-d673-43b4-ae7a-160146e98327 with <0> Job and <1> Queues
I0714 05:39:59.370108       1 enqueue.go:79] Try to enqueue PodGroup to 0 Queues
I0714 05:39:59.370182       1 allocate.go:64] Try to allocate resource to 0 Queues
I0714 05:39:59.370391       1 session.go:244] Close Session bfeec1f9-d673-43b4-ae7a-160146e98327
I0714 05:40:00.373223       1 cache.go:1363] There are <0> Jobs, <1> Queues and <5> Nodes in total for scheduling.
I0714 05:40:00.373389       1 session.go:190] Open Session db53306d-996a-4f46-a189-3d53cdeb34a3 with <0> Job and <1> Queues
I0714 05:40:00.375171       1 enqueue.go:79] Try to enqueue PodGroup to 0 Queues
I0714 05:40:00.375238       1 allocate.go:64] Try to allocate resource to 0 Queues
I0714 05:40:00.375471       1 session.go:244] Close Session db53306d-996a-4f46-a189-3d53cdeb34a3
I0714 05:40:01.376874       1 cache.go:1363] There are <0> Jobs, <1> Queues and <5> Nodes in total for scheduling.
I0714 05:40:01.376957       1 session.go:190] Open Session 7c666386-3544-426e-ac51-9a0188543ff9 with <0> Job and <1> Queues
I0714 05:40:01.377737       1 enqueue.go:79] Try to enqueue PodGroup to 0 Queues
I0714 05:40:01.377771       1 allocate.go:64] Try to allocate resource to 0 Queues
I0714 05:40:01.377868       1 session.go:244] Close Session 7c666386-3544-426e-ac51-9a0188543ff9
I0714 05:40:02.380076       1 cache.go:1363] There are <0> Jobs, <1> Queues and <5> Nodes in total for scheduling.
I0714 05:40:02.380268       1 session.go:190] Open Session e693f88e-dea0-4c17-b1dc-6adc7329725e with <0> Job and <1> Queues
I0714 05:40:02.382229       1 enqueue.go:79] Try to enqueue PodGroup to 0 Queues
I0714 05:40:02.382305       1 allocate.go:64] Try to allocate resource to 0 Queues
I0714 05:40:02.382524       1 session.go:244] Close Session e693f88e-dea0-4c17-b1dc-6adc7329725e
I0714 05:40:03.385052       1 cache.go:1363] There are <0> Jobs, <1> Queues and <5> Nodes in total for scheduling.
I0714 05:40:03.385226       1 session.go:190] Open Session 50d07647-018f-4d91-a5a0-31713c8413de with <0> Job and <1> Queues
I0714 05:40:03.386994       1 enqueue.go:79] Try to enqueue PodGroup to 0 Queues
I0714 05:40:03.387061       1 allocate.go:64] Try to allocate resource to 0 Queues
I0714 05:40:03.387305       1 session.go:244] Close Session 50d07647-018f-4d91-a5a0-31713c8413de
I0714 05:40:04.390229       1 cache.go:1363] There are <0> Jobs, <1> Queues and <5> Nodes in total for scheduling.
I0714 05:40:04.390420       1 session.go:190] Open Session fbef9ce6-7ef4-4ce7-9bc5-0f4e8c3a3f18 with <0> Job and <1> Queues
I0714 05:40:04.392186       1 enqueue.go:79] Try to enqueue PodGroup to 0 Queues
I0714 05:40:04.392269       1 allocate.go:64] Try to allocate resource to 0 Queues
I0714 05:40:04.392522       1 session.go:244] Close Session fbef9ce6-7ef4-4ce7-9bc5-0f4e8c3a3f18
I0714 05:40:05.395149       1 cache.go:1363] There are <0> Jobs, <1> Queues and <5> Nodes in total for scheduling.
I0714 05:40:05.395323       1 session.go:190] Open Session 0879531a-a89c-4bb8-90fc-114c9054474f with <0> Job and <1> Queues
I0714 05:40:05.397059       1 enqueue.go:79] Try to enqueue PodGroup to 0 Queues
I0714 05:40:05.397129       1 allocate.go:64] Try to allocate resource to 0 Queues
I0714 05:40:05.397347       1 session.go:244] Close Session 0879531a-a89c-4bb8-90fc-114c9054474f
I0714 05:40:06.288850       1 cache.go:1489] The metrics type is not set in the volcano scheduler configmap file. As a result, the CPU and memory load information of the node is not collected.
I0714 05:40:06.399781       1 cache.go:1363] There are <0> Jobs, <1> Queues and <5> Nodes in total for scheduling.
I0714 05:40:06.399905       1 session.go:190] Open Session 2fa68eff-d4b9-4c0f-86f7-0028ac3825bc with <0> Job and <1> Queues
I0714 05:40:06.401818       1 enqueue.go:79] Try to enqueue PodGroup to 0 Queues
I0714 05:40:06.401887       1 allocate.go:64] Try to allocate resource to 0 Queues
I0714 05:40:06.402114       1 session.go:244] Close Session 2fa68eff-d4b9-4c0f-86f7-0028ac3825bc
I0714 05:40:07.405183       1 cache.go:1363] There are <0> Jobs, <1> Queues and <5> Nodes in total for scheduling.
I0714 05:40:07.405363       1 session.go:190] Open Session 2342db65-4307-45a6-9287-69fd1f39cbc8 with <0> Job and <1> Queues
I0714 05:40:07.407194       1 enqueue.go:79] Try to enqueue PodGroup to 0 Queues
I0714 05:40:07.407269       1 allocate.go:64] Try to allocate resource to 0 Queues
I0714 05:40:07.407481       1 session.go:244] Close Session 2342db65-4307-45a6-9287-69fd1f39cbc8
I0714 05:40:08.409815       1 cache.go:1363] There are <0> Jobs, <1> Queues and <5> Nodes in total for scheduling.
I0714 05:40:08.409990       1 session.go:190] Open Session 9c19529b-c5e0-4757-8ff5-69e10272e52f with <0> Job and <1> Queues
I0714 05:40:08.411671       1 enqueue.go:79] Try to enqueue PodGroup to 0 Queues
I0714 05:40:08.411738       1 allocate.go:64] Try to allocate resource to 0 Queues
I0714 05:40:08.411966       1 session.go:244] Close Session 9c19529b-c5e0-4757-8ff5-69e10272e52f
I0714 05:40:09.414083       1 cache.go:1363] There are <0> Jobs, <1> Queues and <5> Nodes in total for scheduling.
I0714 05:40:09.414247       1 session.go:190] Open Session d071d166-c3a5-4c3c-950d-fb09f74192a8 with <0> Job and <1> Queues
I0714 05:40:09.416336       1 enqueue.go:79] Try to enqueue PodGroup to 0 Queues
I0714 05:40:09.416404       1 allocate.go:64] Try to allocate resource to 0 Queues
I0714 05:40:09.416610       1 session.go:244] Close Session d071d166-c3a5-4c3c-950d-fb09f74192a8
I0714 05:40:10.419262       1 cache.go:1363] There are <0> Jobs, <1> Queues and <5> Nodes in total for scheduling.
I0714 05:40:10.419439       1 session.go:190] Open Session 68c8f844-50ca-4f7d-807d-b0ed740ff421 with <0> Job and <1> Queues
I0714 05:40:10.421501       1 enqueue.go:79] Try to enqueue PodGroup to 0 Queues
I0714 05:40:10.421583       1 allocate.go:64] Try to allocate resource to 0 Queues
I0714 05:40:10.421804       1 session.go:244] Close Session 68c8f844-50ca-4f7d-807d-b0ed740ff421
I0714 05:40:11.424797       1 cache.go:1363] There are <0> Jobs, <1> Queues and <5> Nodes in total for scheduling.
I0714 05:40:11.424968       1 session.go:190] Open Session a25dcc26-bef1-4177-81ee-c41e9383863e with <0> Job and <1> Queues
I0714 05:40:11.426886       1 enqueue.go:79] Try to enqueue PodGroup to 0 Queues
I0714 05:40:11.426955       1 allocate.go:64] Try to allocate resource to 0 Queues
I0714 05:40:11.427169       1 session.go:244] Close Session a25dcc26-bef1-4177-81ee-c41e9383863e
I0714 05:40:12.429958       1 cache.go:1363] There are <0> Jobs, <1> Queues and <5> Nodes in total for scheduling.
I0714 05:40:12.430133       1 session.go:190] Open Session e865b0d4-49a3-42a0-ac41-786b5b3b6724 with <0> Job and <1> Queues
I0714 05:40:12.431923       1 enqueue.go:79] Try to enqueue PodGroup to 0 Queues
I0714 05:40:12.431995       1 allocate.go:64] Try to allocate resource to 0 Queues
I0714 05:40:12.432234       1 session.go:244] Close Session e865b0d4-49a3-42a0-ac41-786b5b3b6724
I0714 05:40:13.435078       1 cache.go:1363] There are <0> Jobs, <1> Queues and <5> Nodes in total for scheduling.
I0714 05:40:13.435249       1 session.go:190] Open Session d6e15c03-7013-47a3-8f0c-637b9ffd11de with <0> Job and <1> Queues
I0714 05:40:13.437042       1 enqueue.go:79] Try to enqueue PodGroup to 0 Queues
I0714 05:40:13.437111       1 allocate.go:64] Try to allocate resource to 0 Queues
I0714 05:40:13.437323       1 session.go:244] Close Session d6e15c03-7013-47a3-8f0c-637b9ffd11de
I0714 05:40:14.441663       1 cache.go:1363] There are <0> Jobs, <1> Queues and <5> Nodes in total for scheduling.
I0714 05:40:14.443050       1 session.go:190] Open Session 15d15b0f-1145-4936-8a1e-e8a1d22aa912 with <0> Job and <1> Queues
I0714 05:40:14.445295       1 enqueue.go:79] Try to enqueue PodGroup to 0 Queues
I0714 05:40:14.445409       1 allocate.go:64] Try to allocate resource to 0 Queues
I0714 05:40:14.445655       1 session.go:244] Close Session 15d15b0f-1145-4936-8a1e-e8a1d22aa912
I0714 05:40:15.448623       1 cache.go:1363] There are <0> Jobs, <1> Queues and <5> Nodes in total for scheduling.
I0714 05:40:15.448824       1 session.go:190] Open Session bc5b03be-e6f7-4cfb-bf7a-bb35ff7d8e07 with <0> Job and <1> Queues
I0714 05:40:15.450551       1 enqueue.go:79] Try to enqueue PodGroup to 0 Queues
I0714 05:40:15.450625       1 allocate.go:64] Try to allocate resource to 0 Queues
I0714 05:40:15.450838       1 session.go:244] Close Session bc5b03be-e6f7-4cfb-bf7a-bb35ff7d8e07
I0714 05:40:16.452897       1 cache.go:1363] There are <0> Jobs, <1> Queues and <5> Nodes in total for scheduling.
I0714 05:40:16.452999       1 session.go:190] Open Session 61b9d4cc-eddd-4d97-8771-f3d2bc0c6703 with <0> Job and <1> Queues
I0714 05:40:16.454350       1 enqueue.go:79] Try to enqueue PodGroup to 0 Queues
I0714 05:40:16.454402       1 allocate.go:64] Try to allocate resource to 0 Queues
I0714 05:40:16.454572       1 session.go:244] Close Session 61b9d4cc-eddd-4d97-8771-f3d2bc0c6703
I0714 05:40:17.457495       1 cache.go:1363] There are <0> Jobs, <1> Queues and <5> Nodes in total for scheduling.
I0714 05:40:17.457660       1 session.go:190] Open Session c041d7e2-dde1-40e0-92e0-519c38cf47f5 with <0> Job and <1> Queues
I0714 05:40:17.459276       1 enqueue.go:79] Try to enqueue PodGroup to 0 Queues
I0714 05:40:17.459338       1 allocate.go:64] Try to allocate resource to 0 Queues
I0714 05:40:17.459556       1 session.go:244] Close Session c041d7e2-dde1-40e0-92e0-519c38cf47f5
I0714 05:40:18.462471       1 cache.go:1363] There are <0> Jobs, <1> Queues and <5> Nodes in total for scheduling.
I0714 05:40:18.462662       1 session.go:190] Open Session 10a9a131-7841-4a37-b2c6-67c4cf99b223 with <0> Job and <1> Queues
I0714 05:40:18.464401       1 enqueue.go:79] Try to enqueue PodGroup to 0 Queues
I0714 05:40:18.464466       1 allocate.go:64] Try to allocate resource to 0 Queues
I0714 05:40:18.464682       1 session.go:244] Close Session 10a9a131-7841-4a37-b2c6-67c4cf99b223
I0714 05:40:19.466996       1 cache.go:1363] There are <0> Jobs, <1> Queues and <5> Nodes in total for scheduling.
I0714 05:40:19.467179       1 session.go:190] Open Session 4b4a889f-ef47-4c8e-ab7f-0060fdaf7f72 with <0> Job and <1> Queues
I0714 05:40:19.469023       1 enqueue.go:79] Try to enqueue PodGroup to 0 Queues
I0714 05:40:19.469088       1 allocate.go:64] Try to allocate resource to 0 Queues
I0714 05:40:19.469311       1 session.go:244] Close Session 4b4a889f-ef47-4c8e-ab7f-0060fdaf7f72
I0714 05:40:20.471962       1 cache.go:1363] There are <0> Jobs, <1> Queues and <5> Nodes in total for scheduling.
I0714 05:40:20.472160       1 session.go:190] Open Session 7d208073-5707-4671-ad3c-b9ec2a05746b with <0> Job and <1> Queues
I0714 05:40:20.473979       1 enqueue.go:79] Try to enqueue PodGroup to 0 Queues
I0714 05:40:20.474054       1 allocate.go:64] Try to allocate resource to 0 Queues
I0714 05:40:20.474290       1 session.go:244] Close Session 7d208073-5707-4671-ad3c-b9ec2a05746b
I0714 05:40:21.476822       1 cache.go:1363] There are <0> Jobs, <1> Queues and <5> Nodes in total for scheduling.
I0714 05:40:21.476990       1 session.go:190] Open Session d0ef06aa-91dc-40ff-b5d5-91d3a4e021cb with <0> Job and <1> Queues
I0714 05:40:21.478724       1 enqueue.go:79] Try to enqueue PodGroup to 0 Queues
I0714 05:40:21.478792       1 allocate.go:64] Try to allocate resource to 0 Queues
I0714 05:40:21.479017       1 session.go:244] Close Session d0ef06aa-91dc-40ff-b5d5-91d3a4e021cb
I0714 05:40:22.481421       1 cache.go:1363] There are <0> Jobs, <1> Queues and <5> Nodes in total for scheduling.
I0714 05:40:22.481590       1 session.go:190] Open Session 43c944c6-be1f-41ab-9e6e-820996a32610 with <0> Job and <1> Queues
I0714 05:40:22.483327       1 enqueue.go:79] Try to enqueue PodGroup to 0 Queues
I0714 05:40:22.483396       1 allocate.go:64] Try to allocate resource to 0 Queues
I0714 05:40:22.483643       1 session.go:244] Close Session 43c944c6-be1f-41ab-9e6e-820996a32610
I0714 05:40:23.486516       1 cache.go:1363] There are <0> Jobs, <1> Queues and <5> Nodes in total for scheduling.
I0714 05:40:23.486702       1 session.go:190] Open Session 9a4a3e9a-c867-4479-b78c-7df78dcce609 with <0> Job and <1> Queues
I0714 05:40:23.488726       1 enqueue.go:79] Try to enqueue PodGroup to 0 Queues
I0714 05:40:23.488791       1 allocate.go:64] Try to allocate resource to 0 Queues
I0714 05:40:23.489024       1 session.go:244] Close Session 9a4a3e9a-c867-4479-b78c-7df78dcce609
I0714 05:40:24.492143       1 cache.go:1363] There are <0> Jobs, <1> Queues and <5> Nodes in total for scheduling.
I0714 05:40:24.492368       1 session.go:190] Open Session 579e7520-b83a-4ac8-abe4-53747b3928c6 with <0> Job and <1> Queues
I0714 05:40:24.494208       1 enqueue.go:79] Try to enqueue PodGroup to 0 Queues
I0714 05:40:24.494277       1 allocate.go:64] Try to allocate resource to 0 Queues
I0714 05:40:24.494489       1 session.go:244] Close Session 579e7520-b83a-4ac8-abe4-53747b3928c6
I0714 05:40:25.497324       1 cache.go:1363] There are <0> Jobs, <1> Queues and <5> Nodes in total for scheduling.
I0714 05:40:25.497504       1 session.go:190] Open Session 69abd58f-6a94-4c99-8822-a99c26d50965 with <0> Job and <1> Queues
I0714 05:40:25.499225       1 enqueue.go:79] Try to enqueue PodGroup to 0 Queues
I0714 05:40:25.499295       1 allocate.go:64] Try to allocate resource to 0 Queues
I0714 05:40:25.499533       1 session.go:244] Close Session 69abd58f-6a94-4c99-8822-a99c26d50965
I0714 05:40:26.502229       1 cache.go:1363] There are <0> Jobs, <1> Queues and <5> Nodes in total for scheduling.
I0714 05:40:26.502394       1 session.go:190] Open Session aab1d8e0-01e1-43dd-9098-aab03c87e839 with <0> Job and <1> Queues
I0714 05:40:26.504120       1 enqueue.go:79] Try to enqueue PodGroup to 0 Queues
I0714 05:40:26.504192       1 allocate.go:64] Try to allocate resource to 0 Queues
I0714 05:40:26.504448       1 session.go:244] Close Session aab1d8e0-01e1-43dd-9098-aab03c87e839
I0714 05:40:27.506789       1 cache.go:1363] There are <0> Jobs, <1> Queues and <5> Nodes in total for scheduling.
I0714 05:40:27.506968       1 session.go:190] Open Session ea6d4d9b-ca75-427b-bb82-31254726a913 with <0> Job and <1> Queues
I0714 05:40:27.508917       1 enqueue.go:79] Try to enqueue PodGroup to 0 Queues
I0714 05:40:27.508986       1 allocate.go:64] Try to allocate resource to 0 Queues
I0714 05:40:27.509209       1 session.go:244] Close Session ea6d4d9b-ca75-427b-bb82-31254726a913
I0714 05:40:28.511193       1 cache.go:1363] There are <0> Jobs, <1> Queues and <5> Nodes in total for scheduling.
I0714 05:40:28.511353       1 session.go:190] Open Session 7021141d-1934-42c9-8507-810dcf6c4254 with <0> Job and <1> Queues
I0714 05:40:28.513135       1 enqueue.go:79] Try to enqueue PodGroup to 0 Queues
I0714 05:40:28.513204       1 allocate.go:64] Try to allocate resource to 0 Queues
I0714 05:40:28.513452       1 session.go:244] Close Session 7021141d-1934-42c9-8507-810dcf6c4254
I0714 05:40:29.515744       1 cache.go:1363] There are <0> Jobs, <1> Queues and <5> Nodes in total for scheduling.
I0714 05:40:29.515919       1 session.go:190] Open Session cf5cbe58-bee6-4a95-b14a-386eaf60c92e with <0> Job and <1> Queues
I0714 05:40:29.517774       1 enqueue.go:79] Try to enqueue PodGroup to 0 Queues
I0714 05:40:29.517846       1 allocate.go:64] Try to allocate resource to 0 Queues
I0714 05:40:29.518071       1 session.go:244] Close Session cf5cbe58-bee6-4a95-b14a-386eaf60c92e
I0714 05:40:30.520208       1 cache.go:1363] There are <0> Jobs, <1> Queues and <5> Nodes in total for scheduling.
I0714 05:40:30.520412       1 session.go:190] Open Session 498935ad-2225-4d8c-9c6c-5a899e845723 with <0> Job and <1> Queues
I0714 05:40:30.522273       1 enqueue.go:79] Try to enqueue PodGroup to 0 Queues
I0714 05:40:30.522340       1 allocate.go:64] Try to allocate resource to 0 Queues
I0714 05:40:30.522549       1 session.go:244] Close Session 498935ad-2225-4d8c-9c6c-5a899e845723
I0714 05:40:31.525316       1 cache.go:1363] There are <0> Jobs, <1> Queues and <5> Nodes in total for scheduling.
I0714 05:40:31.525483       1 session.go:190] Open Session 80cadb9d-0f44-413a-a250-d3a07d17d114 with <0> Job and <1> Queues
I0714 05:40:31.527147       1 enqueue.go:79] Try to enqueue PodGroup to 0 Queues
I0714 05:40:31.527211       1 allocate.go:64] Try to allocate resource to 0 Queues
I0714 05:40:31.527421       1 session.go:244] Close Session 80cadb9d-0f44-413a-a250-d3a07d17d114
I0714 05:40:32.529912       1 cache.go:1363] There are <0> Jobs, <1> Queues and <5> Nodes in total for scheduling.
I0714 05:40:32.530093       1 session.go:190] Open Session 28ccfd10-9458-4b1b-b4a3-4a672d671ee0 with <0> Job and <1> Queues
I0714 05:40:32.531849       1 enqueue.go:79] Try to enqueue PodGroup to 0 Queues
I0714 05:40:32.531917       1 allocate.go:64] Try to allocate resource to 0 Queues
I0714 05:40:32.532129       1 session.go:244] Close Session 28ccfd10-9458-4b1b-b4a3-4a672d671ee0
I0714 05:40:33.534583       1 cache.go:1363] There are <0> Jobs, <1> Queues and <5> Nodes in total for scheduling.
I0714 05:40:33.534775       1 session.go:190] Open Session f191f464-1abf-4beb-8f55-fa83919276d5 with <0> Job and <1> Queues
I0714 05:40:33.536613       1 enqueue.go:79] Try to enqueue PodGroup to 0 Queues
I0714 05:40:33.536680       1 allocate.go:64] Try to allocate resource to 0 Queues
I0714 05:40:33.536912       1 session.go:244] Close Session f191f464-1abf-4beb-8f55-fa83919276d5
I0714 05:40:34.539572       1 cache.go:1363] There are <0> Jobs, <1> Queues and <5> Nodes in total for scheduling.
I0714 05:40:34.539745       1 session.go:190] Open Session 2ba097b3-a1d6-4811-8e2e-718197947994 with <0> Job and <1> Queues
I0714 05:40:34.541648       1 enqueue.go:79] Try to enqueue PodGroup to 0 Queues
I0714 05:40:34.541714       1 allocate.go:64] Try to allocate resource to 0 Queues
I0714 05:40:34.541939       1 session.go:244] Close Session 2ba097b3-a1d6-4811-8e2e-718197947994
I0714 05:40:35.545006       1 cache.go:1363] There are <0> Jobs, <1> Queues and <5> Nodes in total for scheduling.
I0714 05:40:35.545199       1 session.go:190] Open Session e6ab7e69-e02a-48cf-949c-aea48d5f1377 with <0> Job and <1> Queues
I0714 05:40:35.546976       1 enqueue.go:79] Try to enqueue PodGroup to 0 Queues
I0714 05:40:35.547043       1 allocate.go:64] Try to allocate resource to 0 Queues
I0714 05:40:35.547290       1 session.go:244] Close Session e6ab7e69-e02a-48cf-949c-aea48d5f1377
I0714 05:40:36.289472       1 cache.go:1489] The metrics type is not set in the volcano scheduler configmap file. As a result, the CPU and memory load information of the node is not collected.
I0714 05:40:36.549492       1 cache.go:1363] There are <0> Jobs, <1> Queues and <5> Nodes in total for scheduling.
I0714 05:40:36.549629       1 session.go:190] Open Session 90f1eecf-c49a-4843-b1f0-88fca67ccb22 with <0> Job and <1> Queues
I0714 05:40:36.551431       1 enqueue.go:79] Try to enqueue PodGroup to 0 Queues
I0714 05:40:36.551500       1 allocate.go:64] Try to allocate resource to 0 Queues
I0714 05:40:36.551732       1 session.go:244] Close Session 90f1eecf-c49a-4843-b1f0-88fca67ccb22
I0714 05:40:37.554059       1 cache.go:1363] There are <0> Jobs, <1> Queues and <5> Nodes in total for scheduling.
I0714 05:40:37.554226       1 session.go:190] Open Session 8d04983a-559f-4364-a571-ab260e4b1179 with <0> Job and <1> Queues
I0714 05:40:37.556019       1 enqueue.go:79] Try to enqueue PodGroup to 0 Queues
I0714 05:40:37.556091       1 allocate.go:64] Try to allocate resource to 0 Queues
I0714 05:40:37.556354       1 session.go:244] Close Session 8d04983a-559f-4364-a571-ab260e4b1179
I0714 05:40:38.558828       1 cache.go:1363] There are <0> Jobs, <1> Queues and <5> Nodes in total for scheduling.
I0714 05:40:38.558991       1 session.go:190] Open Session faf19e7f-a2a5-4a5e-bc7d-54a4d1f72f08 with <0> Job and <1> Queues
I0714 05:40:38.560747       1 enqueue.go:79] Try to enqueue PodGroup to 0 Queues
I0714 05:40:38.560821       1 allocate.go:64] Try to allocate resource to 0 Queues
I0714 05:40:38.561044       1 session.go:244] Close Session faf19e7f-a2a5-4a5e-bc7d-54a4d1f72f08
I0714 05:40:39.563336       1 cache.go:1363] There are <0> Jobs, <1> Queues and <5> Nodes in total for scheduling.
I0714 05:40:39.563514       1 session.go:190] Open Session 90630207-3f14-41f2-ba95-3fe53b8ef47c with <0> Job and <1> Queues
I0714 05:40:39.565390       1 enqueue.go:79] Try to enqueue PodGroup to 0 Queues
I0714 05:40:39.565461       1 allocate.go:64] Try to allocate resource to 0 Queues
I0714 05:40:39.565685       1 session.go:244] Close Session 90630207-3f14-41f2-ba95-3fe53b8ef47c
I0714 05:40:40.568133       1 cache.go:1363] There are <0> Jobs, <1> Queues and <5> Nodes in total for scheduling.
I0714 05:40:40.568325       1 session.go:190] Open Session 42da6a0b-9f14-4c0d-bc88-79c04069ff0b with <0> Job and <1> Queues
I0714 05:40:40.570132       1 enqueue.go:79] Try to enqueue PodGroup to 0 Queues
I0714 05:40:40.570205       1 allocate.go:64] Try to allocate resource to 0 Queues
I0714 05:40:40.570430       1 session.go:244] Close Session 42da6a0b-9f14-4c0d-bc88-79c04069ff0b
I0714 05:40:41.573099       1 cache.go:1363] There are <0> Jobs, <1> Queues and <5> Nodes in total for scheduling.
I0714 05:40:41.573256       1 session.go:190] Open Session 86ec9a85-1ef0-4fe5-b42e-4ecfac53ac22 with <0> Job and <1> Queues
I0714 05:40:41.574957       1 enqueue.go:79] Try to enqueue PodGroup to 0 Queues
I0714 05:40:41.575022       1 allocate.go:64] Try to allocate resource to 0 Queues
I0714 05:40:41.575220       1 session.go:244] Close Session 86ec9a85-1ef0-4fe5-b42e-4ecfac53ac22
I0714 05:40:42.577728       1 cache.go:1363] There are <0> Jobs, <1> Queues and <5> Nodes in total for scheduling.
I0714 05:40:42.577926       1 session.go:190] Open Session 46e1cb90-bb61-4417-897a-2529070fbba0 with <0> Job and <1> Queues
I0714 05:40:42.579786       1 enqueue.go:79] Try to enqueue PodGroup to 0 Queues
I0714 05:40:42.579851       1 allocate.go:64] Try to allocate resource to 0 Queues
I0714 05:40:42.580076       1 session.go:244] Close Session 46e1cb90-bb61-4417-897a-2529070fbba0
I0714 05:40:43.582285       1 cache.go:1363] There are <0> Jobs, <1> Queues and <5> Nodes in total for scheduling.
I0714 05:40:43.582458       1 session.go:190] Open Session c745a808-9363-49f8-9867-032e3d46c4f4 with <0> Job and <1> Queues
I0714 05:40:43.584214       1 enqueue.go:79] Try to enqueue PodGroup to 0 Queues
I0714 05:40:43.584275       1 allocate.go:64] Try to allocate resource to 0 Queues
I0714 05:40:43.584533       1 session.go:244] Close Session c745a808-9363-49f8-9867-032e3d46c4f4
I0714 05:40:44.587351       1 cache.go:1363] There are <0> Jobs, <1> Queues and <5> Nodes in total for scheduling.
I0714 05:40:44.587533       1 session.go:190] Open Session 4e1d56ad-8974-4ccc-aee6-a44221f2eb8e with <0> Job and <1> Queues
I0714 05:40:44.589343       1 enqueue.go:79] Try to enqueue PodGroup to 0 Queues
I0714 05:40:44.589409       1 allocate.go:64] Try to allocate resource to 0 Queues
I0714 05:40:44.589622       1 session.go:244] Close Session 4e1d56ad-8974-4ccc-aee6-a44221f2eb8e
I0714 05:40:45.592761       1 cache.go:1363] There are <0> Jobs, <1> Queues and <5> Nodes in total for scheduling.
I0714 05:40:45.592919       1 session.go:190] Open Session b2d409f5-012c-4b00-b1ae-00d6fc229eae with <0> Job and <1> Queues
I0714 05:40:45.594678       1 enqueue.go:79] Try to enqueue PodGroup to 0 Queues
I0714 05:40:45.594743       1 allocate.go:64] Try to allocate resource to 0 Queues
I0714 05:40:45.594984       1 session.go:244] Close Session b2d409f5-012c-4b00-b1ae-00d6fc229eae
I0714 05:40:46.597171       1 cache.go:1363] There are <0> Jobs, <1> Queues and <5> Nodes in total for scheduling.
I0714 05:40:46.597339       1 session.go:190] Open Session 9925b595-c1da-43ce-97bb-48e9cb2dce97 with <0> Job and <1> Queues
I0714 05:40:46.599043       1 enqueue.go:79] Try to enqueue PodGroup to 0 Queues
I0714 05:40:46.599105       1 allocate.go:64] Try to allocate resource to 0 Queues
I0714 05:40:46.599330       1 session.go:244] Close Session 9925b595-c1da-43ce-97bb-48e9cb2dce97
I0714 05:40:47.602173       1 cache.go:1363] There are <0> Jobs, <1> Queues and <5> Nodes in total for scheduling.
I0714 05:40:47.602340       1 session.go:190] Open Session 65478a4a-6607-4c16-bd6c-ab21e58335a5 with <0> Job and <1> Queues
I0714 05:40:47.604040       1 enqueue.go:79] Try to enqueue PodGroup to 0 Queues
I0714 05:40:47.604102       1 allocate.go:64] Try to allocate resource to 0 Queues
I0714 05:40:47.604393       1 session.go:244] Close Session 65478a4a-6607-4c16-bd6c-ab21e58335a5
I0714 05:40:48.607209       1 cache.go:1363] There are <0> Jobs, <1> Queues and <5> Nodes in total for scheduling.
I0714 05:40:48.607380       1 session.go:190] Open Session 176277f3-d8ea-4659-b505-dcd2ec77cd47 with <0> Job and <1> Queues
I0714 05:40:48.609171       1 enqueue.go:79] Try to enqueue PodGroup to 0 Queues
I0714 05:40:48.609235       1 allocate.go:64] Try to allocate resource to 0 Queues
I0714 05:40:48.609445       1 session.go:244] Close Session 176277f3-d8ea-4659-b505-dcd2ec77cd47
I0714 05:40:49.611899       1 cache.go:1363] There are <0> Jobs, <1> Queues and <5> Nodes in total for scheduling.
I0714 05:40:49.612085       1 session.go:190] Open Session 733326c3-2f02-47a0-8009-6ad39011c9a9 with <0> Job and <1> Queues
I0714 05:40:49.613913       1 enqueue.go:79] Try to enqueue PodGroup to 0 Queues
I0714 05:40:49.613996       1 allocate.go:64] Try to allocate resource to 0 Queues
I0714 05:40:49.614228       1 session.go:244] Close Session 733326c3-2f02-47a0-8009-6ad39011c9a9
I0714 05:40:50.616664       1 cache.go:1363] There are <0> Jobs, <1> Queues and <5> Nodes in total for scheduling.
I0714 05:40:50.616797       1 session.go:190] Open Session bb114e1e-6658-43d7-8411-33727d132e06 with <0> Job and <1> Queues
I0714 05:40:50.618359       1 enqueue.go:79] Try to enqueue PodGroup to 0 Queues
I0714 05:40:50.618426       1 allocate.go:64] Try to allocate resource to 0 Queues
I0714 05:40:50.618624       1 session.go:244] Close Session bb114e1e-6658-43d7-8411-33727d132e06
I0714 05:40:51.621091       1 cache.go:1363] There are <0> Jobs, <1> Queues and <5> Nodes in total for scheduling.
I0714 05:40:51.621255       1 session.go:190] Open Session 65bb622d-2b1c-4bae-8837-b08e1e339259 with <0> Job and <1> Queues
I0714 05:40:51.623020       1 enqueue.go:79] Try to enqueue PodGroup to 0 Queues
I0714 05:40:51.623084       1 allocate.go:64] Try to allocate resource to 0 Queues
I0714 05:40:51.623286       1 session.go:244] Close Session 65bb622d-2b1c-4bae-8837-b08e1e339259
I0714 05:40:52.625660       1 cache.go:1363] There are <0> Jobs, <1> Queues and <5> Nodes in total for scheduling.
I0714 05:40:52.625852       1 session.go:190] Open Session 9fef4120-3c18-4d42-918c-3f0e62f0b9cc with <0> Job and <1> Queues
I0714 05:40:52.627594       1 enqueue.go:79] Try to enqueue PodGroup to 0 Queues
I0714 05:40:52.627666       1 allocate.go:64] Try to allocate resource to 0 Queues
I0714 05:40:52.627902       1 session.go:244] Close Session 9fef4120-3c18-4d42-918c-3f0e62f0b9cc
I0714 05:40:53.630466       1 cache.go:1363] There are <0> Jobs, <1> Queues and <5> Nodes in total for scheduling.
I0714 05:40:53.630677       1 session.go:190] Open Session a3c7d604-f605-44e8-b577-7c5df11ee810 with <0> Job and <1> Queues
I0714 05:40:53.632588       1 enqueue.go:79] Try to enqueue PodGroup to 0 Queues
I0714 05:40:53.632661       1 allocate.go:64] Try to allocate resource to 0 Queues
I0714 05:40:53.632886       1 session.go:244] Close Session a3c7d604-f605-44e8-b577-7c5df11ee810
I0714 05:40:54.635370       1 cache.go:1363] There are <0> Jobs, <1> Queues and <5> Nodes in total for scheduling.
I0714 05:40:54.635547       1 session.go:190] Open Session 93563a57-3f19-41d1-a118-a1c514683ac3 with <0> Job and <1> Queues
I0714 05:40:54.637488       1 enqueue.go:79] Try to enqueue PodGroup to 0 Queues
I0714 05:40:54.637557       1 allocate.go:64] Try to allocate resource to 0 Queues
I0714 05:40:54.637787       1 session.go:244] Close Session 93563a57-3f19-41d1-a118-a1c514683ac3
I0714 05:40:55.639925       1 cache.go:1363] There are <0> Jobs, <1> Queues and <5> Nodes in total for scheduling.
I0714 05:40:55.640095       1 session.go:190] Open Session 9055eb0c-a4ae-4134-a11e-3ab98c0e450f with <0> Job and <1> Queues
I0714 05:40:55.641852       1 enqueue.go:79] Try to enqueue PodGroup to 0 Queues
I0714 05:40:55.641925       1 allocate.go:64] Try to allocate resource to 0 Queues
I0714 05:40:55.642142       1 session.go:244] Close Session 9055eb0c-a4ae-4134-a11e-3ab98c0e450f
I0714 05:40:56.645032       1 cache.go:1363] There are <0> Jobs, <1> Queues and <5> Nodes in total for scheduling.
I0714 05:40:56.645195       1 session.go:190] Open Session 5266e0a8-0b25-4cc3-a61f-df4f1590e137 with <0> Job and <1> Queues
I0714 05:40:56.646964       1 enqueue.go:79] Try to enqueue PodGroup to 0 Queues
I0714 05:40:56.647040       1 allocate.go:64] Try to allocate resource to 0 Queues
I0714 05:40:56.647267       1 session.go:244] Close Session 5266e0a8-0b25-4cc3-a61f-df4f1590e137
I0714 05:40:57.649566       1 cache.go:1363] There are <0> Jobs, <1> Queues and <5> Nodes in total for scheduling.
I0714 05:40:57.649751       1 session.go:190] Open Session e297a53b-510b-4ef4-ab4f-2b0698047de5 with <0> Job and <1> Queues
I0714 05:40:57.651472       1 enqueue.go:79] Try to enqueue PodGroup to 0 Queues
I0714 05:40:57.651537       1 allocate.go:64] Try to allocate resource to 0 Queues
I0714 05:40:57.651746       1 session.go:244] Close Session e297a53b-510b-4ef4-ab4f-2b0698047de5
I0714 05:40:58.654377       1 cache.go:1363] There are <0> Jobs, <1> Queues and <5> Nodes in total for scheduling.
I0714 05:40:58.654545       1 session.go:190] Open Session bbe8f161-2192-4341-b23a-93f22e7d90fb with <0> Job and <1> Queues
I0714 05:40:58.656214       1 enqueue.go:79] Try to enqueue PodGroup to 0 Queues
I0714 05:40:58.656309       1 allocate.go:64] Try to allocate resource to 0 Queues
I0714 05:40:58.656559       1 session.go:244] Close Session bbe8f161-2192-4341-b23a-93f22e7d90fb
I0714 05:40:59.659520       1 cache.go:1363] There are <0> Jobs, <1> Queues and <5> Nodes in total for scheduling.
I0714 05:40:59.659698       1 session.go:190] Open Session 919a4150-41fa-4a5f-a846-76fa0caab9be with <0> Job and <1> Queues
I0714 05:40:59.661597       1 enqueue.go:79] Try to enqueue PodGroup to 0 Queues
I0714 05:40:59.661678       1 allocate.go:64] Try to allocate resource to 0 Queues
I0714 05:40:59.661898       1 session.go:244] Close Session 919a4150-41fa-4a5f-a846-76fa0caab9be
I0714 05:41:00.664582       1 cache.go:1363] There are <0> Jobs, <1> Queues and <5> Nodes in total for scheduling.
I0714 05:41:00.664760       1 session.go:190] Open Session e453faa2-e0f2-4a1b-9ff7-4d2541afd204 with <0> Job and <1> Queues
I0714 05:41:00.666676       1 enqueue.go:79] Try to enqueue PodGroup to 0 Queues
I0714 05:41:00.666758       1 allocate.go:64] Try to allocate resource to 0 Queues
I0714 05:41:00.666978       1 session.go:244] Close Session e453faa2-e0f2-4a1b-9ff7-4d2541afd204
I0714 05:41:01.669542       1 cache.go:1363] There are <0> Jobs, <1> Queues and <5> Nodes in total for scheduling.
I0714 05:41:01.669696       1 session.go:190] Open Session df54f2a8-d053-4af7-a676-ba8d86b59e9c with <0> Job and <1> Queues
I0714 05:41:01.671374       1 enqueue.go:79] Try to enqueue PodGroup to 0 Queues
I0714 05:41:01.671445       1 allocate.go:64] Try to allocate resource to 0 Queues
I0714 05:41:01.671663       1 session.go:244] Close Session df54f2a8-d053-4af7-a676-ba8d86b59e9c
I0714 05:41:02.674627       1 cache.go:1363] There are <0> Jobs, <1> Queues and <5> Nodes in total for scheduling.
I0714 05:41:02.674781       1 session.go:190] Open Session c2099d84-cbef-4051-b569-3bddf7cbf1e7 with <0> Job and <1> Queues
I0714 05:41:02.676497       1 enqueue.go:79] Try to enqueue PodGroup to 0 Queues
I0714 05:41:02.676568       1 allocate.go:64] Try to allocate resource to 0 Queues
I0714 05:41:02.676764       1 session.go:244] Close Session c2099d84-cbef-4051-b569-3bddf7cbf1e7
I0714 05:41:03.679421       1 cache.go:1363] There are <0> Jobs, <1> Queues and <5> Nodes in total for scheduling.
I0714 05:41:03.679601       1 session.go:190] Open Session d16d04dd-aac9-4970-a84a-a34d5486d8e7 with <0> Job and <1> Queues
I0714 05:41:03.681414       1 enqueue.go:79] Try to enqueue PodGroup to 0 Queues
I0714 05:41:03.681490       1 allocate.go:64] Try to allocate resource to 0 Queues
I0714 05:41:03.681711       1 session.go:244] Close Session d16d04dd-aac9-4970-a84a-a34d5486d8e7
I0714 05:41:04.684101       1 cache.go:1363] There are <0> Jobs, <1> Queues and <5> Nodes in total for scheduling.
I0714 05:41:04.684344       1 session.go:190] Open Session 9f9ca439-4ca6-48ec-93e8-36a97fc2d664 with <0> Job and <1> Queues
I0714 05:41:04.686165       1 enqueue.go:79] Try to enqueue PodGroup to 0 Queues
I0714 05:41:04.686233       1 allocate.go:64] Try to allocate resource to 0 Queues
I0714 05:41:04.686455       1 session.go:244] Close Session 9f9ca439-4ca6-48ec-93e8-36a97fc2d664
I0714 05:41:05.688443       1 cache.go:1363] There are <0> Jobs, <1> Queues and <5> Nodes in total for scheduling.
I0714 05:41:05.688612       1 session.go:190] Open Session bc098510-27e5-4fc5-918d-284e95a59f2d with <0> Job and <1> Queues
I0714 05:41:05.690494       1 enqueue.go:79] Try to enqueue PodGroup to 0 Queues
I0714 05:41:05.690560       1 allocate.go:64] Try to allocate resource to 0 Queues
I0714 05:41:05.690786       1 session.go:244] Close Session bc098510-27e5-4fc5-918d-284e95a59f2d
I0714 05:41:06.290715       1 cache.go:1489] The metrics type is not set in the volcano scheduler configmap file. As a result, the CPU and memory load information of the node is not collected.
I0714 05:41:06.693032       1 cache.go:1363] There are <0> Jobs, <1> Queues and <5> Nodes in total for scheduling.
I0714 05:41:06.693165       1 session.go:190] Open Session fffaf1b5-1d54-4594-b4ca-cb7083bee6e2 with <0> Job and <1> Queues
I0714 05:41:06.694906       1 enqueue.go:79] Try to enqueue PodGroup to 0 Queues
I0714 05:41:06.694971       1 allocate.go:64] Try to allocate resource to 0 Queues
I0714 05:41:06.695196       1 session.go:244] Close Session fffaf1b5-1d54-4594-b4ca-cb7083bee6e2
I0714 05:41:07.699019       1 cache.go:1363] There are <0> Jobs, <1> Queues and <5> Nodes in total for scheduling.
I0714 05:41:07.699263       1 session.go:190] Open Session ea9f74f9-bec3-4253-94b0-9744cd401924 with <0> Job and <1> Queues
I0714 05:41:07.701224       1 enqueue.go:79] Try to enqueue PodGroup to 0 Queues
I0714 05:41:07.701333       1 allocate.go:64] Try to allocate resource to 0 Queues
I0714 05:41:07.701564       1 session.go:244] Close Session ea9f74f9-bec3-4253-94b0-9744cd401924
I0714 05:41:08.704113       1 cache.go:1363] There are <0> Jobs, <1> Queues and <5> Nodes in total for scheduling.
I0714 05:41:08.704329       1 session.go:190] Open Session 3d6a0460-a45e-4832-a944-ea2573ca0571 with <0> Job and <1> Queues
I0714 05:41:08.706105       1 enqueue.go:79] Try to enqueue PodGroup to 0 Queues
I0714 05:41:08.706171       1 allocate.go:64] Try to allocate resource to 0 Queues
I0714 05:41:08.706396       1 session.go:244] Close Session 3d6a0460-a45e-4832-a944-ea2573ca0571
I0714 05:41:09.708995       1 cache.go:1363] There are <0> Jobs, <1> Queues and <5> Nodes in total for scheduling.
I0714 05:41:09.709169       1 session.go:190] Open Session 17dd40ff-2350-4523-bf2c-b362082ac5f7 with <0> Job and <1> Queues
I0714 05:41:09.710901       1 enqueue.go:79] Try to enqueue PodGroup to 0 Queues
I0714 05:41:09.710972       1 allocate.go:64] Try to allocate resource to 0 Queues
I0714 05:41:09.711203       1 session.go:244] Close Session 17dd40ff-2350-4523-bf2c-b362082ac5f7
I0714 05:41:10.713993       1 cache.go:1363] There are <0> Jobs, <1> Queues and <5> Nodes in total for scheduling.
I0714 05:41:10.714173       1 session.go:190] Open Session 6a3df410-0666-4881-b5af-34a890eabac3 with <0> Job and <1> Queues
I0714 05:41:10.716004       1 enqueue.go:79] Try to enqueue PodGroup to 0 Queues
I0714 05:41:10.716076       1 allocate.go:64] Try to allocate resource to 0 Queues
I0714 05:41:10.716323       1 session.go:244] Close Session 6a3df410-0666-4881-b5af-34a890eabac3
I0714 05:41:11.719068       1 cache.go:1363] There are <0> Jobs, <1> Queues and <5> Nodes in total for scheduling.
I0714 05:41:11.719237       1 session.go:190] Open Session f0dafa38-73be-4850-b638-052e05b4bb58 with <0> Job and <1> Queues
I0714 05:41:11.721035       1 enqueue.go:79] Try to enqueue PodGroup to 0 Queues
I0714 05:41:11.721103       1 allocate.go:64] Try to allocate resource to 0 Queues
I0714 05:41:11.721313       1 session.go:244] Close Session f0dafa38-73be-4850-b638-052e05b4bb58
I0714 05:41:12.723768       1 cache.go:1363] There are <0> Jobs, <1> Queues and <5> Nodes in total for scheduling.
I0714 05:41:12.723940       1 session.go:190] Open Session a7d85f66-97e9-4914-b0cd-c691ea273070 with <0> Job and <1> Queues
I0714 05:41:12.725788       1 enqueue.go:79] Try to enqueue PodGroup to 0 Queues
I0714 05:41:12.725855       1 allocate.go:64] Try to allocate resource to 0 Queues
I0714 05:41:12.726082       1 session.go:244] Close Session a7d85f66-97e9-4914-b0cd-c691ea273070
I0714 05:41:13.728661       1 cache.go:1363] There are <0> Jobs, <1> Queues and <5> Nodes in total for scheduling.
I0714 05:41:13.728830       1 session.go:190] Open Session 2d0a4eda-2ec6-47b6-84bb-156163bcefc9 with <0> Job and <1> Queues
I0714 05:41:13.730485       1 enqueue.go:79] Try to enqueue PodGroup to 0 Queues
I0714 05:41:13.730552       1 allocate.go:64] Try to allocate resource to 0 Queues
I0714 05:41:13.730770       1 session.go:244] Close Session 2d0a4eda-2ec6-47b6-84bb-156163bcefc9
I0714 05:41:14.733931       1 cache.go:1363] There are <0> Jobs, <1> Queues and <5> Nodes in total for scheduling.
I0714 05:41:14.734120       1 session.go:190] Open Session 90efb2c7-4ad0-47d2-aa39-cdb1d49fe7ef with <0> Job and <1> Queues
I0714 05:41:14.735916       1 enqueue.go:79] Try to enqueue PodGroup to 0 Queues
I0714 05:41:14.735987       1 allocate.go:64] Try to allocate resource to 0 Queues
I0714 05:41:14.736212       1 session.go:244] Close Session 90efb2c7-4ad0-47d2-aa39-cdb1d49fe7ef
I0714 05:41:15.738438       1 cache.go:1363] There are <0> Jobs, <1> Queues and <5> Nodes in total for scheduling.
I0714 05:41:15.738595       1 session.go:190] Open Session d3db5e82-ee2e-46cd-ade7-a954b02e3410 with <0> Job and <1> Queues
I0714 05:41:15.740240       1 enqueue.go:79] Try to enqueue PodGroup to 0 Queues
I0714 05:41:15.740341       1 allocate.go:64] Try to allocate resource to 0 Queues
I0714 05:41:15.740544       1 session.go:244] Close Session d3db5e82-ee2e-46cd-ade7-a954b02e3410
I0714 05:41:16.743453       1 cache.go:1363] There are <0> Jobs, <1> Queues and <5> Nodes in total for scheduling.
I0714 05:41:16.743617       1 session.go:190] Open Session d05422cc-c5d9-4e73-aa6d-39525044bfbc with <0> Job and <1> Queues
I0714 05:41:16.745424       1 enqueue.go:79] Try to enqueue PodGroup to 0 Queues
I0714 05:41:16.745496       1 allocate.go:64] Try to allocate resource to 0 Queues
I0714 05:41:16.745727       1 session.go:244] Close Session d05422cc-c5d9-4e73-aa6d-39525044bfbc
I0714 05:41:17.748231       1 cache.go:1363] There are <0> Jobs, <1> Queues and <5> Nodes in total for scheduling.
I0714 05:41:17.748435       1 session.go:190] Open Session 37f4a123-2cc5-46d6-b495-8676c397a180 with <0> Job and <1> Queues
I0714 05:41:17.750269       1 enqueue.go:79] Try to enqueue PodGroup to 0 Queues
I0714 05:41:17.750334       1 allocate.go:64] Try to allocate resource to 0 Queues
I0714 05:41:17.750560       1 session.go:244] Close Session 37f4a123-2cc5-46d6-b495-8676c397a180
I0714 05:41:18.753377       1 cache.go:1363] There are <0> Jobs, <1> Queues and <5> Nodes in total for scheduling.
I0714 05:41:18.753536       1 session.go:190] Open Session 424efd04-293e-4017-bd2e-26d76ed181b4 with <0> Job and <1> Queues
I0714 05:41:18.755288       1 enqueue.go:79] Try to enqueue PodGroup to 0 Queues
I0714 05:41:18.755350       1 allocate.go:64] Try to allocate resource to 0 Queues
I0714 05:41:18.755560       1 session.go:244] Close Session 424efd04-293e-4017-bd2e-26d76ed181b4
I0714 05:41:19.757978       1 cache.go:1363] There are <0> Jobs, <1> Queues and <5> Nodes in total for scheduling.
I0714 05:41:19.758182       1 session.go:190] Open Session a5c7a60a-076c-420a-a4ee-a0f13f998f6a with <0> Job and <1> Queues
I0714 05:41:19.760039       1 enqueue.go:79] Try to enqueue PodGroup to 0 Queues
I0714 05:41:19.760109       1 allocate.go:64] Try to allocate resource to 0 Queues
I0714 05:41:19.760342       1 session.go:244] Close Session a5c7a60a-076c-420a-a4ee-a0f13f998f6a
I0714 05:41:20.763407       1 cache.go:1363] There are <0> Jobs, <1> Queues and <5> Nodes in total for scheduling.
I0714 05:41:20.763575       1 session.go:190] Open Session 659d8b5b-7a11-4923-b634-a2bbd52a46c0 with <0> Job and <1> Queues
I0714 05:41:20.766715       1 enqueue.go:79] Try to enqueue PodGroup to 0 Queues
I0714 05:41:20.766825       1 allocate.go:64] Try to allocate resource to 0 Queues
I0714 05:41:20.767102       1 session.go:244] Close Session 659d8b5b-7a11-4923-b634-a2bbd52a46c0
I0714 05:41:21.770260       1 cache.go:1363] There are <0> Jobs, <1> Queues and <5> Nodes in total for scheduling.
I0714 05:41:21.770432       1 session.go:190] Open Session 1a924741-faf4-410a-96ec-5c58836a390b with <0> Job and <1> Queues
I0714 05:41:21.772219       1 enqueue.go:79] Try to enqueue PodGroup to 0 Queues
I0714 05:41:21.772313       1 allocate.go:64] Try to allocate resource to 0 Queues
I0714 05:41:21.772543       1 session.go:244] Close Session 1a924741-faf4-410a-96ec-5c58836a390b
I0714 05:41:22.774750       1 cache.go:1363] There are <0> Jobs, <1> Queues and <5> Nodes in total for scheduling.
I0714 05:41:22.774922       1 session.go:190] Open Session ddceac71-de13-4aeb-aba6-0189b28d2181 with <0> Job and <1> Queues
I0714 05:41:22.776918       1 enqueue.go:79] Try to enqueue PodGroup to 0 Queues
I0714 05:41:22.776988       1 allocate.go:64] Try to allocate resource to 0 Queues
I0714 05:41:22.777223       1 session.go:244] Close Session ddceac71-de13-4aeb-aba6-0189b28d2181
I0714 05:41:23.779126       1 cache.go:1363] There are <0> Jobs, <1> Queues and <5> Nodes in total for scheduling.
I0714 05:41:23.779288       1 session.go:190] Open Session 1d21eebf-f8d3-4ebe-ad0b-1dbe49e8294f with <0> Job and <1> Queues
I0714 05:41:23.781209       1 enqueue.go:79] Try to enqueue PodGroup to 0 Queues
I0714 05:41:23.781275       1 allocate.go:64] Try to allocate resource to 0 Queues
I0714 05:41:23.781490       1 session.go:244] Close Session 1d21eebf-f8d3-4ebe-ad0b-1dbe49e8294f
I0714 05:41:24.783766       1 cache.go:1363] There are <0> Jobs, <1> Queues and <5> Nodes in total for scheduling.
I0714 05:41:24.783946       1 session.go:190] Open Session 9336db82-0df1-47d9-a068-453a8de92398 with <0> Job and <1> Queues
I0714 05:41:24.785847       1 enqueue.go:79] Try to enqueue PodGroup to 0 Queues
I0714 05:41:24.785917       1 allocate.go:64] Try to allocate resource to 0 Queues
I0714 05:41:24.786136       1 session.go:244] Close Session 9336db82-0df1-47d9-a068-453a8de92398
I0714 05:41:25.788197       1 cache.go:1363] There are <0> Jobs, <1> Queues and <5> Nodes in total for scheduling.
I0714 05:41:25.788394       1 session.go:190] Open Session 7115fba7-3f4e-4870-b71e-1dd0d0c2ad14 with <0> Job and <1> Queues
I0714 05:41:25.790078       1 enqueue.go:79] Try to enqueue PodGroup to 0 Queues
I0714 05:41:25.790144       1 allocate.go:64] Try to allocate resource to 0 Queues
I0714 05:41:25.790364       1 session.go:244] Close Session 7115fba7-3f4e-4870-b71e-1dd0d0c2ad14
I0714 05:41:26.793247       1 cache.go:1363] There are <0> Jobs, <1> Queues and <5> Nodes in total for scheduling.
I0714 05:41:26.793408       1 session.go:190] Open Session f0ce583e-b13b-4f30-976c-417293aba440 with <0> Job and <1> Queues
I0714 05:41:26.795236       1 enqueue.go:79] Try to enqueue PodGroup to 0 Queues
I0714 05:41:26.795297       1 allocate.go:64] Try to allocate resource to 0 Queues
I0714 05:41:26.795515       1 session.go:244] Close Session f0ce583e-b13b-4f30-976c-417293aba440
I0714 05:41:27.797789       1 cache.go:1363] There are <0> Jobs, <1> Queues and <5> Nodes in total for scheduling.
I0714 05:41:27.797944       1 session.go:190] Open Session 20811136-65c2-4026-aa4c-107bbd732913 with <0> Job and <1> Queues
I0714 05:41:27.799653       1 enqueue.go:79] Try to enqueue PodGroup to 0 Queues
I0714 05:41:27.799717       1 allocate.go:64] Try to allocate resource to 0 Queues
I0714 05:41:27.799929       1 session.go:244] Close Session 20811136-65c2-4026-aa4c-107bbd732913
I0714 05:41:28.801881       1 cache.go:1363] There are <0> Jobs, <1> Queues and <5> Nodes in total for scheduling.
I0714 05:41:28.802034       1 session.go:190] Open Session 2b1f6b27-349e-45cc-bb0f-604f9fa55f36 with <0> Job and <1> Queues
I0714 05:41:28.803927       1 enqueue.go:79] Try to enqueue PodGroup to 0 Queues
I0714 05:41:28.803991       1 allocate.go:64] Try to allocate resource to 0 Queues
I0714 05:41:28.804212       1 session.go:244] Close Session 2b1f6b27-349e-45cc-bb0f-604f9fa55f36
I0714 05:41:29.806441       1 cache.go:1363] There are <0> Jobs, <1> Queues and <5> Nodes in total for scheduling.
I0714 05:41:29.806623       1 session.go:190] Open Session 752f410f-1ca4-4d9d-8d4c-1abeb4f838b4 with <0> Job and <1> Queues
I0714 05:41:29.808577       1 enqueue.go:79] Try to enqueue PodGroup to 0 Queues
I0714 05:41:29.808666       1 allocate.go:64] Try to allocate resource to 0 Queues
I0714 05:41:29.808894       1 session.go:244] Close Session 752f410f-1ca4-4d9d-8d4c-1abeb4f838b4
I0714 05:41:30.811783       1 cache.go:1363] There are <0> Jobs, <1> Queues and <5> Nodes in total for scheduling.
I0714 05:41:30.811984       1 session.go:190] Open Session a109c9d5-60f3-4afd-8534-f40700b93fb2 with <0> Job and <1> Queues
I0714 05:41:30.813843       1 enqueue.go:79] Try to enqueue PodGroup to 0 Queues
I0714 05:41:30.813912       1 allocate.go:64] Try to allocate resource to 0 Queues
I0714 05:41:30.814144       1 session.go:244] Close Session a109c9d5-60f3-4afd-8534-f40700b93fb2
I0714 05:41:31.816732       1 cache.go:1363] There are <0> Jobs, <1> Queues and <5> Nodes in total for scheduling.
I0714 05:41:31.816982       1 session.go:190] Open Session 1dade822-6d7f-4237-b4f0-006fa578af09 with <0> Job and <1> Queues
I0714 05:41:31.818685       1 enqueue.go:79] Try to enqueue PodGroup to 0 Queues
I0714 05:41:31.818753       1 allocate.go:64] Try to allocate resource to 0 Queues
I0714 05:41:31.818982       1 session.go:244] Close Session 1dade822-6d7f-4237-b4f0-006fa578af09
I0714 05:41:32.820950       1 cache.go:1363] There are <0> Jobs, <1> Queues and <5> Nodes in total for scheduling.
I0714 05:41:32.821107       1 session.go:190] Open Session 5703b7b1-c065-4d67-8886-eee1054f06e4 with <0> Job and <1> Queues
I0714 05:41:32.822698       1 enqueue.go:79] Try to enqueue PodGroup to 0 Queues
I0714 05:41:32.822765       1 allocate.go:64] Try to allocate resource to 0 Queues
I0714 05:41:32.822967       1 session.go:244] Close Session 5703b7b1-c065-4d67-8886-eee1054f06e4
I0714 05:41:33.825426       1 cache.go:1363] There are <0> Jobs, <1> Queues and <5> Nodes in total for scheduling.
I0714 05:41:33.825574       1 session.go:190] Open Session 970a5b73-2ff7-431f-aaec-2ff891b0fe32 with <0> Job and <1> Queues
I0714 05:41:33.827187       1 enqueue.go:79] Try to enqueue PodGroup to 0 Queues
I0714 05:41:33.827253       1 allocate.go:64] Try to allocate resource to 0 Queues
I0714 05:41:33.827442       1 session.go:244] Close Session 970a5b73-2ff7-431f-aaec-2ff891b0fe32
I0714 05:41:34.830372       1 cache.go:1363] There are <0> Jobs, <1> Queues and <5> Nodes in total for scheduling.
I0714 05:41:34.830580       1 session.go:190] Open Session ac17fb05-2dec-4df7-835d-621552449f02 with <0> Job and <1> Queues
I0714 05:41:34.832352       1 enqueue.go:79] Try to enqueue PodGroup to 0 Queues
I0714 05:41:34.832432       1 allocate.go:64] Try to allocate resource to 0 Queues
I0714 05:41:34.832651       1 session.go:244] Close Session ac17fb05-2dec-4df7-835d-621552449f02
I0714 05:41:35.834825       1 cache.go:1363] There are <0> Jobs, <1> Queues and <5> Nodes in total for scheduling.
I0714 05:41:35.834969       1 session.go:190] Open Session 23ce2926-f351-4707-b68a-acae41fd6d75 with <0> Job and <1> Queues
I0714 05:41:35.836675       1 enqueue.go:79] Try to enqueue PodGroup to 0 Queues
I0714 05:41:35.836743       1 allocate.go:64] Try to allocate resource to 0 Queues
I0714 05:41:35.836956       1 session.go:244] Close Session 23ce2926-f351-4707-b68a-acae41fd6d75
I0714 05:41:36.291752       1 cache.go:1489] The metrics type is not set in the volcano scheduler configmap file. As a result, the CPU and memory load information of the node is not collected.
I0714 05:41:36.839902       1 cache.go:1363] There are <0> Jobs, <1> Queues and <5> Nodes in total for scheduling.
I0714 05:41:36.840108       1 session.go:190] Open Session cd3ee96a-abfd-42f5-8e85-50f0ee5bb0cd with <0> Job and <1> Queues
I0714 05:41:36.842170       1 enqueue.go:79] Try to enqueue PodGroup to 0 Queues
I0714 05:41:36.842242       1 allocate.go:64] Try to allocate resource to 0 Queues
I0714 05:41:36.842470       1 session.go:244] Close Session cd3ee96a-abfd-42f5-8e85-50f0ee5bb0cd
I0714 05:41:37.845325       1 cache.go:1363] There are <0> Jobs, <1> Queues and <5> Nodes in total for scheduling.
I0714 05:41:37.845508       1 session.go:190] Open Session a8b9c7e4-a753-449d-9572-0f44f388bc34 with <0> Job and <1> Queues
I0714 05:41:37.847176       1 enqueue.go:79] Try to enqueue PodGroup to 0 Queues
I0714 05:41:37.847260       1 allocate.go:64] Try to allocate resource to 0 Queues
I0714 05:41:37.847492       1 session.go:244] Close Session a8b9c7e4-a753-449d-9572-0f44f388bc34
I0714 05:41:38.849876       1 cache.go:1363] There are <0> Jobs, <1> Queues and <5> Nodes in total for scheduling.
I0714 05:41:38.850054       1 session.go:190] Open Session cdc5a820-c977-403f-8d2d-15450baebabb with <0> Job and <1> Queues
I0714 05:41:38.851813       1 enqueue.go:79] Try to enqueue PodGroup to 0 Queues
I0714 05:41:38.851878       1 allocate.go:64] Try to allocate resource to 0 Queues
I0714 05:41:38.852100       1 session.go:244] Close Session cdc5a820-c977-403f-8d2d-15450baebabb
I0714 05:41:39.855089       1 cache.go:1363] There are <0> Jobs, <1> Queues and <5> Nodes in total for scheduling.
I0714 05:41:39.855281       1 session.go:190] Open Session 95f193ac-0043-4947-99bc-880ae9bede5f with <0> Job and <1> Queues
I0714 05:41:39.857168       1 enqueue.go:79] Try to enqueue PodGroup to 0 Queues
I0714 05:41:39.857246       1 allocate.go:64] Try to allocate resource to 0 Queues
I0714 05:41:39.857462       1 session.go:244] Close Session 95f193ac-0043-4947-99bc-880ae9bede5f
I0714 05:41:40.860108       1 cache.go:1363] There are <0> Jobs, <1> Queues and <5> Nodes in total for scheduling.
I0714 05:41:40.860313       1 session.go:190] Open Session da5c959a-bba9-4dc1-a755-20929be5ef23 with <0> Job and <1> Queues
I0714 05:41:40.862107       1 enqueue.go:79] Try to enqueue PodGroup to 0 Queues
I0714 05:41:40.862171       1 allocate.go:64] Try to allocate resource to 0 Queues
I0714 05:41:40.862372       1 session.go:244] Close Session da5c959a-bba9-4dc1-a755-20929be5ef23
I0714 05:41:41.864142       1 cache.go:1363] There are <0> Jobs, <1> Queues and <5> Nodes in total for scheduling.
I0714 05:41:41.864230       1 session.go:190] Open Session 8da48def-37b3-4aca-84af-099129f25497 with <0> Job and <1> Queues
I0714 05:41:41.865557       1 enqueue.go:79] Try to enqueue PodGroup to 0 Queues
I0714 05:41:41.865618       1 allocate.go:64] Try to allocate resource to 0 Queues
I0714 05:41:41.865818       1 session.go:244] Close Session 8da48def-37b3-4aca-84af-099129f25497
I0714 05:41:42.867898       1 cache.go:1363] There are <0> Jobs, <1> Queues and <5> Nodes in total for scheduling.
I0714 05:41:42.868079       1 session.go:190] Open Session c28eac7d-531b-4ee4-9f66-00a335ef2ca4 with <0> Job and <1> Queues
I0714 05:41:42.869812       1 enqueue.go:79] Try to enqueue PodGroup to 0 Queues
I0714 05:41:42.869884       1 allocate.go:64] Try to allocate resource to 0 Queues
I0714 05:41:42.870081       1 session.go:244] Close Session c28eac7d-531b-4ee4-9f66-00a335ef2ca4
I0714 05:41:43.872513       1 cache.go:1363] There are <0> Jobs, <1> Queues and <5> Nodes in total for scheduling.
I0714 05:41:43.872682       1 session.go:190] Open Session 975a9f22-6136-4cd5-a5ab-f8d410159cc0 with <0> Job and <1> Queues
I0714 05:41:43.874337       1 enqueue.go:79] Try to enqueue PodGroup to 0 Queues
I0714 05:41:43.874403       1 allocate.go:64] Try to allocate resource to 0 Queues
I0714 05:41:43.874607       1 session.go:244] Close Session 975a9f22-6136-4cd5-a5ab-f8d410159cc0
I0714 05:41:44.877041       1 cache.go:1363] There are <0> Jobs, <1> Queues and <5> Nodes in total for scheduling.
I0714 05:41:44.877213       1 session.go:190] Open Session 088c0d52-4699-4e16-9fc1-7e68c1f99360 with <0> Job and <1> Queues
I0714 05:41:44.878935       1 enqueue.go:79] Try to enqueue PodGroup to 0 Queues
I0714 05:41:44.879010       1 allocate.go:64] Try to allocate resource to 0 Queues
I0714 05:41:44.879242       1 session.go:244] Close Session 088c0d52-4699-4e16-9fc1-7e68c1f99360
I0714 05:41:45.881419       1 cache.go:1363] There are <0> Jobs, <1> Queues and <5> Nodes in total for scheduling.
I0714 05:41:45.881579       1 session.go:190] Open Session a73103c7-532f-4d85-b169-7b08ad681778 with <0> Job and <1> Queues
I0714 05:41:45.883282       1 enqueue.go:79] Try to enqueue PodGroup to 0 Queues
I0714 05:41:45.883350       1 allocate.go:64] Try to allocate resource to 0 Queues
I0714 05:41:45.883584       1 session.go:244] Close Session a73103c7-532f-4d85-b169-7b08ad681778
I0714 05:41:46.886023       1 cache.go:1363] There are <0> Jobs, <1> Queues and <5> Nodes in total for scheduling.
I0714 05:41:46.886187       1 session.go:190] Open Session d681cb2a-9730-493c-82df-bfd3cdf55362 with <0> Job and <1> Queues
I0714 05:41:46.888070       1 enqueue.go:79] Try to enqueue PodGroup to 0 Queues
I0714 05:41:46.888138       1 allocate.go:64] Try to allocate resource to 0 Queues
I0714 05:41:46.888381       1 session.go:244] Close Session d681cb2a-9730-493c-82df-bfd3cdf55362
I0714 05:41:47.891252       1 cache.go:1363] There are <0> Jobs, <1> Queues and <5> Nodes in total for scheduling.
I0714 05:41:47.891422       1 session.go:190] Open Session 01daff54-bd21-4a1e-9740-8bfce15b8cec with <0> Job and <1> Queues
I0714 05:41:47.893327       1 enqueue.go:79] Try to enqueue PodGroup to 0 Queues
I0714 05:41:47.893403       1 allocate.go:64] Try to allocate resource to 0 Queues
I0714 05:41:47.893636       1 session.go:244] Close Session 01daff54-bd21-4a1e-9740-8bfce15b8cec
I0714 05:41:48.896418       1 cache.go:1363] There are <0> Jobs, <1> Queues and <5> Nodes in total for scheduling.
I0714 05:41:48.896583       1 session.go:190] Open Session 1a379199-2e21-40b0-8ce3-5ea6e7f62a71 with <0> Job and <1> Queues
I0714 05:41:48.898294       1 enqueue.go:79] Try to enqueue PodGroup to 0 Queues
I0714 05:41:48.898364       1 allocate.go:64] Try to allocate resource to 0 Queues
I0714 05:41:48.898585       1 session.go:244] Close Session 1a379199-2e21-40b0-8ce3-5ea6e7f62a71
I0714 05:41:49.900809       1 cache.go:1363] There are <0> Jobs, <1> Queues and <5> Nodes in total for scheduling.
I0714 05:41:49.900953       1 session.go:190] Open Session 11e34e53-380e-46f6-a7d8-360cb17ae133 with <0> Job and <1> Queues
I0714 05:41:49.902666       1 enqueue.go:79] Try to enqueue PodGroup to 0 Queues
I0714 05:41:49.902738       1 allocate.go:64] Try to allocate resource to 0 Queues
I0714 05:41:49.902982       1 session.go:244] Close Session 11e34e53-380e-46f6-a7d8-360cb17ae133
I0714 05:41:50.905618       1 cache.go:1363] There are <0> Jobs, <1> Queues and <5> Nodes in total for scheduling.
I0714 05:41:50.905791       1 session.go:190] Open Session 03d39f5a-ccbe-4013-bbc4-c660af50e57d with <0> Job and <1> Queues
I0714 05:41:50.907586       1 enqueue.go:79] Try to enqueue PodGroup to 0 Queues
I0714 05:41:50.907656       1 allocate.go:64] Try to allocate resource to 0 Queues
I0714 05:41:50.907873       1 session.go:244] Close Session 03d39f5a-ccbe-4013-bbc4-c660af50e57d
I0714 05:41:51.910246       1 cache.go:1363] There are <0> Jobs, <1> Queues and <5> Nodes in total for scheduling.
I0714 05:41:51.910419       1 session.go:190] Open Session dbe669a0-4e9a-4016-a57b-ad28c66f9c1e with <0> Job and <1> Queues
I0714 05:41:51.912195       1 enqueue.go:79] Try to enqueue PodGroup to 0 Queues
I0714 05:41:51.912269       1 allocate.go:64] Try to allocate resource to 0 Queues
I0714 05:41:51.912537       1 session.go:244] Close Session dbe669a0-4e9a-4016-a57b-ad28c66f9c1e
I0714 05:41:52.914687       1 cache.go:1363] There are <0> Jobs, <1> Queues and <5> Nodes in total for scheduling.
I0714 05:41:52.914885       1 session.go:190] Open Session 0f07e573-5812-468e-b78a-1980580d3eb3 with <0> Job and <1> Queues
I0714 05:41:52.916876       1 enqueue.go:79] Try to enqueue PodGroup to 0 Queues
I0714 05:41:52.916948       1 allocate.go:64] Try to allocate resource to 0 Queues
I0714 05:41:52.917168       1 session.go:244] Close Session 0f07e573-5812-468e-b78a-1980580d3eb3
I0714 05:41:53.919163       1 cache.go:1363] There are <0> Jobs, <1> Queues and <5> Nodes in total for scheduling.
I0714 05:41:53.919343       1 session.go:190] Open Session 7303a76a-8d94-4201-9c17-11d6714bb606 with <0> Job and <1> Queues
I0714 05:41:53.921169       1 enqueue.go:79] Try to enqueue PodGroup to 0 Queues
I0714 05:41:53.921243       1 allocate.go:64] Try to allocate resource to 0 Queues
I0714 05:41:53.921458       1 session.go:244] Close Session 7303a76a-8d94-4201-9c17-11d6714bb606
I0714 05:41:54.923943       1 cache.go:1363] There are <0> Jobs, <1> Queues and <5> Nodes in total for scheduling.
I0714 05:41:54.924124       1 session.go:190] Open Session eae2788f-069e-4257-b8a3-42fd14fc62e0 with <0> Job and <1> Queues
I0714 05:41:54.926065       1 enqueue.go:79] Try to enqueue PodGroup to 0 Queues
I0714 05:41:54.926142       1 allocate.go:64] Try to allocate resource to 0 Queues
I0714 05:41:54.926361       1 session.go:244] Close Session eae2788f-069e-4257-b8a3-42fd14fc62e0
I0714 05:41:55.929342       1 cache.go:1363] There are <0> Jobs, <1> Queues and <5> Nodes in total for scheduling.
I0714 05:41:55.929508       1 session.go:190] Open Session 0b046689-2dff-45e1-bbbf-91dcbcbbba86 with <0> Job and <1> Queues
I0714 05:41:55.931485       1 enqueue.go:79] Try to enqueue PodGroup to 0 Queues
I0714 05:41:55.931557       1 allocate.go:64] Try to allocate resource to 0 Queues
I0714 05:41:55.931792       1 session.go:244] Close Session 0b046689-2dff-45e1-bbbf-91dcbcbbba86
I0714 05:41:56.934317       1 cache.go:1363] There are <0> Jobs, <1> Queues and <5> Nodes in total for scheduling.
I0714 05:41:56.934475       1 session.go:190] Open Session 486ea2ea-e2b7-481a-9946-ffac76e0cbcb with <0> Job and <1> Queues
I0714 05:41:56.936112       1 enqueue.go:79] Try to enqueue PodGroup to 0 Queues
I0714 05:41:56.936195       1 allocate.go:64] Try to allocate resource to 0 Queues
I0714 05:41:56.936471       1 session.go:244] Close Session 486ea2ea-e2b7-481a-9946-ffac76e0cbcb
I0714 05:41:57.938754       1 cache.go:1363] There are <0> Jobs, <1> Queues and <5> Nodes in total for scheduling.
I0714 05:41:57.938929       1 session.go:190] Open Session 656f4df6-c40c-4c29-a0b4-44bee9117404 with <0> Job and <1> Queues
I0714 05:41:57.940788       1 enqueue.go:79] Try to enqueue PodGroup to 0 Queues
I0714 05:41:57.940861       1 allocate.go:64] Try to allocate resource to 0 Queues
I0714 05:41:57.941084       1 session.go:244] Close Session 656f4df6-c40c-4c29-a0b4-44bee9117404
I0714 05:41:58.943623       1 cache.go:1363] There are <0> Jobs, <1> Queues and <5> Nodes in total for scheduling.
I0714 05:41:58.943798       1 session.go:190] Open Session acade271-fa64-41fc-a64d-cecd4c81f6ac with <0> Job and <1> Queues
I0714 05:41:58.945666       1 enqueue.go:79] Try to enqueue PodGroup to 0 Queues
I0714 05:41:58.945744       1 allocate.go:64] Try to allocate resource to 0 Queues
I0714 05:41:58.946101       1 session.go:244] Close Session acade271-fa64-41fc-a64d-cecd4c81f6ac
I0714 05:41:59.948509       1 cache.go:1363] There are <0> Jobs, <1> Queues and <5> Nodes in total for scheduling.
I0714 05:41:59.948679       1 session.go:190] Open Session e6095619-7a6a-49d4-84c2-0edad3e45422 with <0> Job and <1> Queues
I0714 05:41:59.950506       1 enqueue.go:79] Try to enqueue PodGroup to 0 Queues
I0714 05:41:59.950582       1 allocate.go:64] Try to allocate resource to 0 Queues
I0714 05:41:59.950800       1 session.go:244] Close Session e6095619-7a6a-49d4-84c2-0edad3e45422
I0714 05:42:00.955652       1 cache.go:1363] There are <0> Jobs, <1> Queues and <5> Nodes in total for scheduling.
I0714 05:42:00.955895       1 session.go:190] Open Session 3fa492da-74f4-4db8-8456-85534dd126e2 with <0> Job and <1> Queues
I0714 05:42:00.957981       1 enqueue.go:79] Try to enqueue PodGroup to 0 Queues
I0714 05:42:00.958067       1 allocate.go:64] Try to allocate resource to 0 Queues
I0714 05:42:00.958298       1 session.go:244] Close Session 3fa492da-74f4-4db8-8456-85534dd126e2
I0714 05:42:01.961027       1 cache.go:1363] There are <0> Jobs, <1> Queues and <5> Nodes in total for scheduling.
I0714 05:42:01.961193       1 session.go:190] Open Session e81d14a4-c3bd-4b5a-90f3-5d023a64c649 with <0> Job and <1> Queues
I0714 05:42:01.962930       1 enqueue.go:79] Try to enqueue PodGroup to 0 Queues
I0714 05:42:01.963002       1 allocate.go:64] Try to allocate resource to 0 Queues
I0714 05:42:01.963205       1 session.go:244] Close Session e81d14a4-c3bd-4b5a-90f3-5d023a64c649
I0714 05:42:02.965944       1 cache.go:1363] There are <0> Jobs, <1> Queues and <5> Nodes in total for scheduling.
I0714 05:42:02.966137       1 session.go:190] Open Session 2aafaa77-1f17-436f-871b-da86b9aae8a6 with <0> Job and <1> Queues
I0714 05:42:02.968011       1 enqueue.go:79] Try to enqueue PodGroup to 0 Queues
I0714 05:42:02.968079       1 allocate.go:64] Try to allocate resource to 0 Queues
I0714 05:42:02.968341       1 session.go:244] Close Session 2aafaa77-1f17-436f-871b-da86b9aae8a6
I0714 05:42:03.970797       1 cache.go:1363] There are <0> Jobs, <1> Queues and <5> Nodes in total for scheduling.
I0714 05:42:03.971016       1 session.go:190] Open Session d6c3d9df-8618-4e62-a51e-5e76b88c1444 with <0> Job and <1> Queues
I0714 05:42:03.973183       1 enqueue.go:79] Try to enqueue PodGroup to 0 Queues
I0714 05:42:03.973267       1 allocate.go:64] Try to allocate resource to 0 Queues
I0714 05:42:03.973480       1 session.go:244] Close Session d6c3d9df-8618-4e62-a51e-5e76b88c1444
I0714 05:42:04.975784       1 cache.go:1363] There are <0> Jobs, <1> Queues and <5> Nodes in total for scheduling.
I0714 05:42:04.975964       1 session.go:190] Open Session 04d786a6-89f0-4347-b9d0-0f5a1e9e4432 with <0> Job and <1> Queues
I0714 05:42:04.977821       1 enqueue.go:79] Try to enqueue PodGroup to 0 Queues
I0714 05:42:04.977890       1 allocate.go:64] Try to allocate resource to 0 Queues
I0714 05:42:04.978112       1 session.go:244] Close Session 04d786a6-89f0-4347-b9d0-0f5a1e9e4432
I0714 05:42:05.980504       1 cache.go:1363] There are <0> Jobs, <1> Queues and <5> Nodes in total for scheduling.
I0714 05:42:05.980671       1 session.go:190] Open Session c4a8647e-442d-4b15-886e-8cf5b6e24266 with <0> Job and <1> Queues
I0714 05:42:05.982466       1 enqueue.go:79] Try to enqueue PodGroup to 0 Queues
I0714 05:42:05.982540       1 allocate.go:64] Try to allocate resource to 0 Queues
I0714 05:42:05.982761       1 session.go:244] Close Session c4a8647e-442d-4b15-886e-8cf5b6e24266
I0714 05:42:06.292974       1 cache.go:1489] The metrics type is not set in the volcano scheduler configmap file. As a result, the CPU and memory load information of the node is not collected.
I0714 05:42:06.985555       1 cache.go:1363] There are <0> Jobs, <1> Queues and <5> Nodes in total for scheduling.
I0714 05:42:06.985702       1 session.go:190] Open Session b3f0fac9-3f64-4a7f-9825-13e6c0d0eb02 with <0> Job and <1> Queues
I0714 05:42:06.987459       1 enqueue.go:79] Try to enqueue PodGroup to 0 Queues
I0714 05:42:06.987537       1 allocate.go:64] Try to allocate resource to 0 Queues
I0714 05:42:06.987755       1 session.go:244] Close Session b3f0fac9-3f64-4a7f-9825-13e6c0d0eb02
I0714 05:42:07.990110       1 cache.go:1363] There are <0> Jobs, <1> Queues and <5> Nodes in total for scheduling.
I0714 05:42:07.990265       1 session.go:190] Open Session fabd52ab-f155-43c6-a194-6417bc0fbd8c with <0> Job and <1> Queues
I0714 05:42:07.991991       1 enqueue.go:79] Try to enqueue PodGroup to 0 Queues
I0714 05:42:07.992072       1 allocate.go:64] Try to allocate resource to 0 Queues
I0714 05:42:07.992320       1 session.go:244] Close Session fabd52ab-f155-43c6-a194-6417bc0fbd8c
I0714 05:42:08.994253       1 cache.go:1363] There are <0> Jobs, <1> Queues and <5> Nodes in total for scheduling.
I0714 05:42:08.994423       1 session.go:190] Open Session 72f1fd89-3385-43ae-960f-4532374a1bd3 with <0> Job and <1> Queues
I0714 05:42:08.996108       1 enqueue.go:79] Try to enqueue PodGroup to 0 Queues
I0714 05:42:08.996179       1 allocate.go:64] Try to allocate resource to 0 Queues
I0714 05:42:08.996426       1 session.go:244] Close Session 72f1fd89-3385-43ae-960f-4532374a1bd3
I0714 05:42:09.998833       1 cache.go:1363] There are <0> Jobs, <1> Queues and <5> Nodes in total for scheduling.
I0714 05:42:09.999018       1 session.go:190] Open Session 9c0897a4-3094-4a76-b223-f8f3c3c6b90d with <0> Job and <1> Queues
I0714 05:42:10.000908       1 enqueue.go:79] Try to enqueue PodGroup to 0 Queues
I0714 05:42:10.000979       1 allocate.go:64] Try to allocate resource to 0 Queues
I0714 05:42:10.001200       1 session.go:244] Close Session 9c0897a4-3094-4a76-b223-f8f3c3c6b90d
I0714 05:42:11.003829       1 cache.go:1363] There are <0> Jobs, <1> Queues and <5> Nodes in total for scheduling.
I0714 05:42:11.004000       1 session.go:190] Open Session 5a4bd9de-7458-4a51-abb8-1f41f0be3672 with <0> Job and <1> Queues
I0714 05:42:11.005903       1 enqueue.go:79] Try to enqueue PodGroup to 0 Queues
I0714 05:42:11.005970       1 allocate.go:64] Try to allocate resource to 0 Queues
I0714 05:42:11.006198       1 session.go:244] Close Session 5a4bd9de-7458-4a51-abb8-1f41f0be3672
I0714 05:42:12.008849       1 cache.go:1363] There are <0> Jobs, <1> Queues and <5> Nodes in total for scheduling.
I0714 05:42:12.009012       1 session.go:190] Open Session db6d3b54-1e69-4722-978d-20ef96348835 with <0> Job and <1> Queues
I0714 05:42:12.010699       1 enqueue.go:79] Try to enqueue PodGroup to 0 Queues
I0714 05:42:12.010765       1 allocate.go:64] Try to allocate resource to 0 Queues
I0714 05:42:12.010980       1 session.go:244] Close Session db6d3b54-1e69-4722-978d-20ef96348835
I0714 05:42:13.013365       1 cache.go:1363] There are <0> Jobs, <1> Queues and <5> Nodes in total for scheduling.
I0714 05:42:13.013528       1 session.go:190] Open Session 38267454-a6c9-4ac6-b6d4-249fa0c5999b with <0> Job and <1> Queues
I0714 05:42:13.015255       1 enqueue.go:79] Try to enqueue PodGroup to 0 Queues
I0714 05:42:13.015319       1 allocate.go:64] Try to allocate resource to 0 Queues
I0714 05:42:13.015535       1 session.go:244] Close Session 38267454-a6c9-4ac6-b6d4-249fa0c5999b
I0714 05:42:14.018275       1 cache.go:1363] There are <0> Jobs, <1> Queues and <5> Nodes in total for scheduling.
I0714 05:42:14.018439       1 session.go:190] Open Session 843150ce-1ce8-4011-9a2e-5b62f628766e with <0> Job and <1> Queues
I0714 05:42:14.020228       1 enqueue.go:79] Try to enqueue PodGroup to 0 Queues
I0714 05:42:14.020339       1 allocate.go:64] Try to allocate resource to 0 Queues
I0714 05:42:14.020561       1 session.go:244] Close Session 843150ce-1ce8-4011-9a2e-5b62f628766e
I0714 05:42:15.023475       1 cache.go:1363] There are <0> Jobs, <1> Queues and <5> Nodes in total for scheduling.
I0714 05:42:15.023646       1 session.go:190] Open Session fc0e458f-cf1a-428a-912b-11c4a9524285 with <0> Job and <1> Queues
I0714 05:42:15.025397       1 enqueue.go:79] Try to enqueue PodGroup to 0 Queues
I0714 05:42:15.025466       1 allocate.go:64] Try to allocate resource to 0 Queues
I0714 05:42:15.025682       1 session.go:244] Close Session fc0e458f-cf1a-428a-912b-11c4a9524285
I0714 05:42:16.027827       1 cache.go:1363] There are <0> Jobs, <1> Queues and <5> Nodes in total for scheduling.
I0714 05:42:16.028090       1 session.go:190] Open Session 9f31ffca-8100-4995-8a8a-962d0bacd75d with <0> Job and <1> Queues
I0714 05:42:16.029862       1 enqueue.go:79] Try to enqueue PodGroup to 0 Queues
I0714 05:42:16.029937       1 allocate.go:64] Try to allocate resource to 0 Queues
I0714 05:42:16.030155       1 session.go:244] Close Session 9f31ffca-8100-4995-8a8a-962d0bacd75d
I0714 05:42:17.032667       1 cache.go:1363] There are <0> Jobs, <1> Queues and <5> Nodes in total for scheduling.
I0714 05:42:17.032826       1 session.go:190] Open Session cf73ba8f-0219-487c-a94b-024011a55dc4 with <0> Job and <1> Queues
I0714 05:42:17.034373       1 enqueue.go:79] Try to enqueue PodGroup to 0 Queues
I0714 05:42:17.034443       1 allocate.go:64] Try to allocate resource to 0 Queues
I0714 05:42:17.034657       1 session.go:244] Close Session cf73ba8f-0219-487c-a94b-024011a55dc4
I0714 05:42:18.037583       1 cache.go:1363] There are <0> Jobs, <1> Queues and <5> Nodes in total for scheduling.
I0714 05:42:18.037739       1 session.go:190] Open Session cdce03b3-b637-4d32-8786-72f342b413cd with <0> Job and <1> Queues
I0714 05:42:18.039396       1 enqueue.go:79] Try to enqueue PodGroup to 0 Queues
I0714 05:42:18.039466       1 allocate.go:64] Try to allocate resource to 0 Queues
I0714 05:42:18.039680       1 session.go:244] Close Session cdce03b3-b637-4d32-8786-72f342b413cd
I0714 05:42:19.042133       1 cache.go:1363] There are <0> Jobs, <1> Queues and <5> Nodes in total for scheduling.
I0714 05:42:19.042303       1 session.go:190] Open Session 7e70751b-b3f8-4fd2-8d23-bf3fa23479f4 with <0> Job and <1> Queues
I0714 05:42:19.043936       1 enqueue.go:79] Try to enqueue PodGroup to 0 Queues
I0714 05:42:19.044006       1 allocate.go:64] Try to allocate resource to 0 Queues
I0714 05:42:19.044210       1 session.go:244] Close Session 7e70751b-b3f8-4fd2-8d23-bf3fa23479f4
I0714 05:42:20.046449       1 cache.go:1363] There are <0> Jobs, <1> Queues and <5> Nodes in total for scheduling.
I0714 05:42:20.046616       1 session.go:190] Open Session 1f0a7411-1496-4acb-a9b5-d31fea6c6578 with <0> Job and <1> Queues
I0714 05:42:20.048439       1 enqueue.go:79] Try to enqueue PodGroup to 0 Queues
I0714 05:42:20.048514       1 allocate.go:64] Try to allocate resource to 0 Queues
I0714 05:42:20.048727       1 session.go:244] Close Session 1f0a7411-1496-4acb-a9b5-d31fea6c6578
I0714 05:42:21.051143       1 cache.go:1363] There are <0> Jobs, <1> Queues and <5> Nodes in total for scheduling.
I0714 05:42:21.051328       1 session.go:190] Open Session 4c44b523-890e-4bb1-bed7-0cec2c278105 with <0> Job and <1> Queues
I0714 05:42:21.053117       1 enqueue.go:79] Try to enqueue PodGroup to 0 Queues
I0714 05:42:21.053185       1 allocate.go:64] Try to allocate resource to 0 Queues
I0714 05:42:21.053409       1 session.go:244] Close Session 4c44b523-890e-4bb1-bed7-0cec2c278105
I0714 05:42:22.055435       1 cache.go:1363] There are <0> Jobs, <1> Queues and <5> Nodes in total for scheduling.
I0714 05:42:22.055627       1 session.go:190] Open Session f172bce5-9f35-46fb-b72e-8b51b202c231 with <0> Job and <1> Queues
I0714 05:42:22.057406       1 enqueue.go:79] Try to enqueue PodGroup to 0 Queues
I0714 05:42:22.057478       1 allocate.go:64] Try to allocate resource to 0 Queues
I0714 05:42:22.057683       1 session.go:244] Close Session f172bce5-9f35-46fb-b72e-8b51b202c231
I0714 05:42:23.060693       1 cache.go:1363] There are <0> Jobs, <1> Queues and <5> Nodes in total for scheduling.
I0714 05:42:23.060879       1 session.go:190] Open Session e7d78abb-6a9e-474d-afe9-5075a1b37d15 with <0> Job and <1> Queues
I0714 05:42:23.062648       1 enqueue.go:79] Try to enqueue PodGroup to 0 Queues
I0714 05:42:23.062714       1 allocate.go:64] Try to allocate resource to 0 Queues
I0714 05:42:23.062941       1 session.go:244] Close Session e7d78abb-6a9e-474d-afe9-5075a1b37d15
I0714 05:42:24.065201       1 cache.go:1363] There are <0> Jobs, <1> Queues and <5> Nodes in total for scheduling.
I0714 05:42:24.065382       1 session.go:190] Open Session c9b08aaf-9530-4dc9-b1eb-33bbf2029484 with <0> Job and <1> Queues
I0714 05:42:24.067044       1 enqueue.go:79] Try to enqueue PodGroup to 0 Queues
I0714 05:42:24.067117       1 allocate.go:64] Try to allocate resource to 0 Queues
I0714 05:42:24.067327       1 session.go:244] Close Session c9b08aaf-9530-4dc9-b1eb-33bbf2029484
I0714 05:42:25.070060       1 cache.go:1363] There are <0> Jobs, <1> Queues and <5> Nodes in total for scheduling.
I0714 05:42:25.070264       1 session.go:190] Open Session afabe67f-8252-49e2-a53c-5f62bac0eb37 with <0> Job and <1> Queues
I0714 05:42:25.072008       1 enqueue.go:79] Try to enqueue PodGroup to 0 Queues
I0714 05:42:25.072082       1 allocate.go:64] Try to allocate resource to 0 Queues
I0714 05:42:25.072323       1 session.go:244] Close Session afabe67f-8252-49e2-a53c-5f62bac0eb37
I0714 05:42:26.075188       1 cache.go:1363] There are <0> Jobs, <1> Queues and <5> Nodes in total for scheduling.
I0714 05:42:26.075365       1 session.go:190] Open Session be07cd4f-99a5-43a2-ab67-868ed65b8f27 with <0> Job and <1> Queues
I0714 05:42:26.077133       1 enqueue.go:79] Try to enqueue PodGroup to 0 Queues
I0714 05:42:26.077206       1 allocate.go:64] Try to allocate resource to 0 Queues
I0714 05:42:26.077418       1 session.go:244] Close Session be07cd4f-99a5-43a2-ab67-868ed65b8f27
I0714 05:42:27.080173       1 cache.go:1363] There are <0> Jobs, <1> Queues and <5> Nodes in total for scheduling.
I0714 05:42:27.080380       1 session.go:190] Open Session 23f29d6c-b210-4cc7-b2e1-25c3a08a66a9 with <0> Job and <1> Queues
I0714 05:42:27.082121       1 enqueue.go:79] Try to enqueue PodGroup to 0 Queues
I0714 05:42:27.082187       1 allocate.go:64] Try to allocate resource to 0 Queues
I0714 05:42:27.082390       1 session.go:244] Close Session 23f29d6c-b210-4cc7-b2e1-25c3a08a66a9
I0714 05:42:28.085321       1 cache.go:1363] There are <0> Jobs, <1> Queues and <5> Nodes in total for scheduling.
I0714 05:42:28.085489       1 session.go:190] Open Session ac73b4cb-3bb0-4791-bf9a-6a87b5e08576 with <0> Job and <1> Queues
I0714 05:42:28.087211       1 enqueue.go:79] Try to enqueue PodGroup to 0 Queues
I0714 05:42:28.087285       1 allocate.go:64] Try to allocate resource to 0 Queues
I0714 05:42:28.087509       1 session.go:244] Close Session ac73b4cb-3bb0-4791-bf9a-6a87b5e08576
I0714 05:42:29.089516       1 cache.go:1363] There are <0> Jobs, <1> Queues and <5> Nodes in total for scheduling.
I0714 05:42:29.089664       1 session.go:190] Open Session 46a00336-8375-4eef-b8b3-7730f882b6e8 with <0> Job and <1> Queues
I0714 05:42:29.091280       1 enqueue.go:79] Try to enqueue PodGroup to 0 Queues
I0714 05:42:29.091342       1 allocate.go:64] Try to allocate resource to 0 Queues
I0714 05:42:29.091542       1 session.go:244] Close Session 46a00336-8375-4eef-b8b3-7730f882b6e8
I0714 05:42:30.094295       1 cache.go:1363] There are <0> Jobs, <1> Queues and <5> Nodes in total for scheduling.
I0714 05:42:30.094463       1 session.go:190] Open Session 1e05e1a6-a7d4-4090-9518-339f89bdd941 with <0> Job and <1> Queues
I0714 05:42:30.096151       1 enqueue.go:79] Try to enqueue PodGroup to 0 Queues
I0714 05:42:30.096213       1 allocate.go:64] Try to allocate resource to 0 Queues
I0714 05:42:30.096475       1 session.go:244] Close Session 1e05e1a6-a7d4-4090-9518-339f89bdd941
I0714 05:42:31.099283       1 cache.go:1363] There are <0> Jobs, <1> Queues and <5> Nodes in total for scheduling.
I0714 05:42:31.099452       1 session.go:190] Open Session 11c3a673-4dfb-4ad7-8d3a-a2395c0d9387 with <0> Job and <1> Queues
I0714 05:42:31.101230       1 enqueue.go:79] Try to enqueue PodGroup to 0 Queues
I0714 05:42:31.101311       1 allocate.go:64] Try to allocate resource to 0 Queues
I0714 05:42:31.101637       1 session.go:244] Close Session 11c3a673-4dfb-4ad7-8d3a-a2395c0d9387
I0714 05:42:32.104416       1 cache.go:1363] There are <0> Jobs, <1> Queues and <5> Nodes in total for scheduling.
I0714 05:42:32.104567       1 session.go:190] Open Session 9d0267d3-a7fe-4e8a-a878-e780bdfc4144 with <0> Job and <1> Queues
I0714 05:42:32.106239       1 enqueue.go:79] Try to enqueue PodGroup to 0 Queues
I0714 05:42:32.106306       1 allocate.go:64] Try to allocate resource to 0 Queues
I0714 05:42:32.106511       1 session.go:244] Close Session 9d0267d3-a7fe-4e8a-a878-e780bdfc4144
I0714 05:42:33.109152       1 cache.go:1363] There are <0> Jobs, <1> Queues and <5> Nodes in total for scheduling.
I0714 05:42:33.109333       1 session.go:190] Open Session dffa5d14-a6ed-4886-a86a-2f2c2b225352 with <0> Job and <1> Queues
I0714 05:42:33.111125       1 enqueue.go:79] Try to enqueue PodGroup to 0 Queues
I0714 05:42:33.111199       1 allocate.go:64] Try to allocate resource to 0 Queues
I0714 05:42:33.111410       1 session.go:244] Close Session dffa5d14-a6ed-4886-a86a-2f2c2b225352
I0714 05:42:34.113902       1 cache.go:1363] There are <0> Jobs, <1> Queues and <5> Nodes in total for scheduling.
I0714 05:42:34.114058       1 session.go:190] Open Session ac0f643f-668a-49be-9afe-2c6992626097 with <0> Job and <1> Queues
I0714 05:42:34.115707       1 enqueue.go:79] Try to enqueue PodGroup to 0 Queues
I0714 05:42:34.115769       1 allocate.go:64] Try to allocate resource to 0 Queues
I0714 05:42:34.115956       1 session.go:244] Close Session ac0f643f-668a-49be-9afe-2c6992626097
I0714 05:42:35.117923       1 cache.go:1363] There are <0> Jobs, <1> Queues and <5> Nodes in total for scheduling.
I0714 05:42:35.118092       1 session.go:190] Open Session 6272fade-e3c6-4ba9-86d1-31d4feec52c2 with <0> Job and <1> Queues
I0714 05:42:35.119842       1 enqueue.go:79] Try to enqueue PodGroup to 0 Queues
I0714 05:42:35.119917       1 allocate.go:64] Try to allocate resource to 0 Queues
I0714 05:42:35.120147       1 session.go:244] Close Session 6272fade-e3c6-4ba9-86d1-31d4feec52c2
I0714 05:42:36.122656       1 cache.go:1363] There are <0> Jobs, <1> Queues and <5> Nodes in total for scheduling.
I0714 05:42:36.122864       1 session.go:190] Open Session 2e6aa7bd-0f00-49b6-89c3-2a7d2ef55938 with <0> Job and <1> Queues
I0714 05:42:36.124677       1 enqueue.go:79] Try to enqueue PodGroup to 0 Queues
I0714 05:42:36.124751       1 allocate.go:64] Try to allocate resource to 0 Queues
I0714 05:42:36.124967       1 session.go:244] Close Session 2e6aa7bd-0f00-49b6-89c3-2a7d2ef55938
I0714 05:42:36.293963       1 cache.go:1489] The metrics type is not set in the volcano scheduler configmap file. As a result, the CPU and memory load information of the node is not collected.
I0714 05:42:37.127871       1 cache.go:1363] There are <0> Jobs, <1> Queues and <5> Nodes in total for scheduling.
I0714 05:42:37.128020       1 session.go:190] Open Session c99ccf23-53ff-4c7d-908e-f16a96c50629 with <0> Job and <1> Queues
I0714 05:42:37.129804       1 enqueue.go:79] Try to enqueue PodGroup to 0 Queues
I0714 05:42:37.129872       1 allocate.go:64] Try to allocate resource to 0 Queues
I0714 05:42:37.130098       1 session.go:244] Close Session c99ccf23-53ff-4c7d-908e-f16a96c50629
I0714 05:42:38.132006       1 cache.go:1363] There are <0> Jobs, <1> Queues and <5> Nodes in total for scheduling.
I0714 05:42:38.132154       1 session.go:190] Open Session a43dede6-e093-48da-9387-ce4fc52816b3 with <0> Job and <1> Queues
I0714 05:42:38.134066       1 enqueue.go:79] Try to enqueue PodGroup to 0 Queues
I0714 05:42:38.134133       1 allocate.go:64] Try to allocate resource to 0 Queues
I0714 05:42:38.134352       1 session.go:244] Close Session a43dede6-e093-48da-9387-ce4fc52816b3
I0714 05:42:39.136718       1 cache.go:1363] There are <0> Jobs, <1> Queues and <5> Nodes in total for scheduling.
I0714 05:42:39.136899       1 session.go:190] Open Session 5fbf02e7-cb5c-4bbc-9fff-a68b11f08367 with <0> Job and <1> Queues
I0714 05:42:39.138634       1 enqueue.go:79] Try to enqueue PodGroup to 0 Queues
I0714 05:42:39.138706       1 allocate.go:64] Try to allocate resource to 0 Queues
I0714 05:42:39.138935       1 session.go:244] Close Session 5fbf02e7-cb5c-4bbc-9fff-a68b11f08367
I0714 05:42:40.141807       1 cache.go:1363] There are <0> Jobs, <1> Queues and <5> Nodes in total for scheduling.
I0714 05:42:40.142002       1 session.go:190] Open Session 36a062b1-eeb7-4075-81c2-4b8592b29b9d with <0> Job and <1> Queues
I0714 05:42:40.143792       1 enqueue.go:79] Try to enqueue PodGroup to 0 Queues
I0714 05:42:40.143862       1 allocate.go:64] Try to allocate resource to 0 Queues
I0714 05:42:40.144084       1 session.go:244] Close Session 36a062b1-eeb7-4075-81c2-4b8592b29b9d
I0714 05:42:41.146179       1 cache.go:1363] There are <0> Jobs, <1> Queues and <5> Nodes in total for scheduling.
I0714 05:42:41.146346       1 session.go:190] Open Session 46523582-40be-45f6-864e-a6129b484741 with <0> Job and <1> Queues
I0714 05:42:41.148066       1 enqueue.go:79] Try to enqueue PodGroup to 0 Queues
I0714 05:42:41.148139       1 allocate.go:64] Try to allocate resource to 0 Queues
I0714 05:42:41.148396       1 session.go:244] Close Session 46523582-40be-45f6-864e-a6129b484741
I0714 05:42:42.150907       1 cache.go:1363] There are <0> Jobs, <1> Queues and <5> Nodes in total for scheduling.
I0714 05:42:42.151069       1 session.go:190] Open Session 3bdbc734-6073-4d2d-9233-7c47220ae422 with <0> Job and <1> Queues
I0714 05:42:42.152827       1 enqueue.go:79] Try to enqueue PodGroup to 0 Queues
I0714 05:42:42.152893       1 allocate.go:64] Try to allocate resource to 0 Queues
I0714 05:42:42.153099       1 session.go:244] Close Session 3bdbc734-6073-4d2d-9233-7c47220ae422
I0714 05:42:43.155076       1 cache.go:1363] There are <0> Jobs, <1> Queues and <5> Nodes in total for scheduling.
I0714 05:42:43.155245       1 session.go:190] Open Session bef7f725-7c2b-4a9c-84c0-48d0920a35f0 with <0> Job and <1> Queues
I0714 05:42:43.157140       1 enqueue.go:79] Try to enqueue PodGroup to 0 Queues
I0714 05:42:43.157208       1 allocate.go:64] Try to allocate resource to 0 Queues
I0714 05:42:43.157424       1 session.go:244] Close Session bef7f725-7c2b-4a9c-84c0-48d0920a35f0
I0714 05:42:44.159897       1 cache.go:1363] There are <0> Jobs, <1> Queues and <5> Nodes in total for scheduling.
I0714 05:42:44.160057       1 session.go:190] Open Session 9ac00c54-67ee-44b3-b0dc-912d00feba38 with <0> Job and <1> Queues
I0714 05:42:44.161776       1 enqueue.go:79] Try to enqueue PodGroup to 0 Queues
I0714 05:42:44.161844       1 allocate.go:64] Try to allocate resource to 0 Queues
I0714 05:42:44.162036       1 session.go:244] Close Session 9ac00c54-67ee-44b3-b0dc-912d00feba38
I0714 05:42:45.164808       1 cache.go:1363] There are <0> Jobs, <1> Queues and <5> Nodes in total for scheduling.
I0714 05:42:45.164978       1 session.go:190] Open Session 1dc5a9c0-fa59-4f98-833e-18695628a2ca with <0> Job and <1> Queues
I0714 05:42:45.166692       1 enqueue.go:79] Try to enqueue PodGroup to 0 Queues
I0714 05:42:45.166759       1 allocate.go:64] Try to allocate resource to 0 Queues
I0714 05:42:45.166967       1 session.go:244] Close Session 1dc5a9c0-fa59-4f98-833e-18695628a2ca
I0714 05:42:46.169658       1 cache.go:1363] There are <0> Jobs, <1> Queues and <5> Nodes in total for scheduling.
I0714 05:42:46.169838       1 session.go:190] Open Session 816b00d6-8456-40c0-933b-8d949e5cff5b with <0> Job and <1> Queues
I0714 05:42:46.171547       1 enqueue.go:79] Try to enqueue PodGroup to 0 Queues
I0714 05:42:46.171616       1 allocate.go:64] Try to allocate resource to 0 Queues
I0714 05:42:46.171817       1 session.go:244] Close Session 816b00d6-8456-40c0-933b-8d949e5cff5b
I0714 05:42:47.173679       1 cache.go:1363] There are <0> Jobs, <1> Queues and <5> Nodes in total for scheduling.
I0714 05:42:47.173812       1 session.go:190] Open Session c01ea866-83d3-4c19-b716-f7fa1894b1f1 with <0> Job and <1> Queues
I0714 05:42:47.175404       1 enqueue.go:79] Try to enqueue PodGroup to 0 Queues
I0714 05:42:47.175469       1 allocate.go:64] Try to allocate resource to 0 Queues
I0714 05:42:47.175655       1 session.go:244] Close Session c01ea866-83d3-4c19-b716-f7fa1894b1f1
I0714 05:42:48.178065       1 cache.go:1363] There are <0> Jobs, <1> Queues and <5> Nodes in total for scheduling.
I0714 05:42:48.178218       1 session.go:190] Open Session f94737ca-dbdd-49e0-bcc3-a538259e0b75 with <0> Job and <1> Queues
I0714 05:42:48.179929       1 enqueue.go:79] Try to enqueue PodGroup to 0 Queues
I0714 05:42:48.179994       1 allocate.go:64] Try to allocate resource to 0 Queues
I0714 05:42:48.180206       1 session.go:244] Close Session f94737ca-dbdd-49e0-bcc3-a538259e0b75
I0714 05:42:49.183053       1 cache.go:1363] There are <0> Jobs, <1> Queues and <5> Nodes in total for scheduling.
I0714 05:42:49.183211       1 session.go:190] Open Session 1063cadc-c54a-4485-a3c6-5e7bb08b6985 with <0> Job and <1> Queues
I0714 05:42:49.184936       1 enqueue.go:79] Try to enqueue PodGroup to 0 Queues
I0714 05:42:49.185001       1 allocate.go:64] Try to allocate resource to 0 Queues
I0714 05:42:49.185211       1 session.go:244] Close Session 1063cadc-c54a-4485-a3c6-5e7bb08b6985
I0714 05:42:50.188162       1 cache.go:1363] There are <0> Jobs, <1> Queues and <5> Nodes in total for scheduling.
I0714 05:42:50.188404       1 session.go:190] Open Session f113d88e-dc3a-4c5b-9df2-f11b80d6d182 with <0> Job and <1> Queues
I0714 05:42:50.192111       1 enqueue.go:79] Try to enqueue PodGroup to 0 Queues
I0714 05:42:50.192253       1 allocate.go:64] Try to allocate resource to 0 Queues
I0714 05:42:50.192878       1 session.go:244] Close Session f113d88e-dc3a-4c5b-9df2-f11b80d6d182
I0714 05:42:51.195317       1 cache.go:1363] There are <0> Jobs, <1> Queues and <5> Nodes in total for scheduling.
I0714 05:42:51.195517       1 session.go:190] Open Session 85d3308f-2945-4d76-8ee7-7e00ea950cae with <0> Job and <1> Queues
I0714 05:42:51.197376       1 enqueue.go:79] Try to enqueue PodGroup to 0 Queues
I0714 05:42:51.197447       1 allocate.go:64] Try to allocate resource to 0 Queues
I0714 05:42:51.197666       1 session.go:244] Close Session 85d3308f-2945-4d76-8ee7-7e00ea950cae
I0714 05:42:52.200609       1 cache.go:1363] There are <0> Jobs, <1> Queues and <5> Nodes in total for scheduling.
I0714 05:42:52.200806       1 session.go:190] Open Session 4c40fca7-6b04-4087-87ec-7447cc87f6f9 with <0> Job and <1> Queues
I0714 05:42:52.202659       1 enqueue.go:79] Try to enqueue PodGroup to 0 Queues
I0714 05:42:52.202735       1 allocate.go:64] Try to allocate resource to 0 Queues
I0714 05:42:52.202938       1 session.go:244] Close Session 4c40fca7-6b04-4087-87ec-7447cc87f6f9
I0714 05:42:53.205592       1 cache.go:1363] There are <0> Jobs, <1> Queues and <5> Nodes in total for scheduling.
I0714 05:42:53.205769       1 session.go:190] Open Session 86aa2730-2d21-45c5-985e-d8cfd97e2375 with <0> Job and <1> Queues
I0714 05:42:53.207600       1 enqueue.go:79] Try to enqueue PodGroup to 0 Queues
I0714 05:42:53.207664       1 allocate.go:64] Try to allocate resource to 0 Queues
I0714 05:42:53.207878       1 session.go:244] Close Session 86aa2730-2d21-45c5-985e-d8cfd97e2375
I0714 05:42:54.209999       1 cache.go:1363] There are <0> Jobs, <1> Queues and <5> Nodes in total for scheduling.
I0714 05:42:54.210140       1 session.go:190] Open Session 169da9b0-76cf-4429-8028-0a5f82c46bea with <0> Job and <1> Queues
I0714 05:42:54.211772       1 enqueue.go:79] Try to enqueue PodGroup to 0 Queues
I0714 05:42:54.211834       1 allocate.go:64] Try to allocate resource to 0 Queues
I0714 05:42:54.212057       1 session.go:244] Close Session 169da9b0-76cf-4429-8028-0a5f82c46bea
I0714 05:42:55.213693       1 cache.go:1363] There are <0> Jobs, <1> Queues and <5> Nodes in total for scheduling.
I0714 05:42:55.213999       1 session.go:190] Open Session e2fd48a4-6341-455a-a034-3236a96258f6 with <0> Job and <1> Queues
I0714 05:42:55.214944       1 enqueue.go:79] Try to enqueue PodGroup to 0 Queues
I0714 05:42:55.214997       1 allocate.go:64] Try to allocate resource to 0 Queues
I0714 05:42:55.215114       1 session.go:244] Close Session e2fd48a4-6341-455a-a034-3236a96258f6
I0714 05:42:56.217577       1 cache.go:1363] There are <0> Jobs, <1> Queues and <5> Nodes in total for scheduling.
I0714 05:42:56.217750       1 session.go:190] Open Session c49ace9c-f38d-4697-816a-5d22a2c0607b with <0> Job and <1> Queues
I0714 05:42:56.219521       1 enqueue.go:79] Try to enqueue PodGroup to 0 Queues
I0714 05:42:56.219592       1 allocate.go:64] Try to allocate resource to 0 Queues
I0714 05:42:56.219825       1 session.go:244] Close Session c49ace9c-f38d-4697-816a-5d22a2c0607b
I0714 05:42:57.222527       1 cache.go:1363] There are <0> Jobs, <1> Queues and <5> Nodes in total for scheduling.
I0714 05:42:57.222691       1 session.go:190] Open Session 119e458c-75c5-452d-b389-e54e86161f09 with <0> Job and <1> Queues
I0714 05:42:57.224424       1 enqueue.go:79] Try to enqueue PodGroup to 0 Queues
I0714 05:42:57.224490       1 allocate.go:64] Try to allocate resource to 0 Queues
I0714 05:42:57.224694       1 session.go:244] Close Session 119e458c-75c5-452d-b389-e54e86161f09
I0714 05:42:58.227156       1 cache.go:1363] There are <0> Jobs, <1> Queues and <5> Nodes in total for scheduling.
I0714 05:42:58.227328       1 session.go:190] Open Session 86998f9c-8427-4477-9498-37cd01ae03e7 with <0> Job and <1> Queues
I0714 05:42:58.229130       1 enqueue.go:79] Try to enqueue PodGroup to 0 Queues
I0714 05:42:58.229198       1 allocate.go:64] Try to allocate resource to 0 Queues
I0714 05:42:58.229418       1 session.go:244] Close Session 86998f9c-8427-4477-9498-37cd01ae03e7
I0714 05:42:59.232107       1 cache.go:1363] There are <0> Jobs, <1> Queues and <5> Nodes in total for scheduling.
I0714 05:42:59.232331       1 session.go:190] Open Session 7a91f4ed-dc7e-4f06-b2f0-bd1464050e9a with <0> Job and <1> Queues
I0714 05:42:59.234053       1 enqueue.go:79] Try to enqueue PodGroup to 0 Queues
I0714 05:42:59.234119       1 allocate.go:64] Try to allocate resource to 0 Queues
I0714 05:42:59.234323       1 session.go:244] Close Session 7a91f4ed-dc7e-4f06-b2f0-bd1464050e9a
I0714 05:43:00.236909       1 cache.go:1363] There are <0> Jobs, <1> Queues and <5> Nodes in total for scheduling.
I0714 05:43:00.237066       1 session.go:190] Open Session 8528e0db-3016-488e-b6af-9ab11eeae905 with <0> Job and <1> Queues
I0714 05:43:00.238649       1 enqueue.go:79] Try to enqueue PodGroup to 0 Queues
I0714 05:43:00.238708       1 allocate.go:64] Try to allocate resource to 0 Queues
I0714 05:43:00.238905       1 session.go:244] Close Session 8528e0db-3016-488e-b6af-9ab11eeae905
I0714 05:43:01.241081       1 cache.go:1363] There are <0> Jobs, <1> Queues and <5> Nodes in total for scheduling.
I0714 05:43:01.241257       1 session.go:190] Open Session 6867b33a-70e6-43a1-a43f-055eefc98120 with <0> Job and <1> Queues
I0714 05:43:01.243012       1 enqueue.go:79] Try to enqueue PodGroup to 0 Queues
I0714 05:43:01.243086       1 allocate.go:64] Try to allocate resource to 0 Queues
I0714 05:43:01.243284       1 session.go:244] Close Session 6867b33a-70e6-43a1-a43f-055eefc98120
I0714 05:43:02.245476       1 cache.go:1363] There are <0> Jobs, <1> Queues and <5> Nodes in total for scheduling.
I0714 05:43:02.245656       1 session.go:190] Open Session 9ea8f4cb-2112-4d4c-bbb1-ed22f1df3da4 with <0> Job and <1> Queues
I0714 05:43:02.247484       1 enqueue.go:79] Try to enqueue PodGroup to 0 Queues
I0714 05:43:02.247550       1 allocate.go:64] Try to allocate resource to 0 Queues
I0714 05:43:02.247755       1 session.go:244] Close Session 9ea8f4cb-2112-4d4c-bbb1-ed22f1df3da4
I0714 05:43:03.250234       1 cache.go:1363] There are <0> Jobs, <1> Queues and <5> Nodes in total for scheduling.
I0714 05:43:03.250407       1 session.go:190] Open Session 8a01a278-2b2a-49b2-9dbb-8890c7e9a690 with <0> Job and <1> Queues
I0714 05:43:03.252242       1 enqueue.go:79] Try to enqueue PodGroup to 0 Queues
I0714 05:43:03.252351       1 allocate.go:64] Try to allocate resource to 0 Queues
I0714 05:43:03.252568       1 session.go:244] Close Session 8a01a278-2b2a-49b2-9dbb-8890c7e9a690
I0714 05:43:04.255109       1 cache.go:1363] There are <0> Jobs, <1> Queues and <5> Nodes in total for scheduling.
I0714 05:43:04.255265       1 session.go:190] Open Session fc9d4d86-0d57-4497-8412-8896ec10bdd3 with <0> Job and <1> Queues
I0714 05:43:04.257144       1 enqueue.go:79] Try to enqueue PodGroup to 0 Queues
I0714 05:43:04.257216       1 allocate.go:64] Try to allocate resource to 0 Queues
I0714 05:43:04.257417       1 session.go:244] Close Session fc9d4d86-0d57-4497-8412-8896ec10bdd3
I0714 05:43:05.260168       1 cache.go:1363] There are <0> Jobs, <1> Queues and <5> Nodes in total for scheduling.
I0714 05:43:05.260345       1 session.go:190] Open Session fd83fec8-07a4-4a4c-817c-a45616d2a776 with <0> Job and <1> Queues
I0714 05:43:05.262024       1 enqueue.go:79] Try to enqueue PodGroup to 0 Queues
I0714 05:43:05.262086       1 allocate.go:64] Try to allocate resource to 0 Queues
I0714 05:43:05.262294       1 session.go:244] Close Session fd83fec8-07a4-4a4c-817c-a45616d2a776
I0714 05:43:06.264938       1 cache.go:1363] There are <0> Jobs, <1> Queues and <5> Nodes in total for scheduling.
I0714 05:43:06.265095       1 session.go:190] Open Session a598299b-4189-4638-a8a9-28e33a1829e9 with <0> Job and <1> Queues
I0714 05:43:06.266926       1 enqueue.go:79] Try to enqueue PodGroup to 0 Queues
I0714 05:43:06.266999       1 allocate.go:64] Try to allocate resource to 0 Queues
I0714 05:43:06.267214       1 session.go:244] Close Session a598299b-4189-4638-a8a9-28e33a1829e9
I0714 05:43:06.294331       1 cache.go:1489] The metrics type is not set in the volcano scheduler configmap file. As a result, the CPU and memory load information of the node is not collected.
I0714 05:43:07.269423       1 cache.go:1363] There are <0> Jobs, <1> Queues and <5> Nodes in total for scheduling.
I0714 05:43:07.269579       1 session.go:190] Open Session 60782c63-377a-4a18-a0ed-4f7cf2f4678f with <0> Job and <1> Queues
I0714 05:43:07.271304       1 enqueue.go:79] Try to enqueue PodGroup to 0 Queues
I0714 05:43:07.271374       1 allocate.go:64] Try to allocate resource to 0 Queues
I0714 05:43:07.271616       1 session.go:244] Close Session 60782c63-377a-4a18-a0ed-4f7cf2f4678f
I0714 05:43:08.274139       1 cache.go:1363] There are <0> Jobs, <1> Queues and <5> Nodes in total for scheduling.
I0714 05:43:08.274312       1 session.go:190] Open Session 9f0703ca-d22c-481f-a3d0-7c1323b362f3 with <0> Job and <1> Queues
I0714 05:43:08.276046       1 enqueue.go:79] Try to enqueue PodGroup to 0 Queues
I0714 05:43:08.276127       1 allocate.go:64] Try to allocate resource to 0 Queues
I0714 05:43:08.276373       1 session.go:244] Close Session 9f0703ca-d22c-481f-a3d0-7c1323b362f3
I0714 05:43:09.278376       1 cache.go:1363] There are <0> Jobs, <1> Queues and <5> Nodes in total for scheduling.
I0714 05:43:09.278546       1 session.go:190] Open Session 366bc5fc-a77e-40e2-87c3-3f4d236027a0 with <0> Job and <1> Queues
I0714 05:43:09.280612       1 enqueue.go:79] Try to enqueue PodGroup to 0 Queues
I0714 05:43:09.280681       1 allocate.go:64] Try to allocate resource to 0 Queues
I0714 05:43:09.280877       1 session.go:244] Close Session 366bc5fc-a77e-40e2-87c3-3f4d236027a0
I0714 05:43:10.283394       1 cache.go:1363] There are <0> Jobs, <1> Queues and <5> Nodes in total for scheduling.
I0714 05:43:10.283583       1 session.go:190] Open Session c28b57c9-589c-42e3-9119-5aa00846e9d7 with <0> Job and <1> Queues
I0714 05:43:10.285426       1 enqueue.go:79] Try to enqueue PodGroup to 0 Queues
I0714 05:43:10.285496       1 allocate.go:64] Try to allocate resource to 0 Queues
I0714 05:43:10.285697       1 session.go:244] Close Session c28b57c9-589c-42e3-9119-5aa00846e9d7
I0714 05:43:11.287809       1 cache.go:1363] There are <0> Jobs, <1> Queues and <5> Nodes in total for scheduling.
I0714 05:43:11.287982       1 session.go:190] Open Session 9358a0a7-803e-46a8-888b-8de2eb0423de with <0> Job and <1> Queues
I0714 05:43:11.289875       1 enqueue.go:79] Try to enqueue PodGroup to 0 Queues
I0714 05:43:11.289942       1 allocate.go:64] Try to allocate resource to 0 Queues
I0714 05:43:11.290186       1 session.go:244] Close Session 9358a0a7-803e-46a8-888b-8de2eb0423de
I0714 05:43:12.292403       1 cache.go:1363] There are <0> Jobs, <1> Queues and <5> Nodes in total for scheduling.
I0714 05:43:12.292605       1 session.go:190] Open Session 33a08515-cc5c-42b7-a349-5acd35bc71da with <0> Job and <1> Queues
I0714 05:43:12.294373       1 enqueue.go:79] Try to enqueue PodGroup to 0 Queues
I0714 05:43:12.294434       1 allocate.go:64] Try to allocate resource to 0 Queues
I0714 05:43:12.294642       1 session.go:244] Close Session 33a08515-cc5c-42b7-a349-5acd35bc71da
I0714 05:43:13.297327       1 cache.go:1363] There are <0> Jobs, <1> Queues and <5> Nodes in total for scheduling.
I0714 05:43:13.297506       1 session.go:190] Open Session 143e0e51-f1eb-48e8-ba71-f20db116fd41 with <0> Job and <1> Queues
I0714 05:43:13.299189       1 enqueue.go:79] Try to enqueue PodGroup to 0 Queues
I0714 05:43:13.299257       1 allocate.go:64] Try to allocate resource to 0 Queues
I0714 05:43:13.299474       1 session.go:244] Close Session 143e0e51-f1eb-48e8-ba71-f20db116fd41
I0714 05:43:14.301675       1 cache.go:1363] There are <0> Jobs, <1> Queues and <5> Nodes in total for scheduling.
I0714 05:43:14.301829       1 session.go:190] Open Session 4266abdc-8af2-438f-a463-8aa0672ee974 with <0> Job and <1> Queues
I0714 05:43:14.303546       1 enqueue.go:79] Try to enqueue PodGroup to 0 Queues
I0714 05:43:14.303608       1 allocate.go:64] Try to allocate resource to 0 Queues
I0714 05:43:14.303866       1 session.go:244] Close Session 4266abdc-8af2-438f-a463-8aa0672ee974
I0714 05:43:15.306848       1 cache.go:1363] There are <0> Jobs, <1> Queues and <5> Nodes in total for scheduling.
I0714 05:43:15.307026       1 session.go:190] Open Session e3366c34-cfc2-4feb-abe9-84ef2cc682dd with <0> Job and <1> Queues
I0714 05:43:15.308871       1 enqueue.go:79] Try to enqueue PodGroup to 0 Queues
I0714 05:43:15.308937       1 allocate.go:64] Try to allocate resource to 0 Queues
I0714 05:43:15.309155       1 session.go:244] Close Session e3366c34-cfc2-4feb-abe9-84ef2cc682dd
I0714 05:43:16.311061       1 cache.go:1363] There are <0> Jobs, <1> Queues and <5> Nodes in total for scheduling.
I0714 05:43:16.311222       1 session.go:190] Open Session 3d850dce-8535-410c-a9d0-e47994c3d1be with <0> Job and <1> Queues
I0714 05:43:16.313122       1 enqueue.go:79] Try to enqueue PodGroup to 0 Queues
I0714 05:43:16.313197       1 allocate.go:64] Try to allocate resource to 0 Queues
I0714 05:43:16.313414       1 session.go:244] Close Session 3d850dce-8535-410c-a9d0-e47994c3d1be
I0714 05:43:17.315357       1 cache.go:1363] There are <0> Jobs, <1> Queues and <5> Nodes in total for scheduling.
I0714 05:43:17.315506       1 session.go:190] Open Session 2b3e6b1f-619f-45c8-ba7b-195d78ae78da with <0> Job and <1> Queues
I0714 05:43:17.317178       1 enqueue.go:79] Try to enqueue PodGroup to 0 Queues
I0714 05:43:17.317246       1 allocate.go:64] Try to allocate resource to 0 Queues
I0714 05:43:17.317445       1 session.go:244] Close Session 2b3e6b1f-619f-45c8-ba7b-195d78ae78da
I0714 05:43:18.320259       1 cache.go:1363] There are <0> Jobs, <1> Queues and <5> Nodes in total for scheduling.
I0714 05:43:18.320473       1 session.go:190] Open Session 6577d11a-0fc9-4139-b81f-e60ac86e8342 with <0> Job and <1> Queues
I0714 05:43:18.322287       1 enqueue.go:79] Try to enqueue PodGroup to 0 Queues
I0714 05:43:18.322353       1 allocate.go:64] Try to allocate resource to 0 Queues
I0714 05:43:18.322578       1 session.go:244] Close Session 6577d11a-0fc9-4139-b81f-e60ac86e8342
I0714 05:43:19.323820       1 cache.go:1363] There are <0> Jobs, <1> Queues and <5> Nodes in total for scheduling.
I0714 05:43:19.323912       1 session.go:190] Open Session 09640077-8e6d-47af-b34b-03d5f6abe3a5 with <0> Job and <1> Queues
I0714 05:43:19.324885       1 enqueue.go:79] Try to enqueue PodGroup to 0 Queues
I0714 05:43:19.324931       1 allocate.go:64] Try to allocate resource to 0 Queues
I0714 05:43:19.325047       1 session.go:244] Close Session 09640077-8e6d-47af-b34b-03d5f6abe3a5
I0714 05:43:20.327455       1 cache.go:1363] There are <0> Jobs, <1> Queues and <5> Nodes in total for scheduling.
I0714 05:43:20.327634       1 session.go:190] Open Session 60686026-3718-4614-9961-ff50cf0141da with <0> Job and <1> Queues
I0714 05:43:20.329454       1 enqueue.go:79] Try to enqueue PodGroup to 0 Queues
I0714 05:43:20.329529       1 allocate.go:64] Try to allocate resource to 0 Queues
I0714 05:43:20.329747       1 session.go:244] Close Session 60686026-3718-4614-9961-ff50cf0141da
I0714 05:43:21.332205       1 cache.go:1363] There are <0> Jobs, <1> Queues and <5> Nodes in total for scheduling.
I0714 05:43:21.332422       1 session.go:190] Open Session 2e33c3c1-2a10-4987-9708-58799969056b with <0> Job and <1> Queues
I0714 05:43:21.334172       1 enqueue.go:79] Try to enqueue PodGroup to 0 Queues
I0714 05:43:21.334236       1 allocate.go:64] Try to allocate resource to 0 Queues
I0714 05:43:21.334446       1 session.go:244] Close Session 2e33c3c1-2a10-4987-9708-58799969056b
I0714 05:43:22.336865       1 cache.go:1363] There are <0> Jobs, <1> Queues and <5> Nodes in total for scheduling.
I0714 05:43:22.337036       1 session.go:190] Open Session a31a854f-081e-47d0-872b-91cbde86440a with <0> Job and <1> Queues
I0714 05:43:22.338771       1 enqueue.go:79] Try to enqueue PodGroup to 0 Queues
I0714 05:43:22.338837       1 allocate.go:64] Try to allocate resource to 0 Queues
I0714 05:43:22.339032       1 session.go:244] Close Session a31a854f-081e-47d0-872b-91cbde86440a
I0714 05:43:23.341713       1 cache.go:1363] There are <0> Jobs, <1> Queues and <5> Nodes in total for scheduling.
I0714 05:43:23.341888       1 session.go:190] Open Session b474234e-829e-4482-ab78-f0fe16717281 with <0> Job and <1> Queues
I0714 05:43:23.343686       1 enqueue.go:79] Try to enqueue PodGroup to 0 Queues
I0714 05:43:23.343762       1 allocate.go:64] Try to allocate resource to 0 Queues
I0714 05:43:23.343978       1 session.go:244] Close Session b474234e-829e-4482-ab78-f0fe16717281
I0714 05:43:24.345867       1 cache.go:1363] There are <0> Jobs, <1> Queues and <5> Nodes in total for scheduling.
I0714 05:43:24.346033       1 session.go:190] Open Session 4cb8489b-de1e-48eb-a17a-d0433cdf4686 with <0> Job and <1> Queues
I0714 05:43:24.347707       1 enqueue.go:79] Try to enqueue PodGroup to 0 Queues
I0714 05:43:24.347771       1 allocate.go:64] Try to allocate resource to 0 Queues
I0714 05:43:24.347986       1 session.go:244] Close Session 4cb8489b-de1e-48eb-a17a-d0433cdf4686
I0714 05:43:25.350140       1 cache.go:1363] There are <0> Jobs, <1> Queues and <5> Nodes in total for scheduling.
I0714 05:43:25.350312       1 session.go:190] Open Session 6cb687c3-be43-41d5-9e7c-fc3edbd87828 with <0> Job and <1> Queues
I0714 05:43:25.352112       1 enqueue.go:79] Try to enqueue PodGroup to 0 Queues
I0714 05:43:25.352179       1 allocate.go:64] Try to allocate resource to 0 Queues
I0714 05:43:25.352430       1 session.go:244] Close Session 6cb687c3-be43-41d5-9e7c-fc3edbd87828
I0714 05:43:26.354681       1 cache.go:1363] There are <0> Jobs, <1> Queues and <5> Nodes in total for scheduling.
I0714 05:43:26.354864       1 session.go:190] Open Session b014fb68-881f-4641-b781-496be102e4e1 with <0> Job and <1> Queues
I0714 05:43:26.356631       1 enqueue.go:79] Try to enqueue PodGroup to 0 Queues
I0714 05:43:26.356699       1 allocate.go:64] Try to allocate resource to 0 Queues
I0714 05:43:26.356917       1 session.go:244] Close Session b014fb68-881f-4641-b781-496be102e4e1
I0714 05:43:27.359565       1 cache.go:1363] There are <0> Jobs, <1> Queues and <5> Nodes in total for scheduling.
I0714 05:43:27.359719       1 session.go:190] Open Session cdfc9ee9-a0e4-4ef0-af41-dbc8ab254e3f with <0> Job and <1> Queues
I0714 05:43:27.361468       1 enqueue.go:79] Try to enqueue PodGroup to 0 Queues
I0714 05:43:27.361531       1 allocate.go:64] Try to allocate resource to 0 Queues
I0714 05:43:27.361754       1 session.go:244] Close Session cdfc9ee9-a0e4-4ef0-af41-dbc8ab254e3f
I0714 05:43:28.363788       1 cache.go:1363] There are <0> Jobs, <1> Queues and <5> Nodes in total for scheduling.
I0714 05:43:28.363949       1 session.go:190] Open Session 3bfa63d9-2a39-4697-ac9c-32da132af7f3 with <0> Job and <1> Queues
I0714 05:43:28.365766       1 enqueue.go:79] Try to enqueue PodGroup to 0 Queues
I0714 05:43:28.365834       1 allocate.go:64] Try to allocate resource to 0 Queues
I0714 05:43:28.366034       1 session.go:244] Close Session 3bfa63d9-2a39-4697-ac9c-32da132af7f3
I0714 05:43:29.368494       1 cache.go:1363] There are <0> Jobs, <1> Queues and <5> Nodes in total for scheduling.
I0714 05:43:29.368691       1 session.go:190] Open Session e6eac08c-5b41-4af6-9138-a82145bcdd8f with <0> Job and <1> Queues
I0714 05:43:29.370459       1 enqueue.go:79] Try to enqueue PodGroup to 0 Queues
I0714 05:43:29.370527       1 allocate.go:64] Try to allocate resource to 0 Queues
I0714 05:43:29.370743       1 session.go:244] Close Session e6eac08c-5b41-4af6-9138-a82145bcdd8f
I0714 05:43:30.372913       1 cache.go:1363] There are <0> Jobs, <1> Queues and <5> Nodes in total for scheduling.
I0714 05:43:30.373076       1 session.go:190] Open Session 7a633edc-017f-4a58-a558-ecbd38d0ac45 with <0> Job and <1> Queues
I0714 05:43:30.374869       1 enqueue.go:79] Try to enqueue PodGroup to 0 Queues
I0714 05:43:30.374937       1 allocate.go:64] Try to allocate resource to 0 Queues
I0714 05:43:30.375153       1 session.go:244] Close Session 7a633edc-017f-4a58-a558-ecbd38d0ac45
I0714 05:43:31.377956       1 cache.go:1363] There are <0> Jobs, <1> Queues and <5> Nodes in total for scheduling.
I0714 05:43:31.378144       1 session.go:190] Open Session b3249057-a6e5-48ff-b815-00f1ecfa4cbb with <0> Job and <1> Queues
I0714 05:43:31.379911       1 enqueue.go:79] Try to enqueue PodGroup to 0 Queues
I0714 05:43:31.379980       1 allocate.go:64] Try to allocate resource to 0 Queues
I0714 05:43:31.380184       1 session.go:244] Close Session b3249057-a6e5-48ff-b815-00f1ecfa4cbb
I0714 05:43:32.382821       1 cache.go:1363] There are <0> Jobs, <1> Queues and <5> Nodes in total for scheduling.
I0714 05:43:32.382979       1 session.go:190] Open Session 67732241-2236-4e2d-8732-229e6f4d4187 with <0> Job and <1> Queues
I0714 05:43:32.384709       1 enqueue.go:79] Try to enqueue PodGroup to 0 Queues
I0714 05:43:32.384772       1 allocate.go:64] Try to allocate resource to 0 Queues
I0714 05:43:32.384970       1 session.go:244] Close Session 67732241-2236-4e2d-8732-229e6f4d4187
I0714 05:43:33.387560       1 cache.go:1363] There are <0> Jobs, <1> Queues and <5> Nodes in total for scheduling.
I0714 05:43:33.387748       1 session.go:190] Open Session 1004f320-b2f8-423c-a693-b6d2e8ce60ea with <0> Job and <1> Queues
I0714 05:43:33.389665       1 enqueue.go:79] Try to enqueue PodGroup to 0 Queues
I0714 05:43:33.389750       1 allocate.go:64] Try to allocate resource to 0 Queues
I0714 05:43:33.389972       1 session.go:244] Close Session 1004f320-b2f8-423c-a693-b6d2e8ce60ea
I0714 05:43:34.392799       1 cache.go:1363] There are <0> Jobs, <1> Queues and <5> Nodes in total for scheduling.
I0714 05:43:34.392962       1 session.go:190] Open Session 9db489ab-8684-41e2-9f32-8c179c3c9998 with <0> Job and <1> Queues
I0714 05:43:34.394671       1 enqueue.go:79] Try to enqueue PodGroup to 0 Queues
I0714 05:43:34.394745       1 allocate.go:64] Try to allocate resource to 0 Queues
I0714 05:43:34.394949       1 session.go:244] Close Session 9db489ab-8684-41e2-9f32-8c179c3c9998
I0714 05:43:35.397565       1 cache.go:1363] There are <0> Jobs, <1> Queues and <5> Nodes in total for scheduling.
I0714 05:43:35.397723       1 session.go:190] Open Session 0a8a90f6-a8c3-4acf-8799-18b14e1fad37 with <0> Job and <1> Queues
I0714 05:43:35.399429       1 enqueue.go:79] Try to enqueue PodGroup to 0 Queues
I0714 05:43:35.399493       1 allocate.go:64] Try to allocate resource to 0 Queues
I0714 05:43:35.399705       1 session.go:244] Close Session 0a8a90f6-a8c3-4acf-8799-18b14e1fad37
I0714 05:43:36.295108       1 cache.go:1489] The metrics type is not set in the volcano scheduler configmap file. As a result, the CPU and memory load information of the node is not collected.
I0714 05:43:36.401833       1 cache.go:1363] There are <0> Jobs, <1> Queues and <5> Nodes in total for scheduling.
I0714 05:43:36.401976       1 session.go:190] Open Session b7806aae-0a21-44dc-a674-b9d9810546d3 with <0> Job and <1> Queues
I0714 05:43:36.403711       1 enqueue.go:79] Try to enqueue PodGroup to 0 Queues
I0714 05:43:36.403782       1 allocate.go:64] Try to allocate resource to 0 Queues
I0714 05:43:36.404009       1 session.go:244] Close Session b7806aae-0a21-44dc-a674-b9d9810546d3
I0714 05:43:37.406227       1 cache.go:1363] There are <0> Jobs, <1> Queues and <5> Nodes in total for scheduling.
I0714 05:43:37.406394       1 session.go:190] Open Session 7d64da26-0644-4674-b354-e61f0d0cc6ce with <0> Job and <1> Queues
I0714 05:43:37.408078       1 enqueue.go:79] Try to enqueue PodGroup to 0 Queues
I0714 05:43:37.408144       1 allocate.go:64] Try to allocate resource to 0 Queues
I0714 05:43:37.408418       1 session.go:244] Close Session 7d64da26-0644-4674-b354-e61f0d0cc6ce
I0714 05:43:38.410697       1 cache.go:1363] There are <0> Jobs, <1> Queues and <5> Nodes in total for scheduling.
I0714 05:43:38.410887       1 session.go:190] Open Session 8ca6adf1-e2dc-4b45-a6b2-63a8d5da62d1 with <0> Job and <1> Queues
I0714 05:43:38.412685       1 enqueue.go:79] Try to enqueue PodGroup to 0 Queues
I0714 05:43:38.412759       1 allocate.go:64] Try to allocate resource to 0 Queues
I0714 05:43:38.412989       1 session.go:244] Close Session 8ca6adf1-e2dc-4b45-a6b2-63a8d5da62d1
I0714 05:43:39.413998       1 cache.go:1363] There are <0> Jobs, <1> Queues and <5> Nodes in total for scheduling.
I0714 05:43:39.414090       1 session.go:190] Open Session c44211d1-8e72-4349-bb54-a75dfc00f68c with <0> Job and <1> Queues
I0714 05:43:39.414983       1 enqueue.go:79] Try to enqueue PodGroup to 0 Queues
I0714 05:43:39.415034       1 allocate.go:64] Try to allocate resource to 0 Queues
I0714 05:43:39.415139       1 session.go:244] Close Session c44211d1-8e72-4349-bb54-a75dfc00f68c
I0714 05:43:40.424637       1 cache.go:1363] There are <0> Jobs, <1> Queues and <5> Nodes in total for scheduling.
I0714 05:43:40.424916       1 session.go:190] Open Session 502adbaf-2c10-47fa-8b59-091cadeffe22 with <0> Job and <1> Queues
I0714 05:43:40.427093       1 enqueue.go:79] Try to enqueue PodGroup to 0 Queues
I0714 05:43:40.427169       1 allocate.go:64] Try to allocate resource to 0 Queues
I0714 05:43:40.427367       1 session.go:244] Close Session 502adbaf-2c10-47fa-8b59-091cadeffe22
I0714 05:43:41.430207       1 cache.go:1363] There are <0> Jobs, <1> Queues and <5> Nodes in total for scheduling.
I0714 05:43:41.430408       1 session.go:190] Open Session cd08ff0f-646e-4eab-addd-0423474a28fe with <0> Job and <1> Queues
I0714 05:43:41.432259       1 enqueue.go:79] Try to enqueue PodGroup to 0 Queues
I0714 05:43:41.432382       1 allocate.go:64] Try to allocate resource to 0 Queues
I0714 05:43:41.432604       1 session.go:244] Close Session cd08ff0f-646e-4eab-addd-0423474a28fe
I0714 05:43:42.435406       1 cache.go:1363] There are <0> Jobs, <1> Queues and <5> Nodes in total for scheduling.
I0714 05:43:42.435543       1 session.go:190] Open Session 7acd4e47-8a61-4a70-8605-4fc87408f798 with <0> Job and <1> Queues
I0714 05:43:42.437297       1 enqueue.go:79] Try to enqueue PodGroup to 0 Queues
I0714 05:43:42.437365       1 allocate.go:64] Try to allocate resource to 0 Queues
I0714 05:43:42.437561       1 session.go:244] Close Session 7acd4e47-8a61-4a70-8605-4fc87408f798
I0714 05:43:43.439661       1 cache.go:1363] There are <0> Jobs, <1> Queues and <5> Nodes in total for scheduling.
I0714 05:43:43.439823       1 session.go:190] Open Session 8129e68c-7b9f-4ad9-a440-ca8c3861e443 with <0> Job and <1> Queues
I0714 05:43:43.441586       1 enqueue.go:79] Try to enqueue PodGroup to 0 Queues
I0714 05:43:43.441655       1 allocate.go:64] Try to allocate resource to 0 Queues
I0714 05:43:43.441860       1 session.go:244] Close Session 8129e68c-7b9f-4ad9-a440-ca8c3861e443
I0714 05:43:44.444530       1 cache.go:1363] There are <0> Jobs, <1> Queues and <5> Nodes in total for scheduling.
I0714 05:43:44.444682       1 session.go:190] Open Session 47d95414-3397-41a4-92a1-244f07155a8b with <0> Job and <1> Queues
I0714 05:43:44.446582       1 enqueue.go:79] Try to enqueue PodGroup to 0 Queues
I0714 05:43:44.446651       1 allocate.go:64] Try to allocate resource to 0 Queues
I0714 05:43:44.446847       1 session.go:244] Close Session 47d95414-3397-41a4-92a1-244f07155a8b
I0714 05:43:45.449444       1 cache.go:1363] There are <0> Jobs, <1> Queues and <5> Nodes in total for scheduling.
I0714 05:43:45.449608       1 session.go:190] Open Session 3b8b351b-3a64-49b2-84e6-f03bfccb020e with <0> Job and <1> Queues
I0714 05:43:45.451312       1 enqueue.go:79] Try to enqueue PodGroup to 0 Queues
I0714 05:43:45.451386       1 allocate.go:64] Try to allocate resource to 0 Queues
I0714 05:43:45.451596       1 session.go:244] Close Session 3b8b351b-3a64-49b2-84e6-f03bfccb020e
I0714 05:43:46.453704       1 cache.go:1363] There are <0> Jobs, <1> Queues and <5> Nodes in total for scheduling.
I0714 05:43:46.453874       1 session.go:190] Open Session eb4703a3-bc70-415b-96b9-895852c2277e with <0> Job and <1> Queues
I0714 05:43:46.455720       1 enqueue.go:79] Try to enqueue PodGroup to 0 Queues
I0714 05:43:46.455790       1 allocate.go:64] Try to allocate resource to 0 Queues
I0714 05:43:46.456004       1 session.go:244] Close Session eb4703a3-bc70-415b-96b9-895852c2277e
I0714 05:43:47.458856       1 cache.go:1363] There are <0> Jobs, <1> Queues and <5> Nodes in total for scheduling.
I0714 05:43:47.459000       1 session.go:190] Open Session fa8c1837-9526-42d7-a99a-c8e3102b023e with <0> Job and <1> Queues
I0714 05:43:47.460727       1 enqueue.go:79] Try to enqueue PodGroup to 0 Queues
I0714 05:43:47.460798       1 allocate.go:64] Try to allocate resource to 0 Queues
I0714 05:43:47.461006       1 session.go:244] Close Session fa8c1837-9526-42d7-a99a-c8e3102b023e
I0714 05:43:48.463713       1 cache.go:1363] There are <0> Jobs, <1> Queues and <5> Nodes in total for scheduling.
I0714 05:43:48.463914       1 session.go:190] Open Session 250315d9-ea79-4ada-ad0f-d4a995dc91ef with <0> Job and <1> Queues
I0714 05:43:48.465787       1 enqueue.go:79] Try to enqueue PodGroup to 0 Queues
I0714 05:43:48.465875       1 allocate.go:64] Try to allocate resource to 0 Queues
I0714 05:43:48.466085       1 session.go:244] Close Session 250315d9-ea79-4ada-ad0f-d4a995dc91ef
I0714 05:43:49.468348       1 cache.go:1363] There are <0> Jobs, <1> Queues and <5> Nodes in total for scheduling.
I0714 05:43:49.468525       1 session.go:190] Open Session 3f7fd599-f1da-4bc5-a386-feb22f15a395 with <0> Job and <1> Queues
I0714 05:43:49.470391       1 enqueue.go:79] Try to enqueue PodGroup to 0 Queues
I0714 05:43:49.470468       1 allocate.go:64] Try to allocate resource to 0 Queues
I0714 05:43:49.470689       1 session.go:244] Close Session 3f7fd599-f1da-4bc5-a386-feb22f15a395
I0714 05:43:50.473463       1 cache.go:1363] There are <0> Jobs, <1> Queues and <5> Nodes in total for scheduling.
I0714 05:43:50.473631       1 session.go:190] Open Session 671304de-5d16-4a9e-bfe2-d41d9de7a6ab with <0> Job and <1> Queues
I0714 05:43:50.475416       1 enqueue.go:79] Try to enqueue PodGroup to 0 Queues
I0714 05:43:50.475484       1 allocate.go:64] Try to allocate resource to 0 Queues
I0714 05:43:50.475701       1 session.go:244] Close Session 671304de-5d16-4a9e-bfe2-d41d9de7a6ab
I0714 05:43:51.478633       1 cache.go:1363] There are <0> Jobs, <1> Queues and <5> Nodes in total for scheduling.
I0714 05:43:51.478811       1 session.go:190] Open Session 183953bf-cdd6-40b8-8aae-177ade38835c with <0> Job and <1> Queues
I0714 05:43:51.480674       1 enqueue.go:79] Try to enqueue PodGroup to 0 Queues
I0714 05:43:51.480744       1 allocate.go:64] Try to allocate resource to 0 Queues
I0714 05:43:51.480948       1 session.go:244] Close Session 183953bf-cdd6-40b8-8aae-177ade38835c
I0714 05:43:52.483481       1 cache.go:1363] There are <0> Jobs, <1> Queues and <5> Nodes in total for scheduling.
I0714 05:43:52.483653       1 session.go:190] Open Session aef72a8e-6992-4d10-88c4-c3d5deff3f28 with <0> Job and <1> Queues
I0714 05:43:52.485581       1 enqueue.go:79] Try to enqueue PodGroup to 0 Queues
I0714 05:43:52.485650       1 allocate.go:64] Try to allocate resource to 0 Queues
I0714 05:43:52.485862       1 session.go:244] Close Session aef72a8e-6992-4d10-88c4-c3d5deff3f28
I0714 05:43:53.488226       1 cache.go:1363] There are <0> Jobs, <1> Queues and <5> Nodes in total for scheduling.
I0714 05:43:53.488431       1 session.go:190] Open Session 41dc14db-95dd-4c87-a65b-17a9047e35ff with <0> Job and <1> Queues
I0714 05:43:53.490164       1 enqueue.go:79] Try to enqueue PodGroup to 0 Queues
I0714 05:43:53.490232       1 allocate.go:64] Try to allocate resource to 0 Queues
I0714 05:43:53.490446       1 session.go:244] Close Session 41dc14db-95dd-4c87-a65b-17a9047e35ff
I0714 05:43:54.492707       1 cache.go:1363] There are <0> Jobs, <1> Queues and <5> Nodes in total for scheduling.
I0714 05:43:54.492890       1 session.go:190] Open Session f65b4d56-5fa1-4bad-871f-9aa30fca0dc1 with <0> Job and <1> Queues
I0714 05:43:54.494691       1 enqueue.go:79] Try to enqueue PodGroup to 0 Queues
I0714 05:43:54.494761       1 allocate.go:64] Try to allocate resource to 0 Queues
I0714 05:43:54.494995       1 session.go:244] Close Session f65b4d56-5fa1-4bad-871f-9aa30fca0dc1
I0714 05:43:55.497107       1 cache.go:1363] There are <0> Jobs, <1> Queues and <5> Nodes in total for scheduling.
I0714 05:43:55.497282       1 session.go:190] Open Session 6c297bad-7428-436b-a064-c8c3a3193470 with <0> Job and <1> Queues
I0714 05:43:55.498983       1 enqueue.go:79] Try to enqueue PodGroup to 0 Queues
I0714 05:43:55.499051       1 allocate.go:64] Try to allocate resource to 0 Queues
I0714 05:43:55.499274       1 session.go:244] Close Session 6c297bad-7428-436b-a064-c8c3a3193470
I0714 05:43:56.501502       1 cache.go:1363] There are <0> Jobs, <1> Queues and <5> Nodes in total for scheduling.
I0714 05:43:56.501684       1 session.go:190] Open Session 678bf0e3-7f09-4d34-a631-4a2bca36490a with <0> Job and <1> Queues
I0714 05:43:56.503619       1 enqueue.go:79] Try to enqueue PodGroup to 0 Queues
I0714 05:43:56.503694       1 allocate.go:64] Try to allocate resource to 0 Queues
I0714 05:43:56.503900       1 session.go:244] Close Session 678bf0e3-7f09-4d34-a631-4a2bca36490a
I0714 05:43:57.506415       1 cache.go:1363] There are <0> Jobs, <1> Queues and <5> Nodes in total for scheduling.
I0714 05:43:57.506579       1 session.go:190] Open Session e898ec98-8b3e-4022-9b3e-bc1cfd0907b4 with <0> Job and <1> Queues
I0714 05:43:57.508372       1 enqueue.go:79] Try to enqueue PodGroup to 0 Queues
I0714 05:43:57.508442       1 allocate.go:64] Try to allocate resource to 0 Queues
I0714 05:43:57.508660       1 session.go:244] Close Session e898ec98-8b3e-4022-9b3e-bc1cfd0907b4
I0714 05:43:58.510862       1 cache.go:1363] There are <0> Jobs, <1> Queues and <5> Nodes in total for scheduling.
I0714 05:43:58.511029       1 session.go:190] Open Session 99fc5729-257f-41bc-8fa8-27bbffd7edfb with <0> Job and <1> Queues
I0714 05:43:58.512970       1 enqueue.go:79] Try to enqueue PodGroup to 0 Queues
I0714 05:43:58.513044       1 allocate.go:64] Try to allocate resource to 0 Queues
I0714 05:43:58.513264       1 session.go:244] Close Session 99fc5729-257f-41bc-8fa8-27bbffd7edfb
I0714 05:43:59.515989       1 cache.go:1363] There are <0> Jobs, <1> Queues and <5> Nodes in total for scheduling.
I0714 05:43:59.516168       1 session.go:190] Open Session 8e95bf51-afba-488b-b236-64538edd8d82 with <0> Job and <1> Queues
I0714 05:43:59.518061       1 enqueue.go:79] Try to enqueue PodGroup to 0 Queues
I0714 05:43:59.518134       1 allocate.go:64] Try to allocate resource to 0 Queues
I0714 05:43:59.518363       1 session.go:244] Close Session 8e95bf51-afba-488b-b236-64538edd8d82
I0714 05:44:00.521280       1 cache.go:1363] There are <0> Jobs, <1> Queues and <5> Nodes in total for scheduling.
I0714 05:44:00.521435       1 session.go:190] Open Session a7d6a9d4-90d6-466e-b5be-e8b127e2dee0 with <0> Job and <1> Queues
I0714 05:44:00.523335       1 enqueue.go:79] Try to enqueue PodGroup to 0 Queues
I0714 05:44:00.523395       1 allocate.go:64] Try to allocate resource to 0 Queues
I0714 05:44:00.523597       1 session.go:244] Close Session a7d6a9d4-90d6-466e-b5be-e8b127e2dee0
I0714 05:44:01.526179       1 cache.go:1363] There are <0> Jobs, <1> Queues and <5> Nodes in total for scheduling.
I0714 05:44:01.526376       1 session.go:190] Open Session ce113124-7b2e-41fc-b676-ce96111941d9 with <0> Job and <1> Queues
I0714 05:44:01.528653       1 enqueue.go:79] Try to enqueue PodGroup to 0 Queues
I0714 05:44:01.528734       1 allocate.go:64] Try to allocate resource to 0 Queues
I0714 05:44:01.528954       1 session.go:244] Close Session ce113124-7b2e-41fc-b676-ce96111941d9
I0714 05:44:02.531349       1 cache.go:1363] There are <0> Jobs, <1> Queues and <5> Nodes in total for scheduling.
I0714 05:44:02.531532       1 session.go:190] Open Session cbce0e83-42d9-489e-8e64-be35c6fe564a with <0> Job and <1> Queues
I0714 05:44:02.533299       1 enqueue.go:79] Try to enqueue PodGroup to 0 Queues
I0714 05:44:02.533372       1 allocate.go:64] Try to allocate resource to 0 Queues
I0714 05:44:02.533598       1 session.go:244] Close Session cbce0e83-42d9-489e-8e64-be35c6fe564a
I0714 05:44:03.535614       1 cache.go:1363] There are <0> Jobs, <1> Queues and <5> Nodes in total for scheduling.
I0714 05:44:03.535798       1 session.go:190] Open Session 92b06b74-c565-48e6-91bb-b1d5f99c1f72 with <0> Job and <1> Queues
I0714 05:44:03.537633       1 enqueue.go:79] Try to enqueue PodGroup to 0 Queues
I0714 05:44:03.537705       1 allocate.go:64] Try to allocate resource to 0 Queues
I0714 05:44:03.537906       1 session.go:244] Close Session 92b06b74-c565-48e6-91bb-b1d5f99c1f72
I0714 05:44:04.540227       1 cache.go:1363] There are <0> Jobs, <1> Queues and <5> Nodes in total for scheduling.
I0714 05:44:04.540448       1 session.go:190] Open Session c9815fad-9b36-4706-bd40-ac42afa435be with <0> Job and <1> Queues
I0714 05:44:04.542337       1 enqueue.go:79] Try to enqueue PodGroup to 0 Queues
I0714 05:44:04.542405       1 allocate.go:64] Try to allocate resource to 0 Queues
I0714 05:44:04.542624       1 session.go:244] Close Session c9815fad-9b36-4706-bd40-ac42afa435be
I0714 05:44:05.544863       1 cache.go:1363] There are <0> Jobs, <1> Queues and <5> Nodes in total for scheduling.
I0714 05:44:05.545069       1 session.go:190] Open Session 5c714227-dc2c-4f23-a14f-dd8e047f3ef8 with <0> Job and <1> Queues
I0714 05:44:05.546816       1 enqueue.go:79] Try to enqueue PodGroup to 0 Queues
I0714 05:44:05.546893       1 allocate.go:64] Try to allocate resource to 0 Queues
I0714 05:44:05.547127       1 session.go:244] Close Session 5c714227-dc2c-4f23-a14f-dd8e047f3ef8
I0714 05:44:06.296440       1 cache.go:1489] The metrics type is not set in the volcano scheduler configmap file. As a result, the CPU and memory load information of the node is not collected.
I0714 05:44:06.549503       1 cache.go:1363] There are <0> Jobs, <1> Queues and <5> Nodes in total for scheduling.
I0714 05:44:06.549667       1 session.go:190] Open Session be2e1d5c-bff5-48c5-96e4-e36982d2cff7 with <0> Job and <1> Queues
I0714 05:44:06.551440       1 enqueue.go:79] Try to enqueue PodGroup to 0 Queues
I0714 05:44:06.551509       1 allocate.go:64] Try to allocate resource to 0 Queues
I0714 05:44:06.551742       1 session.go:244] Close Session be2e1d5c-bff5-48c5-96e4-e36982d2cff7
I0714 05:44:07.553688       1 cache.go:1363] There are <0> Jobs, <1> Queues and <5> Nodes in total for scheduling.
I0714 05:44:07.553857       1 session.go:190] Open Session d2733a18-2845-42c2-9dfc-849646a3124f with <0> Job and <1> Queues
I0714 05:44:07.555562       1 enqueue.go:79] Try to enqueue PodGroup to 0 Queues
I0714 05:44:07.555629       1 allocate.go:64] Try to allocate resource to 0 Queues
I0714 05:44:07.555858       1 session.go:244] Close Session d2733a18-2845-42c2-9dfc-849646a3124f
I0714 05:44:08.558787       1 cache.go:1363] There are <0> Jobs, <1> Queues and <5> Nodes in total for scheduling.
I0714 05:44:08.558976       1 session.go:190] Open Session 87836e23-8a0a-42f3-95d8-ca55f13d2c01 with <0> Job and <1> Queues
I0714 05:44:08.560842       1 enqueue.go:79] Try to enqueue PodGroup to 0 Queues
I0714 05:44:08.560916       1 allocate.go:64] Try to allocate resource to 0 Queues
I0714 05:44:08.561152       1 session.go:244] Close Session 87836e23-8a0a-42f3-95d8-ca55f13d2c01
I0714 05:44:09.563513       1 cache.go:1363] There are <0> Jobs, <1> Queues and <5> Nodes in total for scheduling.
I0714 05:44:09.563675       1 session.go:190] Open Session c8b80207-9a99-448b-8c0a-bf6295ed5731 with <0> Job and <1> Queues
I0714 05:44:09.565525       1 enqueue.go:79] Try to enqueue PodGroup to 0 Queues
I0714 05:44:09.565599       1 allocate.go:64] Try to allocate resource to 0 Queues
I0714 05:44:09.565811       1 session.go:244] Close Session c8b80207-9a99-448b-8c0a-bf6295ed5731
I0714 05:44:10.567982       1 cache.go:1363] There are <0> Jobs, <1> Queues and <5> Nodes in total for scheduling.
I0714 05:44:10.568142       1 session.go:190] Open Session 30fea27c-ef59-4b08-bdb3-102877bbdd21 with <0> Job and <1> Queues
I0714 05:44:10.569927       1 enqueue.go:79] Try to enqueue PodGroup to 0 Queues
I0714 05:44:10.569996       1 allocate.go:64] Try to allocate resource to 0 Queues
I0714 05:44:10.570220       1 session.go:244] Close Session 30fea27c-ef59-4b08-bdb3-102877bbdd21
I0714 05:44:11.573125       1 cache.go:1363] There are <0> Jobs, <1> Queues and <5> Nodes in total for scheduling.
I0714 05:44:11.573303       1 session.go:190] Open Session 979e2414-8c66-4596-ad6a-f30695a57b2e with <0> Job and <1> Queues
I0714 05:44:11.575049       1 enqueue.go:79] Try to enqueue PodGroup to 0 Queues
I0714 05:44:11.575123       1 allocate.go:64] Try to allocate resource to 0 Queues
I0714 05:44:11.575345       1 session.go:244] Close Session 979e2414-8c66-4596-ad6a-f30695a57b2e
I0714 05:44:12.577548       1 cache.go:1363] There are <0> Jobs, <1> Queues and <5> Nodes in total for scheduling.
I0714 05:44:12.577713       1 session.go:190] Open Session 1ede8d30-a016-40d4-a016-049c044fc619 with <0> Job and <1> Queues
I0714 05:44:12.579410       1 enqueue.go:79] Try to enqueue PodGroup to 0 Queues
I0714 05:44:12.579481       1 allocate.go:64] Try to allocate resource to 0 Queues
I0714 05:44:12.579708       1 session.go:244] Close Session 1ede8d30-a016-40d4-a016-049c044fc619
I0714 05:44:13.582321       1 cache.go:1363] There are <0> Jobs, <1> Queues and <5> Nodes in total for scheduling.
I0714 05:44:13.582488       1 session.go:190] Open Session e1fe1172-0512-4139-bfc9-e943d6b774f1 with <0> Job and <1> Queues
I0714 05:44:13.584371       1 enqueue.go:79] Try to enqueue PodGroup to 0 Queues
I0714 05:44:13.584445       1 allocate.go:64] Try to allocate resource to 0 Queues
I0714 05:44:13.584675       1 session.go:244] Close Session e1fe1172-0512-4139-bfc9-e943d6b774f1
I0714 05:44:14.587358       1 cache.go:1363] There are <0> Jobs, <1> Queues and <5> Nodes in total for scheduling.
I0714 05:44:14.587520       1 session.go:190] Open Session f6eff595-daba-40da-9d29-7f2656b0be87 with <0> Job and <1> Queues
I0714 05:44:14.589266       1 enqueue.go:79] Try to enqueue PodGroup to 0 Queues
I0714 05:44:14.589342       1 allocate.go:64] Try to allocate resource to 0 Queues
I0714 05:44:14.589680       1 session.go:244] Close Session f6eff595-daba-40da-9d29-7f2656b0be87
I0714 05:44:15.592392       1 cache.go:1363] There are <0> Jobs, <1> Queues and <5> Nodes in total for scheduling.
I0714 05:44:15.592553       1 session.go:190] Open Session e52640a1-cda9-4695-bfb7-ef274572a291 with <0> Job and <1> Queues
