I0714 09:18:37.889722       1 cache.go:1363] There are <0> Jobs, <1> Queues and <5> Nodes in total for scheduling.
I0714 09:18:37.889922       1 session.go:190] Open Session 42388694-3ba1-422e-b01d-1c216c90bde0 with <0> Job and <1> Queues
I0714 09:18:37.891751       1 enqueue.go:79] Try to enqueue PodGroup to 0 Queues
I0714 09:18:37.891826       1 allocate.go:64] Try to allocate resource to 0 Queues
I0714 09:18:37.892059       1 session.go:244] Close Session 42388694-3ba1-422e-b01d-1c216c90bde0
I0714 09:18:38.894116       1 cache.go:1363] There are <0> Jobs, <1> Queues and <5> Nodes in total for scheduling.
I0714 09:18:38.894281       1 session.go:190] Open Session 65632b05-80f5-4529-a16f-189ff8158204 with <0> Job and <1> Queues
I0714 09:18:38.896081       1 enqueue.go:79] Try to enqueue PodGroup to 0 Queues
I0714 09:18:38.896147       1 allocate.go:64] Try to allocate resource to 0 Queues
I0714 09:18:38.896384       1 session.go:244] Close Session 65632b05-80f5-4529-a16f-189ff8158204
I0714 09:18:39.898815       1 cache.go:1363] There are <0> Jobs, <1> Queues and <5> Nodes in total for scheduling.
I0714 09:18:39.898978       1 session.go:190] Open Session df6392f1-2c1d-4a05-91c3-ed980b262fa2 with <0> Job and <1> Queues
I0714 09:18:39.900821       1 enqueue.go:79] Try to enqueue PodGroup to 0 Queues
I0714 09:18:39.900886       1 allocate.go:64] Try to allocate resource to 0 Queues
I0714 09:18:39.901085       1 session.go:244] Close Session df6392f1-2c1d-4a05-91c3-ed980b262fa2
I0714 09:18:40.903762       1 cache.go:1363] There are <0> Jobs, <1> Queues and <5> Nodes in total for scheduling.
I0714 09:18:40.903911       1 session.go:190] Open Session 03922ec3-3b53-4c62-a51f-c5263493e7d3 with <0> Job and <1> Queues
I0714 09:18:40.905728       1 enqueue.go:79] Try to enqueue PodGroup to 0 Queues
I0714 09:18:40.905794       1 allocate.go:64] Try to allocate resource to 0 Queues
I0714 09:18:40.906012       1 session.go:244] Close Session 03922ec3-3b53-4c62-a51f-c5263493e7d3
I0714 09:18:41.908745       1 cache.go:1363] There are <0> Jobs, <1> Queues and <5> Nodes in total for scheduling.
I0714 09:18:41.908878       1 session.go:190] Open Session 6046354f-8c3f-4f6a-9711-703485625faa with <0> Job and <1> Queues
I0714 09:18:41.910495       1 enqueue.go:79] Try to enqueue PodGroup to 0 Queues
I0714 09:18:41.910561       1 allocate.go:64] Try to allocate resource to 0 Queues
I0714 09:18:41.910761       1 session.go:244] Close Session 6046354f-8c3f-4f6a-9711-703485625faa
I0714 09:18:42.913023       1 cache.go:1363] There are <0> Jobs, <1> Queues and <5> Nodes in total for scheduling.
I0714 09:18:42.913186       1 session.go:190] Open Session 120b6dbd-ebae-4291-8853-61b4cf6f69c5 with <0> Job and <1> Queues
I0714 09:18:42.914980       1 enqueue.go:79] Try to enqueue PodGroup to 0 Queues
I0714 09:18:42.915053       1 allocate.go:64] Try to allocate resource to 0 Queues
I0714 09:18:42.915254       1 session.go:244] Close Session 120b6dbd-ebae-4291-8853-61b4cf6f69c5
I0714 09:18:43.917473       1 cache.go:1363] There are <0> Jobs, <1> Queues and <5> Nodes in total for scheduling.
I0714 09:18:43.917642       1 session.go:190] Open Session 3615a1a7-9080-4d8e-bd6b-661e8903cca3 with <0> Job and <1> Queues
I0714 09:18:43.919329       1 enqueue.go:79] Try to enqueue PodGroup to 0 Queues
I0714 09:18:43.919390       1 allocate.go:64] Try to allocate resource to 0 Queues
I0714 09:18:43.919597       1 session.go:244] Close Session 3615a1a7-9080-4d8e-bd6b-661e8903cca3
I0714 09:18:44.922182       1 cache.go:1363] There are <0> Jobs, <1> Queues and <5> Nodes in total for scheduling.
I0714 09:18:44.922338       1 session.go:190] Open Session 2c652586-a83d-4a10-a4c2-e547e97d5eb1 with <0> Job and <1> Queues
I0714 09:18:44.924168       1 enqueue.go:79] Try to enqueue PodGroup to 0 Queues
I0714 09:18:44.924375       1 allocate.go:64] Try to allocate resource to 0 Queues
I0714 09:18:44.924593       1 session.go:244] Close Session 2c652586-a83d-4a10-a4c2-e547e97d5eb1
I0714 09:18:45.927018       1 cache.go:1363] There are <0> Jobs, <1> Queues and <5> Nodes in total for scheduling.
I0714 09:18:45.927195       1 session.go:190] Open Session fa033bcb-2dd9-4c0d-a45e-2c9a16631193 with <0> Job and <1> Queues
I0714 09:18:45.929215       1 enqueue.go:79] Try to enqueue PodGroup to 0 Queues
I0714 09:18:45.929287       1 allocate.go:64] Try to allocate resource to 0 Queues
I0714 09:18:45.929510       1 session.go:244] Close Session fa033bcb-2dd9-4c0d-a45e-2c9a16631193
I0714 09:18:46.932412       1 cache.go:1363] There are <0> Jobs, <1> Queues and <5> Nodes in total for scheduling.
I0714 09:18:46.932590       1 session.go:190] Open Session 4826ea5f-a935-494c-b762-8b3fbedefb1b with <0> Job and <1> Queues
I0714 09:18:46.934496       1 enqueue.go:79] Try to enqueue PodGroup to 0 Queues
I0714 09:18:46.934577       1 allocate.go:64] Try to allocate resource to 0 Queues
I0714 09:18:46.934800       1 session.go:244] Close Session 4826ea5f-a935-494c-b762-8b3fbedefb1b
I0714 09:18:47.937903       1 cache.go:1363] There are <0> Jobs, <1> Queues and <5> Nodes in total for scheduling.
I0714 09:18:47.938106       1 session.go:190] Open Session 8753e053-b08c-4be0-87a2-2e67ae1a2acc with <0> Job and <1> Queues
I0714 09:18:47.939863       1 enqueue.go:79] Try to enqueue PodGroup to 0 Queues
I0714 09:18:47.939937       1 allocate.go:64] Try to allocate resource to 0 Queues
I0714 09:18:47.940177       1 session.go:244] Close Session 8753e053-b08c-4be0-87a2-2e67ae1a2acc
I0714 09:18:48.942410       1 cache.go:1363] There are <0> Jobs, <1> Queues and <5> Nodes in total for scheduling.
I0714 09:18:48.942585       1 session.go:190] Open Session c44c1f10-e330-4643-8d63-88423322b9c2 with <0> Job and <1> Queues
I0714 09:18:48.944429       1 enqueue.go:79] Try to enqueue PodGroup to 0 Queues
I0714 09:18:48.944499       1 allocate.go:64] Try to allocate resource to 0 Queues
I0714 09:18:48.944724       1 session.go:244] Close Session c44c1f10-e330-4643-8d63-88423322b9c2
I0714 09:18:49.946744       1 cache.go:1363] There are <0> Jobs, <1> Queues and <5> Nodes in total for scheduling.
I0714 09:18:49.946914       1 session.go:190] Open Session d4c2f592-287b-4828-84a5-246e153b438d with <0> Job and <1> Queues
I0714 09:18:49.948943       1 enqueue.go:79] Try to enqueue PodGroup to 0 Queues
I0714 09:18:49.949020       1 allocate.go:64] Try to allocate resource to 0 Queues
I0714 09:18:49.949238       1 session.go:244] Close Session d4c2f592-287b-4828-84a5-246e153b438d
I0714 09:18:50.951888       1 cache.go:1363] There are <0> Jobs, <1> Queues and <5> Nodes in total for scheduling.
I0714 09:18:50.952052       1 session.go:190] Open Session d4cc7916-6d61-4bde-ba78-ea30c4ee00fe with <0> Job and <1> Queues
I0714 09:18:50.953853       1 enqueue.go:79] Try to enqueue PodGroup to 0 Queues
I0714 09:18:50.953926       1 allocate.go:64] Try to allocate resource to 0 Queues
I0714 09:18:50.954146       1 session.go:244] Close Session d4cc7916-6d61-4bde-ba78-ea30c4ee00fe
I0714 09:18:51.956874       1 cache.go:1363] There are <0> Jobs, <1> Queues and <5> Nodes in total for scheduling.
I0714 09:18:51.957060       1 session.go:190] Open Session d46a7c2c-1f71-4253-843e-7883dbf0ae93 with <0> Job and <1> Queues
I0714 09:18:51.958774       1 enqueue.go:79] Try to enqueue PodGroup to 0 Queues
I0714 09:18:51.958846       1 allocate.go:64] Try to allocate resource to 0 Queues
I0714 09:18:51.959056       1 session.go:244] Close Session d46a7c2c-1f71-4253-843e-7883dbf0ae93
I0714 09:18:52.961749       1 cache.go:1363] There are <0> Jobs, <1> Queues and <5> Nodes in total for scheduling.
I0714 09:18:52.961930       1 session.go:190] Open Session 4c87d36c-7e9d-4261-8c9d-6eedcec39166 with <0> Job and <1> Queues
I0714 09:18:52.963820       1 enqueue.go:79] Try to enqueue PodGroup to 0 Queues
I0714 09:18:52.963896       1 allocate.go:64] Try to allocate resource to 0 Queues
I0714 09:18:52.964134       1 session.go:244] Close Session 4c87d36c-7e9d-4261-8c9d-6eedcec39166
I0714 09:18:53.967216       1 cache.go:1363] There are <0> Jobs, <1> Queues and <5> Nodes in total for scheduling.
I0714 09:18:53.967392       1 session.go:190] Open Session d7443534-3977-4176-a0c0-3dfc9604c7ca with <0> Job and <1> Queues
I0714 09:18:53.969125       1 enqueue.go:79] Try to enqueue PodGroup to 0 Queues
I0714 09:18:53.969199       1 allocate.go:64] Try to allocate resource to 0 Queues
I0714 09:18:53.969450       1 session.go:244] Close Session d7443534-3977-4176-a0c0-3dfc9604c7ca
I0714 09:18:54.972461       1 cache.go:1363] There are <0> Jobs, <1> Queues and <5> Nodes in total for scheduling.
I0714 09:18:54.972632       1 session.go:190] Open Session 5a4fcd63-5ca6-429d-bc77-97b2f27b8696 with <0> Job and <1> Queues
I0714 09:18:54.974456       1 enqueue.go:79] Try to enqueue PodGroup to 0 Queues
I0714 09:18:54.974531       1 allocate.go:64] Try to allocate resource to 0 Queues
I0714 09:18:54.974754       1 session.go:244] Close Session 5a4fcd63-5ca6-429d-bc77-97b2f27b8696
I0714 09:18:55.976817       1 cache.go:1363] There are <0> Jobs, <1> Queues and <5> Nodes in total for scheduling.
I0714 09:18:55.977092       1 session.go:190] Open Session 178d4a14-7516-4695-b683-39ba74f2a2d0 with <0> Job and <1> Queues
I0714 09:18:55.978842       1 enqueue.go:79] Try to enqueue PodGroup to 0 Queues
I0714 09:18:55.978913       1 allocate.go:64] Try to allocate resource to 0 Queues
I0714 09:18:55.979124       1 session.go:244] Close Session 178d4a14-7516-4695-b683-39ba74f2a2d0
I0714 09:18:56.981758       1 cache.go:1363] There are <0> Jobs, <1> Queues and <5> Nodes in total for scheduling.
I0714 09:18:56.981917       1 session.go:190] Open Session 0660df27-0460-4101-ab98-41bc6e45a1f0 with <0> Job and <1> Queues
I0714 09:18:56.983631       1 enqueue.go:79] Try to enqueue PodGroup to 0 Queues
I0714 09:18:56.983700       1 allocate.go:64] Try to allocate resource to 0 Queues
I0714 09:18:56.983919       1 session.go:244] Close Session 0660df27-0460-4101-ab98-41bc6e45a1f0
I0714 09:18:57.986101       1 cache.go:1363] There are <0> Jobs, <1> Queues and <5> Nodes in total for scheduling.
I0714 09:18:57.986312       1 session.go:190] Open Session 509b29b6-35a1-4f45-9ce3-69cfaa4fce15 with <0> Job and <1> Queues
I0714 09:18:57.988101       1 enqueue.go:79] Try to enqueue PodGroup to 0 Queues
I0714 09:18:57.988172       1 allocate.go:64] Try to allocate resource to 0 Queues
I0714 09:18:57.988421       1 session.go:244] Close Session 509b29b6-35a1-4f45-9ce3-69cfaa4fce15
I0714 09:18:58.991312       1 cache.go:1363] There are <0> Jobs, <1> Queues and <5> Nodes in total for scheduling.
I0714 09:18:58.991490       1 session.go:190] Open Session 75e6dd37-350c-4aee-91dd-4d942759bf61 with <0> Job and <1> Queues
I0714 09:18:58.993435       1 enqueue.go:79] Try to enqueue PodGroup to 0 Queues
I0714 09:18:58.993511       1 allocate.go:64] Try to allocate resource to 0 Queues
I0714 09:18:58.993732       1 session.go:244] Close Session 75e6dd37-350c-4aee-91dd-4d942759bf61
I0714 09:18:59.996282       1 cache.go:1363] There are <0> Jobs, <1> Queues and <5> Nodes in total for scheduling.
I0714 09:18:59.996484       1 session.go:190] Open Session 44d8be21-29fb-4b53-8016-a74e4cd95c2a with <0> Job and <1> Queues
I0714 09:18:59.998270       1 enqueue.go:79] Try to enqueue PodGroup to 0 Queues
I0714 09:18:59.998346       1 allocate.go:64] Try to allocate resource to 0 Queues
I0714 09:18:59.998560       1 session.go:244] Close Session 44d8be21-29fb-4b53-8016-a74e4cd95c2a
I0714 09:19:01.000847       1 cache.go:1363] There are <0> Jobs, <1> Queues and <5> Nodes in total for scheduling.
I0714 09:19:01.001013       1 session.go:190] Open Session 6082d382-9c4a-40c6-bc03-f2ea3c9a12c8 with <0> Job and <1> Queues
I0714 09:19:01.002886       1 enqueue.go:79] Try to enqueue PodGroup to 0 Queues
I0714 09:19:01.002957       1 allocate.go:64] Try to allocate resource to 0 Queues
I0714 09:19:01.003159       1 session.go:244] Close Session 6082d382-9c4a-40c6-bc03-f2ea3c9a12c8
I0714 09:19:02.005286       1 cache.go:1363] There are <0> Jobs, <1> Queues and <5> Nodes in total for scheduling.
I0714 09:19:02.005433       1 session.go:190] Open Session 647a860d-fa7c-43ce-a916-45f63f7e98ea with <0> Job and <1> Queues
I0714 09:19:02.007091       1 enqueue.go:79] Try to enqueue PodGroup to 0 Queues
I0714 09:19:02.007158       1 allocate.go:64] Try to allocate resource to 0 Queues
I0714 09:19:02.007371       1 session.go:244] Close Session 647a860d-fa7c-43ce-a916-45f63f7e98ea
I0714 09:19:03.009225       1 cache.go:1363] There are <0> Jobs, <1> Queues and <5> Nodes in total for scheduling.
I0714 09:19:03.009380       1 session.go:190] Open Session 71c146c4-482d-4e33-bef2-b318b021eaad with <0> Job and <1> Queues
I0714 09:19:03.011013       1 enqueue.go:79] Try to enqueue PodGroup to 0 Queues
I0714 09:19:03.011083       1 allocate.go:64] Try to allocate resource to 0 Queues
I0714 09:19:03.011283       1 session.go:244] Close Session 71c146c4-482d-4e33-bef2-b318b021eaad
I0714 09:19:04.014114       1 cache.go:1363] There are <0> Jobs, <1> Queues and <5> Nodes in total for scheduling.
I0714 09:19:04.014285       1 session.go:190] Open Session e76b3e95-54ee-438d-ad79-b56cc47be592 with <0> Job and <1> Queues
I0714 09:19:04.016060       1 enqueue.go:79] Try to enqueue PodGroup to 0 Queues
I0714 09:19:04.016141       1 allocate.go:64] Try to allocate resource to 0 Queues
I0714 09:19:04.016397       1 session.go:244] Close Session e76b3e95-54ee-438d-ad79-b56cc47be592
I0714 09:19:05.018815       1 cache.go:1363] There are <0> Jobs, <1> Queues and <5> Nodes in total for scheduling.
I0714 09:19:05.018994       1 session.go:190] Open Session 5a674dbb-360c-46bc-ab73-6b2c9e5c0814 with <0> Job and <1> Queues
I0714 09:19:05.020904       1 enqueue.go:79] Try to enqueue PodGroup to 0 Queues
I0714 09:19:05.020996       1 allocate.go:64] Try to allocate resource to 0 Queues
I0714 09:19:05.021232       1 session.go:244] Close Session 5a674dbb-360c-46bc-ab73-6b2c9e5c0814
I0714 09:19:06.024493       1 cache.go:1363] There are <0> Jobs, <1> Queues and <5> Nodes in total for scheduling.
I0714 09:19:06.024657       1 session.go:190] Open Session d85d288f-1b99-4b9f-9bf9-fe3fed157669 with <0> Job and <1> Queues
I0714 09:19:06.026375       1 enqueue.go:79] Try to enqueue PodGroup to 0 Queues
I0714 09:19:06.026452       1 allocate.go:64] Try to allocate resource to 0 Queues
I0714 09:19:06.026685       1 session.go:244] Close Session d85d288f-1b99-4b9f-9bf9-fe3fed157669
I0714 09:19:06.654937       1 cache.go:1489] The metrics type is not set in the volcano scheduler configmap file. As a result, the CPU and memory load information of the node is not collected.
I0714 09:19:07.029247       1 cache.go:1363] There are <0> Jobs, <1> Queues and <5> Nodes in total for scheduling.
I0714 09:19:07.029407       1 session.go:190] Open Session 799db198-939b-4b78-80b0-f3f5aafc2b08 with <0> Job and <1> Queues
I0714 09:19:07.031177       1 enqueue.go:79] Try to enqueue PodGroup to 0 Queues
I0714 09:19:07.031248       1 allocate.go:64] Try to allocate resource to 0 Queues
I0714 09:19:07.031475       1 session.go:244] Close Session 799db198-939b-4b78-80b0-f3f5aafc2b08
I0714 09:19:08.033870       1 cache.go:1363] There are <0> Jobs, <1> Queues and <5> Nodes in total for scheduling.
I0714 09:19:08.034079       1 session.go:190] Open Session 2b2b5109-e56c-4463-b61b-fd749d2002a4 with <0> Job and <1> Queues
I0714 09:19:08.035924       1 enqueue.go:79] Try to enqueue PodGroup to 0 Queues
I0714 09:19:08.036006       1 allocate.go:64] Try to allocate resource to 0 Queues
I0714 09:19:08.036223       1 session.go:244] Close Session 2b2b5109-e56c-4463-b61b-fd749d2002a4
I0714 09:19:09.039267       1 cache.go:1363] There are <0> Jobs, <1> Queues and <5> Nodes in total for scheduling.
I0714 09:19:09.039441       1 session.go:190] Open Session 68ed5690-345a-4c8c-a044-9cc9c119ef78 with <0> Job and <1> Queues
I0714 09:19:09.041432       1 enqueue.go:79] Try to enqueue PodGroup to 0 Queues
I0714 09:19:09.041508       1 allocate.go:64] Try to allocate resource to 0 Queues
I0714 09:19:09.041740       1 session.go:244] Close Session 68ed5690-345a-4c8c-a044-9cc9c119ef78
I0714 09:19:10.044325       1 cache.go:1363] There are <0> Jobs, <1> Queues and <5> Nodes in total for scheduling.
I0714 09:19:10.044515       1 session.go:190] Open Session 41a625f6-9912-46a6-ac92-cf21072fa2cf with <0> Job and <1> Queues
I0714 09:19:10.046666       1 enqueue.go:79] Try to enqueue PodGroup to 0 Queues
I0714 09:19:10.046746       1 allocate.go:64] Try to allocate resource to 0 Queues
I0714 09:19:10.047036       1 session.go:244] Close Session 41a625f6-9912-46a6-ac92-cf21072fa2cf
I0714 09:19:11.049324       1 cache.go:1363] There are <0> Jobs, <1> Queues and <5> Nodes in total for scheduling.
I0714 09:19:11.049495       1 session.go:190] Open Session ad234493-a73c-43fa-ba68-1d1103e4673d with <0> Job and <1> Queues
I0714 09:19:11.051576       1 enqueue.go:79] Try to enqueue PodGroup to 0 Queues
I0714 09:19:11.051655       1 allocate.go:64] Try to allocate resource to 0 Queues
I0714 09:19:11.051895       1 session.go:244] Close Session ad234493-a73c-43fa-ba68-1d1103e4673d
I0714 09:19:12.054503       1 cache.go:1363] There are <0> Jobs, <1> Queues and <5> Nodes in total for scheduling.
I0714 09:19:12.054644       1 session.go:190] Open Session ac17ccc1-4de2-4419-819b-d3ffe3fb4fbc with <0> Job and <1> Queues
I0714 09:19:12.056496       1 enqueue.go:79] Try to enqueue PodGroup to 0 Queues
I0714 09:19:12.056566       1 allocate.go:64] Try to allocate resource to 0 Queues
I0714 09:19:12.056789       1 session.go:244] Close Session ac17ccc1-4de2-4419-819b-d3ffe3fb4fbc
I0714 09:19:13.058853       1 cache.go:1363] There are <0> Jobs, <1> Queues and <5> Nodes in total for scheduling.
I0714 09:19:13.059028       1 session.go:190] Open Session ad433c4b-93ee-43e0-b992-e5720781cd00 with <0> Job and <1> Queues
I0714 09:19:13.060915       1 enqueue.go:79] Try to enqueue PodGroup to 0 Queues
I0714 09:19:13.060990       1 allocate.go:64] Try to allocate resource to 0 Queues
I0714 09:19:13.061211       1 session.go:244] Close Session ad433c4b-93ee-43e0-b992-e5720781cd00
I0714 09:19:14.063528       1 cache.go:1363] There are <0> Jobs, <1> Queues and <5> Nodes in total for scheduling.
I0714 09:19:14.063697       1 session.go:190] Open Session b8a0be67-a9fc-4dfd-9afd-a98372cd0bdc with <0> Job and <1> Queues
I0714 09:19:14.065560       1 enqueue.go:79] Try to enqueue PodGroup to 0 Queues
I0714 09:19:14.065641       1 allocate.go:64] Try to allocate resource to 0 Queues
I0714 09:19:14.065857       1 session.go:244] Close Session b8a0be67-a9fc-4dfd-9afd-a98372cd0bdc
I0714 09:19:15.068515       1 cache.go:1363] There are <0> Jobs, <1> Queues and <5> Nodes in total for scheduling.
I0714 09:19:15.068690       1 session.go:190] Open Session 96bb1a2f-49a1-4b0f-8a39-814a0272f3a9 with <0> Job and <1> Queues
I0714 09:19:15.070435       1 enqueue.go:79] Try to enqueue PodGroup to 0 Queues
I0714 09:19:15.070509       1 allocate.go:64] Try to allocate resource to 0 Queues
I0714 09:19:15.070732       1 session.go:244] Close Session 96bb1a2f-49a1-4b0f-8a39-814a0272f3a9
I0714 09:19:16.072868       1 cache.go:1363] There are <0> Jobs, <1> Queues and <5> Nodes in total for scheduling.
I0714 09:19:16.073016       1 session.go:190] Open Session 10d458f3-3129-4be7-9e6c-481ca3c19e06 with <0> Job and <1> Queues
I0714 09:19:16.075061       1 enqueue.go:79] Try to enqueue PodGroup to 0 Queues
I0714 09:19:16.075151       1 allocate.go:64] Try to allocate resource to 0 Queues
I0714 09:19:16.075391       1 session.go:244] Close Session 10d458f3-3129-4be7-9e6c-481ca3c19e06
I0714 09:19:17.077358       1 cache.go:1363] There are <0> Jobs, <1> Queues and <5> Nodes in total for scheduling.
I0714 09:19:17.077532       1 session.go:190] Open Session 1af1de08-6d4d-4585-bf86-13344dfff2c9 with <0> Job and <1> Queues
I0714 09:19:17.079226       1 enqueue.go:79] Try to enqueue PodGroup to 0 Queues
I0714 09:19:17.079295       1 allocate.go:64] Try to allocate resource to 0 Queues
I0714 09:19:17.079546       1 session.go:244] Close Session 1af1de08-6d4d-4585-bf86-13344dfff2c9
W0714 09:19:17.950864       1 event_handlers.go:181] Not support non-csi pvc.
I0714 09:19:17.951000       1 event_handlers.go:387] Added pod <default/yolo-cls> into cache.
W0714 09:19:17.975137       1 event_handlers.go:181] Not support non-csi pvc.
I0714 09:19:18.081967       1 cache.go:1363] There are <1> Jobs, <1> Queues and <5> Nodes in total for scheduling.
I0714 09:19:18.082112       1 session.go:190] Open Session 9a5eefba-ac74-47b2-b4b6-f050c387990e with <1> Job and <1> Queues
I0714 09:19:18.084193       1 enqueue.go:79] Try to enqueue PodGroup to 1 Queues
I0714 09:19:18.084538       1 allocate.go:64] Try to allocate resource to 1 Queues
I0714 09:19:18.084597       1 allocate.go:129] Try to allocate resource to Jobs in Queue <default>
I0714 09:19:18.084631       1 allocate.go:161] Try to allocate resource to 1 tasks of Job <default/podgroup-87b6bed1-3e6c-4a65-b82d-ecb21fcd712d>
I0714 09:19:18.084673       1 allocate.go:181] There are <5> nodes for Job <default/podgroup-87b6bed1-3e6c-4a65-b82d-ecb21fcd712d>
I0714 09:19:18.085013       1 predicate_helper.go:75] Predicates failed: task default/yolo-cls on node gpu-master fit failed: Insufficient nvidia.com/gpu
I0714 09:19:18.085318       1 predicate_helper.go:75] Predicates failed: task default/yolo-cls on node gpuorin4-desktop fit failed: plugin NodeAffinity predicates failed node(s) didn't match Pod's node affinity/selector
I0714 09:19:18.085376       1 predicate_helper.go:75] Predicates failed: task default/yolo-cls on node gpuorin5-desktop fit failed: plugin NodeAffinity predicates failed node(s) didn't match Pod's node affinity/selector
I0714 09:19:18.086364       1 allocate.go:249] Binding Task <default/yolo-cls> to node <gpu-orin2>
I0714 09:19:18.086571       1 statement.go:266] After allocated Task <default/yolo-cls> to Node <gpu-orin2>: idle <cpu 5900.00, memory 7832690688.00, nvidia.com/gpu 4000.00, pods 105.00, ephemeral-storage 225118140453000.00, hugepages-1Gi 0.00, hugepages-2Mi 0.00, hugepages-32Mi 0.00, hugepages-64Ki 0.00>, used <cpu 100.00, memory 52428800.00, pods 5.00, nvidia.com/gpu 1000.00>, releasing <cpu 0.00, memory 0.00>
I0714 09:19:18.087077       1 statement.go:284] Allocating operations ...
I0714 09:19:18.087199       1 statement.go:378] Committing operations ...
I0714 09:19:18.087331       1 proportion.go:302] Queue <default>: deserved <cpu 0.00, memory 0.00, nvidia.com/gpu 1000.00, pods 1.00>, allocated <cpu 0.00, memory 0.00, pods 1.00, nvidia.com/gpu 1000.00>, share <1>
I0714 09:19:18.087398       1 allocate.go:125] Queue <default> is overused, ignore it.
I0714 09:19:18.104772       1 session.go:244] Close Session 9a5eefba-ac74-47b2-b4b6-f050c387990e
I0714 09:19:18.121732       1 cache.go:900] bind ok, latency 17.565492ms
W0714 09:19:18.124229       1 event_handlers.go:181] Not support non-csi pvc.
W0714 09:19:18.162489       1 event_handlers.go:181] Not support non-csi pvc.
W0714 09:19:18.606794       1 event_handlers.go:181] Not support non-csi pvc.
I0714 09:19:18.611502       1 event_handlers.go:442] Deleted pod <default/yolo-cls> from cache.
I0714 09:19:18.628228       1 cache.go:1013] Try to delete Job <default/podgroup-87b6bed1-3e6c-4a65-b82d-ecb21fcd712d:default/podgroup-87b6bed1-3e6c-4a65-b82d-ecb21fcd712d>
I0714 09:19:18.628547       1 cache.go:1054] Job <default/podgroup-87b6bed1-3e6c-4a65-b82d-ecb21fcd712d:default/podgroup-87b6bed1-3e6c-4a65-b82d-ecb21fcd712d> was deleted.
W0714 09:19:18.791482       1 event_handlers.go:181] Not support non-csi pvc.
I0714 09:19:18.791622       1 event_handlers.go:387] Added pod <default/yolo-cls> into cache.
W0714 09:19:18.821959       1 event_handlers.go:181] Not support non-csi pvc.
I0714 09:19:19.107286       1 cache.go:1363] There are <0> Jobs, <1> Queues and <5> Nodes in total for scheduling.
I0714 09:19:19.107390       1 session.go:190] Open Session 9a329404-6f81-4c03-aae7-ce37227e1052 with <0> Job and <1> Queues
I0714 09:19:19.109376       1 enqueue.go:79] Try to enqueue PodGroup to 0 Queues
I0714 09:19:19.109453       1 allocate.go:64] Try to allocate resource to 0 Queues
I0714 09:19:19.109674       1 session.go:244] Close Session 9a329404-6f81-4c03-aae7-ce37227e1052
I0714 09:19:20.112208       1 cache.go:1363] There are <0> Jobs, <1> Queues and <5> Nodes in total for scheduling.
I0714 09:19:20.112418       1 session.go:190] Open Session 41e5ba67-0ee7-4677-97be-0e7cf413d2f6 with <0> Job and <1> Queues
I0714 09:19:20.114240       1 enqueue.go:79] Try to enqueue PodGroup to 0 Queues
I0714 09:19:20.114310       1 allocate.go:64] Try to allocate resource to 0 Queues
I0714 09:19:20.114518       1 session.go:244] Close Session 41e5ba67-0ee7-4677-97be-0e7cf413d2f6
W0714 09:19:20.843918       1 event_handlers.go:181] Not support non-csi pvc.
I0714 09:19:21.117001       1 cache.go:1363] There are <0> Jobs, <1> Queues and <5> Nodes in total for scheduling.
I0714 09:19:21.117129       1 session.go:190] Open Session 50d4ec6f-c0db-45e2-a219-70b657b01243 with <0> Job and <1> Queues
I0714 09:19:21.119104       1 enqueue.go:79] Try to enqueue PodGroup to 0 Queues
I0714 09:19:21.119187       1 allocate.go:64] Try to allocate resource to 0 Queues
I0714 09:19:21.119395       1 session.go:244] Close Session 50d4ec6f-c0db-45e2-a219-70b657b01243
I0714 09:19:22.121897       1 cache.go:1363] There are <0> Jobs, <1> Queues and <5> Nodes in total for scheduling.
I0714 09:19:22.122077       1 session.go:190] Open Session 2f18ebb8-6862-4aa5-90ef-0001922f0b90 with <0> Job and <1> Queues
I0714 09:19:22.123875       1 enqueue.go:79] Try to enqueue PodGroup to 0 Queues
I0714 09:19:22.123950       1 allocate.go:64] Try to allocate resource to 0 Queues
I0714 09:19:22.124167       1 session.go:244] Close Session 2f18ebb8-6862-4aa5-90ef-0001922f0b90
I0714 09:19:23.126449       1 cache.go:1363] There are <0> Jobs, <1> Queues and <5> Nodes in total for scheduling.
I0714 09:19:23.126618       1 session.go:190] Open Session 6f416d77-76ff-46ff-933e-47cd6c43ac32 with <0> Job and <1> Queues
I0714 09:19:23.128514       1 enqueue.go:79] Try to enqueue PodGroup to 0 Queues
I0714 09:19:23.128581       1 allocate.go:64] Try to allocate resource to 0 Queues
I0714 09:19:23.128819       1 session.go:244] Close Session 6f416d77-76ff-46ff-933e-47cd6c43ac32
I0714 09:19:24.131771       1 cache.go:1363] There are <0> Jobs, <1> Queues and <5> Nodes in total for scheduling.
I0714 09:19:24.131918       1 session.go:190] Open Session dd665486-8c4b-4512-aded-5fe80b8abf3d with <0> Job and <1> Queues
I0714 09:19:24.133764       1 enqueue.go:79] Try to enqueue PodGroup to 0 Queues
I0714 09:19:24.133841       1 allocate.go:64] Try to allocate resource to 0 Queues
I0714 09:19:24.134051       1 session.go:244] Close Session dd665486-8c4b-4512-aded-5fe80b8abf3d
W0714 09:19:24.958357       1 event_handlers.go:181] Not support non-csi pvc.
I0714 09:19:24.958475       1 event_handlers.go:387] Added pod <default/yolo-det> into cache.
W0714 09:19:24.983860       1 event_handlers.go:181] Not support non-csi pvc.
I0714 09:19:25.136646       1 cache.go:1363] There are <1> Jobs, <1> Queues and <5> Nodes in total for scheduling.
I0714 09:19:25.136784       1 session.go:190] Open Session 68f4fc1a-da45-4e72-a0b4-71f41430b5ba with <1> Job and <1> Queues
I0714 09:19:25.138881       1 enqueue.go:79] Try to enqueue PodGroup to 1 Queues
I0714 09:19:25.139134       1 allocate.go:64] Try to allocate resource to 1 Queues
I0714 09:19:25.139196       1 allocate.go:129] Try to allocate resource to Jobs in Queue <default>
I0714 09:19:25.139229       1 allocate.go:161] Try to allocate resource to 1 tasks of Job <default/podgroup-26fef88c-d788-4185-8218-531d7a66a8e7>
I0714 09:19:25.139269       1 allocate.go:181] There are <5> nodes for Job <default/podgroup-26fef88c-d788-4185-8218-531d7a66a8e7>
I0714 09:19:25.139580       1 predicate_helper.go:75] Predicates failed: task default/yolo-det on node gpu-master fit failed: Insufficient nvidia.com/gpu
I0714 09:19:25.139932       1 predicate_helper.go:75] Predicates failed: task default/yolo-det on node gpuorin4-desktop fit failed: plugin NodeAffinity predicates failed node(s) didn't match Pod's node affinity/selector
I0714 09:19:25.139954       1 predicate_helper.go:75] Predicates failed: task default/yolo-det on node gpuorin5-desktop fit failed: plugin NodeAffinity predicates failed node(s) didn't match Pod's node affinity/selector
I0714 09:19:25.141126       1 allocate.go:249] Binding Task <default/yolo-det> to node <gpu-orin3>
I0714 09:19:25.141357       1 statement.go:266] After allocated Task <default/yolo-det> to Node <gpu-orin3>: idle <cpu 5900.00, memory 7832723456.00, hugepages-64Ki 0.00, pods 105.00, hugepages-32Mi 0.00, nvidia.com/gpu 4000.00, ephemeral-storage 111715275387000.00, hugepages-2Mi 0.00, hugepages-1Gi 0.00>, used <cpu 100.00, memory 52428800.00, pods 5.00, nvidia.com/gpu 1000.00>, releasing <cpu 0.00, memory 0.00>
I0714 09:19:25.141797       1 statement.go:284] Allocating operations ...
I0714 09:19:25.141923       1 statement.go:378] Committing operations ...
I0714 09:19:25.142037       1 proportion.go:302] Queue <default>: deserved <cpu 0.00, memory 0.00, pods 1.00, nvidia.com/gpu 1000.00>, allocated <cpu 0.00, memory 0.00, nvidia.com/gpu 1000.00, pods 1.00>, share <1>
I0714 09:19:25.142100       1 allocate.go:125] Queue <default> is overused, ignore it.
I0714 09:19:25.159202       1 session.go:244] Close Session 68f4fc1a-da45-4e72-a0b4-71f41430b5ba
I0714 09:19:25.163979       1 cache.go:900] bind ok, latency 12.940042ms
W0714 09:19:25.165722       1 event_handlers.go:181] Not support non-csi pvc.
W0714 09:19:25.660895       1 event_handlers.go:181] Not support non-csi pvc.
I0714 09:19:25.665342       1 event_handlers.go:442] Deleted pod <default/yolo-det> from cache.
I0714 09:19:25.674467       1 cache.go:1013] Try to delete Job <default/podgroup-26fef88c-d788-4185-8218-531d7a66a8e7:default/podgroup-26fef88c-d788-4185-8218-531d7a66a8e7>
I0714 09:19:25.674684       1 cache.go:1054] Job <default/podgroup-26fef88c-d788-4185-8218-531d7a66a8e7:default/podgroup-26fef88c-d788-4185-8218-531d7a66a8e7> was deleted.
W0714 09:19:25.789211       1 event_handlers.go:181] Not support non-csi pvc.
I0714 09:19:25.789341       1 event_handlers.go:387] Added pod <default/yolo-det> into cache.
I0714 09:19:26.161408       1 cache.go:1363] There are <0> Jobs, <1> Queues and <5> Nodes in total for scheduling.
I0714 09:19:26.161551       1 session.go:190] Open Session f9c1f710-007d-4707-99f9-0c214cec350e with <0> Job and <1> Queues
I0714 09:19:26.163256       1 enqueue.go:79] Try to enqueue PodGroup to 0 Queues
I0714 09:19:26.163329       1 allocate.go:64] Try to allocate resource to 0 Queues
I0714 09:19:26.163633       1 session.go:244] Close Session f9c1f710-007d-4707-99f9-0c214cec350e
I0714 09:19:27.166244       1 cache.go:1363] There are <0> Jobs, <1> Queues and <5> Nodes in total for scheduling.
I0714 09:19:27.166387       1 session.go:190] Open Session d64c48b7-6cd6-4d65-9181-bceac16ddad2 with <0> Job and <1> Queues
I0714 09:19:27.168030       1 enqueue.go:79] Try to enqueue PodGroup to 0 Queues
I0714 09:19:27.168090       1 allocate.go:64] Try to allocate resource to 0 Queues
I0714 09:19:27.168343       1 session.go:244] Close Session d64c48b7-6cd6-4d65-9181-bceac16ddad2
I0714 09:19:28.171064       1 cache.go:1363] There are <0> Jobs, <1> Queues and <5> Nodes in total for scheduling.
I0714 09:19:28.171250       1 session.go:190] Open Session ff32d212-6332-4f6d-83b7-c029ab9e00ed with <0> Job and <1> Queues
I0714 09:19:28.173473       1 enqueue.go:79] Try to enqueue PodGroup to 0 Queues
I0714 09:19:28.173559       1 allocate.go:64] Try to allocate resource to 0 Queues
I0714 09:19:28.173789       1 session.go:244] Close Session ff32d212-6332-4f6d-83b7-c029ab9e00ed
W0714 09:19:28.223797       1 event_handlers.go:181] Not support non-csi pvc.
I0714 09:19:29.175991       1 cache.go:1363] There are <0> Jobs, <1> Queues and <5> Nodes in total for scheduling.
I0714 09:19:29.176122       1 session.go:190] Open Session 69b7abbe-21a4-4ec9-969d-a14bb5b3b111 with <0> Job and <1> Queues
I0714 09:19:29.177965       1 enqueue.go:79] Try to enqueue PodGroup to 0 Queues
I0714 09:19:29.178048       1 allocate.go:64] Try to allocate resource to 0 Queues
I0714 09:19:29.178236       1 session.go:244] Close Session 69b7abbe-21a4-4ec9-969d-a14bb5b3b111
I0714 09:19:30.180630       1 cache.go:1363] There are <0> Jobs, <1> Queues and <5> Nodes in total for scheduling.
I0714 09:19:30.180780       1 session.go:190] Open Session 417ce8cf-2f7f-4770-9089-fb147ed3aabd with <0> Job and <1> Queues
I0714 09:19:30.183376       1 enqueue.go:79] Try to enqueue PodGroup to 0 Queues
I0714 09:19:30.183491       1 allocate.go:64] Try to allocate resource to 0 Queues
I0714 09:19:30.183728       1 session.go:244] Close Session 417ce8cf-2f7f-4770-9089-fb147ed3aabd
W0714 09:19:31.115169       1 event_handlers.go:181] Not support non-csi pvc.
I0714 09:19:31.185728       1 cache.go:1363] There are <0> Jobs, <1> Queues and <5> Nodes in total for scheduling.
I0714 09:19:31.185848       1 session.go:190] Open Session e4717bfe-4cae-4ebb-90fe-3429ad37d444 with <0> Job and <1> Queues
I0714 09:19:31.187830       1 enqueue.go:79] Try to enqueue PodGroup to 0 Queues
I0714 09:19:31.187918       1 allocate.go:64] Try to allocate resource to 0 Queues
I0714 09:19:31.188132       1 session.go:244] Close Session e4717bfe-4cae-4ebb-90fe-3429ad37d444
I0714 09:19:32.190661       1 cache.go:1363] There are <0> Jobs, <1> Queues and <5> Nodes in total for scheduling.
I0714 09:19:32.190806       1 session.go:190] Open Session 1261437c-95ed-4a12-96fd-9d053f97eb70 with <0> Job and <1> Queues
I0714 09:19:32.192565       1 enqueue.go:79] Try to enqueue PodGroup to 0 Queues
I0714 09:19:32.192632       1 allocate.go:64] Try to allocate resource to 0 Queues
I0714 09:19:32.192860       1 session.go:244] Close Session 1261437c-95ed-4a12-96fd-9d053f97eb70
I0714 09:19:33.195164       1 cache.go:1363] There are <0> Jobs, <1> Queues and <5> Nodes in total for scheduling.
I0714 09:19:33.195346       1 session.go:190] Open Session 29f00184-7d92-4106-8def-fd06df77488c with <0> Job and <1> Queues
I0714 09:19:33.197295       1 enqueue.go:79] Try to enqueue PodGroup to 0 Queues
I0714 09:19:33.197369       1 allocate.go:64] Try to allocate resource to 0 Queues
I0714 09:19:33.197601       1 session.go:244] Close Session 29f00184-7d92-4106-8def-fd06df77488c
I0714 09:19:34.200798       1 cache.go:1363] There are <0> Jobs, <1> Queues and <5> Nodes in total for scheduling.
I0714 09:19:34.200960       1 session.go:190] Open Session 88a302c0-e24d-446d-bb0e-38e692bb7f7c with <0> Job and <1> Queues
I0714 09:19:34.202750       1 enqueue.go:79] Try to enqueue PodGroup to 0 Queues
I0714 09:19:34.202818       1 allocate.go:64] Try to allocate resource to 0 Queues
I0714 09:19:34.203052       1 session.go:244] Close Session 88a302c0-e24d-446d-bb0e-38e692bb7f7c
W0714 09:19:35.067945       1 event_handlers.go:181] Not support non-csi pvc.
I0714 09:19:35.068073       1 event_handlers.go:387] Added pod <default/yolo-seg> into cache.
W0714 09:19:35.096977       1 event_handlers.go:181] Not support non-csi pvc.
I0714 09:19:35.206084       1 cache.go:1363] There are <1> Jobs, <1> Queues and <5> Nodes in total for scheduling.
I0714 09:19:35.206230       1 session.go:190] Open Session a62d8bae-0460-4257-a11f-0a38e4c1daf2 with <1> Job and <1> Queues
I0714 09:19:35.208350       1 enqueue.go:79] Try to enqueue PodGroup to 1 Queues
I0714 09:19:35.208624       1 allocate.go:64] Try to allocate resource to 1 Queues
I0714 09:19:35.208686       1 allocate.go:129] Try to allocate resource to Jobs in Queue <default>
I0714 09:19:35.208725       1 allocate.go:161] Try to allocate resource to 1 tasks of Job <default/podgroup-b29c7405-17e5-4f45-9424-38bc54f52767>
I0714 09:19:35.208774       1 allocate.go:181] There are <5> nodes for Job <default/podgroup-b29c7405-17e5-4f45-9424-38bc54f52767>
I0714 09:19:35.209099       1 predicate_helper.go:75] Predicates failed: task default/yolo-seg on node gpu-master fit failed: Insufficient nvidia.com/gpu
I0714 09:19:35.209619       1 predicate_helper.go:75] Predicates failed: task default/yolo-seg on node gpuorin5-desktop fit failed: plugin NodeAffinity predicates failed node(s) didn't match Pod's node affinity/selector
I0714 09:19:35.209698       1 predicate_helper.go:75] Predicates failed: task default/yolo-seg on node gpuorin4-desktop fit failed: plugin NodeAffinity predicates failed node(s) didn't match Pod's node affinity/selector
I0714 09:19:35.210619       1 allocate.go:249] Binding Task <default/yolo-seg> to node <gpu-orin2>
I0714 09:19:35.210898       1 statement.go:266] After allocated Task <default/yolo-seg> to Node <gpu-orin2>: idle <cpu 5900.00, memory 7832690688.00, ephemeral-storage 225118140453000.00, hugepages-1Gi 0.00, hugepages-2Mi 0.00, hugepages-32Mi 0.00, hugepages-64Ki 0.00, nvidia.com/gpu 3000.00, pods 104.00>, used <cpu 100.00, memory 52428800.00, pods 6.00, nvidia.com/gpu 2000.00>, releasing <cpu 0.00, memory 0.00>
I0714 09:19:35.211366       1 statement.go:284] Allocating operations ...
I0714 09:19:35.211507       1 statement.go:378] Committing operations ...
I0714 09:19:35.211632       1 proportion.go:302] Queue <default>: deserved <cpu 0.00, memory 0.00, nvidia.com/gpu 1000.00, pods 1.00>, allocated <cpu 0.00, memory 0.00, nvidia.com/gpu 1000.00, pods 1.00>, share <1>
I0714 09:19:35.211695       1 allocate.go:125] Queue <default> is overused, ignore it.
I0714 09:19:35.224282       1 session.go:244] Close Session a62d8bae-0460-4257-a11f-0a38e4c1daf2
I0714 09:19:35.235488       1 cache.go:900] bind ok, latency 13.076973ms
W0714 09:19:35.237136       1 event_handlers.go:181] Not support non-csi pvc.
W0714 09:19:35.296383       1 event_handlers.go:181] Not support non-csi pvc.
W0714 09:19:35.742874       1 event_handlers.go:181] Not support non-csi pvc.
I0714 09:19:35.745262       1 event_handlers.go:442] Deleted pod <default/yolo-seg> from cache.
I0714 09:19:35.752008       1 cache.go:1013] Try to delete Job <default/podgroup-b29c7405-17e5-4f45-9424-38bc54f52767:default/podgroup-b29c7405-17e5-4f45-9424-38bc54f52767>
I0714 09:19:35.752224       1 cache.go:1054] Job <default/podgroup-b29c7405-17e5-4f45-9424-38bc54f52767:default/podgroup-b29c7405-17e5-4f45-9424-38bc54f52767> was deleted.
W0714 09:19:35.895052       1 event_handlers.go:181] Not support non-csi pvc.
I0714 09:19:35.895388       1 event_handlers.go:387] Added pod <default/yolo-seg> into cache.
W0714 09:19:35.923398       1 event_handlers.go:181] Not support non-csi pvc.
I0714 09:19:36.227477       1 cache.go:1363] There are <0> Jobs, <1> Queues and <5> Nodes in total for scheduling.
I0714 09:19:36.227695       1 session.go:190] Open Session cd52d8d4-5075-44ac-880c-d4e844acbc16 with <0> Job and <1> Queues
I0714 09:19:36.229598       1 enqueue.go:79] Try to enqueue PodGroup to 0 Queues
I0714 09:19:36.229687       1 allocate.go:64] Try to allocate resource to 0 Queues
I0714 09:19:36.229931       1 session.go:244] Close Session cd52d8d4-5075-44ac-880c-d4e844acbc16
I0714 09:19:36.655612       1 cache.go:1489] The metrics type is not set in the volcano scheduler configmap file. As a result, the CPU and memory load information of the node is not collected.
I0714 09:19:37.232249       1 cache.go:1363] There are <0> Jobs, <1> Queues and <5> Nodes in total for scheduling.
I0714 09:19:37.232461       1 session.go:190] Open Session bc951fb7-48a1-45c0-b7f0-0b8cb0561fe8 with <0> Job and <1> Queues
I0714 09:19:37.234276       1 enqueue.go:79] Try to enqueue PodGroup to 0 Queues
I0714 09:19:37.234354       1 allocate.go:64] Try to allocate resource to 0 Queues
I0714 09:19:37.234569       1 session.go:244] Close Session bc951fb7-48a1-45c0-b7f0-0b8cb0561fe8
W0714 09:19:37.956952       1 event_handlers.go:181] Not support non-csi pvc.
I0714 09:19:38.236572       1 cache.go:1363] There are <0> Jobs, <1> Queues and <5> Nodes in total for scheduling.
I0714 09:19:38.236721       1 session.go:190] Open Session 86fd28ab-52f6-4ffd-9eb0-d62cd6de9733 with <0> Job and <1> Queues
I0714 09:19:38.238509       1 enqueue.go:79] Try to enqueue PodGroup to 0 Queues
I0714 09:19:38.238586       1 allocate.go:64] Try to allocate resource to 0 Queues
I0714 09:19:38.238804       1 session.go:244] Close Session 86fd28ab-52f6-4ffd-9eb0-d62cd6de9733
I0714 09:19:39.241340       1 cache.go:1363] There are <0> Jobs, <1> Queues and <5> Nodes in total for scheduling.
I0714 09:19:39.241500       1 session.go:190] Open Session 865fea84-8ea1-4e9e-9dad-6b6cbbda9b5f with <0> Job and <1> Queues
I0714 09:19:39.243455       1 enqueue.go:79] Try to enqueue PodGroup to 0 Queues
I0714 09:19:39.243537       1 allocate.go:64] Try to allocate resource to 0 Queues
I0714 09:19:39.243752       1 session.go:244] Close Session 865fea84-8ea1-4e9e-9dad-6b6cbbda9b5f
I0714 09:19:40.245948       1 cache.go:1363] There are <0> Jobs, <1> Queues and <5> Nodes in total for scheduling.
I0714 09:19:40.246119       1 session.go:190] Open Session 25e20479-7d31-42d0-a7c6-52c30990de5b with <0> Job and <1> Queues
I0714 09:19:40.247990       1 enqueue.go:79] Try to enqueue PodGroup to 0 Queues
I0714 09:19:40.248063       1 allocate.go:64] Try to allocate resource to 0 Queues
I0714 09:19:40.248315       1 session.go:244] Close Session 25e20479-7d31-42d0-a7c6-52c30990de5b
I0714 09:19:41.251081       1 cache.go:1363] There are <0> Jobs, <1> Queues and <5> Nodes in total for scheduling.
I0714 09:19:41.251223       1 session.go:190] Open Session 68754d2c-9688-4f29-8e02-7837f4df714d with <0> Job and <1> Queues
I0714 09:19:41.253018       1 enqueue.go:79] Try to enqueue PodGroup to 0 Queues
I0714 09:19:41.253107       1 allocate.go:64] Try to allocate resource to 0 Queues
I0714 09:19:41.253303       1 session.go:244] Close Session 68754d2c-9688-4f29-8e02-7837f4df714d
W0714 09:19:41.987356       1 event_handlers.go:181] Not support non-csi pvc.
I0714 09:19:41.987466       1 event_handlers.go:387] Added pod <default/yolo-obb> into cache.
W0714 09:19:42.022201       1 event_handlers.go:181] Not support non-csi pvc.
I0714 09:19:42.256159       1 cache.go:1363] There are <1> Jobs, <1> Queues and <5> Nodes in total for scheduling.
I0714 09:19:42.256381       1 session.go:190] Open Session 8181df49-44cc-4854-9200-248ca5569224 with <1> Job and <1> Queues
I0714 09:19:42.258552       1 enqueue.go:79] Try to enqueue PodGroup to 1 Queues
I0714 09:19:42.258905       1 allocate.go:64] Try to allocate resource to 1 Queues
I0714 09:19:42.258966       1 allocate.go:129] Try to allocate resource to Jobs in Queue <default>
I0714 09:19:42.259001       1 allocate.go:161] Try to allocate resource to 1 tasks of Job <default/podgroup-986097e9-c361-4775-9a31-764dd57ae912>
I0714 09:19:42.259042       1 allocate.go:181] There are <5> nodes for Job <default/podgroup-986097e9-c361-4775-9a31-764dd57ae912>
I0714 09:19:42.259356       1 predicate_helper.go:75] Predicates failed: task default/yolo-obb on node gpu-master fit failed: Insufficient nvidia.com/gpu
I0714 09:19:42.259659       1 predicate_helper.go:75] Predicates failed: task default/yolo-obb on node gpuorin4-desktop fit failed: plugin NodeAffinity predicates failed node(s) didn't match Pod's node affinity/selector
I0714 09:19:42.259825       1 predicate_helper.go:75] Predicates failed: task default/yolo-obb on node gpuorin5-desktop fit failed: plugin NodeAffinity predicates failed node(s) didn't match Pod's node affinity/selector
I0714 09:19:42.260640       1 allocate.go:249] Binding Task <default/yolo-obb> to node <gpu-orin3>
I0714 09:19:42.260850       1 statement.go:266] After allocated Task <default/yolo-obb> to Node <gpu-orin3>: idle <cpu 5900.00, memory 7832723456.00, pods 104.00, nvidia.com/gpu 3000.00, ephemeral-storage 111715275387000.00, hugepages-2Mi 0.00, hugepages-32Mi 0.00, hugepages-1Gi 0.00, hugepages-64Ki 0.00>, used <cpu 100.00, memory 52428800.00, nvidia.com/gpu 2000.00, pods 6.00>, releasing <cpu 0.00, memory 0.00>
I0714 09:19:42.261309       1 statement.go:284] Allocating operations ...
I0714 09:19:42.261454       1 statement.go:378] Committing operations ...
I0714 09:19:42.261578       1 proportion.go:302] Queue <default>: deserved <cpu 0.00, memory 0.00, pods 1.00, nvidia.com/gpu 1000.00>, allocated <cpu 0.00, memory 0.00, nvidia.com/gpu 1000.00, pods 1.00>, share <1>
I0714 09:19:42.261637       1 allocate.go:125] Queue <default> is overused, ignore it.
I0714 09:19:42.273810       1 session.go:244] Close Session 8181df49-44cc-4854-9200-248ca5569224
I0714 09:19:42.285807       1 cache.go:900] bind ok, latency 7.453483ms
W0714 09:19:42.288584       1 event_handlers.go:181] Not support non-csi pvc.
W0714 09:19:42.324471       1 event_handlers.go:181] Not support non-csi pvc.
W0714 09:19:42.638240       1 event_handlers.go:181] Not support non-csi pvc.
I0714 09:19:42.643544       1 event_handlers.go:442] Deleted pod <default/yolo-obb> from cache.
I0714 09:19:42.661098       1 cache.go:1013] Try to delete Job <default/podgroup-986097e9-c361-4775-9a31-764dd57ae912:default/podgroup-986097e9-c361-4775-9a31-764dd57ae912>
I0714 09:19:42.661320       1 cache.go:1054] Job <default/podgroup-986097e9-c361-4775-9a31-764dd57ae912:default/podgroup-986097e9-c361-4775-9a31-764dd57ae912> was deleted.
W0714 09:19:42.773702       1 event_handlers.go:181] Not support non-csi pvc.
I0714 09:19:42.773845       1 event_handlers.go:387] Added pod <default/yolo-obb> into cache.
W0714 09:19:42.807951       1 event_handlers.go:181] Not support non-csi pvc.
I0714 09:19:43.277320       1 cache.go:1363] There are <0> Jobs, <1> Queues and <5> Nodes in total for scheduling.
I0714 09:19:43.277522       1 session.go:190] Open Session 81fba774-19e7-498f-80da-a7d3baec0180 with <0> Job and <1> Queues
I0714 09:19:43.279416       1 enqueue.go:79] Try to enqueue PodGroup to 0 Queues
I0714 09:19:43.279492       1 allocate.go:64] Try to allocate resource to 0 Queues
I0714 09:19:43.279719       1 session.go:244] Close Session 81fba774-19e7-498f-80da-a7d3baec0180
I0714 09:19:44.282517       1 cache.go:1363] There are <0> Jobs, <1> Queues and <5> Nodes in total for scheduling.
I0714 09:19:44.282689       1 session.go:190] Open Session 8b5d08a8-4e01-443f-82ba-d1e14c7f6b86 with <0> Job and <1> Queues
I0714 09:19:44.284599       1 enqueue.go:79] Try to enqueue PodGroup to 0 Queues
I0714 09:19:44.284681       1 allocate.go:64] Try to allocate resource to 0 Queues
I0714 09:19:44.284938       1 session.go:244] Close Session 8b5d08a8-4e01-443f-82ba-d1e14c7f6b86
W0714 09:19:45.172528       1 event_handlers.go:181] Not support non-csi pvc.
I0714 09:19:45.287372       1 cache.go:1363] There are <0> Jobs, <1> Queues and <5> Nodes in total for scheduling.
I0714 09:19:45.287510       1 session.go:190] Open Session 7490e7f9-393e-4924-bf5f-382b8231182a with <0> Job and <1> Queues
I0714 09:19:45.289587       1 enqueue.go:79] Try to enqueue PodGroup to 0 Queues
I0714 09:19:45.289686       1 allocate.go:64] Try to allocate resource to 0 Queues
I0714 09:19:45.289936       1 session.go:244] Close Session 7490e7f9-393e-4924-bf5f-382b8231182a
I0714 09:19:46.292131       1 cache.go:1363] There are <0> Jobs, <1> Queues and <5> Nodes in total for scheduling.
I0714 09:19:46.292263       1 session.go:190] Open Session afdcea20-c5b7-4462-a4c7-3b8f6683f3ab with <0> Job and <1> Queues
I0714 09:19:46.294095       1 enqueue.go:79] Try to enqueue PodGroup to 0 Queues
I0714 09:19:46.294180       1 allocate.go:64] Try to allocate resource to 0 Queues
I0714 09:19:46.294389       1 session.go:244] Close Session afdcea20-c5b7-4462-a4c7-3b8f6683f3ab
I0714 09:19:47.296324       1 cache.go:1363] There are <0> Jobs, <1> Queues and <5> Nodes in total for scheduling.
I0714 09:19:47.296413       1 session.go:190] Open Session 0600235f-550d-4f2d-9436-35289eebbe8b with <0> Job and <1> Queues
I0714 09:19:47.297393       1 enqueue.go:79] Try to enqueue PodGroup to 0 Queues
I0714 09:19:47.297443       1 allocate.go:64] Try to allocate resource to 0 Queues
I0714 09:19:47.297554       1 session.go:244] Close Session 0600235f-550d-4f2d-9436-35289eebbe8b
I0714 09:19:48.299998       1 cache.go:1363] There are <0> Jobs, <1> Queues and <5> Nodes in total for scheduling.
I0714 09:19:48.300170       1 session.go:190] Open Session 5d6c7656-39df-42c0-8b4f-960c87984e2f with <0> Job and <1> Queues
I0714 09:19:48.302156       1 enqueue.go:79] Try to enqueue PodGroup to 0 Queues
I0714 09:19:48.302238       1 allocate.go:64] Try to allocate resource to 0 Queues
I0714 09:19:48.302454       1 session.go:244] Close Session 5d6c7656-39df-42c0-8b4f-960c87984e2f
W0714 09:19:48.741601       1 event_handlers.go:181] Not support non-csi pvc.
I0714 09:19:48.741709       1 event_handlers.go:387] Added pod <default/yolo-pos> into cache.
W0714 09:19:48.768436       1 event_handlers.go:181] Not support non-csi pvc.
I0714 09:19:49.307524       1 cache.go:1363] There are <1> Jobs, <1> Queues and <5> Nodes in total for scheduling.
I0714 09:19:49.307735       1 session.go:190] Open Session c0192ac0-f282-430a-8dc2-43df117ce23b with <1> Job and <1> Queues
I0714 09:19:49.311063       1 enqueue.go:79] Try to enqueue PodGroup to 1 Queues
I0714 09:19:49.311388       1 allocate.go:64] Try to allocate resource to 1 Queues
I0714 09:19:49.311435       1 allocate.go:129] Try to allocate resource to Jobs in Queue <default>
I0714 09:19:49.311482       1 allocate.go:161] Try to allocate resource to 1 tasks of Job <default/podgroup-130837e2-b95d-4949-a3e7-1733bd1cfe6b>
I0714 09:19:49.311517       1 allocate.go:181] There are <5> nodes for Job <default/podgroup-130837e2-b95d-4949-a3e7-1733bd1cfe6b>
I0714 09:19:49.314860       1 predicate_helper.go:75] Predicates failed: task default/yolo-pos on node gpu-master fit failed: Insufficient nvidia.com/gpu
I0714 09:19:49.315508       1 predicate_helper.go:75] Predicates failed: task default/yolo-pos on node gpuorin4-desktop fit failed: plugin NodeAffinity predicates failed node(s) didn't match Pod's node affinity/selector
I0714 09:19:49.315597       1 predicate_helper.go:75] Predicates failed: task default/yolo-pos on node gpuorin5-desktop fit failed: plugin NodeAffinity predicates failed node(s) didn't match Pod's node affinity/selector
I0714 09:19:49.316846       1 allocate.go:249] Binding Task <default/yolo-pos> to node <gpu-orin2>
I0714 09:19:49.317077       1 statement.go:266] After allocated Task <default/yolo-pos> to Node <gpu-orin2>: idle <cpu 5900.00, memory 7832690688.00, ephemeral-storage 225118140453000.00, hugepages-1Gi 0.00, hugepages-2Mi 0.00, hugepages-32Mi 0.00, hugepages-64Ki 0.00, nvidia.com/gpu 2000.00, pods 103.00>, used <cpu 100.00, memory 52428800.00, pods 7.00, nvidia.com/gpu 3000.00>, releasing <cpu 0.00, memory 0.00>
I0714 09:19:49.317592       1 statement.go:284] Allocating operations ...
I0714 09:19:49.317737       1 statement.go:378] Committing operations ...
I0714 09:19:49.317872       1 proportion.go:302] Queue <default>: deserved <cpu 0.00, memory 0.00, nvidia.com/gpu 1000.00, pods 1.00>, allocated <cpu 0.00, memory 0.00, nvidia.com/gpu 1000.00, pods 1.00>, share <1>
I0714 09:19:49.317933       1 allocate.go:125] Queue <default> is overused, ignore it.
I0714 09:19:49.328827       1 session.go:244] Close Session c0192ac0-f282-430a-8dc2-43df117ce23b
I0714 09:19:49.337117       1 cache.go:900] bind ok, latency 10.881082ms
W0714 09:19:49.338769       1 event_handlers.go:181] Not support non-csi pvc.
W0714 09:19:49.380168       1 event_handlers.go:181] Not support non-csi pvc.
W0714 09:19:49.409697       1 event_handlers.go:181] Not support non-csi pvc.
I0714 09:19:49.412991       1 event_handlers.go:442] Deleted pod <default/yolo-pos> from cache.
I0714 09:19:49.415700       1 cache.go:1013] Try to delete Job <default/podgroup-130837e2-b95d-4949-a3e7-1733bd1cfe6b:default/podgroup-130837e2-b95d-4949-a3e7-1733bd1cfe6b>
I0714 09:19:49.415939       1 cache.go:1054] Job <default/podgroup-130837e2-b95d-4949-a3e7-1733bd1cfe6b:default/podgroup-130837e2-b95d-4949-a3e7-1733bd1cfe6b> was deleted.
W0714 09:19:49.542073       1 event_handlers.go:181] Not support non-csi pvc.
I0714 09:19:49.542236       1 event_handlers.go:387] Added pod <default/yolo-pos> into cache.
W0714 09:19:49.581533       1 event_handlers.go:181] Not support non-csi pvc.
I0714 09:19:50.331373       1 cache.go:1363] There are <0> Jobs, <1> Queues and <5> Nodes in total for scheduling.
I0714 09:19:50.331500       1 session.go:190] Open Session 0df785f6-d63d-435b-a69d-7bbe59dde95c with <0> Job and <1> Queues
I0714 09:19:50.333462       1 enqueue.go:79] Try to enqueue PodGroup to 0 Queues
I0714 09:19:50.333543       1 allocate.go:64] Try to allocate resource to 0 Queues
I0714 09:19:50.333776       1 session.go:244] Close Session 0df785f6-d63d-435b-a69d-7bbe59dde95c
I0714 09:19:51.336752       1 cache.go:1363] There are <0> Jobs, <1> Queues and <5> Nodes in total for scheduling.
I0714 09:19:51.336922       1 session.go:190] Open Session 1da47b5a-7523-4966-912e-e9210a23c99c with <0> Job and <1> Queues
I0714 09:19:51.338780       1 enqueue.go:79] Try to enqueue PodGroup to 0 Queues
I0714 09:19:51.338855       1 allocate.go:64] Try to allocate resource to 0 Queues
I0714 09:19:51.339095       1 session.go:244] Close Session 1da47b5a-7523-4966-912e-e9210a23c99c
I0714 09:19:52.341557       1 cache.go:1363] There are <0> Jobs, <1> Queues and <5> Nodes in total for scheduling.
I0714 09:19:52.341724       1 session.go:190] Open Session 88585e13-c281-4cbc-b33e-edc68136f6fc with <0> Job and <1> Queues
I0714 09:19:52.343739       1 enqueue.go:79] Try to enqueue PodGroup to 0 Queues
I0714 09:19:52.343812       1 allocate.go:64] Try to allocate resource to 0 Queues
I0714 09:19:52.344032       1 session.go:244] Close Session 88585e13-c281-4cbc-b33e-edc68136f6fc
W0714 09:19:53.068135       1 event_handlers.go:181] Not support non-csi pvc.
I0714 09:19:53.346558       1 cache.go:1363] There are <0> Jobs, <1> Queues and <5> Nodes in total for scheduling.
I0714 09:19:53.346709       1 session.go:190] Open Session 909a7a66-3a74-442a-a240-2abe70bb2e28 with <0> Job and <1> Queues
I0714 09:19:53.349067       1 enqueue.go:79] Try to enqueue PodGroup to 0 Queues
I0714 09:19:53.349147       1 allocate.go:64] Try to allocate resource to 0 Queues
I0714 09:19:53.349387       1 session.go:244] Close Session 909a7a66-3a74-442a-a240-2abe70bb2e28
I0714 09:19:54.351899       1 cache.go:1363] There are <0> Jobs, <1> Queues and <5> Nodes in total for scheduling.
I0714 09:19:54.352112       1 session.go:190] Open Session 28866e6d-6231-4f6a-bbdd-60b17cacafb2 with <0> Job and <1> Queues
I0714 09:19:54.354380       1 enqueue.go:79] Try to enqueue PodGroup to 0 Queues
I0714 09:19:54.354457       1 allocate.go:64] Try to allocate resource to 0 Queues
I0714 09:19:54.354669       1 session.go:244] Close Session 28866e6d-6231-4f6a-bbdd-60b17cacafb2
I0714 09:19:55.357802       1 cache.go:1363] There are <0> Jobs, <1> Queues and <5> Nodes in total for scheduling.
I0714 09:19:55.357969       1 session.go:190] Open Session fcfe63ac-a020-408d-ba9c-88aa8b6f84c7 with <0> Job and <1> Queues
I0714 09:19:55.359899       1 enqueue.go:79] Try to enqueue PodGroup to 0 Queues
I0714 09:19:55.359972       1 allocate.go:64] Try to allocate resource to 0 Queues
I0714 09:19:55.360192       1 session.go:244] Close Session fcfe63ac-a020-408d-ba9c-88aa8b6f84c7
I0714 09:19:56.362809       1 cache.go:1363] There are <0> Jobs, <1> Queues and <5> Nodes in total for scheduling.
I0714 09:19:56.362969       1 session.go:190] Open Session 428620da-037a-46fa-8d38-aa3bc650be5f with <0> Job and <1> Queues
I0714 09:19:56.365219       1 enqueue.go:79] Try to enqueue PodGroup to 0 Queues
I0714 09:19:56.365296       1 allocate.go:64] Try to allocate resource to 0 Queues
I0714 09:19:56.365528       1 session.go:244] Close Session 428620da-037a-46fa-8d38-aa3bc650be5f
I0714 09:19:57.368016       1 cache.go:1363] There are <0> Jobs, <1> Queues and <5> Nodes in total for scheduling.
I0714 09:19:57.368176       1 session.go:190] Open Session 44117627-a806-4182-b3e6-9f693d1c10c3 with <0> Job and <1> Queues
I0714 09:19:57.370187       1 enqueue.go:79] Try to enqueue PodGroup to 0 Queues
I0714 09:19:57.370263       1 allocate.go:64] Try to allocate resource to 0 Queues
I0714 09:19:57.370480       1 session.go:244] Close Session 44117627-a806-4182-b3e6-9f693d1c10c3
I0714 09:19:58.373256       1 cache.go:1363] There are <0> Jobs, <1> Queues and <5> Nodes in total for scheduling.
I0714 09:19:58.373449       1 session.go:190] Open Session f647903d-ee53-4a9b-ba53-fe8eabc6df3e with <0> Job and <1> Queues
I0714 09:19:58.375366       1 enqueue.go:79] Try to enqueue PodGroup to 0 Queues
I0714 09:19:58.375432       1 allocate.go:64] Try to allocate resource to 0 Queues
I0714 09:19:58.375650       1 session.go:244] Close Session f647903d-ee53-4a9b-ba53-fe8eabc6df3e
I0714 09:19:59.378876       1 cache.go:1363] There are <0> Jobs, <1> Queues and <5> Nodes in total for scheduling.
I0714 09:19:59.379056       1 session.go:190] Open Session f765884b-36e6-4467-acec-e8d4674795ed with <0> Job and <1> Queues
I0714 09:19:59.380990       1 enqueue.go:79] Try to enqueue PodGroup to 0 Queues
I0714 09:19:59.381061       1 allocate.go:64] Try to allocate resource to 0 Queues
I0714 09:19:59.381294       1 session.go:244] Close Session f765884b-36e6-4467-acec-e8d4674795ed
I0714 09:20:00.383850       1 cache.go:1363] There are <0> Jobs, <1> Queues and <5> Nodes in total for scheduling.
I0714 09:20:00.384007       1 session.go:190] Open Session 586dc829-7dbb-4951-9ce9-f5d56003d483 with <0> Job and <1> Queues
I0714 09:20:00.386446       1 enqueue.go:79] Try to enqueue PodGroup to 0 Queues
I0714 09:20:00.386533       1 allocate.go:64] Try to allocate resource to 0 Queues
I0714 09:20:00.386761       1 session.go:244] Close Session 586dc829-7dbb-4951-9ce9-f5d56003d483
I0714 09:20:01.389280       1 cache.go:1363] There are <0> Jobs, <1> Queues and <5> Nodes in total for scheduling.
I0714 09:20:01.389427       1 session.go:190] Open Session 10f30bb2-22a4-4494-acfe-5128ebcf1c1c with <0> Job and <1> Queues
I0714 09:20:01.391223       1 enqueue.go:79] Try to enqueue PodGroup to 0 Queues
I0714 09:20:01.391299       1 allocate.go:64] Try to allocate resource to 0 Queues
I0714 09:20:01.391517       1 session.go:244] Close Session 10f30bb2-22a4-4494-acfe-5128ebcf1c1c
I0714 09:20:02.394229       1 cache.go:1363] There are <0> Jobs, <1> Queues and <5> Nodes in total for scheduling.
I0714 09:20:02.394387       1 session.go:190] Open Session cf5e9300-d09f-4efa-9430-779283d59e1a with <0> Job and <1> Queues
I0714 09:20:02.396772       1 enqueue.go:79] Try to enqueue PodGroup to 0 Queues
I0714 09:20:02.396857       1 allocate.go:64] Try to allocate resource to 0 Queues
I0714 09:20:02.397101       1 session.go:244] Close Session cf5e9300-d09f-4efa-9430-779283d59e1a
I0714 09:20:03.399826       1 cache.go:1363] There are <0> Jobs, <1> Queues and <5> Nodes in total for scheduling.
I0714 09:20:03.400016       1 session.go:190] Open Session 344b7a8e-bfcd-472f-a73c-8acd0632db15 with <0> Job and <1> Queues
I0714 09:20:03.402000       1 enqueue.go:79] Try to enqueue PodGroup to 0 Queues
I0714 09:20:03.402083       1 allocate.go:64] Try to allocate resource to 0 Queues
I0714 09:20:03.402288       1 session.go:244] Close Session 344b7a8e-bfcd-472f-a73c-8acd0632db15
I0714 09:20:04.405210       1 cache.go:1363] There are <0> Jobs, <1> Queues and <5> Nodes in total for scheduling.
I0714 09:20:04.405394       1 session.go:190] Open Session f2ebd3d1-b449-4942-84ff-8ccfd2457d7d with <0> Job and <1> Queues
I0714 09:20:04.407263       1 enqueue.go:79] Try to enqueue PodGroup to 0 Queues
I0714 09:20:04.407347       1 allocate.go:64] Try to allocate resource to 0 Queues
I0714 09:20:04.407584       1 session.go:244] Close Session f2ebd3d1-b449-4942-84ff-8ccfd2457d7d
I0714 09:20:05.409819       1 cache.go:1363] There are <0> Jobs, <1> Queues and <5> Nodes in total for scheduling.
I0714 09:20:05.409925       1 session.go:190] Open Session 7ed7fcbb-6a4d-4a04-a831-0f1009fbc256 with <0> Job and <1> Queues
I0714 09:20:05.412475       1 enqueue.go:79] Try to enqueue PodGroup to 0 Queues
I0714 09:20:05.412552       1 allocate.go:64] Try to allocate resource to 0 Queues
I0714 09:20:05.412755       1 session.go:244] Close Session 7ed7fcbb-6a4d-4a04-a831-0f1009fbc256
I0714 09:20:06.415259       1 cache.go:1363] There are <0> Jobs, <1> Queues and <5> Nodes in total for scheduling.
I0714 09:20:06.415438       1 session.go:190] Open Session d275dd26-9980-4d63-b2a7-620195414052 with <0> Job and <1> Queues
I0714 09:20:06.417532       1 enqueue.go:79] Try to enqueue PodGroup to 0 Queues
I0714 09:20:06.417608       1 allocate.go:64] Try to allocate resource to 0 Queues
I0714 09:20:06.417848       1 session.go:244] Close Session d275dd26-9980-4d63-b2a7-620195414052
I0714 09:20:06.656396       1 cache.go:1489] The metrics type is not set in the volcano scheduler configmap file. As a result, the CPU and memory load information of the node is not collected.
I0714 09:20:07.420094       1 cache.go:1363] There are <0> Jobs, <1> Queues and <5> Nodes in total for scheduling.
I0714 09:20:07.420252       1 session.go:190] Open Session e52b2d5c-2aee-4316-b06e-9594783250a6 with <0> Job and <1> Queues
I0714 09:20:07.422212       1 enqueue.go:79] Try to enqueue PodGroup to 0 Queues
I0714 09:20:07.422289       1 allocate.go:64] Try to allocate resource to 0 Queues
I0714 09:20:07.422506       1 session.go:244] Close Session e52b2d5c-2aee-4316-b06e-9594783250a6
I0714 09:20:08.424996       1 cache.go:1363] There are <0> Jobs, <1> Queues and <5> Nodes in total for scheduling.
I0714 09:20:08.425182       1 session.go:190] Open Session 295417d3-f1c9-467b-8e8b-7af148129854 with <0> Job and <1> Queues
I0714 09:20:08.427006       1 enqueue.go:79] Try to enqueue PodGroup to 0 Queues
I0714 09:20:08.427077       1 allocate.go:64] Try to allocate resource to 0 Queues
I0714 09:20:08.427342       1 session.go:244] Close Session 295417d3-f1c9-467b-8e8b-7af148129854
I0714 09:20:09.430345       1 cache.go:1363] There are <0> Jobs, <1> Queues and <5> Nodes in total for scheduling.
I0714 09:20:09.430517       1 session.go:190] Open Session 59d70cc1-265f-4e31-b03c-e9977dd4ce88 with <0> Job and <1> Queues
I0714 09:20:09.432440       1 enqueue.go:79] Try to enqueue PodGroup to 0 Queues
I0714 09:20:09.432516       1 allocate.go:64] Try to allocate resource to 0 Queues
I0714 09:20:09.432752       1 session.go:244] Close Session 59d70cc1-265f-4e31-b03c-e9977dd4ce88
I0714 09:20:10.435355       1 cache.go:1363] There are <0> Jobs, <1> Queues and <5> Nodes in total for scheduling.
I0714 09:20:10.435514       1 session.go:190] Open Session 7dac8746-4cfa-4771-9499-9d76425f806f with <0> Job and <1> Queues
I0714 09:20:10.437708       1 enqueue.go:79] Try to enqueue PodGroup to 0 Queues
I0714 09:20:10.437784       1 allocate.go:64] Try to allocate resource to 0 Queues
I0714 09:20:10.438004       1 session.go:244] Close Session 7dac8746-4cfa-4771-9499-9d76425f806f
I0714 09:20:11.440499       1 cache.go:1363] There are <0> Jobs, <1> Queues and <5> Nodes in total for scheduling.
I0714 09:20:11.440671       1 session.go:190] Open Session 7d7eb506-b89c-42d7-8d29-7abc5bc3de52 with <0> Job and <1> Queues
I0714 09:20:11.442651       1 enqueue.go:79] Try to enqueue PodGroup to 0 Queues
I0714 09:20:11.442726       1 allocate.go:64] Try to allocate resource to 0 Queues
I0714 09:20:11.442958       1 session.go:244] Close Session 7d7eb506-b89c-42d7-8d29-7abc5bc3de52
I0714 09:20:12.445391       1 cache.go:1363] There are <0> Jobs, <1> Queues and <5> Nodes in total for scheduling.
I0714 09:20:12.445566       1 session.go:190] Open Session be8f614a-4cd8-440f-9e3f-a12c15223d4b with <0> Job and <1> Queues
I0714 09:20:12.447883       1 enqueue.go:79] Try to enqueue PodGroup to 0 Queues
I0714 09:20:12.447967       1 allocate.go:64] Try to allocate resource to 0 Queues
I0714 09:20:12.448266       1 session.go:244] Close Session be8f614a-4cd8-440f-9e3f-a12c15223d4b
I0714 09:20:13.450893       1 cache.go:1363] There are <0> Jobs, <1> Queues and <5> Nodes in total for scheduling.
I0714 09:20:13.451072       1 session.go:190] Open Session e7e2cdaf-5ffa-4c23-a536-9085cc6e012f with <0> Job and <1> Queues
I0714 09:20:13.453095       1 enqueue.go:79] Try to enqueue PodGroup to 0 Queues
I0714 09:20:13.453175       1 allocate.go:64] Try to allocate resource to 0 Queues
I0714 09:20:13.453409       1 session.go:244] Close Session e7e2cdaf-5ffa-4c23-a536-9085cc6e012f
I0714 09:20:14.456066       1 cache.go:1363] There are <0> Jobs, <1> Queues and <5> Nodes in total for scheduling.
I0714 09:20:14.456223       1 session.go:190] Open Session fa5bcfb6-b723-44cc-bb7a-5272aa3ab912 with <0> Job and <1> Queues
I0714 09:20:14.458390       1 enqueue.go:79] Try to enqueue PodGroup to 0 Queues
I0714 09:20:14.458471       1 allocate.go:64] Try to allocate resource to 0 Queues
I0714 09:20:14.458683       1 session.go:244] Close Session fa5bcfb6-b723-44cc-bb7a-5272aa3ab912
I0714 09:20:15.460950       1 cache.go:1363] There are <0> Jobs, <1> Queues and <5> Nodes in total for scheduling.
I0714 09:20:15.461075       1 session.go:190] Open Session 02fda312-060a-4cc2-b35e-b451a9e2e5d6 with <0> Job and <1> Queues
I0714 09:20:15.462768       1 enqueue.go:79] Try to enqueue PodGroup to 0 Queues
I0714 09:20:15.462833       1 allocate.go:64] Try to allocate resource to 0 Queues
I0714 09:20:15.463227       1 session.go:244] Close Session 02fda312-060a-4cc2-b35e-b451a9e2e5d6
I0714 09:20:16.465053       1 cache.go:1363] There are <0> Jobs, <1> Queues and <5> Nodes in total for scheduling.
I0714 09:20:16.465169       1 session.go:190] Open Session 7d8e13cf-c368-46c6-950d-428b053bef9f with <0> Job and <1> Queues
I0714 09:20:16.466989       1 enqueue.go:79] Try to enqueue PodGroup to 0 Queues
I0714 09:20:16.467048       1 allocate.go:64] Try to allocate resource to 0 Queues
I0714 09:20:16.467244       1 session.go:244] Close Session 7d8e13cf-c368-46c6-950d-428b053bef9f
I0714 09:20:17.470308       1 cache.go:1363] There are <0> Jobs, <1> Queues and <5> Nodes in total for scheduling.
I0714 09:20:17.470497       1 session.go:190] Open Session 8ffdcb54-8e71-4e9e-80a0-be3e6e4dec91 with <0> Job and <1> Queues
I0714 09:20:17.472560       1 enqueue.go:79] Try to enqueue PodGroup to 0 Queues
I0714 09:20:17.472639       1 allocate.go:64] Try to allocate resource to 0 Queues
I0714 09:20:17.472874       1 session.go:244] Close Session 8ffdcb54-8e71-4e9e-80a0-be3e6e4dec91
I0714 09:20:18.475341       1 cache.go:1363] There are <0> Jobs, <1> Queues and <5> Nodes in total for scheduling.
I0714 09:20:18.475517       1 session.go:190] Open Session 92126ea5-ffaf-4104-8542-237da40dc052 with <0> Job and <1> Queues
I0714 09:20:18.477458       1 enqueue.go:79] Try to enqueue PodGroup to 0 Queues
I0714 09:20:18.477533       1 allocate.go:64] Try to allocate resource to 0 Queues
I0714 09:20:18.477769       1 session.go:244] Close Session 92126ea5-ffaf-4104-8542-237da40dc052
I0714 09:20:19.480241       1 cache.go:1363] There are <0> Jobs, <1> Queues and <5> Nodes in total for scheduling.
I0714 09:20:19.480448       1 session.go:190] Open Session bdf86a2a-24cc-4a3c-a77d-f6eb0ad498f4 with <0> Job and <1> Queues
I0714 09:20:19.482407       1 enqueue.go:79] Try to enqueue PodGroup to 0 Queues
I0714 09:20:19.482508       1 allocate.go:64] Try to allocate resource to 0 Queues
I0714 09:20:19.482750       1 session.go:244] Close Session bdf86a2a-24cc-4a3c-a77d-f6eb0ad498f4
I0714 09:20:20.485090       1 cache.go:1363] There are <0> Jobs, <1> Queues and <5> Nodes in total for scheduling.
I0714 09:20:20.485218       1 session.go:190] Open Session bded8cde-5111-4210-9c06-d11857957aef with <0> Job and <1> Queues
I0714 09:20:20.486975       1 enqueue.go:79] Try to enqueue PodGroup to 0 Queues
I0714 09:20:20.487067       1 allocate.go:64] Try to allocate resource to 0 Queues
I0714 09:20:20.487292       1 session.go:244] Close Session bded8cde-5111-4210-9c06-d11857957aef
I0714 09:20:21.490347       1 cache.go:1363] There are <0> Jobs, <1> Queues and <5> Nodes in total for scheduling.
I0714 09:20:21.490519       1 session.go:190] Open Session 66f60626-673a-48df-8b69-3fb13a645a28 with <0> Job and <1> Queues
I0714 09:20:21.492589       1 enqueue.go:79] Try to enqueue PodGroup to 0 Queues
I0714 09:20:21.492667       1 allocate.go:64] Try to allocate resource to 0 Queues
I0714 09:20:21.492904       1 session.go:244] Close Session 66f60626-673a-48df-8b69-3fb13a645a28
I0714 09:20:22.495613       1 cache.go:1363] There are <0> Jobs, <1> Queues and <5> Nodes in total for scheduling.
I0714 09:20:22.495799       1 session.go:190] Open Session 1bb3f19f-5e3a-4159-95a2-e52c134a7190 with <0> Job and <1> Queues
I0714 09:20:22.498042       1 enqueue.go:79] Try to enqueue PodGroup to 0 Queues
I0714 09:20:22.498116       1 allocate.go:64] Try to allocate resource to 0 Queues
I0714 09:20:22.498337       1 session.go:244] Close Session 1bb3f19f-5e3a-4159-95a2-e52c134a7190
I0714 09:20:23.500985       1 cache.go:1363] There are <0> Jobs, <1> Queues and <5> Nodes in total for scheduling.
I0714 09:20:23.501155       1 session.go:190] Open Session 674170f5-6912-465c-b127-567e5edba474 with <0> Job and <1> Queues
I0714 09:20:23.503026       1 enqueue.go:79] Try to enqueue PodGroup to 0 Queues
I0714 09:20:23.503097       1 allocate.go:64] Try to allocate resource to 0 Queues
I0714 09:20:23.503326       1 session.go:244] Close Session 674170f5-6912-465c-b127-567e5edba474
I0714 09:20:24.506081       1 cache.go:1363] There are <0> Jobs, <1> Queues and <5> Nodes in total for scheduling.
I0714 09:20:24.506625       1 session.go:190] Open Session d22cfc2d-755f-43ac-8ea2-a72dd6fe819f with <0> Job and <1> Queues
I0714 09:20:24.508782       1 enqueue.go:79] Try to enqueue PodGroup to 0 Queues
I0714 09:20:24.508864       1 allocate.go:64] Try to allocate resource to 0 Queues
I0714 09:20:24.509100       1 session.go:244] Close Session d22cfc2d-755f-43ac-8ea2-a72dd6fe819f
I0714 09:20:25.512153       1 cache.go:1363] There are <0> Jobs, <1> Queues and <5> Nodes in total for scheduling.
I0714 09:20:25.512368       1 session.go:190] Open Session 71f35bb2-81ff-43bb-b320-050428af98a8 with <0> Job and <1> Queues
I0714 09:20:25.514336       1 enqueue.go:79] Try to enqueue PodGroup to 0 Queues
I0714 09:20:25.514406       1 allocate.go:64] Try to allocate resource to 0 Queues
I0714 09:20:25.514643       1 session.go:244] Close Session 71f35bb2-81ff-43bb-b320-050428af98a8
I0714 09:20:26.516895       1 cache.go:1363] There are <0> Jobs, <1> Queues and <5> Nodes in total for scheduling.
I0714 09:20:26.517059       1 session.go:190] Open Session c2ab0dc7-8eb1-47da-b4d9-824ec937e357 with <0> Job and <1> Queues
I0714 09:20:26.519195       1 enqueue.go:79] Try to enqueue PodGroup to 0 Queues
I0714 09:20:26.519277       1 allocate.go:64] Try to allocate resource to 0 Queues
I0714 09:20:26.519498       1 session.go:244] Close Session c2ab0dc7-8eb1-47da-b4d9-824ec937e357
I0714 09:20:27.522850       1 cache.go:1363] There are <0> Jobs, <1> Queues and <5> Nodes in total for scheduling.
I0714 09:20:27.523035       1 session.go:190] Open Session d3f32df2-4aa0-4fc4-9b9b-02bbf2380c06 with <0> Job and <1> Queues
I0714 09:20:27.525031       1 enqueue.go:79] Try to enqueue PodGroup to 0 Queues
I0714 09:20:27.525103       1 allocate.go:64] Try to allocate resource to 0 Queues
I0714 09:20:27.525352       1 session.go:244] Close Session d3f32df2-4aa0-4fc4-9b9b-02bbf2380c06
I0714 09:20:28.528113       1 cache.go:1363] There are <0> Jobs, <1> Queues and <5> Nodes in total for scheduling.
I0714 09:20:28.528322       1 session.go:190] Open Session 33413d30-cfb9-49fc-8c6a-84f26815418e with <0> Job and <1> Queues
I0714 09:20:28.530457       1 enqueue.go:79] Try to enqueue PodGroup to 0 Queues
I0714 09:20:28.530529       1 allocate.go:64] Try to allocate resource to 0 Queues
I0714 09:20:28.530771       1 session.go:244] Close Session 33413d30-cfb9-49fc-8c6a-84f26815418e
I0714 09:20:29.533231       1 cache.go:1363] There are <0> Jobs, <1> Queues and <5> Nodes in total for scheduling.
I0714 09:20:29.533397       1 session.go:190] Open Session 102deb54-2ed5-4a04-a38b-c4d5cd6726fa with <0> Job and <1> Queues
I0714 09:20:29.535580       1 enqueue.go:79] Try to enqueue PodGroup to 0 Queues
I0714 09:20:29.535656       1 allocate.go:64] Try to allocate resource to 0 Queues
I0714 09:20:29.535879       1 session.go:244] Close Session 102deb54-2ed5-4a04-a38b-c4d5cd6726fa
I0714 09:20:30.538138       1 cache.go:1363] There are <0> Jobs, <1> Queues and <5> Nodes in total for scheduling.
I0714 09:20:30.538327       1 session.go:190] Open Session fccdb990-746d-45ab-a7bb-3f7a434d1b21 with <0> Job and <1> Queues
I0714 09:20:30.540468       1 enqueue.go:79] Try to enqueue PodGroup to 0 Queues
I0714 09:20:30.540538       1 allocate.go:64] Try to allocate resource to 0 Queues
I0714 09:20:30.540783       1 session.go:244] Close Session fccdb990-746d-45ab-a7bb-3f7a434d1b21
I0714 09:20:31.543259       1 cache.go:1363] There are <0> Jobs, <1> Queues and <5> Nodes in total for scheduling.
I0714 09:20:31.543415       1 session.go:190] Open Session 87411f50-d02d-47ba-b4af-090f1de5f675 with <0> Job and <1> Queues
I0714 09:20:31.545349       1 enqueue.go:79] Try to enqueue PodGroup to 0 Queues
I0714 09:20:31.545429       1 allocate.go:64] Try to allocate resource to 0 Queues
I0714 09:20:31.545651       1 session.go:244] Close Session 87411f50-d02d-47ba-b4af-090f1de5f675
I0714 09:20:32.548163       1 cache.go:1363] There are <0> Jobs, <1> Queues and <5> Nodes in total for scheduling.
I0714 09:20:32.548388       1 session.go:190] Open Session ab3a6e64-3060-4696-9d92-c26b464a3bc5 with <0> Job and <1> Queues
I0714 09:20:32.550554       1 enqueue.go:79] Try to enqueue PodGroup to 0 Queues
I0714 09:20:32.550627       1 allocate.go:64] Try to allocate resource to 0 Queues
I0714 09:20:32.550858       1 session.go:244] Close Session ab3a6e64-3060-4696-9d92-c26b464a3bc5
I0714 09:20:33.553389       1 cache.go:1363] There are <0> Jobs, <1> Queues and <5> Nodes in total for scheduling.
I0714 09:20:33.553562       1 session.go:190] Open Session 4094e0df-1533-44e7-b5c3-12e9596aa2e7 with <0> Job and <1> Queues
I0714 09:20:33.556643       1 enqueue.go:79] Try to enqueue PodGroup to 0 Queues
I0714 09:20:33.556735       1 allocate.go:64] Try to allocate resource to 0 Queues
I0714 09:20:33.557041       1 session.go:244] Close Session 4094e0df-1533-44e7-b5c3-12e9596aa2e7
I0714 09:20:34.559552       1 cache.go:1363] There are <0> Jobs, <1> Queues and <5> Nodes in total for scheduling.
I0714 09:20:34.559723       1 session.go:190] Open Session 3907e041-c025-49ad-bce1-c42098a2a0c0 with <0> Job and <1> Queues
I0714 09:20:34.561691       1 enqueue.go:79] Try to enqueue PodGroup to 0 Queues
I0714 09:20:34.561776       1 allocate.go:64] Try to allocate resource to 0 Queues
I0714 09:20:34.561995       1 session.go:244] Close Session 3907e041-c025-49ad-bce1-c42098a2a0c0
I0714 09:20:35.564109       1 cache.go:1363] There are <0> Jobs, <1> Queues and <5> Nodes in total for scheduling.
I0714 09:20:35.564349       1 session.go:190] Open Session 0d21daeb-5d32-4003-8796-b75035475edc with <0> Job and <1> Queues
I0714 09:20:35.566257       1 enqueue.go:79] Try to enqueue PodGroup to 0 Queues
I0714 09:20:35.566351       1 allocate.go:64] Try to allocate resource to 0 Queues
I0714 09:20:35.566570       1 session.go:244] Close Session 0d21daeb-5d32-4003-8796-b75035475edc
I0714 09:20:36.568989       1 cache.go:1363] There are <0> Jobs, <1> Queues and <5> Nodes in total for scheduling.
I0714 09:20:36.569148       1 session.go:190] Open Session 8627c406-8699-4b40-98aa-c9d5425889d9 with <0> Job and <1> Queues
I0714 09:20:36.571033       1 enqueue.go:79] Try to enqueue PodGroup to 0 Queues
I0714 09:20:36.571104       1 allocate.go:64] Try to allocate resource to 0 Queues
I0714 09:20:36.571320       1 session.go:244] Close Session 8627c406-8699-4b40-98aa-c9d5425889d9
I0714 09:20:36.657015       1 cache.go:1489] The metrics type is not set in the volcano scheduler configmap file. As a result, the CPU and memory load information of the node is not collected.
I0714 09:20:37.573566       1 cache.go:1363] There are <0> Jobs, <1> Queues and <5> Nodes in total for scheduling.
I0714 09:20:37.573755       1 session.go:190] Open Session d61bfaf7-acc7-4c30-a7c2-a6481bd46427 with <0> Job and <1> Queues
I0714 09:20:37.575694       1 enqueue.go:79] Try to enqueue PodGroup to 0 Queues
I0714 09:20:37.575770       1 allocate.go:64] Try to allocate resource to 0 Queues
I0714 09:20:37.576017       1 session.go:244] Close Session d61bfaf7-acc7-4c30-a7c2-a6481bd46427
I0714 09:20:38.578947       1 cache.go:1363] There are <0> Jobs, <1> Queues and <5> Nodes in total for scheduling.
I0714 09:20:38.579125       1 session.go:190] Open Session 6f542196-ab8f-4360-89cb-4c530ee14c79 with <0> Job and <1> Queues
I0714 09:20:38.581047       1 enqueue.go:79] Try to enqueue PodGroup to 0 Queues
I0714 09:20:38.581126       1 allocate.go:64] Try to allocate resource to 0 Queues
I0714 09:20:38.581341       1 session.go:244] Close Session 6f542196-ab8f-4360-89cb-4c530ee14c79
I0714 09:20:39.583751       1 cache.go:1363] There are <0> Jobs, <1> Queues and <5> Nodes in total for scheduling.
I0714 09:20:39.583928       1 session.go:190] Open Session 2b69dc83-cbbd-4459-9042-9ec85d78892c with <0> Job and <1> Queues
I0714 09:20:39.585861       1 enqueue.go:79] Try to enqueue PodGroup to 0 Queues
I0714 09:20:39.585942       1 allocate.go:64] Try to allocate resource to 0 Queues
I0714 09:20:39.586171       1 session.go:244] Close Session 2b69dc83-cbbd-4459-9042-9ec85d78892c
I0714 09:20:40.589468       1 cache.go:1363] There are <0> Jobs, <1> Queues and <5> Nodes in total for scheduling.
I0714 09:20:40.589641       1 session.go:190] Open Session 49cd005e-488e-4944-90b2-9c53716e26f9 with <0> Job and <1> Queues
I0714 09:20:40.591593       1 enqueue.go:79] Try to enqueue PodGroup to 0 Queues
I0714 09:20:40.591671       1 allocate.go:64] Try to allocate resource to 0 Queues
I0714 09:20:40.591890       1 session.go:244] Close Session 49cd005e-488e-4944-90b2-9c53716e26f9
I0714 09:20:41.594574       1 cache.go:1363] There are <0> Jobs, <1> Queues and <5> Nodes in total for scheduling.
I0714 09:20:41.594749       1 session.go:190] Open Session d7fabd4d-d575-40fd-81eb-814a775d32af with <0> Job and <1> Queues
I0714 09:20:41.596708       1 enqueue.go:79] Try to enqueue PodGroup to 0 Queues
I0714 09:20:41.596781       1 allocate.go:64] Try to allocate resource to 0 Queues
I0714 09:20:41.596988       1 session.go:244] Close Session d7fabd4d-d575-40fd-81eb-814a775d32af
I0714 09:20:42.599647       1 cache.go:1363] There are <0> Jobs, <1> Queues and <5> Nodes in total for scheduling.
I0714 09:20:42.599819       1 session.go:190] Open Session 6bb43fda-76d7-4b3d-a53d-3cb2853520c8 with <0> Job and <1> Queues
I0714 09:20:42.601916       1 enqueue.go:79] Try to enqueue PodGroup to 0 Queues
I0714 09:20:42.601994       1 allocate.go:64] Try to allocate resource to 0 Queues
I0714 09:20:42.602205       1 session.go:244] Close Session 6bb43fda-76d7-4b3d-a53d-3cb2853520c8
I0714 09:20:43.604731       1 cache.go:1363] There are <0> Jobs, <1> Queues and <5> Nodes in total for scheduling.
I0714 09:20:43.604899       1 session.go:190] Open Session 3bd890d5-f639-498b-a4ac-9edd9631bdd0 with <0> Job and <1> Queues
I0714 09:20:43.606873       1 enqueue.go:79] Try to enqueue PodGroup to 0 Queues
I0714 09:20:43.606946       1 allocate.go:64] Try to allocate resource to 0 Queues
I0714 09:20:43.607174       1 session.go:244] Close Session 3bd890d5-f639-498b-a4ac-9edd9631bdd0
I0714 09:20:44.609867       1 cache.go:1363] There are <0> Jobs, <1> Queues and <5> Nodes in total for scheduling.
I0714 09:20:44.610045       1 session.go:190] Open Session 211f5ee2-4411-47f7-a5d4-a131d5dffdaa with <0> Job and <1> Queues
I0714 09:20:44.611947       1 enqueue.go:79] Try to enqueue PodGroup to 0 Queues
I0714 09:20:44.612124       1 allocate.go:64] Try to allocate resource to 0 Queues
I0714 09:20:44.612376       1 session.go:244] Close Session 211f5ee2-4411-47f7-a5d4-a131d5dffdaa
I0714 09:20:45.614618       1 cache.go:1363] There are <0> Jobs, <1> Queues and <5> Nodes in total for scheduling.
I0714 09:20:45.614765       1 session.go:190] Open Session 2729e29f-60af-4ed6-8102-ff3ea4a8491c with <0> Job and <1> Queues
I0714 09:20:45.616771       1 enqueue.go:79] Try to enqueue PodGroup to 0 Queues
I0714 09:20:45.616843       1 allocate.go:64] Try to allocate resource to 0 Queues
I0714 09:20:45.617047       1 session.go:244] Close Session 2729e29f-60af-4ed6-8102-ff3ea4a8491c
I0714 09:20:46.619318       1 cache.go:1363] There are <0> Jobs, <1> Queues and <5> Nodes in total for scheduling.
I0714 09:20:46.619405       1 session.go:190] Open Session 37f5a80b-784f-476c-aaaf-6bac4b9bcc97 with <0> Job and <1> Queues
I0714 09:20:46.620777       1 enqueue.go:79] Try to enqueue PodGroup to 0 Queues
I0714 09:20:46.620846       1 allocate.go:64] Try to allocate resource to 0 Queues
I0714 09:20:46.620989       1 session.go:244] Close Session 37f5a80b-784f-476c-aaaf-6bac4b9bcc97
I0714 09:20:47.623759       1 cache.go:1363] There are <0> Jobs, <1> Queues and <5> Nodes in total for scheduling.
I0714 09:20:47.623927       1 session.go:190] Open Session 74704213-f04e-44ac-9a8a-1d95f3f358b4 with <0> Job and <1> Queues
I0714 09:20:47.625857       1 enqueue.go:79] Try to enqueue PodGroup to 0 Queues
I0714 09:20:47.625931       1 allocate.go:64] Try to allocate resource to 0 Queues
I0714 09:20:47.626150       1 session.go:244] Close Session 74704213-f04e-44ac-9a8a-1d95f3f358b4
I0714 09:20:48.629438       1 cache.go:1363] There are <0> Jobs, <1> Queues and <5> Nodes in total for scheduling.
I0714 09:20:48.629619       1 session.go:190] Open Session 47ec4de6-069f-46a9-a005-43bec0383188 with <0> Job and <1> Queues
I0714 09:20:48.631460       1 enqueue.go:79] Try to enqueue PodGroup to 0 Queues
I0714 09:20:48.631529       1 allocate.go:64] Try to allocate resource to 0 Queues
I0714 09:20:48.631748       1 session.go:244] Close Session 47ec4de6-069f-46a9-a005-43bec0383188
I0714 09:20:49.634981       1 cache.go:1363] There are <0> Jobs, <1> Queues and <5> Nodes in total for scheduling.
I0714 09:20:49.635163       1 session.go:190] Open Session 59ab5767-c356-415b-876b-76294411f054 with <0> Job and <1> Queues
I0714 09:20:49.637211       1 enqueue.go:79] Try to enqueue PodGroup to 0 Queues
I0714 09:20:49.637279       1 allocate.go:64] Try to allocate resource to 0 Queues
I0714 09:20:49.637515       1 session.go:244] Close Session 59ab5767-c356-415b-876b-76294411f054
I0714 09:20:50.639068       1 cache.go:1363] There are <0> Jobs, <1> Queues and <5> Nodes in total for scheduling.
I0714 09:20:50.639184       1 session.go:190] Open Session 15bdbf6f-d9d2-4320-9c74-53222c446537 with <0> Job and <1> Queues
I0714 09:20:50.640731       1 enqueue.go:79] Try to enqueue PodGroup to 0 Queues
I0714 09:20:50.640803       1 allocate.go:64] Try to allocate resource to 0 Queues
I0714 09:20:50.640986       1 session.go:244] Close Session 15bdbf6f-d9d2-4320-9c74-53222c446537
I0714 09:20:51.643590       1 cache.go:1363] There are <0> Jobs, <1> Queues and <5> Nodes in total for scheduling.
I0714 09:20:51.643763       1 session.go:190] Open Session 28f78497-74e3-4df9-bfbd-7dbe2e56bcf5 with <0> Job and <1> Queues
I0714 09:20:51.645782       1 enqueue.go:79] Try to enqueue PodGroup to 0 Queues
I0714 09:20:51.645870       1 allocate.go:64] Try to allocate resource to 0 Queues
I0714 09:20:51.646859       1 session.go:244] Close Session 28f78497-74e3-4df9-bfbd-7dbe2e56bcf5
I0714 09:20:52.649895       1 cache.go:1363] There are <0> Jobs, <1> Queues and <5> Nodes in total for scheduling.
I0714 09:20:52.650077       1 session.go:190] Open Session 1d49209f-5b14-4aaa-b3db-ba17f83c0390 with <0> Job and <1> Queues
I0714 09:20:52.651975       1 enqueue.go:79] Try to enqueue PodGroup to 0 Queues
I0714 09:20:52.652057       1 allocate.go:64] Try to allocate resource to 0 Queues
I0714 09:20:52.652317       1 session.go:244] Close Session 1d49209f-5b14-4aaa-b3db-ba17f83c0390
I0714 09:20:53.654899       1 cache.go:1363] There are <0> Jobs, <1> Queues and <5> Nodes in total for scheduling.
I0714 09:20:53.655096       1 session.go:190] Open Session 7eb10e31-7b81-450e-a2ad-6174f9e9f05f with <0> Job and <1> Queues
I0714 09:20:53.657405       1 enqueue.go:79] Try to enqueue PodGroup to 0 Queues
I0714 09:20:53.657503       1 allocate.go:64] Try to allocate resource to 0 Queues
I0714 09:20:53.657730       1 session.go:244] Close Session 7eb10e31-7b81-450e-a2ad-6174f9e9f05f
I0714 09:20:54.659819       1 cache.go:1363] There are <0> Jobs, <1> Queues and <5> Nodes in total for scheduling.
I0714 09:20:54.659966       1 session.go:190] Open Session 37b41481-fc9b-4d4d-84ab-944953511088 with <0> Job and <1> Queues
I0714 09:20:54.661757       1 enqueue.go:79] Try to enqueue PodGroup to 0 Queues
I0714 09:20:54.661836       1 allocate.go:64] Try to allocate resource to 0 Queues
I0714 09:20:54.662111       1 session.go:244] Close Session 37b41481-fc9b-4d4d-84ab-944953511088
I0714 09:20:55.664493       1 cache.go:1363] There are <0> Jobs, <1> Queues and <5> Nodes in total for scheduling.
I0714 09:20:55.664659       1 session.go:190] Open Session dc4ba2f6-af12-4c1b-bc82-bba7b3eadeff with <0> Job and <1> Queues
I0714 09:20:55.666475       1 enqueue.go:79] Try to enqueue PodGroup to 0 Queues
I0714 09:20:55.666558       1 allocate.go:64] Try to allocate resource to 0 Queues
I0714 09:20:55.666774       1 session.go:244] Close Session dc4ba2f6-af12-4c1b-bc82-bba7b3eadeff
I0714 09:20:56.669005       1 cache.go:1363] There are <0> Jobs, <1> Queues and <5> Nodes in total for scheduling.
I0714 09:20:56.669169       1 session.go:190] Open Session 99be5dfb-6e73-4e05-a226-b2235058aeeb with <0> Job and <1> Queues
I0714 09:20:56.670993       1 enqueue.go:79] Try to enqueue PodGroup to 0 Queues
I0714 09:20:56.671070       1 allocate.go:64] Try to allocate resource to 0 Queues
I0714 09:20:56.671300       1 session.go:244] Close Session 99be5dfb-6e73-4e05-a226-b2235058aeeb
I0714 09:20:57.673582       1 cache.go:1363] There are <0> Jobs, <1> Queues and <5> Nodes in total for scheduling.
I0714 09:20:57.673765       1 session.go:190] Open Session 8511e07c-3fbf-4601-8796-84e5a0549336 with <0> Job and <1> Queues
I0714 09:20:57.675670       1 enqueue.go:79] Try to enqueue PodGroup to 0 Queues
I0714 09:20:57.675747       1 allocate.go:64] Try to allocate resource to 0 Queues
I0714 09:20:57.675945       1 session.go:244] Close Session 8511e07c-3fbf-4601-8796-84e5a0549336
I0714 09:20:58.678345       1 cache.go:1363] There are <0> Jobs, <1> Queues and <5> Nodes in total for scheduling.
I0714 09:20:58.678515       1 session.go:190] Open Session 88604f48-6083-42bf-8d27-d627bcf701a6 with <0> Job and <1> Queues
I0714 09:20:58.680488       1 enqueue.go:79] Try to enqueue PodGroup to 0 Queues
I0714 09:20:58.680569       1 allocate.go:64] Try to allocate resource to 0 Queues
I0714 09:20:58.680781       1 session.go:244] Close Session 88604f48-6083-42bf-8d27-d627bcf701a6
I0714 09:20:59.683620       1 cache.go:1363] There are <0> Jobs, <1> Queues and <5> Nodes in total for scheduling.
I0714 09:20:59.683786       1 session.go:190] Open Session 603d7787-4661-4f61-89c2-fabb64fcbe4c with <0> Job and <1> Queues
I0714 09:20:59.685719       1 enqueue.go:79] Try to enqueue PodGroup to 0 Queues
I0714 09:20:59.685798       1 allocate.go:64] Try to allocate resource to 0 Queues
I0714 09:20:59.686037       1 session.go:244] Close Session 603d7787-4661-4f61-89c2-fabb64fcbe4c
I0714 09:21:00.688858       1 cache.go:1363] There are <0> Jobs, <1> Queues and <5> Nodes in total for scheduling.
I0714 09:21:00.689038       1 session.go:190] Open Session e8e8a0ec-d381-410d-af9f-68507a901ee0 with <0> Job and <1> Queues
I0714 09:21:00.690863       1 enqueue.go:79] Try to enqueue PodGroup to 0 Queues
I0714 09:21:00.690949       1 allocate.go:64] Try to allocate resource to 0 Queues
I0714 09:21:00.691167       1 session.go:244] Close Session e8e8a0ec-d381-410d-af9f-68507a901ee0
I0714 09:21:01.693325       1 cache.go:1363] There are <0> Jobs, <1> Queues and <5> Nodes in total for scheduling.
I0714 09:21:01.693488       1 session.go:190] Open Session 8ab8348a-aa85-4b18-9784-eb18e5c4db41 with <0> Job and <1> Queues
I0714 09:21:01.695321       1 enqueue.go:79] Try to enqueue PodGroup to 0 Queues
I0714 09:21:01.695391       1 allocate.go:64] Try to allocate resource to 0 Queues
I0714 09:21:01.695600       1 session.go:244] Close Session 8ab8348a-aa85-4b18-9784-eb18e5c4db41
I0714 09:21:02.698467       1 cache.go:1363] There are <0> Jobs, <1> Queues and <5> Nodes in total for scheduling.
I0714 09:21:02.698652       1 session.go:190] Open Session 3b2ee950-9f45-4ec8-a197-3d27160d3f72 with <0> Job and <1> Queues
I0714 09:21:02.700545       1 enqueue.go:79] Try to enqueue PodGroup to 0 Queues
I0714 09:21:02.700619       1 allocate.go:64] Try to allocate resource to 0 Queues
I0714 09:21:02.700850       1 session.go:244] Close Session 3b2ee950-9f45-4ec8-a197-3d27160d3f72
I0714 09:21:03.703951       1 cache.go:1363] There are <0> Jobs, <1> Queues and <5> Nodes in total for scheduling.
I0714 09:21:03.704131       1 session.go:190] Open Session 9bed8e8a-1f90-44de-9614-5819f604cf6b with <0> Job and <1> Queues
I0714 09:21:03.706033       1 enqueue.go:79] Try to enqueue PodGroup to 0 Queues
I0714 09:21:03.706113       1 allocate.go:64] Try to allocate resource to 0 Queues
I0714 09:21:03.706338       1 session.go:244] Close Session 9bed8e8a-1f90-44de-9614-5819f604cf6b
I0714 09:21:04.708945       1 cache.go:1363] There are <0> Jobs, <1> Queues and <5> Nodes in total for scheduling.
I0714 09:21:04.709113       1 session.go:190] Open Session d5eb119d-44f2-4d04-ab67-11602b85e96f with <0> Job and <1> Queues
I0714 09:21:04.711026       1 enqueue.go:79] Try to enqueue PodGroup to 0 Queues
I0714 09:21:04.711114       1 allocate.go:64] Try to allocate resource to 0 Queues
I0714 09:21:04.711332       1 session.go:244] Close Session d5eb119d-44f2-4d04-ab67-11602b85e96f
I0714 09:21:05.715177       1 cache.go:1363] There are <0> Jobs, <1> Queues and <5> Nodes in total for scheduling.
I0714 09:21:05.715368       1 session.go:190] Open Session e467089d-179f-4be7-b613-c74e35a1afcf with <0> Job and <1> Queues
I0714 09:21:05.717586       1 enqueue.go:79] Try to enqueue PodGroup to 0 Queues
I0714 09:21:05.717688       1 allocate.go:64] Try to allocate resource to 0 Queues
I0714 09:21:05.717921       1 session.go:244] Close Session e467089d-179f-4be7-b613-c74e35a1afcf
I0714 09:21:06.657313       1 cache.go:1489] The metrics type is not set in the volcano scheduler configmap file. As a result, the CPU and memory load information of the node is not collected.
I0714 09:21:06.721000       1 cache.go:1363] There are <0> Jobs, <1> Queues and <5> Nodes in total for scheduling.
I0714 09:21:06.721135       1 session.go:190] Open Session c4c8a4c2-ca79-4c52-a671-0a2b04b6b9f2 with <0> Job and <1> Queues
I0714 09:21:06.723184       1 enqueue.go:79] Try to enqueue PodGroup to 0 Queues
I0714 09:21:06.723273       1 allocate.go:64] Try to allocate resource to 0 Queues
I0714 09:21:06.723525       1 session.go:244] Close Session c4c8a4c2-ca79-4c52-a671-0a2b04b6b9f2
I0714 09:21:07.726153       1 cache.go:1363] There are <0> Jobs, <1> Queues and <5> Nodes in total for scheduling.
I0714 09:21:07.726327       1 session.go:190] Open Session 9dbfc02b-30a9-4981-a5b8-deb304edafa3 with <0> Job and <1> Queues
I0714 09:21:07.728571       1 enqueue.go:79] Try to enqueue PodGroup to 0 Queues
I0714 09:21:07.728648       1 allocate.go:64] Try to allocate resource to 0 Queues
I0714 09:21:07.728867       1 session.go:244] Close Session 9dbfc02b-30a9-4981-a5b8-deb304edafa3
I0714 09:21:08.731410       1 cache.go:1363] There are <0> Jobs, <1> Queues and <5> Nodes in total for scheduling.
I0714 09:21:08.731580       1 session.go:190] Open Session eb996fb1-a8eb-4929-aa87-298bf71bb3dc with <0> Job and <1> Queues
I0714 09:21:08.733905       1 enqueue.go:79] Try to enqueue PodGroup to 0 Queues
I0714 09:21:08.733981       1 allocate.go:64] Try to allocate resource to 0 Queues
I0714 09:21:08.734201       1 session.go:244] Close Session eb996fb1-a8eb-4929-aa87-298bf71bb3dc
I0714 09:21:09.736573       1 cache.go:1363] There are <0> Jobs, <1> Queues and <5> Nodes in total for scheduling.
I0714 09:21:09.736755       1 session.go:190] Open Session a7df3d28-5785-4070-8240-6bd8047e7a09 with <0> Job and <1> Queues
I0714 09:21:09.738955       1 enqueue.go:79] Try to enqueue PodGroup to 0 Queues
I0714 09:21:09.739038       1 allocate.go:64] Try to allocate resource to 0 Queues
I0714 09:21:09.739260       1 session.go:244] Close Session a7df3d28-5785-4070-8240-6bd8047e7a09
I0714 09:21:10.742016       1 cache.go:1363] There are <0> Jobs, <1> Queues and <5> Nodes in total for scheduling.
I0714 09:21:10.742209       1 session.go:190] Open Session 5a0829b4-3ada-4e43-a8e8-370400dd57b9 with <0> Job and <1> Queues
I0714 09:21:10.744147       1 enqueue.go:79] Try to enqueue PodGroup to 0 Queues
I0714 09:21:10.744218       1 allocate.go:64] Try to allocate resource to 0 Queues
I0714 09:21:10.744499       1 session.go:244] Close Session 5a0829b4-3ada-4e43-a8e8-370400dd57b9
I0714 09:21:11.747574       1 cache.go:1363] There are <0> Jobs, <1> Queues and <5> Nodes in total for scheduling.
I0714 09:21:11.747744       1 session.go:190] Open Session 92f0ffbf-5e12-4c3d-8562-a9aa9251ff62 with <0> Job and <1> Queues
I0714 09:21:11.749663       1 enqueue.go:79] Try to enqueue PodGroup to 0 Queues
I0714 09:21:11.749730       1 allocate.go:64] Try to allocate resource to 0 Queues
I0714 09:21:11.749937       1 session.go:244] Close Session 92f0ffbf-5e12-4c3d-8562-a9aa9251ff62
I0714 09:21:12.752139       1 cache.go:1363] There are <0> Jobs, <1> Queues and <5> Nodes in total for scheduling.
I0714 09:21:12.752369       1 session.go:190] Open Session 24851b1b-c6b9-4ac0-89e4-d1579691c595 with <0> Job and <1> Queues
I0714 09:21:12.754409       1 enqueue.go:79] Try to enqueue PodGroup to 0 Queues
I0714 09:21:12.754478       1 allocate.go:64] Try to allocate resource to 0 Queues
I0714 09:21:12.754687       1 session.go:244] Close Session 24851b1b-c6b9-4ac0-89e4-d1579691c595
W0714 09:21:13.276994       1 event_handlers.go:181] Not support non-csi pvc.
I0714 09:21:13.277761       1 event_handlers.go:442] Deleted pod <default/yolo-cls> from cache.
W0714 09:21:13.348949       1 event_handlers.go:181] Not support non-csi pvc.
I0714 09:21:13.359237       1 event_handlers.go:442] Deleted pod <default/yolo-det> from cache.
W0714 09:21:13.424428       1 event_handlers.go:181] Not support non-csi pvc.
I0714 09:21:13.429733       1 event_handlers.go:442] Deleted pod <default/yolo-seg> from cache.
W0714 09:21:13.482288       1 event_handlers.go:181] Not support non-csi pvc.
I0714 09:21:13.483694       1 event_handlers.go:442] Deleted pod <default/yolo-obb> from cache.
W0714 09:21:13.543163       1 event_handlers.go:181] Not support non-csi pvc.
I0714 09:21:13.548636       1 event_handlers.go:442] Deleted pod <default/yolo-pos> from cache.
I0714 09:21:13.756913       1 cache.go:1363] There are <0> Jobs, <1> Queues and <5> Nodes in total for scheduling.
I0714 09:21:13.757037       1 session.go:190] Open Session 4936a2b5-95a2-4760-b8b2-6900d9b684fb with <0> Job and <1> Queues
I0714 09:21:13.758697       1 enqueue.go:79] Try to enqueue PodGroup to 0 Queues
I0714 09:21:13.758764       1 allocate.go:64] Try to allocate resource to 0 Queues
I0714 09:21:13.758968       1 session.go:244] Close Session 4936a2b5-95a2-4760-b8b2-6900d9b684fb
I0714 09:21:14.761335       1 cache.go:1363] There are <0> Jobs, <1> Queues and <5> Nodes in total for scheduling.
I0714 09:21:14.761473       1 session.go:190] Open Session 5b229b9d-0e8e-4ea4-9bb6-cd9c359d559a with <0> Job and <1> Queues
I0714 09:21:14.763058       1 enqueue.go:79] Try to enqueue PodGroup to 0 Queues
I0714 09:21:14.763126       1 allocate.go:64] Try to allocate resource to 0 Queues
I0714 09:21:14.763332       1 session.go:244] Close Session 5b229b9d-0e8e-4ea4-9bb6-cd9c359d559a
I0714 09:21:15.765536       1 cache.go:1363] There are <0> Jobs, <1> Queues and <5> Nodes in total for scheduling.
I0714 09:21:15.765680       1 session.go:190] Open Session ed55a31b-e6d9-4a1f-9b64-453b0e7a240c with <0> Job and <1> Queues
I0714 09:21:15.767258       1 enqueue.go:79] Try to enqueue PodGroup to 0 Queues
I0714 09:21:15.767325       1 allocate.go:64] Try to allocate resource to 0 Queues
I0714 09:21:15.767541       1 session.go:244] Close Session ed55a31b-e6d9-4a1f-9b64-453b0e7a240c
I0714 09:21:16.769807       1 cache.go:1363] There are <0> Jobs, <1> Queues and <5> Nodes in total for scheduling.
I0714 09:21:16.769984       1 session.go:190] Open Session 6f1f599c-0b94-4639-bc03-f656a3954a66 with <0> Job and <1> Queues
I0714 09:21:16.771170       1 enqueue.go:79] Try to enqueue PodGroup to 0 Queues
I0714 09:21:16.771221       1 allocate.go:64] Try to allocate resource to 0 Queues
I0714 09:21:16.771371       1 session.go:244] Close Session 6f1f599c-0b94-4639-bc03-f656a3954a66
I0714 09:21:17.773474       1 cache.go:1363] There are <0> Jobs, <1> Queues and <5> Nodes in total for scheduling.
I0714 09:21:17.773571       1 session.go:190] Open Session 3a79e243-2f1b-40e3-b3c6-4246d53e856b with <0> Job and <1> Queues
I0714 09:21:17.774741       1 enqueue.go:79] Try to enqueue PodGroup to 0 Queues
I0714 09:21:17.774790       1 allocate.go:64] Try to allocate resource to 0 Queues
I0714 09:21:17.774975       1 session.go:244] Close Session 3a79e243-2f1b-40e3-b3c6-4246d53e856b
I0714 09:21:18.777162       1 cache.go:1363] There are <0> Jobs, <1> Queues and <5> Nodes in total for scheduling.
I0714 09:21:18.777331       1 session.go:190] Open Session 99e99492-6d62-4e8e-9c9a-16c79083d743 with <0> Job and <1> Queues
I0714 09:21:18.779269       1 enqueue.go:79] Try to enqueue PodGroup to 0 Queues
I0714 09:21:18.779340       1 allocate.go:64] Try to allocate resource to 0 Queues
I0714 09:21:18.779589       1 session.go:244] Close Session 99e99492-6d62-4e8e-9c9a-16c79083d743
I0714 09:21:19.781555       1 cache.go:1363] There are <0> Jobs, <1> Queues and <5> Nodes in total for scheduling.
I0714 09:21:19.781724       1 session.go:190] Open Session 2c263ae6-7cad-4f23-982c-93829cef8e1e with <0> Job and <1> Queues
I0714 09:21:19.784707       1 enqueue.go:79] Try to enqueue PodGroup to 0 Queues
I0714 09:21:19.784790       1 allocate.go:64] Try to allocate resource to 0 Queues
I0714 09:21:19.785010       1 session.go:244] Close Session 2c263ae6-7cad-4f23-982c-93829cef8e1e
I0714 09:21:20.788513       1 cache.go:1363] There are <0> Jobs, <1> Queues and <5> Nodes in total for scheduling.
I0714 09:21:20.788688       1 session.go:190] Open Session f4d6173f-1a7a-44d1-9de5-bde8776c0129 with <0> Job and <1> Queues
I0714 09:21:20.790371       1 enqueue.go:79] Try to enqueue PodGroup to 0 Queues
I0714 09:21:20.790440       1 allocate.go:64] Try to allocate resource to 0 Queues
I0714 09:21:20.790676       1 session.go:244] Close Session f4d6173f-1a7a-44d1-9de5-bde8776c0129
I0714 09:21:21.793718       1 cache.go:1363] There are <0> Jobs, <1> Queues and <5> Nodes in total for scheduling.
I0714 09:21:21.793901       1 session.go:190] Open Session 7d0f4b18-324d-41ae-bf05-59c3d4593fc8 with <0> Job and <1> Queues
I0714 09:21:21.795592       1 enqueue.go:79] Try to enqueue PodGroup to 0 Queues
I0714 09:21:21.795660       1 allocate.go:64] Try to allocate resource to 0 Queues
I0714 09:21:21.795873       1 session.go:244] Close Session 7d0f4b18-324d-41ae-bf05-59c3d4593fc8
I0714 09:21:22.798388       1 cache.go:1363] There are <0> Jobs, <1> Queues and <5> Nodes in total for scheduling.
I0714 09:21:22.798622       1 session.go:190] Open Session 1c6d8a20-6da1-48e7-b6d7-3b7521ba0e24 with <0> Job and <1> Queues
I0714 09:21:22.800453       1 enqueue.go:79] Try to enqueue PodGroup to 0 Queues
I0714 09:21:22.800527       1 allocate.go:64] Try to allocate resource to 0 Queues
I0714 09:21:22.800763       1 session.go:244] Close Session 1c6d8a20-6da1-48e7-b6d7-3b7521ba0e24
I0714 09:21:23.803359       1 cache.go:1363] There are <0> Jobs, <1> Queues and <5> Nodes in total for scheduling.
I0714 09:21:23.803562       1 session.go:190] Open Session a60a556d-9854-4824-89d7-7dcb6c956d6b with <0> Job and <1> Queues
I0714 09:21:23.805366       1 enqueue.go:79] Try to enqueue PodGroup to 0 Queues
I0714 09:21:23.805438       1 allocate.go:64] Try to allocate resource to 0 Queues
I0714 09:21:23.805663       1 session.go:244] Close Session a60a556d-9854-4824-89d7-7dcb6c956d6b
I0714 09:21:24.808659       1 cache.go:1363] There are <0> Jobs, <1> Queues and <5> Nodes in total for scheduling.
I0714 09:21:24.808820       1 session.go:190] Open Session 359ca668-bffb-4a7d-9469-f1b3ec4fcfe6 with <0> Job and <1> Queues
I0714 09:21:24.810573       1 enqueue.go:79] Try to enqueue PodGroup to 0 Queues
I0714 09:21:24.810640       1 allocate.go:64] Try to allocate resource to 0 Queues
I0714 09:21:24.810876       1 session.go:244] Close Session 359ca668-bffb-4a7d-9469-f1b3ec4fcfe6
I0714 09:21:25.813517       1 cache.go:1363] There are <0> Jobs, <1> Queues and <5> Nodes in total for scheduling.
I0714 09:21:25.813669       1 session.go:190] Open Session 0c7e3a07-e6fd-4728-8671-4fd0d3bf67cb with <0> Job and <1> Queues
I0714 09:21:25.815351       1 enqueue.go:79] Try to enqueue PodGroup to 0 Queues
I0714 09:21:25.815422       1 allocate.go:64] Try to allocate resource to 0 Queues
I0714 09:21:25.815627       1 session.go:244] Close Session 0c7e3a07-e6fd-4728-8671-4fd0d3bf67cb
I0714 09:21:26.818495       1 cache.go:1363] There are <0> Jobs, <1> Queues and <5> Nodes in total for scheduling.
I0714 09:21:26.818664       1 session.go:190] Open Session 02257182-2171-467d-8407-7e4292a5215d with <0> Job and <1> Queues
I0714 09:21:26.820510       1 enqueue.go:79] Try to enqueue PodGroup to 0 Queues
I0714 09:21:26.820585       1 allocate.go:64] Try to allocate resource to 0 Queues
I0714 09:21:26.820815       1 session.go:244] Close Session 02257182-2171-467d-8407-7e4292a5215d
I0714 09:21:27.823000       1 cache.go:1363] There are <0> Jobs, <1> Queues and <5> Nodes in total for scheduling.
I0714 09:21:27.823188       1 session.go:190] Open Session 18a098d6-8ed5-4a38-a337-d131316fc96f with <0> Job and <1> Queues
I0714 09:21:27.824929       1 enqueue.go:79] Try to enqueue PodGroup to 0 Queues
I0714 09:21:27.825006       1 allocate.go:64] Try to allocate resource to 0 Queues
I0714 09:21:27.825239       1 session.go:244] Close Session 18a098d6-8ed5-4a38-a337-d131316fc96f
I0714 09:21:28.827919       1 cache.go:1363] There are <0> Jobs, <1> Queues and <5> Nodes in total for scheduling.
I0714 09:21:28.828159       1 session.go:190] Open Session 35ae14a4-bd14-47de-99d3-d7c0296fa3b6 with <0> Job and <1> Queues
I0714 09:21:28.830004       1 enqueue.go:79] Try to enqueue PodGroup to 0 Queues
I0714 09:21:28.830079       1 allocate.go:64] Try to allocate resource to 0 Queues
I0714 09:21:28.830302       1 session.go:244] Close Session 35ae14a4-bd14-47de-99d3-d7c0296fa3b6
I0714 09:21:29.832757       1 cache.go:1363] There are <0> Jobs, <1> Queues and <5> Nodes in total for scheduling.
I0714 09:21:29.832934       1 session.go:190] Open Session 04b3f07c-987c-485f-aa74-002770691091 with <0> Job and <1> Queues
I0714 09:21:29.834716       1 enqueue.go:79] Try to enqueue PodGroup to 0 Queues
I0714 09:21:29.834789       1 allocate.go:64] Try to allocate resource to 0 Queues
I0714 09:21:29.835017       1 session.go:244] Close Session 04b3f07c-987c-485f-aa74-002770691091
I0714 09:21:30.837879       1 cache.go:1363] There are <0> Jobs, <1> Queues and <5> Nodes in total for scheduling.
I0714 09:21:30.838062       1 session.go:190] Open Session 5b9fe98f-4c91-4c09-b204-7336d61025ba with <0> Job and <1> Queues
I0714 09:21:30.840036       1 enqueue.go:79] Try to enqueue PodGroup to 0 Queues
I0714 09:21:30.840104       1 allocate.go:64] Try to allocate resource to 0 Queues
I0714 09:21:30.840391       1 session.go:244] Close Session 5b9fe98f-4c91-4c09-b204-7336d61025ba
I0714 09:21:31.843153       1 cache.go:1363] There are <0> Jobs, <1> Queues and <5> Nodes in total for scheduling.
I0714 09:21:31.843319       1 session.go:190] Open Session 03d9f5f3-b97e-4362-8596-ebc53b79c4fe with <0> Job and <1> Queues
I0714 09:21:31.845112       1 enqueue.go:79] Try to enqueue PodGroup to 0 Queues
I0714 09:21:31.845178       1 allocate.go:64] Try to allocate resource to 0 Queues
I0714 09:21:31.845388       1 session.go:244] Close Session 03d9f5f3-b97e-4362-8596-ebc53b79c4fe
I0714 09:21:32.847845       1 cache.go:1363] There are <0> Jobs, <1> Queues and <5> Nodes in total for scheduling.
I0714 09:21:32.848051       1 session.go:190] Open Session 9d0fd8f9-250d-4bef-82c6-7ed0b8f4c824 with <0> Job and <1> Queues
I0714 09:21:32.850031       1 enqueue.go:79] Try to enqueue PodGroup to 0 Queues
I0714 09:21:32.850113       1 allocate.go:64] Try to allocate resource to 0 Queues
I0714 09:21:32.850326       1 session.go:244] Close Session 9d0fd8f9-250d-4bef-82c6-7ed0b8f4c824
I0714 09:21:33.853272       1 cache.go:1363] There are <0> Jobs, <1> Queues and <5> Nodes in total for scheduling.
I0714 09:21:33.853460       1 session.go:190] Open Session f167bbd6-1364-414f-8d15-49a17d4515e4 with <0> Job and <1> Queues
I0714 09:21:33.855273       1 enqueue.go:79] Try to enqueue PodGroup to 0 Queues
I0714 09:21:33.855343       1 allocate.go:64] Try to allocate resource to 0 Queues
I0714 09:21:33.855560       1 session.go:244] Close Session f167bbd6-1364-414f-8d15-49a17d4515e4
I0714 09:21:34.858189       1 cache.go:1363] There are <0> Jobs, <1> Queues and <5> Nodes in total for scheduling.
I0714 09:21:34.858342       1 session.go:190] Open Session 0d8099b3-2e67-41ad-93ed-28a6ed0193fb with <0> Job and <1> Queues
I0714 09:21:34.860345       1 enqueue.go:79] Try to enqueue PodGroup to 0 Queues
I0714 09:21:34.860422       1 allocate.go:64] Try to allocate resource to 0 Queues
I0714 09:21:34.860679       1 session.go:244] Close Session 0d8099b3-2e67-41ad-93ed-28a6ed0193fb
I0714 09:21:35.863317       1 cache.go:1363] There are <0> Jobs, <1> Queues and <5> Nodes in total for scheduling.
I0714 09:21:35.863481       1 session.go:190] Open Session 54405d6f-d766-46d6-99ea-8b7100bfedd0 with <0> Job and <1> Queues
I0714 09:21:35.865308       1 enqueue.go:79] Try to enqueue PodGroup to 0 Queues
I0714 09:21:35.865386       1 allocate.go:64] Try to allocate resource to 0 Queues
I0714 09:21:35.865603       1 session.go:244] Close Session 54405d6f-d766-46d6-99ea-8b7100bfedd0
I0714 09:21:36.658591       1 cache.go:1489] The metrics type is not set in the volcano scheduler configmap file. As a result, the CPU and memory load information of the node is not collected.
I0714 09:21:36.867804       1 cache.go:1363] There are <0> Jobs, <1> Queues and <5> Nodes in total for scheduling.
I0714 09:21:36.867956       1 session.go:190] Open Session 62cb4a84-40fa-4e54-b459-1ee1ee4bc84d with <0> Job and <1> Queues
I0714 09:21:36.869794       1 enqueue.go:79] Try to enqueue PodGroup to 0 Queues
I0714 09:21:36.869870       1 allocate.go:64] Try to allocate resource to 0 Queues
I0714 09:21:36.870078       1 session.go:244] Close Session 62cb4a84-40fa-4e54-b459-1ee1ee4bc84d
I0714 09:21:37.872135       1 cache.go:1363] There are <0> Jobs, <1> Queues and <5> Nodes in total for scheduling.
I0714 09:21:37.872345       1 session.go:190] Open Session 8b11efa2-c796-4e82-8fdb-d7218eec23ab with <0> Job and <1> Queues
I0714 09:21:37.874112       1 enqueue.go:79] Try to enqueue PodGroup to 0 Queues
I0714 09:21:37.874190       1 allocate.go:64] Try to allocate resource to 0 Queues
I0714 09:21:37.874396       1 session.go:244] Close Session 8b11efa2-c796-4e82-8fdb-d7218eec23ab
I0714 09:21:38.876605       1 cache.go:1363] There are <0> Jobs, <1> Queues and <5> Nodes in total for scheduling.
I0714 09:21:38.876778       1 session.go:190] Open Session 034632ac-b3e0-44fb-a93d-2fe5233cbb1c with <0> Job and <1> Queues
I0714 09:21:38.878530       1 enqueue.go:79] Try to enqueue PodGroup to 0 Queues
I0714 09:21:38.878606       1 allocate.go:64] Try to allocate resource to 0 Queues
I0714 09:21:38.878812       1 session.go:244] Close Session 034632ac-b3e0-44fb-a93d-2fe5233cbb1c
I0714 09:21:39.881255       1 cache.go:1363] There are <0> Jobs, <1> Queues and <5> Nodes in total for scheduling.
I0714 09:21:39.881430       1 session.go:190] Open Session 9a5bace2-3dce-4d66-83a4-7838539d3e5f with <0> Job and <1> Queues
I0714 09:21:39.883185       1 enqueue.go:79] Try to enqueue PodGroup to 0 Queues
I0714 09:21:39.883253       1 allocate.go:64] Try to allocate resource to 0 Queues
I0714 09:21:39.883494       1 session.go:244] Close Session 9a5bace2-3dce-4d66-83a4-7838539d3e5f
I0714 09:21:40.885337       1 cache.go:1363] There are <0> Jobs, <1> Queues and <5> Nodes in total for scheduling.
I0714 09:21:40.885499       1 session.go:190] Open Session fec89eb4-52c3-448f-b9d0-00e24e7cdbf0 with <0> Job and <1> Queues
I0714 09:21:40.887156       1 enqueue.go:79] Try to enqueue PodGroup to 0 Queues
I0714 09:21:40.887238       1 allocate.go:64] Try to allocate resource to 0 Queues
I0714 09:21:40.887467       1 session.go:244] Close Session fec89eb4-52c3-448f-b9d0-00e24e7cdbf0
I0714 09:21:41.889932       1 cache.go:1363] There are <0> Jobs, <1> Queues and <5> Nodes in total for scheduling.
I0714 09:21:41.890105       1 session.go:190] Open Session 64261d0f-1ae9-43af-ba8c-7a4329ed53fb with <0> Job and <1> Queues
I0714 09:21:41.891896       1 enqueue.go:79] Try to enqueue PodGroup to 0 Queues
I0714 09:21:41.891961       1 allocate.go:64] Try to allocate resource to 0 Queues
I0714 09:21:41.892174       1 session.go:244] Close Session 64261d0f-1ae9-43af-ba8c-7a4329ed53fb
I0714 09:21:42.894695       1 cache.go:1363] There are <0> Jobs, <1> Queues and <5> Nodes in total for scheduling.
I0714 09:21:42.894863       1 session.go:190] Open Session 34441ce0-4f0a-4ccc-9927-7cd85dd3fe40 with <0> Job and <1> Queues
I0714 09:21:42.896596       1 enqueue.go:79] Try to enqueue PodGroup to 0 Queues
I0714 09:21:42.896661       1 allocate.go:64] Try to allocate resource to 0 Queues
I0714 09:21:42.896882       1 session.go:244] Close Session 34441ce0-4f0a-4ccc-9927-7cd85dd3fe40
I0714 09:21:43.899773       1 cache.go:1363] There are <0> Jobs, <1> Queues and <5> Nodes in total for scheduling.
I0714 09:21:43.899956       1 session.go:190] Open Session a76ca4cc-a23e-4932-a158-f3295452c26f with <0> Job and <1> Queues
I0714 09:21:43.901831       1 enqueue.go:79] Try to enqueue PodGroup to 0 Queues
I0714 09:21:43.901928       1 allocate.go:64] Try to allocate resource to 0 Queues
I0714 09:21:43.902159       1 session.go:244] Close Session a76ca4cc-a23e-4932-a158-f3295452c26f
I0714 09:21:44.905171       1 cache.go:1363] There are <0> Jobs, <1> Queues and <5> Nodes in total for scheduling.
I0714 09:21:44.905334       1 session.go:190] Open Session 4a5e378a-c69d-491a-abe6-9f6d280044d7 with <0> Job and <1> Queues
I0714 09:21:44.907143       1 enqueue.go:79] Try to enqueue PodGroup to 0 Queues
I0714 09:21:44.907227       1 allocate.go:64] Try to allocate resource to 0 Queues
I0714 09:21:44.907450       1 session.go:244] Close Session 4a5e378a-c69d-491a-abe6-9f6d280044d7
I0714 09:21:45.909714       1 cache.go:1363] There are <0> Jobs, <1> Queues and <5> Nodes in total for scheduling.
I0714 09:21:45.909868       1 session.go:190] Open Session 2fa2b6fb-90ed-4784-83d3-82ea2b23d295 with <0> Job and <1> Queues
I0714 09:21:45.911571       1 enqueue.go:79] Try to enqueue PodGroup to 0 Queues
I0714 09:21:45.911648       1 allocate.go:64] Try to allocate resource to 0 Queues
I0714 09:21:45.911873       1 session.go:244] Close Session 2fa2b6fb-90ed-4784-83d3-82ea2b23d295
I0714 09:21:46.914302       1 cache.go:1363] There are <0> Jobs, <1> Queues and <5> Nodes in total for scheduling.
I0714 09:21:46.914492       1 session.go:190] Open Session ea77cd42-7319-4679-8a91-f25349758955 with <0> Job and <1> Queues
I0714 09:21:46.916387       1 enqueue.go:79] Try to enqueue PodGroup to 0 Queues
I0714 09:21:46.916476       1 allocate.go:64] Try to allocate resource to 0 Queues
I0714 09:21:46.916705       1 session.go:244] Close Session ea77cd42-7319-4679-8a91-f25349758955
I0714 09:21:47.919126       1 cache.go:1363] There are <0> Jobs, <1> Queues and <5> Nodes in total for scheduling.
I0714 09:21:47.919300       1 session.go:190] Open Session 02d96a8a-525d-4c09-9ce7-7f6e18a3baa9 with <0> Job and <1> Queues
I0714 09:21:47.921099       1 enqueue.go:79] Try to enqueue PodGroup to 0 Queues
I0714 09:21:47.921177       1 allocate.go:64] Try to allocate resource to 0 Queues
I0714 09:21:47.921388       1 session.go:244] Close Session 02d96a8a-525d-4c09-9ce7-7f6e18a3baa9
I0714 09:21:48.923742       1 cache.go:1363] There are <0> Jobs, <1> Queues and <5> Nodes in total for scheduling.
I0714 09:21:48.923930       1 session.go:190] Open Session b79b8c8c-a5b0-4e65-8c04-3c4ee115e877 with <0> Job and <1> Queues
I0714 09:21:48.925743       1 enqueue.go:79] Try to enqueue PodGroup to 0 Queues
I0714 09:21:48.925824       1 allocate.go:64] Try to allocate resource to 0 Queues
I0714 09:21:48.926052       1 session.go:244] Close Session b79b8c8c-a5b0-4e65-8c04-3c4ee115e877
I0714 09:21:49.928509       1 cache.go:1363] There are <0> Jobs, <1> Queues and <5> Nodes in total for scheduling.
I0714 09:21:49.928690       1 session.go:190] Open Session 610a538b-3d0f-4969-86cd-402751a69f46 with <0> Job and <1> Queues
I0714 09:21:49.930453       1 enqueue.go:79] Try to enqueue PodGroup to 0 Queues
I0714 09:21:49.930534       1 allocate.go:64] Try to allocate resource to 0 Queues
I0714 09:21:49.930752       1 session.go:244] Close Session 610a538b-3d0f-4969-86cd-402751a69f46
I0714 09:21:50.933053       1 cache.go:1363] There are <0> Jobs, <1> Queues and <5> Nodes in total for scheduling.
I0714 09:21:50.933243       1 session.go:190] Open Session e17898d8-12b2-40bd-95c3-2c45fdb15154 with <0> Job and <1> Queues
I0714 09:21:50.935500       1 enqueue.go:79] Try to enqueue PodGroup to 0 Queues
I0714 09:21:50.935586       1 allocate.go:64] Try to allocate resource to 0 Queues
I0714 09:21:50.935802       1 session.go:244] Close Session e17898d8-12b2-40bd-95c3-2c45fdb15154
I0714 09:21:51.938584       1 cache.go:1363] There are <0> Jobs, <1> Queues and <5> Nodes in total for scheduling.
I0714 09:21:51.938770       1 session.go:190] Open Session 7af64f7e-08b7-40a8-be08-20cc0e4719de with <0> Job and <1> Queues
I0714 09:21:51.940634       1 enqueue.go:79] Try to enqueue PodGroup to 0 Queues
I0714 09:21:51.940713       1 allocate.go:64] Try to allocate resource to 0 Queues
I0714 09:21:51.940938       1 session.go:244] Close Session 7af64f7e-08b7-40a8-be08-20cc0e4719de
I0714 09:21:52.943453       1 cache.go:1363] There are <0> Jobs, <1> Queues and <5> Nodes in total for scheduling.
I0714 09:21:52.943633       1 session.go:190] Open Session 183944aa-eb96-430d-ac12-0ff63ca8dad9 with <0> Job and <1> Queues
I0714 09:21:52.945858       1 enqueue.go:79] Try to enqueue PodGroup to 0 Queues
I0714 09:21:52.945945       1 allocate.go:64] Try to allocate resource to 0 Queues
I0714 09:21:52.946185       1 session.go:244] Close Session 183944aa-eb96-430d-ac12-0ff63ca8dad9
I0714 09:21:53.948741       1 cache.go:1363] There are <0> Jobs, <1> Queues and <5> Nodes in total for scheduling.
I0714 09:21:53.948907       1 session.go:190] Open Session e5ed9a2c-4b9e-4669-87f1-2ab49a4cc2ea with <0> Job and <1> Queues
I0714 09:21:53.950689       1 enqueue.go:79] Try to enqueue PodGroup to 0 Queues
I0714 09:21:53.950773       1 allocate.go:64] Try to allocate resource to 0 Queues
I0714 09:21:53.950990       1 session.go:244] Close Session e5ed9a2c-4b9e-4669-87f1-2ab49a4cc2ea
I0714 09:21:54.954074       1 cache.go:1363] There are <0> Jobs, <1> Queues and <5> Nodes in total for scheduling.
I0714 09:21:54.954245       1 session.go:190] Open Session 9f517772-8cca-4e32-9c75-7427fd8508e8 with <0> Job and <1> Queues
I0714 09:21:54.956041       1 enqueue.go:79] Try to enqueue PodGroup to 0 Queues
I0714 09:21:54.956121       1 allocate.go:64] Try to allocate resource to 0 Queues
I0714 09:21:54.956383       1 session.go:244] Close Session 9f517772-8cca-4e32-9c75-7427fd8508e8
I0714 09:21:55.959009       1 cache.go:1363] There are <0> Jobs, <1> Queues and <5> Nodes in total for scheduling.
I0714 09:21:55.959168       1 session.go:190] Open Session ce4a7786-f4f2-4e90-a8ad-87a22e0d8845 with <0> Job and <1> Queues
I0714 09:21:55.961164       1 enqueue.go:79] Try to enqueue PodGroup to 0 Queues
I0714 09:21:55.961243       1 allocate.go:64] Try to allocate resource to 0 Queues
I0714 09:21:55.961473       1 session.go:244] Close Session ce4a7786-f4f2-4e90-a8ad-87a22e0d8845
I0714 09:21:56.963504       1 cache.go:1363] There are <0> Jobs, <1> Queues and <5> Nodes in total for scheduling.
I0714 09:21:56.963686       1 session.go:190] Open Session dd84b5bf-048b-46ec-b4ae-e01620958a29 with <0> Job and <1> Queues
I0714 09:21:56.965538       1 enqueue.go:79] Try to enqueue PodGroup to 0 Queues
I0714 09:21:56.965622       1 allocate.go:64] Try to allocate resource to 0 Queues
I0714 09:21:56.965854       1 session.go:244] Close Session dd84b5bf-048b-46ec-b4ae-e01620958a29
I0714 09:21:57.968368       1 cache.go:1363] There are <0> Jobs, <1> Queues and <5> Nodes in total for scheduling.
I0714 09:21:57.968555       1 session.go:190] Open Session a5a0b3c9-bcc3-424c-ae7c-aac48271ea2b with <0> Job and <1> Queues
I0714 09:21:57.970344       1 enqueue.go:79] Try to enqueue PodGroup to 0 Queues
I0714 09:21:57.970417       1 allocate.go:64] Try to allocate resource to 0 Queues
I0714 09:21:57.970640       1 session.go:244] Close Session a5a0b3c9-bcc3-424c-ae7c-aac48271ea2b
I0714 09:21:58.973701       1 cache.go:1363] There are <0> Jobs, <1> Queues and <5> Nodes in total for scheduling.
I0714 09:21:58.973893       1 session.go:190] Open Session d809dd05-539b-48aa-afd2-c609e3f99768 with <0> Job and <1> Queues
I0714 09:21:58.975881       1 enqueue.go:79] Try to enqueue PodGroup to 0 Queues
I0714 09:21:58.975962       1 allocate.go:64] Try to allocate resource to 0 Queues
I0714 09:21:58.976172       1 session.go:244] Close Session d809dd05-539b-48aa-afd2-c609e3f99768
I0714 09:21:59.979049       1 cache.go:1363] There are <0> Jobs, <1> Queues and <5> Nodes in total for scheduling.
I0714 09:21:59.979215       1 session.go:190] Open Session e596cd56-6ced-4a5c-bfc2-c746aa5c03ad with <0> Job and <1> Queues
I0714 09:21:59.981141       1 enqueue.go:79] Try to enqueue PodGroup to 0 Queues
I0714 09:21:59.981225       1 allocate.go:64] Try to allocate resource to 0 Queues
I0714 09:21:59.981433       1 session.go:244] Close Session e596cd56-6ced-4a5c-bfc2-c746aa5c03ad
I0714 09:22:00.983829       1 cache.go:1363] There are <0> Jobs, <1> Queues and <5> Nodes in total for scheduling.
I0714 09:22:00.983995       1 session.go:190] Open Session 21180cc8-43e4-4444-991e-acaeb6339d11 with <0> Job and <1> Queues
I0714 09:22:00.985808       1 enqueue.go:79] Try to enqueue PodGroup to 0 Queues
I0714 09:22:00.985881       1 allocate.go:64] Try to allocate resource to 0 Queues
I0714 09:22:00.986102       1 session.go:244] Close Session 21180cc8-43e4-4444-991e-acaeb6339d11
W0714 09:22:01.956211       1 event_handlers.go:181] Not support non-csi pvc.
I0714 09:22:01.956390       1 event_handlers.go:387] Added pod <default/yolo-cls> into cache.
W0714 09:22:01.983741       1 event_handlers.go:181] Not support non-csi pvc.
I0714 09:22:01.988657       1 cache.go:1363] There are <1> Jobs, <1> Queues and <5> Nodes in total for scheduling.
I0714 09:22:01.988774       1 session.go:190] Open Session 4392f568-3189-4164-8eaa-a32ef064ee88 with <1> Job and <1> Queues
I0714 09:22:01.990915       1 enqueue.go:79] Try to enqueue PodGroup to 1 Queues
I0714 09:22:01.991177       1 allocate.go:64] Try to allocate resource to 1 Queues
I0714 09:22:01.991232       1 allocate.go:129] Try to allocate resource to Jobs in Queue <default>
I0714 09:22:01.991265       1 allocate.go:161] Try to allocate resource to 1 tasks of Job <default/podgroup-067a66d9-1e3f-4905-909e-511ab0318429>
I0714 09:22:01.991330       1 allocate.go:181] There are <5> nodes for Job <default/podgroup-067a66d9-1e3f-4905-909e-511ab0318429>
I0714 09:22:01.991607       1 predicate_helper.go:75] Predicates failed: task default/yolo-cls on node gpu-master fit failed: Insufficient nvidia.com/gpu
I0714 09:22:01.992151       1 predicate_helper.go:75] Predicates failed: task default/yolo-cls on node gpuorin4-desktop fit failed: plugin NodeAffinity predicates failed node(s) didn't match Pod's node affinity/selector
I0714 09:22:01.992151       1 predicate_helper.go:75] Predicates failed: task default/yolo-cls on node gpuorin5-desktop fit failed: plugin NodeAffinity predicates failed node(s) didn't match Pod's node affinity/selector
I0714 09:22:01.993319       1 allocate.go:249] Binding Task <default/yolo-cls> to node <gpu-orin2>
I0714 09:22:01.993544       1 statement.go:266] After allocated Task <default/yolo-cls> to Node <gpu-orin2>: idle <cpu 5900.00, memory 7832690688.00, hugepages-64Ki 0.00, hugepages-2Mi 0.00, ephemeral-storage 225118140453000.00, hugepages-1Gi 0.00, nvidia.com/gpu 4000.00, pods 105.00, hugepages-32Mi 0.00>, used <cpu 100.00, memory 52428800.00, pods 5.00, nvidia.com/gpu 1000.00>, releasing <cpu 0.00, memory 0.00>
I0714 09:22:01.994017       1 statement.go:284] Allocating operations ...
I0714 09:22:01.994135       1 statement.go:378] Committing operations ...
I0714 09:22:01.994260       1 proportion.go:302] Queue <default>: deserved <cpu 0.00, memory 0.00, nvidia.com/gpu 1000.00, pods 1.00>, allocated <cpu 0.00, memory 0.00, nvidia.com/gpu 1000.00, pods 1.00>, share <1>
I0714 09:22:01.994321       1 allocate.go:125] Queue <default> is overused, ignore it.
I0714 09:22:02.002064       1 session.go:244] Close Session 4392f568-3189-4164-8eaa-a32ef064ee88
I0714 09:22:02.017907       1 cache.go:900] bind ok, latency 9.415832ms
W0714 09:22:02.019639       1 event_handlers.go:181] Not support non-csi pvc.
W0714 09:22:02.060683       1 event_handlers.go:181] Not support non-csi pvc.
W0714 09:22:02.599185       1 event_handlers.go:181] Not support non-csi pvc.
I0714 09:22:02.601969       1 event_handlers.go:442] Deleted pod <default/yolo-cls> from cache.
I0714 09:22:02.614620       1 cache.go:1013] Try to delete Job <default/podgroup-067a66d9-1e3f-4905-909e-511ab0318429:default/podgroup-067a66d9-1e3f-4905-909e-511ab0318429>
I0714 09:22:02.615012       1 cache.go:1054] Job <default/podgroup-067a66d9-1e3f-4905-909e-511ab0318429:default/podgroup-067a66d9-1e3f-4905-909e-511ab0318429> was deleted.
W0714 09:22:02.729538       1 event_handlers.go:181] Not support non-csi pvc.
I0714 09:22:02.729703       1 event_handlers.go:387] Added pod <default/yolo-cls> into cache.
W0714 09:22:02.771023       1 event_handlers.go:181] Not support non-csi pvc.
I0714 09:22:03.004754       1 cache.go:1363] There are <0> Jobs, <1> Queues and <5> Nodes in total for scheduling.
I0714 09:22:03.004922       1 session.go:190] Open Session d07b33b7-c163-453f-aa58-f59b2e56ad37 with <0> Job and <1> Queues
I0714 09:22:03.007207       1 enqueue.go:79] Try to enqueue PodGroup to 0 Queues
I0714 09:22:03.007303       1 allocate.go:64] Try to allocate resource to 0 Queues
I0714 09:22:03.007543       1 session.go:244] Close Session d07b33b7-c163-453f-aa58-f59b2e56ad37
I0714 09:22:04.009855       1 cache.go:1363] There are <0> Jobs, <1> Queues and <5> Nodes in total for scheduling.
I0714 09:22:04.010035       1 session.go:190] Open Session d2d88736-27d7-447a-8b76-c0bd5ab4ed7e with <0> Job and <1> Queues
I0714 09:22:04.011871       1 enqueue.go:79] Try to enqueue PodGroup to 0 Queues
I0714 09:22:04.011940       1 allocate.go:64] Try to allocate resource to 0 Queues
I0714 09:22:04.012141       1 session.go:244] Close Session d2d88736-27d7-447a-8b76-c0bd5ab4ed7e
W0714 09:22:04.629734       1 event_handlers.go:181] Not support non-csi pvc.
I0714 09:22:05.014496       1 cache.go:1363] There are <0> Jobs, <1> Queues and <5> Nodes in total for scheduling.
I0714 09:22:05.014620       1 session.go:190] Open Session ca94dd4e-35fa-4bd4-a61c-86844790da2f with <0> Job and <1> Queues
I0714 09:22:05.016420       1 enqueue.go:79] Try to enqueue PodGroup to 0 Queues
I0714 09:22:05.016490       1 allocate.go:64] Try to allocate resource to 0 Queues
I0714 09:22:05.016690       1 session.go:244] Close Session ca94dd4e-35fa-4bd4-a61c-86844790da2f
I0714 09:22:06.019362       1 cache.go:1363] There are <0> Jobs, <1> Queues and <5> Nodes in total for scheduling.
I0714 09:22:06.019540       1 session.go:190] Open Session c0491660-8580-44fc-a2fa-6ff1de6620de with <0> Job and <1> Queues
I0714 09:22:06.021363       1 enqueue.go:79] Try to enqueue PodGroup to 0 Queues
I0714 09:22:06.021437       1 allocate.go:64] Try to allocate resource to 0 Queues
I0714 09:22:06.021657       1 session.go:244] Close Session c0491660-8580-44fc-a2fa-6ff1de6620de
I0714 09:22:06.659487       1 cache.go:1489] The metrics type is not set in the volcano scheduler configmap file. As a result, the CPU and memory load information of the node is not collected.
I0714 09:22:07.024559       1 cache.go:1363] There are <0> Jobs, <1> Queues and <5> Nodes in total for scheduling.
I0714 09:22:07.024754       1 session.go:190] Open Session 9cb3d4b0-e664-480d-9c61-43b7d04750b3 with <0> Job and <1> Queues
I0714 09:22:07.026554       1 enqueue.go:79] Try to enqueue PodGroup to 0 Queues
I0714 09:22:07.026640       1 allocate.go:64] Try to allocate resource to 0 Queues
I0714 09:22:07.026848       1 session.go:244] Close Session 9cb3d4b0-e664-480d-9c61-43b7d04750b3
I0714 09:22:08.029796       1 cache.go:1363] There are <0> Jobs, <1> Queues and <5> Nodes in total for scheduling.
I0714 09:22:08.029971       1 session.go:190] Open Session f419985a-d699-4154-967e-6e5e77fea7e2 with <0> Job and <1> Queues
I0714 09:22:08.031813       1 enqueue.go:79] Try to enqueue PodGroup to 0 Queues
I0714 09:22:08.031897       1 allocate.go:64] Try to allocate resource to 0 Queues
I0714 09:22:08.032129       1 session.go:244] Close Session f419985a-d699-4154-967e-6e5e77fea7e2
W0714 09:22:08.179068       1 event_handlers.go:181] Not support non-csi pvc.
I0714 09:22:08.179179       1 event_handlers.go:387] Added pod <default/yolo-det> into cache.
W0714 09:22:08.204555       1 event_handlers.go:181] Not support non-csi pvc.
I0714 09:22:09.034688       1 cache.go:1363] There are <1> Jobs, <1> Queues and <5> Nodes in total for scheduling.
I0714 09:22:09.034867       1 session.go:190] Open Session b8a5a806-1058-4571-be2a-27b89ad97ba4 with <1> Job and <1> Queues
I0714 09:22:09.037500       1 enqueue.go:79] Try to enqueue PodGroup to 1 Queues
I0714 09:22:09.037783       1 allocate.go:64] Try to allocate resource to 1 Queues
I0714 09:22:09.037837       1 allocate.go:129] Try to allocate resource to Jobs in Queue <default>
I0714 09:22:09.037872       1 allocate.go:161] Try to allocate resource to 1 tasks of Job <default/podgroup-88192dde-c458-45e2-81f2-d0b145389dad>
I0714 09:22:09.037919       1 allocate.go:181] There are <5> nodes for Job <default/podgroup-88192dde-c458-45e2-81f2-d0b145389dad>
I0714 09:22:09.038255       1 predicate_helper.go:75] Predicates failed: task default/yolo-det on node gpu-master fit failed: Insufficient nvidia.com/gpu
I0714 09:22:09.038592       1 predicate_helper.go:75] Predicates failed: task default/yolo-det on node gpuorin4-desktop fit failed: plugin NodeAffinity predicates failed node(s) didn't match Pod's node affinity/selector
I0714 09:22:09.038625       1 predicate_helper.go:75] Predicates failed: task default/yolo-det on node gpuorin5-desktop fit failed: plugin NodeAffinity predicates failed node(s) didn't match Pod's node affinity/selector
I0714 09:22:09.039695       1 allocate.go:249] Binding Task <default/yolo-det> to node <gpu-orin3>
I0714 09:22:09.039942       1 statement.go:266] After allocated Task <default/yolo-det> to Node <gpu-orin3>: idle <cpu 5900.00, memory 7832723456.00, pods 105.00, hugepages-1Gi 0.00, hugepages-64Ki 0.00, hugepages-2Mi 0.00, hugepages-32Mi 0.00, nvidia.com/gpu 4000.00, ephemeral-storage 111715275387000.00>, used <cpu 100.00, memory 52428800.00, nvidia.com/gpu 1000.00, pods 5.00>, releasing <cpu 0.00, memory 0.00>
I0714 09:22:09.040493       1 statement.go:284] Allocating operations ...
I0714 09:22:09.040620       1 statement.go:378] Committing operations ...
I0714 09:22:09.040748       1 proportion.go:302] Queue <default>: deserved <cpu 0.00, memory 0.00, nvidia.com/gpu 1000.00, pods 1.00>, allocated <cpu 0.00, memory 0.00, pods 1.00, nvidia.com/gpu 1000.00>, share <1>
I0714 09:22:09.040830       1 allocate.go:125] Queue <default> is overused, ignore it.
I0714 09:22:09.055284       1 session.go:244] Close Session b8a5a806-1058-4571-be2a-27b89ad97ba4
I0714 09:22:09.068905       1 cache.go:900] bind ok, latency 12.839592ms
W0714 09:22:09.070756       1 event_handlers.go:181] Not support non-csi pvc.
W0714 09:22:09.108816       1 event_handlers.go:181] Not support non-csi pvc.
W0714 09:22:09.390499       1 event_handlers.go:181] Not support non-csi pvc.
I0714 09:22:09.394654       1 event_handlers.go:442] Deleted pod <default/yolo-det> from cache.
I0714 09:22:09.403118       1 cache.go:1013] Try to delete Job <default/podgroup-88192dde-c458-45e2-81f2-d0b145389dad:default/podgroup-88192dde-c458-45e2-81f2-d0b145389dad>
I0714 09:22:09.403363       1 cache.go:1054] Job <default/podgroup-88192dde-c458-45e2-81f2-d0b145389dad:default/podgroup-88192dde-c458-45e2-81f2-d0b145389dad> was deleted.
W0714 09:22:09.541006       1 event_handlers.go:181] Not support non-csi pvc.
I0714 09:22:09.541146       1 event_handlers.go:387] Added pod <default/yolo-det> into cache.
W0714 09:22:09.569151       1 event_handlers.go:181] Not support non-csi pvc.
I0714 09:22:10.057575       1 cache.go:1363] There are <0> Jobs, <1> Queues and <5> Nodes in total for scheduling.
I0714 09:22:10.057703       1 session.go:190] Open Session 9985e734-c5ac-4867-bded-4cc420c15a5b with <0> Job and <1> Queues
I0714 09:22:10.059575       1 enqueue.go:79] Try to enqueue PodGroup to 0 Queues
I0714 09:22:10.059653       1 allocate.go:64] Try to allocate resource to 0 Queues
I0714 09:22:10.059887       1 session.go:244] Close Session 9985e734-c5ac-4867-bded-4cc420c15a5b
I0714 09:22:11.062569       1 cache.go:1363] There are <0> Jobs, <1> Queues and <5> Nodes in total for scheduling.
I0714 09:22:11.062754       1 session.go:190] Open Session d824ed01-03ed-4cf8-96b9-ae50c5b24b90 with <0> Job and <1> Queues
I0714 09:22:11.064686       1 enqueue.go:79] Try to enqueue PodGroup to 0 Queues
I0714 09:22:11.064762       1 allocate.go:64] Try to allocate resource to 0 Queues
I0714 09:22:11.065235       1 session.go:244] Close Session d824ed01-03ed-4cf8-96b9-ae50c5b24b90
W0714 09:22:12.009510       1 event_handlers.go:181] Not support non-csi pvc.
I0714 09:22:12.067240       1 cache.go:1363] There are <0> Jobs, <1> Queues and <5> Nodes in total for scheduling.
I0714 09:22:12.067350       1 session.go:190] Open Session 8f0014d4-8d0b-4c11-bea4-0c720505f8ef with <0> Job and <1> Queues
I0714 09:22:12.069438       1 enqueue.go:79] Try to enqueue PodGroup to 0 Queues
I0714 09:22:12.069519       1 allocate.go:64] Try to allocate resource to 0 Queues
I0714 09:22:12.069730       1 session.go:244] Close Session 8f0014d4-8d0b-4c11-bea4-0c720505f8ef
I0714 09:22:13.072595       1 cache.go:1363] There are <0> Jobs, <1> Queues and <5> Nodes in total for scheduling.
I0714 09:22:13.072778       1 session.go:190] Open Session 860a684b-30d1-4a73-8769-4bb0457ac7fc with <0> Job and <1> Queues
I0714 09:22:13.074593       1 enqueue.go:79] Try to enqueue PodGroup to 0 Queues
I0714 09:22:13.074666       1 allocate.go:64] Try to allocate resource to 0 Queues
I0714 09:22:13.075012       1 session.go:244] Close Session 860a684b-30d1-4a73-8769-4bb0457ac7fc
I0714 09:22:14.077505       1 cache.go:1363] There are <0> Jobs, <1> Queues and <5> Nodes in total for scheduling.
I0714 09:22:14.077699       1 session.go:190] Open Session d7adac7a-6d3d-4cc7-90b8-e5880784add1 with <0> Job and <1> Queues
I0714 09:22:14.079565       1 enqueue.go:79] Try to enqueue PodGroup to 0 Queues
I0714 09:22:14.079632       1 allocate.go:64] Try to allocate resource to 0 Queues
I0714 09:22:14.079865       1 session.go:244] Close Session d7adac7a-6d3d-4cc7-90b8-e5880784add1
I0714 09:22:15.082379       1 cache.go:1363] There are <0> Jobs, <1> Queues and <5> Nodes in total for scheduling.
I0714 09:22:15.082556       1 session.go:190] Open Session e3acf6a6-74eb-4fd1-8723-78e5c26fef72 with <0> Job and <1> Queues
I0714 09:22:15.084375       1 enqueue.go:79] Try to enqueue PodGroup to 0 Queues
I0714 09:22:15.084455       1 allocate.go:64] Try to allocate resource to 0 Queues
I0714 09:22:15.084671       1 session.go:244] Close Session e3acf6a6-74eb-4fd1-8723-78e5c26fef72
W0714 09:22:15.700967       1 event_handlers.go:181] Not support non-csi pvc.
I0714 09:22:15.701082       1 event_handlers.go:387] Added pod <default/yolo-seg> into cache.
W0714 09:22:15.727678       1 event_handlers.go:181] Not support non-csi pvc.
I0714 09:22:16.087024       1 cache.go:1363] There are <1> Jobs, <1> Queues and <5> Nodes in total for scheduling.
I0714 09:22:16.087156       1 session.go:190] Open Session 664c3786-3072-42a7-ab7d-745264a65fdf with <1> Job and <1> Queues
I0714 09:22:16.089528       1 enqueue.go:79] Try to enqueue PodGroup to 1 Queues
I0714 09:22:16.089790       1 allocate.go:64] Try to allocate resource to 1 Queues
I0714 09:22:16.089853       1 allocate.go:129] Try to allocate resource to Jobs in Queue <default>
I0714 09:22:16.089890       1 allocate.go:161] Try to allocate resource to 1 tasks of Job <default/podgroup-64d73758-37c9-449d-8021-bbff5e532445>
I0714 09:22:16.089933       1 allocate.go:181] There are <5> nodes for Job <default/podgroup-64d73758-37c9-449d-8021-bbff5e532445>
I0714 09:22:16.090300       1 predicate_helper.go:75] Predicates failed: task default/yolo-seg on node gpu-master fit failed: Insufficient nvidia.com/gpu
I0714 09:22:16.090604       1 predicate_helper.go:75] Predicates failed: task default/yolo-seg on node gpuorin4-desktop fit failed: plugin NodeAffinity predicates failed node(s) didn't match Pod's node affinity/selector
I0714 09:22:16.090680       1 predicate_helper.go:75] Predicates failed: task default/yolo-seg on node gpuorin5-desktop fit failed: plugin NodeAffinity predicates failed node(s) didn't match Pod's node affinity/selector
I0714 09:22:16.091280       1 allocate.go:249] Binding Task <default/yolo-seg> to node <gpu-orin3>
I0714 09:22:16.091480       1 statement.go:266] After allocated Task <default/yolo-seg> to Node <gpu-orin3>: idle <cpu 5900.00, memory 7832723456.00, hugepages-2Mi 0.00, hugepages-32Mi 0.00, hugepages-1Gi 0.00, hugepages-64Ki 0.00, pods 104.00, nvidia.com/gpu 3000.00, ephemeral-storage 111715275387000.00>, used <cpu 100.00, memory 52428800.00, pods 6.00, nvidia.com/gpu 2000.00>, releasing <cpu 0.00, memory 0.00>
I0714 09:22:16.091922       1 statement.go:284] Allocating operations ...
I0714 09:22:16.092047       1 statement.go:378] Committing operations ...
I0714 09:22:16.092165       1 proportion.go:302] Queue <default>: deserved <cpu 0.00, memory 0.00, pods 1.00, nvidia.com/gpu 1000.00>, allocated <cpu 0.00, memory 0.00, pods 1.00, nvidia.com/gpu 1000.00>, share <1>
I0714 09:22:16.092220       1 allocate.go:125] Queue <default> is overused, ignore it.
I0714 09:22:16.102828       1 session.go:244] Close Session 664c3786-3072-42a7-ab7d-745264a65fdf
I0714 09:22:16.112863       1 cache.go:900] bind ok, latency 11.977555ms
W0714 09:22:16.114706       1 event_handlers.go:181] Not support non-csi pvc.
W0714 09:22:16.149545       1 event_handlers.go:181] Not support non-csi pvc.
W0714 09:22:16.358399       1 event_handlers.go:181] Not support non-csi pvc.
I0714 09:22:16.361456       1 event_handlers.go:442] Deleted pod <default/yolo-seg> from cache.
I0714 09:22:16.369464       1 cache.go:1013] Try to delete Job <default/podgroup-64d73758-37c9-449d-8021-bbff5e532445:default/podgroup-64d73758-37c9-449d-8021-bbff5e532445>
I0714 09:22:16.369663       1 cache.go:1054] Job <default/podgroup-64d73758-37c9-449d-8021-bbff5e532445:default/podgroup-64d73758-37c9-449d-8021-bbff5e532445> was deleted.
W0714 09:22:16.511639       1 event_handlers.go:181] Not support non-csi pvc.
I0714 09:22:16.511764       1 event_handlers.go:387] Added pod <default/yolo-seg> into cache.
W0714 09:22:16.539291       1 event_handlers.go:181] Not support non-csi pvc.
I0714 09:22:17.105520       1 cache.go:1363] There are <0> Jobs, <1> Queues and <5> Nodes in total for scheduling.
I0714 09:22:17.105662       1 session.go:190] Open Session 9b2e3680-2228-4def-830d-8713a31dcc84 with <0> Job and <1> Queues
I0714 09:22:17.107445       1 enqueue.go:79] Try to enqueue PodGroup to 0 Queues
I0714 09:22:17.107524       1 allocate.go:64] Try to allocate resource to 0 Queues
I0714 09:22:17.107733       1 session.go:244] Close Session 9b2e3680-2228-4def-830d-8713a31dcc84
I0714 09:22:18.110817       1 cache.go:1363] There are <0> Jobs, <1> Queues and <5> Nodes in total for scheduling.
I0714 09:22:18.110993       1 session.go:190] Open Session 4683ec30-7383-45c4-b24a-3f14acfc3058 with <0> Job and <1> Queues
I0714 09:22:18.112889       1 enqueue.go:79] Try to enqueue PodGroup to 0 Queues
I0714 09:22:18.112964       1 allocate.go:64] Try to allocate resource to 0 Queues
I0714 09:22:18.113169       1 session.go:244] Close Session 4683ec30-7383-45c4-b24a-3f14acfc3058
W0714 09:22:19.050233       1 event_handlers.go:181] Not support non-csi pvc.
I0714 09:22:19.115389       1 cache.go:1363] There are <0> Jobs, <1> Queues and <5> Nodes in total for scheduling.
I0714 09:22:19.115505       1 session.go:190] Open Session 5488411a-7478-4e51-8a79-d3546f494118 with <0> Job and <1> Queues
I0714 09:22:19.117366       1 enqueue.go:79] Try to enqueue PodGroup to 0 Queues
I0714 09:22:19.117448       1 allocate.go:64] Try to allocate resource to 0 Queues
I0714 09:22:19.117669       1 session.go:244] Close Session 5488411a-7478-4e51-8a79-d3546f494118
I0714 09:22:20.119564       1 cache.go:1363] There are <0> Jobs, <1> Queues and <5> Nodes in total for scheduling.
I0714 09:22:20.119684       1 session.go:190] Open Session 57b45e6f-a692-4d24-a458-e9f416d571fb with <0> Job and <1> Queues
I0714 09:22:20.121181       1 enqueue.go:79] Try to enqueue PodGroup to 0 Queues
I0714 09:22:20.121259       1 allocate.go:64] Try to allocate resource to 0 Queues
I0714 09:22:20.121459       1 session.go:244] Close Session 57b45e6f-a692-4d24-a458-e9f416d571fb
I0714 09:22:21.123955       1 cache.go:1363] There are <0> Jobs, <1> Queues and <5> Nodes in total for scheduling.
I0714 09:22:21.124075       1 session.go:190] Open Session b9ec1e05-84cc-4e25-bf06-0c1abdff5b06 with <0> Job and <1> Queues
I0714 09:22:21.125547       1 enqueue.go:79] Try to enqueue PodGroup to 0 Queues
I0714 09:22:21.125613       1 allocate.go:64] Try to allocate resource to 0 Queues
I0714 09:22:21.125794       1 session.go:244] Close Session b9ec1e05-84cc-4e25-bf06-0c1abdff5b06
I0714 09:22:22.128375       1 cache.go:1363] There are <0> Jobs, <1> Queues and <5> Nodes in total for scheduling.
I0714 09:22:22.128592       1 session.go:190] Open Session dfa49d69-0a13-47b7-9c6e-abef5967e725 with <0> Job and <1> Queues
I0714 09:22:22.130564       1 enqueue.go:79] Try to enqueue PodGroup to 0 Queues
I0714 09:22:22.130639       1 allocate.go:64] Try to allocate resource to 0 Queues
I0714 09:22:22.130871       1 session.go:244] Close Session dfa49d69-0a13-47b7-9c6e-abef5967e725
W0714 09:22:22.676439       1 event_handlers.go:181] Not support non-csi pvc.
I0714 09:22:22.676561       1 event_handlers.go:387] Added pod <default/yolo-obb> into cache.
W0714 09:22:22.701811       1 event_handlers.go:181] Not support non-csi pvc.
I0714 09:22:23.134228       1 cache.go:1363] There are <1> Jobs, <1> Queues and <5> Nodes in total for scheduling.
I0714 09:22:23.134403       1 session.go:190] Open Session 135f509d-b717-49a1-b8e4-29bca96011eb with <1> Job and <1> Queues
I0714 09:22:23.136671       1 enqueue.go:79] Try to enqueue PodGroup to 1 Queues
I0714 09:22:23.136920       1 allocate.go:64] Try to allocate resource to 1 Queues
I0714 09:22:23.136978       1 allocate.go:129] Try to allocate resource to Jobs in Queue <default>
I0714 09:22:23.137022       1 allocate.go:161] Try to allocate resource to 1 tasks of Job <default/podgroup-77235086-1542-45a1-b643-6dc91482d9ce>
I0714 09:22:23.137080       1 allocate.go:181] There are <5> nodes for Job <default/podgroup-77235086-1542-45a1-b643-6dc91482d9ce>
I0714 09:22:23.137387       1 predicate_helper.go:75] Predicates failed: task default/yolo-obb on node gpu-master fit failed: Insufficient nvidia.com/gpu
I0714 09:22:23.137729       1 predicate_helper.go:75] Predicates failed: task default/yolo-obb on node gpuorin4-desktop fit failed: plugin NodeAffinity predicates failed node(s) didn't match Pod's node affinity/selector
I0714 09:22:23.137833       1 predicate_helper.go:75] Predicates failed: task default/yolo-obb on node gpuorin5-desktop fit failed: plugin NodeAffinity predicates failed node(s) didn't match Pod's node affinity/selector
I0714 09:22:23.138426       1 allocate.go:249] Binding Task <default/yolo-obb> to node <gpu-orin2>
I0714 09:22:23.138616       1 statement.go:266] After allocated Task <default/yolo-obb> to Node <gpu-orin2>: idle <cpu 5900.00, memory 7832690688.00, hugepages-32Mi 0.00, hugepages-64Ki 0.00, nvidia.com/gpu 3000.00, ephemeral-storage 225118140453000.00, hugepages-1Gi 0.00, hugepages-2Mi 0.00, pods 104.00>, used <cpu 100.00, memory 52428800.00, pods 6.00, nvidia.com/gpu 2000.00>, releasing <cpu 0.00, memory 0.00>
I0714 09:22:23.139035       1 statement.go:284] Allocating operations ...
I0714 09:22:23.139165       1 statement.go:378] Committing operations ...
I0714 09:22:23.139290       1 proportion.go:302] Queue <default>: deserved <cpu 0.00, memory 0.00, nvidia.com/gpu 1000.00, pods 1.00>, allocated <cpu 0.00, memory 0.00, nvidia.com/gpu 1000.00, pods 1.00>, share <1>
I0714 09:22:23.139346       1 allocate.go:125] Queue <default> is overused, ignore it.
I0714 09:22:23.157072       1 session.go:244] Close Session 135f509d-b717-49a1-b8e4-29bca96011eb
I0714 09:22:23.168336       1 cache.go:900] bind ok, latency 19.165497ms
W0714 09:22:23.170395       1 event_handlers.go:181] Not support non-csi pvc.
W0714 09:22:23.209089       1 event_handlers.go:181] Not support non-csi pvc.
W0714 09:22:23.322589       1 event_handlers.go:181] Not support non-csi pvc.
I0714 09:22:23.332573       1 event_handlers.go:442] Deleted pod <default/yolo-obb> from cache.
I0714 09:22:23.339730       1 cache.go:1013] Try to delete Job <default/podgroup-77235086-1542-45a1-b643-6dc91482d9ce:default/podgroup-77235086-1542-45a1-b643-6dc91482d9ce>
I0714 09:22:23.339963       1 cache.go:1054] Job <default/podgroup-77235086-1542-45a1-b643-6dc91482d9ce:default/podgroup-77235086-1542-45a1-b643-6dc91482d9ce> was deleted.
W0714 09:22:23.471775       1 event_handlers.go:181] Not support non-csi pvc.
I0714 09:22:23.471948       1 event_handlers.go:387] Added pod <default/yolo-obb> into cache.
W0714 09:22:23.509718       1 event_handlers.go:181] Not support non-csi pvc.
I0714 09:22:24.159361       1 cache.go:1363] There are <0> Jobs, <1> Queues and <5> Nodes in total for scheduling.
I0714 09:22:24.159547       1 session.go:190] Open Session 71d0e64a-93b5-4a5a-ac77-9f8fc7541c47 with <0> Job and <1> Queues
I0714 09:22:24.161492       1 enqueue.go:79] Try to enqueue PodGroup to 0 Queues
I0714 09:22:24.161564       1 allocate.go:64] Try to allocate resource to 0 Queues
I0714 09:22:24.161786       1 session.go:244] Close Session 71d0e64a-93b5-4a5a-ac77-9f8fc7541c47
I0714 09:22:25.164232       1 cache.go:1363] There are <0> Jobs, <1> Queues and <5> Nodes in total for scheduling.
I0714 09:22:25.164458       1 session.go:190] Open Session 9916f3c0-a828-4256-92a2-e4b2aaed2612 with <0> Job and <1> Queues
I0714 09:22:25.166374       1 enqueue.go:79] Try to enqueue PodGroup to 0 Queues
I0714 09:22:25.166442       1 allocate.go:64] Try to allocate resource to 0 Queues
I0714 09:22:25.167074       1 session.go:244] Close Session 9916f3c0-a828-4256-92a2-e4b2aaed2612
W0714 09:22:25.720491       1 event_handlers.go:181] Not support non-csi pvc.
I0714 09:22:26.169294       1 cache.go:1363] There are <0> Jobs, <1> Queues and <5> Nodes in total for scheduling.
I0714 09:22:26.169433       1 session.go:190] Open Session 881ae162-61ee-4d32-b68c-cd4a5ec409b1 with <0> Job and <1> Queues
I0714 09:22:26.171414       1 enqueue.go:79] Try to enqueue PodGroup to 0 Queues
I0714 09:22:26.171489       1 allocate.go:64] Try to allocate resource to 0 Queues
I0714 09:22:26.171718       1 session.go:244] Close Session 881ae162-61ee-4d32-b68c-cd4a5ec409b1
I0714 09:22:27.174143       1 cache.go:1363] There are <0> Jobs, <1> Queues and <5> Nodes in total for scheduling.
I0714 09:22:27.174274       1 session.go:190] Open Session 50adc527-1fa9-4509-84dc-233b99a8612d with <0> Job and <1> Queues
I0714 09:22:27.176077       1 enqueue.go:79] Try to enqueue PodGroup to 0 Queues
I0714 09:22:27.176153       1 allocate.go:64] Try to allocate resource to 0 Queues
I0714 09:22:27.176379       1 session.go:244] Close Session 50adc527-1fa9-4509-84dc-233b99a8612d
I0714 09:22:28.179578       1 cache.go:1363] There are <0> Jobs, <1> Queues and <5> Nodes in total for scheduling.
I0714 09:22:28.179783       1 session.go:190] Open Session 5169eccd-9484-40ff-a2e5-8a7bba560fdd with <0> Job and <1> Queues
I0714 09:22:28.181712       1 enqueue.go:79] Try to enqueue PodGroup to 0 Queues
I0714 09:22:28.181784       1 allocate.go:64] Try to allocate resource to 0 Queues
I0714 09:22:28.182004       1 session.go:244] Close Session 5169eccd-9484-40ff-a2e5-8a7bba560fdd
I0714 09:22:29.184384       1 cache.go:1363] There are <0> Jobs, <1> Queues and <5> Nodes in total for scheduling.
I0714 09:22:29.184591       1 session.go:190] Open Session 4326abcf-03a8-4dc2-8a8b-2695aba13278 with <0> Job and <1> Queues
I0714 09:22:29.186520       1 enqueue.go:79] Try to enqueue PodGroup to 0 Queues
I0714 09:22:29.186592       1 allocate.go:64] Try to allocate resource to 0 Queues
I0714 09:22:29.186823       1 session.go:244] Close Session 4326abcf-03a8-4dc2-8a8b-2695aba13278
W0714 09:22:29.547134       1 event_handlers.go:181] Not support non-csi pvc.
I0714 09:22:29.547256       1 event_handlers.go:387] Added pod <default/yolo-pos> into cache.
W0714 09:22:29.573129       1 event_handlers.go:181] Not support non-csi pvc.
I0714 09:22:30.189846       1 cache.go:1363] There are <1> Jobs, <1> Queues and <5> Nodes in total for scheduling.
I0714 09:22:30.189994       1 session.go:190] Open Session 1a926a78-fd99-40d1-b67d-b780bcf07503 with <1> Job and <1> Queues
I0714 09:22:30.192441       1 enqueue.go:79] Try to enqueue PodGroup to 1 Queues
I0714 09:22:30.192856       1 allocate.go:64] Try to allocate resource to 1 Queues
I0714 09:22:30.192912       1 allocate.go:129] Try to allocate resource to Jobs in Queue <default>
I0714 09:22:30.193134       1 allocate.go:161] Try to allocate resource to 1 tasks of Job <default/podgroup-125eb1d2-4308-414e-80f9-7fd336923639>
I0714 09:22:30.193193       1 allocate.go:181] There are <5> nodes for Job <default/podgroup-125eb1d2-4308-414e-80f9-7fd336923639>
I0714 09:22:30.193565       1 predicate_helper.go:75] Predicates failed: task default/yolo-pos on node gpu-master fit failed: Insufficient nvidia.com/gpu
I0714 09:22:30.193848       1 predicate_helper.go:75] Predicates failed: task default/yolo-pos on node gpuorin4-desktop fit failed: plugin NodeAffinity predicates failed node(s) didn't match Pod's node affinity/selector
I0714 09:22:30.193921       1 predicate_helper.go:75] Predicates failed: task default/yolo-pos on node gpuorin5-desktop fit failed: plugin NodeAffinity predicates failed node(s) didn't match Pod's node affinity/selector
I0714 09:22:30.194932       1 allocate.go:249] Binding Task <default/yolo-pos> to node <gpu-orin3>
I0714 09:22:30.195202       1 statement.go:266] After allocated Task <default/yolo-pos> to Node <gpu-orin3>: idle <cpu 5900.00, memory 7832723456.00, nvidia.com/gpu 2000.00, ephemeral-storage 111715275387000.00, hugepages-2Mi 0.00, hugepages-32Mi 0.00, hugepages-1Gi 0.00, hugepages-64Ki 0.00, pods 103.00>, used <cpu 100.00, memory 52428800.00, pods 7.00, nvidia.com/gpu 3000.00>, releasing <cpu 0.00, memory 0.00>
I0714 09:22:30.195679       1 statement.go:284] Allocating operations ...
I0714 09:22:30.195806       1 statement.go:378] Committing operations ...
I0714 09:22:30.195958       1 proportion.go:302] Queue <default>: deserved <cpu 0.00, memory 0.00, pods 1.00, nvidia.com/gpu 1000.00>, allocated <cpu 0.00, memory 0.00, nvidia.com/gpu 1000.00, pods 1.00>, share <1>
I0714 09:22:30.196032       1 allocate.go:125] Queue <default> is overused, ignore it.
I0714 09:22:30.209495       1 cache.go:900] bind ok, latency 11.841392ms
W0714 09:22:30.211627       1 event_handlers.go:181] Not support non-csi pvc.
I0714 09:22:30.212158       1 session.go:244] Close Session 1a926a78-fd99-40d1-b67d-b780bcf07503
W0714 09:22:30.243292       1 event_handlers.go:181] Not support non-csi pvc.
W0714 09:22:30.796622       1 event_handlers.go:181] Not support non-csi pvc.
I0714 09:22:30.803233       1 event_handlers.go:442] Deleted pod <default/yolo-pos> from cache.
I0714 09:22:30.814425       1 cache.go:1013] Try to delete Job <default/podgroup-125eb1d2-4308-414e-80f9-7fd336923639:default/podgroup-125eb1d2-4308-414e-80f9-7fd336923639>
I0714 09:22:30.814620       1 cache.go:1054] Job <default/podgroup-125eb1d2-4308-414e-80f9-7fd336923639:default/podgroup-125eb1d2-4308-414e-80f9-7fd336923639> was deleted.
W0714 09:22:31.003383       1 event_handlers.go:181] Not support non-csi pvc.
I0714 09:22:31.003515       1 event_handlers.go:387] Added pod <default/yolo-pos> into cache.
W0714 09:22:31.046401       1 event_handlers.go:181] Not support non-csi pvc.
I0714 09:22:31.214984       1 cache.go:1363] There are <0> Jobs, <1> Queues and <5> Nodes in total for scheduling.
I0714 09:22:31.215101       1 session.go:190] Open Session 607f8670-b0de-4e38-bef5-c4bd565b41d9 with <0> Job and <1> Queues
I0714 09:22:31.216989       1 enqueue.go:79] Try to enqueue PodGroup to 0 Queues
I0714 09:22:31.217067       1 allocate.go:64] Try to allocate resource to 0 Queues
I0714 09:22:31.217274       1 session.go:244] Close Session 607f8670-b0de-4e38-bef5-c4bd565b41d9
I0714 09:22:32.222215       1 cache.go:1363] There are <0> Jobs, <1> Queues and <5> Nodes in total for scheduling.
I0714 09:22:32.222453       1 session.go:190] Open Session 95cb727a-7498-4e4f-b708-e5aac4a5bf42 with <0> Job and <1> Queues
I0714 09:22:32.224738       1 enqueue.go:79] Try to enqueue PodGroup to 0 Queues
I0714 09:22:32.224836       1 allocate.go:64] Try to allocate resource to 0 Queues
I0714 09:22:32.225060       1 session.go:244] Close Session 95cb727a-7498-4e4f-b708-e5aac4a5bf42
I0714 09:22:33.227943       1 cache.go:1363] There are <0> Jobs, <1> Queues and <5> Nodes in total for scheduling.
I0714 09:22:33.228134       1 session.go:190] Open Session fec430d3-3349-4e3e-bb27-2d34c10d3f67 with <0> Job and <1> Queues
I0714 09:22:33.230630       1 enqueue.go:79] Try to enqueue PodGroup to 0 Queues
I0714 09:22:33.230717       1 allocate.go:64] Try to allocate resource to 0 Queues
I0714 09:22:33.230938       1 session.go:244] Close Session fec430d3-3349-4e3e-bb27-2d34c10d3f67
W0714 09:22:34.149589       1 event_handlers.go:181] Not support non-csi pvc.
I0714 09:22:34.233823       1 cache.go:1363] There are <0> Jobs, <1> Queues and <5> Nodes in total for scheduling.
I0714 09:22:34.233972       1 session.go:190] Open Session 3205286f-8009-408e-837c-869ab0407e55 with <0> Job and <1> Queues
I0714 09:22:34.236140       1 enqueue.go:79] Try to enqueue PodGroup to 0 Queues
I0714 09:22:34.236228       1 allocate.go:64] Try to allocate resource to 0 Queues
I0714 09:22:34.236493       1 session.go:244] Close Session 3205286f-8009-408e-837c-869ab0407e55
I0714 09:22:35.239425       1 cache.go:1363] There are <0> Jobs, <1> Queues and <5> Nodes in total for scheduling.
I0714 09:22:35.239566       1 session.go:190] Open Session 83fac392-bb97-47b3-b032-a044440fcd22 with <0> Job and <1> Queues
I0714 09:22:35.241404       1 enqueue.go:79] Try to enqueue PodGroup to 0 Queues
I0714 09:22:35.241482       1 allocate.go:64] Try to allocate resource to 0 Queues
I0714 09:22:35.241709       1 session.go:244] Close Session 83fac392-bb97-47b3-b032-a044440fcd22
I0714 09:22:36.244631       1 cache.go:1363] There are <0> Jobs, <1> Queues and <5> Nodes in total for scheduling.
I0714 09:22:36.244789       1 session.go:190] Open Session 13852f9d-1303-477e-ac20-fde4487a6164 with <0> Job and <1> Queues
I0714 09:22:36.246615       1 enqueue.go:79] Try to enqueue PodGroup to 0 Queues
I0714 09:22:36.246688       1 allocate.go:64] Try to allocate resource to 0 Queues
I0714 09:22:36.246915       1 session.go:244] Close Session 13852f9d-1303-477e-ac20-fde4487a6164
I0714 09:22:36.660362       1 cache.go:1489] The metrics type is not set in the volcano scheduler configmap file. As a result, the CPU and memory load information of the node is not collected.
I0714 09:22:37.249274       1 cache.go:1363] There are <0> Jobs, <1> Queues and <5> Nodes in total for scheduling.
I0714 09:22:37.249519       1 session.go:190] Open Session 5b52a016-bac2-49b5-88f7-9779a9843080 with <0> Job and <1> Queues
I0714 09:22:37.251470       1 enqueue.go:79] Try to enqueue PodGroup to 0 Queues
I0714 09:22:37.251558       1 allocate.go:64] Try to allocate resource to 0 Queues
I0714 09:22:37.251795       1 session.go:244] Close Session 5b52a016-bac2-49b5-88f7-9779a9843080
I0714 09:22:38.254406       1 cache.go:1363] There are <0> Jobs, <1> Queues and <5> Nodes in total for scheduling.
I0714 09:22:38.254590       1 session.go:190] Open Session ce51a845-b797-4d0f-8f1f-243a1f8426d6 with <0> Job and <1> Queues
I0714 09:22:38.256507       1 enqueue.go:79] Try to enqueue PodGroup to 0 Queues
I0714 09:22:38.256591       1 allocate.go:64] Try to allocate resource to 0 Queues
I0714 09:22:38.256830       1 session.go:244] Close Session ce51a845-b797-4d0f-8f1f-243a1f8426d6
I0714 09:22:39.259570       1 cache.go:1363] There are <0> Jobs, <1> Queues and <5> Nodes in total for scheduling.
I0714 09:22:39.259755       1 session.go:190] Open Session 9b2d26bd-6f88-4cdc-94b2-b202e1735b3f with <0> Job and <1> Queues
I0714 09:22:39.261702       1 enqueue.go:79] Try to enqueue PodGroup to 0 Queues
I0714 09:22:39.261787       1 allocate.go:64] Try to allocate resource to 0 Queues
I0714 09:22:39.262031       1 session.go:244] Close Session 9b2d26bd-6f88-4cdc-94b2-b202e1735b3f
I0714 09:22:40.265132       1 cache.go:1363] There are <0> Jobs, <1> Queues and <5> Nodes in total for scheduling.
I0714 09:22:40.265306       1 session.go:190] Open Session f66c06ea-f389-4adf-acfd-2c04bf313f82 with <0> Job and <1> Queues
I0714 09:22:40.267261       1 enqueue.go:79] Try to enqueue PodGroup to 0 Queues
I0714 09:22:40.267345       1 allocate.go:64] Try to allocate resource to 0 Queues
I0714 09:22:40.267575       1 session.go:244] Close Session f66c06ea-f389-4adf-acfd-2c04bf313f82
I0714 09:22:41.270156       1 cache.go:1363] There are <0> Jobs, <1> Queues and <5> Nodes in total for scheduling.
I0714 09:22:41.270322       1 session.go:190] Open Session 12a9f663-cabf-4171-806e-a37d42b1c2a5 with <0> Job and <1> Queues
I0714 09:22:41.272494       1 enqueue.go:79] Try to enqueue PodGroup to 0 Queues
I0714 09:22:41.272591       1 allocate.go:64] Try to allocate resource to 0 Queues
I0714 09:22:41.272827       1 session.go:244] Close Session 12a9f663-cabf-4171-806e-a37d42b1c2a5
I0714 09:22:42.276481       1 cache.go:1363] There are <0> Jobs, <1> Queues and <5> Nodes in total for scheduling.
I0714 09:22:42.276982       1 session.go:190] Open Session 33124721-11e3-4b79-aca5-94b7ce856ee1 with <0> Job and <1> Queues
I0714 09:22:42.279459       1 enqueue.go:79] Try to enqueue PodGroup to 0 Queues
I0714 09:22:42.279536       1 allocate.go:64] Try to allocate resource to 0 Queues
I0714 09:22:42.279780       1 session.go:244] Close Session 33124721-11e3-4b79-aca5-94b7ce856ee1
I0714 09:22:43.282493       1 cache.go:1363] There are <0> Jobs, <1> Queues and <5> Nodes in total for scheduling.
I0714 09:22:43.282679       1 session.go:190] Open Session 2e356850-892f-4d18-af62-50990f1cd72c with <0> Job and <1> Queues
I0714 09:22:43.284532       1 enqueue.go:79] Try to enqueue PodGroup to 0 Queues
I0714 09:22:43.284608       1 allocate.go:64] Try to allocate resource to 0 Queues
I0714 09:22:43.284830       1 session.go:244] Close Session 2e356850-892f-4d18-af62-50990f1cd72c
I0714 09:22:44.287688       1 cache.go:1363] There are <0> Jobs, <1> Queues and <5> Nodes in total for scheduling.
I0714 09:22:44.287877       1 session.go:190] Open Session 6589dde7-5048-4052-9301-7193e5a49bf8 with <0> Job and <1> Queues
I0714 09:22:44.289956       1 enqueue.go:79] Try to enqueue PodGroup to 0 Queues
I0714 09:22:44.290060       1 allocate.go:64] Try to allocate resource to 0 Queues
I0714 09:22:44.290275       1 session.go:244] Close Session 6589dde7-5048-4052-9301-7193e5a49bf8
I0714 09:22:45.293289       1 cache.go:1363] There are <0> Jobs, <1> Queues and <5> Nodes in total for scheduling.
I0714 09:22:45.293470       1 session.go:190] Open Session 2ad83445-66e7-45ff-a583-1c09bae9e1b6 with <0> Job and <1> Queues
I0714 09:22:45.295348       1 enqueue.go:79] Try to enqueue PodGroup to 0 Queues
I0714 09:22:45.295417       1 allocate.go:64] Try to allocate resource to 0 Queues
I0714 09:22:45.295625       1 session.go:244] Close Session 2ad83445-66e7-45ff-a583-1c09bae9e1b6
I0714 09:22:46.297888       1 cache.go:1363] There are <0> Jobs, <1> Queues and <5> Nodes in total for scheduling.
I0714 09:22:46.298061       1 session.go:190] Open Session 39a5ca00-57ae-4cf5-ae87-64e22a9d2491 with <0> Job and <1> Queues
I0714 09:22:46.299988       1 enqueue.go:79] Try to enqueue PodGroup to 0 Queues
I0714 09:22:46.300056       1 allocate.go:64] Try to allocate resource to 0 Queues
I0714 09:22:46.300343       1 session.go:244] Close Session 39a5ca00-57ae-4cf5-ae87-64e22a9d2491
I0714 09:22:47.303176       1 cache.go:1363] There are <0> Jobs, <1> Queues and <5> Nodes in total for scheduling.
I0714 09:22:47.303330       1 session.go:190] Open Session 84cc7044-effc-49ca-8e6e-0392a2479f95 with <0> Job and <1> Queues
I0714 09:22:47.305422       1 enqueue.go:79] Try to enqueue PodGroup to 0 Queues
I0714 09:22:47.305493       1 allocate.go:64] Try to allocate resource to 0 Queues
I0714 09:22:47.305694       1 session.go:244] Close Session 84cc7044-effc-49ca-8e6e-0392a2479f95
I0714 09:22:48.309169       1 cache.go:1363] There are <0> Jobs, <1> Queues and <5> Nodes in total for scheduling.
I0714 09:22:48.309328       1 session.go:190] Open Session 2e76679f-8920-493c-a676-aa584a0b0cc2 with <0> Job and <1> Queues
I0714 09:22:48.311240       1 enqueue.go:79] Try to enqueue PodGroup to 0 Queues
I0714 09:22:48.311307       1 allocate.go:64] Try to allocate resource to 0 Queues
I0714 09:22:48.311521       1 session.go:244] Close Session 2e76679f-8920-493c-a676-aa584a0b0cc2
I0714 09:22:49.314069       1 cache.go:1363] There are <0> Jobs, <1> Queues and <5> Nodes in total for scheduling.
I0714 09:22:49.314246       1 session.go:190] Open Session 77c6809c-dd3f-4be7-b1b2-d0cee5d48134 with <0> Job and <1> Queues
I0714 09:22:49.316828       1 enqueue.go:79] Try to enqueue PodGroup to 0 Queues
I0714 09:22:49.316899       1 allocate.go:64] Try to allocate resource to 0 Queues
I0714 09:22:49.317604       1 session.go:244] Close Session 77c6809c-dd3f-4be7-b1b2-d0cee5d48134
I0714 09:22:50.320136       1 cache.go:1363] There are <0> Jobs, <1> Queues and <5> Nodes in total for scheduling.
I0714 09:22:50.320337       1 session.go:190] Open Session b8df7d8e-91cf-4267-8731-50783797641b with <0> Job and <1> Queues
I0714 09:22:50.323165       1 enqueue.go:79] Try to enqueue PodGroup to 0 Queues
I0714 09:22:50.323265       1 allocate.go:64] Try to allocate resource to 0 Queues
I0714 09:22:50.323515       1 session.go:244] Close Session b8df7d8e-91cf-4267-8731-50783797641b
I0714 09:22:51.326455       1 cache.go:1363] There are <0> Jobs, <1> Queues and <5> Nodes in total for scheduling.
I0714 09:22:51.326633       1 session.go:190] Open Session c6a02ddb-5b90-44fe-8290-ed401f65d8aa with <0> Job and <1> Queues
I0714 09:22:51.328527       1 enqueue.go:79] Try to enqueue PodGroup to 0 Queues
I0714 09:22:51.328596       1 allocate.go:64] Try to allocate resource to 0 Queues
I0714 09:22:51.328832       1 session.go:244] Close Session c6a02ddb-5b90-44fe-8290-ed401f65d8aa
I0714 09:22:52.330838       1 cache.go:1363] There are <0> Jobs, <1> Queues and <5> Nodes in total for scheduling.
I0714 09:22:52.331019       1 session.go:190] Open Session 0c7ffa31-739a-46df-b639-e065130a582d with <0> Job and <1> Queues
I0714 09:22:52.333137       1 enqueue.go:79] Try to enqueue PodGroup to 0 Queues
I0714 09:22:52.333207       1 allocate.go:64] Try to allocate resource to 0 Queues
I0714 09:22:52.333432       1 session.go:244] Close Session 0c7ffa31-739a-46df-b639-e065130a582d
I0714 09:22:53.336341       1 cache.go:1363] There are <0> Jobs, <1> Queues and <5> Nodes in total for scheduling.
I0714 09:22:53.336525       1 session.go:190] Open Session e80b8b40-ee66-4392-aa97-9e83e4370fab with <0> Job and <1> Queues
I0714 09:22:53.338730       1 enqueue.go:79] Try to enqueue PodGroup to 0 Queues
I0714 09:22:53.338826       1 allocate.go:64] Try to allocate resource to 0 Queues
I0714 09:22:53.339054       1 session.go:244] Close Session e80b8b40-ee66-4392-aa97-9e83e4370fab
I0714 09:22:54.342171       1 cache.go:1363] There are <0> Jobs, <1> Queues and <5> Nodes in total for scheduling.
I0714 09:22:54.342341       1 session.go:190] Open Session 2c229fd0-1966-453e-8574-8ef2f0e2d387 with <0> Job and <1> Queues
I0714 09:22:54.344196       1 enqueue.go:79] Try to enqueue PodGroup to 0 Queues
I0714 09:22:54.344261       1 allocate.go:64] Try to allocate resource to 0 Queues
I0714 09:22:54.344515       1 session.go:244] Close Session 2c229fd0-1966-453e-8574-8ef2f0e2d387
I0714 09:22:55.347122       1 cache.go:1363] There are <0> Jobs, <1> Queues and <5> Nodes in total for scheduling.
I0714 09:22:55.347298       1 session.go:190] Open Session 289de8aa-d806-40f5-972d-8fa85e7bc1b5 with <0> Job and <1> Queues
I0714 09:22:55.349216       1 enqueue.go:79] Try to enqueue PodGroup to 0 Queues
I0714 09:22:55.349286       1 allocate.go:64] Try to allocate resource to 0 Queues
I0714 09:22:55.349509       1 session.go:244] Close Session 289de8aa-d806-40f5-972d-8fa85e7bc1b5
I0714 09:22:56.352235       1 cache.go:1363] There are <0> Jobs, <1> Queues and <5> Nodes in total for scheduling.
I0714 09:22:56.352446       1 session.go:190] Open Session da172465-8e65-4a09-8444-f9af555e0491 with <0> Job and <1> Queues
I0714 09:22:56.354461       1 enqueue.go:79] Try to enqueue PodGroup to 0 Queues
I0714 09:22:56.354547       1 allocate.go:64] Try to allocate resource to 0 Queues
I0714 09:22:56.354758       1 session.go:244] Close Session da172465-8e65-4a09-8444-f9af555e0491
I0714 09:22:57.357252       1 cache.go:1363] There are <0> Jobs, <1> Queues and <5> Nodes in total for scheduling.
I0714 09:22:57.357388       1 session.go:190] Open Session 2136e498-f06b-444d-b573-bff06bac0702 with <0> Job and <1> Queues
I0714 09:22:57.359259       1 enqueue.go:79] Try to enqueue PodGroup to 0 Queues
I0714 09:22:57.359334       1 allocate.go:64] Try to allocate resource to 0 Queues
I0714 09:22:57.359549       1 session.go:244] Close Session 2136e498-f06b-444d-b573-bff06bac0702
I0714 09:22:58.362624       1 cache.go:1363] There are <0> Jobs, <1> Queues and <5> Nodes in total for scheduling.
I0714 09:22:58.362792       1 session.go:190] Open Session 23f249e8-3356-417e-a2fe-15ead24576c9 with <0> Job and <1> Queues
I0714 09:22:58.365061       1 enqueue.go:79] Try to enqueue PodGroup to 0 Queues
I0714 09:22:58.365139       1 allocate.go:64] Try to allocate resource to 0 Queues
I0714 09:22:58.365370       1 session.go:244] Close Session 23f249e8-3356-417e-a2fe-15ead24576c9
I0714 09:22:59.368378       1 cache.go:1363] There are <0> Jobs, <1> Queues and <5> Nodes in total for scheduling.
I0714 09:22:59.368550       1 session.go:190] Open Session c4a14b2a-dc1d-4096-bd4e-f1e5c2b6577d with <0> Job and <1> Queues
I0714 09:22:59.370450       1 enqueue.go:79] Try to enqueue PodGroup to 0 Queues
I0714 09:22:59.370541       1 allocate.go:64] Try to allocate resource to 0 Queues
I0714 09:22:59.370749       1 session.go:244] Close Session c4a14b2a-dc1d-4096-bd4e-f1e5c2b6577d
I0714 09:23:00.373809       1 cache.go:1363] There are <0> Jobs, <1> Queues and <5> Nodes in total for scheduling.
I0714 09:23:00.373973       1 session.go:190] Open Session 65c53ec7-2af0-46d6-b675-68f46212f330 with <0> Job and <1> Queues
I0714 09:23:00.376169       1 enqueue.go:79] Try to enqueue PodGroup to 0 Queues
I0714 09:23:00.376251       1 allocate.go:64] Try to allocate resource to 0 Queues
I0714 09:23:00.376561       1 session.go:244] Close Session 65c53ec7-2af0-46d6-b675-68f46212f330
I0714 09:23:01.378912       1 cache.go:1363] There are <0> Jobs, <1> Queues and <5> Nodes in total for scheduling.
I0714 09:23:01.379059       1 session.go:190] Open Session f022bd94-ce18-4491-bd84-b2b45900f395 with <0> Job and <1> Queues
I0714 09:23:01.380966       1 enqueue.go:79] Try to enqueue PodGroup to 0 Queues
I0714 09:23:01.381044       1 allocate.go:64] Try to allocate resource to 0 Queues
I0714 09:23:01.381264       1 session.go:244] Close Session f022bd94-ce18-4491-bd84-b2b45900f395
I0714 09:23:02.383464       1 cache.go:1363] There are <0> Jobs, <1> Queues and <5> Nodes in total for scheduling.
I0714 09:23:02.383631       1 session.go:190] Open Session d7b6cdaf-6d6c-48cf-a178-8577dfc89f03 with <0> Job and <1> Queues
I0714 09:23:02.385573       1 enqueue.go:79] Try to enqueue PodGroup to 0 Queues
I0714 09:23:02.385647       1 allocate.go:64] Try to allocate resource to 0 Queues
I0714 09:23:02.385884       1 session.go:244] Close Session d7b6cdaf-6d6c-48cf-a178-8577dfc89f03
I0714 09:23:03.388734       1 cache.go:1363] There are <0> Jobs, <1> Queues and <5> Nodes in total for scheduling.
I0714 09:23:03.388909       1 session.go:190] Open Session 02cf7d6a-6eaa-420e-bfda-b9381c57e22a with <0> Job and <1> Queues
I0714 09:23:03.390803       1 enqueue.go:79] Try to enqueue PodGroup to 0 Queues
I0714 09:23:03.390877       1 allocate.go:64] Try to allocate resource to 0 Queues
I0714 09:23:03.391087       1 session.go:244] Close Session 02cf7d6a-6eaa-420e-bfda-b9381c57e22a
I0714 09:23:04.394061       1 cache.go:1363] There are <0> Jobs, <1> Queues and <5> Nodes in total for scheduling.
I0714 09:23:04.394248       1 session.go:190] Open Session 04dede81-ce8c-4b60-9f2f-37681cebf2c5 with <0> Job and <1> Queues
I0714 09:23:04.396146       1 enqueue.go:79] Try to enqueue PodGroup to 0 Queues
I0714 09:23:04.396237       1 allocate.go:64] Try to allocate resource to 0 Queues
I0714 09:23:04.396499       1 session.go:244] Close Session 04dede81-ce8c-4b60-9f2f-37681cebf2c5
I0714 09:23:05.399007       1 cache.go:1363] There are <0> Jobs, <1> Queues and <5> Nodes in total for scheduling.
I0714 09:23:05.399183       1 session.go:190] Open Session a74a4057-a2b5-4c3f-b7ae-0b13b628da9c with <0> Job and <1> Queues
I0714 09:23:05.401124       1 enqueue.go:79] Try to enqueue PodGroup to 0 Queues
I0714 09:23:05.401193       1 allocate.go:64] Try to allocate resource to 0 Queues
I0714 09:23:05.401427       1 session.go:244] Close Session a74a4057-a2b5-4c3f-b7ae-0b13b628da9c
I0714 09:23:06.404095       1 cache.go:1363] There are <0> Jobs, <1> Queues and <5> Nodes in total for scheduling.
I0714 09:23:06.404257       1 session.go:190] Open Session 411f7c6b-d6b0-4e4f-b356-23398c8d4126 with <0> Job and <1> Queues
I0714 09:23:06.406335       1 enqueue.go:79] Try to enqueue PodGroup to 0 Queues
I0714 09:23:06.406404       1 allocate.go:64] Try to allocate resource to 0 Queues
I0714 09:23:06.406612       1 session.go:244] Close Session 411f7c6b-d6b0-4e4f-b356-23398c8d4126
I0714 09:23:06.661464       1 cache.go:1489] The metrics type is not set in the volcano scheduler configmap file. As a result, the CPU and memory load information of the node is not collected.
I0714 09:23:07.409529       1 cache.go:1363] There are <0> Jobs, <1> Queues and <5> Nodes in total for scheduling.
I0714 09:23:07.409687       1 session.go:190] Open Session 26c02e33-9032-4f59-89bc-152b2169b6e8 with <0> Job and <1> Queues
I0714 09:23:07.411602       1 enqueue.go:79] Try to enqueue PodGroup to 0 Queues
I0714 09:23:07.411669       1 allocate.go:64] Try to allocate resource to 0 Queues
I0714 09:23:07.411884       1 session.go:244] Close Session 26c02e33-9032-4f59-89bc-152b2169b6e8
I0714 09:23:08.415070       1 cache.go:1363] There are <0> Jobs, <1> Queues and <5> Nodes in total for scheduling.
I0714 09:23:08.415246       1 session.go:190] Open Session ce5a756e-c3c7-44c0-81f5-632e495d7dc5 with <0> Job and <1> Queues
I0714 09:23:08.417246       1 enqueue.go:79] Try to enqueue PodGroup to 0 Queues
I0714 09:23:08.417326       1 allocate.go:64] Try to allocate resource to 0 Queues
I0714 09:23:08.417554       1 session.go:244] Close Session ce5a756e-c3c7-44c0-81f5-632e495d7dc5
I0714 09:23:09.420494       1 cache.go:1363] There are <0> Jobs, <1> Queues and <5> Nodes in total for scheduling.
I0714 09:23:09.420669       1 session.go:190] Open Session 509f2f6d-472f-435c-8c47-0d7341d30357 with <0> Job and <1> Queues
I0714 09:23:09.422560       1 enqueue.go:79] Try to enqueue PodGroup to 0 Queues
I0714 09:23:09.422636       1 allocate.go:64] Try to allocate resource to 0 Queues
I0714 09:23:09.422845       1 session.go:244] Close Session 509f2f6d-472f-435c-8c47-0d7341d30357
I0714 09:23:10.425792       1 cache.go:1363] There are <0> Jobs, <1> Queues and <5> Nodes in total for scheduling.
I0714 09:23:10.425966       1 session.go:190] Open Session d8f1f5c9-734c-4b06-a819-b97290fa2e83 with <0> Job and <1> Queues
I0714 09:23:10.428116       1 enqueue.go:79] Try to enqueue PodGroup to 0 Queues
I0714 09:23:10.428201       1 allocate.go:64] Try to allocate resource to 0 Queues
I0714 09:23:10.428455       1 session.go:244] Close Session d8f1f5c9-734c-4b06-a819-b97290fa2e83
I0714 09:23:11.431291       1 cache.go:1363] There are <0> Jobs, <1> Queues and <5> Nodes in total for scheduling.
I0714 09:23:11.431467       1 session.go:190] Open Session 7b8224f6-be24-4cca-9837-d4be057325bf with <0> Job and <1> Queues
I0714 09:23:11.433440       1 enqueue.go:79] Try to enqueue PodGroup to 0 Queues
I0714 09:23:11.433519       1 allocate.go:64] Try to allocate resource to 0 Queues
I0714 09:23:11.433773       1 session.go:244] Close Session 7b8224f6-be24-4cca-9837-d4be057325bf
I0714 09:23:12.436255       1 cache.go:1363] There are <0> Jobs, <1> Queues and <5> Nodes in total for scheduling.
I0714 09:23:12.436469       1 session.go:190] Open Session 13c0e835-30b4-4cae-90d3-103ec2fc819a with <0> Job and <1> Queues
I0714 09:23:12.438359       1 enqueue.go:79] Try to enqueue PodGroup to 0 Queues
I0714 09:23:12.438436       1 allocate.go:64] Try to allocate resource to 0 Queues
I0714 09:23:12.438789       1 session.go:244] Close Session 13c0e835-30b4-4cae-90d3-103ec2fc819a
I0714 09:23:13.441817       1 cache.go:1363] There are <0> Jobs, <1> Queues and <5> Nodes in total for scheduling.
I0714 09:23:13.441987       1 session.go:190] Open Session e02dbe1c-995c-4905-8795-590aa5619012 with <0> Job and <1> Queues
I0714 09:23:13.443922       1 enqueue.go:79] Try to enqueue PodGroup to 0 Queues
I0714 09:23:13.443991       1 allocate.go:64] Try to allocate resource to 0 Queues
I0714 09:23:13.444209       1 session.go:244] Close Session e02dbe1c-995c-4905-8795-590aa5619012
I0714 09:23:14.446976       1 cache.go:1363] There are <0> Jobs, <1> Queues and <5> Nodes in total for scheduling.
I0714 09:23:14.447145       1 session.go:190] Open Session b891b29f-249d-4796-a357-44ca76baf590 with <0> Job and <1> Queues
I0714 09:23:14.449140       1 enqueue.go:79] Try to enqueue PodGroup to 0 Queues
I0714 09:23:14.449219       1 allocate.go:64] Try to allocate resource to 0 Queues
I0714 09:23:14.449434       1 session.go:244] Close Session b891b29f-249d-4796-a357-44ca76baf590
I0714 09:23:15.451816       1 cache.go:1363] There are <0> Jobs, <1> Queues and <5> Nodes in total for scheduling.
I0714 09:23:15.451985       1 session.go:190] Open Session f1bc624a-abf6-48b9-9a3c-efaf9bd852c9 with <0> Job and <1> Queues
I0714 09:23:15.453847       1 enqueue.go:79] Try to enqueue PodGroup to 0 Queues
I0714 09:23:15.453922       1 allocate.go:64] Try to allocate resource to 0 Queues
I0714 09:23:15.454116       1 session.go:244] Close Session f1bc624a-abf6-48b9-9a3c-efaf9bd852c9
I0714 09:23:16.456704       1 cache.go:1363] There are <0> Jobs, <1> Queues and <5> Nodes in total for scheduling.
I0714 09:23:16.456842       1 session.go:190] Open Session 4f497dd2-a895-4f3f-ae9b-6ca5a464acab with <0> Job and <1> Queues
I0714 09:23:16.458634       1 enqueue.go:79] Try to enqueue PodGroup to 0 Queues
I0714 09:23:16.458717       1 allocate.go:64] Try to allocate resource to 0 Queues
I0714 09:23:16.458931       1 session.go:244] Close Session 4f497dd2-a895-4f3f-ae9b-6ca5a464acab
I0714 09:23:17.461824       1 cache.go:1363] There are <0> Jobs, <1> Queues and <5> Nodes in total for scheduling.
I0714 09:23:17.461981       1 session.go:190] Open Session 9a2fcfc7-900c-4b5f-8b83-e762527d2980 with <0> Job and <1> Queues
I0714 09:23:17.463886       1 enqueue.go:79] Try to enqueue PodGroup to 0 Queues
I0714 09:23:17.463954       1 allocate.go:64] Try to allocate resource to 0 Queues
I0714 09:23:17.464172       1 session.go:244] Close Session 9a2fcfc7-900c-4b5f-8b83-e762527d2980
W0714 09:23:18.145624       1 event_handlers.go:181] Not support non-csi pvc.
I0714 09:23:18.148465       1 event_handlers.go:442] Deleted pod <default/yolo-cls> from cache.
W0714 09:23:18.211395       1 event_handlers.go:181] Not support non-csi pvc.
I0714 09:23:18.214008       1 event_handlers.go:442] Deleted pod <default/yolo-det> from cache.
W0714 09:23:18.272154       1 event_handlers.go:181] Not support non-csi pvc.
I0714 09:23:18.276254       1 event_handlers.go:442] Deleted pod <default/yolo-seg> from cache.
W0714 09:23:18.332994       1 event_handlers.go:181] Not support non-csi pvc.
I0714 09:23:18.337729       1 event_handlers.go:442] Deleted pod <default/yolo-obb> from cache.
W0714 09:23:18.396367       1 event_handlers.go:181] Not support non-csi pvc.
I0714 09:23:18.405766       1 event_handlers.go:442] Deleted pod <default/yolo-pos> from cache.
I0714 09:23:18.466046       1 cache.go:1363] There are <0> Jobs, <1> Queues and <5> Nodes in total for scheduling.
I0714 09:23:18.466155       1 session.go:190] Open Session 906d24d0-4917-457c-ba63-7edd718e157a with <0> Job and <1> Queues
I0714 09:23:18.467873       1 enqueue.go:79] Try to enqueue PodGroup to 0 Queues
I0714 09:23:18.467951       1 allocate.go:64] Try to allocate resource to 0 Queues
I0714 09:23:18.468166       1 session.go:244] Close Session 906d24d0-4917-457c-ba63-7edd718e157a
I0714 09:23:19.470610       1 cache.go:1363] There are <0> Jobs, <1> Queues and <5> Nodes in total for scheduling.
I0714 09:23:19.470790       1 session.go:190] Open Session 0fcece30-a3af-4b4b-abaf-b85031ad6a54 with <0> Job and <1> Queues
I0714 09:23:19.472655       1 enqueue.go:79] Try to enqueue PodGroup to 0 Queues
I0714 09:23:19.472718       1 allocate.go:64] Try to allocate resource to 0 Queues
I0714 09:23:19.472917       1 session.go:244] Close Session 0fcece30-a3af-4b4b-abaf-b85031ad6a54
I0714 09:23:20.475426       1 cache.go:1363] There are <0> Jobs, <1> Queues and <5> Nodes in total for scheduling.
I0714 09:23:20.475611       1 session.go:190] Open Session 3b556026-b54b-4a22-b5ad-23e2b0f5772e with <0> Job and <1> Queues
I0714 09:23:20.477383       1 enqueue.go:79] Try to enqueue PodGroup to 0 Queues
I0714 09:23:20.477461       1 allocate.go:64] Try to allocate resource to 0 Queues
I0714 09:23:20.477675       1 session.go:244] Close Session 3b556026-b54b-4a22-b5ad-23e2b0f5772e
I0714 09:23:21.479960       1 cache.go:1363] There are <0> Jobs, <1> Queues and <5> Nodes in total for scheduling.
I0714 09:23:21.480136       1 session.go:190] Open Session 16931cc4-5053-4fe9-b00f-ccd98a4da46c with <0> Job and <1> Queues
I0714 09:23:21.481918       1 enqueue.go:79] Try to enqueue PodGroup to 0 Queues
I0714 09:23:21.481994       1 allocate.go:64] Try to allocate resource to 0 Queues
I0714 09:23:21.482229       1 session.go:244] Close Session 16931cc4-5053-4fe9-b00f-ccd98a4da46c
I0714 09:23:22.484879       1 cache.go:1363] There are <0> Jobs, <1> Queues and <5> Nodes in total for scheduling.
I0714 09:23:22.485051       1 session.go:190] Open Session 1bc5e886-eab3-48d4-a653-797b781831d1 with <0> Job and <1> Queues
I0714 09:23:22.486947       1 enqueue.go:79] Try to enqueue PodGroup to 0 Queues
I0714 09:23:22.487021       1 allocate.go:64] Try to allocate resource to 0 Queues
I0714 09:23:22.487241       1 session.go:244] Close Session 1bc5e886-eab3-48d4-a653-797b781831d1
I0714 09:23:23.491357       1 cache.go:1363] There are <0> Jobs, <1> Queues and <5> Nodes in total for scheduling.
I0714 09:23:23.491611       1 session.go:190] Open Session 53a45745-1227-4d99-93ab-cb0772e8e908 with <0> Job and <1> Queues
I0714 09:23:23.493716       1 enqueue.go:79] Try to enqueue PodGroup to 0 Queues
I0714 09:23:23.493807       1 allocate.go:64] Try to allocate resource to 0 Queues
I0714 09:23:23.494071       1 session.go:244] Close Session 53a45745-1227-4d99-93ab-cb0772e8e908
I0714 09:23:24.496206       1 cache.go:1363] There are <0> Jobs, <1> Queues and <5> Nodes in total for scheduling.
I0714 09:23:24.496439       1 session.go:190] Open Session 6ad721d4-4200-4b2b-bc14-93c822e8ac8d with <0> Job and <1> Queues
I0714 09:23:24.498227       1 enqueue.go:79] Try to enqueue PodGroup to 0 Queues
I0714 09:23:24.498296       1 allocate.go:64] Try to allocate resource to 0 Queues
I0714 09:23:24.498514       1 session.go:244] Close Session 6ad721d4-4200-4b2b-bc14-93c822e8ac8d
I0714 09:23:25.501356       1 cache.go:1363] There are <0> Jobs, <1> Queues and <5> Nodes in total for scheduling.
I0714 09:23:25.501530       1 session.go:190] Open Session a95e3745-c2df-488f-b880-53186cde1557 with <0> Job and <1> Queues
I0714 09:23:25.503292       1 enqueue.go:79] Try to enqueue PodGroup to 0 Queues
I0714 09:23:25.503364       1 allocate.go:64] Try to allocate resource to 0 Queues
I0714 09:23:25.503581       1 session.go:244] Close Session a95e3745-c2df-488f-b880-53186cde1557
I0714 09:23:26.505843       1 cache.go:1363] There are <0> Jobs, <1> Queues and <5> Nodes in total for scheduling.
I0714 09:23:26.506022       1 session.go:190] Open Session 84cee063-d71b-4327-9942-3e59eb71f98f with <0> Job and <1> Queues
I0714 09:23:26.507722       1 enqueue.go:79] Try to enqueue PodGroup to 0 Queues
I0714 09:23:26.507786       1 allocate.go:64] Try to allocate resource to 0 Queues
I0714 09:23:26.507998       1 session.go:244] Close Session 84cee063-d71b-4327-9942-3e59eb71f98f
I0714 09:23:27.510624       1 cache.go:1363] There are <0> Jobs, <1> Queues and <5> Nodes in total for scheduling.
I0714 09:23:27.510785       1 session.go:190] Open Session 4e69331b-880a-475d-91bb-d4c95fb1ca9a with <0> Job and <1> Queues
I0714 09:23:27.512723       1 enqueue.go:79] Try to enqueue PodGroup to 0 Queues
I0714 09:23:27.512789       1 allocate.go:64] Try to allocate resource to 0 Queues
I0714 09:23:27.513022       1 session.go:244] Close Session 4e69331b-880a-475d-91bb-d4c95fb1ca9a
I0714 09:23:28.515871       1 cache.go:1363] There are <0> Jobs, <1> Queues and <5> Nodes in total for scheduling.
I0714 09:23:28.516029       1 session.go:190] Open Session 5256dafe-59fb-440a-aee1-04531c673a20 with <0> Job and <1> Queues
I0714 09:23:28.517917       1 enqueue.go:79] Try to enqueue PodGroup to 0 Queues
I0714 09:23:28.517997       1 allocate.go:64] Try to allocate resource to 0 Queues
I0714 09:23:28.518199       1 session.go:244] Close Session 5256dafe-59fb-440a-aee1-04531c673a20
I0714 09:23:29.521041       1 cache.go:1363] There are <0> Jobs, <1> Queues and <5> Nodes in total for scheduling.
I0714 09:23:29.521214       1 session.go:190] Open Session 76602a36-c9e2-43ec-ae7e-ea6bc0923cd1 with <0> Job and <1> Queues
I0714 09:23:29.522980       1 enqueue.go:79] Try to enqueue PodGroup to 0 Queues
I0714 09:23:29.523077       1 allocate.go:64] Try to allocate resource to 0 Queues
I0714 09:23:29.523290       1 session.go:244] Close Session 76602a36-c9e2-43ec-ae7e-ea6bc0923cd1
I0714 09:23:30.525131       1 cache.go:1363] There are <0> Jobs, <1> Queues and <5> Nodes in total for scheduling.
I0714 09:23:30.525212       1 session.go:190] Open Session 53f17374-b0d0-405b-88ef-444c76fc234d with <0> Job and <1> Queues
I0714 09:23:30.526006       1 enqueue.go:79] Try to enqueue PodGroup to 0 Queues
I0714 09:23:30.526045       1 allocate.go:64] Try to allocate resource to 0 Queues
I0714 09:23:30.526156       1 session.go:244] Close Session 53f17374-b0d0-405b-88ef-444c76fc234d
I0714 09:23:31.528899       1 cache.go:1363] There are <0> Jobs, <1> Queues and <5> Nodes in total for scheduling.
I0714 09:23:31.529082       1 session.go:190] Open Session 7f7abe56-29c8-4544-905d-846222f2397f with <0> Job and <1> Queues
I0714 09:23:31.530842       1 enqueue.go:79] Try to enqueue PodGroup to 0 Queues
I0714 09:23:31.530912       1 allocate.go:64] Try to allocate resource to 0 Queues
I0714 09:23:31.531141       1 session.go:244] Close Session 7f7abe56-29c8-4544-905d-846222f2397f
I0714 09:23:32.533917       1 cache.go:1363] There are <0> Jobs, <1> Queues and <5> Nodes in total for scheduling.
I0714 09:23:32.534081       1 session.go:190] Open Session 56403859-6afe-47ed-873e-910fa509b4a7 with <0> Job and <1> Queues
I0714 09:23:32.535836       1 enqueue.go:79] Try to enqueue PodGroup to 0 Queues
I0714 09:23:32.535903       1 allocate.go:64] Try to allocate resource to 0 Queues
I0714 09:23:32.536130       1 session.go:244] Close Session 56403859-6afe-47ed-873e-910fa509b4a7
I0714 09:23:33.538922       1 cache.go:1363] There are <0> Jobs, <1> Queues and <5> Nodes in total for scheduling.
I0714 09:23:33.539098       1 session.go:190] Open Session 6433d38f-4750-433c-b4c5-bfadfeec08d3 with <0> Job and <1> Queues
I0714 09:23:33.540932       1 enqueue.go:79] Try to enqueue PodGroup to 0 Queues
I0714 09:23:33.541001       1 allocate.go:64] Try to allocate resource to 0 Queues
I0714 09:23:33.541229       1 session.go:244] Close Session 6433d38f-4750-433c-b4c5-bfadfeec08d3
I0714 09:23:34.543781       1 cache.go:1363] There are <0> Jobs, <1> Queues and <5> Nodes in total for scheduling.
I0714 09:23:34.543993       1 session.go:190] Open Session a006719b-7eca-405c-98a4-9bccbba45a94 with <0> Job and <1> Queues
I0714 09:23:34.545876       1 enqueue.go:79] Try to enqueue PodGroup to 0 Queues
I0714 09:23:34.545942       1 allocate.go:64] Try to allocate resource to 0 Queues
I0714 09:23:34.546189       1 session.go:244] Close Session a006719b-7eca-405c-98a4-9bccbba45a94
I0714 09:23:35.548936       1 cache.go:1363] There are <0> Jobs, <1> Queues and <5> Nodes in total for scheduling.
I0714 09:23:35.549137       1 session.go:190] Open Session b283bda5-c8bd-4ac6-85f7-0f151acefea9 with <0> Job and <1> Queues
I0714 09:23:35.550859       1 enqueue.go:79] Try to enqueue PodGroup to 0 Queues
I0714 09:23:35.550923       1 allocate.go:64] Try to allocate resource to 0 Queues
I0714 09:23:35.551156       1 session.go:244] Close Session b283bda5-c8bd-4ac6-85f7-0f151acefea9
I0714 09:23:36.553303       1 cache.go:1363] There are <0> Jobs, <1> Queues and <5> Nodes in total for scheduling.
I0714 09:23:36.553478       1 session.go:190] Open Session 897a1dc2-6ba3-472b-b726-adb27bd39ca6 with <0> Job and <1> Queues
I0714 09:23:36.555253       1 enqueue.go:79] Try to enqueue PodGroup to 0 Queues
I0714 09:23:36.555317       1 allocate.go:64] Try to allocate resource to 0 Queues
I0714 09:23:36.555550       1 session.go:244] Close Session 897a1dc2-6ba3-472b-b726-adb27bd39ca6
I0714 09:23:36.662438       1 cache.go:1489] The metrics type is not set in the volcano scheduler configmap file. As a result, the CPU and memory load information of the node is not collected.
I0714 09:23:37.557635       1 cache.go:1363] There are <0> Jobs, <1> Queues and <5> Nodes in total for scheduling.
I0714 09:23:37.557801       1 session.go:190] Open Session 362a3b96-c872-4a73-8e7e-799705543d69 with <0> Job and <1> Queues
I0714 09:23:37.559548       1 enqueue.go:79] Try to enqueue PodGroup to 0 Queues
I0714 09:23:37.559717       1 allocate.go:64] Try to allocate resource to 0 Queues
I0714 09:23:37.559943       1 session.go:244] Close Session 362a3b96-c872-4a73-8e7e-799705543d69
I0714 09:23:38.562646       1 cache.go:1363] There are <0> Jobs, <1> Queues and <5> Nodes in total for scheduling.
I0714 09:23:38.562923       1 session.go:190] Open Session e41dcf12-eb06-4271-94f1-912f01cbf58e with <0> Job and <1> Queues
I0714 09:23:38.564695       1 enqueue.go:79] Try to enqueue PodGroup to 0 Queues
I0714 09:23:38.564762       1 allocate.go:64] Try to allocate resource to 0 Queues
I0714 09:23:38.564993       1 session.go:244] Close Session e41dcf12-eb06-4271-94f1-912f01cbf58e
I0714 09:23:39.567456       1 cache.go:1363] There are <0> Jobs, <1> Queues and <5> Nodes in total for scheduling.
I0714 09:23:39.567626       1 session.go:190] Open Session 4ee0c78a-ddcc-48aa-8379-452ac45b7b3d with <0> Job and <1> Queues
I0714 09:23:39.569582       1 enqueue.go:79] Try to enqueue PodGroup to 0 Queues
I0714 09:23:39.569655       1 allocate.go:64] Try to allocate resource to 0 Queues
I0714 09:23:39.569886       1 session.go:244] Close Session 4ee0c78a-ddcc-48aa-8379-452ac45b7b3d
I0714 09:23:40.572982       1 cache.go:1363] There are <0> Jobs, <1> Queues and <5> Nodes in total for scheduling.
I0714 09:23:40.573151       1 session.go:190] Open Session 41d72b32-2984-4237-9606-fea4b421c047 with <0> Job and <1> Queues
I0714 09:23:40.574853       1 enqueue.go:79] Try to enqueue PodGroup to 0 Queues
I0714 09:23:40.574919       1 allocate.go:64] Try to allocate resource to 0 Queues
I0714 09:23:40.575153       1 session.go:244] Close Session 41d72b32-2984-4237-9606-fea4b421c047
I0714 09:23:41.577477       1 cache.go:1363] There are <0> Jobs, <1> Queues and <5> Nodes in total for scheduling.
I0714 09:23:41.577641       1 session.go:190] Open Session c4ae992a-a683-4dc6-a3a4-1c5469bf22b8 with <0> Job and <1> Queues
I0714 09:23:41.579365       1 enqueue.go:79] Try to enqueue PodGroup to 0 Queues
I0714 09:23:41.579432       1 allocate.go:64] Try to allocate resource to 0 Queues
I0714 09:23:41.579750       1 session.go:244] Close Session c4ae992a-a683-4dc6-a3a4-1c5469bf22b8
I0714 09:23:42.582311       1 cache.go:1363] There are <0> Jobs, <1> Queues and <5> Nodes in total for scheduling.
I0714 09:23:42.582476       1 session.go:190] Open Session 1375ddcc-da3f-4b1e-9c6e-98211131e033 with <0> Job and <1> Queues
I0714 09:23:42.584459       1 enqueue.go:79] Try to enqueue PodGroup to 0 Queues
I0714 09:23:42.584525       1 allocate.go:64] Try to allocate resource to 0 Queues
I0714 09:23:42.584763       1 session.go:244] Close Session 1375ddcc-da3f-4b1e-9c6e-98211131e033
I0714 09:23:43.587203       1 cache.go:1363] There are <0> Jobs, <1> Queues and <5> Nodes in total for scheduling.
I0714 09:23:43.587370       1 session.go:190] Open Session a0d14ad6-97ac-4b1a-a620-d8a3b37100a5 with <0> Job and <1> Queues
I0714 09:23:43.589133       1 enqueue.go:79] Try to enqueue PodGroup to 0 Queues
I0714 09:23:43.589206       1 allocate.go:64] Try to allocate resource to 0 Queues
I0714 09:23:43.589415       1 session.go:244] Close Session a0d14ad6-97ac-4b1a-a620-d8a3b37100a5
I0714 09:23:44.592213       1 cache.go:1363] There are <0> Jobs, <1> Queues and <5> Nodes in total for scheduling.
I0714 09:23:44.592479       1 session.go:190] Open Session c5a404ee-e0d3-4958-8676-4e7580e1b1f7 with <0> Job and <1> Queues
I0714 09:23:44.594256       1 enqueue.go:79] Try to enqueue PodGroup to 0 Queues
I0714 09:23:44.594320       1 allocate.go:64] Try to allocate resource to 0 Queues
I0714 09:23:44.594522       1 session.go:244] Close Session c5a404ee-e0d3-4958-8676-4e7580e1b1f7
I0714 09:23:45.596902       1 cache.go:1363] There are <0> Jobs, <1> Queues and <5> Nodes in total for scheduling.
I0714 09:23:45.597085       1 session.go:190] Open Session 8b36fd12-b634-4d4d-bf62-418667f3442c with <0> Job and <1> Queues
I0714 09:23:45.598918       1 enqueue.go:79] Try to enqueue PodGroup to 0 Queues
I0714 09:23:45.598987       1 allocate.go:64] Try to allocate resource to 0 Queues
I0714 09:23:45.599224       1 session.go:244] Close Session 8b36fd12-b634-4d4d-bf62-418667f3442c
I0714 09:23:46.601685       1 cache.go:1363] There are <0> Jobs, <1> Queues and <5> Nodes in total for scheduling.
I0714 09:23:46.601848       1 session.go:190] Open Session 8a9b86af-6bee-4129-8c97-1164235d34a3 with <0> Job and <1> Queues
I0714 09:23:46.603584       1 enqueue.go:79] Try to enqueue PodGroup to 0 Queues
I0714 09:23:46.603650       1 allocate.go:64] Try to allocate resource to 0 Queues
I0714 09:23:46.603875       1 session.go:244] Close Session 8a9b86af-6bee-4129-8c97-1164235d34a3
I0714 09:23:47.606463       1 cache.go:1363] There are <0> Jobs, <1> Queues and <5> Nodes in total for scheduling.
I0714 09:23:47.606620       1 session.go:190] Open Session 5acc60c4-e18e-49e9-8161-06cb309c0fb9 with <0> Job and <1> Queues
I0714 09:23:47.608405       1 enqueue.go:79] Try to enqueue PodGroup to 0 Queues
I0714 09:23:47.608466       1 allocate.go:64] Try to allocate resource to 0 Queues
I0714 09:23:47.608684       1 session.go:244] Close Session 5acc60c4-e18e-49e9-8161-06cb309c0fb9
I0714 09:23:48.611237       1 cache.go:1363] There are <0> Jobs, <1> Queues and <5> Nodes in total for scheduling.
I0714 09:23:48.611429       1 session.go:190] Open Session 41e4a19c-0d2d-4533-8539-d1bf7a983279 with <0> Job and <1> Queues
I0714 09:23:48.613190       1 enqueue.go:79] Try to enqueue PodGroup to 0 Queues
I0714 09:23:48.613257       1 allocate.go:64] Try to allocate resource to 0 Queues
I0714 09:23:48.613465       1 session.go:244] Close Session 41e4a19c-0d2d-4533-8539-d1bf7a983279
I0714 09:23:49.615446       1 cache.go:1363] There are <0> Jobs, <1> Queues and <5> Nodes in total for scheduling.
I0714 09:23:49.615631       1 session.go:190] Open Session 0efc5b6d-1d21-4d73-a9cb-9bf6b7298da9 with <0> Job and <1> Queues
I0714 09:23:49.617517       1 enqueue.go:79] Try to enqueue PodGroup to 0 Queues
I0714 09:23:49.617590       1 allocate.go:64] Try to allocate resource to 0 Queues
I0714 09:23:49.617824       1 session.go:244] Close Session 0efc5b6d-1d21-4d73-a9cb-9bf6b7298da9
I0714 09:23:50.620744       1 cache.go:1363] There are <0> Jobs, <1> Queues and <5> Nodes in total for scheduling.
I0714 09:23:50.620906       1 session.go:190] Open Session 05ff1cd1-52bb-4a80-b1dc-8737b10e1fc3 with <0> Job and <1> Queues
I0714 09:23:50.622637       1 enqueue.go:79] Try to enqueue PodGroup to 0 Queues
I0714 09:23:50.622703       1 allocate.go:64] Try to allocate resource to 0 Queues
I0714 09:23:50.622929       1 session.go:244] Close Session 05ff1cd1-52bb-4a80-b1dc-8737b10e1fc3
I0714 09:23:51.625759       1 cache.go:1363] There are <0> Jobs, <1> Queues and <5> Nodes in total for scheduling.
I0714 09:23:51.625929       1 session.go:190] Open Session 71ca00d8-f33b-44ee-8c57-9ffec77c6c03 with <0> Job and <1> Queues
I0714 09:23:51.627706       1 enqueue.go:79] Try to enqueue PodGroup to 0 Queues
I0714 09:23:51.627772       1 allocate.go:64] Try to allocate resource to 0 Queues
I0714 09:23:51.627995       1 session.go:244] Close Session 71ca00d8-f33b-44ee-8c57-9ffec77c6c03
I0714 09:23:52.630272       1 cache.go:1363] There are <0> Jobs, <1> Queues and <5> Nodes in total for scheduling.
I0714 09:23:52.630471       1 session.go:190] Open Session 2be8ec15-d139-49fb-9c2d-07834849af64 with <0> Job and <1> Queues
I0714 09:23:52.632267       1 enqueue.go:79] Try to enqueue PodGroup to 0 Queues
I0714 09:23:52.632369       1 allocate.go:64] Try to allocate resource to 0 Queues
I0714 09:23:52.632587       1 session.go:244] Close Session 2be8ec15-d139-49fb-9c2d-07834849af64
I0714 09:23:53.635375       1 cache.go:1363] There are <0> Jobs, <1> Queues and <5> Nodes in total for scheduling.
I0714 09:23:53.635570       1 session.go:190] Open Session 179a84b0-1ddd-415d-9a50-798b1d0fe977 with <0> Job and <1> Queues
I0714 09:23:53.637480       1 enqueue.go:79] Try to enqueue PodGroup to 0 Queues
I0714 09:23:53.637554       1 allocate.go:64] Try to allocate resource to 0 Queues
I0714 09:23:53.637764       1 session.go:244] Close Session 179a84b0-1ddd-415d-9a50-798b1d0fe977
I0714 09:23:54.640161       1 cache.go:1363] There are <0> Jobs, <1> Queues and <5> Nodes in total for scheduling.
I0714 09:23:54.640369       1 session.go:190] Open Session 9bbb8b9f-4b04-4ea0-88d8-e725dafb6d55 with <0> Job and <1> Queues
I0714 09:23:54.642157       1 enqueue.go:79] Try to enqueue PodGroup to 0 Queues
I0714 09:23:54.642230       1 allocate.go:64] Try to allocate resource to 0 Queues
I0714 09:23:54.642944       1 session.go:244] Close Session 9bbb8b9f-4b04-4ea0-88d8-e725dafb6d55
I0714 09:23:55.646106       1 cache.go:1363] There are <0> Jobs, <1> Queues and <5> Nodes in total for scheduling.
I0714 09:23:55.646279       1 session.go:190] Open Session fe755d31-6ddd-4f27-a21a-4618f05478b4 with <0> Job and <1> Queues
I0714 09:23:55.648040       1 enqueue.go:79] Try to enqueue PodGroup to 0 Queues
I0714 09:23:55.648111       1 allocate.go:64] Try to allocate resource to 0 Queues
I0714 09:23:55.648663       1 session.go:244] Close Session fe755d31-6ddd-4f27-a21a-4618f05478b4
I0714 09:23:56.651546       1 cache.go:1363] There are <0> Jobs, <1> Queues and <5> Nodes in total for scheduling.
I0714 09:23:56.651710       1 session.go:190] Open Session ca0c9458-bccf-479c-b30a-63fd8e5e4792 with <0> Job and <1> Queues
I0714 09:23:56.653823       1 enqueue.go:79] Try to enqueue PodGroup to 0 Queues
I0714 09:23:56.653916       1 allocate.go:64] Try to allocate resource to 0 Queues
I0714 09:23:56.654137       1 session.go:244] Close Session ca0c9458-bccf-479c-b30a-63fd8e5e4792
I0714 09:23:57.656527       1 cache.go:1363] There are <0> Jobs, <1> Queues and <5> Nodes in total for scheduling.
I0714 09:23:57.656684       1 session.go:190] Open Session b2383e47-94fe-45f2-a217-7319c4981ac4 with <0> Job and <1> Queues
I0714 09:23:57.658447       1 enqueue.go:79] Try to enqueue PodGroup to 0 Queues
I0714 09:23:57.658515       1 allocate.go:64] Try to allocate resource to 0 Queues
I0714 09:23:57.658725       1 session.go:244] Close Session b2383e47-94fe-45f2-a217-7319c4981ac4
I0714 09:23:58.661628       1 cache.go:1363] There are <0> Jobs, <1> Queues and <5> Nodes in total for scheduling.
I0714 09:23:58.661794       1 session.go:190] Open Session 2877c9b2-d49f-443f-9991-03e64f801596 with <0> Job and <1> Queues
I0714 09:23:58.663604       1 enqueue.go:79] Try to enqueue PodGroup to 0 Queues
I0714 09:23:58.663670       1 allocate.go:64] Try to allocate resource to 0 Queues
I0714 09:23:58.663874       1 session.go:244] Close Session 2877c9b2-d49f-443f-9991-03e64f801596
I0714 09:23:59.666273       1 cache.go:1363] There are <0> Jobs, <1> Queues and <5> Nodes in total for scheduling.
I0714 09:23:59.666450       1 session.go:190] Open Session 108a4f8c-4c43-40e0-9ace-ca442718bbbe with <0> Job and <1> Queues
I0714 09:23:59.668358       1 enqueue.go:79] Try to enqueue PodGroup to 0 Queues
I0714 09:23:59.668442       1 allocate.go:64] Try to allocate resource to 0 Queues
I0714 09:23:59.668675       1 session.go:244] Close Session 108a4f8c-4c43-40e0-9ace-ca442718bbbe
I0714 09:24:00.670821       1 cache.go:1363] There are <0> Jobs, <1> Queues and <5> Nodes in total for scheduling.
I0714 09:24:00.670990       1 session.go:190] Open Session 3400c956-312e-45a9-a464-9f7e5056262e with <0> Job and <1> Queues
I0714 09:24:00.672808       1 enqueue.go:79] Try to enqueue PodGroup to 0 Queues
I0714 09:24:00.672879       1 allocate.go:64] Try to allocate resource to 0 Queues
I0714 09:24:00.673117       1 session.go:244] Close Session 3400c956-312e-45a9-a464-9f7e5056262e
I0714 09:24:01.676121       1 cache.go:1363] There are <0> Jobs, <1> Queues and <5> Nodes in total for scheduling.
I0714 09:24:01.676324       1 session.go:190] Open Session b864cc76-7768-4770-b93c-4e52a504f70d with <0> Job and <1> Queues
I0714 09:24:01.678119       1 enqueue.go:79] Try to enqueue PodGroup to 0 Queues
I0714 09:24:01.678195       1 allocate.go:64] Try to allocate resource to 0 Queues
I0714 09:24:01.678407       1 session.go:244] Close Session b864cc76-7768-4770-b93c-4e52a504f70d
I0714 09:24:02.680810       1 cache.go:1363] There are <0> Jobs, <1> Queues and <5> Nodes in total for scheduling.
I0714 09:24:02.680975       1 session.go:190] Open Session 6e121e38-8f24-4c50-a272-98d2b4c199a6 with <0> Job and <1> Queues
I0714 09:24:02.682780       1 enqueue.go:79] Try to enqueue PodGroup to 0 Queues
I0714 09:24:02.682866       1 allocate.go:64] Try to allocate resource to 0 Queues
I0714 09:24:02.683084       1 session.go:244] Close Session 6e121e38-8f24-4c50-a272-98d2b4c199a6
I0714 09:24:03.686391       1 cache.go:1363] There are <0> Jobs, <1> Queues and <5> Nodes in total for scheduling.
I0714 09:24:03.686563       1 session.go:190] Open Session dd91c334-736c-427e-ba4a-76f132b26c8c with <0> Job and <1> Queues
I0714 09:24:03.688468       1 enqueue.go:79] Try to enqueue PodGroup to 0 Queues
I0714 09:24:03.688545       1 allocate.go:64] Try to allocate resource to 0 Queues
I0714 09:24:03.688775       1 session.go:244] Close Session dd91c334-736c-427e-ba4a-76f132b26c8c
I0714 09:24:04.690039       1 cache.go:1363] There are <0> Jobs, <1> Queues and <5> Nodes in total for scheduling.
I0714 09:24:04.690131       1 session.go:190] Open Session 36eac381-188e-4e32-a3dd-0115cdbdac29 with <0> Job and <1> Queues
I0714 09:24:04.691074       1 enqueue.go:79] Try to enqueue PodGroup to 0 Queues
I0714 09:24:04.691120       1 allocate.go:64] Try to allocate resource to 0 Queues
I0714 09:24:04.691230       1 session.go:244] Close Session 36eac381-188e-4e32-a3dd-0115cdbdac29
I0714 09:24:05.693670       1 cache.go:1363] There are <0> Jobs, <1> Queues and <5> Nodes in total for scheduling.
I0714 09:24:05.693845       1 session.go:190] Open Session 55906905-788a-43d5-81af-c2c6256eb29c with <0> Job and <1> Queues
I0714 09:24:05.695669       1 enqueue.go:79] Try to enqueue PodGroup to 0 Queues
I0714 09:24:05.695736       1 allocate.go:64] Try to allocate resource to 0 Queues
I0714 09:24:05.695944       1 session.go:244] Close Session 55906905-788a-43d5-81af-c2c6256eb29c
I0714 09:24:06.663310       1 cache.go:1489] The metrics type is not set in the volcano scheduler configmap file. As a result, the CPU and memory load information of the node is not collected.
I0714 09:24:06.698830       1 cache.go:1363] There are <0> Jobs, <1> Queues and <5> Nodes in total for scheduling.
I0714 09:24:06.698954       1 session.go:190] Open Session 5e85fe8f-3c9e-41e6-a430-86659bcad745 with <0> Job and <1> Queues
I0714 09:24:06.700912       1 enqueue.go:79] Try to enqueue PodGroup to 0 Queues
I0714 09:24:06.700985       1 allocate.go:64] Try to allocate resource to 0 Queues
I0714 09:24:06.701223       1 session.go:244] Close Session 5e85fe8f-3c9e-41e6-a430-86659bcad745
W0714 09:24:06.726477       1 event_handlers.go:181] Not support non-csi pvc.
I0714 09:24:06.726560       1 event_handlers.go:387] Added pod <default/yolo-cls> into cache.
W0714 09:24:06.751541       1 event_handlers.go:181] Not support non-csi pvc.
I0714 09:24:07.704496       1 cache.go:1363] There are <1> Jobs, <1> Queues and <5> Nodes in total for scheduling.
I0714 09:24:07.704683       1 session.go:190] Open Session 54491977-7e4a-44f7-ad79-c62f9a4cc279 with <1> Job and <1> Queues
I0714 09:24:07.706830       1 enqueue.go:79] Try to enqueue PodGroup to 1 Queues
I0714 09:24:07.707067       1 allocate.go:64] Try to allocate resource to 1 Queues
I0714 09:24:07.707121       1 allocate.go:129] Try to allocate resource to Jobs in Queue <default>
I0714 09:24:07.707155       1 allocate.go:161] Try to allocate resource to 1 tasks of Job <default/podgroup-01158d73-5d7e-4fc1-9da4-f7bd655e026b>
I0714 09:24:07.707203       1 allocate.go:181] There are <5> nodes for Job <default/podgroup-01158d73-5d7e-4fc1-9da4-f7bd655e026b>
I0714 09:24:07.707524       1 predicate_helper.go:75] Predicates failed: task default/yolo-cls on node gpu-master fit failed: Insufficient nvidia.com/gpu
I0714 09:24:07.707915       1 predicate_helper.go:75] Predicates failed: task default/yolo-cls on node gpuorin4-desktop fit failed: plugin NodeAffinity predicates failed node(s) didn't match Pod's node affinity/selector
I0714 09:24:07.708027       1 predicate_helper.go:75] Predicates failed: task default/yolo-cls on node gpuorin5-desktop fit failed: plugin NodeAffinity predicates failed node(s) didn't match Pod's node affinity/selector
I0714 09:24:07.708866       1 allocate.go:249] Binding Task <default/yolo-cls> to node <gpu-orin2>
I0714 09:24:07.709088       1 statement.go:266] After allocated Task <default/yolo-cls> to Node <gpu-orin2>: idle <cpu 5900.00, memory 7832690688.00, hugepages-1Gi 0.00, hugepages-2Mi 0.00, hugepages-32Mi 0.00, hugepages-64Ki 0.00, nvidia.com/gpu 4000.00, pods 105.00, ephemeral-storage 225118140453000.00>, used <cpu 100.00, memory 52428800.00, pods 5.00, nvidia.com/gpu 1000.00>, releasing <cpu 0.00, memory 0.00>
I0714 09:24:07.709530       1 statement.go:284] Allocating operations ...
I0714 09:24:07.709665       1 statement.go:378] Committing operations ...
I0714 09:24:07.709801       1 proportion.go:302] Queue <default>: deserved <cpu 0.00, memory 0.00, nvidia.com/gpu 1000.00, pods 1.00>, allocated <cpu 0.00, memory 0.00, pods 1.00, nvidia.com/gpu 1000.00>, share <1>
I0714 09:24:07.709874       1 allocate.go:125] Queue <default> is overused, ignore it.
I0714 09:24:07.730262       1 session.go:244] Close Session 54491977-7e4a-44f7-ad79-c62f9a4cc279
I0714 09:24:07.735235       1 cache.go:900] bind ok, latency 20.691196ms
W0714 09:24:07.738880       1 event_handlers.go:181] Not support non-csi pvc.
W0714 09:24:07.776618       1 event_handlers.go:181] Not support non-csi pvc.
W0714 09:24:07.949120       1 event_handlers.go:181] Not support non-csi pvc.
I0714 09:24:07.953041       1 event_handlers.go:442] Deleted pod <default/yolo-cls> from cache.
I0714 09:24:07.963205       1 cache.go:1013] Try to delete Job <default/podgroup-01158d73-5d7e-4fc1-9da4-f7bd655e026b:default/podgroup-01158d73-5d7e-4fc1-9da4-f7bd655e026b>
I0714 09:24:07.963435       1 cache.go:1054] Job <default/podgroup-01158d73-5d7e-4fc1-9da4-f7bd655e026b:default/podgroup-01158d73-5d7e-4fc1-9da4-f7bd655e026b> was deleted.
W0714 09:24:08.115840       1 event_handlers.go:181] Not support non-csi pvc.
I0714 09:24:08.115973       1 event_handlers.go:387] Added pod <default/yolo-cls> into cache.
W0714 09:24:08.144728       1 event_handlers.go:181] Not support non-csi pvc.
I0714 09:24:08.733392       1 cache.go:1363] There are <0> Jobs, <1> Queues and <5> Nodes in total for scheduling.
I0714 09:24:08.733562       1 session.go:190] Open Session 9a6f5cb2-baf8-4fb6-8f04-5702f3be6994 with <0> Job and <1> Queues
I0714 09:24:08.735320       1 enqueue.go:79] Try to enqueue PodGroup to 0 Queues
I0714 09:24:08.735395       1 allocate.go:64] Try to allocate resource to 0 Queues
I0714 09:24:08.735609       1 session.go:244] Close Session 9a6f5cb2-baf8-4fb6-8f04-5702f3be6994
I0714 09:24:09.737502       1 cache.go:1363] There are <0> Jobs, <1> Queues and <5> Nodes in total for scheduling.
I0714 09:24:09.737676       1 session.go:190] Open Session ac405ebb-16c7-4583-b8c0-bd555054aa8f with <0> Job and <1> Queues
I0714 09:24:09.739384       1 enqueue.go:79] Try to enqueue PodGroup to 0 Queues
I0714 09:24:09.739456       1 allocate.go:64] Try to allocate resource to 0 Queues
I0714 09:24:09.739936       1 session.go:244] Close Session ac405ebb-16c7-4583-b8c0-bd555054aa8f
W0714 09:24:10.196230       1 event_handlers.go:181] Not support non-csi pvc.
I0714 09:24:10.749887       1 cache.go:1363] There are <0> Jobs, <1> Queues and <5> Nodes in total for scheduling.
I0714 09:24:10.750151       1 session.go:190] Open Session 63c19c9c-da02-438c-baa4-f65e828a3a00 with <0> Job and <1> Queues
I0714 09:24:10.752256       1 enqueue.go:79] Try to enqueue PodGroup to 0 Queues
I0714 09:24:10.752461       1 allocate.go:64] Try to allocate resource to 0 Queues
I0714 09:24:10.752708       1 session.go:244] Close Session 63c19c9c-da02-438c-baa4-f65e828a3a00
I0714 09:24:11.754829       1 cache.go:1363] There are <0> Jobs, <1> Queues and <5> Nodes in total for scheduling.
I0714 09:24:11.755004       1 session.go:190] Open Session 652a0079-a759-4500-8c0a-08afe2bbc060 with <0> Job and <1> Queues
I0714 09:24:11.756777       1 enqueue.go:79] Try to enqueue PodGroup to 0 Queues
I0714 09:24:11.756869       1 allocate.go:64] Try to allocate resource to 0 Queues
I0714 09:24:11.757095       1 session.go:244] Close Session 652a0079-a759-4500-8c0a-08afe2bbc060
I0714 09:24:12.758746       1 cache.go:1363] There are <0> Jobs, <1> Queues and <5> Nodes in total for scheduling.
I0714 09:24:12.758852       1 session.go:190] Open Session e8c9cc2e-e9dd-4789-967f-ca7f526c2f95 with <0> Job and <1> Queues
I0714 09:24:12.759986       1 enqueue.go:79] Try to enqueue PodGroup to 0 Queues
I0714 09:24:12.760045       1 allocate.go:64] Try to allocate resource to 0 Queues
I0714 09:24:12.760181       1 session.go:244] Close Session e8c9cc2e-e9dd-4789-967f-ca7f526c2f95
I0714 09:24:13.762255       1 cache.go:1363] There are <0> Jobs, <1> Queues and <5> Nodes in total for scheduling.
I0714 09:24:13.762391       1 session.go:190] Open Session 83db29f9-b697-4887-8307-711bf8ef8b43 with <0> Job and <1> Queues
I0714 09:24:13.763734       1 enqueue.go:79] Try to enqueue PodGroup to 0 Queues
I0714 09:24:13.763818       1 allocate.go:64] Try to allocate resource to 0 Queues
I0714 09:24:13.763994       1 session.go:244] Close Session 83db29f9-b697-4887-8307-711bf8ef8b43
W0714 09:24:14.170548       1 event_handlers.go:181] Not support non-csi pvc.
I0714 09:24:14.170641       1 event_handlers.go:387] Added pod <default/yolo-det> into cache.
W0714 09:24:14.191890       1 event_handlers.go:181] Not support non-csi pvc.
I0714 09:24:14.766883       1 cache.go:1363] There are <1> Jobs, <1> Queues and <5> Nodes in total for scheduling.
I0714 09:24:14.767066       1 session.go:190] Open Session fae6272f-a1a0-40ed-9374-7dcbe7e04751 with <1> Job and <1> Queues
I0714 09:24:14.769143       1 enqueue.go:79] Try to enqueue PodGroup to 1 Queues
I0714 09:24:14.769311       1 allocate.go:64] Try to allocate resource to 1 Queues
I0714 09:24:14.769357       1 allocate.go:129] Try to allocate resource to Jobs in Queue <default>
I0714 09:24:14.769384       1 allocate.go:161] Try to allocate resource to 1 tasks of Job <default/podgroup-18add706-052d-4d2f-959f-b3250582c197>
I0714 09:24:14.769414       1 allocate.go:181] There are <5> nodes for Job <default/podgroup-18add706-052d-4d2f-959f-b3250582c197>
I0714 09:24:14.769581       1 predicate_helper.go:75] Predicates failed: task default/yolo-det on node gpu-master fit failed: Insufficient nvidia.com/gpu
I0714 09:24:14.769899       1 predicate_helper.go:75] Predicates failed: task default/yolo-det on node gpuorin4-desktop fit failed: plugin NodeAffinity predicates failed node(s) didn't match Pod's node affinity/selector
I0714 09:24:14.769962       1 predicate_helper.go:75] Predicates failed: task default/yolo-det on node gpuorin5-desktop fit failed: plugin NodeAffinity predicates failed node(s) didn't match Pod's node affinity/selector
I0714 09:24:14.770402       1 allocate.go:249] Binding Task <default/yolo-det> to node <gpu-orin3>
I0714 09:24:14.770517       1 statement.go:266] After allocated Task <default/yolo-det> to Node <gpu-orin3>: idle <cpu 5900.00, memory 7832723456.00, ephemeral-storage 111715275387000.00, hugepages-1Gi 0.00, nvidia.com/gpu 4000.00, pods 105.00, hugepages-2Mi 0.00, hugepages-32Mi 0.00, hugepages-64Ki 0.00>, used <cpu 100.00, memory 52428800.00, pods 5.00, nvidia.com/gpu 1000.00>, releasing <cpu 0.00, memory 0.00>
I0714 09:24:14.770757       1 statement.go:284] Allocating operations ...
I0714 09:24:14.770826       1 statement.go:378] Committing operations ...
I0714 09:24:14.770896       1 proportion.go:302] Queue <default>: deserved <cpu 0.00, memory 0.00, pods 1.00, nvidia.com/gpu 1000.00>, allocated <cpu 0.00, memory 0.00, nvidia.com/gpu 1000.00, pods 1.00>, share <1>
I0714 09:24:14.770940       1 allocate.go:125] Queue <default> is overused, ignore it.
I0714 09:24:14.789878       1 session.go:244] Close Session fae6272f-a1a0-40ed-9374-7dcbe7e04751
I0714 09:24:14.797375       1 cache.go:900] bind ok, latency 14.18695ms
W0714 09:24:14.798144       1 event_handlers.go:181] Not support non-csi pvc.
W0714 09:24:14.834668       1 event_handlers.go:181] Not support non-csi pvc.
W0714 09:24:15.361434       1 event_handlers.go:181] Not support non-csi pvc.
I0714 09:24:15.363482       1 event_handlers.go:442] Deleted pod <default/yolo-det> from cache.
I0714 09:24:15.376507       1 cache.go:1013] Try to delete Job <default/podgroup-18add706-052d-4d2f-959f-b3250582c197:default/podgroup-18add706-052d-4d2f-959f-b3250582c197>
I0714 09:24:15.377132       1 cache.go:1054] Job <default/podgroup-18add706-052d-4d2f-959f-b3250582c197:default/podgroup-18add706-052d-4d2f-959f-b3250582c197> was deleted.
W0714 09:24:15.574094       1 event_handlers.go:181] Not support non-csi pvc.
I0714 09:24:15.574495       1 event_handlers.go:387] Added pod <default/yolo-det> into cache.
W0714 09:24:15.613474       1 event_handlers.go:181] Not support non-csi pvc.
I0714 09:24:15.793044       1 cache.go:1363] There are <0> Jobs, <1> Queues and <5> Nodes in total for scheduling.
I0714 09:24:15.793156       1 session.go:190] Open Session 99c28a5b-1df6-42e9-8e23-8ba72e233e2e with <0> Job and <1> Queues
I0714 09:24:15.795016       1 enqueue.go:79] Try to enqueue PodGroup to 0 Queues
I0714 09:24:15.795098       1 allocate.go:64] Try to allocate resource to 0 Queues
I0714 09:24:15.795311       1 session.go:244] Close Session 99c28a5b-1df6-42e9-8e23-8ba72e233e2e
I0714 09:24:16.798132       1 cache.go:1363] There are <0> Jobs, <1> Queues and <5> Nodes in total for scheduling.
I0714 09:24:16.798305       1 session.go:190] Open Session 5884b9ad-ed94-4158-94f3-040fba67c5bd with <0> Job and <1> Queues
I0714 09:24:16.800384       1 enqueue.go:79] Try to enqueue PodGroup to 0 Queues
I0714 09:24:16.800468       1 allocate.go:64] Try to allocate resource to 0 Queues
I0714 09:24:16.800688       1 session.go:244] Close Session 5884b9ad-ed94-4158-94f3-040fba67c5bd
I0714 09:24:17.803289       1 cache.go:1363] There are <0> Jobs, <1> Queues and <5> Nodes in total for scheduling.
I0714 09:24:17.803425       1 session.go:190] Open Session e9ff7341-98c8-4af9-93c1-a6d2f0fa5612 with <0> Job and <1> Queues
I0714 09:24:17.805277       1 enqueue.go:79] Try to enqueue PodGroup to 0 Queues
I0714 09:24:17.805361       1 allocate.go:64] Try to allocate resource to 0 Queues
I0714 09:24:17.805577       1 session.go:244] Close Session e9ff7341-98c8-4af9-93c1-a6d2f0fa5612
W0714 09:24:17.814657       1 event_handlers.go:181] Not support non-csi pvc.
I0714 09:24:18.807902       1 cache.go:1363] There are <0> Jobs, <1> Queues and <5> Nodes in total for scheduling.
I0714 09:24:18.808066       1 session.go:190] Open Session 99ba7cf7-f8b8-494a-bde5-90471b9c7c2a with <0> Job and <1> Queues
I0714 09:24:18.809869       1 enqueue.go:79] Try to enqueue PodGroup to 0 Queues
I0714 09:24:18.809950       1 allocate.go:64] Try to allocate resource to 0 Queues
I0714 09:24:18.810151       1 session.go:244] Close Session 99ba7cf7-f8b8-494a-bde5-90471b9c7c2a
I0714 09:24:19.812971       1 cache.go:1363] There are <0> Jobs, <1> Queues and <5> Nodes in total for scheduling.
I0714 09:24:19.813147       1 session.go:190] Open Session ced15aec-4fca-4b6c-96a5-7aa0c51f7a0c with <0> Job and <1> Queues
I0714 09:24:19.815036       1 enqueue.go:79] Try to enqueue PodGroup to 0 Queues
I0714 09:24:19.815118       1 allocate.go:64] Try to allocate resource to 0 Queues
I0714 09:24:19.815352       1 session.go:244] Close Session ced15aec-4fca-4b6c-96a5-7aa0c51f7a0c
I0714 09:24:20.818144       1 cache.go:1363] There are <0> Jobs, <1> Queues and <5> Nodes in total for scheduling.
I0714 09:24:20.818320       1 session.go:190] Open Session 89a14adf-8e5d-432c-b573-a5afca952100 with <0> Job and <1> Queues
I0714 09:24:20.820114       1 enqueue.go:79] Try to enqueue PodGroup to 0 Queues
I0714 09:24:20.820197       1 allocate.go:64] Try to allocate resource to 0 Queues
I0714 09:24:20.820463       1 session.go:244] Close Session 89a14adf-8e5d-432c-b573-a5afca952100
W0714 09:24:21.695372       1 event_handlers.go:181] Not support non-csi pvc.
I0714 09:24:21.695513       1 event_handlers.go:387] Added pod <default/yolo-seg> into cache.
W0714 09:24:21.730576       1 event_handlers.go:181] Not support non-csi pvc.
I0714 09:24:21.823602       1 cache.go:1363] There are <1> Jobs, <1> Queues and <5> Nodes in total for scheduling.
I0714 09:24:21.823774       1 session.go:190] Open Session 31b2c825-497c-49a9-972a-ed1d10afd840 with <1> Job and <1> Queues
I0714 09:24:21.825883       1 enqueue.go:79] Try to enqueue PodGroup to 1 Queues
I0714 09:24:21.826108       1 allocate.go:64] Try to allocate resource to 1 Queues
I0714 09:24:21.826163       1 allocate.go:129] Try to allocate resource to Jobs in Queue <default>
I0714 09:24:21.826198       1 allocate.go:161] Try to allocate resource to 1 tasks of Job <default/podgroup-1200ab16-6841-4a76-87e2-14f4983eaceb>
I0714 09:24:21.826241       1 allocate.go:181] There are <5> nodes for Job <default/podgroup-1200ab16-6841-4a76-87e2-14f4983eaceb>
I0714 09:24:21.826551       1 predicate_helper.go:75] Predicates failed: task default/yolo-seg on node gpu-master fit failed: Insufficient nvidia.com/gpu
I0714 09:24:21.826942       1 predicate_helper.go:75] Predicates failed: task default/yolo-seg on node gpuorin4-desktop fit failed: plugin NodeAffinity predicates failed node(s) didn't match Pod's node affinity/selector
I0714 09:24:21.826997       1 predicate_helper.go:75] Predicates failed: task default/yolo-seg on node gpuorin5-desktop fit failed: plugin NodeAffinity predicates failed node(s) didn't match Pod's node affinity/selector
I0714 09:24:21.827987       1 allocate.go:249] Binding Task <default/yolo-seg> to node <gpu-orin3>
I0714 09:24:21.828222       1 statement.go:266] After allocated Task <default/yolo-seg> to Node <gpu-orin3>: idle <cpu 5900.00, memory 7832723456.00, hugepages-2Mi 0.00, hugepages-32Mi 0.00, hugepages-64Ki 0.00, nvidia.com/gpu 3000.00, pods 104.00, ephemeral-storage 111715275387000.00, hugepages-1Gi 0.00>, used <cpu 100.00, memory 52428800.00, pods 6.00, nvidia.com/gpu 2000.00>, releasing <cpu 0.00, memory 0.00>
I0714 09:24:21.828762       1 statement.go:284] Allocating operations ...
I0714 09:24:21.828898       1 statement.go:378] Committing operations ...
I0714 09:24:21.829028       1 proportion.go:302] Queue <default>: deserved <cpu 0.00, memory 0.00, pods 1.00, nvidia.com/gpu 1000.00>, allocated <cpu 0.00, memory 0.00, nvidia.com/gpu 1000.00, pods 1.00>, share <1>
I0714 09:24:21.829098       1 allocate.go:125] Queue <default> is overused, ignore it.
I0714 09:24:21.840406       1 session.go:244] Close Session 31b2c825-497c-49a9-972a-ed1d10afd840
I0714 09:24:21.845227       1 cache.go:900] bind ok, latency 11.960275ms
W0714 09:24:21.847540       1 event_handlers.go:181] Not support non-csi pvc.
W0714 09:24:21.882671       1 event_handlers.go:181] Not support non-csi pvc.
W0714 09:24:22.370538       1 event_handlers.go:181] Not support non-csi pvc.
I0714 09:24:22.376252       1 event_handlers.go:442] Deleted pod <default/yolo-seg> from cache.
I0714 09:24:22.385837       1 cache.go:1013] Try to delete Job <default/podgroup-1200ab16-6841-4a76-87e2-14f4983eaceb:default/podgroup-1200ab16-6841-4a76-87e2-14f4983eaceb>
I0714 09:24:22.386070       1 cache.go:1054] Job <default/podgroup-1200ab16-6841-4a76-87e2-14f4983eaceb:default/podgroup-1200ab16-6841-4a76-87e2-14f4983eaceb> was deleted.
W0714 09:24:22.516891       1 event_handlers.go:181] Not support non-csi pvc.
I0714 09:24:22.517036       1 event_handlers.go:387] Added pod <default/yolo-seg> into cache.
W0714 09:24:22.573218       1 event_handlers.go:181] Not support non-csi pvc.
I0714 09:24:22.843197       1 cache.go:1363] There are <0> Jobs, <1> Queues and <5> Nodes in total for scheduling.
I0714 09:24:22.843353       1 session.go:190] Open Session 2ac1d229-7078-4103-b262-0c826ebf6651 with <0> Job and <1> Queues
I0714 09:24:22.845301       1 enqueue.go:79] Try to enqueue PodGroup to 0 Queues
I0714 09:24:22.845377       1 allocate.go:64] Try to allocate resource to 0 Queues
I0714 09:24:22.845606       1 session.go:244] Close Session 2ac1d229-7078-4103-b262-0c826ebf6651
I0714 09:24:23.848316       1 cache.go:1363] There are <0> Jobs, <1> Queues and <5> Nodes in total for scheduling.
I0714 09:24:23.848487       1 session.go:190] Open Session f1b7db88-5bb5-4ca4-a4f7-681b6484cd9e with <0> Job and <1> Queues
I0714 09:24:23.850374       1 enqueue.go:79] Try to enqueue PodGroup to 0 Queues
I0714 09:24:23.850450       1 allocate.go:64] Try to allocate resource to 0 Queues
I0714 09:24:23.850682       1 session.go:244] Close Session f1b7db88-5bb5-4ca4-a4f7-681b6484cd9e
I0714 09:24:24.853897       1 cache.go:1363] There are <0> Jobs, <1> Queues and <5> Nodes in total for scheduling.
I0714 09:24:24.854065       1 session.go:190] Open Session 153332c9-0af3-4d75-a5f5-a64054833da6 with <0> Job and <1> Queues
I0714 09:24:24.855874       1 enqueue.go:79] Try to enqueue PodGroup to 0 Queues
I0714 09:24:24.855947       1 allocate.go:64] Try to allocate resource to 0 Queues
I0714 09:24:24.856165       1 session.go:244] Close Session 153332c9-0af3-4d75-a5f5-a64054833da6
W0714 09:24:24.908190       1 event_handlers.go:181] Not support non-csi pvc.
I0714 09:24:25.858118       1 cache.go:1363] There are <0> Jobs, <1> Queues and <5> Nodes in total for scheduling.
I0714 09:24:25.858243       1 session.go:190] Open Session 99b536e2-cfd5-4327-9bb7-d6c03b9aa834 with <0> Job and <1> Queues
I0714 09:24:25.860094       1 enqueue.go:79] Try to enqueue PodGroup to 0 Queues
I0714 09:24:25.860160       1 allocate.go:64] Try to allocate resource to 0 Queues
I0714 09:24:25.860401       1 session.go:244] Close Session 99b536e2-cfd5-4327-9bb7-d6c03b9aa834
I0714 09:24:26.863014       1 cache.go:1363] There are <0> Jobs, <1> Queues and <5> Nodes in total for scheduling.
I0714 09:24:26.863149       1 session.go:190] Open Session d74ed58f-3d36-464c-8025-0fd23982f71b with <0> Job and <1> Queues
I0714 09:24:26.864888       1 enqueue.go:79] Try to enqueue PodGroup to 0 Queues
I0714 09:24:26.864950       1 allocate.go:64] Try to allocate resource to 0 Queues
I0714 09:24:26.865152       1 session.go:244] Close Session d74ed58f-3d36-464c-8025-0fd23982f71b
I0714 09:24:27.867571       1 cache.go:1363] There are <0> Jobs, <1> Queues and <5> Nodes in total for scheduling.
I0714 09:24:27.867689       1 session.go:190] Open Session f77100ad-4f9a-40ce-a434-617d5d00d70f with <0> Job and <1> Queues
I0714 09:24:27.869294       1 enqueue.go:79] Try to enqueue PodGroup to 0 Queues
I0714 09:24:27.869358       1 allocate.go:64] Try to allocate resource to 0 Queues
I0714 09:24:27.869547       1 session.go:244] Close Session f77100ad-4f9a-40ce-a434-617d5d00d70f
W0714 09:24:28.670958       1 event_handlers.go:181] Not support non-csi pvc.
I0714 09:24:28.671071       1 event_handlers.go:387] Added pod <default/yolo-obb> into cache.
W0714 09:24:28.701355       1 event_handlers.go:181] Not support non-csi pvc.
I0714 09:24:28.872016       1 cache.go:1363] There are <1> Jobs, <1> Queues and <5> Nodes in total for scheduling.
I0714 09:24:28.872141       1 session.go:190] Open Session 9d8d1298-ebcc-4739-9f96-9d343be199c2 with <1> Job and <1> Queues
I0714 09:24:28.874300       1 enqueue.go:79] Try to enqueue PodGroup to 1 Queues
I0714 09:24:28.874511       1 allocate.go:64] Try to allocate resource to 1 Queues
I0714 09:24:28.874565       1 allocate.go:129] Try to allocate resource to Jobs in Queue <default>
I0714 09:24:28.874602       1 allocate.go:161] Try to allocate resource to 1 tasks of Job <default/podgroup-bcb9014e-48bd-4e4e-8e80-57ad4a2c823b>
I0714 09:24:28.874642       1 allocate.go:181] There are <5> nodes for Job <default/podgroup-bcb9014e-48bd-4e4e-8e80-57ad4a2c823b>
I0714 09:24:28.874936       1 predicate_helper.go:75] Predicates failed: task default/yolo-obb on node gpu-master fit failed: Insufficient nvidia.com/gpu
I0714 09:24:28.875377       1 predicate_helper.go:75] Predicates failed: task default/yolo-obb on node gpuorin4-desktop fit failed: plugin NodeAffinity predicates failed node(s) didn't match Pod's node affinity/selector
I0714 09:24:28.875416       1 predicate_helper.go:75] Predicates failed: task default/yolo-obb on node gpuorin5-desktop fit failed: plugin NodeAffinity predicates failed node(s) didn't match Pod's node affinity/selector
I0714 09:24:28.876180       1 allocate.go:249] Binding Task <default/yolo-obb> to node <gpu-orin2>
I0714 09:24:28.876424       1 statement.go:266] After allocated Task <default/yolo-obb> to Node <gpu-orin2>: idle <cpu 5900.00, memory 7832690688.00, hugepages-2Mi 0.00, hugepages-64Ki 0.00, nvidia.com/gpu 3000.00, pods 104.00, ephemeral-storage 225118140453000.00, hugepages-1Gi 0.00, hugepages-32Mi 0.00>, used <cpu 100.00, memory 52428800.00, pods 6.00, nvidia.com/gpu 2000.00>, releasing <cpu 0.00, memory 0.00>
I0714 09:24:28.876826       1 statement.go:284] Allocating operations ...
I0714 09:24:28.876946       1 statement.go:378] Committing operations ...
I0714 09:24:28.877048       1 proportion.go:302] Queue <default>: deserved <cpu 0.00, memory 0.00, pods 1.00, nvidia.com/gpu 1000.00>, allocated <cpu 0.00, memory 0.00, nvidia.com/gpu 1000.00, pods 1.00>, share <1>
I0714 09:24:28.877104       1 allocate.go:125] Queue <default> is overused, ignore it.
I0714 09:24:28.895667       1 session.go:244] Close Session 9d8d1298-ebcc-4739-9f96-9d343be199c2
I0714 09:24:28.896384       1 cache.go:900] bind ok, latency 16.96327ms
W0714 09:24:28.898266       1 event_handlers.go:181] Not support non-csi pvc.
W0714 09:24:28.942552       1 event_handlers.go:181] Not support non-csi pvc.
W0714 09:24:29.328338       1 event_handlers.go:181] Not support non-csi pvc.
I0714 09:24:29.332894       1 event_handlers.go:442] Deleted pod <default/yolo-obb> from cache.
I0714 09:24:29.339488       1 cache.go:1013] Try to delete Job <default/podgroup-bcb9014e-48bd-4e4e-8e80-57ad4a2c823b:default/podgroup-bcb9014e-48bd-4e4e-8e80-57ad4a2c823b>
I0714 09:24:29.339701       1 cache.go:1054] Job <default/podgroup-bcb9014e-48bd-4e4e-8e80-57ad4a2c823b:default/podgroup-bcb9014e-48bd-4e4e-8e80-57ad4a2c823b> was deleted.
W0714 09:24:29.467654       1 event_handlers.go:181] Not support non-csi pvc.
I0714 09:24:29.467831       1 event_handlers.go:387] Added pod <default/yolo-obb> into cache.
W0714 09:24:29.498883       1 event_handlers.go:181] Not support non-csi pvc.
I0714 09:24:29.897962       1 cache.go:1363] There are <0> Jobs, <1> Queues and <5> Nodes in total for scheduling.
I0714 09:24:29.898133       1 session.go:190] Open Session 1a97245d-acdc-4ac5-96a6-b559c0f12b32 with <0> Job and <1> Queues
I0714 09:24:29.900021       1 enqueue.go:79] Try to enqueue PodGroup to 0 Queues
I0714 09:24:29.900100       1 allocate.go:64] Try to allocate resource to 0 Queues
I0714 09:24:29.900354       1 session.go:244] Close Session 1a97245d-acdc-4ac5-96a6-b559c0f12b32
I0714 09:24:30.902795       1 cache.go:1363] There are <0> Jobs, <1> Queues and <5> Nodes in total for scheduling.
I0714 09:24:30.902916       1 session.go:190] Open Session 02f2d446-0ef3-4ad5-9e4d-014c60d83245 with <0> Job and <1> Queues
I0714 09:24:30.904551       1 enqueue.go:79] Try to enqueue PodGroup to 0 Queues
I0714 09:24:30.904622       1 allocate.go:64] Try to allocate resource to 0 Queues
I0714 09:24:30.904811       1 session.go:244] Close Session 02f2d446-0ef3-4ad5-9e4d-014c60d83245
I0714 09:24:31.906889       1 cache.go:1363] There are <0> Jobs, <1> Queues and <5> Nodes in total for scheduling.
I0714 09:24:31.907018       1 session.go:190] Open Session 39d028b1-6617-43c2-9fc3-1c075d144055 with <0> Job and <1> Queues
I0714 09:24:31.908714       1 enqueue.go:79] Try to enqueue PodGroup to 0 Queues
I0714 09:24:31.908777       1 allocate.go:64] Try to allocate resource to 0 Queues
I0714 09:24:31.908961       1 session.go:244] Close Session 39d028b1-6617-43c2-9fc3-1c075d144055
W0714 09:24:32.298566       1 event_handlers.go:181] Not support non-csi pvc.
I0714 09:24:32.911751       1 cache.go:1363] There are <0> Jobs, <1> Queues and <5> Nodes in total for scheduling.
I0714 09:24:32.911915       1 session.go:190] Open Session 02deb1d8-2212-46c0-843d-ed4bf2c9d4ca with <0> Job and <1> Queues
I0714 09:24:32.914093       1 enqueue.go:79] Try to enqueue PodGroup to 0 Queues
I0714 09:24:32.914176       1 allocate.go:64] Try to allocate resource to 0 Queues
I0714 09:24:32.914410       1 session.go:244] Close Session 02deb1d8-2212-46c0-843d-ed4bf2c9d4ca
I0714 09:24:33.916881       1 cache.go:1363] There are <0> Jobs, <1> Queues and <5> Nodes in total for scheduling.
I0714 09:24:33.917055       1 session.go:190] Open Session 8225998e-03c7-4d18-b091-34f6c20df819 with <0> Job and <1> Queues
I0714 09:24:33.918970       1 enqueue.go:79] Try to enqueue PodGroup to 0 Queues
I0714 09:24:33.919044       1 allocate.go:64] Try to allocate resource to 0 Queues
I0714 09:24:33.919269       1 session.go:244] Close Session 8225998e-03c7-4d18-b091-34f6c20df819
I0714 09:24:34.921806       1 cache.go:1363] There are <0> Jobs, <1> Queues and <5> Nodes in total for scheduling.
I0714 09:24:34.921999       1 session.go:190] Open Session 432d36a8-7332-430a-8b9d-ea9bbfc350a1 with <0> Job and <1> Queues
I0714 09:24:34.924078       1 enqueue.go:79] Try to enqueue PodGroup to 0 Queues
I0714 09:24:34.924146       1 allocate.go:64] Try to allocate resource to 0 Queues
I0714 09:24:34.924410       1 session.go:244] Close Session 432d36a8-7332-430a-8b9d-ea9bbfc350a1
I0714 09:24:35.927529       1 cache.go:1363] There are <0> Jobs, <1> Queues and <5> Nodes in total for scheduling.
I0714 09:24:35.927719       1 session.go:190] Open Session 291b1ea2-eefc-4ee4-9f16-fc42aa9af8c7 with <0> Job and <1> Queues
I0714 09:24:35.929792       1 enqueue.go:79] Try to enqueue PodGroup to 0 Queues
I0714 09:24:35.929874       1 allocate.go:64] Try to allocate resource to 0 Queues
I0714 09:24:35.930389       1 session.go:244] Close Session 291b1ea2-eefc-4ee4-9f16-fc42aa9af8c7
W0714 09:24:36.223649       1 event_handlers.go:181] Not support non-csi pvc.
I0714 09:24:36.223785       1 event_handlers.go:387] Added pod <default/yolo-pos> into cache.
W0714 09:24:36.249673       1 event_handlers.go:181] Not support non-csi pvc.
I0714 09:24:36.663576       1 cache.go:1489] The metrics type is not set in the volcano scheduler configmap file. As a result, the CPU and memory load information of the node is not collected.
I0714 09:24:36.933283       1 cache.go:1363] There are <1> Jobs, <1> Queues and <5> Nodes in total for scheduling.
I0714 09:24:36.933438       1 session.go:190] Open Session 67b464fe-28a6-4385-b63f-37902eb33345 with <1> Job and <1> Queues
I0714 09:24:36.935586       1 enqueue.go:79] Try to enqueue PodGroup to 1 Queues
I0714 09:24:36.935811       1 allocate.go:64] Try to allocate resource to 1 Queues
I0714 09:24:36.935866       1 allocate.go:129] Try to allocate resource to Jobs in Queue <default>
I0714 09:24:36.935902       1 allocate.go:161] Try to allocate resource to 1 tasks of Job <default/podgroup-44897649-41ac-472c-a685-5742048da3c1>
I0714 09:24:36.935943       1 allocate.go:181] There are <5> nodes for Job <default/podgroup-44897649-41ac-472c-a685-5742048da3c1>
I0714 09:24:36.936259       1 predicate_helper.go:75] Predicates failed: task default/yolo-pos on node gpu-master fit failed: Insufficient nvidia.com/gpu
I0714 09:24:36.936676       1 predicate_helper.go:75] Predicates failed: task default/yolo-pos on node gpuorin4-desktop fit failed: plugin NodeAffinity predicates failed node(s) didn't match Pod's node affinity/selector
I0714 09:24:36.936726       1 predicate_helper.go:75] Predicates failed: task default/yolo-pos on node gpuorin5-desktop fit failed: plugin NodeAffinity predicates failed node(s) didn't match Pod's node affinity/selector
I0714 09:24:36.937559       1 allocate.go:249] Binding Task <default/yolo-pos> to node <gpu-orin3>
I0714 09:24:36.937792       1 statement.go:266] After allocated Task <default/yolo-pos> to Node <gpu-orin3>: idle <cpu 5900.00, memory 7832723456.00, pods 103.00, ephemeral-storage 111715275387000.00, hugepages-1Gi 0.00, hugepages-2Mi 0.00, hugepages-32Mi 0.00, hugepages-64Ki 0.00, nvidia.com/gpu 2000.00>, used <cpu 100.00, memory 52428800.00, pods 7.00, nvidia.com/gpu 3000.00>, releasing <cpu 0.00, memory 0.00>
I0714 09:24:36.938338       1 statement.go:284] Allocating operations ...
I0714 09:24:36.938463       1 statement.go:378] Committing operations ...
I0714 09:24:36.938577       1 proportion.go:302] Queue <default>: deserved <cpu 0.00, memory 0.00, pods 1.00, nvidia.com/gpu 1000.00>, allocated <cpu 0.00, memory 0.00, nvidia.com/gpu 1000.00, pods 1.00>, share <1>
I0714 09:24:36.938634       1 allocate.go:125] Queue <default> is overused, ignore it.
I0714 09:24:36.959005       1 session.go:244] Close Session 67b464fe-28a6-4385-b63f-37902eb33345
I0714 09:24:36.967651       1 cache.go:900] bind ok, latency 14.61128ms
W0714 09:24:36.970081       1 event_handlers.go:181] Not support non-csi pvc.
W0714 09:24:37.007015       1 event_handlers.go:181] Not support non-csi pvc.
W0714 09:24:37.409008       1 event_handlers.go:181] Not support non-csi pvc.
I0714 09:24:37.412367       1 event_handlers.go:442] Deleted pod <default/yolo-pos> from cache.
I0714 09:24:37.416527       1 cache.go:1013] Try to delete Job <default/podgroup-44897649-41ac-472c-a685-5742048da3c1:default/podgroup-44897649-41ac-472c-a685-5742048da3c1>
I0714 09:24:37.416743       1 cache.go:1054] Job <default/podgroup-44897649-41ac-472c-a685-5742048da3c1:default/podgroup-44897649-41ac-472c-a685-5742048da3c1> was deleted.
W0714 09:24:37.549907       1 event_handlers.go:181] Not support non-csi pvc.
I0714 09:24:37.550003       1 event_handlers.go:387] Added pod <default/yolo-pos> into cache.
W0714 09:24:37.581953       1 event_handlers.go:181] Not support non-csi pvc.
I0714 09:24:37.961856       1 cache.go:1363] There are <0> Jobs, <1> Queues and <5> Nodes in total for scheduling.
I0714 09:24:37.961977       1 session.go:190] Open Session 60112f44-6e5e-4272-9b19-6395bfa9adff with <0> Job and <1> Queues
I0714 09:24:37.963891       1 enqueue.go:79] Try to enqueue PodGroup to 0 Queues
I0714 09:24:37.963962       1 allocate.go:64] Try to allocate resource to 0 Queues
I0714 09:24:37.964174       1 session.go:244] Close Session 60112f44-6e5e-4272-9b19-6395bfa9adff
I0714 09:24:38.967032       1 cache.go:1363] There are <0> Jobs, <1> Queues and <5> Nodes in total for scheduling.
I0714 09:24:38.967203       1 session.go:190] Open Session de0f4810-d208-4af9-8bbc-e659820d5fd2 with <0> Job and <1> Queues
I0714 09:24:38.969426       1 enqueue.go:79] Try to enqueue PodGroup to 0 Queues
I0714 09:24:38.969504       1 allocate.go:64] Try to allocate resource to 0 Queues
I0714 09:24:38.969730       1 session.go:244] Close Session de0f4810-d208-4af9-8bbc-e659820d5fd2
I0714 09:24:39.972845       1 cache.go:1363] There are <0> Jobs, <1> Queues and <5> Nodes in total for scheduling.
I0714 09:24:39.973010       1 session.go:190] Open Session 01ded6ee-e532-4cf8-83a4-a6b17ab3e7ea with <0> Job and <1> Queues
I0714 09:24:39.974962       1 enqueue.go:79] Try to enqueue PodGroup to 0 Queues
I0714 09:24:39.975036       1 allocate.go:64] Try to allocate resource to 0 Queues
I0714 09:24:39.975238       1 session.go:244] Close Session 01ded6ee-e532-4cf8-83a4-a6b17ab3e7ea
I0714 09:24:40.978106       1 cache.go:1363] There are <0> Jobs, <1> Queues and <5> Nodes in total for scheduling.
I0714 09:24:40.978285       1 session.go:190] Open Session 4c9fcd69-ec42-4060-9c02-e006258d13da with <0> Job and <1> Queues
I0714 09:24:40.980345       1 enqueue.go:79] Try to enqueue PodGroup to 0 Queues
I0714 09:24:40.980421       1 allocate.go:64] Try to allocate resource to 0 Queues
I0714 09:24:40.980655       1 session.go:244] Close Session 4c9fcd69-ec42-4060-9c02-e006258d13da
I0714 09:24:41.983081       1 cache.go:1363] There are <0> Jobs, <1> Queues and <5> Nodes in total for scheduling.
I0714 09:24:41.983224       1 session.go:190] Open Session 984022bd-0ad5-48f9-a756-4bb6dadececb with <0> Job and <1> Queues
I0714 09:24:41.985175       1 enqueue.go:79] Try to enqueue PodGroup to 0 Queues
I0714 09:24:41.985248       1 allocate.go:64] Try to allocate resource to 0 Queues
I0714 09:24:41.985480       1 session.go:244] Close Session 984022bd-0ad5-48f9-a756-4bb6dadececb
I0714 09:24:42.987909       1 cache.go:1363] There are <0> Jobs, <1> Queues and <5> Nodes in total for scheduling.
I0714 09:24:42.988092       1 session.go:190] Open Session 94c2c777-40c7-495d-aada-69d3a3a08635 with <0> Job and <1> Queues
I0714 09:24:42.990363       1 enqueue.go:79] Try to enqueue PodGroup to 0 Queues
I0714 09:24:42.990446       1 allocate.go:64] Try to allocate resource to 0 Queues
I0714 09:24:42.990664       1 session.go:244] Close Session 94c2c777-40c7-495d-aada-69d3a3a08635
I0714 09:24:43.993102       1 cache.go:1363] There are <0> Jobs, <1> Queues and <5> Nodes in total for scheduling.
I0714 09:24:43.993264       1 session.go:190] Open Session 7c201109-863d-4c23-bb21-5cb108883305 with <0> Job and <1> Queues
I0714 09:24:43.995156       1 enqueue.go:79] Try to enqueue PodGroup to 0 Queues
I0714 09:24:43.995236       1 allocate.go:64] Try to allocate resource to 0 Queues
I0714 09:24:43.995445       1 session.go:244] Close Session 7c201109-863d-4c23-bb21-5cb108883305
I0714 09:24:44.998128       1 cache.go:1363] There are <0> Jobs, <1> Queues and <5> Nodes in total for scheduling.
I0714 09:24:44.998321       1 session.go:190] Open Session beb933dc-3b2f-41be-b95b-61be19105c52 with <0> Job and <1> Queues
I0714 09:24:45.000228       1 enqueue.go:79] Try to enqueue PodGroup to 0 Queues
I0714 09:24:45.000378       1 allocate.go:64] Try to allocate resource to 0 Queues
I0714 09:24:45.000641       1 session.go:244] Close Session beb933dc-3b2f-41be-b95b-61be19105c52
I0714 09:24:46.002856       1 cache.go:1363] There are <0> Jobs, <1> Queues and <5> Nodes in total for scheduling.
I0714 09:24:46.003022       1 session.go:190] Open Session 6a43fe53-08d3-4fb3-9848-22d7b0ca93b5 with <0> Job and <1> Queues
I0714 09:24:46.006479       1 enqueue.go:79] Try to enqueue PodGroup to 0 Queues
I0714 09:24:46.006589       1 allocate.go:64] Try to allocate resource to 0 Queues
I0714 09:24:46.006862       1 session.go:244] Close Session 6a43fe53-08d3-4fb3-9848-22d7b0ca93b5
I0714 09:24:47.009962       1 cache.go:1363] There are <0> Jobs, <1> Queues and <5> Nodes in total for scheduling.
I0714 09:24:47.010144       1 session.go:190] Open Session db20dad6-4598-4d27-a9eb-54d089cf2a8a with <0> Job and <1> Queues
I0714 09:24:47.012055       1 enqueue.go:79] Try to enqueue PodGroup to 0 Queues
I0714 09:24:47.012133       1 allocate.go:64] Try to allocate resource to 0 Queues
I0714 09:24:47.012374       1 session.go:244] Close Session db20dad6-4598-4d27-a9eb-54d089cf2a8a
I0714 09:24:48.014694       1 cache.go:1363] There are <0> Jobs, <1> Queues and <5> Nodes in total for scheduling.
I0714 09:24:48.014856       1 session.go:190] Open Session dcef2ac1-9b8a-4e25-929f-790f4c347cdd with <0> Job and <1> Queues
I0714 09:24:48.016728       1 enqueue.go:79] Try to enqueue PodGroup to 0 Queues
I0714 09:24:48.016792       1 allocate.go:64] Try to allocate resource to 0 Queues
I0714 09:24:48.017022       1 session.go:244] Close Session dcef2ac1-9b8a-4e25-929f-790f4c347cdd
I0714 09:24:49.019775       1 cache.go:1363] There are <0> Jobs, <1> Queues and <5> Nodes in total for scheduling.
I0714 09:24:49.019965       1 session.go:190] Open Session 1e3addeb-8ea6-43aa-b6b2-e1c0a88b0cf1 with <0> Job and <1> Queues
I0714 09:24:49.021987       1 enqueue.go:79] Try to enqueue PodGroup to 0 Queues
I0714 09:24:49.022065       1 allocate.go:64] Try to allocate resource to 0 Queues
I0714 09:24:49.022294       1 session.go:244] Close Session 1e3addeb-8ea6-43aa-b6b2-e1c0a88b0cf1
I0714 09:24:50.024580       1 cache.go:1363] There are <0> Jobs, <1> Queues and <5> Nodes in total for scheduling.
I0714 09:24:50.024761       1 session.go:190] Open Session 41cf24c4-5d1e-4f7d-88c3-c174a593d1c2 with <0> Job and <1> Queues
I0714 09:24:50.026739       1 enqueue.go:79] Try to enqueue PodGroup to 0 Queues
I0714 09:24:50.026820       1 allocate.go:64] Try to allocate resource to 0 Queues
I0714 09:24:50.027044       1 session.go:244] Close Session 41cf24c4-5d1e-4f7d-88c3-c174a593d1c2
I0714 09:24:51.029491       1 cache.go:1363] There are <0> Jobs, <1> Queues and <5> Nodes in total for scheduling.
I0714 09:24:51.029669       1 session.go:190] Open Session 3b02ffd8-6f4c-4b6f-85fe-c8bea02488cb with <0> Job and <1> Queues
I0714 09:24:51.031539       1 enqueue.go:79] Try to enqueue PodGroup to 0 Queues
I0714 09:24:51.031612       1 allocate.go:64] Try to allocate resource to 0 Queues
I0714 09:24:51.031844       1 session.go:244] Close Session 3b02ffd8-6f4c-4b6f-85fe-c8bea02488cb
I0714 09:24:52.034306       1 cache.go:1363] There are <0> Jobs, <1> Queues and <5> Nodes in total for scheduling.
I0714 09:24:52.034485       1 session.go:190] Open Session 1f5ad212-afc9-4048-ab17-73056bf66630 with <0> Job and <1> Queues
I0714 09:24:52.036687       1 enqueue.go:79] Try to enqueue PodGroup to 0 Queues
I0714 09:24:52.036763       1 allocate.go:64] Try to allocate resource to 0 Queues
I0714 09:24:52.036969       1 session.go:244] Close Session 1f5ad212-afc9-4048-ab17-73056bf66630
I0714 09:24:53.040122       1 cache.go:1363] There are <0> Jobs, <1> Queues and <5> Nodes in total for scheduling.
I0714 09:24:53.040336       1 session.go:190] Open Session f1d07823-9fa7-4a31-a3f6-44c191c8fb3f with <0> Job and <1> Queues
I0714 09:24:53.042207       1 enqueue.go:79] Try to enqueue PodGroup to 0 Queues
I0714 09:24:53.042282       1 allocate.go:64] Try to allocate resource to 0 Queues
I0714 09:24:53.042487       1 session.go:244] Close Session f1d07823-9fa7-4a31-a3f6-44c191c8fb3f
I0714 09:24:54.045416       1 cache.go:1363] There are <0> Jobs, <1> Queues and <5> Nodes in total for scheduling.
I0714 09:24:54.045591       1 session.go:190] Open Session d8fa494a-6968-4c67-be0f-0fead0d45cdc with <0> Job and <1> Queues
I0714 09:24:54.047527       1 enqueue.go:79] Try to enqueue PodGroup to 0 Queues
I0714 09:24:54.047609       1 allocate.go:64] Try to allocate resource to 0 Queues
I0714 09:24:54.047828       1 session.go:244] Close Session d8fa494a-6968-4c67-be0f-0fead0d45cdc
W0714 09:24:54.116736       1 event_handlers.go:181] Not support non-csi pvc.
I0714 09:24:55.049198       1 cache.go:1363] There are <0> Jobs, <1> Queues and <5> Nodes in total for scheduling.
I0714 09:24:55.049292       1 session.go:190] Open Session 07db6c2c-780d-4a17-a60f-007ffb0258ab with <0> Job and <1> Queues
I0714 09:24:55.050439       1 enqueue.go:79] Try to enqueue PodGroup to 0 Queues
I0714 09:24:55.050490       1 allocate.go:64] Try to allocate resource to 0 Queues
I0714 09:24:55.050609       1 session.go:244] Close Session 07db6c2c-780d-4a17-a60f-007ffb0258ab
I0714 09:24:56.053077       1 cache.go:1363] There are <0> Jobs, <1> Queues and <5> Nodes in total for scheduling.
I0714 09:24:56.053295       1 session.go:190] Open Session fb31fb6c-f979-4202-bbc1-1c359e1110f9 with <0> Job and <1> Queues
I0714 09:24:56.055205       1 enqueue.go:79] Try to enqueue PodGroup to 0 Queues
I0714 09:24:56.055275       1 allocate.go:64] Try to allocate resource to 0 Queues
I0714 09:24:56.055491       1 session.go:244] Close Session fb31fb6c-f979-4202-bbc1-1c359e1110f9
I0714 09:24:57.058568       1 cache.go:1363] There are <0> Jobs, <1> Queues and <5> Nodes in total for scheduling.
I0714 09:24:57.058726       1 session.go:190] Open Session d5414456-8f07-458a-8272-0772898c6fbc with <0> Job and <1> Queues
I0714 09:24:57.060639       1 enqueue.go:79] Try to enqueue PodGroup to 0 Queues
I0714 09:24:57.060718       1 allocate.go:64] Try to allocate resource to 0 Queues
I0714 09:24:57.060925       1 session.go:244] Close Session d5414456-8f07-458a-8272-0772898c6fbc
I0714 09:24:58.063904       1 cache.go:1363] There are <0> Jobs, <1> Queues and <5> Nodes in total for scheduling.
I0714 09:24:58.064031       1 session.go:190] Open Session 1f4e09bc-0be0-42ab-ba1c-64e9786c203e with <0> Job and <1> Queues
I0714 09:24:58.065971       1 enqueue.go:79] Try to enqueue PodGroup to 0 Queues
I0714 09:24:58.066054       1 allocate.go:64] Try to allocate resource to 0 Queues
I0714 09:24:58.066276       1 session.go:244] Close Session 1f4e09bc-0be0-42ab-ba1c-64e9786c203e
I0714 09:24:59.068997       1 cache.go:1363] There are <0> Jobs, <1> Queues and <5> Nodes in total for scheduling.
I0714 09:24:59.069213       1 session.go:190] Open Session 15d1d874-02e5-4f09-b5de-dbec02491752 with <0> Job and <1> Queues
I0714 09:24:59.071117       1 enqueue.go:79] Try to enqueue PodGroup to 0 Queues
I0714 09:24:59.071219       1 allocate.go:64] Try to allocate resource to 0 Queues
I0714 09:24:59.071436       1 session.go:244] Close Session 15d1d874-02e5-4f09-b5de-dbec02491752
I0714 09:25:00.074235       1 cache.go:1363] There are <0> Jobs, <1> Queues and <5> Nodes in total for scheduling.
I0714 09:25:00.074415       1 session.go:190] Open Session 4f6a7621-c966-4732-860b-f4b46c5993a1 with <0> Job and <1> Queues
I0714 09:25:00.076162       1 enqueue.go:79] Try to enqueue PodGroup to 0 Queues
I0714 09:25:00.076258       1 allocate.go:64] Try to allocate resource to 0 Queues
I0714 09:25:00.076543       1 session.go:244] Close Session 4f6a7621-c966-4732-860b-f4b46c5993a1
I0714 09:25:01.078977       1 cache.go:1363] There are <0> Jobs, <1> Queues and <5> Nodes in total for scheduling.
I0714 09:25:01.079151       1 session.go:190] Open Session 493bf56a-0fa1-4762-aa71-30f44231f3c7 with <0> Job and <1> Queues
I0714 09:25:01.081114       1 enqueue.go:79] Try to enqueue PodGroup to 0 Queues
I0714 09:25:01.081189       1 allocate.go:64] Try to allocate resource to 0 Queues
I0714 09:25:01.081426       1 session.go:244] Close Session 493bf56a-0fa1-4762-aa71-30f44231f3c7
I0714 09:25:02.084366       1 cache.go:1363] There are <0> Jobs, <1> Queues and <5> Nodes in total for scheduling.
I0714 09:25:02.084536       1 session.go:190] Open Session fe650af6-11a7-4f95-a66e-e9da058b4ff7 with <0> Job and <1> Queues
I0714 09:25:02.086448       1 enqueue.go:79] Try to enqueue PodGroup to 0 Queues
I0714 09:25:02.086534       1 allocate.go:64] Try to allocate resource to 0 Queues
I0714 09:25:02.086752       1 session.go:244] Close Session fe650af6-11a7-4f95-a66e-e9da058b4ff7
I0714 09:25:03.089672       1 cache.go:1363] There are <0> Jobs, <1> Queues and <5> Nodes in total for scheduling.
I0714 09:25:03.089853       1 session.go:190] Open Session d4e594aa-b3a8-4b6e-b914-109730173dc0 with <0> Job and <1> Queues
I0714 09:25:03.091721       1 enqueue.go:79] Try to enqueue PodGroup to 0 Queues
I0714 09:25:03.091807       1 allocate.go:64] Try to allocate resource to 0 Queues
I0714 09:25:03.092022       1 session.go:244] Close Session d4e594aa-b3a8-4b6e-b914-109730173dc0
I0714 09:25:04.094668       1 cache.go:1363] There are <0> Jobs, <1> Queues and <5> Nodes in total for scheduling.
I0714 09:25:04.094845       1 session.go:190] Open Session 120d7c45-f202-4c7d-b353-b186c8e5d5e7 with <0> Job and <1> Queues
I0714 09:25:04.097143       1 enqueue.go:79] Try to enqueue PodGroup to 0 Queues
I0714 09:25:04.097238       1 allocate.go:64] Try to allocate resource to 0 Queues
I0714 09:25:04.097501       1 session.go:244] Close Session 120d7c45-f202-4c7d-b353-b186c8e5d5e7
I0714 09:25:05.098782       1 cache.go:1363] There are <0> Jobs, <1> Queues and <5> Nodes in total for scheduling.
I0714 09:25:05.098861       1 session.go:190] Open Session 645e9fe7-a2f8-4417-9c61-87635d380949 with <0> Job and <1> Queues
I0714 09:25:05.099806       1 enqueue.go:79] Try to enqueue PodGroup to 0 Queues
I0714 09:25:05.099856       1 allocate.go:64] Try to allocate resource to 0 Queues
I0714 09:25:05.099973       1 session.go:244] Close Session 645e9fe7-a2f8-4417-9c61-87635d380949
I0714 09:25:06.103161       1 cache.go:1363] There are <0> Jobs, <1> Queues and <5> Nodes in total for scheduling.
I0714 09:25:06.103327       1 session.go:190] Open Session 43d55bb5-a8d5-433b-b7be-9159abb5179f with <0> Job and <1> Queues
I0714 09:25:06.105319       1 enqueue.go:79] Try to enqueue PodGroup to 0 Queues
I0714 09:25:06.105393       1 allocate.go:64] Try to allocate resource to 0 Queues
I0714 09:25:06.105625       1 session.go:244] Close Session 43d55bb5-a8d5-433b-b7be-9159abb5179f
I0714 09:25:06.664065       1 cache.go:1489] The metrics type is not set in the volcano scheduler configmap file. As a result, the CPU and memory load information of the node is not collected.
I0714 09:25:07.108487       1 cache.go:1363] There are <0> Jobs, <1> Queues and <5> Nodes in total for scheduling.
I0714 09:25:07.108683       1 session.go:190] Open Session 6e67de88-d915-4fe0-9bbe-c72afa787bb1 with <0> Job and <1> Queues
I0714 09:25:07.110563       1 enqueue.go:79] Try to enqueue PodGroup to 0 Queues
I0714 09:25:07.110629       1 allocate.go:64] Try to allocate resource to 0 Queues
I0714 09:25:07.110851       1 session.go:244] Close Session 6e67de88-d915-4fe0-9bbe-c72afa787bb1
I0714 09:25:08.113629       1 cache.go:1363] There are <0> Jobs, <1> Queues and <5> Nodes in total for scheduling.
I0714 09:25:08.113791       1 session.go:190] Open Session b3b5cf4b-c52b-46df-8b98-42dcbd997a97 with <0> Job and <1> Queues
I0714 09:25:08.116075       1 enqueue.go:79] Try to enqueue PodGroup to 0 Queues
I0714 09:25:08.116163       1 allocate.go:64] Try to allocate resource to 0 Queues
I0714 09:25:08.116427       1 session.go:244] Close Session b3b5cf4b-c52b-46df-8b98-42dcbd997a97
I0714 09:25:09.119669       1 cache.go:1363] There are <0> Jobs, <1> Queues and <5> Nodes in total for scheduling.
I0714 09:25:09.119845       1 session.go:190] Open Session 0bc6b2f8-ae05-4b59-b957-d43c53a70ab9 with <0> Job and <1> Queues
I0714 09:25:09.122093       1 enqueue.go:79] Try to enqueue PodGroup to 0 Queues
I0714 09:25:09.122172       1 allocate.go:64] Try to allocate resource to 0 Queues
I0714 09:25:09.122421       1 session.go:244] Close Session 0bc6b2f8-ae05-4b59-b957-d43c53a70ab9
I0714 09:25:10.125471       1 cache.go:1363] There are <0> Jobs, <1> Queues and <5> Nodes in total for scheduling.
I0714 09:25:10.125645       1 session.go:190] Open Session 731dd497-9569-4fce-8cee-bfeed849838a with <0> Job and <1> Queues
I0714 09:25:10.127591       1 enqueue.go:79] Try to enqueue PodGroup to 0 Queues
I0714 09:25:10.127667       1 allocate.go:64] Try to allocate resource to 0 Queues
I0714 09:25:10.127878       1 session.go:244] Close Session 731dd497-9569-4fce-8cee-bfeed849838a
I0714 09:25:11.130339       1 cache.go:1363] There are <0> Jobs, <1> Queues and <5> Nodes in total for scheduling.
I0714 09:25:11.130515       1 session.go:190] Open Session 39e35ae0-1c0f-4dbe-941a-96239238acee with <0> Job and <1> Queues
I0714 09:25:11.132441       1 enqueue.go:79] Try to enqueue PodGroup to 0 Queues
I0714 09:25:11.132518       1 allocate.go:64] Try to allocate resource to 0 Queues
I0714 09:25:11.132749       1 session.go:244] Close Session 39e35ae0-1c0f-4dbe-941a-96239238acee
I0714 09:25:12.135050       1 cache.go:1363] There are <0> Jobs, <1> Queues and <5> Nodes in total for scheduling.
I0714 09:25:12.135191       1 session.go:190] Open Session 9dd520af-ec0a-4bd9-982b-4167fff72091 with <0> Job and <1> Queues
I0714 09:25:12.137040       1 enqueue.go:79] Try to enqueue PodGroup to 0 Queues
I0714 09:25:12.137108       1 allocate.go:64] Try to allocate resource to 0 Queues
I0714 09:25:12.137321       1 session.go:244] Close Session 9dd520af-ec0a-4bd9-982b-4167fff72091
I0714 09:25:13.139980       1 cache.go:1363] There are <0> Jobs, <1> Queues and <5> Nodes in total for scheduling.
I0714 09:25:13.140149       1 session.go:190] Open Session ce7c58f2-bb3e-4806-afa3-d4d1eff6bb20 with <0> Job and <1> Queues
I0714 09:25:13.142020       1 enqueue.go:79] Try to enqueue PodGroup to 0 Queues
I0714 09:25:13.142111       1 allocate.go:64] Try to allocate resource to 0 Queues
I0714 09:25:13.142320       1 session.go:244] Close Session ce7c58f2-bb3e-4806-afa3-d4d1eff6bb20
I0714 09:25:14.145567       1 cache.go:1363] There are <0> Jobs, <1> Queues and <5> Nodes in total for scheduling.
I0714 09:25:14.145749       1 session.go:190] Open Session a95679fe-ecb6-47fc-bdef-05f9f4bd8318 with <0> Job and <1> Queues
I0714 09:25:14.147773       1 enqueue.go:79] Try to enqueue PodGroup to 0 Queues
I0714 09:25:14.147853       1 allocate.go:64] Try to allocate resource to 0 Queues
I0714 09:25:14.148101       1 session.go:244] Close Session a95679fe-ecb6-47fc-bdef-05f9f4bd8318
I0714 09:25:15.151306       1 cache.go:1363] There are <0> Jobs, <1> Queues and <5> Nodes in total for scheduling.
I0714 09:25:15.151479       1 session.go:190] Open Session 95270425-5966-4d06-ba7f-444f1b89d1e2 with <0> Job and <1> Queues
I0714 09:25:15.153401       1 enqueue.go:79] Try to enqueue PodGroup to 0 Queues
I0714 09:25:15.153474       1 allocate.go:64] Try to allocate resource to 0 Queues
I0714 09:25:15.153679       1 session.go:244] Close Session 95270425-5966-4d06-ba7f-444f1b89d1e2
I0714 09:25:16.155895       1 cache.go:1363] There are <0> Jobs, <1> Queues and <5> Nodes in total for scheduling.
I0714 09:25:16.156080       1 session.go:190] Open Session f85a608e-91fb-48fb-afa1-63586435f517 with <0> Job and <1> Queues
I0714 09:25:16.158047       1 enqueue.go:79] Try to enqueue PodGroup to 0 Queues
I0714 09:25:16.158119       1 allocate.go:64] Try to allocate resource to 0 Queues
I0714 09:25:16.158351       1 session.go:244] Close Session f85a608e-91fb-48fb-afa1-63586435f517
I0714 09:25:17.161168       1 cache.go:1363] There are <0> Jobs, <1> Queues and <5> Nodes in total for scheduling.
I0714 09:25:17.161316       1 session.go:190] Open Session 1088e1f9-cc28-4473-9c8f-ef84fac3163c with <0> Job and <1> Queues
I0714 09:25:17.163221       1 enqueue.go:79] Try to enqueue PodGroup to 0 Queues
I0714 09:25:17.163295       1 allocate.go:64] Try to allocate resource to 0 Queues
I0714 09:25:17.163514       1 session.go:244] Close Session 1088e1f9-cc28-4473-9c8f-ef84fac3163c
I0714 09:25:18.165656       1 cache.go:1363] There are <0> Jobs, <1> Queues and <5> Nodes in total for scheduling.
I0714 09:25:18.165799       1 session.go:190] Open Session f190eff4-5619-4983-967b-b3ca6d4ed308 with <0> Job and <1> Queues
I0714 09:25:18.167728       1 enqueue.go:79] Try to enqueue PodGroup to 0 Queues
I0714 09:25:18.167792       1 allocate.go:64] Try to allocate resource to 0 Queues
I0714 09:25:18.167994       1 session.go:244] Close Session f190eff4-5619-4983-967b-b3ca6d4ed308
I0714 09:25:19.171083       1 cache.go:1363] There are <0> Jobs, <1> Queues and <5> Nodes in total for scheduling.
I0714 09:25:19.171260       1 session.go:190] Open Session 53915b45-adf3-400f-b7e3-761e213a0cb7 with <0> Job and <1> Queues
I0714 09:25:19.173278       1 enqueue.go:79] Try to enqueue PodGroup to 0 Queues
I0714 09:25:19.173359       1 allocate.go:64] Try to allocate resource to 0 Queues
I0714 09:25:19.173603       1 session.go:244] Close Session 53915b45-adf3-400f-b7e3-761e213a0cb7
I0714 09:25:20.176806       1 cache.go:1363] There are <0> Jobs, <1> Queues and <5> Nodes in total for scheduling.
I0714 09:25:20.176983       1 session.go:190] Open Session c38c9c2a-fb5f-4c44-b478-e12520a15083 with <0> Job and <1> Queues
I0714 09:25:20.178931       1 enqueue.go:79] Try to enqueue PodGroup to 0 Queues
I0714 09:25:20.179013       1 allocate.go:64] Try to allocate resource to 0 Queues
I0714 09:25:20.179234       1 session.go:244] Close Session c38c9c2a-fb5f-4c44-b478-e12520a15083
I0714 09:25:21.181781       1 cache.go:1363] There are <0> Jobs, <1> Queues and <5> Nodes in total for scheduling.
I0714 09:25:21.181979       1 session.go:190] Open Session 10d3e897-0497-44de-9849-29993982d93c with <0> Job and <1> Queues
I0714 09:25:21.183980       1 enqueue.go:79] Try to enqueue PodGroup to 0 Queues
I0714 09:25:21.184067       1 allocate.go:64] Try to allocate resource to 0 Queues
I0714 09:25:21.184380       1 session.go:244] Close Session 10d3e897-0497-44de-9849-29993982d93c
I0714 09:25:22.186567       1 cache.go:1363] There are <0> Jobs, <1> Queues and <5> Nodes in total for scheduling.
I0714 09:25:22.186761       1 session.go:190] Open Session 15d37602-3f63-4537-968d-38023a0d496c with <0> Job and <1> Queues
I0714 09:25:22.188793       1 enqueue.go:79] Try to enqueue PodGroup to 0 Queues
I0714 09:25:22.188884       1 allocate.go:64] Try to allocate resource to 0 Queues
I0714 09:25:22.189114       1 session.go:244] Close Session 15d37602-3f63-4537-968d-38023a0d496c
I0714 09:25:23.191686       1 cache.go:1363] There are <0> Jobs, <1> Queues and <5> Nodes in total for scheduling.
I0714 09:25:23.191891       1 session.go:190] Open Session 9949e65e-6908-4a3b-9b29-8f039e3e9cfa with <0> Job and <1> Queues
I0714 09:25:23.193948       1 enqueue.go:79] Try to enqueue PodGroup to 0 Queues
I0714 09:25:23.194048       1 allocate.go:64] Try to allocate resource to 0 Queues
I0714 09:25:23.194282       1 session.go:244] Close Session 9949e65e-6908-4a3b-9b29-8f039e3e9cfa
I0714 09:25:24.196709       1 cache.go:1363] There are <0> Jobs, <1> Queues and <5> Nodes in total for scheduling.
I0714 09:25:24.196894       1 session.go:190] Open Session 7b4b253d-a8ea-424d-b7f8-03e4431003c4 with <0> Job and <1> Queues
I0714 09:25:24.198850       1 enqueue.go:79] Try to enqueue PodGroup to 0 Queues
I0714 09:25:24.198935       1 allocate.go:64] Try to allocate resource to 0 Queues
I0714 09:25:24.199175       1 session.go:244] Close Session 7b4b253d-a8ea-424d-b7f8-03e4431003c4
I0714 09:25:25.201835       1 cache.go:1363] There are <0> Jobs, <1> Queues and <5> Nodes in total for scheduling.
I0714 09:25:25.202036       1 session.go:190] Open Session 51938f61-1276-4a3d-ba4e-c3ee254120d6 with <0> Job and <1> Queues
I0714 09:25:25.204012       1 enqueue.go:79] Try to enqueue PodGroup to 0 Queues
I0714 09:25:25.204122       1 allocate.go:64] Try to allocate resource to 0 Queues
I0714 09:25:25.204397       1 session.go:244] Close Session 51938f61-1276-4a3d-ba4e-c3ee254120d6
I0714 09:25:26.206862       1 cache.go:1363] There are <0> Jobs, <1> Queues and <5> Nodes in total for scheduling.
I0714 09:25:26.207053       1 session.go:190] Open Session b0ac7f17-506d-40aa-92b0-8dc483876f3b with <0> Job and <1> Queues
I0714 09:25:26.208951       1 enqueue.go:79] Try to enqueue PodGroup to 0 Queues
I0714 09:25:26.209036       1 allocate.go:64] Try to allocate resource to 0 Queues
I0714 09:25:26.209251       1 session.go:244] Close Session b0ac7f17-506d-40aa-92b0-8dc483876f3b
I0714 09:25:27.211866       1 cache.go:1363] There are <0> Jobs, <1> Queues and <5> Nodes in total for scheduling.
I0714 09:25:27.212043       1 session.go:190] Open Session cd8fd649-fa50-4dff-b76c-e19a01c8bc13 with <0> Job and <1> Queues
I0714 09:25:27.213976       1 enqueue.go:79] Try to enqueue PodGroup to 0 Queues
I0714 09:25:27.214062       1 allocate.go:64] Try to allocate resource to 0 Queues
I0714 09:25:27.214291       1 session.go:244] Close Session cd8fd649-fa50-4dff-b76c-e19a01c8bc13
I0714 09:25:28.216203       1 cache.go:1363] There are <0> Jobs, <1> Queues and <5> Nodes in total for scheduling.
I0714 09:25:28.216393       1 session.go:190] Open Session e19097de-f5b4-4124-9774-c45ce17523de with <0> Job and <1> Queues
I0714 09:25:28.218237       1 enqueue.go:79] Try to enqueue PodGroup to 0 Queues
I0714 09:25:28.218322       1 allocate.go:64] Try to allocate resource to 0 Queues
I0714 09:25:28.218558       1 session.go:244] Close Session e19097de-f5b4-4124-9774-c45ce17523de
I0714 09:25:29.220747       1 cache.go:1363] There are <0> Jobs, <1> Queues and <5> Nodes in total for scheduling.
I0714 09:25:29.220962       1 session.go:190] Open Session c13d3573-a46a-4fba-8106-31881d777d4d with <0> Job and <1> Queues
I0714 09:25:29.222843       1 enqueue.go:79] Try to enqueue PodGroup to 0 Queues
I0714 09:25:29.222940       1 allocate.go:64] Try to allocate resource to 0 Queues
I0714 09:25:29.223165       1 session.go:244] Close Session c13d3573-a46a-4fba-8106-31881d777d4d
I0714 09:25:30.225284       1 cache.go:1363] There are <0> Jobs, <1> Queues and <5> Nodes in total for scheduling.
I0714 09:25:30.225458       1 session.go:190] Open Session b0c6b858-7090-400c-b62c-3957219bb606 with <0> Job and <1> Queues
I0714 09:25:30.227310       1 enqueue.go:79] Try to enqueue PodGroup to 0 Queues
I0714 09:25:30.227396       1 allocate.go:64] Try to allocate resource to 0 Queues
I0714 09:25:30.227612       1 session.go:244] Close Session b0c6b858-7090-400c-b62c-3957219bb606
I0714 09:25:31.230390       1 cache.go:1363] There are <0> Jobs, <1> Queues and <5> Nodes in total for scheduling.
I0714 09:25:31.230575       1 session.go:190] Open Session d3e89987-55bb-447e-a7d9-c50be1753694 with <0> Job and <1> Queues
I0714 09:25:31.232558       1 enqueue.go:79] Try to enqueue PodGroup to 0 Queues
I0714 09:25:31.232638       1 allocate.go:64] Try to allocate resource to 0 Queues
I0714 09:25:31.232858       1 session.go:244] Close Session d3e89987-55bb-447e-a7d9-c50be1753694
W0714 09:25:32.170649       1 event_handlers.go:181] Not support non-csi pvc.
I0714 09:25:32.174964       1 event_handlers.go:442] Deleted pod <default/yolo-cls> from cache.
I0714 09:25:32.235273       1 cache.go:1363] There are <0> Jobs, <1> Queues and <5> Nodes in total for scheduling.
I0714 09:25:32.235419       1 session.go:190] Open Session 5a5c9467-1150-40b2-b40c-4fe3e243c776 with <0> Job and <1> Queues
W0714 09:25:32.236035       1 event_handlers.go:181] Not support non-csi pvc.
I0714 09:25:32.237313       1 enqueue.go:79] Try to enqueue PodGroup to 0 Queues
I0714 09:25:32.237386       1 allocate.go:64] Try to allocate resource to 0 Queues
I0714 09:25:32.237601       1 session.go:244] Close Session 5a5c9467-1150-40b2-b40c-4fe3e243c776
I0714 09:25:32.239684       1 event_handlers.go:442] Deleted pod <default/yolo-det> from cache.
W0714 09:25:32.313881       1 event_handlers.go:181] Not support non-csi pvc.
I0714 09:25:32.320790       1 event_handlers.go:442] Deleted pod <default/yolo-seg> from cache.
W0714 09:25:32.377063       1 event_handlers.go:181] Not support non-csi pvc.
I0714 09:25:32.381522       1 event_handlers.go:442] Deleted pod <default/yolo-obb> from cache.
W0714 09:25:32.438490       1 event_handlers.go:181] Not support non-csi pvc.
I0714 09:25:32.442896       1 event_handlers.go:442] Deleted pod <default/yolo-pos> from cache.
I0714 09:25:33.240282       1 cache.go:1363] There are <0> Jobs, <1> Queues and <5> Nodes in total for scheduling.
I0714 09:25:33.240495       1 session.go:190] Open Session 38338fe8-fff6-4447-9d3a-be16b2840813 with <0> Job and <1> Queues
I0714 09:25:33.242283       1 enqueue.go:79] Try to enqueue PodGroup to 0 Queues
I0714 09:25:33.242350       1 allocate.go:64] Try to allocate resource to 0 Queues
I0714 09:25:33.242617       1 session.go:244] Close Session 38338fe8-fff6-4447-9d3a-be16b2840813
I0714 09:25:34.245281       1 cache.go:1363] There are <0> Jobs, <1> Queues and <5> Nodes in total for scheduling.
I0714 09:25:34.245444       1 session.go:190] Open Session b3fee4f5-4ba7-4dae-b7d1-491cf7a667ad with <0> Job and <1> Queues
I0714 09:25:34.247163       1 enqueue.go:79] Try to enqueue PodGroup to 0 Queues
I0714 09:25:34.247230       1 allocate.go:64] Try to allocate resource to 0 Queues
I0714 09:25:34.247448       1 session.go:244] Close Session b3fee4f5-4ba7-4dae-b7d1-491cf7a667ad
I0714 09:25:35.249682       1 cache.go:1363] There are <0> Jobs, <1> Queues and <5> Nodes in total for scheduling.
I0714 09:25:35.249845       1 session.go:190] Open Session 9ebd96d4-9acc-41fc-8c87-979998b3da22 with <0> Job and <1> Queues
I0714 09:25:35.252947       1 enqueue.go:79] Try to enqueue PodGroup to 0 Queues
I0714 09:25:35.253030       1 allocate.go:64] Try to allocate resource to 0 Queues
I0714 09:25:35.253543       1 session.go:244] Close Session 9ebd96d4-9acc-41fc-8c87-979998b3da22
I0714 09:25:36.256341       1 cache.go:1363] There are <0> Jobs, <1> Queues and <5> Nodes in total for scheduling.
I0714 09:25:36.256533       1 session.go:190] Open Session 893b74da-dbee-4a3a-82a3-1798d76d517d with <0> Job and <1> Queues
I0714 09:25:36.258417       1 enqueue.go:79] Try to enqueue PodGroup to 0 Queues
I0714 09:25:36.258486       1 allocate.go:64] Try to allocate resource to 0 Queues
I0714 09:25:36.258707       1 session.go:244] Close Session 893b74da-dbee-4a3a-82a3-1798d76d517d
I0714 09:25:36.664544       1 cache.go:1489] The metrics type is not set in the volcano scheduler configmap file. As a result, the CPU and memory load information of the node is not collected.
I0714 09:25:37.261492       1 cache.go:1363] There are <0> Jobs, <1> Queues and <5> Nodes in total for scheduling.
I0714 09:25:37.261625       1 session.go:190] Open Session 938cadbc-75b5-4578-9555-635f73bde92b with <0> Job and <1> Queues
I0714 09:25:37.263366       1 enqueue.go:79] Try to enqueue PodGroup to 0 Queues
I0714 09:25:37.263430       1 allocate.go:64] Try to allocate resource to 0 Queues
I0714 09:25:37.263655       1 session.go:244] Close Session 938cadbc-75b5-4578-9555-635f73bde92b
I0714 09:25:38.265761       1 cache.go:1363] There are <0> Jobs, <1> Queues and <5> Nodes in total for scheduling.
I0714 09:25:38.265915       1 session.go:190] Open Session 2378dc7f-b9dc-494f-88dd-8898ce296baa with <0> Job and <1> Queues
I0714 09:25:38.267642       1 enqueue.go:79] Try to enqueue PodGroup to 0 Queues
I0714 09:25:38.267706       1 allocate.go:64] Try to allocate resource to 0 Queues
I0714 09:25:38.267930       1 session.go:244] Close Session 2378dc7f-b9dc-494f-88dd-8898ce296baa
I0714 09:25:39.270189       1 cache.go:1363] There are <0> Jobs, <1> Queues and <5> Nodes in total for scheduling.
I0714 09:25:39.270350       1 session.go:190] Open Session 2e97051c-fe5a-4598-b068-2147a22d37f5 with <0> Job and <1> Queues
I0714 09:25:39.272178       1 enqueue.go:79] Try to enqueue PodGroup to 0 Queues
I0714 09:25:39.272239       1 allocate.go:64] Try to allocate resource to 0 Queues
I0714 09:25:39.272497       1 session.go:244] Close Session 2e97051c-fe5a-4598-b068-2147a22d37f5
I0714 09:25:40.275264       1 cache.go:1363] There are <0> Jobs, <1> Queues and <5> Nodes in total for scheduling.
I0714 09:25:40.275507       1 session.go:190] Open Session 714963e1-e054-4bfa-88f6-7bd7c0d1d3f8 with <0> Job and <1> Queues
I0714 09:25:40.277320       1 enqueue.go:79] Try to enqueue PodGroup to 0 Queues
I0714 09:25:40.277383       1 allocate.go:64] Try to allocate resource to 0 Queues
I0714 09:25:40.277621       1 session.go:244] Close Session 714963e1-e054-4bfa-88f6-7bd7c0d1d3f8
I0714 09:25:41.280621       1 cache.go:1363] There are <0> Jobs, <1> Queues and <5> Nodes in total for scheduling.
I0714 09:25:41.280784       1 session.go:190] Open Session fcc82d6b-5364-4452-92d1-d5d5fd7e5113 with <0> Job and <1> Queues
I0714 09:25:41.282491       1 enqueue.go:79] Try to enqueue PodGroup to 0 Queues
I0714 09:25:41.282555       1 allocate.go:64] Try to allocate resource to 0 Queues
I0714 09:25:41.282784       1 session.go:244] Close Session fcc82d6b-5364-4452-92d1-d5d5fd7e5113
I0714 09:25:42.285616       1 cache.go:1363] There are <0> Jobs, <1> Queues and <5> Nodes in total for scheduling.
I0714 09:25:42.285777       1 session.go:190] Open Session 7c20461d-e10d-43b3-a0c9-4b56c9c9c5ef with <0> Job and <1> Queues
I0714 09:25:42.287633       1 enqueue.go:79] Try to enqueue PodGroup to 0 Queues
I0714 09:25:42.287697       1 allocate.go:64] Try to allocate resource to 0 Queues
I0714 09:25:42.287892       1 session.go:244] Close Session 7c20461d-e10d-43b3-a0c9-4b56c9c9c5ef
I0714 09:25:43.289999       1 cache.go:1363] There are <0> Jobs, <1> Queues and <5> Nodes in total for scheduling.
I0714 09:25:43.290166       1 session.go:190] Open Session 9ae5ec5d-4478-473c-9d29-47c8131d121e with <0> Job and <1> Queues
I0714 09:25:43.291899       1 enqueue.go:79] Try to enqueue PodGroup to 0 Queues
I0714 09:25:43.291966       1 allocate.go:64] Try to allocate resource to 0 Queues
I0714 09:25:43.292170       1 session.go:244] Close Session 9ae5ec5d-4478-473c-9d29-47c8131d121e
I0714 09:25:44.294802       1 cache.go:1363] There are <0> Jobs, <1> Queues and <5> Nodes in total for scheduling.
I0714 09:25:44.294978       1 session.go:190] Open Session 383f53cb-0308-4a18-816c-4d54e9f48b02 with <0> Job and <1> Queues
I0714 09:25:44.296884       1 enqueue.go:79] Try to enqueue PodGroup to 0 Queues
I0714 09:25:44.296952       1 allocate.go:64] Try to allocate resource to 0 Queues
I0714 09:25:44.297160       1 session.go:244] Close Session 383f53cb-0308-4a18-816c-4d54e9f48b02
I0714 09:25:45.299591       1 cache.go:1363] There are <0> Jobs, <1> Queues and <5> Nodes in total for scheduling.
I0714 09:25:45.299746       1 session.go:190] Open Session db8fed2e-08b2-48f7-bb5f-1888a3d3ba97 with <0> Job and <1> Queues
I0714 09:25:45.301547       1 enqueue.go:79] Try to enqueue PodGroup to 0 Queues
I0714 09:25:45.301617       1 allocate.go:64] Try to allocate resource to 0 Queues
I0714 09:25:45.301821       1 session.go:244] Close Session db8fed2e-08b2-48f7-bb5f-1888a3d3ba97
I0714 09:25:46.304246       1 cache.go:1363] There are <0> Jobs, <1> Queues and <5> Nodes in total for scheduling.
I0714 09:25:46.304466       1 session.go:190] Open Session f2413144-7f20-49b1-840a-b5b2108d52c2 with <0> Job and <1> Queues
I0714 09:25:46.306146       1 enqueue.go:79] Try to enqueue PodGroup to 0 Queues
I0714 09:25:46.306214       1 allocate.go:64] Try to allocate resource to 0 Queues
I0714 09:25:46.306418       1 session.go:244] Close Session f2413144-7f20-49b1-840a-b5b2108d52c2
I0714 09:25:47.309151       1 cache.go:1363] There are <0> Jobs, <1> Queues and <5> Nodes in total for scheduling.
I0714 09:25:47.309333       1 session.go:190] Open Session fed819c3-3cfb-436e-af05-2ff7d345eb24 with <0> Job and <1> Queues
I0714 09:25:47.311110       1 enqueue.go:79] Try to enqueue PodGroup to 0 Queues
I0714 09:25:47.311183       1 allocate.go:64] Try to allocate resource to 0 Queues
I0714 09:25:47.311401       1 session.go:244] Close Session fed819c3-3cfb-436e-af05-2ff7d345eb24
I0714 09:25:48.312820       1 cache.go:1363] There are <0> Jobs, <1> Queues and <5> Nodes in total for scheduling.
I0714 09:25:48.312911       1 session.go:190] Open Session ca8d48cf-3792-48f4-99c3-7d30439734e6 with <0> Job and <1> Queues
I0714 09:25:48.313693       1 enqueue.go:79] Try to enqueue PodGroup to 0 Queues
I0714 09:25:48.313734       1 allocate.go:64] Try to allocate resource to 0 Queues
I0714 09:25:48.313825       1 session.go:244] Close Session ca8d48cf-3792-48f4-99c3-7d30439734e6
I0714 09:25:49.314954       1 cache.go:1363] There are <0> Jobs, <1> Queues and <5> Nodes in total for scheduling.
I0714 09:25:49.315074       1 session.go:190] Open Session 448bcc98-688a-462e-94a0-9354e7dda02e with <0> Job and <1> Queues
I0714 09:25:49.316006       1 enqueue.go:79] Try to enqueue PodGroup to 0 Queues
I0714 09:25:49.316046       1 allocate.go:64] Try to allocate resource to 0 Queues
I0714 09:25:49.316160       1 session.go:244] Close Session 448bcc98-688a-462e-94a0-9354e7dda02e
I0714 09:25:50.318334       1 cache.go:1363] There are <0> Jobs, <1> Queues and <5> Nodes in total for scheduling.
I0714 09:25:50.318511       1 session.go:190] Open Session acd8e0b9-4cc7-4454-ab06-6cf9b4740280 with <0> Job and <1> Queues
I0714 09:25:50.320504       1 enqueue.go:79] Try to enqueue PodGroup to 0 Queues
I0714 09:25:50.320581       1 allocate.go:64] Try to allocate resource to 0 Queues
I0714 09:25:50.320825       1 session.go:244] Close Session acd8e0b9-4cc7-4454-ab06-6cf9b4740280
I0714 09:25:51.323515       1 cache.go:1363] There are <0> Jobs, <1> Queues and <5> Nodes in total for scheduling.
I0714 09:25:51.323681       1 session.go:190] Open Session 3a75372b-1913-4fd5-85b3-8e10bff76406 with <0> Job and <1> Queues
I0714 09:25:51.325486       1 enqueue.go:79] Try to enqueue PodGroup to 0 Queues
I0714 09:25:51.325552       1 allocate.go:64] Try to allocate resource to 0 Queues
I0714 09:25:51.325772       1 session.go:244] Close Session 3a75372b-1913-4fd5-85b3-8e10bff76406
I0714 09:25:52.328024       1 cache.go:1363] There are <0> Jobs, <1> Queues and <5> Nodes in total for scheduling.
I0714 09:25:52.328206       1 session.go:190] Open Session 7ced9a2f-4c57-446e-8a9c-01a75b58e624 with <0> Job and <1> Queues
I0714 09:25:52.329970       1 enqueue.go:79] Try to enqueue PodGroup to 0 Queues
I0714 09:25:52.330047       1 allocate.go:64] Try to allocate resource to 0 Queues
I0714 09:25:52.330260       1 session.go:244] Close Session 7ced9a2f-4c57-446e-8a9c-01a75b58e624
I0714 09:25:53.332564       1 cache.go:1363] There are <0> Jobs, <1> Queues and <5> Nodes in total for scheduling.
I0714 09:25:53.332736       1 session.go:190] Open Session c1fde3df-6dca-4e3a-8abe-4759445bf116 with <0> Job and <1> Queues
I0714 09:25:53.334674       1 enqueue.go:79] Try to enqueue PodGroup to 0 Queues
I0714 09:25:53.334740       1 allocate.go:64] Try to allocate resource to 0 Queues
I0714 09:25:53.334967       1 session.go:244] Close Session c1fde3df-6dca-4e3a-8abe-4759445bf116
I0714 09:25:54.337859       1 cache.go:1363] There are <0> Jobs, <1> Queues and <5> Nodes in total for scheduling.
I0714 09:25:54.338030       1 session.go:190] Open Session 0ff8614e-0c41-49f1-afe3-db026ebb9bbb with <0> Job and <1> Queues
I0714 09:25:54.339854       1 enqueue.go:79] Try to enqueue PodGroup to 0 Queues
I0714 09:25:54.339924       1 allocate.go:64] Try to allocate resource to 0 Queues
I0714 09:25:54.340164       1 session.go:244] Close Session 0ff8614e-0c41-49f1-afe3-db026ebb9bbb
I0714 09:25:55.342210       1 cache.go:1363] There are <0> Jobs, <1> Queues and <5> Nodes in total for scheduling.
I0714 09:25:55.342382       1 session.go:190] Open Session 251f93d2-a3b3-4839-9817-99490b2206cc with <0> Job and <1> Queues
I0714 09:25:55.344097       1 enqueue.go:79] Try to enqueue PodGroup to 0 Queues
I0714 09:25:55.344177       1 allocate.go:64] Try to allocate resource to 0 Queues
I0714 09:25:55.344437       1 session.go:244] Close Session 251f93d2-a3b3-4839-9817-99490b2206cc
I0714 09:25:56.347444       1 cache.go:1363] There are <0> Jobs, <1> Queues and <5> Nodes in total for scheduling.
I0714 09:25:56.347620       1 session.go:190] Open Session b9f43476-211c-400c-b519-34e7f66931b5 with <0> Job and <1> Queues
I0714 09:25:56.349448       1 enqueue.go:79] Try to enqueue PodGroup to 0 Queues
I0714 09:25:56.349522       1 allocate.go:64] Try to allocate resource to 0 Queues
I0714 09:25:56.349731       1 session.go:244] Close Session b9f43476-211c-400c-b519-34e7f66931b5
I0714 09:25:57.351832       1 cache.go:1363] There are <0> Jobs, <1> Queues and <5> Nodes in total for scheduling.
I0714 09:25:57.351985       1 session.go:190] Open Session 738f0a9d-3ae7-42c8-9089-4ee2aa0e8fad with <0> Job and <1> Queues
I0714 09:25:57.353797       1 enqueue.go:79] Try to enqueue PodGroup to 0 Queues
I0714 09:25:57.353869       1 allocate.go:64] Try to allocate resource to 0 Queues
I0714 09:25:57.354084       1 session.go:244] Close Session 738f0a9d-3ae7-42c8-9089-4ee2aa0e8fad
I0714 09:25:58.356371       1 cache.go:1363] There are <0> Jobs, <1> Queues and <5> Nodes in total for scheduling.
I0714 09:25:58.356516       1 session.go:190] Open Session a76a68da-6b91-4af6-b6ab-69efd14fe106 with <0> Job and <1> Queues
I0714 09:25:58.358164       1 enqueue.go:79] Try to enqueue PodGroup to 0 Queues
I0714 09:25:58.358229       1 allocate.go:64] Try to allocate resource to 0 Queues
I0714 09:25:58.358452       1 session.go:244] Close Session a76a68da-6b91-4af6-b6ab-69efd14fe106
I0714 09:25:59.361192       1 cache.go:1363] There are <0> Jobs, <1> Queues and <5> Nodes in total for scheduling.
I0714 09:25:59.361373       1 session.go:190] Open Session 35148d2b-a113-426a-bd86-6cc1b764832d with <0> Job and <1> Queues
I0714 09:25:59.363211       1 enqueue.go:79] Try to enqueue PodGroup to 0 Queues
I0714 09:25:59.363286       1 allocate.go:64] Try to allocate resource to 0 Queues
I0714 09:25:59.363495       1 session.go:244] Close Session 35148d2b-a113-426a-bd86-6cc1b764832d
I0714 09:26:00.365479       1 cache.go:1363] There are <0> Jobs, <1> Queues and <5> Nodes in total for scheduling.
I0714 09:26:00.365644       1 session.go:190] Open Session a4b2c02f-19ba-41fd-8028-d66f009f8882 with <0> Job and <1> Queues
I0714 09:26:00.367379       1 enqueue.go:79] Try to enqueue PodGroup to 0 Queues
I0714 09:26:00.367459       1 allocate.go:64] Try to allocate resource to 0 Queues
I0714 09:26:00.367683       1 session.go:244] Close Session a4b2c02f-19ba-41fd-8028-d66f009f8882
I0714 09:26:01.370611       1 cache.go:1363] There are <0> Jobs, <1> Queues and <5> Nodes in total for scheduling.
I0714 09:26:01.370800       1 session.go:190] Open Session 4f09367a-6c7b-4d8f-922b-778ebec308b7 with <0> Job and <1> Queues
I0714 09:26:01.372725       1 enqueue.go:79] Try to enqueue PodGroup to 0 Queues
I0714 09:26:01.372801       1 allocate.go:64] Try to allocate resource to 0 Queues
I0714 09:26:01.373030       1 session.go:244] Close Session 4f09367a-6c7b-4d8f-922b-778ebec308b7
I0714 09:26:02.375169       1 cache.go:1363] There are <0> Jobs, <1> Queues and <5> Nodes in total for scheduling.
I0714 09:26:02.375317       1 session.go:190] Open Session f09545b1-bfce-4db2-9dbf-6a2906c350fc with <0> Job and <1> Queues
I0714 09:26:02.377076       1 enqueue.go:79] Try to enqueue PodGroup to 0 Queues
I0714 09:26:02.377154       1 allocate.go:64] Try to allocate resource to 0 Queues
I0714 09:26:02.377390       1 session.go:244] Close Session f09545b1-bfce-4db2-9dbf-6a2906c350fc
I0714 09:26:03.379425       1 cache.go:1363] There are <0> Jobs, <1> Queues and <5> Nodes in total for scheduling.
I0714 09:26:03.379592       1 session.go:190] Open Session 00f16fff-dfd8-45db-b7ce-a5f9c038725c with <0> Job and <1> Queues
I0714 09:26:03.381454       1 enqueue.go:79] Try to enqueue PodGroup to 0 Queues
I0714 09:26:03.381534       1 allocate.go:64] Try to allocate resource to 0 Queues
I0714 09:26:03.381776       1 session.go:244] Close Session 00f16fff-dfd8-45db-b7ce-a5f9c038725c
I0714 09:26:04.384149       1 cache.go:1363] There are <0> Jobs, <1> Queues and <5> Nodes in total for scheduling.
I0714 09:26:04.384330       1 session.go:190] Open Session 29267e0a-3a9e-42e0-9190-70b60997a507 with <0> Job and <1> Queues
I0714 09:26:04.386236       1 enqueue.go:79] Try to enqueue PodGroup to 0 Queues
I0714 09:26:04.386308       1 allocate.go:64] Try to allocate resource to 0 Queues
I0714 09:26:04.386529       1 session.go:244] Close Session 29267e0a-3a9e-42e0-9190-70b60997a507
I0714 09:26:05.389221       1 cache.go:1363] There are <0> Jobs, <1> Queues and <5> Nodes in total for scheduling.
I0714 09:26:05.389394       1 session.go:190] Open Session 8a6ff6a5-7b61-459a-8162-04d022e174a4 with <0> Job and <1> Queues
I0714 09:26:05.391444       1 enqueue.go:79] Try to enqueue PodGroup to 0 Queues
I0714 09:26:05.391516       1 allocate.go:64] Try to allocate resource to 0 Queues
I0714 09:26:05.391740       1 session.go:244] Close Session 8a6ff6a5-7b61-459a-8162-04d022e174a4
I0714 09:26:06.393849       1 cache.go:1363] There are <0> Jobs, <1> Queues and <5> Nodes in total for scheduling.
I0714 09:26:06.394018       1 session.go:190] Open Session af2d7762-b407-4079-baf1-85e2710e9f5e with <0> Job and <1> Queues
I0714 09:26:06.395843       1 enqueue.go:79] Try to enqueue PodGroup to 0 Queues
I0714 09:26:06.395910       1 allocate.go:64] Try to allocate resource to 0 Queues
I0714 09:26:06.396129       1 session.go:244] Close Session af2d7762-b407-4079-baf1-85e2710e9f5e
I0714 09:26:06.665328       1 cache.go:1489] The metrics type is not set in the volcano scheduler configmap file. As a result, the CPU and memory load information of the node is not collected.
I0714 09:26:07.399203       1 cache.go:1363] There are <0> Jobs, <1> Queues and <5> Nodes in total for scheduling.
I0714 09:26:07.399375       1 session.go:190] Open Session 85c7834e-c0ec-40c8-80ac-75363e42d656 with <0> Job and <1> Queues
I0714 09:26:07.401205       1 enqueue.go:79] Try to enqueue PodGroup to 0 Queues
I0714 09:26:07.401280       1 allocate.go:64] Try to allocate resource to 0 Queues
I0714 09:26:07.401493       1 session.go:244] Close Session 85c7834e-c0ec-40c8-80ac-75363e42d656
I0714 09:26:08.403500       1 cache.go:1363] There are <0> Jobs, <1> Queues and <5> Nodes in total for scheduling.
I0714 09:26:08.403676       1 session.go:190] Open Session 028a98fa-7cb1-4dfc-b4f4-ae6ed9810e00 with <0> Job and <1> Queues
I0714 09:26:08.405490       1 enqueue.go:79] Try to enqueue PodGroup to 0 Queues
I0714 09:26:08.405868       1 allocate.go:64] Try to allocate resource to 0 Queues
I0714 09:26:08.406112       1 session.go:244] Close Session 028a98fa-7cb1-4dfc-b4f4-ae6ed9810e00
I0714 09:26:09.408987       1 cache.go:1363] There are <0> Jobs, <1> Queues and <5> Nodes in total for scheduling.
I0714 09:26:09.409156       1 session.go:190] Open Session 2ccd86d5-5867-4247-8de1-a61a51474bfb with <0> Job and <1> Queues
I0714 09:26:09.410941       1 enqueue.go:79] Try to enqueue PodGroup to 0 Queues
I0714 09:26:09.411013       1 allocate.go:64] Try to allocate resource to 0 Queues
I0714 09:26:09.411229       1 session.go:244] Close Session 2ccd86d5-5867-4247-8de1-a61a51474bfb
I0714 09:26:10.413812       1 cache.go:1363] There are <0> Jobs, <1> Queues and <5> Nodes in total for scheduling.
I0714 09:26:10.413992       1 session.go:190] Open Session f076ea78-6224-4338-a991-b16ff568a393 with <0> Job and <1> Queues
I0714 09:26:10.415684       1 enqueue.go:79] Try to enqueue PodGroup to 0 Queues
I0714 09:26:10.415777       1 allocate.go:64] Try to allocate resource to 0 Queues
I0714 09:26:10.416052       1 session.go:244] Close Session f076ea78-6224-4338-a991-b16ff568a393
I0714 09:26:11.418499       1 cache.go:1363] There are <0> Jobs, <1> Queues and <5> Nodes in total for scheduling.
I0714 09:26:11.418680       1 session.go:190] Open Session d3774976-d93c-450b-8aaf-277456c6e7ad with <0> Job and <1> Queues
I0714 09:26:11.420512       1 enqueue.go:79] Try to enqueue PodGroup to 0 Queues
I0714 09:26:11.420590       1 allocate.go:64] Try to allocate resource to 0 Queues
I0714 09:26:11.420798       1 session.go:244] Close Session d3774976-d93c-450b-8aaf-277456c6e7ad
I0714 09:26:12.423703       1 cache.go:1363] There are <0> Jobs, <1> Queues and <5> Nodes in total for scheduling.
I0714 09:26:12.423867       1 session.go:190] Open Session 188769ed-3d56-4122-9f51-91ede0e2af7c with <0> Job and <1> Queues
I0714 09:26:12.425647       1 enqueue.go:79] Try to enqueue PodGroup to 0 Queues
I0714 09:26:12.425733       1 allocate.go:64] Try to allocate resource to 0 Queues
I0714 09:26:12.425949       1 session.go:244] Close Session 188769ed-3d56-4122-9f51-91ede0e2af7c
I0714 09:26:13.428574       1 cache.go:1363] There are <0> Jobs, <1> Queues and <5> Nodes in total for scheduling.
I0714 09:26:13.428744       1 session.go:190] Open Session 494da3c8-870c-41a1-b2e3-af3b03b6e509 with <0> Job and <1> Queues
I0714 09:26:13.430468       1 enqueue.go:79] Try to enqueue PodGroup to 0 Queues
I0714 09:26:13.430553       1 allocate.go:64] Try to allocate resource to 0 Queues
I0714 09:26:13.430763       1 session.go:244] Close Session 494da3c8-870c-41a1-b2e3-af3b03b6e509
I0714 09:26:14.433407       1 cache.go:1363] There are <0> Jobs, <1> Queues and <5> Nodes in total for scheduling.
I0714 09:26:14.433582       1 session.go:190] Open Session 934719a6-95d1-43d5-a13d-656c51b6b8fc with <0> Job and <1> Queues
I0714 09:26:14.435295       1 enqueue.go:79] Try to enqueue PodGroup to 0 Queues
I0714 09:26:14.435371       1 allocate.go:64] Try to allocate resource to 0 Queues
I0714 09:26:14.435598       1 session.go:244] Close Session 934719a6-95d1-43d5-a13d-656c51b6b8fc
I0714 09:26:15.438143       1 cache.go:1363] There are <0> Jobs, <1> Queues and <5> Nodes in total for scheduling.
I0714 09:26:15.438313       1 session.go:190] Open Session 92229703-6679-470e-826f-24804478f401 with <0> Job and <1> Queues
I0714 09:26:15.440082       1 enqueue.go:79] Try to enqueue PodGroup to 0 Queues
I0714 09:26:15.440162       1 allocate.go:64] Try to allocate resource to 0 Queues
I0714 09:26:15.440430       1 session.go:244] Close Session 92229703-6679-470e-826f-24804478f401
I0714 09:26:16.442805       1 cache.go:1363] There are <0> Jobs, <1> Queues and <5> Nodes in total for scheduling.
I0714 09:26:16.442991       1 session.go:190] Open Session 44248f95-750f-49c1-97c9-a50212efc066 with <0> Job and <1> Queues
I0714 09:26:16.444934       1 enqueue.go:79] Try to enqueue PodGroup to 0 Queues
I0714 09:26:16.445021       1 allocate.go:64] Try to allocate resource to 0 Queues
I0714 09:26:16.445240       1 session.go:244] Close Session 44248f95-750f-49c1-97c9-a50212efc066
I0714 09:26:17.447674       1 cache.go:1363] There are <0> Jobs, <1> Queues and <5> Nodes in total for scheduling.
I0714 09:26:17.447818       1 session.go:190] Open Session 9a272a8e-8dbf-4415-a28f-8ce5b811757e with <0> Job and <1> Queues
I0714 09:26:17.449991       1 enqueue.go:79] Try to enqueue PodGroup to 0 Queues
I0714 09:26:17.450080       1 allocate.go:64] Try to allocate resource to 0 Queues
I0714 09:26:17.450302       1 session.go:244] Close Session 9a272a8e-8dbf-4415-a28f-8ce5b811757e
I0714 09:26:18.452557       1 cache.go:1363] There are <0> Jobs, <1> Queues and <5> Nodes in total for scheduling.
I0714 09:26:18.452687       1 session.go:190] Open Session ae466fb5-cc59-428a-a691-647f47261632 with <0> Job and <1> Queues
I0714 09:26:18.454382       1 enqueue.go:79] Try to enqueue PodGroup to 0 Queues
I0714 09:26:18.454458       1 allocate.go:64] Try to allocate resource to 0 Queues
I0714 09:26:18.454650       1 session.go:244] Close Session ae466fb5-cc59-428a-a691-647f47261632
I0714 09:26:19.456723       1 cache.go:1363] There are <0> Jobs, <1> Queues and <5> Nodes in total for scheduling.
I0714 09:26:19.456824       1 session.go:190] Open Session 9ea27c1f-0dbe-4995-94fd-2f63aa3f8a77 with <0> Job and <1> Queues
I0714 09:26:19.457843       1 enqueue.go:79] Try to enqueue PodGroup to 0 Queues
I0714 09:26:19.457893       1 allocate.go:64] Try to allocate resource to 0 Queues
I0714 09:26:19.458014       1 session.go:244] Close Session 9ea27c1f-0dbe-4995-94fd-2f63aa3f8a77
I0714 09:26:20.460727       1 cache.go:1363] There are <0> Jobs, <1> Queues and <5> Nodes in total for scheduling.
I0714 09:26:20.460873       1 session.go:190] Open Session 882d3bfd-eaae-44a0-ad8a-cdb5d8032e7d with <0> Job and <1> Queues
I0714 09:26:20.462861       1 enqueue.go:79] Try to enqueue PodGroup to 0 Queues
I0714 09:26:20.462940       1 allocate.go:64] Try to allocate resource to 0 Queues
I0714 09:26:20.463159       1 session.go:244] Close Session 882d3bfd-eaae-44a0-ad8a-cdb5d8032e7d
W0714 09:26:20.731563       1 event_handlers.go:181] Not support non-csi pvc.
I0714 09:26:20.731694       1 event_handlers.go:387] Added pod <default/yolo-cls> into cache.
W0714 09:26:20.767420       1 event_handlers.go:181] Not support non-csi pvc.
I0714 09:26:21.465832       1 cache.go:1363] There are <1> Jobs, <1> Queues and <5> Nodes in total for scheduling.
I0714 09:26:21.466009       1 session.go:190] Open Session 6437ceb0-340c-4791-9a41-dd3fe20f9a5f with <1> Job and <1> Queues
I0714 09:26:21.468272       1 enqueue.go:79] Try to enqueue PodGroup to 1 Queues
I0714 09:26:21.468567       1 allocate.go:64] Try to allocate resource to 1 Queues
I0714 09:26:21.468622       1 allocate.go:129] Try to allocate resource to Jobs in Queue <default>
I0714 09:26:21.468665       1 allocate.go:161] Try to allocate resource to 1 tasks of Job <default/podgroup-0f19262b-66a2-4efb-95fe-57b0e11d58e1>
I0714 09:26:21.468708       1 allocate.go:181] There are <5> nodes for Job <default/podgroup-0f19262b-66a2-4efb-95fe-57b0e11d58e1>
I0714 09:26:21.469038       1 predicate_helper.go:75] Predicates failed: task default/yolo-cls on node gpu-master fit failed: Insufficient nvidia.com/gpu
I0714 09:26:21.469422       1 predicate_helper.go:75] Predicates failed: task default/yolo-cls on node gpuorin4-desktop fit failed: plugin NodeAffinity predicates failed node(s) didn't match Pod's node affinity/selector
I0714 09:26:21.469530       1 predicate_helper.go:75] Predicates failed: task default/yolo-cls on node gpuorin5-desktop fit failed: plugin NodeAffinity predicates failed node(s) didn't match Pod's node affinity/selector
I0714 09:26:21.470626       1 allocate.go:249] Binding Task <default/yolo-cls> to node <gpu-orin3>
I0714 09:26:21.470856       1 statement.go:266] After allocated Task <default/yolo-cls> to Node <gpu-orin3>: idle <cpu 5900.00, memory 7832723456.00, ephemeral-storage 111715275387000.00, hugepages-64Ki 0.00, hugepages-2Mi 0.00, hugepages-32Mi 0.00, hugepages-1Gi 0.00, nvidia.com/gpu 4000.00, pods 105.00>, used <cpu 100.00, memory 52428800.00, pods 5.00, nvidia.com/gpu 1000.00>, releasing <cpu 0.00, memory 0.00>
I0714 09:26:21.471392       1 statement.go:284] Allocating operations ...
I0714 09:26:21.471526       1 statement.go:378] Committing operations ...
I0714 09:26:21.471645       1 proportion.go:302] Queue <default>: deserved <cpu 0.00, memory 0.00, pods 1.00, nvidia.com/gpu 1000.00>, allocated <cpu 0.00, memory 0.00, nvidia.com/gpu 1000.00, pods 1.00>, share <1>
I0714 09:26:21.471711       1 allocate.go:125] Queue <default> is overused, ignore it.
I0714 09:26:21.493116       1 session.go:244] Close Session 6437ceb0-340c-4791-9a41-dd3fe20f9a5f
I0714 09:26:21.498952       1 cache.go:900] bind ok, latency 17.510195ms
W0714 09:26:21.500883       1 event_handlers.go:181] Not support non-csi pvc.
W0714 09:26:21.541606       1 event_handlers.go:181] Not support non-csi pvc.
W0714 09:26:21.969950       1 event_handlers.go:181] Not support non-csi pvc.
I0714 09:26:21.977007       1 event_handlers.go:442] Deleted pod <default/yolo-cls> from cache.
I0714 09:26:21.990330       1 cache.go:1013] Try to delete Job <default/podgroup-0f19262b-66a2-4efb-95fe-57b0e11d58e1:default/podgroup-0f19262b-66a2-4efb-95fe-57b0e11d58e1>
I0714 09:26:21.990816       1 cache.go:1054] Job <default/podgroup-0f19262b-66a2-4efb-95fe-57b0e11d58e1:default/podgroup-0f19262b-66a2-4efb-95fe-57b0e11d58e1> was deleted.
W0714 09:26:22.137832       1 event_handlers.go:181] Not support non-csi pvc.
I0714 09:26:22.137961       1 event_handlers.go:387] Added pod <default/yolo-cls> into cache.
W0714 09:26:22.191185       1 event_handlers.go:181] Not support non-csi pvc.
I0714 09:26:22.495738       1 cache.go:1363] There are <0> Jobs, <1> Queues and <5> Nodes in total for scheduling.
I0714 09:26:22.495879       1 session.go:190] Open Session ecedf3f7-29ba-4b71-9200-d5841eb6890c with <0> Job and <1> Queues
I0714 09:26:22.497831       1 enqueue.go:79] Try to enqueue PodGroup to 0 Queues
I0714 09:26:22.497907       1 allocate.go:64] Try to allocate resource to 0 Queues
I0714 09:26:22.498129       1 session.go:244] Close Session ecedf3f7-29ba-4b71-9200-d5841eb6890c
I0714 09:26:23.501870       1 cache.go:1363] There are <0> Jobs, <1> Queues and <5> Nodes in total for scheduling.
I0714 09:26:23.502096       1 session.go:190] Open Session 4a69deb1-ee62-49e7-a560-6d9817616dff with <0> Job and <1> Queues
I0714 09:26:23.506485       1 enqueue.go:79] Try to enqueue PodGroup to 0 Queues
I0714 09:26:23.506660       1 allocate.go:64] Try to allocate resource to 0 Queues
I0714 09:26:23.506894       1 session.go:244] Close Session 4a69deb1-ee62-49e7-a560-6d9817616dff
I0714 09:26:24.509361       1 cache.go:1363] There are <0> Jobs, <1> Queues and <5> Nodes in total for scheduling.
I0714 09:26:24.509541       1 session.go:190] Open Session 44b75a48-3278-485f-98e4-7f2fd533137f with <0> Job and <1> Queues
I0714 09:26:24.511292       1 enqueue.go:79] Try to enqueue PodGroup to 0 Queues
I0714 09:26:24.511367       1 allocate.go:64] Try to allocate resource to 0 Queues
I0714 09:26:24.511608       1 session.go:244] Close Session 44b75a48-3278-485f-98e4-7f2fd533137f
W0714 09:26:24.748407       1 event_handlers.go:181] Not support non-csi pvc.
I0714 09:26:25.514002       1 cache.go:1363] There are <0> Jobs, <1> Queues and <5> Nodes in total for scheduling.
I0714 09:26:25.514170       1 session.go:190] Open Session 1a52736a-c1b8-472f-bff7-b6d6c7a1b772 with <0> Job and <1> Queues
I0714 09:26:25.515991       1 enqueue.go:79] Try to enqueue PodGroup to 0 Queues
I0714 09:26:25.516069       1 allocate.go:64] Try to allocate resource to 0 Queues
I0714 09:26:25.516282       1 session.go:244] Close Session 1a52736a-c1b8-472f-bff7-b6d6c7a1b772
I0714 09:26:26.518474       1 cache.go:1363] There are <0> Jobs, <1> Queues and <5> Nodes in total for scheduling.
I0714 09:26:26.518641       1 session.go:190] Open Session 70fa58b1-c473-48fd-a399-97891bea55b0 with <0> Job and <1> Queues
I0714 09:26:26.520723       1 enqueue.go:79] Try to enqueue PodGroup to 0 Queues
I0714 09:26:26.520802       1 allocate.go:64] Try to allocate resource to 0 Queues
I0714 09:26:26.521129       1 session.go:244] Close Session 70fa58b1-c473-48fd-a399-97891bea55b0
I0714 09:26:27.523716       1 cache.go:1363] There are <0> Jobs, <1> Queues and <5> Nodes in total for scheduling.
I0714 09:26:27.523875       1 session.go:190] Open Session 7c684b66-2585-4984-ad98-edd5ffe763ab with <0> Job and <1> Queues
I0714 09:26:27.525867       1 enqueue.go:79] Try to enqueue PodGroup to 0 Queues
I0714 09:26:27.525949       1 allocate.go:64] Try to allocate resource to 0 Queues
I0714 09:26:27.526184       1 session.go:244] Close Session 7c684b66-2585-4984-ad98-edd5ffe763ab
I0714 09:26:28.529146       1 cache.go:1363] There are <0> Jobs, <1> Queues and <5> Nodes in total for scheduling.
I0714 09:26:28.529286       1 session.go:190] Open Session 62927a3e-90fd-404c-8303-25d6ada54239 with <0> Job and <1> Queues
I0714 09:26:28.530975       1 enqueue.go:79] Try to enqueue PodGroup to 0 Queues
I0714 09:26:28.531049       1 allocate.go:64] Try to allocate resource to 0 Queues
I0714 09:26:28.531271       1 session.go:244] Close Session 62927a3e-90fd-404c-8303-25d6ada54239
W0714 09:26:28.877605       1 event_handlers.go:181] Not support non-csi pvc.
I0714 09:26:28.877721       1 event_handlers.go:387] Added pod <default/yolo-det> into cache.
W0714 09:26:28.904500       1 event_handlers.go:181] Not support non-csi pvc.
I0714 09:26:29.534714       1 cache.go:1363] There are <1> Jobs, <1> Queues and <5> Nodes in total for scheduling.
I0714 09:26:29.534903       1 session.go:190] Open Session 0bc038ae-44c2-436d-b457-0825c1a096f5 with <1> Job and <1> Queues
I0714 09:26:29.537438       1 enqueue.go:79] Try to enqueue PodGroup to 1 Queues
I0714 09:26:29.537741       1 allocate.go:64] Try to allocate resource to 1 Queues
I0714 09:26:29.537793       1 allocate.go:129] Try to allocate resource to Jobs in Queue <default>
I0714 09:26:29.537832       1 allocate.go:161] Try to allocate resource to 1 tasks of Job <default/podgroup-4d9dcc31-c80c-465f-a27a-91d16a8ffef8>
I0714 09:26:29.537875       1 allocate.go:181] There are <5> nodes for Job <default/podgroup-4d9dcc31-c80c-465f-a27a-91d16a8ffef8>
I0714 09:26:29.538190       1 predicate_helper.go:75] Predicates failed: task default/yolo-det on node gpu-master fit failed: Insufficient nvidia.com/gpu
I0714 09:26:29.538748       1 predicate_helper.go:75] Predicates failed: task default/yolo-det on node gpuorin5-desktop fit failed: plugin NodeAffinity predicates failed node(s) didn't match Pod's node affinity/selector
I0714 09:26:29.538803       1 predicate_helper.go:75] Predicates failed: task default/yolo-det on node gpuorin4-desktop fit failed: plugin NodeAffinity predicates failed node(s) didn't match Pod's node affinity/selector
I0714 09:26:29.540019       1 allocate.go:249] Binding Task <default/yolo-det> to node <gpu-orin2>
I0714 09:26:29.540240       1 statement.go:266] After allocated Task <default/yolo-det> to Node <gpu-orin2>: idle <cpu 5900.00, memory 7832690688.00, nvidia.com/gpu 4000.00, pods 105.00, ephemeral-storage 225118140453000.00, hugepages-1Gi 0.00, hugepages-32Mi 0.00, hugepages-2Mi 0.00, hugepages-64Ki 0.00>, used <cpu 100.00, memory 52428800.00, pods 5.00, nvidia.com/gpu 1000.00>, releasing <cpu 0.00, memory 0.00>
I0714 09:26:29.540767       1 statement.go:284] Allocating operations ...
I0714 09:26:29.540889       1 statement.go:378] Committing operations ...
I0714 09:26:29.541008       1 proportion.go:302] Queue <default>: deserved <cpu 0.00, memory 0.00, pods 1.00, nvidia.com/gpu 1000.00>, allocated <cpu 0.00, memory 0.00, nvidia.com/gpu 1000.00, pods 1.00>, share <1>
I0714 09:26:29.541062       1 allocate.go:125] Queue <default> is overused, ignore it.
I0714 09:26:29.563488       1 session.go:244] Close Session 0bc038ae-44c2-436d-b457-0825c1a096f5
I0714 09:26:29.581953       1 cache.go:900] bind ok, latency 18.143681ms
W0714 09:26:29.584008       1 event_handlers.go:181] Not support non-csi pvc.
W0714 09:26:29.615410       1 event_handlers.go:181] Not support non-csi pvc.
W0714 09:26:30.108973       1 event_handlers.go:181] Not support non-csi pvc.
I0714 09:26:30.114559       1 event_handlers.go:442] Deleted pod <default/yolo-det> from cache.
I0714 09:26:30.120444       1 cache.go:1013] Try to delete Job <default/podgroup-4d9dcc31-c80c-465f-a27a-91d16a8ffef8:default/podgroup-4d9dcc31-c80c-465f-a27a-91d16a8ffef8>
I0714 09:26:30.120646       1 cache.go:1054] Job <default/podgroup-4d9dcc31-c80c-465f-a27a-91d16a8ffef8:default/podgroup-4d9dcc31-c80c-465f-a27a-91d16a8ffef8> was deleted.
W0714 09:26:30.242277       1 event_handlers.go:181] Not support non-csi pvc.
I0714 09:26:30.242404       1 event_handlers.go:387] Added pod <default/yolo-det> into cache.
W0714 09:26:30.276625       1 event_handlers.go:181] Not support non-csi pvc.
I0714 09:26:30.565671       1 cache.go:1363] There are <0> Jobs, <1> Queues and <5> Nodes in total for scheduling.
I0714 09:26:30.565802       1 session.go:190] Open Session 1b041c51-5fe1-44bc-8326-2e660c170e3d with <0> Job and <1> Queues
I0714 09:26:30.567823       1 enqueue.go:79] Try to enqueue PodGroup to 0 Queues
I0714 09:26:30.567902       1 allocate.go:64] Try to allocate resource to 0 Queues
I0714 09:26:30.568137       1 session.go:244] Close Session 1b041c51-5fe1-44bc-8326-2e660c170e3d
I0714 09:26:31.570450       1 cache.go:1363] There are <0> Jobs, <1> Queues and <5> Nodes in total for scheduling.
I0714 09:26:31.570635       1 session.go:190] Open Session 36551d76-5f2c-421f-85dc-e3684df85e40 with <0> Job and <1> Queues
I0714 09:26:31.572830       1 enqueue.go:79] Try to enqueue PodGroup to 0 Queues
I0714 09:26:31.572914       1 allocate.go:64] Try to allocate resource to 0 Queues
I0714 09:26:31.573139       1 session.go:244] Close Session 36551d76-5f2c-421f-85dc-e3684df85e40
I0714 09:26:32.575837       1 cache.go:1363] There are <0> Jobs, <1> Queues and <5> Nodes in total for scheduling.
I0714 09:26:32.575990       1 session.go:190] Open Session d323da04-3178-4009-a563-d823a2e5cea7 with <0> Job and <1> Queues
I0714 09:26:32.577979       1 enqueue.go:79] Try to enqueue PodGroup to 0 Queues
I0714 09:26:32.578062       1 allocate.go:64] Try to allocate resource to 0 Queues
I0714 09:26:32.578286       1 session.go:244] Close Session d323da04-3178-4009-a563-d823a2e5cea7
W0714 09:26:32.785792       1 event_handlers.go:181] Not support non-csi pvc.
I0714 09:26:33.580657       1 cache.go:1363] There are <0> Jobs, <1> Queues and <5> Nodes in total for scheduling.
I0714 09:26:33.580813       1 session.go:190] Open Session 44d9fc2a-47cd-4e0e-a8df-d344377a2212 with <0> Job and <1> Queues
I0714 09:26:33.582601       1 enqueue.go:79] Try to enqueue PodGroup to 0 Queues
I0714 09:26:33.582678       1 allocate.go:64] Try to allocate resource to 0 Queues
I0714 09:26:33.582905       1 session.go:244] Close Session 44d9fc2a-47cd-4e0e-a8df-d344377a2212
I0714 09:26:34.585478       1 cache.go:1363] There are <0> Jobs, <1> Queues and <5> Nodes in total for scheduling.
I0714 09:26:34.585659       1 session.go:190] Open Session b410c62c-3658-4d65-882c-8937a39a0d05 with <0> Job and <1> Queues
I0714 09:26:34.587478       1 enqueue.go:79] Try to enqueue PodGroup to 0 Queues
I0714 09:26:34.587551       1 allocate.go:64] Try to allocate resource to 0 Queues
I0714 09:26:34.587785       1 session.go:244] Close Session b410c62c-3658-4d65-882c-8937a39a0d05
I0714 09:26:35.590712       1 cache.go:1363] There are <0> Jobs, <1> Queues and <5> Nodes in total for scheduling.
I0714 09:26:35.590894       1 session.go:190] Open Session d658f1fa-4f97-4009-8556-7ddfd5780ceb with <0> Job and <1> Queues
I0714 09:26:35.592870       1 enqueue.go:79] Try to enqueue PodGroup to 0 Queues
I0714 09:26:35.592949       1 allocate.go:64] Try to allocate resource to 0 Queues
I0714 09:26:35.593203       1 session.go:244] Close Session d658f1fa-4f97-4009-8556-7ddfd5780ceb
W0714 09:26:36.364244       1 event_handlers.go:181] Not support non-csi pvc.
I0714 09:26:36.364413       1 event_handlers.go:387] Added pod <default/yolo-seg> into cache.
W0714 09:26:36.390187       1 event_handlers.go:181] Not support non-csi pvc.
I0714 09:26:36.595780       1 cache.go:1363] There are <1> Jobs, <1> Queues and <5> Nodes in total for scheduling.
I0714 09:26:36.595921       1 session.go:190] Open Session 7b741586-eb5c-4a89-8d26-7e3ffd547853 with <1> Job and <1> Queues
I0714 09:26:36.598261       1 enqueue.go:79] Try to enqueue PodGroup to 1 Queues
I0714 09:26:36.598507       1 allocate.go:64] Try to allocate resource to 1 Queues
I0714 09:26:36.598554       1 allocate.go:129] Try to allocate resource to Jobs in Queue <default>
I0714 09:26:36.598588       1 allocate.go:161] Try to allocate resource to 1 tasks of Job <default/podgroup-42826902-c752-4a05-9037-718448cdeee7>
I0714 09:26:36.598627       1 allocate.go:181] There are <5> nodes for Job <default/podgroup-42826902-c752-4a05-9037-718448cdeee7>
I0714 09:26:36.598928       1 predicate_helper.go:75] Predicates failed: task default/yolo-seg on node gpu-master fit failed: Insufficient nvidia.com/gpu
I0714 09:26:36.599304       1 predicate_helper.go:75] Predicates failed: task default/yolo-seg on node gpuorin4-desktop fit failed: plugin NodeAffinity predicates failed node(s) didn't match Pod's node affinity/selector
I0714 09:26:36.599376       1 predicate_helper.go:75] Predicates failed: task default/yolo-seg on node gpuorin5-desktop fit failed: plugin NodeAffinity predicates failed node(s) didn't match Pod's node affinity/selector
I0714 09:26:36.600030       1 allocate.go:249] Binding Task <default/yolo-seg> to node <gpu-orin2>
I0714 09:26:36.600248       1 statement.go:266] After allocated Task <default/yolo-seg> to Node <gpu-orin2>: idle <cpu 5900.00, memory 7832690688.00, pods 104.00, hugepages-2Mi 0.00, hugepages-64Ki 0.00, nvidia.com/gpu 3000.00, ephemeral-storage 225118140453000.00, hugepages-1Gi 0.00, hugepages-32Mi 0.00>, used <cpu 100.00, memory 52428800.00, pods 6.00, nvidia.com/gpu 2000.00>, releasing <cpu 0.00, memory 0.00>
I0714 09:26:36.600731       1 statement.go:284] Allocating operations ...
I0714 09:26:36.600868       1 statement.go:378] Committing operations ...
I0714 09:26:36.600985       1 proportion.go:302] Queue <default>: deserved <cpu 0.00, memory 0.00, nvidia.com/gpu 1000.00, pods 1.00>, allocated <cpu 0.00, memory 0.00, nvidia.com/gpu 1000.00, pods 1.00>, share <1>
I0714 09:26:36.601063       1 allocate.go:125] Queue <default> is overused, ignore it.
I0714 09:26:36.626953       1 session.go:244] Close Session 7b741586-eb5c-4a89-8d26-7e3ffd547853
I0714 09:26:36.635411       1 cache.go:900] bind ok, latency 23.592606ms
W0714 09:26:36.636183       1 event_handlers.go:181] Not support non-csi pvc.
I0714 09:26:36.666193       1 cache.go:1489] The metrics type is not set in the volcano scheduler configmap file. As a result, the CPU and memory load information of the node is not collected.
W0714 09:26:36.679149       1 event_handlers.go:181] Not support non-csi pvc.
W0714 09:26:37.072705       1 event_handlers.go:181] Not support non-csi pvc.
I0714 09:26:37.073920       1 event_handlers.go:442] Deleted pod <default/yolo-seg> from cache.
I0714 09:26:37.080616       1 cache.go:1013] Try to delete Job <default/podgroup-42826902-c752-4a05-9037-718448cdeee7:default/podgroup-42826902-c752-4a05-9037-718448cdeee7>
I0714 09:26:37.080837       1 cache.go:1054] Job <default/podgroup-42826902-c752-4a05-9037-718448cdeee7:default/podgroup-42826902-c752-4a05-9037-718448cdeee7> was deleted.
W0714 09:26:37.214564       1 event_handlers.go:181] Not support non-csi pvc.
I0714 09:26:37.214728       1 event_handlers.go:387] Added pod <default/yolo-seg> into cache.
W0714 09:26:37.247078       1 event_handlers.go:181] Not support non-csi pvc.
I0714 09:26:37.629806       1 cache.go:1363] There are <0> Jobs, <1> Queues and <5> Nodes in total for scheduling.
I0714 09:26:37.629937       1 session.go:190] Open Session 2c938b78-47ea-401d-9e12-e37f52370eee with <0> Job and <1> Queues
I0714 09:26:37.631735       1 enqueue.go:79] Try to enqueue PodGroup to 0 Queues
I0714 09:26:37.631807       1 allocate.go:64] Try to allocate resource to 0 Queues
I0714 09:26:37.632011       1 session.go:244] Close Session 2c938b78-47ea-401d-9e12-e37f52370eee
I0714 09:26:38.634466       1 cache.go:1363] There are <0> Jobs, <1> Queues and <5> Nodes in total for scheduling.
I0714 09:26:38.634621       1 session.go:190] Open Session 6dc873ee-ed0d-4800-a654-ac15498ea41e with <0> Job and <1> Queues
I0714 09:26:38.636446       1 enqueue.go:79] Try to enqueue PodGroup to 0 Queues
I0714 09:26:38.636518       1 allocate.go:64] Try to allocate resource to 0 Queues
I0714 09:26:38.636749       1 session.go:244] Close Session 6dc873ee-ed0d-4800-a654-ac15498ea41e
I0714 09:26:39.639496       1 cache.go:1363] There are <0> Jobs, <1> Queues and <5> Nodes in total for scheduling.
I0714 09:26:39.639684       1 session.go:190] Open Session e087439b-7ec0-4eb9-85f2-af88bd518280 with <0> Job and <1> Queues
I0714 09:26:39.641573       1 enqueue.go:79] Try to enqueue PodGroup to 0 Queues
I0714 09:26:39.641655       1 allocate.go:64] Try to allocate resource to 0 Queues
I0714 09:26:39.641881       1 session.go:244] Close Session e087439b-7ec0-4eb9-85f2-af88bd518280
W0714 09:26:39.808417       1 event_handlers.go:181] Not support non-csi pvc.
I0714 09:26:40.644869       1 cache.go:1363] There are <0> Jobs, <1> Queues and <5> Nodes in total for scheduling.
I0714 09:26:40.644985       1 session.go:190] Open Session a208dd41-284e-4a00-8863-f53e000d91fa with <0> Job and <1> Queues
I0714 09:26:40.646734       1 enqueue.go:79] Try to enqueue PodGroup to 0 Queues
I0714 09:26:40.646803       1 allocate.go:64] Try to allocate resource to 0 Queues
I0714 09:26:40.647024       1 session.go:244] Close Session a208dd41-284e-4a00-8863-f53e000d91fa
I0714 09:26:41.649835       1 cache.go:1363] There are <0> Jobs, <1> Queues and <5> Nodes in total for scheduling.
I0714 09:26:41.650000       1 session.go:190] Open Session 1b17adaa-b9ae-4b41-bcc1-ce22db6cd426 with <0> Job and <1> Queues
I0714 09:26:41.652003       1 enqueue.go:79] Try to enqueue PodGroup to 0 Queues
I0714 09:26:41.652086       1 allocate.go:64] Try to allocate resource to 0 Queues
I0714 09:26:41.652349       1 session.go:244] Close Session 1b17adaa-b9ae-4b41-bcc1-ce22db6cd426
I0714 09:26:42.654614       1 cache.go:1363] There are <0> Jobs, <1> Queues and <5> Nodes in total for scheduling.
I0714 09:26:42.654782       1 session.go:190] Open Session 2836116a-8855-42ae-bf51-3209d861468b with <0> Job and <1> Queues
I0714 09:26:42.656965       1 enqueue.go:79] Try to enqueue PodGroup to 0 Queues
I0714 09:26:42.657056       1 allocate.go:64] Try to allocate resource to 0 Queues
I0714 09:26:42.657279       1 session.go:244] Close Session 2836116a-8855-42ae-bf51-3209d861468b
W0714 09:26:43.292087       1 event_handlers.go:181] Not support non-csi pvc.
I0714 09:26:43.292203       1 event_handlers.go:387] Added pod <default/yolo-obb> into cache.
W0714 09:26:43.316417       1 event_handlers.go:181] Not support non-csi pvc.
I0714 09:26:43.659866       1 cache.go:1363] There are <1> Jobs, <1> Queues and <5> Nodes in total for scheduling.
I0714 09:26:43.659986       1 session.go:190] Open Session e671af48-eeb5-46c2-b0f2-26bb2d7897be with <1> Job and <1> Queues
I0714 09:26:43.662276       1 enqueue.go:79] Try to enqueue PodGroup to 1 Queues
I0714 09:26:43.662514       1 allocate.go:64] Try to allocate resource to 1 Queues
I0714 09:26:43.662569       1 allocate.go:129] Try to allocate resource to Jobs in Queue <default>
I0714 09:26:43.662600       1 allocate.go:161] Try to allocate resource to 1 tasks of Job <default/podgroup-a02cf702-7cd9-45d8-ac3e-36490cfe7841>
I0714 09:26:43.662645       1 allocate.go:181] There are <5> nodes for Job <default/podgroup-a02cf702-7cd9-45d8-ac3e-36490cfe7841>
I0714 09:26:43.662961       1 predicate_helper.go:75] Predicates failed: task default/yolo-obb on node gpu-master fit failed: Insufficient nvidia.com/gpu
I0714 09:26:43.663456       1 predicate_helper.go:75] Predicates failed: task default/yolo-obb on node gpuorin5-desktop fit failed: plugin NodeAffinity predicates failed node(s) didn't match Pod's node affinity/selector
I0714 09:26:43.663812       1 predicate_helper.go:75] Predicates failed: task default/yolo-obb on node gpuorin4-desktop fit failed: plugin NodeAffinity predicates failed node(s) didn't match Pod's node affinity/selector
I0714 09:26:43.664581       1 allocate.go:249] Binding Task <default/yolo-obb> to node <gpu-orin3>
I0714 09:26:43.664798       1 statement.go:266] After allocated Task <default/yolo-obb> to Node <gpu-orin3>: idle <cpu 5900.00, memory 7832723456.00, hugepages-64Ki 0.00, nvidia.com/gpu 3000.00, pods 104.00, ephemeral-storage 111715275387000.00, hugepages-1Gi 0.00, hugepages-2Mi 0.00, hugepages-32Mi 0.00>, used <cpu 100.00, memory 52428800.00, pods 6.00, nvidia.com/gpu 2000.00>, releasing <cpu 0.00, memory 0.00>
I0714 09:26:43.665225       1 statement.go:284] Allocating operations ...
I0714 09:26:43.665361       1 statement.go:378] Committing operations ...
I0714 09:26:43.665477       1 proportion.go:302] Queue <default>: deserved <cpu 0.00, memory 0.00, nvidia.com/gpu 1000.00, pods 1.00>, allocated <cpu 0.00, memory 0.00, nvidia.com/gpu 1000.00, pods 1.00>, share <1>
I0714 09:26:43.665543       1 allocate.go:125] Queue <default> is overused, ignore it.
I0714 09:26:43.678920       1 session.go:244] Close Session e671af48-eeb5-46c2-b0f2-26bb2d7897be
I0714 09:26:43.692482       1 cache.go:900] bind ok, latency 10.69967ms
W0714 09:26:43.695053       1 event_handlers.go:181] Not support non-csi pvc.
W0714 09:26:43.734195       1 event_handlers.go:181] Not support non-csi pvc.
W0714 09:26:43.947866       1 event_handlers.go:181] Not support non-csi pvc.
I0714 09:26:43.952917       1 event_handlers.go:442] Deleted pod <default/yolo-obb> from cache.
I0714 09:26:43.964954       1 cache.go:1013] Try to delete Job <default/podgroup-a02cf702-7cd9-45d8-ac3e-36490cfe7841:default/podgroup-a02cf702-7cd9-45d8-ac3e-36490cfe7841>
I0714 09:26:43.965318       1 cache.go:1054] Job <default/podgroup-a02cf702-7cd9-45d8-ac3e-36490cfe7841:default/podgroup-a02cf702-7cd9-45d8-ac3e-36490cfe7841> was deleted.
W0714 09:26:44.086150       1 event_handlers.go:181] Not support non-csi pvc.
I0714 09:26:44.086372       1 event_handlers.go:387] Added pod <default/yolo-obb> into cache.
W0714 09:26:44.120575       1 event_handlers.go:181] Not support non-csi pvc.
I0714 09:26:44.681774       1 cache.go:1363] There are <0> Jobs, <1> Queues and <5> Nodes in total for scheduling.
I0714 09:26:44.681920       1 session.go:190] Open Session 778d2441-6e87-4eef-87fb-9d1d1ce279c0 with <0> Job and <1> Queues
I0714 09:26:44.683813       1 enqueue.go:79] Try to enqueue PodGroup to 0 Queues
I0714 09:26:44.683906       1 allocate.go:64] Try to allocate resource to 0 Queues
I0714 09:26:44.684140       1 session.go:244] Close Session 778d2441-6e87-4eef-87fb-9d1d1ce279c0
I0714 09:26:45.687018       1 cache.go:1363] There are <0> Jobs, <1> Queues and <5> Nodes in total for scheduling.
I0714 09:26:45.687174       1 session.go:190] Open Session ecd2f3ce-baba-466b-8b30-9a5f295a9604 with <0> Job and <1> Queues
I0714 09:26:45.689135       1 enqueue.go:79] Try to enqueue PodGroup to 0 Queues
I0714 09:26:45.689209       1 allocate.go:64] Try to allocate resource to 0 Queues
I0714 09:26:45.689435       1 session.go:244] Close Session ecd2f3ce-baba-466b-8b30-9a5f295a9604
I0714 09:26:46.691824       1 cache.go:1363] There are <0> Jobs, <1> Queues and <5> Nodes in total for scheduling.
I0714 09:26:46.691981       1 session.go:190] Open Session 77499817-9e59-4d60-9b11-f8894fe20a52 with <0> Job and <1> Queues
I0714 09:26:46.693883       1 enqueue.go:79] Try to enqueue PodGroup to 0 Queues
I0714 09:26:46.693959       1 allocate.go:64] Try to allocate resource to 0 Queues
I0714 09:26:46.694183       1 session.go:244] Close Session 77499817-9e59-4d60-9b11-f8894fe20a52
W0714 09:26:46.857914       1 event_handlers.go:181] Not support non-csi pvc.
I0714 09:26:47.696874       1 cache.go:1363] There are <0> Jobs, <1> Queues and <5> Nodes in total for scheduling.
I0714 09:26:47.697014       1 session.go:190] Open Session 970ff43a-21c4-4618-9e50-31d159f37d7b with <0> Job and <1> Queues
I0714 09:26:47.698836       1 enqueue.go:79] Try to enqueue PodGroup to 0 Queues
I0714 09:26:47.698906       1 allocate.go:64] Try to allocate resource to 0 Queues
I0714 09:26:47.699111       1 session.go:244] Close Session 970ff43a-21c4-4618-9e50-31d159f37d7b
I0714 09:26:48.701419       1 cache.go:1363] There are <0> Jobs, <1> Queues and <5> Nodes in total for scheduling.
I0714 09:26:48.701568       1 session.go:190] Open Session 877f62b6-62a6-47ab-bafb-bba122a1ac5a with <0> Job and <1> Queues
I0714 09:26:48.703417       1 enqueue.go:79] Try to enqueue PodGroup to 0 Queues
I0714 09:26:48.703488       1 allocate.go:64] Try to allocate resource to 0 Queues
I0714 09:26:48.703716       1 session.go:244] Close Session 877f62b6-62a6-47ab-bafb-bba122a1ac5a
I0714 09:26:49.706425       1 cache.go:1363] There are <0> Jobs, <1> Queues and <5> Nodes in total for scheduling.
I0714 09:26:49.706598       1 session.go:190] Open Session 9d82c1b4-cd54-4e3b-ace8-c9fe9cf14849 with <0> Job and <1> Queues
I0714 09:26:49.708662       1 enqueue.go:79] Try to enqueue PodGroup to 0 Queues
I0714 09:26:49.708739       1 allocate.go:64] Try to allocate resource to 0 Queues
I0714 09:26:49.708954       1 session.go:244] Close Session 9d82c1b4-cd54-4e3b-ace8-c9fe9cf14849
I0714 09:26:50.711694       1 cache.go:1363] There are <0> Jobs, <1> Queues and <5> Nodes in total for scheduling.
I0714 09:26:50.711885       1 session.go:190] Open Session 0b7473f6-8aa4-48e3-b7d2-5b22460d1d17 with <0> Job and <1> Queues
I0714 09:26:50.713877       1 enqueue.go:79] Try to enqueue PodGroup to 0 Queues
I0714 09:26:50.713954       1 allocate.go:64] Try to allocate resource to 0 Queues
I0714 09:26:50.714189       1 session.go:244] Close Session 0b7473f6-8aa4-48e3-b7d2-5b22460d1d17
W0714 09:26:50.831008       1 event_handlers.go:181] Not support non-csi pvc.
I0714 09:26:50.831131       1 event_handlers.go:387] Added pod <default/yolo-pos> into cache.
W0714 09:26:50.855942       1 event_handlers.go:181] Not support non-csi pvc.
I0714 09:26:51.717358       1 cache.go:1363] There are <1> Jobs, <1> Queues and <5> Nodes in total for scheduling.
I0714 09:26:51.717537       1 session.go:190] Open Session 3c5cafb5-e0d6-4df8-8692-ff1609146be5 with <1> Job and <1> Queues
I0714 09:26:51.719810       1 enqueue.go:79] Try to enqueue PodGroup to 1 Queues
I0714 09:26:51.720069       1 allocate.go:64] Try to allocate resource to 1 Queues
I0714 09:26:51.720128       1 allocate.go:129] Try to allocate resource to Jobs in Queue <default>
I0714 09:26:51.720177       1 allocate.go:161] Try to allocate resource to 1 tasks of Job <default/podgroup-fcfcd1f0-171f-42e4-9964-23323c80edc7>
I0714 09:26:51.720226       1 allocate.go:181] There are <5> nodes for Job <default/podgroup-fcfcd1f0-171f-42e4-9964-23323c80edc7>
I0714 09:26:51.720569       1 predicate_helper.go:75] Predicates failed: task default/yolo-pos on node gpu-master fit failed: Insufficient nvidia.com/gpu
I0714 09:26:51.720974       1 predicate_helper.go:75] Predicates failed: task default/yolo-pos on node gpuorin4-desktop fit failed: plugin NodeAffinity predicates failed node(s) didn't match Pod's node affinity/selector
I0714 09:26:51.721101       1 predicate_helper.go:75] Predicates failed: task default/yolo-pos on node gpuorin5-desktop fit failed: plugin NodeAffinity predicates failed node(s) didn't match Pod's node affinity/selector
I0714 09:26:51.721983       1 allocate.go:249] Binding Task <default/yolo-pos> to node <gpu-orin2>
I0714 09:26:51.722233       1 statement.go:266] After allocated Task <default/yolo-pos> to Node <gpu-orin2>: idle <cpu 5900.00, memory 7832690688.00, hugepages-2Mi 0.00, hugepages-64Ki 0.00, nvidia.com/gpu 2000.00, pods 103.00, ephemeral-storage 225118140453000.00, hugepages-1Gi 0.00, hugepages-32Mi 0.00>, used <cpu 100.00, memory 52428800.00, nvidia.com/gpu 3000.00, pods 7.00>, releasing <cpu 0.00, memory 0.00>
I0714 09:26:51.722684       1 statement.go:284] Allocating operations ...
I0714 09:26:51.722803       1 statement.go:378] Committing operations ...
I0714 09:26:51.722926       1 proportion.go:302] Queue <default>: deserved <cpu 0.00, memory 0.00, pods 1.00, nvidia.com/gpu 1000.00>, allocated <cpu 0.00, memory 0.00, nvidia.com/gpu 1000.00, pods 1.00>, share <1>
I0714 09:26:51.722995       1 allocate.go:125] Queue <default> is overused, ignore it.
I0714 09:26:51.736750       1 session.go:244] Close Session 3c5cafb5-e0d6-4df8-8692-ff1609146be5
I0714 09:26:51.750032       1 cache.go:900] bind ok, latency 9.029104ms
W0714 09:26:51.753173       1 event_handlers.go:181] Not support non-csi pvc.
W0714 09:26:51.789974       1 event_handlers.go:181] Not support non-csi pvc.
W0714 09:26:52.015431       1 event_handlers.go:181] Not support non-csi pvc.
I0714 09:26:52.025317       1 event_handlers.go:442] Deleted pod <default/yolo-pos> from cache.
I0714 09:26:52.033985       1 cache.go:1013] Try to delete Job <default/podgroup-fcfcd1f0-171f-42e4-9964-23323c80edc7:default/podgroup-fcfcd1f0-171f-42e4-9964-23323c80edc7>
I0714 09:26:52.034212       1 cache.go:1054] Job <default/podgroup-fcfcd1f0-171f-42e4-9964-23323c80edc7:default/podgroup-fcfcd1f0-171f-42e4-9964-23323c80edc7> was deleted.
W0714 09:26:52.154614       1 event_handlers.go:181] Not support non-csi pvc.
I0714 09:26:52.154735       1 event_handlers.go:387] Added pod <default/yolo-pos> into cache.
W0714 09:26:52.181591       1 event_handlers.go:181] Not support non-csi pvc.
I0714 09:26:52.739707       1 cache.go:1363] There are <0> Jobs, <1> Queues and <5> Nodes in total for scheduling.
I0714 09:26:52.739878       1 session.go:190] Open Session d954a2ea-1c08-42ca-a79c-b2792f3666ce with <0> Job and <1> Queues
I0714 09:26:52.741890       1 enqueue.go:79] Try to enqueue PodGroup to 0 Queues
I0714 09:26:52.741977       1 allocate.go:64] Try to allocate resource to 0 Queues
I0714 09:26:52.742202       1 session.go:244] Close Session d954a2ea-1c08-42ca-a79c-b2792f3666ce
I0714 09:26:53.744634       1 cache.go:1363] There are <0> Jobs, <1> Queues and <5> Nodes in total for scheduling.
I0714 09:26:53.744789       1 session.go:190] Open Session a01fadd9-5876-46ee-843b-cf86eafc2aca with <0> Job and <1> Queues
I0714 09:26:53.746766       1 enqueue.go:79] Try to enqueue PodGroup to 0 Queues
I0714 09:26:53.746845       1 allocate.go:64] Try to allocate resource to 0 Queues
I0714 09:26:53.747083       1 session.go:244] Close Session a01fadd9-5876-46ee-843b-cf86eafc2aca
I0714 09:26:54.749462       1 cache.go:1363] There are <0> Jobs, <1> Queues and <5> Nodes in total for scheduling.
I0714 09:26:54.749644       1 session.go:190] Open Session e356721e-850e-4470-bee6-d323d3c461d4 with <0> Job and <1> Queues
I0714 09:26:54.751472       1 enqueue.go:79] Try to enqueue PodGroup to 0 Queues
I0714 09:26:54.751549       1 allocate.go:64] Try to allocate resource to 0 Queues
I0714 09:26:54.751783       1 session.go:244] Close Session e356721e-850e-4470-bee6-d323d3c461d4
W0714 09:26:54.901250       1 event_handlers.go:181] Not support non-csi pvc.
I0714 09:26:55.754854       1 cache.go:1363] There are <0> Jobs, <1> Queues and <5> Nodes in total for scheduling.
I0714 09:26:55.755047       1 session.go:190] Open Session 6710bd24-42f2-4b0c-82cb-7ccea93ff9f5 with <0> Job and <1> Queues
I0714 09:26:55.758711       1 enqueue.go:79] Try to enqueue PodGroup to 0 Queues
I0714 09:26:55.758854       1 allocate.go:64] Try to allocate resource to 0 Queues
I0714 09:26:55.759151       1 session.go:244] Close Session 6710bd24-42f2-4b0c-82cb-7ccea93ff9f5
I0714 09:26:56.762390       1 cache.go:1363] There are <0> Jobs, <1> Queues and <5> Nodes in total for scheduling.
I0714 09:26:56.762576       1 session.go:190] Open Session ed563c8e-2b08-448f-acb5-cd97263e5ce0 with <0> Job and <1> Queues
I0714 09:26:56.764593       1 enqueue.go:79] Try to enqueue PodGroup to 0 Queues
I0714 09:26:56.764681       1 allocate.go:64] Try to allocate resource to 0 Queues
I0714 09:26:56.764902       1 session.go:244] Close Session ed563c8e-2b08-448f-acb5-cd97263e5ce0
I0714 09:26:57.767997       1 cache.go:1363] There are <0> Jobs, <1> Queues and <5> Nodes in total for scheduling.
I0714 09:26:57.768183       1 session.go:190] Open Session 893b81a4-13fd-4c70-a6a4-f44c152b02b7 with <0> Job and <1> Queues
I0714 09:26:57.770404       1 enqueue.go:79] Try to enqueue PodGroup to 0 Queues
I0714 09:26:57.770489       1 allocate.go:64] Try to allocate resource to 0 Queues
I0714 09:26:57.770708       1 session.go:244] Close Session 893b81a4-13fd-4c70-a6a4-f44c152b02b7
I0714 09:26:58.773206       1 cache.go:1363] There are <0> Jobs, <1> Queues and <5> Nodes in total for scheduling.
I0714 09:26:58.773355       1 session.go:190] Open Session 2b32ebed-4752-4581-9360-bc63a518d418 with <0> Job and <1> Queues
I0714 09:26:58.775299       1 enqueue.go:79] Try to enqueue PodGroup to 0 Queues
I0714 09:26:58.775370       1 allocate.go:64] Try to allocate resource to 0 Queues
I0714 09:26:58.775571       1 session.go:244] Close Session 2b32ebed-4752-4581-9360-bc63a518d418
I0714 09:26:59.778035       1 cache.go:1363] There are <0> Jobs, <1> Queues and <5> Nodes in total for scheduling.
I0714 09:26:59.778251       1 session.go:190] Open Session 77ecc40e-1e6f-4617-9904-dae7bc880f22 with <0> Job and <1> Queues
I0714 09:26:59.780253       1 enqueue.go:79] Try to enqueue PodGroup to 0 Queues
I0714 09:26:59.780357       1 allocate.go:64] Try to allocate resource to 0 Queues
I0714 09:26:59.780579       1 session.go:244] Close Session 77ecc40e-1e6f-4617-9904-dae7bc880f22
I0714 09:27:00.782892       1 cache.go:1363] There are <0> Jobs, <1> Queues and <5> Nodes in total for scheduling.
I0714 09:27:00.783083       1 session.go:190] Open Session f2ff0c7d-044b-4ff3-b943-dfeec4927f06 with <0> Job and <1> Queues
I0714 09:27:00.785001       1 enqueue.go:79] Try to enqueue PodGroup to 0 Queues
I0714 09:27:00.785080       1 allocate.go:64] Try to allocate resource to 0 Queues
I0714 09:27:00.785316       1 session.go:244] Close Session f2ff0c7d-044b-4ff3-b943-dfeec4927f06
I0714 09:27:01.787940       1 cache.go:1363] There are <0> Jobs, <1> Queues and <5> Nodes in total for scheduling.
I0714 09:27:01.788109       1 session.go:190] Open Session 80021fe5-2f94-47ee-8b51-6d44a5285aa7 with <0> Job and <1> Queues
I0714 09:27:01.790048       1 enqueue.go:79] Try to enqueue PodGroup to 0 Queues
I0714 09:27:01.790126       1 allocate.go:64] Try to allocate resource to 0 Queues
I0714 09:27:01.790361       1 session.go:244] Close Session 80021fe5-2f94-47ee-8b51-6d44a5285aa7
I0714 09:27:02.793012       1 cache.go:1363] There are <0> Jobs, <1> Queues and <5> Nodes in total for scheduling.
I0714 09:27:02.793177       1 session.go:190] Open Session c1d86dec-28b8-4966-a711-62c27efb2c43 with <0> Job and <1> Queues
I0714 09:27:02.795129       1 enqueue.go:79] Try to enqueue PodGroup to 0 Queues
I0714 09:27:02.795201       1 allocate.go:64] Try to allocate resource to 0 Queues
I0714 09:27:02.795442       1 session.go:244] Close Session c1d86dec-28b8-4966-a711-62c27efb2c43
I0714 09:27:03.797709       1 cache.go:1363] There are <0> Jobs, <1> Queues and <5> Nodes in total for scheduling.
I0714 09:27:03.797855       1 session.go:190] Open Session 9ef5142d-7e96-4255-9820-8f0ced88fd40 with <0> Job and <1> Queues
I0714 09:27:03.799703       1 enqueue.go:79] Try to enqueue PodGroup to 0 Queues
I0714 09:27:03.799773       1 allocate.go:64] Try to allocate resource to 0 Queues
I0714 09:27:03.799996       1 session.go:244] Close Session 9ef5142d-7e96-4255-9820-8f0ced88fd40
I0714 09:27:04.802307       1 cache.go:1363] There are <0> Jobs, <1> Queues and <5> Nodes in total for scheduling.
I0714 09:27:04.802497       1 session.go:190] Open Session 10b57311-3d02-4c60-8dfb-d48c6c943bf0 with <0> Job and <1> Queues
I0714 09:27:04.804751       1 enqueue.go:79] Try to enqueue PodGroup to 0 Queues
I0714 09:27:04.804837       1 allocate.go:64] Try to allocate resource to 0 Queues
I0714 09:27:04.805062       1 session.go:244] Close Session 10b57311-3d02-4c60-8dfb-d48c6c943bf0
I0714 09:27:05.807890       1 cache.go:1363] There are <0> Jobs, <1> Queues and <5> Nodes in total for scheduling.
I0714 09:27:05.808074       1 session.go:190] Open Session 8b535641-8fa0-4df6-b7f1-4f9672035d28 with <0> Job and <1> Queues
I0714 09:27:05.809988       1 enqueue.go:79] Try to enqueue PodGroup to 0 Queues
I0714 09:27:05.810066       1 allocate.go:64] Try to allocate resource to 0 Queues
I0714 09:27:05.810295       1 session.go:244] Close Session 8b535641-8fa0-4df6-b7f1-4f9672035d28
I0714 09:27:06.666845       1 cache.go:1489] The metrics type is not set in the volcano scheduler configmap file. As a result, the CPU and memory load information of the node is not collected.
I0714 09:27:06.813220       1 cache.go:1363] There are <0> Jobs, <1> Queues and <5> Nodes in total for scheduling.
I0714 09:27:06.813389       1 session.go:190] Open Session 1cfac350-8457-4d5d-a225-6a94665434a8 with <0> Job and <1> Queues
I0714 09:27:06.815244       1 enqueue.go:79] Try to enqueue PodGroup to 0 Queues
I0714 09:27:06.815321       1 allocate.go:64] Try to allocate resource to 0 Queues
I0714 09:27:06.815547       1 session.go:244] Close Session 1cfac350-8457-4d5d-a225-6a94665434a8
I0714 09:27:07.818393       1 cache.go:1363] There are <0> Jobs, <1> Queues and <5> Nodes in total for scheduling.
I0714 09:27:07.818564       1 session.go:190] Open Session 5a0bd390-6399-4364-b90a-15ae36200861 with <0> Job and <1> Queues
I0714 09:27:07.820651       1 enqueue.go:79] Try to enqueue PodGroup to 0 Queues
I0714 09:27:07.820729       1 allocate.go:64] Try to allocate resource to 0 Queues
I0714 09:27:07.820964       1 session.go:244] Close Session 5a0bd390-6399-4364-b90a-15ae36200861
I0714 09:27:08.823472       1 cache.go:1363] There are <0> Jobs, <1> Queues and <5> Nodes in total for scheduling.
I0714 09:27:08.823635       1 session.go:190] Open Session 5ca7b199-4322-4015-bad4-481ad1678b4f with <0> Job and <1> Queues
I0714 09:27:08.825641       1 enqueue.go:79] Try to enqueue PodGroup to 0 Queues
I0714 09:27:08.825722       1 allocate.go:64] Try to allocate resource to 0 Queues
I0714 09:27:08.825942       1 session.go:244] Close Session 5ca7b199-4322-4015-bad4-481ad1678b4f
I0714 09:27:09.828843       1 cache.go:1363] There are <0> Jobs, <1> Queues and <5> Nodes in total for scheduling.
I0714 09:27:09.829027       1 session.go:190] Open Session 74560429-40b7-481d-93b7-0fe0f2390cac with <0> Job and <1> Queues
I0714 09:27:09.830967       1 enqueue.go:79] Try to enqueue PodGroup to 0 Queues
I0714 09:27:09.831065       1 allocate.go:64] Try to allocate resource to 0 Queues
I0714 09:27:09.831578       1 session.go:244] Close Session 74560429-40b7-481d-93b7-0fe0f2390cac
I0714 09:27:10.833771       1 cache.go:1363] There are <0> Jobs, <1> Queues and <5> Nodes in total for scheduling.
I0714 09:27:10.833948       1 session.go:190] Open Session 90133c22-8ae0-4bd7-b32c-d5f87e6368e3 with <0> Job and <1> Queues
I0714 09:27:10.836485       1 enqueue.go:79] Try to enqueue PodGroup to 0 Queues
I0714 09:27:10.836575       1 allocate.go:64] Try to allocate resource to 0 Queues
I0714 09:27:10.836806       1 session.go:244] Close Session 90133c22-8ae0-4bd7-b32c-d5f87e6368e3
I0714 09:27:11.839197       1 cache.go:1363] There are <0> Jobs, <1> Queues and <5> Nodes in total for scheduling.
I0714 09:27:11.839365       1 session.go:190] Open Session ceafbfb2-27cb-4d4a-89c3-ec63915d1010 with <0> Job and <1> Queues
I0714 09:27:11.841350       1 enqueue.go:79] Try to enqueue PodGroup to 0 Queues
I0714 09:27:11.841428       1 allocate.go:64] Try to allocate resource to 0 Queues
I0714 09:27:11.841638       1 session.go:244] Close Session ceafbfb2-27cb-4d4a-89c3-ec63915d1010
I0714 09:27:12.844711       1 cache.go:1363] There are <0> Jobs, <1> Queues and <5> Nodes in total for scheduling.
I0714 09:27:12.844870       1 session.go:190] Open Session cfa6202f-0520-426a-811c-fc253ed4f046 with <0> Job and <1> Queues
I0714 09:27:12.847019       1 enqueue.go:79] Try to enqueue PodGroup to 0 Queues
I0714 09:27:12.847097       1 allocate.go:64] Try to allocate resource to 0 Queues
I0714 09:27:12.847333       1 session.go:244] Close Session cfa6202f-0520-426a-811c-fc253ed4f046
I0714 09:27:13.850259       1 cache.go:1363] There are <0> Jobs, <1> Queues and <5> Nodes in total for scheduling.
I0714 09:27:13.850410       1 session.go:190] Open Session edd6c321-e891-45c7-aa0d-d184b8aaf9ae with <0> Job and <1> Queues
I0714 09:27:13.852512       1 enqueue.go:79] Try to enqueue PodGroup to 0 Queues
I0714 09:27:13.852590       1 allocate.go:64] Try to allocate resource to 0 Queues
I0714 09:27:13.852812       1 session.go:244] Close Session edd6c321-e891-45c7-aa0d-d184b8aaf9ae
I0714 09:27:14.855224       1 cache.go:1363] There are <0> Jobs, <1> Queues and <5> Nodes in total for scheduling.
I0714 09:27:14.855402       1 session.go:190] Open Session 42d92d5e-0f10-4ab7-b82f-77443c8343a1 with <0> Job and <1> Queues
I0714 09:27:14.857377       1 enqueue.go:79] Try to enqueue PodGroup to 0 Queues
I0714 09:27:14.857461       1 allocate.go:64] Try to allocate resource to 0 Queues
I0714 09:27:14.857652       1 session.go:244] Close Session 42d92d5e-0f10-4ab7-b82f-77443c8343a1
I0714 09:27:15.859937       1 cache.go:1363] There are <0> Jobs, <1> Queues and <5> Nodes in total for scheduling.
I0714 09:27:15.860089       1 session.go:190] Open Session e78fb585-dc9b-4c5b-b42b-c52a872510fa with <0> Job and <1> Queues
I0714 09:27:15.862135       1 enqueue.go:79] Try to enqueue PodGroup to 0 Queues
I0714 09:27:15.862217       1 allocate.go:64] Try to allocate resource to 0 Queues
I0714 09:27:15.862448       1 session.go:244] Close Session e78fb585-dc9b-4c5b-b42b-c52a872510fa
I0714 09:27:16.865652       1 cache.go:1363] There are <0> Jobs, <1> Queues and <5> Nodes in total for scheduling.
I0714 09:27:16.865849       1 session.go:190] Open Session d3b632c9-d788-4cc9-a3b0-22ba5747fa3d with <0> Job and <1> Queues
I0714 09:27:16.868198       1 enqueue.go:79] Try to enqueue PodGroup to 0 Queues
I0714 09:27:16.868276       1 allocate.go:64] Try to allocate resource to 0 Queues
I0714 09:27:16.868586       1 session.go:244] Close Session d3b632c9-d788-4cc9-a3b0-22ba5747fa3d
I0714 09:27:17.871017       1 cache.go:1363] There are <0> Jobs, <1> Queues and <5> Nodes in total for scheduling.
I0714 09:27:17.871183       1 session.go:190] Open Session 71e9c2b5-dea3-4430-a124-c2a6aa733e8b with <0> Job and <1> Queues
I0714 09:27:17.873127       1 enqueue.go:79] Try to enqueue PodGroup to 0 Queues
I0714 09:27:17.873203       1 allocate.go:64] Try to allocate resource to 0 Queues
I0714 09:27:17.873422       1 session.go:244] Close Session 71e9c2b5-dea3-4430-a124-c2a6aa733e8b
I0714 09:27:18.875574       1 cache.go:1363] There are <0> Jobs, <1> Queues and <5> Nodes in total for scheduling.
I0714 09:27:18.875744       1 session.go:190] Open Session 9c5667cb-6d29-4f7c-bd8d-961a33467791 with <0> Job and <1> Queues
I0714 09:27:18.877717       1 enqueue.go:79] Try to enqueue PodGroup to 0 Queues
I0714 09:27:18.877792       1 allocate.go:64] Try to allocate resource to 0 Queues
I0714 09:27:18.878033       1 session.go:244] Close Session 9c5667cb-6d29-4f7c-bd8d-961a33467791
I0714 09:27:19.880944       1 cache.go:1363] There are <0> Jobs, <1> Queues and <5> Nodes in total for scheduling.
I0714 09:27:19.881126       1 session.go:190] Open Session 38de0347-b4ef-4124-9fc3-2d3ae80a94d4 with <0> Job and <1> Queues
I0714 09:27:19.883118       1 enqueue.go:79] Try to enqueue PodGroup to 0 Queues
I0714 09:27:19.883194       1 allocate.go:64] Try to allocate resource to 0 Queues
I0714 09:27:19.883420       1 session.go:244] Close Session 38de0347-b4ef-4124-9fc3-2d3ae80a94d4
I0714 09:27:20.886672       1 cache.go:1363] There are <0> Jobs, <1> Queues and <5> Nodes in total for scheduling.
I0714 09:27:20.886842       1 session.go:190] Open Session 2125dc8c-6042-4839-a819-f277e63b2e70 with <0> Job and <1> Queues
I0714 09:27:20.888777       1 enqueue.go:79] Try to enqueue PodGroup to 0 Queues
I0714 09:27:20.888848       1 allocate.go:64] Try to allocate resource to 0 Queues
I0714 09:27:20.889071       1 session.go:244] Close Session 2125dc8c-6042-4839-a819-f277e63b2e70
I0714 09:27:21.891406       1 cache.go:1363] There are <0> Jobs, <1> Queues and <5> Nodes in total for scheduling.
I0714 09:27:21.891582       1 session.go:190] Open Session 9d07acf4-7c3d-4c73-b116-800e1e147c44 with <0> Job and <1> Queues
I0714 09:27:21.893572       1 enqueue.go:79] Try to enqueue PodGroup to 0 Queues
I0714 09:27:21.893641       1 allocate.go:64] Try to allocate resource to 0 Queues
I0714 09:27:21.893874       1 session.go:244] Close Session 9d07acf4-7c3d-4c73-b116-800e1e147c44
I0714 09:27:22.896842       1 cache.go:1363] There are <0> Jobs, <1> Queues and <5> Nodes in total for scheduling.
I0714 09:27:22.897013       1 session.go:190] Open Session 29633870-ab08-4a8f-8dde-983208d02987 with <0> Job and <1> Queues
I0714 09:27:22.899016       1 enqueue.go:79] Try to enqueue PodGroup to 0 Queues
I0714 09:27:22.899094       1 allocate.go:64] Try to allocate resource to 0 Queues
I0714 09:27:22.899313       1 session.go:244] Close Session 29633870-ab08-4a8f-8dde-983208d02987
I0714 09:27:23.901823       1 cache.go:1363] There are <0> Jobs, <1> Queues and <5> Nodes in total for scheduling.
I0714 09:27:23.901983       1 session.go:190] Open Session 6412c50e-ba78-494e-9036-7ca15bdfb532 with <0> Job and <1> Queues
I0714 09:27:23.903805       1 enqueue.go:79] Try to enqueue PodGroup to 0 Queues
I0714 09:27:23.903871       1 allocate.go:64] Try to allocate resource to 0 Queues
I0714 09:27:23.904101       1 session.go:244] Close Session 6412c50e-ba78-494e-9036-7ca15bdfb532
I0714 09:27:24.906440       1 cache.go:1363] There are <0> Jobs, <1> Queues and <5> Nodes in total for scheduling.
I0714 09:27:24.906611       1 session.go:190] Open Session c72a99d8-3abf-4f86-908e-fb92195b0e2e with <0> Job and <1> Queues
I0714 09:27:24.908727       1 enqueue.go:79] Try to enqueue PodGroup to 0 Queues
I0714 09:27:24.908802       1 allocate.go:64] Try to allocate resource to 0 Queues
I0714 09:27:24.909034       1 session.go:244] Close Session c72a99d8-3abf-4f86-908e-fb92195b0e2e
I0714 09:27:25.911554       1 cache.go:1363] There are <0> Jobs, <1> Queues and <5> Nodes in total for scheduling.
I0714 09:27:25.911697       1 session.go:190] Open Session c417c6c6-dc8a-4288-81b4-ef05350e85a3 with <0> Job and <1> Queues
I0714 09:27:25.913895       1 enqueue.go:79] Try to enqueue PodGroup to 0 Queues
I0714 09:27:25.913959       1 allocate.go:64] Try to allocate resource to 0 Queues
I0714 09:27:25.914183       1 session.go:244] Close Session c417c6c6-dc8a-4288-81b4-ef05350e85a3
I0714 09:27:26.916800       1 cache.go:1363] There are <0> Jobs, <1> Queues and <5> Nodes in total for scheduling.
I0714 09:27:26.916990       1 session.go:190] Open Session 21a1d65e-aa71-414f-a4c8-c5bf86df0b09 with <0> Job and <1> Queues
I0714 09:27:26.918985       1 enqueue.go:79] Try to enqueue PodGroup to 0 Queues
I0714 09:27:26.919058       1 allocate.go:64] Try to allocate resource to 0 Queues
I0714 09:27:26.919293       1 session.go:244] Close Session 21a1d65e-aa71-414f-a4c8-c5bf86df0b09
I0714 09:27:27.921447       1 cache.go:1363] There are <0> Jobs, <1> Queues and <5> Nodes in total for scheduling.
I0714 09:27:27.921621       1 session.go:190] Open Session 7062a902-39af-454f-8e26-905f059c4370 with <0> Job and <1> Queues
I0714 09:27:27.923506       1 enqueue.go:79] Try to enqueue PodGroup to 0 Queues
I0714 09:27:27.923586       1 allocate.go:64] Try to allocate resource to 0 Queues
I0714 09:27:27.923831       1 session.go:244] Close Session 7062a902-39af-454f-8e26-905f059c4370
I0714 09:27:28.926680       1 cache.go:1363] There are <0> Jobs, <1> Queues and <5> Nodes in total for scheduling.
I0714 09:27:28.926851       1 session.go:190] Open Session 3f72ae67-21cf-4110-aeb9-e17979279d37 with <0> Job and <1> Queues
I0714 09:27:28.928946       1 enqueue.go:79] Try to enqueue PodGroup to 0 Queues
I0714 09:27:28.929036       1 allocate.go:64] Try to allocate resource to 0 Queues
I0714 09:27:28.929263       1 session.go:244] Close Session 3f72ae67-21cf-4110-aeb9-e17979279d37
I0714 09:27:29.931981       1 cache.go:1363] There are <0> Jobs, <1> Queues and <5> Nodes in total for scheduling.
I0714 09:27:29.932181       1 session.go:190] Open Session aec3edd8-a962-4679-80c9-e562929a39a8 with <0> Job and <1> Queues
I0714 09:27:29.934112       1 enqueue.go:79] Try to enqueue PodGroup to 0 Queues
I0714 09:27:29.934191       1 allocate.go:64] Try to allocate resource to 0 Queues
I0714 09:27:29.934444       1 session.go:244] Close Session aec3edd8-a962-4679-80c9-e562929a39a8
I0714 09:27:30.936856       1 cache.go:1363] There are <0> Jobs, <1> Queues and <5> Nodes in total for scheduling.
I0714 09:27:30.937002       1 session.go:190] Open Session 687c3b23-4b14-44e2-b70d-763d41b7709f with <0> Job and <1> Queues
I0714 09:27:30.938845       1 enqueue.go:79] Try to enqueue PodGroup to 0 Queues
I0714 09:27:30.938911       1 allocate.go:64] Try to allocate resource to 0 Queues
I0714 09:27:30.939126       1 session.go:244] Close Session 687c3b23-4b14-44e2-b70d-763d41b7709f
I0714 09:27:31.941908       1 cache.go:1363] There are <0> Jobs, <1> Queues and <5> Nodes in total for scheduling.
I0714 09:27:31.942056       1 session.go:190] Open Session a04f467a-e2c3-4fec-9337-442c7bbc4ce8 with <0> Job and <1> Queues
I0714 09:27:31.943993       1 enqueue.go:79] Try to enqueue PodGroup to 0 Queues
I0714 09:27:31.944074       1 allocate.go:64] Try to allocate resource to 0 Queues
I0714 09:27:31.944330       1 session.go:244] Close Session a04f467a-e2c3-4fec-9337-442c7bbc4ce8
I0714 09:27:32.947019       1 cache.go:1363] There are <0> Jobs, <1> Queues and <5> Nodes in total for scheduling.
I0714 09:27:32.947189       1 session.go:190] Open Session 10493575-14a4-4154-bc2f-8630b7344d6f with <0> Job and <1> Queues
I0714 09:27:32.949104       1 enqueue.go:79] Try to enqueue PodGroup to 0 Queues
I0714 09:27:32.949176       1 allocate.go:64] Try to allocate resource to 0 Queues
I0714 09:27:32.949404       1 session.go:244] Close Session 10493575-14a4-4154-bc2f-8630b7344d6f
I0714 09:27:33.951684       1 cache.go:1363] There are <0> Jobs, <1> Queues and <5> Nodes in total for scheduling.
I0714 09:27:33.951838       1 session.go:190] Open Session 7d8d23ef-0516-4c68-b697-ef943ed6dafd with <0> Job and <1> Queues
I0714 09:27:33.953736       1 enqueue.go:79] Try to enqueue PodGroup to 0 Queues
I0714 09:27:33.953812       1 allocate.go:64] Try to allocate resource to 0 Queues
I0714 09:27:33.954029       1 session.go:244] Close Session 7d8d23ef-0516-4c68-b697-ef943ed6dafd
I0714 09:27:34.956918       1 cache.go:1363] There are <0> Jobs, <1> Queues and <5> Nodes in total for scheduling.
I0714 09:27:34.957100       1 session.go:190] Open Session f9320e31-0585-4653-8d1e-f087841d132f with <0> Job and <1> Queues
I0714 09:27:34.958968       1 enqueue.go:79] Try to enqueue PodGroup to 0 Queues
I0714 09:27:34.959049       1 allocate.go:64] Try to allocate resource to 0 Queues
I0714 09:27:34.959267       1 session.go:244] Close Session f9320e31-0585-4653-8d1e-f087841d132f
I0714 09:27:35.961719       1 cache.go:1363] There are <0> Jobs, <1> Queues and <5> Nodes in total for scheduling.
I0714 09:27:35.961888       1 session.go:190] Open Session 004743cd-a5ce-4904-b761-7219705b7502 with <0> Job and <1> Queues
I0714 09:27:35.963769       1 enqueue.go:79] Try to enqueue PodGroup to 0 Queues
I0714 09:27:35.963840       1 allocate.go:64] Try to allocate resource to 0 Queues
I0714 09:27:35.964062       1 session.go:244] Close Session 004743cd-a5ce-4904-b761-7219705b7502
I0714 09:27:36.667641       1 cache.go:1489] The metrics type is not set in the volcano scheduler configmap file. As a result, the CPU and memory load information of the node is not collected.
I0714 09:27:36.966879       1 cache.go:1363] There are <0> Jobs, <1> Queues and <5> Nodes in total for scheduling.
I0714 09:27:36.967033       1 session.go:190] Open Session 378833ff-cd3d-450f-9cff-532357c78347 with <0> Job and <1> Queues
I0714 09:27:36.968967       1 enqueue.go:79] Try to enqueue PodGroup to 0 Queues
I0714 09:27:36.969045       1 allocate.go:64] Try to allocate resource to 0 Queues
I0714 09:27:36.969257       1 session.go:244] Close Session 378833ff-cd3d-450f-9cff-532357c78347
I0714 09:27:37.971471       1 cache.go:1363] There are <0> Jobs, <1> Queues and <5> Nodes in total for scheduling.
I0714 09:27:37.971648       1 session.go:190] Open Session 69d034b6-efb7-4af3-b7a5-20ce251f8dfe with <0> Job and <1> Queues
I0714 09:27:37.973584       1 enqueue.go:79] Try to enqueue PodGroup to 0 Queues
I0714 09:27:37.973666       1 allocate.go:64] Try to allocate resource to 0 Queues
I0714 09:27:37.973896       1 session.go:244] Close Session 69d034b6-efb7-4af3-b7a5-20ce251f8dfe
I0714 09:27:38.976928       1 cache.go:1363] There are <0> Jobs, <1> Queues and <5> Nodes in total for scheduling.
I0714 09:27:38.977083       1 session.go:190] Open Session f8aae572-6470-4431-9b4e-3b5d2fca77f6 with <0> Job and <1> Queues
I0714 09:27:38.978915       1 enqueue.go:79] Try to enqueue PodGroup to 0 Queues
I0714 09:27:38.978985       1 allocate.go:64] Try to allocate resource to 0 Queues
I0714 09:27:38.979212       1 session.go:244] Close Session f8aae572-6470-4431-9b4e-3b5d2fca77f6
I0714 09:27:39.982215       1 cache.go:1363] There are <0> Jobs, <1> Queues and <5> Nodes in total for scheduling.
I0714 09:27:39.982387       1 session.go:190] Open Session 44227a4b-5151-4724-a292-783de65bb355 with <0> Job and <1> Queues
I0714 09:27:39.984350       1 enqueue.go:79] Try to enqueue PodGroup to 0 Queues
I0714 09:27:39.984423       1 allocate.go:64] Try to allocate resource to 0 Queues
I0714 09:27:39.984640       1 session.go:244] Close Session 44227a4b-5151-4724-a292-783de65bb355
I0714 09:27:40.987805       1 cache.go:1363] There are <0> Jobs, <1> Queues and <5> Nodes in total for scheduling.
I0714 09:27:40.987954       1 session.go:190] Open Session d24215be-6946-4d47-aae2-e60f0355fc35 with <0> Job and <1> Queues
I0714 09:27:40.989895       1 enqueue.go:79] Try to enqueue PodGroup to 0 Queues
I0714 09:27:40.989973       1 allocate.go:64] Try to allocate resource to 0 Queues
I0714 09:27:40.990182       1 session.go:244] Close Session d24215be-6946-4d47-aae2-e60f0355fc35
I0714 09:27:41.993305       1 cache.go:1363] There are <0> Jobs, <1> Queues and <5> Nodes in total for scheduling.
I0714 09:27:41.993489       1 session.go:190] Open Session df3f5417-1720-4a6e-b8ff-70111e583da5 with <0> Job and <1> Queues
I0714 09:27:41.995326       1 enqueue.go:79] Try to enqueue PodGroup to 0 Queues
I0714 09:27:41.995394       1 allocate.go:64] Try to allocate resource to 0 Queues
I0714 09:27:41.995626       1 session.go:244] Close Session df3f5417-1720-4a6e-b8ff-70111e583da5
I0714 09:27:42.997916       1 cache.go:1363] There are <0> Jobs, <1> Queues and <5> Nodes in total for scheduling.
I0714 09:27:42.998097       1 session.go:190] Open Session a07ad837-9aa6-4c91-b09a-320a4e3995b1 with <0> Job and <1> Queues
I0714 09:27:42.999984       1 enqueue.go:79] Try to enqueue PodGroup to 0 Queues
I0714 09:27:43.000052       1 allocate.go:64] Try to allocate resource to 0 Queues
I0714 09:27:43.000261       1 session.go:244] Close Session a07ad837-9aa6-4c91-b09a-320a4e3995b1
I0714 09:27:44.003232       1 cache.go:1363] There are <0> Jobs, <1> Queues and <5> Nodes in total for scheduling.
I0714 09:27:44.003385       1 session.go:190] Open Session 12e9af7e-b53a-460b-a38d-d1867cdfa85a with <0> Job and <1> Queues
I0714 09:27:44.005268       1 enqueue.go:79] Try to enqueue PodGroup to 0 Queues
I0714 09:27:44.005346       1 allocate.go:64] Try to allocate resource to 0 Queues
I0714 09:27:44.005537       1 session.go:244] Close Session 12e9af7e-b53a-460b-a38d-d1867cdfa85a
I0714 09:27:45.008519       1 cache.go:1363] There are <0> Jobs, <1> Queues and <5> Nodes in total for scheduling.
I0714 09:27:45.008690       1 session.go:190] Open Session 8a0bb1d3-20ff-4a05-b218-0583020ad5ef with <0> Job and <1> Queues
I0714 09:27:45.010662       1 enqueue.go:79] Try to enqueue PodGroup to 0 Queues
I0714 09:27:45.010730       1 allocate.go:64] Try to allocate resource to 0 Queues
I0714 09:27:45.010932       1 session.go:244] Close Session 8a0bb1d3-20ff-4a05-b218-0583020ad5ef
I0714 09:27:46.013323       1 cache.go:1363] There are <0> Jobs, <1> Queues and <5> Nodes in total for scheduling.
I0714 09:27:46.013460       1 session.go:190] Open Session 20faa487-101f-444b-8a53-64894b2c3fd6 with <0> Job and <1> Queues
I0714 09:27:46.015388       1 enqueue.go:79] Try to enqueue PodGroup to 0 Queues
I0714 09:27:46.015459       1 allocate.go:64] Try to allocate resource to 0 Queues
I0714 09:27:46.015666       1 session.go:244] Close Session 20faa487-101f-444b-8a53-64894b2c3fd6
I0714 09:27:47.018603       1 cache.go:1363] There are <0> Jobs, <1> Queues and <5> Nodes in total for scheduling.
I0714 09:27:47.018767       1 session.go:190] Open Session 3809dc82-8a80-48e0-a21c-92d84c78bf64 with <0> Job and <1> Queues
I0714 09:27:47.020824       1 enqueue.go:79] Try to enqueue PodGroup to 0 Queues
I0714 09:27:47.020900       1 allocate.go:64] Try to allocate resource to 0 Queues
I0714 09:27:47.021150       1 session.go:244] Close Session 3809dc82-8a80-48e0-a21c-92d84c78bf64
I0714 09:27:48.023581       1 cache.go:1363] There are <0> Jobs, <1> Queues and <5> Nodes in total for scheduling.
I0714 09:27:48.023725       1 session.go:190] Open Session c84c08b4-b78a-490e-aa1d-2b750f85e0aa with <0> Job and <1> Queues
I0714 09:27:48.025769       1 enqueue.go:79] Try to enqueue PodGroup to 0 Queues
I0714 09:27:48.025843       1 allocate.go:64] Try to allocate resource to 0 Queues
I0714 09:27:48.026061       1 session.go:244] Close Session c84c08b4-b78a-490e-aa1d-2b750f85e0aa
I0714 09:27:49.028810       1 cache.go:1363] There are <0> Jobs, <1> Queues and <5> Nodes in total for scheduling.
I0714 09:27:49.028986       1 session.go:190] Open Session dc84ec73-9458-4524-9bf2-b11872bfccdd with <0> Job and <1> Queues
I0714 09:27:49.030839       1 enqueue.go:79] Try to enqueue PodGroup to 0 Queues
I0714 09:27:49.030923       1 allocate.go:64] Try to allocate resource to 0 Queues
I0714 09:27:49.031127       1 session.go:244] Close Session dc84ec73-9458-4524-9bf2-b11872bfccdd
I0714 09:27:50.033835       1 cache.go:1363] There are <0> Jobs, <1> Queues and <5> Nodes in total for scheduling.
I0714 09:27:50.034012       1 session.go:190] Open Session 31e606c9-b8db-4d70-ac1e-087c2ddb9676 with <0> Job and <1> Queues
I0714 09:27:50.035948       1 enqueue.go:79] Try to enqueue PodGroup to 0 Queues
I0714 09:27:50.036018       1 allocate.go:64] Try to allocate resource to 0 Queues
I0714 09:27:50.036217       1 session.go:244] Close Session 31e606c9-b8db-4d70-ac1e-087c2ddb9676
W0714 09:27:50.177805       1 event_handlers.go:181] Not support non-csi pvc.
I0714 09:27:50.194267       1 event_handlers.go:442] Deleted pod <default/yolo-cls> from cache.
W0714 09:27:50.258735       1 event_handlers.go:181] Not support non-csi pvc.
I0714 09:27:50.264818       1 event_handlers.go:442] Deleted pod <default/yolo-det> from cache.
W0714 09:27:50.336441       1 event_handlers.go:181] Not support non-csi pvc.
I0714 09:27:50.340688       1 event_handlers.go:442] Deleted pod <default/yolo-seg> from cache.
W0714 09:27:50.401255       1 event_handlers.go:181] Not support non-csi pvc.
I0714 09:27:50.405180       1 event_handlers.go:442] Deleted pod <default/yolo-obb> from cache.
W0714 09:27:50.451304       1 event_handlers.go:181] Not support non-csi pvc.
I0714 09:27:50.463405       1 event_handlers.go:442] Deleted pod <default/yolo-pos> from cache.
I0714 09:27:51.039502       1 cache.go:1363] There are <0> Jobs, <1> Queues and <5> Nodes in total for scheduling.
I0714 09:27:51.039664       1 session.go:190] Open Session b8cd5ecb-192c-40e4-a84b-c3780a553c34 with <0> Job and <1> Queues
I0714 09:27:51.041599       1 enqueue.go:79] Try to enqueue PodGroup to 0 Queues
I0714 09:27:51.041667       1 allocate.go:64] Try to allocate resource to 0 Queues
I0714 09:27:51.041890       1 session.go:244] Close Session b8cd5ecb-192c-40e4-a84b-c3780a553c34
I0714 09:27:52.044721       1 cache.go:1363] There are <0> Jobs, <1> Queues and <5> Nodes in total for scheduling.
I0714 09:27:52.044930       1 session.go:190] Open Session 9745828c-5b7d-47e2-b8c3-6bd10aabec4f with <0> Job and <1> Queues
I0714 09:27:52.046810       1 enqueue.go:79] Try to enqueue PodGroup to 0 Queues
I0714 09:27:52.046885       1 allocate.go:64] Try to allocate resource to 0 Queues
I0714 09:27:52.047102       1 session.go:244] Close Session 9745828c-5b7d-47e2-b8c3-6bd10aabec4f
I0714 09:27:53.049497       1 cache.go:1363] There are <0> Jobs, <1> Queues and <5> Nodes in total for scheduling.
I0714 09:27:53.049682       1 session.go:190] Open Session b545a687-dbbe-48e9-8f8c-68427c85ca46 with <0> Job and <1> Queues
I0714 09:27:53.051457       1 enqueue.go:79] Try to enqueue PodGroup to 0 Queues
I0714 09:27:53.051522       1 allocate.go:64] Try to allocate resource to 0 Queues
I0714 09:27:53.051736       1 session.go:244] Close Session b545a687-dbbe-48e9-8f8c-68427c85ca46
I0714 09:27:54.054553       1 cache.go:1363] There are <0> Jobs, <1> Queues and <5> Nodes in total for scheduling.
I0714 09:27:54.054726       1 session.go:190] Open Session fc96f83c-5b17-4695-9ac8-3cdc696d0c75 with <0> Job and <1> Queues
I0714 09:27:54.056617       1 enqueue.go:79] Try to enqueue PodGroup to 0 Queues
I0714 09:27:54.056688       1 allocate.go:64] Try to allocate resource to 0 Queues
I0714 09:27:54.056890       1 session.go:244] Close Session fc96f83c-5b17-4695-9ac8-3cdc696d0c75
I0714 09:27:55.059186       1 cache.go:1363] There are <0> Jobs, <1> Queues and <5> Nodes in total for scheduling.
I0714 09:27:55.059359       1 session.go:190] Open Session 0ab8b213-851b-44d3-bfcc-f3d7d84f5a05 with <0> Job and <1> Queues
I0714 09:27:55.061228       1 enqueue.go:79] Try to enqueue PodGroup to 0 Queues
I0714 09:27:55.061298       1 allocate.go:64] Try to allocate resource to 0 Queues
I0714 09:27:55.061517       1 session.go:244] Close Session 0ab8b213-851b-44d3-bfcc-f3d7d84f5a05
I0714 09:27:56.064199       1 cache.go:1363] There are <0> Jobs, <1> Queues and <5> Nodes in total for scheduling.
I0714 09:27:56.064379       1 session.go:190] Open Session 9eeee320-3f64-4f78-8d3a-59c5c87ca8d3 with <0> Job and <1> Queues
I0714 09:27:56.066181       1 enqueue.go:79] Try to enqueue PodGroup to 0 Queues
I0714 09:27:56.066242       1 allocate.go:64] Try to allocate resource to 0 Queues
I0714 09:27:56.066443       1 session.go:244] Close Session 9eeee320-3f64-4f78-8d3a-59c5c87ca8d3
I0714 09:27:57.069447       1 cache.go:1363] There are <0> Jobs, <1> Queues and <5> Nodes in total for scheduling.
I0714 09:27:57.069650       1 session.go:190] Open Session c2b1da58-acf5-42d6-b3d8-0e678ea3820d with <0> Job and <1> Queues
I0714 09:27:57.071525       1 enqueue.go:79] Try to enqueue PodGroup to 0 Queues
I0714 09:27:57.071610       1 allocate.go:64] Try to allocate resource to 0 Queues
I0714 09:27:57.071836       1 session.go:244] Close Session c2b1da58-acf5-42d6-b3d8-0e678ea3820d
I0714 09:27:58.074533       1 cache.go:1363] There are <0> Jobs, <1> Queues and <5> Nodes in total for scheduling.
I0714 09:27:58.074693       1 session.go:190] Open Session 0a463fbe-c751-4452-bd30-d0f3466b9928 with <0> Job and <1> Queues
I0714 09:27:58.076686       1 enqueue.go:79] Try to enqueue PodGroup to 0 Queues
I0714 09:27:58.076759       1 allocate.go:64] Try to allocate resource to 0 Queues
I0714 09:27:58.076981       1 session.go:244] Close Session 0a463fbe-c751-4452-bd30-d0f3466b9928
I0714 09:27:59.079158       1 cache.go:1363] There are <0> Jobs, <1> Queues and <5> Nodes in total for scheduling.
I0714 09:27:59.079310       1 session.go:190] Open Session 74c3cb60-ce30-4314-8715-b2c96c5a40e4 with <0> Job and <1> Queues
I0714 09:27:59.081091       1 enqueue.go:79] Try to enqueue PodGroup to 0 Queues
I0714 09:27:59.081155       1 allocate.go:64] Try to allocate resource to 0 Queues
I0714 09:27:59.081345       1 session.go:244] Close Session 74c3cb60-ce30-4314-8715-b2c96c5a40e4
I0714 09:28:00.084446       1 cache.go:1363] There are <0> Jobs, <1> Queues and <5> Nodes in total for scheduling.
I0714 09:28:00.084623       1 session.go:190] Open Session 3d9acdae-1f5f-46e4-85a3-8b067f559162 with <0> Job and <1> Queues
I0714 09:28:00.086435       1 enqueue.go:79] Try to enqueue PodGroup to 0 Queues
I0714 09:28:00.086503       1 allocate.go:64] Try to allocate resource to 0 Queues
I0714 09:28:00.086788       1 session.go:244] Close Session 3d9acdae-1f5f-46e4-85a3-8b067f559162
I0714 09:28:01.089151       1 cache.go:1363] There are <0> Jobs, <1> Queues and <5> Nodes in total for scheduling.
I0714 09:28:01.089313       1 session.go:190] Open Session ae3dcad5-5553-428a-8551-e86a9dfff936 with <0> Job and <1> Queues
I0714 09:28:01.090965       1 enqueue.go:79] Try to enqueue PodGroup to 0 Queues
I0714 09:28:01.091030       1 allocate.go:64] Try to allocate resource to 0 Queues
I0714 09:28:01.091238       1 session.go:244] Close Session ae3dcad5-5553-428a-8551-e86a9dfff936
I0714 09:28:02.093603       1 cache.go:1363] There are <0> Jobs, <1> Queues and <5> Nodes in total for scheduling.
I0714 09:28:02.093792       1 session.go:190] Open Session 74bb67e6-d9e4-4a15-a64a-373fa0cb73ae with <0> Job and <1> Queues
I0714 09:28:02.095577       1 enqueue.go:79] Try to enqueue PodGroup to 0 Queues
I0714 09:28:02.095647       1 allocate.go:64] Try to allocate resource to 0 Queues
I0714 09:28:02.095895       1 session.go:244] Close Session 74bb67e6-d9e4-4a15-a64a-373fa0cb73ae
I0714 09:28:03.098962       1 cache.go:1363] There are <0> Jobs, <1> Queues and <5> Nodes in total for scheduling.
I0714 09:28:03.099162       1 session.go:190] Open Session 6e2526d5-bcbd-4e95-b192-26509865e0e8 with <0> Job and <1> Queues
I0714 09:28:03.100948       1 enqueue.go:79] Try to enqueue PodGroup to 0 Queues
I0714 09:28:03.101018       1 allocate.go:64] Try to allocate resource to 0 Queues
I0714 09:28:03.101225       1 session.go:244] Close Session 6e2526d5-bcbd-4e95-b192-26509865e0e8
I0714 09:28:04.103536       1 cache.go:1363] There are <0> Jobs, <1> Queues and <5> Nodes in total for scheduling.
I0714 09:28:04.103686       1 session.go:190] Open Session 6552e840-7d74-4186-b9dc-7c9715fa5400 with <0> Job and <1> Queues
I0714 09:28:04.105318       1 enqueue.go:79] Try to enqueue PodGroup to 0 Queues
I0714 09:28:04.105373       1 allocate.go:64] Try to allocate resource to 0 Queues
I0714 09:28:04.105573       1 session.go:244] Close Session 6552e840-7d74-4186-b9dc-7c9715fa5400
I0714 09:28:05.107879       1 cache.go:1363] There are <0> Jobs, <1> Queues and <5> Nodes in total for scheduling.
I0714 09:28:05.108051       1 session.go:190] Open Session f1950f88-9b03-4950-97e8-0e860fa96e2d with <0> Job and <1> Queues
I0714 09:28:05.109891       1 enqueue.go:79] Try to enqueue PodGroup to 0 Queues
I0714 09:28:05.109961       1 allocate.go:64] Try to allocate resource to 0 Queues
I0714 09:28:05.110168       1 session.go:244] Close Session f1950f88-9b03-4950-97e8-0e860fa96e2d
I0714 09:28:06.112759       1 cache.go:1363] There are <0> Jobs, <1> Queues and <5> Nodes in total for scheduling.
I0714 09:28:06.112924       1 session.go:190] Open Session 261215c8-87e1-4554-992a-50b0a9545fe0 with <0> Job and <1> Queues
I0714 09:28:06.114845       1 enqueue.go:79] Try to enqueue PodGroup to 0 Queues
I0714 09:28:06.114911       1 allocate.go:64] Try to allocate resource to 0 Queues
I0714 09:28:06.115117       1 session.go:244] Close Session 261215c8-87e1-4554-992a-50b0a9545fe0
I0714 09:28:06.668596       1 cache.go:1489] The metrics type is not set in the volcano scheduler configmap file. As a result, the CPU and memory load information of the node is not collected.
I0714 09:28:07.118374       1 cache.go:1363] There are <0> Jobs, <1> Queues and <5> Nodes in total for scheduling.
I0714 09:28:07.118555       1 session.go:190] Open Session bce19910-3747-4dcd-955c-63982618a68b with <0> Job and <1> Queues
I0714 09:28:07.120437       1 enqueue.go:79] Try to enqueue PodGroup to 0 Queues
I0714 09:28:07.120506       1 allocate.go:64] Try to allocate resource to 0 Queues
I0714 09:28:07.120717       1 session.go:244] Close Session bce19910-3747-4dcd-955c-63982618a68b
I0714 09:28:08.123383       1 cache.go:1363] There are <0> Jobs, <1> Queues and <5> Nodes in total for scheduling.
I0714 09:28:08.123573       1 session.go:190] Open Session 04156eca-08d1-4707-9466-6d794cfbfec6 with <0> Job and <1> Queues
I0714 09:28:08.125461       1 enqueue.go:79] Try to enqueue PodGroup to 0 Queues
I0714 09:28:08.125536       1 allocate.go:64] Try to allocate resource to 0 Queues
I0714 09:28:08.125766       1 session.go:244] Close Session 04156eca-08d1-4707-9466-6d794cfbfec6
I0714 09:28:09.127911       1 cache.go:1363] There are <0> Jobs, <1> Queues and <5> Nodes in total for scheduling.
I0714 09:28:09.128090       1 session.go:190] Open Session fc767e0a-5e1c-4b22-b237-af261e7d6bfb with <0> Job and <1> Queues
I0714 09:28:09.129474       1 enqueue.go:79] Try to enqueue PodGroup to 0 Queues
I0714 09:28:09.129523       1 allocate.go:64] Try to allocate resource to 0 Queues
I0714 09:28:09.129628       1 session.go:244] Close Session fc767e0a-5e1c-4b22-b237-af261e7d6bfb
I0714 09:28:10.132679       1 cache.go:1363] There are <0> Jobs, <1> Queues and <5> Nodes in total for scheduling.
I0714 09:28:10.132866       1 session.go:190] Open Session 8c5fe67e-8c4c-434e-b0b3-c6ae332549f8 with <0> Job and <1> Queues
I0714 09:28:10.134657       1 enqueue.go:79] Try to enqueue PodGroup to 0 Queues
I0714 09:28:10.134725       1 allocate.go:64] Try to allocate resource to 0 Queues
I0714 09:28:10.134955       1 session.go:244] Close Session 8c5fe67e-8c4c-434e-b0b3-c6ae332549f8
I0714 09:28:11.137891       1 cache.go:1363] There are <0> Jobs, <1> Queues and <5> Nodes in total for scheduling.
I0714 09:28:11.138075       1 session.go:190] Open Session 2f29d7c3-9895-42ed-ab76-fa486c698ce7 with <0> Job and <1> Queues
I0714 09:28:11.139882       1 enqueue.go:79] Try to enqueue PodGroup to 0 Queues
I0714 09:28:11.139947       1 allocate.go:64] Try to allocate resource to 0 Queues
I0714 09:28:11.140185       1 session.go:244] Close Session 2f29d7c3-9895-42ed-ab76-fa486c698ce7
I0714 09:28:12.142847       1 cache.go:1363] There are <0> Jobs, <1> Queues and <5> Nodes in total for scheduling.
I0714 09:28:12.143029       1 session.go:190] Open Session 311bcc95-3440-48c3-91c7-c64929142fcd with <0> Job and <1> Queues
I0714 09:28:12.144840       1 enqueue.go:79] Try to enqueue PodGroup to 0 Queues
I0714 09:28:12.144911       1 allocate.go:64] Try to allocate resource to 0 Queues
I0714 09:28:12.145120       1 session.go:244] Close Session 311bcc95-3440-48c3-91c7-c64929142fcd
I0714 09:28:13.147570       1 cache.go:1363] There are <0> Jobs, <1> Queues and <5> Nodes in total for scheduling.
I0714 09:28:13.147761       1 session.go:190] Open Session 1d6450c8-5fbc-4e3e-81ef-1f5d56a66c0c with <0> Job and <1> Queues
I0714 09:28:13.149659       1 enqueue.go:79] Try to enqueue PodGroup to 0 Queues
I0714 09:28:13.149731       1 allocate.go:64] Try to allocate resource to 0 Queues
I0714 09:28:13.149973       1 session.go:244] Close Session 1d6450c8-5fbc-4e3e-81ef-1f5d56a66c0c
I0714 09:28:14.151709       1 cache.go:1363] There are <0> Jobs, <1> Queues and <5> Nodes in total for scheduling.
I0714 09:28:14.151811       1 session.go:190] Open Session dc85222e-1325-4d7f-a673-b6a54bdc4307 with <0> Job and <1> Queues
I0714 09:28:14.152822       1 enqueue.go:79] Try to enqueue PodGroup to 0 Queues
I0714 09:28:14.152871       1 allocate.go:64] Try to allocate resource to 0 Queues
I0714 09:28:14.152984       1 session.go:244] Close Session dc85222e-1325-4d7f-a673-b6a54bdc4307
I0714 09:28:15.154944       1 cache.go:1363] There are <0> Jobs, <1> Queues and <5> Nodes in total for scheduling.
I0714 09:28:15.155115       1 session.go:190] Open Session 3c0d3f12-0fea-49ac-9996-c9d2dd3e7752 with <0> Job and <1> Queues
I0714 09:28:15.156972       1 enqueue.go:79] Try to enqueue PodGroup to 0 Queues
I0714 09:28:15.157047       1 allocate.go:64] Try to allocate resource to 0 Queues
I0714 09:28:15.157266       1 session.go:244] Close Session 3c0d3f12-0fea-49ac-9996-c9d2dd3e7752
I0714 09:28:16.159368       1 cache.go:1363] There are <0> Jobs, <1> Queues and <5> Nodes in total for scheduling.
I0714 09:28:16.159509       1 session.go:190] Open Session eb507485-2920-4363-a0f7-bbd55e5f5750 with <0> Job and <1> Queues
I0714 09:28:16.161075       1 enqueue.go:79] Try to enqueue PodGroup to 0 Queues
I0714 09:28:16.161157       1 allocate.go:64] Try to allocate resource to 0 Queues
I0714 09:28:16.161359       1 session.go:244] Close Session eb507485-2920-4363-a0f7-bbd55e5f5750
I0714 09:28:17.164483       1 cache.go:1363] There are <0> Jobs, <1> Queues and <5> Nodes in total for scheduling.
I0714 09:28:17.164673       1 session.go:190] Open Session 7d76033d-a958-4eb4-8922-85b89262c2fc with <0> Job and <1> Queues
I0714 09:28:17.166459       1 enqueue.go:79] Try to enqueue PodGroup to 0 Queues
I0714 09:28:17.166535       1 allocate.go:64] Try to allocate resource to 0 Queues
I0714 09:28:17.166762       1 session.go:244] Close Session 7d76033d-a958-4eb4-8922-85b89262c2fc
I0714 09:28:18.168830       1 cache.go:1363] There are <0> Jobs, <1> Queues and <5> Nodes in total for scheduling.
I0714 09:28:18.169015       1 session.go:190] Open Session d03cb88d-3f5b-4780-886f-e4eabc838eb3 with <0> Job and <1> Queues
I0714 09:28:18.170820       1 enqueue.go:79] Try to enqueue PodGroup to 0 Queues
I0714 09:28:18.170891       1 allocate.go:64] Try to allocate resource to 0 Queues
I0714 09:28:18.171114       1 session.go:244] Close Session d03cb88d-3f5b-4780-886f-e4eabc838eb3
I0714 09:28:19.172474       1 cache.go:1363] There are <0> Jobs, <1> Queues and <5> Nodes in total for scheduling.
I0714 09:28:19.172567       1 session.go:190] Open Session 37a67bc3-8b43-471b-8645-51f367868161 with <0> Job and <1> Queues
I0714 09:28:19.173480       1 enqueue.go:79] Try to enqueue PodGroup to 0 Queues
I0714 09:28:19.173531       1 allocate.go:64] Try to allocate resource to 0 Queues
I0714 09:28:19.173649       1 session.go:244] Close Session 37a67bc3-8b43-471b-8645-51f367868161
I0714 09:28:20.175944       1 cache.go:1363] There are <0> Jobs, <1> Queues and <5> Nodes in total for scheduling.
I0714 09:28:20.176118       1 session.go:190] Open Session 4d2156b7-732b-4f02-aaa3-81a83ecacc8c with <0> Job and <1> Queues
I0714 09:28:20.178037       1 enqueue.go:79] Try to enqueue PodGroup to 0 Queues
I0714 09:28:20.178113       1 allocate.go:64] Try to allocate resource to 0 Queues
I0714 09:28:20.178354       1 session.go:244] Close Session 4d2156b7-732b-4f02-aaa3-81a83ecacc8c
I0714 09:28:21.180833       1 cache.go:1363] There are <0> Jobs, <1> Queues and <5> Nodes in total for scheduling.
I0714 09:28:21.181016       1 session.go:190] Open Session dc665add-9d66-4d1d-a4aa-01d3901b02ce with <0> Job and <1> Queues
I0714 09:28:21.182812       1 enqueue.go:79] Try to enqueue PodGroup to 0 Queues
I0714 09:28:21.182890       1 allocate.go:64] Try to allocate resource to 0 Queues
I0714 09:28:21.183109       1 session.go:244] Close Session dc665add-9d66-4d1d-a4aa-01d3901b02ce
I0714 09:28:22.185384       1 cache.go:1363] There are <0> Jobs, <1> Queues and <5> Nodes in total for scheduling.
I0714 09:28:22.185563       1 session.go:190] Open Session 12a90511-1edb-46bd-9901-1dbf543ba025 with <0> Job and <1> Queues
I0714 09:28:22.187323       1 enqueue.go:79] Try to enqueue PodGroup to 0 Queues
I0714 09:28:22.187393       1 allocate.go:64] Try to allocate resource to 0 Queues
I0714 09:28:22.187618       1 session.go:244] Close Session 12a90511-1edb-46bd-9901-1dbf543ba025
I0714 09:28:23.190023       1 cache.go:1363] There are <0> Jobs, <1> Queues and <5> Nodes in total for scheduling.
I0714 09:28:23.190199       1 session.go:190] Open Session e5c35b4c-87b3-4ec8-91ec-a1b25ac41302 with <0> Job and <1> Queues
I0714 09:28:23.191931       1 enqueue.go:79] Try to enqueue PodGroup to 0 Queues
I0714 09:28:23.191998       1 allocate.go:64] Try to allocate resource to 0 Queues
I0714 09:28:23.192223       1 session.go:244] Close Session e5c35b4c-87b3-4ec8-91ec-a1b25ac41302
I0714 09:28:24.193711       1 cache.go:1363] There are <0> Jobs, <1> Queues and <5> Nodes in total for scheduling.
I0714 09:28:24.193799       1 session.go:190] Open Session c71cb491-27af-469b-9e1c-d899a3c4efb8 with <0> Job and <1> Queues
I0714 09:28:24.194702       1 enqueue.go:79] Try to enqueue PodGroup to 0 Queues
I0714 09:28:24.194758       1 allocate.go:64] Try to allocate resource to 0 Queues
I0714 09:28:24.194916       1 session.go:244] Close Session c71cb491-27af-469b-9e1c-d899a3c4efb8
I0714 09:28:25.197618       1 cache.go:1363] There are <0> Jobs, <1> Queues and <5> Nodes in total for scheduling.
I0714 09:28:25.197768       1 session.go:190] Open Session 2249fb93-84a1-41b2-8467-2771e9e8ac39 with <0> Job and <1> Queues
I0714 09:28:25.199562       1 enqueue.go:79] Try to enqueue PodGroup to 0 Queues
I0714 09:28:25.199627       1 allocate.go:64] Try to allocate resource to 0 Queues
I0714 09:28:25.199847       1 session.go:244] Close Session 2249fb93-84a1-41b2-8467-2771e9e8ac39
I0714 09:28:26.202719       1 cache.go:1363] There are <0> Jobs, <1> Queues and <5> Nodes in total for scheduling.
I0714 09:28:26.202890       1 session.go:190] Open Session 9607916e-abf8-473c-96e7-0ca389bb00b4 with <0> Job and <1> Queues
I0714 09:28:26.204733       1 enqueue.go:79] Try to enqueue PodGroup to 0 Queues
I0714 09:28:26.204822       1 allocate.go:64] Try to allocate resource to 0 Queues
I0714 09:28:26.205048       1 session.go:244] Close Session 9607916e-abf8-473c-96e7-0ca389bb00b4
I0714 09:28:27.207511       1 cache.go:1363] There are <0> Jobs, <1> Queues and <5> Nodes in total for scheduling.
I0714 09:28:27.207691       1 session.go:190] Open Session c6e5f4bf-b5fb-4659-96f3-000ebac19c20 with <0> Job and <1> Queues
I0714 09:28:27.209521       1 enqueue.go:79] Try to enqueue PodGroup to 0 Queues
I0714 09:28:27.209613       1 allocate.go:64] Try to allocate resource to 0 Queues
I0714 09:28:27.209839       1 session.go:244] Close Session c6e5f4bf-b5fb-4659-96f3-000ebac19c20
I0714 09:28:28.212681       1 cache.go:1363] There are <0> Jobs, <1> Queues and <5> Nodes in total for scheduling.
I0714 09:28:28.212837       1 session.go:190] Open Session 6e5de215-4b5b-4909-a927-7d84e6b05c4d with <0> Job and <1> Queues
I0714 09:28:28.214644       1 enqueue.go:79] Try to enqueue PodGroup to 0 Queues
I0714 09:28:28.214713       1 allocate.go:64] Try to allocate resource to 0 Queues
I0714 09:28:28.214926       1 session.go:244] Close Session 6e5de215-4b5b-4909-a927-7d84e6b05c4d
I0714 09:28:29.216750       1 cache.go:1363] There are <0> Jobs, <1> Queues and <5> Nodes in total for scheduling.
I0714 09:28:29.216837       1 session.go:190] Open Session bb9b0c47-2ac1-43ad-94f6-1e362de0d44a with <0> Job and <1> Queues
I0714 09:28:29.217704       1 enqueue.go:79] Try to enqueue PodGroup to 0 Queues
I0714 09:28:29.217753       1 allocate.go:64] Try to allocate resource to 0 Queues
I0714 09:28:29.217863       1 session.go:244] Close Session bb9b0c47-2ac1-43ad-94f6-1e362de0d44a
I0714 09:28:30.220527       1 cache.go:1363] There are <0> Jobs, <1> Queues and <5> Nodes in total for scheduling.
I0714 09:28:30.220706       1 session.go:190] Open Session 65d455c0-d0dd-44a8-83c0-05f67e6f4e34 with <0> Job and <1> Queues
I0714 09:28:30.222464       1 enqueue.go:79] Try to enqueue PodGroup to 0 Queues
I0714 09:28:30.222550       1 allocate.go:64] Try to allocate resource to 0 Queues
I0714 09:28:30.222749       1 session.go:244] Close Session 65d455c0-d0dd-44a8-83c0-05f67e6f4e34
I0714 09:28:31.225487       1 cache.go:1363] There are <0> Jobs, <1> Queues and <5> Nodes in total for scheduling.
I0714 09:28:31.225657       1 session.go:190] Open Session 12bcbd0d-3365-42ba-8450-23605f6d97ae with <0> Job and <1> Queues
I0714 09:28:31.227343       1 enqueue.go:79] Try to enqueue PodGroup to 0 Queues
I0714 09:28:31.227430       1 allocate.go:64] Try to allocate resource to 0 Queues
I0714 09:28:31.227657       1 session.go:244] Close Session 12bcbd0d-3365-42ba-8450-23605f6d97ae
I0714 09:28:32.230564       1 cache.go:1363] There are <0> Jobs, <1> Queues and <5> Nodes in total for scheduling.
I0714 09:28:32.230763       1 session.go:190] Open Session 38307e9b-dbc1-4d9c-93b4-a68e0c0484da with <0> Job and <1> Queues
I0714 09:28:32.232660       1 enqueue.go:79] Try to enqueue PodGroup to 0 Queues
I0714 09:28:32.232745       1 allocate.go:64] Try to allocate resource to 0 Queues
I0714 09:28:32.232982       1 session.go:244] Close Session 38307e9b-dbc1-4d9c-93b4-a68e0c0484da
I0714 09:28:33.235135       1 cache.go:1363] There are <0> Jobs, <1> Queues and <5> Nodes in total for scheduling.
I0714 09:28:33.235316       1 session.go:190] Open Session ad762df1-52da-4b11-9ff0-ecf82d399f73 with <0> Job and <1> Queues
I0714 09:28:33.237230       1 enqueue.go:79] Try to enqueue PodGroup to 0 Queues
I0714 09:28:33.237318       1 allocate.go:64] Try to allocate resource to 0 Queues
I0714 09:28:33.237539       1 session.go:244] Close Session ad762df1-52da-4b11-9ff0-ecf82d399f73
I0714 09:28:34.239697       1 cache.go:1363] There are <0> Jobs, <1> Queues and <5> Nodes in total for scheduling.
I0714 09:28:34.239876       1 session.go:190] Open Session a830dacb-d329-403c-b08c-824414b18a12 with <0> Job and <1> Queues
I0714 09:28:34.241702       1 enqueue.go:79] Try to enqueue PodGroup to 0 Queues
I0714 09:28:34.241783       1 allocate.go:64] Try to allocate resource to 0 Queues
I0714 09:28:34.242024       1 session.go:244] Close Session a830dacb-d329-403c-b08c-824414b18a12
I0714 09:28:35.244421       1 cache.go:1363] There are <0> Jobs, <1> Queues and <5> Nodes in total for scheduling.
I0714 09:28:35.244579       1 session.go:190] Open Session 8bed3d3b-d7f4-4fc8-9c08-50cd1ccb0d1e with <0> Job and <1> Queues
I0714 09:28:35.246396       1 enqueue.go:79] Try to enqueue PodGroup to 0 Queues
I0714 09:28:35.246482       1 allocate.go:64] Try to allocate resource to 0 Queues
I0714 09:28:35.246706       1 session.go:244] Close Session 8bed3d3b-d7f4-4fc8-9c08-50cd1ccb0d1e
I0714 09:28:36.248909       1 cache.go:1363] There are <0> Jobs, <1> Queues and <5> Nodes in total for scheduling.
I0714 09:28:36.249100       1 session.go:190] Open Session 59c886aa-d5f4-4e4c-b96e-5cbb8abe7c5f with <0> Job and <1> Queues
I0714 09:28:36.250871       1 enqueue.go:79] Try to enqueue PodGroup to 0 Queues
I0714 09:28:36.250950       1 allocate.go:64] Try to allocate resource to 0 Queues
I0714 09:28:36.251158       1 session.go:244] Close Session 59c886aa-d5f4-4e4c-b96e-5cbb8abe7c5f
I0714 09:28:36.669586       1 cache.go:1489] The metrics type is not set in the volcano scheduler configmap file. As a result, the CPU and memory load information of the node is not collected.
I0714 09:28:37.253805       1 cache.go:1363] There are <0> Jobs, <1> Queues and <5> Nodes in total for scheduling.
I0714 09:28:37.253974       1 session.go:190] Open Session 9c3c9d53-35a5-444b-9eef-96c4c17468f7 with <0> Job and <1> Queues
I0714 09:28:37.255817       1 enqueue.go:79] Try to enqueue PodGroup to 0 Queues
I0714 09:28:37.255908       1 allocate.go:64] Try to allocate resource to 0 Queues
I0714 09:28:37.256112       1 session.go:244] Close Session 9c3c9d53-35a5-444b-9eef-96c4c17468f7
I0714 09:28:38.258949       1 cache.go:1363] There are <0> Jobs, <1> Queues and <5> Nodes in total for scheduling.
I0714 09:28:38.259122       1 session.go:190] Open Session f19610c5-0428-4325-bbc6-a6f495ab3688 with <0> Job and <1> Queues
I0714 09:28:38.260897       1 enqueue.go:79] Try to enqueue PodGroup to 0 Queues
I0714 09:28:38.260981       1 allocate.go:64] Try to allocate resource to 0 Queues
I0714 09:28:38.261198       1 session.go:244] Close Session f19610c5-0428-4325-bbc6-a6f495ab3688
W0714 09:28:38.780471       1 event_handlers.go:181] Not support non-csi pvc.
I0714 09:28:38.780640       1 event_handlers.go:387] Added pod <default/yolo-cls> into cache.
W0714 09:28:38.804547       1 event_handlers.go:181] Not support non-csi pvc.
I0714 09:28:39.264127       1 cache.go:1363] There are <1> Jobs, <1> Queues and <5> Nodes in total for scheduling.
I0714 09:28:39.264769       1 session.go:190] Open Session 9b94f487-2a52-4d29-8f8a-cfb171cd1e62 with <1> Job and <1> Queues
I0714 09:28:39.267924       1 enqueue.go:79] Try to enqueue PodGroup to 1 Queues
I0714 09:28:39.268568       1 allocate.go:64] Try to allocate resource to 1 Queues
I0714 09:28:39.268802       1 allocate.go:129] Try to allocate resource to Jobs in Queue <default>
I0714 09:28:39.268988       1 allocate.go:161] Try to allocate resource to 1 tasks of Job <default/podgroup-b0b8c6f3-0a31-46fb-a4b8-a94ac7747225>
I0714 09:28:39.269192       1 allocate.go:181] There are <5> nodes for Job <default/podgroup-b0b8c6f3-0a31-46fb-a4b8-a94ac7747225>
I0714 09:28:39.269746       1 predicate_helper.go:75] Predicates failed: task default/yolo-cls on node gpu-master fit failed: Insufficient nvidia.com/gpu
I0714 09:28:39.270396       1 predicate_helper.go:75] Predicates failed: task default/yolo-cls on node gpuorin5-desktop fit failed: plugin NodeAffinity predicates failed node(s) didn't match Pod's node affinity/selector
I0714 09:28:39.270723       1 predicate_helper.go:75] Predicates failed: task default/yolo-cls on node gpuorin4-desktop fit failed: plugin NodeAffinity predicates failed node(s) didn't match Pod's node affinity/selector
I0714 09:28:39.271731       1 allocate.go:249] Binding Task <default/yolo-cls> to node <gpu-orin3>
I0714 09:28:39.271945       1 statement.go:266] After allocated Task <default/yolo-cls> to Node <gpu-orin3>: idle <cpu 5900.00, memory 7832723456.00, ephemeral-storage 111715275387000.00, hugepages-1Gi 0.00, nvidia.com/gpu 4000.00, pods 105.00, hugepages-32Mi 0.00, hugepages-64Ki 0.00, hugepages-2Mi 0.00>, used <cpu 100.00, memory 52428800.00, pods 5.00, nvidia.com/gpu 1000.00>, releasing <cpu 0.00, memory 0.00>
I0714 09:28:39.272681       1 statement.go:284] Allocating operations ...
I0714 09:28:39.272817       1 statement.go:378] Committing operations ...
I0714 09:28:39.272948       1 proportion.go:302] Queue <default>: deserved <cpu 0.00, memory 0.00, nvidia.com/gpu 1000.00, pods 1.00>, allocated <cpu 0.00, memory 0.00, nvidia.com/gpu 1000.00, pods 1.00>, share <1>
I0714 09:28:39.273033       1 allocate.go:125] Queue <default> is overused, ignore it.
I0714 09:28:39.303592       1 session.go:244] Close Session 9b94f487-2a52-4d29-8f8a-cfb171cd1e62
I0714 09:28:39.304950       1 cache.go:900] bind ok, latency 16.963334ms
W0714 09:28:39.305715       1 event_handlers.go:181] Not support non-csi pvc.
W0714 09:28:39.341044       1 event_handlers.go:181] Not support non-csi pvc.
W0714 09:28:39.418743       1 event_handlers.go:181] Not support non-csi pvc.
I0714 09:28:39.423002       1 event_handlers.go:442] Deleted pod <default/yolo-cls> from cache.
I0714 09:28:39.436439       1 cache.go:1013] Try to delete Job <default/podgroup-b0b8c6f3-0a31-46fb-a4b8-a94ac7747225:default/podgroup-b0b8c6f3-0a31-46fb-a4b8-a94ac7747225>
I0714 09:28:39.436655       1 cache.go:1054] Job <default/podgroup-b0b8c6f3-0a31-46fb-a4b8-a94ac7747225:default/podgroup-b0b8c6f3-0a31-46fb-a4b8-a94ac7747225> was deleted.
W0714 09:28:39.621508       1 event_handlers.go:181] Not support non-csi pvc.
I0714 09:28:39.621634       1 event_handlers.go:387] Added pod <default/yolo-cls> into cache.
W0714 09:28:39.657504       1 event_handlers.go:181] Not support non-csi pvc.
I0714 09:28:40.305847       1 cache.go:1363] There are <0> Jobs, <1> Queues and <5> Nodes in total for scheduling.
I0714 09:28:40.306009       1 session.go:190] Open Session fc60ff77-8074-4622-9958-75b7bced16c7 with <0> Job and <1> Queues
I0714 09:28:40.308039       1 enqueue.go:79] Try to enqueue PodGroup to 0 Queues
I0714 09:28:40.308110       1 allocate.go:64] Try to allocate resource to 0 Queues
I0714 09:28:40.308351       1 session.go:244] Close Session fc60ff77-8074-4622-9958-75b7bced16c7
I0714 09:28:41.311205       1 cache.go:1363] There are <0> Jobs, <1> Queues and <5> Nodes in total for scheduling.
I0714 09:28:41.311360       1 session.go:190] Open Session aa289689-c163-437b-ba66-64da47a669d6 with <0> Job and <1> Queues
I0714 09:28:41.313476       1 enqueue.go:79] Try to enqueue PodGroup to 0 Queues
I0714 09:28:41.313565       1 allocate.go:64] Try to allocate resource to 0 Queues
I0714 09:28:41.313795       1 session.go:244] Close Session aa289689-c163-437b-ba66-64da47a669d6
I0714 09:28:42.316427       1 cache.go:1363] There are <0> Jobs, <1> Queues and <5> Nodes in total for scheduling.
I0714 09:28:42.316610       1 session.go:190] Open Session a45a49ab-8a94-44ba-a4a9-5a902f60eb5d with <0> Job and <1> Queues
I0714 09:28:42.318399       1 enqueue.go:79] Try to enqueue PodGroup to 0 Queues
I0714 09:28:42.318474       1 allocate.go:64] Try to allocate resource to 0 Queues
I0714 09:28:42.318715       1 session.go:244] Close Session a45a49ab-8a94-44ba-a4a9-5a902f60eb5d
W0714 09:28:42.492920       1 event_handlers.go:181] Not support non-csi pvc.
I0714 09:28:43.321627       1 cache.go:1363] There are <0> Jobs, <1> Queues and <5> Nodes in total for scheduling.
I0714 09:28:43.321785       1 session.go:190] Open Session 39371fe5-251a-4075-8dbd-0d16ae9cf9f6 with <0> Job and <1> Queues
I0714 09:28:43.323531       1 enqueue.go:79] Try to enqueue PodGroup to 0 Queues
I0714 09:28:43.323600       1 allocate.go:64] Try to allocate resource to 0 Queues
I0714 09:28:43.323851       1 session.go:244] Close Session 39371fe5-251a-4075-8dbd-0d16ae9cf9f6
I0714 09:28:44.326398       1 cache.go:1363] There are <0> Jobs, <1> Queues and <5> Nodes in total for scheduling.
I0714 09:28:44.326588       1 session.go:190] Open Session f30ee2cd-aff7-4e43-848b-a626417bc4e5 with <0> Job and <1> Queues
I0714 09:28:44.328804       1 enqueue.go:79] Try to enqueue PodGroup to 0 Queues
I0714 09:28:44.328889       1 allocate.go:64] Try to allocate resource to 0 Queues
I0714 09:28:44.329113       1 session.go:244] Close Session f30ee2cd-aff7-4e43-848b-a626417bc4e5
I0714 09:28:45.331822       1 cache.go:1363] There are <0> Jobs, <1> Queues and <5> Nodes in total for scheduling.
I0714 09:28:45.331980       1 session.go:190] Open Session e892f4b7-c505-44e2-8570-2f0cfc78d824 with <0> Job and <1> Queues
I0714 09:28:45.334082       1 enqueue.go:79] Try to enqueue PodGroup to 0 Queues
I0714 09:28:45.334165       1 allocate.go:64] Try to allocate resource to 0 Queues
I0714 09:28:45.334411       1 session.go:244] Close Session e892f4b7-c505-44e2-8570-2f0cfc78d824
W0714 09:28:46.307375       1 event_handlers.go:181] Not support non-csi pvc.
I0714 09:28:46.307498       1 event_handlers.go:387] Added pod <default/yolo-det> into cache.
W0714 09:28:46.333215       1 event_handlers.go:181] Not support non-csi pvc.
I0714 09:28:46.337122       1 cache.go:1363] There are <1> Jobs, <1> Queues and <5> Nodes in total for scheduling.
I0714 09:28:46.337230       1 session.go:190] Open Session c293a310-589f-45ea-b11e-1778ebcce730 with <1> Job and <1> Queues
I0714 09:28:46.339247       1 enqueue.go:79] Try to enqueue PodGroup to 1 Queues
I0714 09:28:46.339698       1 allocate.go:64] Try to allocate resource to 1 Queues
I0714 09:28:46.339856       1 allocate.go:129] Try to allocate resource to Jobs in Queue <default>
I0714 09:28:46.339969       1 allocate.go:161] Try to allocate resource to 1 tasks of Job <default/podgroup-f590cdb3-9623-412c-9877-b53c29d9611e>
I0714 09:28:46.340101       1 allocate.go:181] There are <5> nodes for Job <default/podgroup-f590cdb3-9623-412c-9877-b53c29d9611e>
I0714 09:28:46.340511       1 predicate_helper.go:75] Predicates failed: task default/yolo-det on node gpu-master fit failed: Insufficient nvidia.com/gpu
I0714 09:28:46.341258       1 predicate_helper.go:75] Predicates failed: task default/yolo-det on node gpuorin4-desktop fit failed: plugin NodeAffinity predicates failed node(s) didn't match Pod's node affinity/selector
I0714 09:28:46.341342       1 predicate_helper.go:75] Predicates failed: task default/yolo-det on node gpuorin5-desktop fit failed: plugin NodeAffinity predicates failed node(s) didn't match Pod's node affinity/selector
I0714 09:28:46.342206       1 allocate.go:249] Binding Task <default/yolo-det> to node <gpu-orin2>
I0714 09:28:46.342408       1 statement.go:266] After allocated Task <default/yolo-det> to Node <gpu-orin2>: idle <cpu 5900.00, memory 7832690688.00, hugepages-2Mi 0.00, hugepages-64Ki 0.00, hugepages-32Mi 0.00, ephemeral-storage 225118140453000.00, hugepages-1Gi 0.00, nvidia.com/gpu 4000.00, pods 105.00>, used <cpu 100.00, memory 52428800.00, pods 5.00, nvidia.com/gpu 1000.00>, releasing <cpu 0.00, memory 0.00>
I0714 09:28:46.342800       1 statement.go:284] Allocating operations ...
I0714 09:28:46.342926       1 statement.go:378] Committing operations ...
I0714 09:28:46.343071       1 proportion.go:302] Queue <default>: deserved <cpu 0.00, memory 0.00, nvidia.com/gpu 1000.00, pods 1.00>, allocated <cpu 0.00, memory 0.00, nvidia.com/gpu 1000.00, pods 1.00>, share <1>
I0714 09:28:46.343129       1 allocate.go:125] Queue <default> is overused, ignore it.
I0714 09:28:46.352404       1 session.go:244] Close Session c293a310-589f-45ea-b11e-1778ebcce730
I0714 09:28:46.367198       1 cache.go:900] bind ok, latency 10.149001ms
W0714 09:28:46.369814       1 event_handlers.go:181] Not support non-csi pvc.
W0714 09:28:46.431012       1 event_handlers.go:181] Not support non-csi pvc.
W0714 09:28:46.942730       1 event_handlers.go:181] Not support non-csi pvc.
I0714 09:28:46.944617       1 event_handlers.go:442] Deleted pod <default/yolo-det> from cache.
I0714 09:28:46.951056       1 cache.go:1013] Try to delete Job <default/podgroup-f590cdb3-9623-412c-9877-b53c29d9611e:default/podgroup-f590cdb3-9623-412c-9877-b53c29d9611e>
I0714 09:28:46.951268       1 cache.go:1054] Job <default/podgroup-f590cdb3-9623-412c-9877-b53c29d9611e:default/podgroup-f590cdb3-9623-412c-9877-b53c29d9611e> was deleted.
W0714 09:28:47.116508       1 event_handlers.go:181] Not support non-csi pvc.
I0714 09:28:47.116660       1 event_handlers.go:387] Added pod <default/yolo-det> into cache.
W0714 09:28:47.153822       1 event_handlers.go:181] Not support non-csi pvc.
I0714 09:28:47.354249       1 cache.go:1363] There are <0> Jobs, <1> Queues and <5> Nodes in total for scheduling.
I0714 09:28:47.354380       1 session.go:190] Open Session 2962cc96-14fb-46da-957f-7460aaf7baf8 with <0> Job and <1> Queues
I0714 09:28:47.356244       1 enqueue.go:79] Try to enqueue PodGroup to 0 Queues
I0714 09:28:47.356372       1 allocate.go:64] Try to allocate resource to 0 Queues
I0714 09:28:47.356596       1 session.go:244] Close Session 2962cc96-14fb-46da-957f-7460aaf7baf8
I0714 09:28:48.359237       1 cache.go:1363] There are <0> Jobs, <1> Queues and <5> Nodes in total for scheduling.
I0714 09:28:48.359372       1 session.go:190] Open Session 28fb5640-86d4-4da9-858b-94055504190c with <0> Job and <1> Queues
I0714 09:28:48.361181       1 enqueue.go:79] Try to enqueue PodGroup to 0 Queues
I0714 09:28:48.361254       1 allocate.go:64] Try to allocate resource to 0 Queues
I0714 09:28:48.361467       1 session.go:244] Close Session 28fb5640-86d4-4da9-858b-94055504190c
I0714 09:28:49.363726       1 cache.go:1363] There are <0> Jobs, <1> Queues and <5> Nodes in total for scheduling.
I0714 09:28:49.363905       1 session.go:190] Open Session 562ac883-8cd9-4296-a3de-443231282d18 with <0> Job and <1> Queues
I0714 09:28:49.365956       1 enqueue.go:79] Try to enqueue PodGroup to 0 Queues
I0714 09:28:49.366035       1 allocate.go:64] Try to allocate resource to 0 Queues
I0714 09:28:49.366267       1 session.go:244] Close Session 562ac883-8cd9-4296-a3de-443231282d18
W0714 09:28:49.438043       1 event_handlers.go:181] Not support non-csi pvc.
I0714 09:28:50.368694       1 cache.go:1363] There are <0> Jobs, <1> Queues and <5> Nodes in total for scheduling.
I0714 09:28:50.368849       1 session.go:190] Open Session 1d931fc2-7890-4aba-9354-1fdb5e37ee1d with <0> Job and <1> Queues
I0714 09:28:50.370649       1 enqueue.go:79] Try to enqueue PodGroup to 0 Queues
I0714 09:28:50.370734       1 allocate.go:64] Try to allocate resource to 0 Queues
I0714 09:28:50.370950       1 session.go:244] Close Session 1d931fc2-7890-4aba-9354-1fdb5e37ee1d
I0714 09:28:51.373963       1 cache.go:1363] There are <0> Jobs, <1> Queues and <5> Nodes in total for scheduling.
I0714 09:28:51.374140       1 session.go:190] Open Session 5ca713b1-9808-448c-8f98-7f2386904ace with <0> Job and <1> Queues
I0714 09:28:51.376267       1 enqueue.go:79] Try to enqueue PodGroup to 0 Queues
I0714 09:28:51.376382       1 allocate.go:64] Try to allocate resource to 0 Queues
I0714 09:28:51.376603       1 session.go:244] Close Session 5ca713b1-9808-448c-8f98-7f2386904ace
I0714 09:28:52.378492       1 cache.go:1363] There are <0> Jobs, <1> Queues and <5> Nodes in total for scheduling.
I0714 09:28:52.378630       1 session.go:190] Open Session 98ff680d-d6db-4566-b727-5cf4d9e75adf with <0> Job and <1> Queues
I0714 09:28:52.380182       1 enqueue.go:79] Try to enqueue PodGroup to 0 Queues
I0714 09:28:52.380243       1 allocate.go:64] Try to allocate resource to 0 Queues
I0714 09:28:52.380473       1 session.go:244] Close Session 98ff680d-d6db-4566-b727-5cf4d9e75adf
W0714 09:28:53.159579       1 event_handlers.go:181] Not support non-csi pvc.
I0714 09:28:53.159695       1 event_handlers.go:387] Added pod <default/yolo-seg> into cache.
W0714 09:28:53.188275       1 event_handlers.go:181] Not support non-csi pvc.
I0714 09:28:53.383154       1 cache.go:1363] There are <1> Jobs, <1> Queues and <5> Nodes in total for scheduling.
I0714 09:28:53.383297       1 session.go:190] Open Session 7c428c58-afb7-4e2e-996b-8c9c4c9be572 with <1> Job and <1> Queues
I0714 09:28:53.385776       1 enqueue.go:79] Try to enqueue PodGroup to 1 Queues
I0714 09:28:53.386014       1 allocate.go:64] Try to allocate resource to 1 Queues
I0714 09:28:53.386065       1 allocate.go:129] Try to allocate resource to Jobs in Queue <default>
I0714 09:28:53.386103       1 allocate.go:161] Try to allocate resource to 1 tasks of Job <default/podgroup-7aa5aaa8-821a-49bf-8715-789a4dc2b7e9>
I0714 09:28:53.386155       1 allocate.go:181] There are <5> nodes for Job <default/podgroup-7aa5aaa8-821a-49bf-8715-789a4dc2b7e9>
I0714 09:28:53.386457       1 predicate_helper.go:75] Predicates failed: task default/yolo-seg on node gpu-master fit failed: Insufficient nvidia.com/gpu
I0714 09:28:53.386878       1 predicate_helper.go:75] Predicates failed: task default/yolo-seg on node gpuorin5-desktop fit failed: plugin NodeAffinity predicates failed node(s) didn't match Pod's node affinity/selector
I0714 09:28:53.386878       1 predicate_helper.go:75] Predicates failed: task default/yolo-seg on node gpuorin4-desktop fit failed: plugin NodeAffinity predicates failed node(s) didn't match Pod's node affinity/selector
I0714 09:28:53.388272       1 allocate.go:249] Binding Task <default/yolo-seg> to node <gpu-orin2>
I0714 09:28:53.388525       1 statement.go:266] After allocated Task <default/yolo-seg> to Node <gpu-orin2>: idle <cpu 5900.00, memory 7832690688.00, hugepages-32Mi 0.00, ephemeral-storage 225118140453000.00, hugepages-1Gi 0.00, nvidia.com/gpu 3000.00, pods 104.00, hugepages-2Mi 0.00, hugepages-64Ki 0.00>, used <cpu 100.00, memory 52428800.00, pods 6.00, nvidia.com/gpu 2000.00>, releasing <cpu 0.00, memory 0.00>
I0714 09:28:53.388923       1 statement.go:284] Allocating operations ...
I0714 09:28:53.389060       1 statement.go:378] Committing operations ...
I0714 09:28:53.389170       1 proportion.go:302] Queue <default>: deserved <cpu 0.00, memory 0.00, pods 1.00, nvidia.com/gpu 1000.00>, allocated <cpu 0.00, memory 0.00, nvidia.com/gpu 1000.00, pods 1.00>, share <1>
I0714 09:28:53.389225       1 allocate.go:125] Queue <default> is overused, ignore it.
I0714 09:28:53.400440       1 session.go:244] Close Session 7c428c58-afb7-4e2e-996b-8c9c4c9be572
I0714 09:28:53.420982       1 cache.go:900] bind ok, latency 12.489535ms
W0714 09:28:53.423530       1 event_handlers.go:181] Not support non-csi pvc.
W0714 09:28:53.471623       1 event_handlers.go:181] Not support non-csi pvc.
W0714 09:28:53.813285       1 event_handlers.go:181] Not support non-csi pvc.
I0714 09:28:53.820067       1 event_handlers.go:442] Deleted pod <default/yolo-seg> from cache.
I0714 09:28:53.828761       1 cache.go:1013] Try to delete Job <default/podgroup-7aa5aaa8-821a-49bf-8715-789a4dc2b7e9:default/podgroup-7aa5aaa8-821a-49bf-8715-789a4dc2b7e9>
I0714 09:28:53.829005       1 cache.go:1054] Job <default/podgroup-7aa5aaa8-821a-49bf-8715-789a4dc2b7e9:default/podgroup-7aa5aaa8-821a-49bf-8715-789a4dc2b7e9> was deleted.
W0714 09:28:53.959535       1 event_handlers.go:181] Not support non-csi pvc.
I0714 09:28:53.959656       1 event_handlers.go:387] Added pod <default/yolo-seg> into cache.
W0714 09:28:53.995959       1 event_handlers.go:181] Not support non-csi pvc.
I0714 09:28:54.403725       1 cache.go:1363] There are <0> Jobs, <1> Queues and <5> Nodes in total for scheduling.
I0714 09:28:54.403865       1 session.go:190] Open Session f3fa0a4b-aba3-488b-ae7f-749e64d6168c with <0> Job and <1> Queues
I0714 09:28:54.406203       1 enqueue.go:79] Try to enqueue PodGroup to 0 Queues
I0714 09:28:54.406290       1 allocate.go:64] Try to allocate resource to 0 Queues
I0714 09:28:54.406506       1 session.go:244] Close Session f3fa0a4b-aba3-488b-ae7f-749e64d6168c
I0714 09:28:55.409431       1 cache.go:1363] There are <0> Jobs, <1> Queues and <5> Nodes in total for scheduling.
I0714 09:28:55.409610       1 session.go:190] Open Session 9ada41a9-08c7-4c5a-9163-ab9319c0612e with <0> Job and <1> Queues
I0714 09:28:55.411948       1 enqueue.go:79] Try to enqueue PodGroup to 0 Queues
I0714 09:28:55.412033       1 allocate.go:64] Try to allocate resource to 0 Queues
I0714 09:28:55.412261       1 session.go:244] Close Session 9ada41a9-08c7-4c5a-9163-ab9319c0612e
I0714 09:28:56.414596       1 cache.go:1363] There are <0> Jobs, <1> Queues and <5> Nodes in total for scheduling.
I0714 09:28:56.414768       1 session.go:190] Open Session 82ed3a10-43fe-41ff-96d6-abacd061f24f with <0> Job and <1> Queues
I0714 09:28:56.416659       1 enqueue.go:79] Try to enqueue PodGroup to 0 Queues
I0714 09:28:56.416729       1 allocate.go:64] Try to allocate resource to 0 Queues
I0714 09:28:56.416974       1 session.go:244] Close Session 82ed3a10-43fe-41ff-96d6-abacd061f24f
W0714 09:28:56.498213       1 event_handlers.go:181] Not support non-csi pvc.
I0714 09:28:57.420122       1 cache.go:1363] There are <0> Jobs, <1> Queues and <5> Nodes in total for scheduling.
I0714 09:28:57.420330       1 session.go:190] Open Session f9ee7e0c-5cee-4a25-b1ae-533381278300 with <0> Job and <1> Queues
I0714 09:28:57.422224       1 enqueue.go:79] Try to enqueue PodGroup to 0 Queues
I0714 09:28:57.422295       1 allocate.go:64] Try to allocate resource to 0 Queues
I0714 09:28:57.422524       1 session.go:244] Close Session f9ee7e0c-5cee-4a25-b1ae-533381278300
I0714 09:28:58.425381       1 cache.go:1363] There are <0> Jobs, <1> Queues and <5> Nodes in total for scheduling.
I0714 09:28:58.425555       1 session.go:190] Open Session c4aee16b-b69e-490c-ac85-4804126ebf15 with <0> Job and <1> Queues
I0714 09:28:58.427789       1 enqueue.go:79] Try to enqueue PodGroup to 0 Queues
I0714 09:28:58.427874       1 allocate.go:64] Try to allocate resource to 0 Queues
I0714 09:28:58.428087       1 session.go:244] Close Session c4aee16b-b69e-490c-ac85-4804126ebf15
I0714 09:28:59.431039       1 cache.go:1363] There are <0> Jobs, <1> Queues and <5> Nodes in total for scheduling.
I0714 09:28:59.431232       1 session.go:190] Open Session 9fb85dc2-3c4a-4a02-a745-5bb43490f0ed with <0> Job and <1> Queues
I0714 09:28:59.433180       1 enqueue.go:79] Try to enqueue PodGroup to 0 Queues
I0714 09:28:59.433257       1 allocate.go:64] Try to allocate resource to 0 Queues
I0714 09:28:59.433485       1 session.go:244] Close Session 9fb85dc2-3c4a-4a02-a745-5bb43490f0ed
W0714 09:29:00.027764       1 event_handlers.go:181] Not support non-csi pvc.
I0714 09:29:00.027889       1 event_handlers.go:387] Added pod <default/yolo-obb> into cache.
W0714 09:29:00.048548       1 event_handlers.go:181] Not support non-csi pvc.
I0714 09:29:00.435819       1 cache.go:1363] There are <1> Jobs, <1> Queues and <5> Nodes in total for scheduling.
I0714 09:29:00.435998       1 session.go:190] Open Session 5dc06d5b-bf04-4060-b0c2-5cb87ced4d5d with <1> Job and <1> Queues
I0714 09:29:00.438553       1 enqueue.go:79] Try to enqueue PodGroup to 1 Queues
I0714 09:29:00.438800       1 allocate.go:64] Try to allocate resource to 1 Queues
I0714 09:29:00.438852       1 allocate.go:129] Try to allocate resource to Jobs in Queue <default>
I0714 09:29:00.438890       1 allocate.go:161] Try to allocate resource to 1 tasks of Job <default/podgroup-90ed3a85-2934-4baa-b355-9ba3dc0dd532>
I0714 09:29:00.438951       1 allocate.go:181] There are <5> nodes for Job <default/podgroup-90ed3a85-2934-4baa-b355-9ba3dc0dd532>
I0714 09:29:00.439279       1 predicate_helper.go:75] Predicates failed: task default/yolo-obb on node gpu-master fit failed: Insufficient nvidia.com/gpu
I0714 09:29:00.439606       1 predicate_helper.go:75] Predicates failed: task default/yolo-obb on node gpuorin4-desktop fit failed: plugin NodeAffinity predicates failed node(s) didn't match Pod's node affinity/selector
I0714 09:29:00.439682       1 predicate_helper.go:75] Predicates failed: task default/yolo-obb on node gpuorin5-desktop fit failed: plugin NodeAffinity predicates failed node(s) didn't match Pod's node affinity/selector
I0714 09:29:00.440391       1 allocate.go:249] Binding Task <default/yolo-obb> to node <gpu-orin3>
I0714 09:29:00.440596       1 statement.go:266] After allocated Task <default/yolo-obb> to Node <gpu-orin3>: idle <cpu 5900.00, memory 7832723456.00, pods 104.00, ephemeral-storage 111715275387000.00, hugepages-64Ki 0.00, hugepages-2Mi 0.00, hugepages-32Mi 0.00, hugepages-1Gi 0.00, nvidia.com/gpu 3000.00>, used <cpu 100.00, memory 52428800.00, nvidia.com/gpu 2000.00, pods 6.00>, releasing <cpu 0.00, memory 0.00>
I0714 09:29:00.441100       1 statement.go:284] Allocating operations ...
I0714 09:29:00.441243       1 statement.go:378] Committing operations ...
I0714 09:29:00.441364       1 proportion.go:302] Queue <default>: deserved <cpu 0.00, memory 0.00, nvidia.com/gpu 1000.00, pods 1.00>, allocated <cpu 0.00, memory 0.00, nvidia.com/gpu 1000.00, pods 1.00>, share <1>
I0714 09:29:00.441417       1 allocate.go:125] Queue <default> is overused, ignore it.
I0714 09:29:00.457859       1 session.go:244] Close Session 5dc06d5b-bf04-4060-b0c2-5cb87ced4d5d
I0714 09:29:00.470843       1 cache.go:900] bind ok, latency 12.180889ms
W0714 09:29:00.473980       1 event_handlers.go:181] Not support non-csi pvc.
W0714 09:29:00.506846       1 event_handlers.go:181] Not support non-csi pvc.
W0714 09:29:00.649425       1 event_handlers.go:181] Not support non-csi pvc.
I0714 09:29:00.650561       1 event_handlers.go:442] Deleted pod <default/yolo-obb> from cache.
I0714 09:29:00.654494       1 cache.go:1013] Try to delete Job <default/podgroup-90ed3a85-2934-4baa-b355-9ba3dc0dd532:default/podgroup-90ed3a85-2934-4baa-b355-9ba3dc0dd532>
I0714 09:29:00.654881       1 cache.go:1054] Job <default/podgroup-90ed3a85-2934-4baa-b355-9ba3dc0dd532:default/podgroup-90ed3a85-2934-4baa-b355-9ba3dc0dd532> was deleted.
W0714 09:29:00.775124       1 event_handlers.go:181] Not support non-csi pvc.
I0714 09:29:00.775249       1 event_handlers.go:387] Added pod <default/yolo-obb> into cache.
W0714 09:29:00.811610       1 event_handlers.go:181] Not support non-csi pvc.
I0714 09:29:01.460682       1 cache.go:1363] There are <0> Jobs, <1> Queues and <5> Nodes in total for scheduling.
I0714 09:29:01.460803       1 session.go:190] Open Session f843b3dd-0989-43dd-8dbb-4f6f44304fb6 with <0> Job and <1> Queues
I0714 09:29:01.462618       1 enqueue.go:79] Try to enqueue PodGroup to 0 Queues
I0714 09:29:01.462695       1 allocate.go:64] Try to allocate resource to 0 Queues
I0714 09:29:01.462900       1 session.go:244] Close Session f843b3dd-0989-43dd-8dbb-4f6f44304fb6
I0714 09:29:02.465843       1 cache.go:1363] There are <0> Jobs, <1> Queues and <5> Nodes in total for scheduling.
I0714 09:29:02.466005       1 session.go:190] Open Session 43401eaf-a8fe-4588-a2e6-297c58d0a887 with <0> Job and <1> Queues
I0714 09:29:02.467993       1 enqueue.go:79] Try to enqueue PodGroup to 0 Queues
I0714 09:29:02.468089       1 allocate.go:64] Try to allocate resource to 0 Queues
I0714 09:29:02.468342       1 session.go:244] Close Session 43401eaf-a8fe-4588-a2e6-297c58d0a887
I0714 09:29:03.471095       1 cache.go:1363] There are <0> Jobs, <1> Queues and <5> Nodes in total for scheduling.
I0714 09:29:03.471263       1 session.go:190] Open Session be57c273-58f7-4869-a231-c056b5baf842 with <0> Job and <1> Queues
I0714 09:29:03.473200       1 enqueue.go:79] Try to enqueue PodGroup to 0 Queues
I0714 09:29:03.473292       1 allocate.go:64] Try to allocate resource to 0 Queues
I0714 09:29:03.473513       1 session.go:244] Close Session be57c273-58f7-4869-a231-c056b5baf842
W0714 09:29:03.594924       1 event_handlers.go:181] Not support non-csi pvc.
I0714 09:29:04.475737       1 cache.go:1363] There are <0> Jobs, <1> Queues and <5> Nodes in total for scheduling.
I0714 09:29:04.475911       1 session.go:190] Open Session 11ef3bc2-8533-460b-a75e-153f3a3aac1f with <0> Job and <1> Queues
I0714 09:29:04.477895       1 enqueue.go:79] Try to enqueue PodGroup to 0 Queues
I0714 09:29:04.477995       1 allocate.go:64] Try to allocate resource to 0 Queues
I0714 09:29:04.478236       1 session.go:244] Close Session 11ef3bc2-8533-460b-a75e-153f3a3aac1f
I0714 09:29:05.480475       1 cache.go:1363] There are <0> Jobs, <1> Queues and <5> Nodes in total for scheduling.
I0714 09:29:05.480631       1 session.go:190] Open Session 1bb6b68c-b705-4f7c-8259-131380eb512c with <0> Job and <1> Queues
I0714 09:29:05.482569       1 enqueue.go:79] Try to enqueue PodGroup to 0 Queues
I0714 09:29:05.482645       1 allocate.go:64] Try to allocate resource to 0 Queues
I0714 09:29:05.482850       1 session.go:244] Close Session 1bb6b68c-b705-4f7c-8259-131380eb512c
I0714 09:29:06.485718       1 cache.go:1363] There are <0> Jobs, <1> Queues and <5> Nodes in total for scheduling.
I0714 09:29:06.485894       1 session.go:190] Open Session f9391fd1-5c2a-4d8a-8371-487fc1f0f32e with <0> Job and <1> Queues
I0714 09:29:06.487758       1 enqueue.go:79] Try to enqueue PodGroup to 0 Queues
I0714 09:29:06.487840       1 allocate.go:64] Try to allocate resource to 0 Queues
I0714 09:29:06.488050       1 session.go:244] Close Session f9391fd1-5c2a-4d8a-8371-487fc1f0f32e
I0714 09:29:06.669898       1 cache.go:1489] The metrics type is not set in the volcano scheduler configmap file. As a result, the CPU and memory load information of the node is not collected.
I0714 09:29:07.490919       1 cache.go:1363] There are <0> Jobs, <1> Queues and <5> Nodes in total for scheduling.
I0714 09:29:07.491099       1 session.go:190] Open Session b109398f-3981-4914-b6d7-b5835957ab80 with <0> Job and <1> Queues
I0714 09:29:07.493058       1 enqueue.go:79] Try to enqueue PodGroup to 0 Queues
I0714 09:29:07.493148       1 allocate.go:64] Try to allocate resource to 0 Queues
I0714 09:29:07.493373       1 session.go:244] Close Session b109398f-3981-4914-b6d7-b5835957ab80
W0714 09:29:07.541757       1 event_handlers.go:181] Not support non-csi pvc.
I0714 09:29:07.541836       1 event_handlers.go:387] Added pod <default/yolo-pos> into cache.
W0714 09:29:07.566911       1 event_handlers.go:181] Not support non-csi pvc.
I0714 09:29:08.495859       1 cache.go:1363] There are <1> Jobs, <1> Queues and <5> Nodes in total for scheduling.
I0714 09:29:08.496032       1 session.go:190] Open Session f7fe995e-7003-452b-b4f3-6a5f2b7800dd with <1> Job and <1> Queues
I0714 09:29:08.498386       1 enqueue.go:79] Try to enqueue PodGroup to 1 Queues
I0714 09:29:08.498631       1 allocate.go:64] Try to allocate resource to 1 Queues
I0714 09:29:08.498685       1 allocate.go:129] Try to allocate resource to Jobs in Queue <default>
